Workbook
Name Additional_Factor: 'אפשרויות בחירה'!$C$701:$C$850
Name Amoritization: 'אפשרויות בחירה'!$C$546:$C$550
Name Capsule: 'אפשרויות בחירה'!$C$926:$C$928
Name Company_Name: 'File Name Info'!$A$34:$A$120
Name Company_Name_ID: 'File Name Info'!$A$34:$B$120
Name Consortium: 'אפשרויות בחירה'!$C$514:$C$515
Name Country_list: 'אפשרויות בחירה'!$C$4:$C$85
Name Country_list_funds: 'אפשרויות בחירה'!$C$4:$C$103
Name CSA: 'אפשרויות בחירה'!$C$688:$C$689
Name Delivery: 'אפשרויות בחירה'!$C$666:$C$667
Name Dependence_Independence: 'אפשרויות בחירה'!$C$654:$C$655
Name Duration_Underlying_Interest_Rate: 'אפשרויות בחירה'!$C$680:$C$687
Name File_Type: 'File Name Info'!$A$10:$A$12
Name Full_File_Type: 'File Name Info'!$A$11:$B$13
Name Full_Type: 'File Name Info'!$A$2:$B$8
Name Full_Type_Nostro: 'File Name Info'!$A$3:$B$6
Name Full_Year: 'File Name Info'!$A$22:$B$31
Name Fund_Strategy: 'אפשרויות בחירה'!$C$597:$C$621
Name Fund_type: 'אפשרויות בחירה'!$C$328:$C$498
Name Holding_interest: 'אפשרויות בחירה'!$C$146:$C$147
Name In_the_books: 'אפשרויות בחירה'!$C$656:$C$657
Name Industry_Sector: 'אפשרויות בחירה'!$C$1129:$C$1245
Name Industry_sector_all: 'אפשרויות בחירה'!$C$202:$C$327
Name Industry_sectors: 'אפשרויות בחירה'!$C$202:$C$327
Name israel_abroad: 'אפשרויות בחירה'!$C$2:$C$3
Name Issuer_Number_Banks: 'אפשרויות בחירה'!$C$111:$C$113
Name Issuer_Number_Fund: 'אפשרויות בחירה'!$C$114:$C$117
Name issuer_number_loan: 'אפשרויות בחירה'!$C$118:$C$126
Name Issuer_Number_Type: 'אפשרויות בחירה'!$C$104:$C$110
Name Issuer_Number_Type_2: 'אפשרויות בחירה'!$C$1076:$C$1079
Name Issuer_Number_Type_3: 'אפשרויות בחירה'!$C$1081:$C$1085
Name Issuer_Number_Type_V2: 'אפשרויות בחירה'!$C$104:$C$110
Name Issuer_Type_TFunds: 'אפשרויות בחירה'!$C$1087:$C$1089
Name Leading_factor: 'אפשרויות בחירה'!$C$692:$C$700
Name Linked_Type: 'אפשרויות בחירה'!$C$516:$C$519
Name other_investments: 'אפשרויות בחירה'!$C$1000:$C$1033
Name Penalty: 'אפשרויות בחירה'!$C$851:$C$852
Name QTR: 'File Name Info'!$A$15:$A$19
Name Rating_Agency: 'אפשרויות בחירה'!$C$188:$C$201
Name real_estate_lifestage: 'אפשרויות בחירה'!$C$634:$C$642
Name real_estate_loans: 'אפשרויות בחירה'!$C$553:$C$591
Name Real_Estate_Main_Use: 'אפשרויות בחירה'!$C$622:$C$633
Name Recourse_Nonrecourse: 'אפשרויות בחירה'!$C$544:$C$545
Name Repayment_Rights: 'אפשרויות בחירה'!$C$551:$C$552
Name Reset_frequency: 'אפשרויות בחירה'!$C$658:$C$665
Name Security_ID_Number_Type: 'אפשרויות בחירה'!$C$1113:$C$1116
Name Security_Number_Loans: 'אפשרויות בחירה'!$C$131
Name Stock_Exchange: 'אפשרויות בחירה'!$C$1283:$C$1315
Name Stock_Exchange_Gov_Bonds: 'אפשרויות בחירה'!$C$148:$C$181
Name Subordination_Risk: 'אפשרויות בחירה'!$C$186:$C$187
Name Tradeable_Status: 'אפשרויות בחירה'!$C$1272:$C$1281
Name Tradeable_Status_All: 'אפשרויות בחירה'!$C$135:$C$145
Name tradeable_status_bonds: 'אפשרויות בחירה'!$C$1248:$C$1253
Name tradeable_status_funds: 'אפשרויות בחירה'!$C$1118:$C$1119
Name tradeable_status_stock: 'אפשרויות בחירה'!$C$1255:$C$1259
Name Tradeable_Status_v2: 'אפשרויות בחירה'!$C$1121:$C$1126
Name tradeable_status_warrants: 'אפשרויות בחירה'!$C$1261:$C$1265
Name tradeable_status_warrants_v2: 'אפשרויות בחירה'!$C$1267:$C$1269
Name Transaction: 'אפשרויות בחירה'!$C$643:$C$646
Name Type: 'File Name Info'!$A$2:$A$8

Sheet עמוד פתיחה
A1: קובץ דיווח עבור רשימת נכסים ברמת הנכס הבודד (חוזר גופים מוסדיים 2015-9-14)
A3: יש לבחור תחום: | C3: נכסי אפיק השקעה מובטח תשואה
A5: האם מדובר בקובץ לממומנה או לציבור: | C5: לציבור
A7: יש לבחור את רבעון הדיווח: | C7: Q4
A9: יש לבחור את שנת הדיווח: | C9: 2025
A11: יש לבחור את הגוף המוסדי: | C11: מור גמל ופנסיה בע"מ
A13: ח.פ. הגוף המוסדי: | C13: =IFERROR(VLOOKUP(C11,'File Name Info'!A35:B121,2,0),"תא מחושב") -> 514956465
A15: שם קובץ לשמירה | C15: =IF(C5="לממונה",CONCATENATE(C13, "_",VLOOKUP(C3,Full_Type,2,0),"_",C7,VLOOKUP(C9,Full_Year,2,0),".xlxs"),IF(C5="לציבור",CONCATENATE(C13,"_",VLOOKUP(C3,Full_Type_Nostro,2,0),"_",VLOOKUP(C5,Full_File_Type,2,0),"_",C7,VLOOKUP(C9,Full_Year,2,0),".xlsx"),"שם קובץ לשמירה")) -> 514956465_ca_p_Q425.xlsx
A17: פרטי האחראי על הדיווח בגוף המוסדי | B17: שם: | C17: ליאת דוידוב
B19: מספר טלפון:
B21: כתובת מייל: | C21: liat.davidov@more.co.il
A23: הוראות למילוי הדיווח: | C23: יש לדווח לפי ההנחיות בחלק ג' לנספח 5.4.3.2 שבפרק 3 שבחלק 4 לשער 5 בחוזר המאוחד - "רשימת נכסים ברמת הנכס הבודד".

Sheet סכום נכסים
A1: Column1 | B1: Column2 | C1: ידווח בקבצי נכסי הנוסטרו בלבד | D1: Column3 | E1: Column4
A2: ריק במקור | B2: שווי הוגן | C2: עלות מופחתת | D2: השיטה שיושמה בדוח הכספי | E2: שיעור מסך נכסי השקעה
A3: מזומנים ושווי מזומנים | B3: 924895.26 | C3: ריק במקור | D3: ריק במקור | E3: 0.21461939
A4: איגרות חוב ממשלתיות | B4: 1042136.3 | C4: ריק במקור | D4: ריק במקור | E4: 0.24182484
A5: ניירות ערך מסחריים | B5: 0 | C5: ריק במקור | D5: ריק במקור | E5: 0
A6: איגרות חוב | B6: 530457.51 | C6: ריק במקור | D6: ריק במקור | E6: 0.1230912
A7: מניות, מניות בכורה ויחידות השתתפות | B7: 831025.92 | C7: ריק במקור | D7: ריק במקור | E7: 0.19283727
A8: קרנות סל | B8: 346255.48 | C8: ריק במקור | D8: ריק במקור | E8: 0.080347627
A9: קרנות נאמנות | B9: 650118.67 | C9: ריק במקור | D9: ריק במקור | E9: 0.15085824
A10: כתבי אופציה | B10: 3549.4365 | C10: ריק במקור | D10: ריק במקור | E10: 0.00082363693
A11: אופציות | B11: 0 | C11: ריק במקור | D11: ריק במקור | E11: 0
A12: חוזים עתידיים | B12: 4574.5952 | C12: ריק במקור | D12: ריק במקור | E12: 0.0010615222
A13: מוצרים מובנים | B13: 7.46292 | C13: ריק במקור | D13: ריק במקור | E13: 1.7317499e-06
A14: לא סחיר איגרות חוב ממשלתיות | B14: 0 | C14: ריק במקור | D14: ריק במקור | E14: 0
... A29: נכסים אחרים | B29: 1860.9746 | C29: ריק במקור | D29: ריק במקור | E29: 0.00043183401
A30: סך הכל נכסים | B30: 4309467.4 | C30: 0 | D30: ריק במקור | E30: 1
A31: מסגרות אשראי | B31: 58597.759 | C31: ריק במקור | D31: ריק במקור | E31: ריק במקור
A32: יתרות התחייבויות להשקעה | B32: 189226.27 | C32: ריק במקור | D32: ריק במקור | E32: ריק במקור
AZ10000: 1

Sheet מזומנים ושווי מזומנים
A1: מספר קופה/קרן/ח.פ. עבור חברת ביטוח | B1: מספר מסלול | C1: שם הבנק | D1: מספר מזהה בנק | E1: סוג מספר מזהה בנק | F1: מאפיין עיקרי | G1: ישראל/חו"ל | H1: בעל עניין/צד קשור | I1: דירוג הבנק | J1: שם מדרג | K1: מטבע פעילות | L1: שווי מטבעי | M1: שער חליפין | N1: שיעור ריבית | O1: שווי הוגן (באלפי ש"ח) | P1: שיעור מנכסי אפיק ההשקעה | Q1: שיעור מסך נכסי ההשקעה
A2: 13908 | B2: 13908 | C2: בנק הבינלאומי הראשון בע"מ | D2: 31 | E2: סימול בנק | F2: מזומן ועו"ש בש"ח | G2: ישראל | H2: לא | I2: ilAAA | J2: S&P מעלות | K2: ILS | L2: 668867.3 | M2: 1 | N2: ריק במקור | O2: 668867.3 | P2: 0.72318167 | Q2: 0.15520881
A3: 13908 | B3: 13908 | C3: בנק הבינלאומי הראשון בע"מ | D3: 31 | E3: סימול בנק | F3: מזומן ועו"ש נקוב במט"ח | G3: ישראל | H3: לא | I3: ilAAA | J3: S&P מעלות | K3: USD | L3: =44594.5536708464-175.90482 -> 44418.649 | M3: 3.19 | N3: ריק במקור | O3: =142256.62621-175.90482*3.19 -> 141695.49 | P3: 0.15380836 | Q3: 0.033010257
A4: 13908 | B4: 13908 | C4: בנק הבינלאומי הראשון בע"מ | D4: 31 | E4: סימול בנק | F4: מזומן ועו"ש נקוב במט"ח | G4: ישראל | H4: לא | I4: ilAAA | J4: S&P מעלות | K4: CHF | L4: 49.01082 | M4: 4.0213 | N4: ריק במקור | O4: 197.08721 | P4: 0.00021309138 | Q4: 4.5733542e-05
A5: 13908 | B5: 13908 | C5: בנק הבינלאומי הראשון בע"מ | D5: 31 | E5: סימול בנק | F5: מזומן ועו"ש נקוב במט"ח | G5: ישראל | H5: לא | I5: ilAAA | J5: S&P מעלות | K5: GBP | L5: 366.10246 | M5: 4.29 | N5: ריק במקור | O5: 1570.5795 | P5: 0.0016981161 | Q5: 0.00036444864
A6: 13908 | B6: 13908 | C6: בנק הבינלאומי הראשון בע"מ | D6: 31 | E6: סימול בנק | F6: מזומן ועו"ש נקוב במט"ח | G6: ישראל | H6: לא | I6: ilAAA | J6: S&P מעלות | K6: JPY | L6: 963382.37 | M6: 0.020365 | N6: ריק במקור | O6: 19619.282 | P6: 0.021212437 | Q6: 0.0045526001
A7: 13908 | B7: 13908 | C7: בנק הבינלאומי הראשון בע"מ | D7: 31 | E7: סימול בנק | F7: מזומן ועו"ש נקוב במט"ח | G7: ישראל | H7: לא | I7: ilAAA | J7: S&P מעלות | K7: CAD | L7: 13.840662 | M7: 2.3275 | N7: ריק במקור | O7: 32.21414 | P7: 3.4830041e-05 | Q7: 7.4752021e-06
A8: 13908 | B8: 13908 | C8: בנק הבינלאומי הראשון בע"מ | D8: 31 | E8: סימול בנק | F8: מזומן ועו"ש נקוב במט"ח | G8: ישראל | H8: לא | I8: ilAAA | J8: S&P מעלות | K8: EUR | L8: 1.0679482e-05 | M8: 3.7455 | N8: ריק במקור | O8: 4e-05 | P8: 4.324814e-11 | Q8: 9.2818894e-12
A9: 13908 | B9: 13908 | C9: בנק הבינלאומי הראשון בע"מ | D9: 31 | E9: סימול בנק | F9: מזומן ועו"ש נקוב במט"ח | G9: ישראל | H9: לא | I9: ilAAA | J9: S&P מעלות | K9: EUR | L9: 7065.94 | M9: 3.7455 | N9: ריק במקור | O9: 26465.478 | P9: 0.028614568 | Q9: 0.0061412411
A10: 13908 | B10: 13908 | C10: בנק הבינלאומי הראשון בע"מ | D10: 31 | E10: סימול בנק | F10: מזומן ועו"ש נקוב במט"ח | G10: ישראל | H10: לא | I10: ilAAA | J10: S&P מעלות | K10: USD | L10: -4.0176991 | M10: 3.19 | N10: ריק במקור | O10: -12.81646 | P10: -1.3857201e-05 | Q10: -2.9740241e-06
A11: 13908 | B11: 13908 | C11: בנק הבינלאומי הראשון בע"מ | D11: 31 | E11: סימול בנק | F11: מזומן ועו"ש נקוב במט"ח | G11: ישראל | H11: לא | I11: ilAAA | J11: S&P מעלות | K11: USD | L11: 470.8692 | M11: 3.19 | N11: ריק במקור | O11: 1502.0728 | P11: 0.0016240463 | Q11: 0.00034855183
A12: 13908 | B12: 13908 | C12: בנק הבינלאומי הראשון בע"מ | D12: 31 | E12: סימול בנק | F12: מזומן ועו"ש נקוב במט"ח | G12: ישראל | H12: לא | I12: ilAAA | J12: S&P מעלות | K12: AUD | L12: 47.942211 | M12: 2.1319 | N12: ריק במקור | O12: 102.208 | P12: 0.00011050765 | Q12: 2.3717084e-05
A13: 13908 | B13: 13908 | C13: בנק הבינלאומי הראשון בע"מ | D13: 31 | E13: סימול בנק | F13: מזומן ועו"ש בש"ח | G13: ישראל | H13: לא | I13: ilAAA | J13: S&P מעלות | K13: ILS | L13: 32395.23 | M13: 1 | N13: ריק במקור | O13: 32395.23 | P13: 0.035025836 | Q13: 0.0075172235
A14: 13908 | B14: 13908 | C14: בנק הבינלאומי הראשון בע"מ | D14: 31 | E14: סימול בנק | F14: מזומן ועו"ש נקוב במט"ח | G14: ישראל | H14: לא | I14: ilAAA | J14: S&P מעלות | K14: USD | L14: 10000 | M14: 3.19 | N14: ריק במקור | O14: 31900 | P14: 0.034490392 | Q14: 0.0074023068
A15: 13908 | B15: 13908 | C15: בנק מזרחי טפחות בע"מ | D15: 20 | E15: סימול בנק | F15: מזומן ועו"ש נקוב במט"ח | G15: ישראל | H15: לא | I15: ilAAA | J15: S&P מעלות | K15: USD | L15: 175.90482 | M15: 3.19 | N15: ריק במקור | O15: =175.90482*3.19 -> 561.13638 | P15: 0.15380836 | Q15: 0.033010257
AZ10000: 1

Sheet איגרות חוב ממשלתיות
A1: מספר קופה/קרן/ח.פ. עבור חברת ביטוח | B1: מספר מסלול | C1: שם מנפיק | D1: שם נייר ערך | E1: מספר נייר ערך | F1: מאפיין עיקרי | G1: ישראל/חו"ל | H1: מדינה לפי חשיפה כלכלית | I1: זירת מסחר | J1: דירוג | K1: שם מדרג | L1: מטבע פעילות | M1: מח"מ | N1: מועד פדיון | O1: שיעור ריבית | P1: תשואה לפדיון | Q1: סכום לקבל (במטבע הפעילות) | R1: ערך נקוב (יחידות) | S1: שער חליפין | T1: שער נייר הערך | U1: שווי הוגן (באלפי ש"ח) | V1: עלות מופחתת (באלפי ש"ח) | W1: השיטה שיושמה בדוח הכספי | X1: שיעור מערך נקוב מונפק | Y1: שיעור מנכסי אפיק ההשקעה | Z1: שיעור מסך נכסי ההשקעה
A2: 13908 | B2: 13908 | C2: מדינת ישראל | D2: ממשל שקלית 0142 | E2: IL0011254005 | F2: לא צמוד למדד המחירים לצרכן ריבית קבועה | G2: ישראל | H2: ישראל | I2: TASE | J2: NR | K2: NR | L2: ILS | M2: 10.981 | N2: 51897 | O2: 0.055 | P2: 0.0417 | Q2: 0 | R2: 3800000 | S2: 1 | T2: 120.4 | U2: 4575.2 | V2: ריק במקור | W2: שווי הוגן | X2: 0.00011746045 | Y2: 0.0043902128 | Z2: 0.0010616625
A3: 13908 | B3: 13908 | C3: מדינת ישראל | D3: ממשל שקלית 0327 | E3: IL0011393449 | F3: לא צמוד למדד המחירים לצרכן ריבית קבועה | G3: ישראל | H3: ישראל | I3: TASE | J3: NR | K3: NR | L3: ILS | M3: 1.224 | N3: 46477 | O3: 0.02 | P3: 0.0376 | Q3: 0 | R3: 8178400 | S3: 1 | T3: 99.41 | U3: 8130.1474 | V3: ריק במקור | W3: שווי הוגן | X3: 0.00028972246 | Y3: 0.0078014245 | Z3: 0.0018865782
A4: 13908 | B4: 13908 | C4: מדינת ישראל | D4: ממשל שקלית 0347 | E4: IL0011401937 | F4: לא צמוד למדד המחירים לצרכן ריבית קבועה | G4: ישראל | H4: ישראל | I4: TASE | J4: NR | K4: NR | L4: ILS | M4: 14.301 | N4: 53782 | O4: 0.0375 | P4: 0.0431 | Q4: 0 | R4: 5370250 | S4: 1 | T4: 95.14 | U4: 5109.2558 | V4: ריק במקור | W4: שווי הוגן | X4: 0.00019813948 | Y4: 0.0049026754 | Z4: 0.0011855887
A5: 13908 | B5: 13908 | C5: מדינת ישראל | D5: ממשל צמודה 0527 | E5: IL0011408478 | F5: צמוד למדד המחירים לצרכן בריבית קבועה | G5: ישראל | H5: ישראל | I5: TASE | J5: NR | K5: NR | L5: ILS | M5: 1.403 | N5: 46538 | O5: 0.0075 | P5: 0.0192 | Q5: 0 | R5: 94877805 | S5: 1 | T5: 117.85 | U5: 111813.49 | V5: ריק במקור | W5: שווי הוגן | X5: 0.0038953859 | Y5: 0.10729258 | Z5: 0.025946012
A6: 13908 | B6: 13908 | C6: מדינת ישראל | D6: ממשל שקלית 0928 | E6: IL0011508798 | F6: לא צמוד למדד המחירים לצרכן ריבית קבועה | G6: ישראל | H6: ישראל | I6: TASE | J6: NR | K6: NR | L6: ILS | M6: 2.676 | N6: 47024 | O6: 0.0225 | P6: 0.0373 | Q6: 0 | R6: 71135295 | S6: 1 | T6: 96.78 | U6: 68844.739 | V6: ריק במקור | W6: שווי הוגן | X6: 0.0020487379 | Y6: 0.066061167 | Z6: 0.015975231
A7: 13908 | B7: 13908 | C7: מדינת ישראל | D7: ממשל צמודה 0529 | E7: IL0011570236 | F7: צמוד למדד המחירים לצרכן בריבית קבועה | G7: ישראל | H7: ישראל | I7: TASE | J7: NR | K7: NR | L7: ILS | M7: 3.383 | N7: 47269 | O7: 0.005 | P7: 0.0171 | Q7: 0 | R7: 50817851 | S7: 1 | T7: 113.71 | U7: 57784.978 | V7: ריק במקור | W7: שווי הוגן | X7: 0.0016884101 | Y7: 0.055448582 | Z7: 0.013408844
A8: 13908 | B8: 13908 | C8: מדינת ישראל | D8: ממשל שקלית 0537 | E8: IL0011661803 | F8: לא צמוד למדד המחירים לצרכן ריבית קבועה | G8: ישראל | H8: ישראל | I8: TASE | J8: NR | K8: NR | L8: ILS | M8: 10.317 | N8: 50191 | O8: 0.015 | P8: 0.0404 | Q8: 0 | R8: 27617147 | S8: 1 | T8: 78 | U8: 21541.375 | V8: ריק במקור | W8: שווי הוגן | X8: 0.00065912066 | Y8: 0.020670401 | Z8: 0.0049986164
A9: 13908 | B9: 13908 | C9: מדינת ישראל | D9: ממשל משתנה 1130 | E9: IL0011665523 | F9: לא צמוד למדד המחירים לצרכן ריבית משתנה | G9: ישראל | H9: ישראל | I9: TASE | J9: NR | K9: NR | L9: ILS | M9: 4.485 | N9: 47816 | O9: 0.037843 | P9: 0.0422 | Q9: 0 | R9: 41429977 | S9: 1 | T9: 98.79 | U9: 40928.674 | V9: ריק במקור | W9: שווי הוגן | X9: 0.0012404804 | Y9: 0.039273822 | Z9: 0.0094973857
A10: 13908 | B10: 13908 | C10: מדינת ישראל | D10: ממשל צמודה 0726 | E10: IL0011695645 | F10: צמוד למדד המחירים לצרכן בריבית קבועה | G10: ישראל | H10: ישראל | I10: TASE | J10: NR | K10: NR | L10: ILS | M10: 0.578 | N10: 46234 | O10: 0.001 | P10: 0.0258 | Q10: 0 | R10: 70544896 | S10: 1 | T10: 116.46 | U10: 82156.586 | V10: ריק במקור | W10: שווי הוגן | X10: 0.0034915325 | Y10: 0.078834782 | Z10: 0.019064209
A11: 13908 | B11: 13908 | C11: מדינת ישראל | D11: ממשל צמודה 1131 | E11: IL0011722209 | F11: צמוד למדד המחירים לצרכן בריבית קבועה | G11: ישראל | H11: ישראל | I11: TASE | J11: NR | K11: NR | L11: ILS | M11: 5.899 | N11: 48182 | O11: 0.001 | P11: 0.017 | Q11: 0 | R11: 15892000 | S11: 1 | T11: 107.5 | U11: 17083.9 | V11: ריק במקור | W11: שווי הוגן | X11: 0.00046429175 | Y11: 0.016393154 | Z11: 0.0039642717
A12: 13908 | B12: 13908 | C12: מדינת ישראל | D12: ממשל שקלית 0432 | E12: IL0011806606 | F12: לא צמוד למדד המחירים לצרכן ריבית קבועה | G12: ישראל | H12: ישראל | I12: TASE | J12: NR | K12: NR | L12: ILS | M12: 6.04 | N12: 48334 | O12: 0.013 | P12: 0.0379 | Q12: 0 | R12: 82012941 | S12: 1 | T12: 87.06 | U12: 71400.466 | V12: ריק במקור | W12: שווי הוגן | X12: 0.0019959954 | Y12: 0.06851356 | Z12: 0.016568281
A13: 13908 | B13: 13908 | C13: מדינת ישראל | D13: ממשל שקלית 1152 | E13: IL0011840761 | F13: לא צמוד למדד המחירים לצרכן ריבית קבועה | G13: ישראל | H13: ישראל | I13: TASE | J13: NR | K13: NR | L13: ILS | M13: 17.816 | N13: 55852 | O13: 0.028 | P13: 0.0444 | Q13: 0 | R13: 3329807 | S13: 1 | T13: 74.76 | U13: 2489.3637 | V13: ריק במקור | W13: שווי הוגן | X13: 0.00011100171 | Y13: 0.0023887123 | Z13: 0.00057764996
... A31: 13908 | B31: 13908 | C31: STATE OF ISRAEL | D31: ISRAEL 5.625 2/35 | E31: US46514Y8B63 | F31: נקוב במט"ח | G31: חו"ל | H31: ישראל | I31: LSE | J31: Baa1 | K31: Moodys | L31: USD | M31: 7.17 | N31: 49359 | O31: 0.05625 | P31: 0.05007 | Q31: 0 | R31: 10519000 | S31: 3.19 | T31: 106.2986 | U31: 35669.144 | V31: ריק במקור | W31: שווי הוגן | X31: 0.0042076 | Y31: 0.034226948 | Z31: 0.0082769261
AZ10000: 1

Sheet ניירות ערך מסחריים
A1: מספר קופה/קרן/ח.פ. עבור חברת ביטוח | B1: מספר מסלול | C1: שם מנפיק | D1: מספר מנפיק | E1: סוג מספר מזהה מנפיק | F1: שם נייר ערך | G1: מספר נייר ערך | H1: סוג מספר נייר ערך | I1: מאפיין עיקרי | J1: ישראל/חו"ל | K1: מדינה לפי חשיפה כלכלית | L1: זירת מסחר | M1: ענף מסחר | N1: בעל עניין/צד קשור | O1: דירוג | P1: שם מדרג | Q1: דירוג נייר הערך/המנפיק | R1: מטבע פעילות | S1: מח"מ | T1: ריבית עוגן | U1: מועד פדיון | V1: שיעור ריבית | W1: תשואה לפדיון | X1: נחיתות חוזית | Y1: האם סווג כחוב בעייתי | Z1: ערך נקוב (יחידות) | AA1: שער חליפין | AB1: שער נייר הערך | AC1: סכום לקבל (במטבע הפעילות) | AD1: שווי הוגן (באלפי ש"ח) | AE1: עלות מופחתת (באלפי ש"ח) | AF1: עלות מופחתת (במטבע הפעילות) | AG1: השיטה שיושמה בדוח הכספי | AH1: שיעור מערך נקוב מונפק | AI1: שיעור מנכסי אפיק ההשקעה | AJ1: שיעור מסך נכסי ההשקעה

Sheet איגרות חוב
A1: מספר קופה/קרן/ח.פ. עבור חברת ביטוח | B1: מספר מסלול | C1: שם מנפיק | D1: מספר מנפיק | E1: סוג מספר מזהה מנפיק | F1: שם נייר ערך | G1: מספר נייר ערך | H1: סוג מספר נייר ערך | I1: מאפיין עיקרי | J1: ישראל/חו"ל | K1: מדינה לפי חשיפה כלכלית | L1: סטאטוס סחירות | M1: זירת מסחר | N1: ענף מסחר | O1: בעל עניין/צד קשור | P1: דירוג | Q1: שם מדרג | R1: דירוג נייר הערך/המנפיק | S1: מטבע פעילות | T1: מח"מ | U1: מועד פדיון | V1: שיעור ריבית | W1: תשואה לפדיון | X1: נחיתות חוזית | Y1: האם סווג כחוב בעייתי | Z1: ערך נקוב (יחידות) | AA1: שער חליפין | AB1: שער נייר הערך | AC1: סכום לקבל (במטבע הפעילות) | AD1: שווי הוגן (באלפי ש"ח) | AE1: עלות מופחתת (באלפי ש"ח) | AF1: עלות מופחתת (במטבע הפעילות) | AG1: השיטה שיושמה בדוח הכספי | AH1: שיעור מערך נקוב מונפק | AI1: שיעור מנכסי אפיק ההשקעה | AJ1: שיעור מסך נכסי ההשקעה
A2: 13908 | B2: 13908 | C2: אדמה פתרונות לחקלאות בע"מ | D2: 520043605 | E2: ח.פ. | F2: אדמה אגח ב | G2: IL0011109159 | H2: ISIN | I2: צמוד למדד המחירים לצרכן | J2: ישראל | K2: ישראל | L2: סחיר | M2: TASE | N2: כימיה, גומי ופלסטיק | O2: לא | P2: ilAA- | Q2: S&P מעלות | R2: נייר ערך | S2: ILS | T2: 5.134 | U2: 50009 | V2: 0.0515 | W2: 0.0337 | X2: החוב לא נחות | Y2: ריק במקור | Z2: 338274.88 | AA2: 1 | AB2: 156.17 | AC2: 0 | AD2: 528.28388 | AE2: ריק במקור | AF2: ריק במקור | AG2: שווי הוגן | AH2: 0.00019230142 | AI2: =+AD2/SUM(AD:AD) -> 0.00099590235 | AJ2: =+AD2/'סכום נכסים'!$B$30 -> 0.00012258681
A3: 13908 | B3: 13908 | C3: אמות השקעות בע"מ | D3: 520026683 | E3: ח.פ. | F3: אמות אגח ד | G3: IL0011331498 | H3: ISIN | I3: צמוד למדד המחירים לצרכן | J3: ישראל | K3: ישראל | L3: סחיר | M3: TASE | N3: נדל"ן מניב בישראל | O3: לא | P3: ilAA | Q3: S&P מעלות | R3: נייר ערך | S3: ILS | T3: 1.462 | U3: 46936 | V3: 0.032 | W3: 0.0261 | X3: החוב לא נחות | Y3: ריק במקור | Z3: 542283.75 | AA3: 1 | AB3: 120.58 | AC3: 0 | AD3: 653.88575 | AE3: ריק במקור | AF3: ריק במקור | AG3: שווי הוגן | AH3: 0.0013095458 | AI3: =+AD3/SUM(AD:AD) -> 0.0012326826 | AJ3: =+AD3/'סכום נכסים'!$B$30 -> 0.00015173238
A4: 13908 | B4: 13908 | C4: איירפורט סיטי בע"מ | D4: 511659401 | E4: ח.פ. | F4: ארפורט אגח ה | G4: IL0011334872 | H4: ISIN | I4: צמוד למדד המחירים לצרכן | J4: ישראל | K4: ישראל | L4: סחיר | M4: TASE | N4: נדל"ן מניב בישראל | O4: לא | P4: ilAA | Q4: S&P מעלות | R4: נייר ערך | S4: ILS | T4: 1.515 | U4: 47177 | V4: 0.0234 | W4: 0.0262 | X4: החוב לא נחות | Y4: ריק במקור | Z4: 2144034.4 | AA4: 1 | AB4: 119.52 | AC4: 0 | AD4: 2562.55 | AE4: ריק במקור | AF4: ריק במקור | AG4: שווי הוגן | AH4: 0.0013152679 | AI4: =+AD4/SUM(AD:AD) -> 0.0048308298 | AJ4: =+AD4/'סכום נכסים'!$B$30 -> 0.00059463263
A5: 13908 | B5: 13908 | C5: שיכון ובינוי בע"מ | D5: 520036104 | E5: ח.פ. | F5: שכון ובי אגח 8 | G5: IL0011358889 | H5: ISIN | I5: צמוד למדד המחירים לצרכן | J5: ישראל | K5: ישראל | L5: סחיר | M5: TASE | N5: בנייה | O5: לא | P5: ilA | Q5: S&P מעלות | R5: נייר ערך | S5: ILS | T5: 1.763 | U5: 47239 | V5: 0.039 | W5: 0.0296 | X5: החוב לא נחות | Y5: ריק במקור | Z5: 1563836.3 | AA5: 1 | AB5: 121.31 | AC5: 0 | AD5: 1897.0898 | AE5: ריק במקור | AF5: ריק במקור | AG5: שווי הוגן | AH5: 0.0011329611 | AI5: =+AD5/SUM(AD:AD) -> 0.0035763276 | AJ5: =+AD5/'סכום נכסים'!$B$30 -> 0.00044021445
A6: 13908 | B6: 13908 | C6: קרסו מוטורס בע"מ | D6: 514065283 | E6: ח.פ. | F6: קרסו מוט' אגח א | G6: IL0011364648 | H6: ISIN | I6: לא צמוד למדד המחירים לצרכן | J6: ישראל | K6: ישראל | L6: סחיר | M6: TASE | N6: מסחר | O6: לא | P6: ilAA- | Q6: S&P מעלות | R6: נייר ערך | S6: ILS | T6: 0.412 | U6: 46266 | V6: 0.0275 | W6: 0.049 | X6: החוב לא נחות | Y6: ריק במקור | Z6: 672514.62 | AA6: 1 | AB6: 100.07 | AC6: 0 | AD6: 672.98538 | AE6: ריק במקור | AF6: ריק במקור | AG6: שווי הוגן | AH6: 0.0074077452 | AI6: =+AD6/SUM(AD:AD) -> 0.0012686886 | AJ6: =+AD6/'סכום נכסים'!$B$30 -> 0.0001561644
A7: 13908 | B7: 13908 | C7: ריט 1 בע"מ | D7: 513821488 | E7: ח.פ. | F7: ריט 1 אגח ה | G7: IL0011367534 | H7: ISIN | I7: צמוד למדד המחירים לצרכן | J7: ישראל | K7: ישראל | L7: סחיר | M7: TASE | N7: נדל"ן מניב בישראל | O7: לא | P7: ilAA | Q7: S&P מעלות | R7: נייר ערך | S7: ILS | T7: 1.421 | U7: 47016 | V7: 0.04 | W7: 0.0261 | X7: החוב לא נחות | Y7: ריק במקור | Z7: 1821756.5 | AA7: 1 | AB7: 122.36 | AC7: 0 | AD7: 2229.1013 | AE7: ריק במקור | AF7: ריק במקור | AG7: שווי הוגן | AH7: 0.0025235064 | AI7: =+AD7/SUM(AD:AD) -> 0.004202224 | AJ7: =+AD7/'סכום נכסים'!$B$30 -> 0.00051725679
A8: 13908 | B8: 13908 | C8: ריט 1 בע"מ | D8: 513821488 | E8: ח.פ. | F8: ריט 1 אגח ו | G8: IL0011385445 | H8: ISIN | I8: צמוד למדד המחירים לצרכן | J8: ישראל | K8: ישראל | L8: סחיר | M8: TASE | N8: נדל"ן מניב בישראל | O8: לא | P8: ilAA | Q8: S&P מעלות | R8: נייר ערך | S8: ILS | T8: 2.8 | U8: 48112 | V8: 0.035 | W8: 0.025 | X8: החוב לא נחות | Y8: ריק במקור | Z8: 231988.13 | AA8: 1 | AB8: 124.44 | AC8: 0 | AD8: 288.68603 | AE8: ריק במקור | AF8: ריק במקור | AG8: שווי הוגן | AH8: 0.00031430709 | AI8: =+AD8/SUM(AD:AD) -> 0.00054422084 | AJ8: =+AD8/'סכום נכסים'!$B$30 -> 6.6988795e-05
A9: 13908 | B9: 13908 | C9: קבוצת עזריאלי בע"מ | D9: 510960719 | E9: ח.פ. | F9: עזריאלי אגח ד | G9: IL0011386500 | H9: ISIN | I9: צמוד למדד המחירים לצרכן | J9: ישראל | K9: ישראל | L9: סחיר | M9: TASE | N9: נדל"ן מניב בישראל | O9: לא | P9: Aa1.il | Q9: מידרוג Moodys | R9: נייר ערך | S9: ILS | T9: 2.447 | U9: 47669 | V9: 0.0134 | W9: 0.0255 | X9: החוב לא נחות | Y9: ריק במקור | Z9: 2803899.2 | AA9: 1 | AB9: 116.05 | AC9: 32.08477 | AD9: 3286.0098 | AE9: ריק במקור | AF9: ריק במקור | AG9: שווי הוגן | AH9: 0.0014104132 | AI9: =+AD9/SUM(AD:AD) -> 0.0061946711 | AJ9: =+AD9/'סכום נכסים'!$B$30 -> 0.00076250949
A10: 13908 | B10: 13908 | C10: ביג מרכזי קניות בע"מ | D10: 513623314 | E10: ח.פ. | F10: ביג אגח ח | G10: IL0011389249 | H10: ISIN | I10: צמוד למדד המחירים לצרכן | J10: ישראל | K10: ישראל | L10: סחיר | M10: TASE | N10: נדל"ן מניב בישראל | O10: לא | P10: ilAA | Q10: S&P מעלות | R10: נייר ערך | S10: ILS | T10: 0.277 | U10: 46124 | V10: 0.0134 | W10: 0.0518 | X10: החוב לא נחות | Y10: ריק במקור | Z10: 63642.87 | AA10: 1 | AB10: 118.26 | AC10: 0 | AD10: 75.26406 | AE10: ריק במקור | AF10: ריק במקור | AG10: שווי הוגן | AH10: 0.0001410666 | AI10: =+AD10/SUM(AD:AD) -> 0.00014188518 | AJ10: =+AD10/'סכום נכסים'!$B$30 -> 1.7464817e-05
A11: 13908 | B11: 13908 | C11: סלע קפיטל נדל"ן בע"מ | D11: 513992529 | E11: ח.פ. | F11: סלע נדלן אגח ג | G11: IL0011389736 | H11: ISIN | I11: צמוד למדד המחירים לצרכן | J11: ישראל | K11: ישראל | L11: סחיר | M11: TASE | N11: נדל"ן מניב בישראל | O11: לא | P11: Aa3.il | Q11: מידרוג Moodys | R11: נייר ערך | S11: ILS | T11: 1.731 | U11: 47221 | V11: 0.0196 | W11: 0.0269 | X11: החוב לא נחות | Y11: ריק במקור | Z11: 3000000 | AA11: 1 | AB11: 117.7 | AC11: 0 | AD11: 3531 | AE11: ריק במקור | AF11: ריק במקור | AG11: שווי הוגן | AH11: 0.0026198756 | AI11: =+AD11/SUM(AD:AD) -> 0.0066565181 | AJ11: =+AD11/'סכום נכסים'!$B$30 -> 0.00081935878
A12: 13908 | B12: 13908 | C12: קבוצת אשטרום בע"מ | D12: 510381601 | E12: ח.פ. | F12: אשטרום קב אגח ג | G12: IL0011401028 | H12: ISIN | I12: לא צמוד למדד המחירים לצרכן | J12: ישראל | K12: ישראל | L12: סחיר | M12: TASE | N12: בנייה | O12: לא | P12: ilA | Q12: S&P מעלות | R12: נייר ערך | S12: ILS | T12: 1.452 | U12: 47133 | V12: 0.043 | W12: 0.0468 | X12: החוב לא נחות | Y12: ריק במקור | Z12: 8022320.4 | AA12: 1 | AB12: 101.52 | AC12: 0 | AD12: 8144.2597 | AE12: ריק במקור | AF12: ריק במקור | AG12: שווי הוגן | AH12: 0.011355826 | AI12: =+AD12/SUM(AD:AD) -> 0.015353274 | AJ12: =+AD12/'סכום נכסים'!$B$30 -> 0.0018898529
A13: 13908 | B13: 13908 | C13: רבוע כחול נדל"ן בע"מ | D13: 513765859 | E13: ח.פ. | F13: רבוע נדלן אגח ו | G13: IL0011406076 | H13: ISIN | I13: צמוד למדד המחירים לצרכן | J13: ישראל | K13: ישראל | L13: סחיר | M13: TASE | N13: נדל"ן מניב בישראל | O13: לא | P13: ilAA | Q13: S&P מעלות | R13: נייר ערך | S13: ILS | T13: 0.907 | U13: 46356 | V13: 0.0215 | W13: 0.0279 | X13: החוב לא נחות | Y13: ריק במקור | Z13: 196428.57 | AA13: 1 | AB13: 119.17 | AC13: 0 | AD13: 234.08393 | AE13: ריק במקור | AF13: ריק במקור | AG13: שווי הוגן | AH13: 0.00028042636 | AI13: =+AD13/SUM(AD:AD) -> 0.00044128686 | AJ13: =+AD13/'סכום נכסים'!$B$30 -> 5.4318529e-05
... A102: 13908 | B102: 13908 | C102: וילאר אינטרנשיונל בע"מ | D102: 520038910 | E102: ח.פ. | F102: וילאר אגח י | G102: IL0011939522 | H102: ISIN | I102: לא צמוד למדד המחירים לצרכן | J102: ישראל | K102: ישראל | L102: סחיר | M102: TASE | N102: נדל"ן מניב בישראל | O102: כן | P102: ilAA | Q102: S&P מעלות | R102: נייר ערך | S102: ILS | T102: 3.654 | U102: 48213 | V102: 0.0489 | W102: 0.0432 | X102: החוב לא נחות | Y102: ריק במקור | Z102: 4042000 | AA102: 1 | AB102: 102.23 | AC102: 0 | AD102: 4132.1366 | AE102: ריק במקור | AF102: ריק במקור | AG102: שווי הוגן | AH102: 0.0087869947 | AI102: =+AD102/SUM(AD:AD) -> 0.0077897598 | AJ102: =+AD102/'סכום נכסים'!$B$30 -> 0.00095885087
A103: 13908 | B103: 13908 | C103: סיאון אינווסטמנט קורפוריישן | D103: D14242259 | E103: LEI | F103: סיאון אגח א | G103: IL0011940181 | H103: ISIN | I103: צמוד למט"ח | J103: ישראל | K103: ארה"ב | L103: סחיר | M103: TASE | N103: אשראי חוץ בנקאי | O103: לא | P103: A1.il | Q103: מידרוג Moodys | R103: נייר ערך | S103: ILS | T103: 0.649 | U103: 46265 | V103: 0.0753 | W103: 0.0886 | X103: החוב לא נחות | Y103: ריק במקור | Z103: 1201000 | AA103: 1 | AB103: 87 | AC103: 0 | AD103: 1044.87 | AE103: ריק במקור | AF103: ריק במקור | AG103: שווי הוגן | AH103: 0.0028526883 | AI103: =+AD103/SUM(AD:AD) -> 0.0019697525 | AJ103: =+AD103/'סכום נכסים'!$B$30 -> 0.00024245919
A104: 13908 | B104: 13908 | C104: מליסרון בע"מ | D104: 520037789 | E104: ח.פ. | F104: מליסרון אגח כא | G104: IL0011946386 | H104: ISIN | I104: צמוד למדד המחירים לצרכן | J104: ישראל | K104: ישראל | L104: סחיר | M104: TASE | N104: נדל"ן מניב בישראל | O104: לא | P104: ilAA | Q104: S&P מעלות | R104: נייר ערך | S104: ILS | T104: 5.32 | U104: 50041 | V104: 0.0361 | W104: 0.026 | X104: החוב לא נחות | Y104: ריק במקור | Z104: 2311884.2 | AA104: 1 | AB104: 114.15 | AC104: 42.36155 | AD104: 2681.3774 | AE104: ריק במקור | AF104: ריק במקור | AG104: שווי הוגן | AH104: 0.00094613179 | AI104: =+AD104/SUM(AD:AD) -> 0.0050548391 | AJ104: =+AD104/'סכום נכסים'!$B$30 -> 0.0006222062
A105: 13908 | B105: 13908 | C105: הפניקס גיוסי הון (2009)בע"מ | D105: 514290345 | E105: ח.פ. | F105: פניקס הון אגחיב | G105: IL0011955858 | H105: ISIN | I105: צמוד למדד המחירים לצרכן | J105: ישראל | K105: ישראל | L105: סחיר | M105: TASE | N105: ביטוח | O105: לא | P105: ilAA- | Q105: S&P מעלות | R105: נייר ערך | S105: ILS | T105: 5.704 | U105: 62494 | V105: 0.0209 | W105: 0.0248 | X105: החוב לא נחות | Y105: ריק במקור | Z105: 50000 | AA105: 1 | AB105: 114.75 | AC105: 0 | AD105: 57.375 | AE105: ריק במקור | AF105: ריק במקור | AG105: שווי הוגן | AH105: 3.2390762e-05 | AI105: =+AD105/SUM(AD:AD) -> 0.00010816135 | AJ105: =+AD105/'סכום נכסים'!$B$30 -> 1.331371e-05
A106: 13908 | B106: 13908 | C106: איירפורט סיטי בע"מ | D106: 511659401 | E106: ח.פ. | F106: ארפורט אגח י | G106: IL0011959819 | H106: ISIN | I106: לא צמוד למדד המחירים לצרכן | J106: ישראל | K106: ישראל | L106: סחיר | M106: TASE | N106: נדל"ן מניב בישראל | O106: לא | P106: ilAA | Q106: S&P מעלות | R106: נייר ערך | S106: ILS | T106: 1.936 | U106: 47238 | V106: 0.05 | W106: 0.0424 | X106: החוב לא נחות | Y106: ריק במקור | Z106: 306250 | AA106: 1 | AB106: 102.39 | AC106: 0 | AD106: 313.56937 | AE106: ריק במקור | AF106: ריק במקור | AG106: שווי הוגן | AH106: 0.00062103929 | AI106: =+AD106/SUM(AD:AD) -> 0.00059113004 | AJ106: =+AD106/'סכום נכסים'!$B$30 -> 7.2762905e-05
A107: 13908 | B107: 13908 | C107: איירפורט סיטי בע"מ | D107: 511659401 | E107: ח.פ. | F107: ארפורט אגח יא | G107: IL0011959991 | H107: ISIN | I107: צמוד למדד המחירים לצרכן | J107: ישראל | K107: ישראל | L107: סחיר | M107: TASE | N107: נדל"ן מניב בישראל | O107: לא | P107: ilAA | Q107: S&P מעלות | R107: נייר ערך | S107: ILS | T107: 7.184 | U107: 50891 | V107: 0.0264 | W107: 0.0239 | X107: החוב לא נחות | Y107: ריק במקור | Z107: 422000 | AA107: 1 | AB107: 110.34 | AC107: 0 | AD107: 465.6348 | AE107: ריק במקור | AF107: ריק במקור | AG107: שווי הוגן | AH107: 0.0014066667 | AI107: =+AD107/SUM(AD:AD) -> 0.00087779849 | AJ107: =+AD107/'סכום נכסים'!$B$30 -> 0.00010804927
A108: 13908 | B108: 13908 | C108: חברת החשמל לישראל בע"מ | D108: 520000472 | E108: ח.פ. | F108: חשמל אגח 34 | G108: IL0011967812 | H108: ISIN | I108: צמוד למדד המחירים לצרכן | J108: ישראל | K108: ישראל | L108: סחיר | M108: TASE | N108: אנרגיה | O108: לא | P108: ilAAA | Q108: S&P מעלות | R108: נייר ערך | S108: ILS | T108: 6.739 | U108: 48742 | V108: 0.03 | W108: 0.0238 | X108: החוב לא נחות | Y108: ריק במקור | Z108: 1017000 | AA108: 1 | AB108: 111.73 | AC108: 0 | AD108: 1136.2941 | AE108: ריק במקור | AF108: ריק במקור | AG108: שווי הוגן | AH108: 0.00024927668 | AI108: =+AD108/SUM(AD:AD) -> 0.002142102 | AJ108: =+AD108/'סכום נכסים'!$B$30 -> 0.0002636739
A109: 13908 | B109: 13908 | C109: חברת החשמל לישראל בע"מ | D109: 520000472 | E109: ח.פ. | F109: חשמל אגח 35 | G109: IL0011967994 | H109: ISIN | I109: צמוד למדד המחירים לצרכן | J109: ישראל | K109: ישראל | L109: סחיר | M109: TASE | N109: אנרגיה | O109: לא | P109: ilAAA | Q109: S&P מעלות | R109: נייר ערך | S109: ILS | T109: 9.728 | U109: 50203 | V109: 0.032 | W109: 0.0257 | X109: החוב לא נחות | Y109: ריק במקור | Z109: 1783900 | AA109: 1 | AB109: 113.96 | AC109: 0 | AD109: 2032.9324 | AE109: ריק במקור | AF109: ריק במקור | AG109: שווי הוגן | AH109: 0.00036226815 | AI109: =+AD109/SUM(AD:AD) -> 0.0038324134 | AJ109: =+AD109/'סכום נכסים'!$B$30 -> 0.00047173635
A110: 13908 | B110: 13908 | C110: מזרחי טפחות חברה להנפקות בע"מ | D110: 520032046 | E110: ח.פ. | F110: מז טפ הנ אגח 67 | G110: IL0011968075 | H110: ISIN | I110: צמוד למדד המחירים לצרכן | J110: ישראל | K110: ישראל | L110: סחיר | M110: TASE | N110: בנקים | O110: לא | P110: ilAAA | Q110: S&P מעלות | R110: נייר ערך | S110: ILS | T110: 3.732 | U110: 48742 | V110: 0.0206 | W110: 0.0222 | X110: החוב לא נחות | Y110: ריק במקור | Z110: 3413707.6 | AA110: 1 | AB110: 107.55 | AC110: 0 | AD110: 3671.4425 | AE110: ריק במקור | AF110: ריק במקור | AG110: שווי הוגן | AH110: 0.0021334638 | AI110: =+AD110/SUM(AD:AD) -> 0.0069212754 | AJ110: =+AD110/'סכום נכסים'!$B$30 -> 0.00085194808
A111: 13908 | B111: 13908 | C111: איסתא בע"מ | D111: 520042763 | E111: ח.פ. | F111: איסתא אג א | G111: IL0011971285 | H111: ISIN | I111: אג"ח להמרה לא צמוד למדד המחירים לצרכן | J111: ישראל | K111: ישראל | L111: סחיר | M111: TASE | N111: מלונאות ותיירות | O111: כן | P111: NR | Q111: NR | R111: NR | S111: ILS | T111: 2.39 | U111: 46934 | V111: 0.0485 | W111: -0.0159 | X111: החוב לא נחות | Y111: ריק במקור | Z111: 588000 | AA111: 1 | AB111: 116.5 | AC111: 0 | AD111: 685.02 | AE111: ריק במקור | AF111: ריק במקור | AG111: שווי הוגן | AH111: 0.00196 | AI111: =+AD111/SUM(AD:AD) -> 0.0012913758 | AJ111: =+AD111/'סכום נכסים'!$B$30 -> 0.000158957
A112: 13908 | B112: 13908 | C112: אלון רבוע כחול ישראל בע"מ | D112: 520042847 | E112: ח.פ. | F112: אלון רבוע אגח ח | G112: IL0011972762 | H112: ISIN | I112: לא צמוד למדד המחירים לצרכן | J112: ישראל | K112: ישראל | L112: סחיר | M112: TASE | N112: השקעה ואחזקות | O112: לא | P112: ilAA- | Q112: S&P מעלות | R112: נייר ערך | S112: ILS | T112: 2.881 | U112: 47664 | V112: 0.055 | W112: 0.0461 | X112: החוב לא נחות | Y112: ריק במקור | Z112: 885959.6 | AA112: 1 | AB112: 102.7 | AC112: 0 | AD112: 909.88051 | AE112: ריק במקור | AF112: ריק במקור | AG112: שווי הוגן | AH112: 0.00073092479 | AI112: =+AD112/SUM(AD:AD) -> 0.001715275 | AJ112: =+AD112/'סכום נכסים'!$B$30 -> 0.00021113526
A113: 13908 | B113: 13908 | C113: נאוויטס פטרוליום, שותפות מוגבל | D113: 550263107 | E113: מספר שותפות | F113: נאוויטס פט אגחה | G113: IL0011979122 | H113: ISIN | I113: לא צמוד למדד המחירים לצרכן | J113: ישראל | K113: ישראל | L113: סחיר | M113: TASE | N113: חיפושי נפט וגז | O113: לא | P113: ilA- | Q113: S&P מעלות | R113: נייר ערך | S113: ILS | T113: 2.121 | U113: 47118 | V113: 0.065 | W113: 0.0481 | X113: החוב לא נחות | Y113: ריק במקור | Z113: 150000 | AA113: 1 | AB113: 103.66 | AC113: 0 | AD113: 155.49 | AE113: ריק במקור | AF113: ריק במקור | AG113: שווי הוגן | AH113: 0.0003 | AI113: =+AD113/SUM(AD:AD) -> 0.00029312433 | AJ113: =+AD113/'סכום נכסים'!$B$30 -> 3.6081024e-05
A114: 13908 | B114: 13908 | C114: כלל ביטוח גיוסי הון בע"מ | D114: 513754069 | E114: ח.פ. | F114: כלל הון אגח יג | G114: IL0011979205 | H114: ISIN | I114: לא צמוד למדד המחירים לצרכן | J114: ישראל | K114: ישראל | L114: סחיר | M114: TASE | N114: ביטוח | O114: לא | P114: ilAA- | Q114: S&P מעלות | R114: נייר ערך | S114: ILS | T114: 6.918 | U114: 50252 | V114: 0.0531 | W114: 0.0446 | X114: החוב לא נחות | Y114: ריק במקור | Z114: 500000 | AA114: 1 | AB114: 108.58 | AC114: 0 | AD114: 542.9 | AE114: ריק במקור | AF114: ריק במקור | AG114: שווי הוגן | AH114: 0.00039265553 | AI114: =+AD114/SUM(AD:AD) -> 0.0010234562 | AJ114: =+AD114/'סכום נכסים'!$B$30 -> 0.00012597844
A115: 13908 | B115: 13908 | C115: ע.י. נופר אנרג'י בע"מ | D115: 514599943 | E115: ח.פ. | F115: נופר אנרג אגח ג | G115: IL0011980435 | H115: ISIN | I115: לא צמוד למדד המחירים לצרכן | J115: ישראל | K115: ישראל | L115: סחיר | M115: TASE | N115: אנרגיה מתחדשת | O115: לא | P115: A3.il | Q115: מידרוג Moodys | R115: נייר ערך | S115: ILS | T115: 2.841 | U115: 47664 | V115: 0.0695 | W115: 0.0557 | X115: החוב לא נחות | Y115: ריק במקור | Z115: 1406950 | AA115: 1 | AB115: 104.11 | AC115: 0 | AD115: 1464.7756 | AE115: ריק במקור | AF115: ריק במקור | AG115: שווי הוגן | AH115: 0.0017519972 | AI115: =+AD115/SUM(AD:AD) -> 0.002761344 | AJ115: =+AD115/'סכום נכסים'!$B$30 -> 0.00033989714
... A226: 13908 | B226: 13908 | C226: מזרחי טפחות חברה להנפקות בע"מ | D226: 520032046 | E226: ח.פ. | F226: מז טפ הנ אגח 62 | G226: IL0023104982 | H226: ISIN | I226: צמוד למדד המחירים לצרכן | J226: ישראל | K226: ישראל | L226: סחיר | M226: TASE | N226: בנקים | O226: לא | P226: ilAAA | Q226: S&P מעלות | R226: נייר ערך | S226: ILS | T226: 2.802 | U226: 47048 | V226: 0.001 | W226: 0.0219 | X226: החוב לא נחות | Y226: ריק במקור | Z226: 1111218 | AA226: 1 | AB226: 108.71 | AC226: 0 | AD226: 1208.0051 | AE226: ריק במקור | AF226: ריק במקור | AG226: שווי הוגן | AH226: 0.00032904406 | AI226: =+AD226/SUM(AD:AD) -> 0.0022772891 | AJ226: =+AD226/'סכום נכסים'!$B$30 -> 0.00028031424
A227: 13908 | B227: 13908 | C227: מזרחי טפחות חברה להנפקות בע"מ | D227: 520032046 | E227: ח.פ. | F227: מז טפ הנ אגח 63 | G227: IL0023105484 | H227: ISIN | I227: לא צמוד למדד המחירים לצרכן | J227: ישראל | K227: ישראל | L227: סחיר | M227: TASE | N227: בנקים | O227: לא | P227: ilAAA | Q227: S&P מעלות | R227: נייר ערך | S227: ILS | T227: 2.589 | U227: 47951 | V227: 0.0274 | W227: 0.0412 | X227: החוב לא נחות | Y227: ריק במקור | Z227: 5368077 | AA227: 1 | AB227: 98.49 | AC227: 0 | AD227: 5287.019 | AE227: ריק במקור | AF227: ריק במקור | AG227: שווי הוגן | AH227: 0.0016971531 | AI227: 0.009966904 | AJ227: 0.0012268381
A228: 13908 | B228: 13908 | C228: מזרחי טפחות חברה להנפקות בע"מ | D228: 520032046 | E228: ח.פ. | F228: מז טפ הנ אגח 64 | G228: IL0023105559 | H228: ISIN | I228: צמוד למדד המחירים לצרכן | J228: ישראל | K228: ישראל | L228: סחיר | M228: TASE | N228: בנקים | O228: לא | P228: ilAAA | Q228: S&P מעלות | R228: נייר ערך | S228: ILS | T228: 2.712 | U228: 47951 | V228: 0.001 | W228: 0.0222 | X228: החוב לא נחות | Y228: ריק במקור | Z228: 7054425 | AA228: 1 | AB228: 107.55 | AC228: 0 | AD228: 7587.0341 | AE228: ריק במקור | AF228: ריק במקור | AG228: שווי הוגן | AH228: 0.003161809 | AI228: 0.014302812 | AJ228: 0.0017605503
A229: 13908 | B229: 13908 | C229: אשטרום נכסים בע"מ | D229: 520036617 | E229: ח.פ. | F229: אשטרום נכ אגח13 | G229: IL0025103032 | H229: ISIN | I229: צמוד למדד המחירים לצרכן | J229: ישראל | K229: ישראל | L229: סחיר | M229: TASE | N229: נדל"ן מניב בישראל | O229: לא | P229: ilA | Q229: S&P מעלות | R229: נייר ערך | S229: ILS | T229: 3.755 | U229: 47848 | V229: 0.013 | W229: 0.0292 | X229: החוב לא נחות | Y229: ריק במקור | Z229: 180000 | AA229: 1 | AB229: 108.39 | AC229: 0 | AD229: 195.102 | AE229: ריק במקור | AF229: ריק במקור | AG229: שווי הוגן | AH229: 0.00048192771 | AI229: 0.00036779949 | AJ229: 4.527288e-05
A230: 13908 | B230: 13908 | C230: מליסרון בע"מ | D230: 520037789 | E230: ח.פ. | F230: מליסרון אגח טז | G230: IL0032302650 | H230: ISIN | I230: צמוד למדד המחירים לצרכן | J230: ישראל | K230: ישראל | L230: סחיר | M230: TASE | N230: נדל"ן מניב בישראל | O230: לא | P230: ilAA | Q230: S&P מעלות | R230: נייר ערך | S230: ILS | T230: 1.211 | U230: 46478 | V230: 0.0235 | W230: 0.0288 | X230: החוב לא נחות | Y230: ריק במקור | Z230: 659770.08 | AA230: 1 | AB230: 119.34 | AC230: 0 | AD230: 787.36961 | AE230: ריק במקור | AF230: ריק במקור | AG230: שווי הוגן | AH230: 0.00072824165 | AI230: 0.0014843217 | AJ230: 0.00018270694
A231: 13908 | B231: 13908 | C231: מליסרון בע"מ | D231: 520037789 | E231: ח.פ. | F231: מליסרון אגח יז | G231: IL0032302734 | H231: ISIN | I231: צמוד למדד המחירים לצרכן | J231: ישראל | K231: ישראל | L231: סחיר | M231: TASE | N231: נדל"ן מניב בישראל | O231: לא | P231: ilAA | Q231: S&P מעלות | R231: נייר ערך | S231: ILS | T231: 3.113 | U231: 48214 | V231: 0.0225 | W231: 0.0252 | X231: החוב לא נחות | Y231: ריק במקור | Z231: 4577453.4 | AA231: 1 | AB231: 118.56 | AC231: 64.7912 | AD231: 5491.82 | AE231: ריק במקור | AF231: ריק במקור | AG231: שווי הוגן | AH231: 0.0028544988 | AI231: 0.010352988 | AJ231: 0.0012743616
A232: 13908 | B232: 13908 | C232: מליסרון בע"מ | D232: 520037789 | E232: ח.פ. | F232: מליסרון אגח יט | G232: IL0032303989 | H232: ISIN | I232: צמוד למדד המחירים לצרכן | J232: ישראל | K232: ישראל | L232: סחיר | M232: TASE | N232: נדל"ן מניב בישראל | O232: לא | P232: ilAA | Q232: S&P מעלות | R232: נייר ערך | S232: ILS | T232: 3.307 | U232: 47300 | V232: 0.0143 | W232: 0.0246 | X232: החוב לא נחות | Y232: ריק במקור | Z232: 1140163.9 | AA232: 1 | AB232: 114.1 | AC232: 10.10296 | AD232: 1311.0299 | AE232: ריק במקור | AF232: ריק במקור | AG232: שווי הוגן | AH232: 0.00059798328 | AI232: 0.0024715079 | AJ232: 0.00030422087
A233: 13908 | B233: 13908 | C233: מליסרון בע"מ | D233: 520037789 | E233: ח.פ. | F233: מליסרון אגח כ | G233: IL0032304227 | H233: ISIN | I233: צמוד למדד המחירים לצרכן | J233: ישראל | K233: ישראל | L233: סחיר | M233: TASE | N233: נדל"ן מניב בישראל | O233: לא | P233: ilAA | Q233: S&P מעלות | R233: נייר ערך | S233: ILS | T233: 4.252 | U233: 47665 | V233: 0.0025 | W233: 0.0249 | X233: החוב לא נחות | Y233: ריק במקור | Z233: 710938.69 | AA233: 1 | AB233: 105.36 | AC233: 1.88733 | AD233: 750.93233 | AE233: ריק במקור | AF233: ריק במקור | AG233: שווי הוגן | AH233: 0.00053815262 | AI233: 0.0014156314 | AJ233: 0.00017425177
A234: 13908 | B234: 13908 | C234: ארי נדל"ן (ארנה) השקעות בע"מ | D234: 520038332 | E234: ח.פ. | F234: ארי נדלן אגח א | G234: IL0036601560 | H234: ISIN | I234: צמוד למדד המחירים לצרכן | J234: ישראל | K234: ישראל | L234: סחיר | M234: TASE | N234: נדל"ן מניב בישראל | O234: לא | P234: NR | Q234: NR | R234: NR | S234: ILS | T234: 1.208 | U234: 46478 | V234: 0.019 | W234: 0.0324 | X234: החוב לא נחות | Y234: ריק במקור | Z234: 96858.64 | AA234: 1 | AB234: 111.97 | AC234: 0 | AD234: 108.45262 | AE234: ריק במקור | AF234: ריק במקור | AG234: שווי הוגן | AH234: 0.0001442045 | AI234: 0.0002044511 | AJ234: 2.5166131e-05
A235: 13908 | B235: 13908 | C235: אלוני-חץ נכסים והשקעות בע"מ | D235: 520038506 | E235: ח.פ. | F235: אלוני חץ אגח ט | G235: IL0039003541 | H235: ISIN | I235: לא צמוד למדד המחירים לצרכן | J235: ישראל | K235: ישראל | L235: סחיר | M235: TASE | N235: נדל"ן מניב בישראל | O235: לא | P235: ilAA- | Q235: S&P מעלות | R235: נייר ערך | S235: ILS | T235: 0.64 | U235: 46446 | V235: 0.0385 | W235: 0.0463 | X235: החוב לא נחות | Y235: ריק במקור | Z235: 27263.5 | AA235: 1 | AB235: 102.73 | AC235: 0 | AD235: 28.00779 | AE235: ריק במקור | AF235: ריק במקור | AG235: שווי הוגן | AH235: 8.7459106e-05 | AI235: 5.2799309e-05 | AJ235: 6.4991302e-06
A236: 13908 | B236: 13908 | C236: אלוני-חץ נכסים והשקעות בע"מ | D236: 520038506 | E236: ח.פ. | F236: אלוני חץ אגח יב | G236: IL0039004952 | H236: ISIN | I236: לא צמוד למדד המחירים לצרכן | J236: ישראל | K236: ישראל | L236: סחיר | M236: TASE | N236: נדל"ן מניב בישראל | O236: לא | P236: ilAA- | Q236: S&P מעלות | R236: נייר ערך | S236: ILS | T236: 3.209 | U236: 47907 | V236: 0.0241 | W236: 0.0448 | X236: החוב לא נחות | Y236: ריק במקור | Z236: 205000 | AA236: 1 | AB236: 95.65 | AC236: 0 | AD236: 196.0825 | AE236: ריק במקור | AF236: ריק במקור | AG236: שווי הוגן | AH236: 9.975947e-05 | AI236: 0.00036964789 | AJ236: 4.5500402e-05
A237: 13908 | B237: 13908 | C237: ישראל קנדה (ט.ר) בע"מ | D237: 520039298 | E237: ח.פ. | F237: ישראל קנדה אגחז | G237: IL0043402127 | H237: ISIN | I237: לא צמוד למדד המחירים לצרכן | J237: ישראל | K237: ישראל | L237: סחיר | M237: TASE | N237: בנייה | O237: לא | P237: ilA- | Q237: S&P מעלות | R237: נייר ערך | S237: ILS | T237: 0.976 | U237: 46568 | V237: 0.0395 | W237: 0.0507 | X237: החוב לא נחות | Y237: ריק במקור | Z237: 538037.5 | AA237: 1 | AB237: 99.02 | AC237: 0 | AD237: 532.76473 | AE237: ריק במקור | AF237: ריק במקור | AG237: שווי הוגן | AH237: 0.00091675632 | AI237: 0.0010043495 | AJ237: 0.00012362658
A238: 13908 | B238: 13908 | C238: מידאס השקעות בנדל"ן בע"מ | D238: 520039496 | E238: ח.פ. | F238: מידאס אגח ד | G238: IL0054402842 | H238: ISIN | I238: צמוד למדד המחירים לצרכן | J238: ישראל | K238: ישראל | L238: סחיר | M238: TASE | N238: נדל"ן מניב בישראל | O238: לא | P238: NR | Q238: NR | R238: NR | S238: ILS | T238: 0.992 | U238: 46387 | V238: 0.019 | W238: 0.0744 | X238: החוב לא נחות | Y238: ריק במקור | Z238: 262500 | AA238: 1 | AB238: 109.19 | AC238: 0 | AD238: 286.62375 | AE238: ריק במקור | AF238: ריק במקור | AG238: שווי הוגן | AH238: 0.0075033872 | AI238: 0.0005403331 | AJ238: 6.6510248e-05
...

Sheet מניות מבכ ויהש
A1: מספר קופה/קרן/ח.פ. עבור חברת ביטוח | B1: מספר מסלול | C1: שם מנפיק | D1: מספר מנפיק | E1: סוג מספר מזהה מנפיק | F1: שם נייר ערך | G1: מספר נייר ערך | H1: סוג מספר נייר ערך | I1: מאפיין עיקרי | J1: ישראל/חו"ל | K1: מדינה לפי חשיפה כלכלית | L1: סטאטוס סחירות | M1: זירת מסחר | N1: ענף מסחר | O1: בעל עניין/צד קשור | P1: מטבע פעילות | Q1: ערך נקוב (יחידות) | R1: שער חליפין | S1: שער נייר הערך | T1: סכום לקבל (במטבע הפעילות) | U1: שווי הוגן (באלפי ש"ח) | V1: שיעור מערך נקוב מונפק | W1: שיעור מנכסי אפיק ההשקעה | X1: שיעור מסך נכסי ההשקעה
A2: 13908 | B2: 13908 | C2: להב אל.אר רילאסטייט בע"מ | D2: 520034257 | E2: ח.פ. | F2: להב | G2: IL0001360101 | H2: ISIN | I2: מניות | J2: ישראל | K2: ישראל | L2: סחיר | M2: TASE | N2: השקעה ואחזקות | O2: כן | P2: ILS | Q2: 1600000 | R2: 1 | S2: 840 | T2: 0 | U2: 13440 | V2: 0.0059301714 | W2: 0.016172781 | X2: 0.0031187148
A3: 13908 | B3: 13908 | C3: וואן טכנולוגיות תוכנה בע"מ | D3: 520034695 | E3: ח.פ. | F3: וואן טכנולוגיות | G3: IL0001610182 | H3: ISIN | I3: מניות | J3: ישראל | K3: ישראל | L3: סחיר | M3: TASE | N3: שירותי מידע | O3: לא | P3: ILS | Q3: 42987 | R3: 1 | S3: 8801 | T3: 0 | U3: 3783.2859 | V3: 0.00058378623 | W3: 0.0045525486 | X3: 0.00087790102
A4: 13908 | B4: 13908 | C4: כלל החזקות עסקי ביטוח בע"מ | D4: 520036120 | E4: ח.פ. | F4: כלל עסקי ביטוח | G4: IL0002240146 | H4: ISIN | I4: מניות | J4: ישראל | K4: ישראל | L4: סחיר | M4: TASE | N4: ביטוח | O4: לא | P4: ILS | Q4: 127580 | R4: 1 | S4: 20570 | T4: 0 | U4: 26243.206 | V4: 0.0015938506 | W4: 0.031579287 | X4: 0.0060896634
A5: 13908 | B5: 13908 | C5: מבנה נדל"ן (כ.ד) בע"מ | D5: 520024126 | E5: ח.פ. | F5: מבנה | G5: IL0002260193 | H5: ISIN | I5: מניות | J5: ישראל | K5: ישראל | L5: סחיר | M5: TASE | N5: נדל"ן מניב בישראל | O5: לא | P5: ILS | Q5: 386595 | R5: 1 | S5: 1559 | T5: 0 | U5: 6027.0161 | V5: 0.00053424328 | W5: 0.0072525007 | X5: 0.0013985524
A6: 13908 | B6: 13908 | C6: בזק החברה הישראלית לתקשורת בע" | D6: 520031931 | E6: ח.פ. | F6: בזק | G6: IL0002300114 | H6: ISIN | I6: מניות | J6: ישראל | K6: ישראל | L6: סחיר | M6: TASE | N6: תקשורת ומדיה | O6: לא | P6: ILS | Q6: 2558142 | R6: 1 | S6: 709.9 | T6: 0 | U6: 18160.25 | V6: 0.00092193024 | W6: 0.021852808 | X6: 0.0042140358
A7: 13908 | B7: 13908 | C7: ישראמקו נגב 2 שותפות מוגבלת | D7: 550010003 | E7: מספר שותפות | F7: ישראמקו יהש | G7: IL0002320179 | H7: ISIN | I7: יחידות השתתפות | J7: ישראל | K7: ישראל | L7: סחיר | M7: TASE | N7: חיפושי נפט וגז | O7: לא | P7: ILS | Q7: 667292 | R7: 1 | S7: 245.5 | T7: 0 | U7: 1638.2019 | V7: 0.00025666876 | W7: 0.0019713006 | X7: 0.00038014021
A8: 13908 | B8: 13908 | C8: פורמולה מערכות (1985)בע"מ | D8: 520036690 | E8: ח.פ. | F8: פורמולה מערכות | G8: IL0002560162 | H8: ISIN | I8: מניות | J8: ישראל | K8: ישראל | L8: סחיר | M8: TASE | N8: שירותי מידע | O8: לא | P8: ILS | Q8: 3100 | R8: 1 | S8: 53730 | T8: 5.084 | U8: 1670.714 | V8: 0.0002021827 | W8: 0.0020104235 | X8: 0.00038768456
A9: 13908 | B9: 13908 | C9: אורביט טכנולוג'יס בע"מ | D9: 520036153 | E9: ח.פ. | F9: אורביט | G9: IL0002650179 | H9: ISIN | I9: מניות | J9: ישראל | K9: ישראל | L9: סחיר | M9: TASE | N9: ביטחוניות | O9: כן | P9: ILS | Q9: 70163 | R9: 1 | S9: 4134 | T9: 0 | U9: 2900.5384 | V9: 0.0027610203 | W9: 0.0034903104 | X9: 0.00067306192
A10: 13908 | B10: 13908 | C10: נייס בע"מ | D10: 520036872 | E10: ח.פ. | F10: נייס | G10: IL0002730112 | H10: ISIN | I10: מניות | J10: ישראל | K10: ישראל | L10: סחיר | M10: TASE | N10: תוכנה ואינטרנט | O10: לא | P10: ILS | Q10: 16810 | R10: 1 | S10: 35710 | T10: 0 | U10: 6002.851 | V10: 0.00027225548 | W10: 0.0072234221 | X10: 0.001392945
A11: 13908 | B11: 13908 | C11: איי.סי.אל גרופ בע"מ | D11: 520027830 | E11: ח.פ. | F11: איי.סי.אל | G11: IL0002810146 | H11: ISIN | I11: מניות | J11: ישראל | K11: ישראל | L11: סחיר | M11: TASE | N11: כימיה, גומי ופלסטיק | O11: לא | P11: ILS | Q11: 501190 | R11: 1 | S11: 1830 | T11: 0 | U11: 9171.777 | V11: 0.00038831687 | W11: 0.011036692 | X11: 0.0021282855
A12: 13908 | B12: 13908 | C12: קבוצת סקופ מתכות בע"מ | D12: 520037425 | E12: ח.פ. | F12: סקופ חסום | G12: IL0002880198 | H12: ISIN | I12: מניות | J12: ישראל | K12: ישראל | L12: חסום | M12: TASE | N12: מסחר | O12: לא | P12: ILS | Q12: 20000 | R12: 1 | S12: 17375.574 | T12: 0 | U12: 3475.1148 | V12: 0.0015114569 | W12: 0.0041817165 | X12: 0.00080639077
A13: 13908 | B13: 13908 | C13: מליסרון בע"מ | D13: 520037789 | E13: ח.פ. | F13: מליסרון | G13: IL0003230146 | H13: ISIN | I13: מניות | J13: ישראל | K13: ישראל | L13: סחיר | M13: TASE | N13: נדל"ן מניב בישראל | O13: לא | P13: ILS | Q13: 19576 | R13: 1 | S13: 41330 | T13: 0 | U13: 8090.7608 | V13: 0.00041074307 | W13: 0.0097358706 | X13: 0.0018774387
... A129: 13908 | B129: 13908 | C129: ITHACA ENERGY PLC | D129: 66296534 | E129: LEI | F129: ITHACA ENERGY PLC | G129: GB00BPJHV584 | H129: ISIN | I129: מניות | J129: חו"ל | K129: ישראל | L129: סחיר | M129: LSE | N129: Energy Equipment & Services | O129: לא | P129: GBP | Q129: 770255 | R129: 4.29 | S129: 165.8 | T129: 0 | U129: 5478.6852 | V129: 0.0004657676 | W129: 0.0065926767 | X129: 0.0012713137
AZ10000: 1

Sheet קרנות סל
A1: מספר קופה/קרן/ח.פ. עבור חברת ביטוח | B1: מספר מסלול | C1: שם מנפיק | D1: מספר מנפיק | E1: סוג מספר מזהה מנפיק | F1: שם נייר ערך | G1: מספר נייר ערך | H1: סוג מספר נייר ערך | I1: מאפיין עיקרי | J1: ישראל/חו"ל | K1: מדינה לפי חשיפה כלכלית | L1: זירת מסחר | M1: סיווג הקרן | N1: בעל עניין/צד קשור | O1: מטבע פעילות | P1: ערך נקוב (יחידות) | Q1: שער חליפין | R1: שער נייר הערך | S1: סכום לקבל (במטבע הפעילות) | T1: שווי הוגן (באלפי ש"ח) | U1: שיעור מערך נקוב מונפק | V1: שיעור מנכסי אפיק ההשקעה | W1: שיעור מסך נכסי ההשקעה
A2: 13908 | B2: 13908 | C2: מיטב קרנות נאמנות בע"מ | D2: 513534974 | E2: ח.פ. | F2: תכ.תא125 | G2: IL0011437188 | H2: ISIN | I2: עוקב אחר מדדי מניות בישראל | J2: ישראל | K2: ישראל | L2: TASE | M2: Large & Mid Cap מניות בארץ - מניות לפי שווי שוק-מניות | N2: לא | O2: ILS | P2: 1880000 | Q2: 1 | R2: 3583 | S2: 0 | T2: 67360.4 | U2: 0.0042841713 | V2: 0.19453959 | W2: 0.015630795
A3: 13908 | B3: 13908 | C3: מיטב קרנות נאמנות בע"מ | D3: 513534974 | E3: ח.פ. | F3: תכ.תלבונד60 | G3: IL0011451015 | H3: ISIN | I3: עוקב אחר מדדים אחרים בישראל | J3: ישראל | K3: ישראל | L3: TASE | M3: 60 אג"ח בארץ - חברות והמרה-תל בונד צמוד מדד-תל בונד | N3: לא | O3: ILS | P3: 15040200 | Q3: 1 | R3: 396.66 | S3: 0 | T3: 59658.457 | U3: 0.011045029 | V3: 0.17229607 | W3: 0.01384358
A4: 13908 | B4: 13908 | C4: קסם קרנות נאמנות בע"מ | D4: 510938608 | E4: ח.פ. | F4: קסם.תלבונד 20 צ | G4: IL0011459604 | H4: ISIN | I4: עוקב אחר מדדים אחרים בישראל | J4: ישראל | K4: ישראל | L4: TASE | M4: 20 אג"ח בארץ - חברות והמרה-תל בונד צמוד מדד-תל בונד | N4: לא | O4: ILS | P4: 3000 | Q4: 1 | R4: 4035.8 | S4: 0 | T4: 121.074 | U4: 5.7499699e-05 | V4: 0.00034966667 | W4: 2.8094887e-05
A5: 13908 | B5: 13908 | C5: קסם קרנות נאמנות בע"מ | D5: 510938608 | E5: ח.פ. | F5: STOX600.קסם | G5: IL0011462087 | H5: ISIN | I5: עוקב אחר מדדי מניות בחו"ל | J5: ישראל | K5: אירופה | L5: TASE | M5: מניות בחו"ל - מניות גיאוגרפי - חשופת מט"ח-אירופה - מדד אחר | N5: לא | O5: ILS | P5: 103320 | Q5: 1 | R5: 52500 | S5: 0 | T5: 54243 | U5: 0.052414773 | V5: 0.156656 | W5: 0.012586938
A6: 13908 | B6: 13908 | C6: קסם קרנות נאמנות בע"מ | D6: 510938608 | E6: ח.פ. | F6: קסם.תלבונד 60 צ | G6: IL0011462327 | H6: ISIN | I6: עוקב אחר מדדים אחרים בישראל | J6: ישראל | K6: ישראל | L6: TASE | M6: אג"ח בארץ - חברות והמרה-תל בונד צמוד מדד-תל בונד צמודות | N6: לא | O6: ILS | P6: 1559524 | Q6: 1 | R6: 3947.29 | S6: 0 | T6: 61558.935 | U6: 0.021654101 | V6: 0.17778472 | W6: 0.014284581
A7: 13908 | B7: 13908 | C7: אי.בי.אי קרנות נאמנות בעמ | D7: 513765339 | E7: ח.פ. | F7: IBI.תלבונד 60צד | G7: IL0011480063 | H7: ISIN | I7: עוקב אחר מדדים אחרים בישראל | J7: ישראל | K7: ישראל | L7: TASE | M7: 60 אג"ח בארץ - חברות והמרה-תל בונד צמוד מדד-תל בונד | N7: לא | O7: ILS | P7: 5495390 | Q7: 1 | R7: 397.01 | S7: 0 | T7: 21817.248 | U7: 0.0039974871 | V7: 0.063009105 | W7: 0.005062632
A8: 13908 | B8: 13908 | C8: אי.בי.אי קרנות נאמנות בעמ | D8: 513765339 | E8: ח.פ. | F8: IBI.תא 125 | G8: IL0011488082 | H8: ISIN | I8: עוקב אחר מדדי מניות בישראל | J8: ישראל | K8: ישראל | L8: TASE | M8: Large & Mid Cap מניות בארץ - מניות לפי שווי שוק-מניות | N8: לא | O8: ILS | P8: 160000 | Q8: 1 | R8: 3579 | S8: 0 | T8: 5726.4 | U8: 0.00039873037 | V8: 0.016538078 | W8: 0.0013287953
A9: 13908 | B9: 13908 | C9: הראל קרנות נאמנות בע"מ | D9: 511776783 | E9: ח.פ. | F9: SP500.הרל | G9: IL0011490203 | H9: ISIN | I9: עוקב אחר מדדי מניות בחו"ל | J9: ישראל | K9: ארה"ב | L9: TASE | M9: S&P 500 - מניות בחו"ל - מניות גיאוגרפי - מנוטרלת מט"ח-ארה"ב | N9: לא | O9: ILS | P9: 17250 | Q9: 1 | R9: 2567 | S9: 0 | T9: 442.8075 | U9: 4.5540018e-05 | V9: 0.0012788462 | W9: 0.00010275226
A10: 13908 | B10: 13908 | C10: מגדל קרנות נאמנות בע"מ | D10: 511303661 | E10: ח.פ. | F10: MTF.תא125 | G10: IL0011502833 | H10: ISIN | I10: עוקב אחר מדדי מניות בישראל | J10: ישראל | K10: ישראל | L10: TASE | M10: Large & Mid Cap מניות בארץ - מניות לפי שווי שוק-מניות | N10: לא | O10: ILS | P10: 5000 | Q10: 1 | R10: 5643 | S10: 0 | T10: 282.15 | U10: 5.2631579e-05 | V10: 0.00081486075 | W10: 6.5472127e-05
A11: 13908 | B11: 13908 | C11: מגדל קרנות נאמנות בע"מ | D11: 511303661 | E11: ח.פ. | F11: SP500.MTF | G11: IL0011503336 | H11: ISIN | I11: עוקב אחר מדדי מניות בחו"ל | J11: ישראל | K11: ארה"ב | L11: TASE | M11: S&P 500 - מניות בחו"ל - מניות גיאוגרפי - חשופת מט"ח-ארה"ב | N11: לא | O11: ILS | P11: 12400 | Q11: 1 | R11: 9445 | S11: 0 | T11: 1171.18 | U11: 0.00014203895 | V11: 0.0033824158 | W11: 0.00027176908
A12: 13908 | B12: 13908 | C12: הראל קרנות נאמנות בע"מ | D12: 511776783 | E12: ח.פ. | F12: הרל.תלבד- 60 צמ | G12: IL0011504730 | H12: ISIN | I12: עוקב אחר מדדים אחרים בישראל | J12: ישראל | K12: ישראל | L12: TASE | M12: אג"ח בארץ - חברות והמרה-תל בונד צמוד מדד-תל בונד צמודות | N12: לא | O12: ILS | P12: 5205892 | Q12: 1 | R12: 395.49 | S12: 0 | T12: 20588.782 | U12: 0.016850115 | V12: 0.059461246 | W12: 0.00477757
A13: 13908 | B13: 13908 | C13: קסם קרנות נאמנות בע"מ | D13: 510938608 | E13: ח.פ. | F13: קסם.תלבונד ש 50 | G13: IL0011507626 | H13: ISIN | I13: עוקב אחר מדדים אחרים בישראל | J13: ישראל | K13: ישראל | L13: TASE | M13: אג"ח בארץ - חברות והמרה-תל בונד שקלי-תל בונד- שקלי | N13: לא | O13: ILS | P13: 714515 | Q13: 1 | R13: 4341.57 | S13: 0 | T13: 31021.169 | U13: 0.018313036 | V13: 0.089590406 | W13: 0.0071983764
... A16: 13908 | B16: 13908 | C16: Ishares iBoxx $ Investment | D16: 78005 | E16: LEI | F16: ISHARES IBOXX H/Y CORP BOND | G16: US4642885135 | H16: ISIN | I16: עוקב אחר מדדים אחרים בחו"ל | J16: חו"ל | K16: ארה"ב | L16: NYSE | M16: Bond/Fixed Income Funds | N16: לא | O16: USD | P16: 42400 | Q16: 3.19 | R16: 8063 | S16: 0 | T16: 10905.691 | U16: 0.00017214779 | V16: 0.031496083 | W16: 0.0025306355
AZ10000: 1

Sheet קרנות נאמנות
A1: מספר קופה/קרן/ח.פ. עבור חברת ביטוח | B1: מספר מסלול | C1: שם מנפיק | D1: מספר מנפיק | E1: סוג מספר מזהה מנפיק | F1: שם נייר ערך | G1: מספר נייר ערך | H1: סוג מספר נייר ערך | I1: מאפיין עיקרי | J1: ישראל/חו"ל | K1: מדינה לפי חשיפה כלכלית | L1: סטאטוס סחירות | M1: זירת מסחר | N1: סיווג הקרן | O1: בעל עניין/צד קשור | P1: מטבע פעילות | Q1: ערך נקוב (יחידות) | R1: שער חליפין | S1: שער נייר הערך | T1: שווי הוגן (באלפי ש"ח) | U1: שיעור מערך נקוב מונפק | V1: שיעור מנכסי אפיק ההשקעה | W1: שיעור מסך נכסי ההשקעה
A2: 13908 | B2: 13908 | C2: מיטב קרנות נאמנות בע"מ | D2: 513534974 | E2: ח.פ. | F2: SP 500 תכלית | G2: IL0051139983 | H2: ISIN | I2: מניות | J2: ישראל | K2: ארה"ב | L2: סחיר | M2: TASE | N2: S&P 500 - מניות בחו"ל - מניות גיאוגרפי - חשופת מט"ח-ארה"ב | O2: לא | P2: ILS | Q2: 16874000 | R2: 1 | S2: 780.91 | T2: 131770.75 | U2: 0.01277209 | V2: 0.20268723 | W2: 0.030577039
A3: 13908 | B3: 13908 | C3: מיטב קרנות נאמנות בע"מ | D3: 513534974 | E3: ח.פ. | F3: תכלית ת"א 125 | G3: IL0051146574 | H3: ISIN | I3: מניות | J3: ישראל | K3: ישראל | L3: סחיר | M3: TASE | N3: Large & Mid Cap מניות בארץ - מניות לפי שווי שוק-מניות | O3: לא | P3: ILS | Q3: 20431000 | R3: 1 | S3: 323.18 | T3: 66028.906 | U3: 0.011282533 | V3: 0.10156439 | W3: 0.015321825
A4: 13908 | B4: 13908 | C4: מיטב קרנות נאמנות בע"מ | D4: 513534974 | E4: ח.פ. | F4: תכ.TTFתלבונד20 | G4: IL0051154727 | H4: ISIN | I4: אג"ח קונצרני | J4: ישראל | K4: ישראל | L4: סחיר | M4: TASE | N4: 20 אג"ח בארץ - חברות והמרה-תל בונד צמוד מדד-תל בונד | O4: לא | P4: ILS | Q4: 43850136 | R4: 1 | S4: 110.8 | T4: 48585.951 | U4: 0.24145351 | V4: 0.074733973 | W4: 0.011274235
A5: 13908 | B5: 13908 | C5: קסם קרנות נאמנות בע"מ | D5: 510938608 | E5: ח.פ. | F5: קסם תל בונד 20 | G5: IL0051155898 | H5: ISIN | I5: אג"ח קונצרני | J5: ישראל | K5: ישראל | L5: סחיר | M5: TASE | N5: 20 אג"ח בארץ - חברות והמרה-תל בונד צמוד מדד-תל בונד | O5: לא | P5: ILS | Q5: 19016000 | R5: 1 | S5: 151.94 | T5: 28892.91 | U5: 0.057663026 | V5: 0.044442518 | W5: 0.00670452
A6: 13908 | B6: 13908 | C6: הראל קרנות נאמנות בע"מ | D6: 511776783 | E6: ח.פ. | F6: הרל.תלבנד 20 צמ | G6: IL0051172703 | H6: ISIN | I6: אג"ח קונצרני | J6: ישראל | K6: ישראל | L6: סחיר | M6: TASE | N6: אג"ח בארץ - חברות והמרה-תל בונד צמוד מדד-תל בונד צמודות | O6: לא | P6: ILS | Q6: 34768000 | R6: 1 | S6: 147.73 | T6: 51362.766 | U6: 0.067512144 | V6: 0.079005217 | W6: 0.011918588
A7: 13908 | B7: 13908 | C7: מגדל קרנות נאמנות בע"מ | D7: 511303661 | E7: ח.פ. | F7: S&P 500 מח MTF | G7: IL0051226277 | H7: ISIN | I7: מניות | J7: ישראל | K7: ארה"ב | L7: סחיר | M7: TASE | N7: S&P 500 - מניות בחו"ל - מניות גיאוגרפי - חשופת מט"ח-ארה"ב | O7: לא | P7: ILS | Q7: 31459071 | R7: 1 | S7: 314.13 | T7: 98822.38 | U7: 0.014262216 | V7: 0.15200668 | W7: 0.02293146
A8: 13908 | B8: 13908 | C8: קסם קרנות נאמנות בע"מ | D8: 510938608 | E8: ח.פ. | F8: S&P 500 קסם | G8: IL0051244825 | H8: ISIN | I8: מניות | J8: ישראל | K8: ארה"ב | L8: סחיר | M8: TASE | N8: S&P 500 - מניות בחו"ל - מניות גיאוגרפי - חשופת מט"ח-ארה"ב | O8: לא | P8: ILS | Q8: 23113000 | R8: 1 | S8: 298.39 | T8: 68966.881 | U8: 0.0050583356 | V8: 0.10608353 | W8: 0.016003574
A9: 13908 | B9: 13908 | C9: אי.בי.אי קרנות נאמנות בעמ | D9: 513765339 | E9: ח.פ. | F9: S&P 500י.IBI | G9: IL0051274699 | H9: ISIN | I9: מניות | J9: ישראל | K9: ארה"ב | L9: סחיר | M9: TASE | N9: S&P 500 - מניות בחו"ל - מניות גיאוגרפי - חשופת מט"ח-ארה"ב | O9: לא | P9: ILS | Q9: 17528160 | R9: 1 | S9: 246.63 | T9: 43229.701 | U9: 0.011680811 | V9: 0.066495093 | W9: 0.010031333
A10: 13908 | B10: 13908 | C10: אי.בי.אי קרנות נאמנות בעמ | D10: 513765339 | E10: ח.פ. | F10: NASDAQ 100י.IBI | G10: IL0051277668 | H10: ISIN | I10: מניות | J10: ישראל | K10: ארה"ב | L10: סחיר | M10: TASE | N10: NASDAQ 100 - מניות בחו"ל - מניות גיאוגרפי - מנוטרלת מט"ח-ארה"ב | O10: לא | P10: ILS | Q10: 13119174 | R10: 1 | S10: 310.25 | T10: 40702.237 | U10: 0.015662513 | V10: 0.062607397 | W10: 0.0094448416
A11: 13908 | B11: 13908 | C11: הראל קרנות נאמנות בע"מ | D11: 511776783 | E11: ח.פ. | F11: NASDAQ 100 הראל | G11: IL0051292832 | H11: ISIN | I11: מניות | J11: ישראל | K11: ארה"ב | L11: סחיר | M11: TASE | N11: מניות בחו"ל - מניות גיאוגרפי - חשופת מט"ח-ארה"ב - מדד אחר | O11: לא | P11: ILS | Q11: 13860000 | R11: 1 | S11: 325.14 | T11: 45064.404 | U11: 0.0091288374 | V11: 0.069317197 | W11: 0.01045707
A12: 13908 | B12: 13908 | C12: אי.בי.אי קרנות נאמנות בעמ | D12: 513765339 | E12: ח.פ. | F12: STOXX-E600י.IBI | G12: IL0051307523 | H12: ISIN | I12: מניות | J12: ישראל | K12: אירופה | L12: סחיר | M12: TASE | N12: STOXX EUROPE 600 - מניות בחו"ל - מניות גיאוגרפי - מנוטרלת מט"ח-אירופה כללי | O12: לא | P12: ILS | Q12: 15622700 | R12: 1 | S12: 164.99 | T12: 25775.893 | U12: 0.097651495 | V12: 0.039647981 | W12: 0.0059812246
A13: 13908 | B13: 13908 | C13: CIFC Global Floating Rate Cred | D13: 635400NLI1L | E13: LEI | F13: CIFC GLBL FLT RT CR-B1 USD | G13: IE0009SO3I10 | H13: ISIN | I13: אחר | J13: חו"ל | K13: גלובלי | L13: סחיר | M13: אחר | N13: Bond/Fixed Income Funds | O13: לא | P13: USD | Q13: 193.86 | R13: 3.19 | S13: 148102.3 | T13: 915.88447 | U13: 0.0050052929 | V13: 0.0014087958 | W13: 0.00021252846
AZ10000: 1

Sheet כתבי אופציה
A1: מספר קופה/קרן/ח.פ. עבור חברת ביטוח | B1: מספר מסלול | C1: שם מנפיק | D1: מספר מנפיק | E1: סוג מספר מזהה מנפיק | F1: שם נייר ערך | G1: מספר נייר ערך | H1: סוג מספר נייר ערך | I1: ישראל/חו"ל | J1: מדינה לפי חשיפה כלכלית | K1: סטאטוס סחירות | L1: זירת מסחר | M1: נכס בסיס (כתב אופציה) | N1: ענף מסחר | O1: תאריך פקיעה | P1: בעל עניין/צד קשור | Q1: מטבע פעילות | R1: שער מימוש | S1: יחס המרה | T1: ערך נקוב (יחידות) | U1: שער חליפין | V1: שער נייר הערך | W1: שווי הוגן (באלפי ש"ח) | X1: שיעור מנכסי אפיק ההשקעה | Y1: שיעור מסך נכסי ההשקעה
A2: 13908 | B2: 13908 | C2: אלומיי קפיטל בע"מ | D2: 520039868 | E2: ח.פ. | F2: אלומיי אפ 2 | G2: IL0012030826 | H2: ISIN | I2: ישראל | J2: ישראל | K2: סחיר | L2: TASE | M2: IL0010826357 | N2: אנרגיה מתחדשת | O2: 46757 | P2: לא | Q2: ILS | R2: 8000 | S2: 1 | T2: 2304 | U2: 1 | V2: 1354 | W2: 31.19616 | X2: 0.0087890458 | Y2: 7.2389827e-06
A3: 13908 | B3: 13908 | C3: מיטב טרייד השקעות בע"מ | D3: 516854239 | E3: ח.פ. | F3: מיטב טרייד אפ 1 | G3: IL0012031998 | H3: ISIN | I3: ישראל | J3: ישראל | K3: סחיר | L3: TASE | M3: IL0012031816 | N3: שירותים פיננסיים | O3: 46770 | P3: כן | Q3: ILS | R3: 690.946 | S3: 1 | T3: 192000 | U3: 1 | V3: 1495 | W3: 2870.4 | X3: 0.80869174 | Y3: 0.00066606838
A4: 13908 | B4: 13908 | C4: אפי קפיטל נדל"ן בע"מ | D4: 513948216 | E4: ח.פ. | F4: אפי קפיטל אפ 1 | G4: IL0012042136 | H4: ISIN | I4: ישראל | J4: ישראל | K4: סחיר | L4: TASE | M4: IL0011814378 | N4: בנייה | O4: 46069 | P4: כן | Q4: ILS | R4: 1143.91 | S4: 1 | T4: 42500 | U4: 1 | V4: 646.1 | W4: 274.5925 | X4: 0.07736228 | Y4: 6.371843e-05
