Workbook
Name Additional_Factor: 'אפשרויות בחירה'!$C$706:$C$854
Name Amoritization: 'אפשרויות בחירה'!$C$544:$C$548
Name Capsule: 'אפשרויות בחירה'!$C$934:$C$936
Name Company_Name: 'File Name Info'!$A$34:$A$130
Name Company_Name_ID: 'File Name Info'!$A$34:$B$130
Name Consortium: 'אפשרויות בחירה'!$C$512:$C$513
Name Country_list: 'אפשרויות בחירה'!$C$4:$C$85
Name Country_list_funds: 'אפשרויות בחירה'!$C$4:$C$103
Name CSA: 'אפשרויות בחירה'!$C$693:$C$694
Name Delivery: 'אפשרויות בחירה'!$C$670:$C$671
Name Dependence_Independence: 'אפשרויות בחירה'!$C$658:$C$659
Name Duration_Underlying_Interest_Rate: 'אפשרויות בחירה'!$C$685:$C$692
Name File_Type: 'File Name Info'!$A$10:$A$12
Name Full_File_Type: 'File Name Info'!$A$11:$B$13
Name Full_Type: 'File Name Info'!$A$2:$B$8
Name Full_Type_Nostro: 'File Name Info'!$A$3:$B$6
Name Full_Year: 'File Name Info'!$A$22:$B$31
Name Fund_Strategy: 'אפשרויות בחירה'!$C$595:$C$625
Name Fund_type: 'אפשרויות בחירה'!$C$326:$C$496
Name Holding_interest: 'אפשרויות בחירה'!$C$146:$C$147
Name In_the_books: 'אפשרויות בחירה'!$C$660:$C$661
Name Industry_Sector: 'אפשרויות בחירה'!#REF!
Name Industry_sector_all: 'אפשרויות בחירה'!$C$202:$C$325
Name Industry_sectors: 'אפשרויות בחירה'!$C$202:$C$325
Name israel_abroad: 'אפשרויות בחירה'!$C$2:$C$3
Name Issuer_Number_Banks: 'אפשרויות בחירה'!$C$111:$C$113
Name Issuer_Number_Fund: 'אפשרויות בחירה'!$C$114:$C$117
Name issuer_number_loan: 'אפשרויות בחירה'!$C$118:$C$126
Name Issuer_Number_Type: 'אפשרויות בחירה'!$C$104:$C$110
Name Issuer_Number_Type_2: 'אפשרויות בחירה'!#REF!
Name Issuer_Number_Type_3: 'אפשרויות בחירה'!#REF!
Name Issuer_Number_Type_V2: 'אפשרויות בחירה'!$C$104:$C$110
Name Issuer_Type_TFunds: 'אפשרויות בחירה'!#REF!
Name Leading_factor: 'אפשרויות בחירה'!$C$697:$C$705
Name Linked_Type: 'אפשרויות בחירה'!$C$514:$C$517
Name other_investments: 'אפשרויות בחירה'!$C$1018:$C$1051
Name Penalty: 'אפשרויות בחירה'!$C$855:$C$856
Name QTR: 'File Name Info'!$A$15:$A$19
Name Rating_Agency: 'אפשרויות בחירה'!$C$188:$C$201
Name real_estate_lifestage: 'אפשרויות בחירה'!$C$638:$C$646
Name real_estate_loans: 'אפשרויות בחירה'!$C$551:$C$589
Name Real_Estate_Main_Use: 'אפשרויות בחירה'!$C$626:$C$637
Name Recourse_Nonrecourse: 'אפשרויות בחירה'!$C$542:$C$543
Name Repayment_Rights: 'אפשרויות בחירה'!$C$549:$C$550
Name Reset_frequency: 'אפשרויות בחירה'!$C$662:$C$669
Name Security_ID_Number_Type: 'אפשרויות בחירה'!#REF!
Name Security_Number_Loans: 'אפשרויות בחירה'!$C$131
Name Stock_Exchange: 'אפשרויות בחירה'!#REF!
Name Stock_Exchange_Gov_Bonds: 'אפשרויות בחירה'!$C$148:$C$181
Name Subordination_Risk: 'אפשרויות בחירה'!$C$186:$C$187
Name Tradeable_Status: 'אפשרויות בחירה'!#REF!
Name Tradeable_Status_All: 'אפשרויות בחירה'!$C$135:$C$145
Name tradeable_status_bonds: 'אפשרויות בחירה'!#REF!
Name tradeable_status_funds: 'אפשרויות בחירה'!#REF!
Name tradeable_status_stock: 'אפשרויות בחירה'!#REF!
Name Tradeable_Status_v2: 'אפשרויות בחירה'!#REF!
Name tradeable_status_warrants: 'אפשרויות בחירה'!#REF!
Name tradeable_status_warrants_v2: 'אפשרויות בחירה'!#REF!
Name Transaction: 'אפשרויות בחירה'!$C$647:$C$650
Name Type: 'File Name Info'!$A$2:$A$8

Sheet עמוד פתיחה
A1: קובץ דיווח עבור רשימת נכסים ברמת הנכס הבודד (חוזר גופים מוסדיים 2015-9-14)
A3: יש לבחור תחום: | D3: נכסי אפיק השקעה מובטח תשואה
A5: האם מדובר בקובץ לממומנה או לציבור: | D5: לציבור
A7: יש לבחור את רבעון הדיווח: | D7: Q2
A9: יש לבחור את שנת הדיווח: | D9: 2026
A11: יש לבחור את הגוף המוסדי: | D11: מור גמל ופנסיה בע"מ
A13: ח.פ. הגוף המוסדי: | D13: =IFERROR(VLOOKUP(D11,'File Name Info'!A35:B130,2,0),"תא מחושב") -> 514956465
A15: שם קובץ לשמירה | D15: =IF(D5="לממונה",CONCATENATE(D13, "_",VLOOKUP(D3,Full_Type,2,0),"_",D7,VLOOKUP(D9,Full_Year,2,0),".xlxs"),IF(D5="לציבור",CONCATENATE(D13,"_",VLOOKUP(D3,Full_Type_Nostro,2,0),"_",VLOOKUP(D5,Full_File_Type,2,0),"_",D7,VLOOKUP(D9,Full_Year,2,0),".xlsx"),"שם קובץ לשמירה")) -> 514956465_ca_p_Q226.xlsx
A17: פרטי האחראי על הדיווח בגוף המוסדי | B17: שם: | D17: לירון פיכמן
B19: מספר טלפון:
B21: כתובת מייל: | D21: Liron.Fichman@more.co.il
A23: הוראות למילוי הדיווח: | D23: יש לדווח לפי ההנחיות בחלק ג' לנספח 5.4.3.2 שבפרק 3 שבחלק 4 לשער 5 בחוזר המאוחד - "רשימת נכסים ברמת הנכס הבודד".

Sheet סכום נכסים
C1: ידווח בקבצי נכסי הנוסטרו בלבד
A2: אפיק | B2: שווי הוגן (באלפי ש"ח) | C2: עלות מופחתת (באלפי ש"ח) | D2: השיטה שיושמה בדוח הכספי | E2: שיעור מסך נכסי השקעה
A3: מזומנים ושווי מזומנים | B3: 1211658.9 | D3: שווי הוגן | E3: 0.21814623
A4: איגרות חוב ממשלתיות | B4: 1319085 | D4: שווי הוגן | E4: 0.23748716
A5: ניירות ערך מסחריים | B5: 0 | E5: 0
A6: איגרות חוב | B6: 670120.2 | D6: שווי הוגן | E6: 0.12064798
A7: מניות מבכ ויהש | B7: 1053135.6 | D7: NA | E7: 0.18960581
A8: קרנות סל | B8: 434231.39 | D8: NA | E8: 0.07817872
A9: קרנות נאמנות | B9: 673326.51 | D9: שווי הוגן | E9: 0.12122524
A10: כתבי אופציה | B10: 4648.3922 | D10: שווי הוגן | E10: 0.00083689333
A11: אופציות | B11: 0 | E11: 0
A12: חוזים עתידיים | B12: 16087.609 | D12: שווי הוגן | E12: 0.002896402
A13: מוצרים מובנים | B13: 6.32804 | D13: שווי הוגן | E13: 1.139296e-06
A14: לא סחיר איגרות חוב ממשלתיות | B14: 0 | E14: 0
A15: לא סחיר איגרות חוב מיועדות | B15: 0 | E15: 0
A16: אפיק השקעה מובטח תשואה | B16: -654959 | E16: -0.11791837
A17: לא סחיר ניירות ערך מסחריים | B17: 4778.868 | D17: שווי הוגן | E17: 0.0008603841
A18: לא סחיר איגרות חוב | B18: 123882.53 | D18: שווי הוגן | E18: 0.022303726
A19: לא סחיר מניות מבכ ויהש | B19: 68647.391 | D19: שווי הוגן | E19: 0.012359229
A20: קרנות השקעה | B20: 295131.11 | D20: שווי הוגן | E20: 0.053135202
A21: לא סחיר כתבי אופציה | B21: 8975.9961 | D21: שווי הוגן | E21: 0.0016160322
A22: לא סחיר אופציות | B22: 0 | E22: 0
A23: לא סחיר נגזרים אחרים | B23: 9356.8167 | D23: NA | E23: 0.0016845948
A24: הלוואות | B24: 66662.564 | D24: שווי הוגן | E24: 0.012001882
A25: לא סחיר מוצרים מובנים | B25: 3718.7689 | D25: שווי הוגן | E25: 0.00066952459
A26: פיקדונות מעל 3 חודשים | B26: 214699.96 | D26: שווי הוגן | E26: 0.038654432
A27: זכויות מקרקעין | B27: 23449.037 | D27: שווי הוגן | E27: 0.0042217484
A28: השקעה בחברות מוחזקות | B28: 0 | E28: 0
A29: נכסים אחרים | B29: 7698.5325 | D29: שווי הוגן | E29: 0.0013860385
A30: סך הכל נכסים | B30: =SUM(B3:B29) -> 5554342.5 | C30: =SUM(C3:C29) -> 0 | D30: =SUM(D3:D29) -> 0 | E30: =SUM(E3:E29) -> 1
A31: מסגרות אשראי | B31: 64944.498
A32: יתרות התחייבות להשקעה | B32: 275918.68

Sheet מזומנים ושווי מזומנים
A1: מספר קופה/קרן/ח.פ. עבור חברת ביטוח | B1: מספר מסלול | C1: שם הבנק | D1: מספר מזהה בנק | E1: סוג מספר מזהה בנק | F1: מאפיין עיקרי | G1: ישראל/חו"ל | H1: בעל עניין/צד קשור | I1: דירוג הבנק | J1: שם מדרג | K1: מטבע פעילות | L1: שווי מטבעי | M1: שער חליפין | N1: שיעור ריבית | O1: שווי הוגן (באלפי ש"ח) | P1: שיעור מנכסי אפיק ההשקעה | Q1: שיעור מסך נכסי ההשקעה
A2: 13908 | B2: 13908 | C2: בנק הבינלאומי הראשון לישראל בע"מ | D2: 31 | E2: סימול בנק | F2: מזומן ועו"ש בש"ח | G2: ישראל | H2: לא | I2: ilAAA | J2: S&P מעלות | K2: ILS | L2: 872843.96 | M2: 1 | O2: 872843.96 | P2: 0.72037102 | Q2: 0.15714622
A3: 13908 | B3: 13908 | C3: בנק המזרחי המאוחד בע"מ | D3: 20 | E3: סימול בנק | F3: מזומן ועו"ש בש"ח | G3: ישראל | H3: לא | I3: ilAAA | J3: S&P מעלות | K3: ILS | L3: 0.01674 | M3: 1 | O3: 0.01674 | P3: 1.3815769e-08 | Q3: 3.0138581e-09
A4: 13908 | B4: 13908 | C4: בנק הבינלאומי הראשון לישראל בע"מ | D4: 31 | E4: סימול בנק | F4: מזומן ועו"ש נקוב במט"ח | G4: ישראל | H4: לא | I4: ilAAA | J4: S&P מעלות | K4: USD | L4: 67268.578 | M4: 2.978 | O4: 200325.83 | P4: 0.16533186 | Q4: 0.036066523
A5: 13908 | B5: 13908 | C5: בנק המזרחי המאוחד בע"מ | D5: 20 | E5: סימול בנק | F5: מזומן ועו"ש נקוב במט"ח | G5: ישראל | H5: לא | I5: ilAAA | J5: S&P מעלות | K5: USD | L5: 216.47349 | M5: 2.978 | O5: 644.65805 | P5: 0.00053204582 | Q5: 0.00011606379
A6: 13908 | B6: 13908 | C6: בנק הבינלאומי הראשון לישראל בע"מ | D6: 31 | E6: סימול בנק | F6: מזומן ועו"ש נקוב במט"ח | G6: ישראל | H6: לא | I6: ilAAA | J6: S&P מעלות | K6: CHF | L6: 49.01082 | M6: 3.6802 | O6: 180.36962 | P6: 0.00014886171 | Q6: 3.2473622e-05
A7: 13908 | B7: 13908 | C7: בנק הבינלאומי הראשון לישראל בע"מ | D7: 31 | E7: סימול בנק | F7: מזומן ועו"ש נקוב במט"ח | G7: ישראל | H7: לא | I7: ilAAA | J7: S&P מעלות | K7: GBP | L7: 435.87909 | M7: 3.9389 | O7: 1716.8842 | P7: 0.0014169699 | Q7: 0.00030910664
A8: 13908 | B8: 13908 | C8: בנק הבינלאומי הראשון לישראל בע"מ | D8: 31 | E8: סימול בנק | F8: מזומן ועו"ש נקוב במט"ח | G8: ישראל | H8: לא | I8: ilAAA | J8: S&P מעלות | K8: JPY | L8: 1548214.4 | M8: 0.018341 | O8: 28395.8 | P8: 0.023435474 | Q8: 0.0051123603
A9: 13908 | B9: 13908 | C9: בנק הבינלאומי הראשון לישראל בע"מ | D9: 31 | E9: סימול בנק | F9: מזומן ועו"ש נקוב במט"ח | G9: ישראל | H9: לא | I9: ilAAA | J9: S&P מעלות | K9: CAD | L9: 0.010001434 | M9: 2.0917 | O9: 0.02092 | P9: 1.7265585e-08 | Q9: 3.7664224e-09
A10: 13908 | B10: 13908 | C10: בנק הבינלאומי הראשון לישראל בע"מ | D10: 31 | E10: סימול בנק | F10: מזומן ועו"ש נקוב במט"ח | G10: ישראל | H10: לא | I10: ilAAA | J10: S&P מעלות | K10: EUR | L10: 8.8378259e-06 | M10: 3.3945 | O10: 3e-05 | P10: 2.4759443e-11 | Q10: 5.4011793e-12
A11: 13908 | B11: 13908 | C11: בנק הבינלאומי הראשון לישראל בע"מ | D11: 31 | E11: סימול בנק | F11: מזומן ועו"ש נקוב במט"ח | G11: ישראל | H11: לא | I11: ilAAA | J11: S&P מעלות | K11: EUR | L11: 13291.655 | M11: 3.3945 | O11: 45118.524 | P11: 0.037236985 | Q11: 0.008123108
A12: 13908 | B12: 13908 | C12: בנק הבינלאומי הראשון לישראל בע"מ | D12: 31 | E12: סימול בנק | F12: מזומן ועו"ש נקוב במט"ח | G12: ישראל | H12: לא | I12: ilAAA | J12: S&P מעלות | K12: USD | L12: -108.34041 | M12: 2.978 | O12: -322.63774 | P12: -0.0002662777 | Q12: -5.8087476e-05
A13: 13908 | B13: 13908 | C13: בנק הבינלאומי הראשון לישראל בע"מ | D13: 31 | E13: סימול בנק | F13: מזומן ועו"ש נקוב במט"ח | G13: ישראל | H13: לא | I13: ilAAA | J13: S&P מעלות | K13: USD | L13: 101.824 | M13: 2.978 | O13: 303.23187 | P13: 0.00025026174 | Q13: 5.4593657e-05
... A16: 13908 | B16: 13908 | C16: בנק הבינלאומי הראשון לישראל בע"מ | D16: 31 | E16: סימול בנק | F16: מזומן ועו"ש נקוב במט"ח | G16: ישראל | H16: לא | I16: ilAAA | J16: S&P מעלות | K16: USD | L16: 10060 | M16: 2.978 | O16: 29958.68 | P16: 0.024725341 | Q16: 0.0053937401

Sheet איגרות חוב ממשלתיות
A1: מספר קופה/קרן/ח.פ. עבור חברת ביטוח | B1: מספר מסלול | C1: שם מנפיק | D1: שם נייר ערך | E1: מספר נייר ערך | F1: מאפיין עיקרי | G1: ישראל/חו"ל | H1: מדינה לפי חשיפה כלכלית | I1: זירת מסחר | J1: דירוג | K1: שם מדרג | L1: מטבע פעילות | M1: מח"מ | N1: מועד פדיון | O1: שיעור ריבית | P1: תשואה לפדיון | Q1: סכום לקבל (במטבע הפעילות) | R1: ערך נקוב (יחידות) | S1: שער חליפין | T1: שער נייר הערך | U1: שווי הוגן (באלפי ש"ח) | V1: עלות מופחתת (באלפי ש"ח) | W1: השיטה שיושמה בדוח הכספי | X1: שיעור מערך נקוב מונפק | Y1: שיעור מנכסי אפיק ההשקעה | Z1: שיעור מסך נכסי ההשקעה
A2: 13908 | B2: 13908 | C2: מדינת ישראל | D2: ממשל שקלית 0142 | E2: IL0011254005 | F2: לא צמוד למדד המחירים לצרכן ריבית קבועה | G2: ישראל | H2: ישראל | I2: TASE | J2: NR | K2: NR | L2: ILS | M2: 11.065 | N2: 51897 | O2: 0.055 | P2: 0.0394 | Q2: 0 | R2: 16725000 | S2: 1 | T2: 120.13 | U2: 20091.743 | W2: שווי הוגן | X2: 0.00045415522 | Y2: 0.015231575 | Z2: 0.0036173035
A3: 13908 | B3: 13908 | C3: מדינת ישראל | D3: ממשל שקלית 0327 | E3: IL0011393449 | F3: לא צמוד למדד המחירים לצרכן ריבית קבועה | G3: ישראל | H3: ישראל | I3: TASE | J3: NR | K3: NR | L3: ILS | M3: 0.748 | N3: 46477 | O3: 0.02 | P3: 0.0319 | Q3: 0 | R3: 41342100 | S3: 1 | T3: 99.63 | U3: 41189.134 | W3: שווי הוגן | X3: 0.0014645573 | Y3: 0.031225534 | Z3: 0.0074156633
A4: 13908 | B4: 13908 | C4: מדינת ישראל | D4: ממשל שקלית 0347 | E4: IL0011401937 | F4: לא צמוד למדד המחירים לצרכן ריבית קבועה | G4: ישראל | H4: ישראל | I4: TASE | J4: NR | K4: NR | L4: ILS | M4: 14.465 | N4: 53782 | O4: 0.0375 | P4: 0.0413 | Q4: 0 | R4: 8370250 | S4: 1 | T4: 95.7 | U4: 8010.3292 | W4: שווי הוגן | X4: 0.00029762104 | Y4: 0.0060726407 | Z4: 0.0014421742
A5: 13908 | B5: 13908 | C5: מדינת ישראל | D5: ממשל צמודה 0527 | E5: IL0011408478 | F5: צמוד למדד המחירים לצרכן בריבית קבועה | G5: ישראל | H5: ישראל | I5: TASE | J5: NR | K5: NR | L5: ILS | M5: 0.915 | N5: 46538 | O5: 0.0075 | P5: 0.0172 | Q5: 0 | R5: 119572805 | S5: 1 | T5: 119.65 | U5: 143068.86 | W5: שווי הוגן | X5: 0.0049092853 | Y5: 0.10846068 | Z5: 0.025758019
A6: 13908 | B6: 13908 | C6: מדינת ישראל | D6: ממשל שקלית 0928 | E6: IL0011508798 | F6: לא צמוד למדד המחירים לצרכן ריבית קבועה | G6: ישראל | H6: ישראל | I6: TASE | J6: NR | K6: NR | L6: ILS | M6: 2.18 | N6: 47024 | O6: 0.0225 | P6: 0.0328 | Q6: 0 | R6: 76135295 | S6: 1 | T6: 99.5 | U6: 75754.619 | W6: שווי הוגן | X6: 0.0021927408 | Y6: 0.057429671 | Z6: 0.013638809
A7: 13908 | B7: 13908 | C7: מדינת ישראל | D7: ממשל צמודה 0529 | E7: IL0011570236 | F7: צמוד למדד המחירים לצרכן בריבית קבועה | G7: ישראל | H7: ישראל | I7: TASE | J7: NR | K7: NR | L7: ILS | M7: 2.903 | N7: 47269 | O7: 0.005 | P7: 0.0163 | Q7: 0 | R7: 106977651 | S7: 1 | T7: 115.67 | U7: 123741.05 | W7: שווי הוגן | X7: 0.0032274144 | Y7: 0.093808245 | Z7: 0.022278253
A8: 13908 | B8: 13908 | C8: מדינת ישראל | D8: ממשל שקלית 0537 | E8: IL0011661803 | F8: לא צמוד למדד המחירים לצרכן ריבית קבועה | G8: ישראל | H8: ישראל | I8: TASE | J8: NR | K8: NR | L8: ILS | M8: 10.026 | N8: 50191 | O8: 0.015 | P8: 0.0381 | Q8: 0 | R8: 31517147 | S8: 1 | T8: 79.78 | U8: 25144.38 | W8: שווי הוגן | X8: 0.00075219945 | Y8: 0.019061986 | Z8: 0.0045269768
A9: 13908 | B9: 13908 | C9: מדינת ישראל | D9: ממשל משתנה 1130 | E9: IL0011665523 | F9: לא צמוד למדד המחירים לצרכן ריבית משתנה | G9: ישראל | H9: ישראל | I9: TASE | J9: NR | K9: NR | L9: ILS | M9: 4.121 | N9: 47816 | O9: 0.0356 | P9: 0.0356 | Q9: 0 | R9: 41429977 | S9: 1 | T9: 99.01 | U9: 41019.82 | W9: שווי הוגן | X9: 0.0011304245 | Y9: 0.031097177 | Z9: 0.0073851802
A10: 13908 | B10: 13908 | C10: מדינת ישראל | D10: ממשל צמודה 1131 | E10: IL0011722209 | F10: צמוד למדד המחירים לצרכן בריבית קבועה | G10: ישראל | H10: ישראל | I10: TASE | J10: NR | K10: NR | L10: ILS | M10: 5.403 | N10: 48182 | O10: 0.001 | P10: 0.0165 | Q10: 0 | R10: 16031800 | S10: 1 | T10: 109.97 | U10: 17630.17 | W10: שווי הוגן | X10: 0.00046837607 | Y10: 0.013365454 | Z10: 0.0031741237
A11: 13908 | B11: 13908 | C11: מדינת ישראל | D11: ממשל שקלית 0432 | E11: IL0011806606 | F11: לא צמוד למדד המחירים לצרכן ריבית קבועה | G11: ישראל | H11: ישראל | I11: TASE | J11: NR | K11: NR | L11: ILS | M11: 5.632 | N11: 48334 | O11: 0.013 | P11: 0.0347 | Q11: 0 | R11: 82012941 | S11: 1 | T11: 88.94 | U11: 72942.31 | W11: שווי הוגן | X11: 0.0019959954 | Y11: 0.055297657 | Z11: 0.013132483
A12: 13908 | B12: 13908 | C12: מדינת ישראל | D12: ממשל שקלית 1152 | E12: IL0011840761 | F12: לא צמוד למדד המחירים לצרכן ריבית קבועה | G12: ישראל | H12: ישראל | I12: TASE | J12: NR | K12: NR | L12: ILS | M12: 17.441 | N12: 55852 | O12: 0.028 | P12: 0.043 | Q12: 0 | R12: 3329807 | S12: 1 | T12: 78.16 | U12: 2602.5772 | W12: שווי הוגן | X12: 9.1604576e-05 | Y12: 0.001973017 | Z12: 0.0004685662
A13: 13908 | B13: 13908 | C13: מדינת ישראל | D13: ממשל שקלית 0229 | E13: IL0011948028 | F13: לא צמוד למדד המחירים לצרכן ריבית קבועה | G13: ישראל | H13: ישראל | I13: TASE | J13: NR | K13: NR | L13: ILS | M13: 2.559 | N13: 47177 | O13: 0.0375 | P13: 0.033 | Q13: 0 | R13: 40715544 | S13: 1 | T13: 102.39 | U13: 41688.645 | W13: שווי הוגן | X13: 0.0011624588 | Y13: 0.031604214 | Z13: 0.007505595
... A38: 13908 | B38: 13908 | C38: STATE OF ISRAEL | D38: ISRAEL 5.8 1/56 | E38: US46515CKR42 | F38: נקוב במט"ח | G38: ישראל | H38: ישראל | I38: FWB | J38: Baa1 | K38: Moodys | L38: USD | M38: 13.753 | N38: 56992 | O38: 0.058 | P38: 0.06086 | Q38: 0 | R38: 300000 | S38: 2.978 | T38: 99.88 | U38: 892.32792 | W38: שווי הוגן | X38: 0.00017142857 | Y38: 0.00067647492 | Z38: 0.0001606541

Sheet ניירות ערך מסחריים
A1: מספר קופה/קרן/ח.פ. עבור חברת ביטוח | B1: מספר מסלול | C1: שם מנפיק | D1: מספר מנפיק | E1: סוג מספר מזהה מנפיק | F1: שם נייר ערך | G1: מספר נייר ערך | H1: סוג מספר נייר ערך | I1: מאפיין עיקרי | J1: ישראל/חו"ל | K1: מדינה לפי חשיפה כלכלית | L1: זירת מסחר | M1: ענף מסחר | N1: בעל עניין/צד קשור | O1: דירוג | P1: שם מדרג | Q1: דירוג נייר הערך/המנפיק | R1: מטבע פעילות | S1: מח"מ | T1: ריבית עוגן | U1: מועד פדיון | V1: שיעור ריבית | W1: תשואה לפדיון | X1: נחיתות חוזית | Y1: האם סווג כחוב בעייתי | Z1: ערך נקוב (יחידות) | AA1: שער חליפין | AB1: שער נייר הערך | AC1: סכום לקבל (במטבע הפעילות) | AD1: שווי הוגן (באלפי ש"ח) | AE1: עלות מופחתת (באלפי ש"ח) | AF1: עלות מופחתת (במטבע הפעילות) | AG1: השיטה שיושמה בדוח הכספי | AH1: שיעור מערך נקוב מונפק | AI1: שיעור מנכסי אפיק ההשקעה | AJ1: שיעור מסך נכסי ההשקעה

Sheet איגרות חוב
A1: מספר קופה/קרן/ח.פ. עבור חברת ביטוח | B1: מספר מסלול | C1: שם מנפיק | D1: מספר מנפיק | E1: סוג מספר מזהה מנפיק | F1: שם נייר ערך | G1: מספר נייר ערך | H1: סוג מספר נייר ערך | I1: מאפיין עיקרי | J1: ישראל/חו"ל | K1: מדינה לפי חשיפה כלכלית | L1: סטאטוס סחירות | M1: זירת מסחר | N1: ענף מסחר | O1: בעל עניין/צד קשור | P1: דירוג | Q1: שם מדרג | R1: דירוג נייר הערך/המנפיק | S1: מטבע פעילות | T1: מח"מ | U1: מועד פדיון | V1: שיעור ריבית | W1: תשואה לפדיון | X1: נחיתות חוזית | Y1: האם סווג כחוב בעייתי | Z1: ערך נקוב (יחידות) | AA1: שער חליפין | AB1: שער נייר הערך | AC1: סכום לקבל (במטבע הפעילות) | AD1: שווי הוגן (באלפי ש"ח) | AE1: עלות מופחתת (באלפי ש"ח) | AF1: עלות מופחתת (במטבע הפעילות) | AG1: השיטה שיושמה בדוח הכספי | AH1: שיעור מערך נקוב מונפק | AI1: שיעור מנכסי אפיק ההשקעה | AJ1: שיעור מסך נכסי ההשקעה
A2: 13908 | B2: 13908 | C2: אדמה פתרונות לחקלאות בע"מ | D2: 520043605 | E2: ח.פ. | F2: אדמה אגח ב | G2: IL0011109159 | H2: ISIN | I2: צמוד למדד המחירים לצרכן | J2: ישראל | K2: ישראל | L2: סחיר | M2: TASE | N2: כימיה, גומי ופלסטיק | O2: לא | P2: ilAA- | Q2: S&P מעלות | R2: נייר ערך | S2: ILS | T2: 4.78 | U2: 50009 | V2: 0.0515 | W2: 0.0304 | X2: החוב לא נחות | Z2: 338274.88 | AA2: 1 | AB2: 159.3 | AC2: 0 | AD2: 538.87188 | AG2: שווי הוגן | AH2: 0.00019230142 | AI2: 0.00080414212 | AJ2: =AD2/'סכום נכסים'!$B$30 -> 9.7018122e-05
A3: 13908 | B3: 13908 | C3: אמות השקעות בע"מ | D3: 520026683 | E3: ח.פ. | F3: אמות אגח ד | G3: IL0011331498 | H3: ISIN | I3: צמוד למדד המחירים לצרכן | J3: ישראל | K3: ישראל | L3: סחיר | M3: TASE | N3: נדל"ן מניב בישראל | O3: לא | P3: ilAA | Q3: S&P מעלות | R3: נייר ערך | S3: ILS | T3: 1.491 | U3: 46936 | V3: 0.032 | W3: 0.0223 | X3: החוב לא נחות | Z3: 542283.75 | AA3: 1 | AB3: 120.75 | AC3: 17.62677 | AD3: 672.4344 | AG3: שווי הוגן | AH3: 0.0019643186 | AI3: 0.0010034534 | AJ3: =AD3/'סכום נכסים'!$B$30 -> 0.00012106463
A4: 13908 | B4: 13908 | C4: איירפורט סיטי בע"מ | D4: 511659401 | E4: ח.פ. | F4: ארפורט אגח ה | G4: IL0011334872 | H4: ISIN | I4: צמוד למדד המחירים לצרכן | J4: ישראל | K4: ישראל | L4: סחיר | M4: TASE | N4: נדל"ן מניב בישראל | O4: לא | P4: ilAA | Q4: S&P מעלות | R4: נייר ערך | S4: ILS | T4: 1.633 | U4: 47177 | V4: 0.0234 | W4: 0.0243 | X4: החוב לא נחות | Z4: 3278142.2 | AA4: 1 | AB4: 119.82 | AC4: 0 | AD4: 3927.8699 | AG4: שווי הוגן | AH4: 0.0028489047 | AI4: 0.0058614409 | AJ4: =AD4/'סכום נכסים'!$B$30 -> 0.000707171
A5: 13908 | B5: 13908 | C5: שיכון ובינוי בע"מ | D5: 520036104 | E5: ח.פ. | F5: שכון ובי אגח 8 | G5: IL0011358889 | H5: ISIN | I5: צמוד למדד המחירים לצרכן | J5: ישראל | K5: ישראל | L5: סחיר | M5: TASE | N5: בנייה | O5: לא | P5: ilA | Q5: S&P מעלות | R5: נייר ערך | S5: ILS | T5: 1.775 | U5: 47239 | V5: 0.039 | W5: 0.0266 | X5: החוב לא נחות | Z5: 4172877.2 | AA5: 1 | AB5: 123.35 | AC5: 0 | AD5: 5147.2441 | AG5: שווי הוגן | AH5: 0.0040308631 | AI5: 0.0076810758 | AJ5: =AD5/'סכום נכסים'!$B$30 -> 0.00092670627
A6: 13908 | B6: 13908 | C6: קרסו מוטורס בע"מ | D6: 514065283 | E6: ח.פ. | F6: קרסו מוט' אגח א | G6: IL0011364648 | H6: ISIN | I6: לא צמוד למדד המחירים לצרכן | J6: ישראל | K6: ישראל | L6: סחיר | M6: TASE | N6: מסחר | O6: לא | P6: ilAA- | Q6: S&P מעלות | R6: נייר ערך | S6: ILS | T6: 0.17 | U6: 46266 | V6: 0.0275 | W6: 0.0359 | X6: החוב לא נחות | Z6: 340643.25 | AA6: 1 | AB6: 100.77 | AC6: 0 | AD6: 343.2662 | AG6: שווי הוגן | AH6: 0.0074077447 | AI6: 0.00051224571 | AJ6: =AD6/'סכום נכסים'!$B$30 -> 6.180141e-05
A7: 13908 | B7: 13908 | C7: ריט 1 בע"מ | D7: 513821488 | E7: ח.פ. | F7: ריט 1 אגח ה | G7: IL0011367534 | H7: ISIN | I7: צמוד למדד המחירים לצרכן | J7: ישראל | K7: ישראל | L7: סחיר | M7: TASE | N7: נדל"ן מניב בישראל | O7: לא | P7: ilAA | Q7: S&P מעלות | R7: נייר ערך | S7: ILS | T7: 1.192 | U7: 47016 | V7: 0.04 | W7: 0.0235 | X7: החוב לא נחות | Z7: 1518130.4 | AA7: 1 | AB7: 123.73 | AC7: 0 | AD7: 1878.3827 | AG7: שווי הוגן | AH7: 0.0025235063 | AI7: 0.0028030534 | AJ7: =AD7/'סכום נכסים'!$B$30 -> 0.00033818273
A8: 13908 | B8: 13908 | C8: ריט 1 בע"מ | D8: 513821488 | E8: ח.פ. | F8: ריט 1 אגח ו | G8: IL0011385445 | H8: ISIN | I8: צמוד למדד המחירים לצרכן | J8: ישראל | K8: ישראל | L8: סחיר | M8: TASE | N8: נדל"ן מניב בישראל | O8: לא | P8: ilAA | Q8: S&P מעלות | R8: נייר ערך | S8: ILS | T8: 2.584 | U8: 48112 | V8: 0.035 | W8: 0.0239 | X8: החוב לא נחות | Z8: 212655.79 | AA8: 1 | AB8: 125.94 | AC8: 0 | AD8: 267.8187 | AG8: שווי הוגן | AH8: 0.0003143071 | AI8: 0.0003996577 | AJ8: =AD8/'סכום נכסים'!$B$30 -> 4.8217894e-05
A9: 13908 | B9: 13908 | C9: קבוצת עזריאלי בע"מ | D9: 510960719 | E9: ח.פ. | F9: עזריאלי אגח ד | G9: IL0011386500 | H9: ISIN | I9: צמוד למדד המחירים לצרכן | J9: ישראל | K9: ישראל | L9: סחיר | M9: TASE | N9: נדל"ן מניב בישראל | O9: לא | P9: Aa1.il | Q9: מידרוג Moodys | R9: נייר ערך | S9: ILS | T9: 2.218 | U9: 47669 | V9: 0.0134 | W9: 0.0231 | X9: החוב לא נחות | Z9: 2523509.4 | AA9: 1 | AB9: 118.34 | AC9: 27.53381 | AD9: 3013.8548 | AG9: שווי הוגן | AH9: 0.0014280434 | AI9: 0.0044974839 | AJ9: =AD9/'סכום נכסים'!$B$30 -> 0.00054261235
A10: 13908 | B10: 13908 | C10: סלע קפיטל נדל"ן בע"מ | D10: 513992529 | E10: ח.פ. | F10: סלע נדלן אגח ג | G10: IL0011389736 | H10: ISIN | I10: צמוד למדד המחירים לצרכן | J10: ישראל | K10: ישראל | L10: סחיר | M10: TASE | N10: נדל"ן מניב בישראל | O10: לא | P10: Aa3.il | Q10: מידרוג Moodys | R10: נייר ערך | S10: ILS | T10: 1.747 | U10: 47221 | V10: 0.0196 | W10: 0.024 | X10: החוב לא נחות | Z10: 2250000 | AA10: 1 | AB10: 119.64 | AC10: 0 | AD10: 2691.9 | AG10: שווי הוגן | AH10: 0.0026198756 | AI10: 0.0040170405 | AJ10: =AD10/'סכום נכסים'!$B$30 -> 0.00048464782
A11: 13908 | B11: 13908 | C11: קבוצת אשטרום בע"מ | D11: 510381601 | E11: ח.פ. | F11: אשטרום קב אגח ג | G11: IL0011401028 | H11: ISIN | I11: לא צמוד למדד המחירים לצרכן | J11: ישראל | K11: ישראל | L11: סחיר | M11: TASE | N11: בנייה | O11: לא | P11: ilA | Q11: S&P מעלות | R11: נייר ערך | S11: ILS | T11: 1.233 | U11: 47133 | V11: 0.043 | W11: 0.041 | X11: החוב לא נחות | Z11: 6876275 | AA11: 1 | AB11: 102.27 | AC11: 0 | AD11: 7032.3664 | AG11: שווי הוגן | AH11: 0.011355827 | AI11: 0.010494187 | AJ11: =AD11/'סכום נכסים'!$B$30 -> 0.0012661024
A12: 13908 | B12: 13908 | C12: רבוע כחול נדל"ן בע"מ | D12: 513765859 | E12: ח.פ. | F12: רבוע נדלן אגח ו | G12: IL0011406076 | H12: ISIN | I12: צמוד למדד המחירים לצרכן | J12: ישראל | K12: ישראל | L12: סחיר | M12: TASE | N12: נדל"ן מניב בישראל | O12: לא | P12: ilAA | Q12: S&P מעלות | R12: נייר ערך | S12: ILS | T12: 0.416 | U12: 46356 | V12: 0.0215 | W12: 0.0348 | X12: החוב לא נחות | Z12: 196428.57 | AA12: 1 | AB12: 120.56 | AC12: 0 | AD12: 236.81428 | AG12: שווי הוגן | AH12: 0.00028042636 | AI12: 0.00035339075 | AJ12: =AD12/'סכום נכסים'!$B$30 -> 4.263588e-05
A13: 13908 | B13: 13908 | C13: ביג מרכזי קניות בע"מ | D13: 513623314 | E13: ח.פ. | F13: ביג אגח ט | G13: IL0011410508 | H13: ISIN | I13: צמוד למדד המחירים לצרכן | J13: ישראל | K13: ישראל | L13: סחיר | M13: TASE | N13: נדל"ן מניב בישראל | O13: לא | P13: Aa3.il | Q13: מידרוג Moodys | R13: נייר ערך | S13: ILS | T13: 0.471 | U13: 46376 | V13: 0.0195 | W13: 0.0381 | X13: החוב לא נחות | Z13: 66676.05 | AA13: 1 | AB13: 119.44 | AC13: 0 | AD13: 79.63787 | AG13: שווי הוגן | AH13: 0.00039599536 | AI13: 0.00011884117 | AJ13: =AD13/'סכום נכסים'!$B$30 -> 1.4337947e-05
... A272: 13908 | B272: 13908 | C272: קבוצת חג'ג' ייזום נדל"ן בע"מ | D272: 520033309 | E272: ח.פ. | F272: חג'ג' אגח יא | G272: IL0082303285 | H272: ISIN | I272: לא צמוד למדד המחירים לצרכן | J272: ישראל | K272: ישראל | L272: סחיר | M272: TASE | N272: בנייה | O272: לא | P272: NR | Q272: NR | R272: NR | S272: ILS | T272: 0.993 | U272: 46569 | V272: 0.029 | W272: 0.0638 | X272: החוב לא נחות | Z272: 666666.67 | AA272: 1 | AB272: 96.77 | AC272: 20.43334 | AD272: 665.56668 | AG272: שווי הוגן | AH272: 0.0054017556 | AI272: 0.00099320492 | AJ272: =AD272/'סכום נכסים'!$B$30 -> 0.00011982817
A273: 13908 | B273: 13908 | C273: ISRAEL ELECTRIC CORP LTD | D273: 213800T8ZHTFZIBYPE21 | E273: LEI | F273: ISRELE 4.25 14/8/28 | G273: IL0060002446 | H273: ISIN | I273: צמוד למט"ח | J273: חו"ל | K273: ישראל | L273: סחיר | M273: NYSE | N273: Energy Equipment & Services | O273: לא | P273: Baa2 | Q273: Moodys | R273: נייר ערך | S273: USD | T273: 2.003 | U273: 46979 | V273: 0.0425 | W273: 0.05015 | X273: החוב לא נחות | Z273: 3500000 | AA273: 2.978 | AB273: 100.1624 | AC273: 0 | AD273: 10439.927 | AG273: שווי הוגן | AH273: 0.0035 | AI273: 0.015579186 | AJ273: =AD273/'סכום נכסים'!$B$30 -> 0.0018795973
A274: 13908 | B274: 13908 | C274: LEVIATHAN BOND LTD | D274: 213800CYKA4XE2HZZB09 | E274: LEI | F274: LVIATH 6.5 6/27 | G274: IL0011677825 | H274: ISIN | I274: לא צמוד למדד המחירים לצרכן | J274: חו"ל | K274: ישראל | L274: סחיר | M274: FWB | N274: Energy Equipment & Services | O274: לא | P274: Ba3 | Q274: Moodys | R274: נייר ערך | S274: USD | T274: 0.483 | U274: 46568 | V274: 0.065 | W274: 0.05981 | X274: החוב לא נחות | Z274: 100000 | AA274: 2.978 | AB274: 100.5963 | AC274: 0 | AD274: 299.57578 | AG274: שווי הוגן | AH274: 0.00016666667 | AI274: 0.00044704783 | AJ274: =AD274/'סכום נכסים'!$B$30 -> 5.3935417e-05
A275: 13908 | B275: 13908 | C275: LEVIATHAN BOND LTD | D275: 213800CYKA4XE2HZZB09 | E275: LEI | F275: LVIATH 6.75 6/30 | G275: IL0011677908 | H275: ISIN | I275: לא צמוד למדד המחירים לצרכן | J275: חו"ל | K275: ישראל | L275: סחיר | M275: NYSE | N275: Oil, Gas & Consumable Fuels | O275: לא | P275: Ba3 | Q275: Moodys | R275: נייר ערך | S275: USD | T275: 3.164 | U275: 47664 | V275: 0.0675 | W275: 0.05876 | X275: החוב לא נחות | Z275: 840000 | AA275: 2.978 | AB275: 103.1745 | AC275: 0 | AD275: 2580.9307 | AG275: שווי הוגן | AH275: 0.0015272727 | AI275: 0.0038514445 | AJ275: =AD275/'סכום נכסים'!$B$30 -> 0.00046466899
A276: 13908 | B276: 13908 | C276: ENERGEAN ISRAEL FINANCE | D276: 549300RVMKU0CYUZBB05 | E276: LEI | F276: ENOIGA 5.875 30/3/31 | G276: IL0011736811 | H276: ISIN | I276: צמוד למט"ח | J276: חו"ל | K276: ישראל | L276: סחיר | M276: NYSE | N276: Energy Equipment & Services | O276: לא | P276: Ba3 | Q276: Moodys | R276: נייר ערך | S276: USD | T276: 4.134 | U276: 47937 | V276: 0.05875 | W276: 0.06865 | X276: החוב לא נחות | Z276: 440000 | AA276: 2.978 | AB276: 97.5364 | AC276: 0 | AD276: 1278.039 | AG276: שווי הוגן | AH276: 0.000704 | AI276: 0.0019071787 | AJ276: =AD276/'סכום נכסים'!$B$30 -> 0.00023009725
A277: 13908 | B277: 13908 | C277: Bank Hapoalim BM | D277: B6ARUI4946ST4S7WOU88 | E277: LEI | F277: HAPOAL 3.255 1/32 | G277: IL0066204707 | H277: ISIN | I277: צמוד למט"ח | J277: חו"ל | K277: ישראל | L277: סחיר | M277: NYSE | N277: Banks | O277: לא | P277: NR | Q277: NR | R277: NR | S277: USD | T277: 0.285 | U277: 48234 | V277: 0.03255 | W277: 0.06166 | X277: החוב לא נחות | Z277: 680000 | AA277: 2.978 | AB277: 100.7149 | AC277: 0 | AD277: 2039.517 | AG277: שווי הוגן | AH277: 0.00068 | AI277: 0.0030435092 | AJ277: =AD277/'סכום נכסים'!$B$30 -> 0.00036719324
A278: 13908 | B278: 13908 | C278: ISRAEL ELECTRIC CORP LTD | D278: 213800T8ZHTFZIBYPE21 | E278: LEI | F278: ISRELE 3.75 2/32 | G278: IL0060004004 | H278: ISIN | I278: צמוד למט"ח | J278: חו"ל | K278: ישראל | L278: סחיר | M278: NYSE | N278: Electric Utilities | O278: לא | P278: Baa2 | Q278: Moodys | R278: נייר ערך | S278: USD | T278: 5.023 | U278: 48266 | V278: 0.0375 | W278: 0.05329 | X278: החוב לא נחות | Z278: 2149000 | AA278: 2.978 | AB278: 93.8153 | AC278: 0 | AD278: 6003.9184 | AG278: שווי הוגן | AH278: 0.004298 | AI278: 0.0089594649 | AJ278: =AD278/'סכום נכסים'!$B$30 -> 0.0010809413
A279: 13908 | B279: 13908 | C279: Israel Discount Bank Ltd | D279: 549300XWZ7BG5G23OF51 | E279: LEI | F279: IDBILI 5.375 26/1/28 | G279: IL0011920878 | H279: ISIN | I279: לא צמוד למדד המחירים לצרכן | J279: חו"ל | K279: ישראל | L279: סחיר | M279: NYSE | N279: Banks | O279: לא | P279: Baa1 | Q279: Moodys | R279: נייר ערך | S279: USD | T279: 1.413 | U279: 46778 | V279: 0.05375 | W279: 0.05116 | X279: החוב לא נחות | Z279: 433000 | AA279: 2.978 | AB279: 102.7112 | AC279: 0 | AD279: 1324.4342 | AG279: שווי הוגן | AH279: 0.00054125 | AI279: 0.0019764129 | AJ279: =AD279/'סכום נכסים'!$B$30 -> 0.00023845022
A280: 13908 | B280: 13908 | C280: TEVA PHARM FNC NL II | D280: 549300BAFGM4RC74ZJ94 | E280: LEI | F280: TEVA 7.875 9/31 | G280: XS2592804194 | H280: ISIN | I280: צמוד למט"ח | J280: חו"ל | K280: ישראל | L280: סחיר | M280: EURONEXT | N280: Pharmaceuticals | O280: לא | P280: Ba1 | Q280: Moodys | R280: נייר ערך | S280: EUR | T280: 4.178 | U280: 48106 | V280: 0.07875 | W280: 0.04148 | X280: החוב לא נחות | Z280: 8000 | AA280: 3.3945 | AB280: 119.6265 | AC280: 0 | AD280: 32.48577 | AG280: שווי הוגן | AH280: 1.6e-05 | AI280: 4.8477527e-05 | AJ280: =AD280/'סכום נכסים'!$B$30 -> 5.8487156e-06
A281: 13908 | B281: 13908 | C281: TEVA PHARM FNC NL II | D281: 549300BAFGM4RC74ZJ94 | E281: LEI | F281: TEVA 7.375 15/9/29 | G281: XS2592804434 | H281: ISIN | I281: צמוד למט"ח | J281: חו"ל | K281: ישראל | L281: סחיר | M281: EURONEXT | N281: Pharmaceuticals | O281: לא | P281: Ba1 | Q281: Moodys | R281: נייר ערך | S281: EUR | T281: 2.665 | U281: 47376 | V281: 0.07375 | W281: 0.03882 | X281: החוב לא נחות | Z281: 5067 | AA281: 3.3945 | AB281: 112.6215 | AC281: 0 | AD281: 19.37082 | AG281: שווי הוגן | AH281: 6.33375e-06 | AI281: 2.8906486e-05 | AJ281: =AD281/'סכום נכסים'!$B$30 -> 3.4875091e-06
A282: 13908 | B282: 13908 | C282: ENERGEAN ISRAEL FINANCE | D282: 549300RVMKU0CYUZBB05 | E282: LEI | F282: ENOIGA 8.5 30/9/33 | G282: IL0011971442 | H282: ISIN | I282: צמוד למט"ח | J282: חו"ל | K282: ישראל | L282: סחיר | M282: NYSE | N282: Energy Equipment & Services | O282: לא | P282: Ba3 | Q282: Moodys | R282: נייר ערך | S282: USD | T282: 3.599 | U282: 48852 | V282: 0.085 | W282: 0.07433 | X282: החוב לא נחות | Z282: 3280000 | AA282: 2.978 | AB282: 108.0482 | AC282: 0 | AD282: 10553.975 | AG282: שווי הוגן | AH282: 0.0043733333 | AI282: 0.015749376 | AJ282: =AD282/'סכום נכסים'!$B$30 -> 0.0019001304
A283: 13908 | B283: 13908 | C283: ORMAT TECHNOLOGIES INC | D283: 5493000TSHHWY24VHM09 | E283: LEI | F283: ORA 2.5 07/27 | G283: US686688AB85 | H283: ISIN | I283: צמוד למט"ח | J283: חו"ל | K283: ארה"ב | L283: סחיר | M283: FWB | N283: Electric Utilities | O283: לא | P283: NR | Q283: NR | R283: NR | S283: USD | T283: 1.94 | U283: 46583 | V283: 0.025 | W283: -0.0386 | X283: החוב לא נחות | Z283: 700000 | AA283: 2.978 | AB283: 139.4989 | AC283: 0 | AD283: 2907.9941 | AG283: שווי הוגן | AH283: 0.0014692394 | AI283: 0.0043395111 | AJ283: =AD283/'סכום נכסים'!$B$30 -> 0.00052355325
A284: 13908 | B284: 13908 | C284: ITHACA ENERGY NORTH | D284: 213800CYKA4XE2HZZB09 | E284: LEI | F284: IAECN 8.125 10/29 | G284: US46567TAC80 | H284: ISIN | I284: צמוד למט"ח | J284: חו"ל | K284: בריטניה | L284: סחיר | M284: אחר | N284: Diversified Telecommunication Services | O284: לא | P284: B1 | Q284: Moodys | R284: נייר ערך | S284: USD | T284: 2.103 | U284: 47406 | V284: 0.08125 | W284: 0.06822 | X284: החוב לא נחות | Z284: 206000 | AA284: 2.978 | AB284: 105.4988 | AC284: 0 | AD284: 647.20138 | AG284: שווי הוגן | AH284: 0.00027466667 | AI284: 0.00096579894 | AJ284: =AD284/'סכום נכסים'!$B$30 -> 0.00011652169
... A296: 13908 | B296: 13908 | C296: South Bow USA Infrastructure Holdings LLC | D296: 529900MUF4C20K50JS49 | E296: LEI | F296: SOBOCN 7.625 10/55 | G296: US836720AG73 | H296: ISIN | I296: צמוד למט"ח | J296: חו"ל | K296: אוסטרליה | L296: סחיר | M296: NYSE | N296: Financial Services | O296: לא | P296: Ba1 | Q296: Moodys | R296: נייר ערך | S296: USD | T296: 3.005 | U296: 47392 | V296: 0.05026 | W296: 0.07599 | X296: החוב לא נחות | Z296: 22000 | AA296: 2.978 | AB296: 107.1978 | AC296: 0 | AD296: 70.23171 | AG296: שווי הוגן | AH296: 4.9285583e-05 | AI296: 0.00010480465 | AJ296: =AD296/'סכום נכסים'!$B$30 -> 1.2644469e-05

Sheet מניות מבכ ויהש
A1: מספר קופה/קרן/ח.פ. עבור חברת ביטוח | B1: מספר מסלול | C1: שם מנפיק | D1: מספר מנפיק | E1: סוג מספר מזהה מנפיק | F1: שם נייר ערך | G1: מספר נייר ערך | H1: סוג מספר נייר ערך | I1: מאפיין עיקרי | J1: ישראל/חו"ל | K1: מדינה לפי חשיפה כלכלית | L1: סטאטוס סחירות | M1: זירת מסחר | N1: ענף מסחר | O1: בעל עניין/צד קשור | P1: מטבע פעילות | Q1: ערך נקוב (יחידות) | R1: שער חליפין | S1: שער נייר הערך | T1: סכום לקבל (במטבע הפעילות) | U1: שווי הוגן (באלפי ש"ח) | V1: שיעור מערך נקוב מונפק | W1: שיעור מנכסי אפיק ההשקעה | X1: שיעור מסך נכסי ההשקעה
A2: 13908 | B2: 13908 | C2: מבטח שמיר אחזקות בע"מ | D2: 520034125 | E2: ח.פ. | F2: מבטח שמיר | G2: IL0001270193 | H2: ISIN | I2: מניות | J2: ישראל | K2: ישראל | L2: סחיר | M2: TASE | N2: השקעה ואחזקות | O2: לא | P2: ILS | Q2: 1000 | R2: 1 | S2: 41980 | T2: 0 | U2: 419.8 | V2: 0.00010280405 | W2: 0.00039861913 | X2: =U2/'סכום נכסים'!$B$30 -> 7.5580503e-05
A3: 13908 | B3: 13908 | C3: להב אל.אר רילאסטייט בע"מ | D3: 520034257 | E3: ח.פ. | F3: להב | G3: IL0001360101 | H3: ISIN | I3: מניות | J3: ישראל | K3: ישראל | L3: סחיר | M3: TASE | N3: השקעה ואחזקות | O3: לא | P3: ILS | Q3: 1600000 | R3: 1 | S3: 1110 | T3: 0 | U3: 17760 | V3: 0.0054581421 | W3: 0.016863925 | X3: =U3/'סכום נכסים'!$B$30 -> 0.0031974982
A4: 13908 | B4: 13908 | C4: וואן טכנולוגיות תוכנה בע"מ | D4: 520034695 | E4: ח.פ. | F4: וואן טכנולוגיות | G4: IL0001610182 | H4: ISIN | I4: מניות | J4: ישראל | K4: ישראל | L4: סחיר | M4: TASE | N4: שרותי מידע | O4: לא | P4: ILS | Q4: 196974 | R4: 1 | S4: 5681 | T4: 0 | U4: 11190.093 | V4: 0.0026744803 | W4: 0.0106255 | X4: =U4/'סכום נכסים'!$B$30 -> 0.0020146566
A5: 13908 | B5: 13908 | C5: כלל החזקות עסקי ביטוח בע"מ | D5: 520036120 | E5: ח.פ. | F5: כלל עסקי ביטוח | G5: IL0002240146 | H5: ISIN | I5: מניות | J5: ישראל | K5: ישראל | L5: סחיר | M5: TASE | N5: ביטוח | O5: לא | P5: ILS | Q5: 124630 | R5: 1 | S5: 22840 | T5: 0 | U5: 28465.492 | V5: 0.0015330095 | W5: 0.027029275 | X5: =U5/'סכום נכסים'!$B$30 -> 0.0051249076
A6: 13908 | B6: 13908 | C6: מבנה נדל"ן (כ.ד) בע"מ | D6: 520024126 | E6: ח.פ. | F6: מבנה | G6: IL0002260193 | H6: ISIN | I6: מניות | J6: ישראל | K6: ישראל | L6: סחיר | M6: TASE | N6: נדל"ן מניב בישראל | O6: לא | P6: ILS | Q6: 390542 | R6: 1 | S6: 1300 | T6: 0 | U6: 5077.046 | V6: 0.0005395146 | W6: 0.0048208853 | X6: =U6/'סכום נכסים'!$B$30 -> 0.00091406786
A7: 13908 | B7: 13908 | C7: בזק החברה הישראלית לתקשורת בע" | D7: 520031931 | E7: ח.פ. | F7: בזק | G7: IL0002300114 | H7: ISIN | I7: מניות | J7: ישראל | K7: ישראל | L7: סחיר | M7: TASE | N7: תקשורת ומדיה | O7: לא | P7: ILS | Q7: 2948142 | R7: 1 | S7: 702.7 | T7: 0 | U7: 20716.594 | V7: 0.0010685327 | W7: 0.019671345 | X7: =U7/'סכום נכסים'!$B$30 -> 0.0037298013
A8: 13908 | B8: 13908 | C8: ישראמקו נגב 2 שותפות מוגבלת | D8: 550010003 | E8: ח.פ. | F8: ישראמקו יהש | G8: IL0002320179 | H8: ISIN | I8: יחידות השתתפות | J8: ישראל | K8: ישראל | L8: סחיר | M8: TASE | N8: חיפושי נפט וגז | O8: לא | P8: ILS | Q8: 667292 | R8: 1 | S8: 187 | T8: 0 | U8: 1247.836 | V8: 0.00025633892 | W8: 0.0011848769 | X8: =U8/'סכום נכסים'!$B$30 -> 0.00022465954
A9: 13908 | B9: 13908 | C9: פורמולה מערכות (1985)בע"מ | D9: 520036690 | E9: ח.פ. | F9: פורמולה מערכות | G9: IL0002560162 | H9: ISIN | I9: מניות | J9: ישראל | K9: ישראל | L9: סחיר | M9: TASE | N9: שרותי מידע | O9: לא | P9: ILS | Q9: 3100 | R9: 1 | S9: 30990 | T9: 0 | U9: 960.69 | V9: 0.00020215633 | W9: 0.00091221869 | X9: =U9/'סכום נכסים'!$B$30 -> 0.00017296197
A10: 13908 | B10: 13908 | C10: נייס בע"מ | D10: 520036872 | E10: ח.פ. | F10: נייס | G10: IL0002730112 | H10: ISIN | I10: מניות | J10: ישראל | K10: ישראל | L10: סחיר | M10: TASE | N10: תוכנה ואינטרנט | O10: לא | P10: ILS | Q10: 16810 | R10: 1 | S10: 26760 | T10: 0 | U10: 4498.356 | V10: 0.00028687383 | W10: 0.0042713929 | X10: =U10/'סכום נכסים'!$B$30 -> 0.00080988091
A11: 13908 | B11: 13908 | C11: איי.סי.אל גרופ בע"מ | D11: 520027830 | E11: ח.פ. | F11: איי.סי.אל | G11: IL0002810146 | H11: ISIN | I11: מניות | J11: ישראל | K11: ישראל | L11: סחיר | M11: TASE | N11: כימיה, גומי ופלסטיק | O11: לא | P11: ILS | Q11: 501190 | R11: 1 | S11: 1494 | T11: 0 | U11: 7487.7786 | V11: 0.00038830315 | W11: 0.0071099851 | X11: =U11/'סכום נכסים'!$B$30 -> 0.0013480945
A12: 13908 | B12: 13908 | C12: קבוצת סקופ מתכות בע"מ | D12: 520037425 | E12: ח.פ. | F12: סקופ | G12: IL0002880198 | H12: ISIN | I12: מניות | J12: ישראל | K12: ישראל | L12: סחיר | M12: TASE | N12: מסחר | O12: לא | P12: ILS | Q12: 20000 | R12: 1 | S12: 28200 | T12: 0 | U12: 5640 | V12: 0.0015114569 | W12: 0.0053554356 | X12: =U12/'סכום נכסים'!$B$30 -> 0.0010154217
A13: 13908 | B13: 13908 | C13: עשות - אשקלון תעשיות בע"מ | D13: 520037581 | E13: ח.פ. | F13: עשות | G13: IL0003120172 | H13: ISIN | I13: מניות | J13: ישראל | K13: ישראל | L13: סחיר | M13: TASE | N13: מתכת ומוצרי בניה | O13: לא | P13: ILS | Q13: 1047 | R13: 1 | S13: 8351 | T13: 0 | U13: 87.43497 | V13: 4.1312265e-05 | W13: 8.3023467e-05 | X13: =U13/'סכום נכסים'!$B$30 -> 1.5741732e-05
... A35: 13908 | B35: 13908 | C35: בנק מזרחי טפחות בע"מ | D35: 520000522 | E35: ח.פ. | F35: מזרחי טפחות | G35: IL0006954379 | H35: ISIN | I35: מניות | J35: ישראל | K35: ישראל | L35: סחיר | M35: TASE | N35: בנקים | O35: לא | P35: ILS | Q35: 77261 | R35: 1 | S35: 19700 | T35: 0 | U35: 15220.417 | V35: 0.00029705346 | W35: 0.014452476 | X35: =U35/'סכום נכסים'!$B$30 -> 0.0027402734
A36: 13908 | B36: 13908 | C36: אזורים-חברה להשקעות בפתוח ובבנ | D36: 520025990 | E36: ח.פ. | F36: אזורים חסום | G36: 7150130 | H36: פנימי | I36: מניות | J36: ישראל | K36: ישראל | L36: חסום | M36: TASE | N36: בנייה | O36: לא | P36: ILS | Q36: 240000 | R36: 1 | S36: 1707.0055 | T36: 0 | U36: 4096.8132 | V36: 0 | W36: 0.0038901098 | X36: =U36/'סכום נכסים'!$B$30 -> 0.00073758742
A37: 13908 | B37: 13908 | C37: אנלייט אנרגיה מתחדשת בע"מ | D37: 520041146 | E37: ח.פ. | F37: אנלייט אנרגיה | G37: IL0007200111 | H37: ISIN | I37: מניות | J37: ישראל | K37: ישראל | L37: סחיר | M37: TASE | N37: אנרגיה מתחדשת | O37: לא | P37: ILS | Q37: 230904 | R37: 1 | S37: 26300 | T37: 0 | U37: 60727.752 | V37: 0.0016521754 | W37: 0.057663753 | X37: =U37/'סכום נכסים'!$B$30 -> 0.010933383
A38: 13908 | B38: 13908 | C38: חברת גב ים לקרקעות בע"מ | D38: 520001736 | E38: ח.פ. | F38: גב ים | G38: IL0007590198 | H38: ISIN | I38: מניות | J38: ישראל | K38: ישראל | L38: סחיר | M38: TASE | N38: נדל"ן מניב בישראל | O38: לא | P38: ILS | Q38: 30000 | R38: 1 | S38: 3662 | T38: 0 | U38: 1098.6 | V38: 0.000135994 | W38: 0.0010431705 | X38: =U38/'סכום נכסים'!$B$30 -> 0.00019779119
A39: 13908 | B39: 13908 | C39: הפניקס פיננסים בע"מ | D39: 520017450 | E39: ח.פ. | F39: הפניקס | G39: IL0007670123 | H39: ISIN | I39: מניות | J39: ישראל | K39: ישראל | L39: סחיר | M39: TASE | N39: ביטוח | O39: לא | P39: ILS | Q39: 221601 | R39: 1 | S39: 16460 | T39: 0 | U39: 36475.525 | V39: 0.00087909568 | W39: 0.034635164 | X39: =U39/'סכום נכסים'!$B$30 -> 0.0065670283
A40: 13908 | B40: 13908 | C40: שופרסל בע"מ | D40: 520022732 | E40: ח.פ. | F40: שופרסל | G40: IL0007770378 | H40: ISIN | I40: מניות | J40: ישראל | K40: ישראל | L40: סחיר | M40: TASE | N40: רשתות שיווק | O40: לא | P40: ILS | Q40: 61290 | R40: 1 | S40: 4261 | T40: 0 | U40: 2611.5669 | V40: 0.00022971951 | W40: 0.0024798011 | X40: =U40/'סכום נכסים'!$B$30 -> 0.0004701847
A41: 13908 | B41: 13908 | C41: כהן פיתוח גז ונפט בע"מ | D41: 520032970 | E41: ח.פ. | F41: כהן פיתוח | G41: IL0008100104 | H41: ISIN | I41: מניות | J41: ישראל | K41: ישראל | L41: סחיר | M41: TASE | N41: חיפושי נפט וגז | O41: לא | P41: ILS | Q41: 19750 | R41: 1 | S41: 15340 | T41: 0 | U41: 3029.65 | V41: 0.0027720835 | W41: 0.00287679 | X41: =U41/'סכום נכסים'!$B$30 -> 0.0005454561
A42: 13908 | B42: 13908 | C42: סנו-מפעלי ברונוס בע"מ | D42: 520032988 | E42: ח.פ. | F42: סנו | G42: IL0008130143 | H42: ISIN | I42: מניות | J42: ישראל | K42: ישראל | L42: סחיר | M42: TASE | N42: כימיה, גומי ופלסטיק | O42: לא | P42: ILS | Q42: 12651 | R42: 1 | S42: 36970 | T42: 0 | U42: 4677.0747 | V42: 0.001029541 | W42: 0.0044410944 | X42: =U42/'סכום נכסים'!$B$30 -> 0.0008420573
A43: 13908 | B43: 13908 | C43: דלק מערכות רכב בע"מ | D43: 520033291 | E43: ח.פ. | F43: דלק רכב | G43: IL0008290103 | H43: ISIN | I43: מניות | J43: ישראל | K43: ישראל | L43: סחיר | M43: TASE | N43: מסחר | O43: לא | P43: ILS | Q43: 234311 | R43: 1 | S43: 1611 | T43: 0 | U43: 3774.7502 | V43: 0.0024161762 | W43: 0.0035842964 | X43: =U43/'סכום נכסים'!$B$30 -> 0.00067960343
A44: 13908 | B44: 13908 | C44: COGNYTE SOFTWARE LTD | D44: 516196425 | E44: ח.פ. | F44: COGNYTE SOFTWARE LTD | G44: IL0011691438 | H44: ISIN | I44: מניות | J44: ישראל | K44: ישראל | L44: סחיר | M44: NASDAQ | N44: תוכנה ואינטרנט | O44: לא | P44: USD | Q44: 20000 | R44: 2.978 | S44: 878 | T44: 0 | U44: 522.9368 | V44: 0.00027134867 | W44: 0.00049655219 | X44: =U44/'סכום נכסים'!$B$30 -> 9.4149181e-05
A45: 13908 | B45: 13908 | C45: אנליסט אי.אמ.אס.-שרותי ניהול ה | D45: 520041963 | E45: ח.פ. | F45: אנליסט | G45: IL0010806136 | H45: ISIN | I45: מניות | J45: ישראל | K45: ישראל | L45: סחיר | M45: TASE | N45: שרותים פיננסיים | O45: לא | P45: ILS | Q45: 15000 | R45: 1 | S45: 14950 | T45: 0 | U45: 2242.5 | V45: 0.0011919909 | W45: 0.0021293554 | X45: =U45/'סכום נכסים'!$B$30 -> 0.00040373815
A46: 13908 | B46: 13908 | C46: ישרוטל בע"מ | D46: 520042482 | E46: ח.פ. | F46: ישרוטל | G46: IL0010809858 | H46: ISIN | I46: מניות | J46: ישראל | K46: ישראל | L46: סחיר | M46: TASE | N46: מלונאות ותיירות | O46: לא | P46: ILS | Q46: 14685 | R46: 1 | S46: 13750 | T46: 0 | U46: 2019.1875 | V46: 0.00024450985 | W46: 0.00191731 | X46: =U46/'סכום נכסים'!$B$30 -> 0.00036353313
A47: 13908 | B47: 13908 | C47: איסתא בע"מ | D47: 520042763 | E47: ח.פ. | F47: איסתא | G47: IL0010810740 | H47: ISIN | I47: מניות | J47: ישראל | K47: ישראל | L47: סחיר | M47: TASE | N47: מלונאות ותיירות | O47: לא | P47: ILS | Q47: 13815 | R47: 1 | S47: 9248 | T47: 41.445 | U47: 1319.0562 | V47: 0.00082441126 | W47: 0.0012525036 | X47: =U47/'סכום נכסים'!$B$30 -> 0.00023748197
A48: 13908 | B48: 13908 | C48: אלביט מערכות בע"מ | D48: 520043027 | E48: ח.פ. | F48: אלביט מערכות | G48: IL0010811243 | H48: ISIN | I48: מניות | J48: ישראל | K48: ישראל | L48: סחיר | M48: TASE | N48: ביטחוניות | O48: לא | P48: ILS | Q48: 13007 | R48: 1 | S48: 226000 | T48: 38.74785 | U48: 29434.568 | V48: 0.00027763977 | W48: 0.027949456 | X48: =U48/'סכום נכסים'!$B$30 -> 0.0052993793
... A129: 13908 | B129: 13908 | C129: בתי זקוק לנפט בע"מ | D129: 520036658 | E129: ח.פ. | F129: בזן | G129: IL0025902482 | H129: ISIN | I129: מניות | J129: ישראל | K129: ישראל | L129: סחיר | M129: TASE | N129: אנרגיה | O129: לא | P129: ILS | Q129: 3058572 | R129: 1 | S129: 157.5 | T129: 0 | U129: 4817.2509 | V129: 0.00097996999 | W129: 0.0045741981 | X129: =U129/'סכום נכסים'!$B$30 -> 0.00086729453
A130: 13908 | B130: 13908 | C130: SOLAREDGE TECHNOLOGIES INC | D130: 5493000K6Y58XXPDF853 | E130: LEI | F130: SOLAREDGE TECHNOLOGIES INC | G130: US83417M1045 | H130: ISIN | I130: מניות | J130: חו"ל | K130: ארה"ב | L130: סחיר | M130: NASDAQ | N130: Semiconductors & Semiconductor Equipment | O130: לא | P130: USD | Q130: 5000 | R130: 2.978 | S130: 5844 | T130: 0 | U130: 870.1716 | V130: 8.221223e-05 | W130: 0.00082626737 | X130: =U130/'סכום נכסים'!$B$30 -> 0.00015666509
A131: 13908 | B131: 13908 | C131: ODDITY TECH LTD NO TRADE | D131: 254900QH12XZS53G0V57 | E131: LEI | F131: ODDITY TECH LTD NO TRADE | G131: IL0011974909 | H131: ISIN | I131: מניות | J131: חו"ל | K131: ישראל | L131: סחיר | M131: NASDAQ | N131: Software | O131: לא | P131: USD | Q131: 5542.55 | R131: 2.978 | S131: 1513 | T131: 0 | U131: 249.73145 | V131: 0 | W131: 0.00023713133 | X131: =U131/'סכום נכסים'!$B$30 -> 4.4961478e-05
A132: 13908 | B132: 13908 | C132: SHL TELEMEDICINE LTD | D132: 1729029 | E132: מספר תאגיד או שותפות בחו"ל | F132: SHL TELEMEDICINE LTD | G132: IL0010855885 | H132: ISIN | I132: מניות | J132: חו"ל | K132: שוויץ | L132: סחיר | M132: SIX | N132: Health Care Providers & Services | O132: לא | P132: CHF | Q132: 25000 | R132: 3.6802 | S132: 102 | T132: 0 | U132: 93.8451 | V132: 0.00067458274 | W132: 8.9110176e-05 | X132: =U132/'סכום נכסים'!$B$30 -> 1.6895807e-05
A133: 13908 | B133: 13908 | C133: PALO ALTO NETWORKS INC | D133: 549300QXR2YVZV231H43 | E133: LEI | F133: PALO ALTO NETWORKS INC | G133: US6974351057 | H133: ISIN | I133: מניות | J133: חו"ל | K133: ארה"ב | L133: סחיר | M133: NASDAQ | N133: Software | O133: לא | P133: USD | Q133: 7700 | R133: 2.978 | S133: 34102 | T133: 0 | U133: 7819.7932 | V133: 9.4478528e-06 | W133: 0.0074252481 | X133: =U133/'סכום נכסים'!$B$30 -> 0.0014078702
A134: 13908 | B134: 13908 | C134: ITHACA ENERGY PLC | D134: 213800CYKA4XE2HZZB09 | E134: LEI | F134: ITHACA ENERGY PLC | G134: GB00BPJHV584 | H134: ISIN | I134: מניות | J134: חו"ל | K134: ישראל | L134: סחיר | M134: LSE | N134: Energy Equipment & Services | O134: לא | P134: GBP | Q134: 770255 | R134: 3.9389 | S134: 217 | T134: 0 | U134: 6583.6876 | V134: 0.0004657676 | W134: 0.0062515098 | X134: =U134/'סכום נכסים'!$B$30 -> 0.0011853226
A135: 13908 | B135: 13908 | C135: SHL TELEMEDICINE LTD - RTS | D135: EQ0000000099507916 | E135: מספר תאגיד או שותפות בחו"ל | F135: RTS - LTD TELEMEDICINE SHL | G135: CH1501961093 | H135: ISIN | I135: מניות | J135: חו"ל | K135: שוויץ | L135: סחיר | M135: SIX | N135: Other | O135: לא | P135: CHF | Q135: 20754 | R135: 3.6802 | S135: 0.0001 | T135: 0 | U135: 0 | V135: 0.0012660472 | W135: 0 | X135: =U135/'סכום נכסים'!$B$30 -> 0
A136: 13908 | B136: 13908 | C136: CSG NV | D136: 315700RSAZS0EH10E702 | E136: LEI | F136: CSV NV | G136: NL0015073TS8 | H136: ISIN | I136: מניות | J136: חו"ל | K136: צכיה | L136: סחיר | M136: EURONEXT | N136: Industrial REITs | O136: לא | P136: EUR | Q136: 28350 | R136: 3.3945 | S136: 1277.4 | T136: 0 | U136: 1229.2941 | V136: 2.835e-05 | W136: 0.0011672704 | X136: =U136/'סכום נכסים'!$B$30 -> 0.00022132126

Sheet קרנות סל
A1: מספר קופה/קרן/ח.פ. עבור חברת ביטוח | B1: מספר מסלול | C1: שם מנפיק | D1: מספר מנפיק | E1: סוג מספר מזהה מנפיק | F1: שם נייר ערך | G1: מספר נייר ערך | H1: סוג מספר נייר ערך | I1: מאפיין עיקרי | J1: ישראל/חו"ל | K1: מדינה לפי חשיפה כלכלית | L1: זירת מסחר | M1: סיווג הקרן | N1: בעל עניין/צד קשור | O1: מטבע פעילות | P1: ערך נקוב (יחידות) | Q1: שער חליפין | R1: שער נייר הערך | S1: סכום לקבל (במטבע הפעילות) | T1: שווי הוגן (באלפי ש"ח) | U1: שיעור מערך נקוב מונפק | V1: שיעור מנכסי אפיק ההשקעה | W1: שיעור מסך נכסי ההשקעה
A2: 13908 | B2: 13908 | C2: מיטב קרנות נאמנות בע"מ | D2: 513534974 | E2: ח.פ. | F2: תכ.תא125 | G2: IL0011437188 | H2: ISIN | I2: עוקב אחר מדדי מניות בישראל | J2: ישראל | K2: ישראל | L2: TASE | M2: Large & Mid Cap מניות בארץ - מניות לפי שווי שוק-מניות | N2: לא | O2: ILS | P2: 1880000 | Q2: 1 | R2: 3930 | S2: 0 | T2: 73884 | U2: 0.0042841713 | V2: 0.17014892 | W2: =T2/'סכום נכסים'!$B$30 -> 0.013302024
A3: 13908 | B3: 13908 | C3: מיטב קרנות נאמנות בע"מ | D3: 513534974 | E3: ח.פ. | F3: תכ.תלבונד60 | G3: IL0011451015 | H3: ISIN | I3: עוקב אחר מדדים אחרים בישראל | J3: ישראל | K3: ישראל | L3: TASE | M3: 60 אג"ח בארץ - חברות והמרה-תל בונד צמוד מדד-תל בונד | N3: לא | O3: ILS | P3: 15040200 | Q3: 1 | R3: 407.77 | S3: 0 | T3: 61329.424 | U3: 0.011045029 | V3: 0.14123674 | W3: =T3/'סכום נכסים'!$B$30 -> 0.011041707
A4: 13908 | B4: 13908 | C4: קסם קרנות נאמנות בע"מ | D4: 510938608 | E4: ח.פ. | F4: קסם.תלבונד 20 צ | G4: IL0011459604 | H4: ISIN | I4: עוקב אחר מדדים אחרים בישראל | J4: ישראל | K4: ישראל | L4: TASE | M4: 20 אג"ח בארץ - חברות והמרה-תל בונד צמוד מדד-תל בונד | N4: לא | O4: ILS | P4: 3000 | Q4: 1 | R4: 4135.78 | S4: 0 | T4: 124.0734 | U4: 5.7499699e-05 | V4: 0.00028573107 | W4: =T4/'סכום נכסים'!$B$30 -> 2.2338089e-05
A5: 13908 | B5: 13908 | C5: קסם קרנות נאמנות בע"מ | D5: 510938608 | E5: ח.פ. | F5: STOX600.קסם | G5: IL0011462087 | H5: ISIN | I5: עוקב אחר מדדי מניות בחו"ל | J5: ישראל | K5: אירופה | L5: TASE | M5: מניות בחו"ל - מניות גיאוגרפי - חשופת מט"ח-אירופה - מדד אחר | N5: לא | O5: ILS | P5: 103320 | Q5: 1 | R5: 52590 | S5: 0 | T5: 54335.988 | U5: 0.052414773 | V5: 0.12513142 | W5: =T5/'סכום נכסים'!$B$30 -> 0.0097826138
A6: 13908 | B6: 13908 | C6: קסם קרנות נאמנות בע"מ | D6: 510938608 | E6: ח.פ. | F6: קסם.תלבונד 60 צ | G6: IL0011462327 | H6: ISIN | I6: עוקב אחר מדדים אחרים בישראל | J6: ישראל | K6: ישראל | L6: TASE | M6: אג"ח בארץ - חברות והמרה-תל בונד צמוד מדד-תל בונד צמודות | N6: לא | O6: ILS | P6: 1559524 | Q6: 1 | R6: 4056.02 | S6: 0 | T6: 63254.605 | U6: 0.021654101 | V6: 0.14567027 | W6: =T6/'סכום נכסים'!$B$30 -> 0.011388316
A7: 13908 | B7: 13908 | C7: אי.בי.אי קרנות נאמנות בעמ | D7: 513765339 | E7: ח.פ. | F7: IBI.תלבונד 60צד | G7: IL0011480063 | H7: ISIN | I7: עוקב אחר מדדים אחרים בישראל | J7: ישראל | K7: ישראל | L7: TASE | M7: 60 אג"ח בארץ - חברות והמרה-תל בונד צמוד מדד-תל בונד | N7: לא | O7: ILS | P7: 5495390 | Q7: 1 | R7: 408.38 | S7: 0 | T7: 22442.074 | U7: 0.0039974871 | V7: 0.051682293 | W7: =T7/'סכום נכסים'!$B$30 -> 0.0040404555
A8: 13908 | B8: 13908 | C8: אי.בי.אי קרנות נאמנות בעמ | D8: 513765339 | E8: ח.פ. | F8: IBI.תא 125 | G8: IL0011488082 | H8: ISIN | I8: עוקב אחר מדדי מניות בישראל | J8: ישראל | K8: ישראל | L8: TASE | M8: Large & Mid Cap מניות בארץ - מניות לפי שווי שוק-מניות | N8: לא | O8: ILS | P8: 160000 | Q8: 1 | R8: 3889 | S8: 0 | T8: 6222.4 | U8: 0.00039873037 | V8: 0.014329687 | W8: =T8/'סכום נכסים'!$B$30 -> 0.0011202766
A9: 13908 | B9: 13908 | C9: הראל קרנות נאמנות בע"מ | D9: 511776783 | E9: ח.פ. | F9: SP500.הרל | G9: IL0011490203 | H9: ISIN | I9: עוקב אחר מדדי מניות בחו"ל | J9: ישראל | K9: ארה"ב | L9: TASE | M9: S&P 500 - מניות בחו"ל - מניות גיאוגרפי - מנוטרלת מט"ח-ארה"ב | N9: לא | O9: ILS | P9: 145764 | Q9: 1 | R9: 2600 | S9: 0 | T9: 3789.864 | U9: 0.00038481711 | V9: 0.0087277523 | W9: =T9/'סכום נכסים'!$B$30 -> 0.0006823245
A10: 13908 | B10: 13908 | C10: מגדל קרנות נאמנות בע"מ | D10: 511303661 | E10: ח.פ. | F10: MTF.תא125 | G10: IL0011502833 | H10: ISIN | I10: עוקב אחר מדדי מניות בישראל | J10: ישראל | K10: ישראל | L10: TASE | M10: Large & Mid Cap מניות בארץ - מניות לפי שווי שוק-מניות | N10: לא | O10: ILS | P10: 5000 | Q10: 1 | R10: 6154 | S10: 0 | T10: 307.7 | U10: 4.7619048e-05 | V10: 0.00070860838 | W10: =T10/'סכום נכסים'!$B$30 -> 5.5398096e-05
A11: 13908 | B11: 13908 | C11: מגדל קרנות נאמנות בע"מ | D11: 511303661 | E11: ח.פ. | F11: SP500.MTF | G11: IL0011503336 | H11: ISIN | I11: עוקב אחר מדדי מניות בחו"ל | J11: ישראל | K11: ארה"ב | L11: TASE | M11: S&P 500 - מניות בחו"ל - מניות גיאוגרפי - חשופת מט"ח-ארה"ב | N11: לא | O11: ILS | P11: 12400 | Q11: 1 | R11: 9608 | S11: 0 | T11: 1191.392 | U11: 0.00014203895 | V11: 0.0027436801 | W11: =T11/'סכום נכסים'!$B$30 -> 0.00021449739
A12: 13908 | B12: 13908 | C12: הראל קרנות נאמנות בע"מ | D12: 511776783 | E12: ח.פ. | F12: הרל.תלבד- 60 צמ | G12: IL0011504730 | H12: ISIN | I12: עוקב אחר מדדים אחרים בישראל | J12: ישראל | K12: ישראל | L12: TASE | M12: אג"ח בארץ - חברות והמרה-תל בונד צמוד מדד-תל בונד צמודות | N12: לא | O12: ILS | P12: 5205892 | Q12: 1 | R12: 406.34 | S12: 0 | T12: 21153.622 | U12: 0.016850115 | V12: 0.048715091 | W12: =T12/'סכום נכסים'!$B$30 -> 0.0038084834
A13: 13908 | B13: 13908 | C13: קסם קרנות נאמנות בע"מ | D13: 510938608 | E13: ח.פ. | F13: קסם.תלבונד ש 50 | G13: IL0011507626 | H13: ISIN | I13: עוקב אחר מדדים אחרים בישראל | J13: ישראל | K13: ישראל | L13: TASE | M13: אג"ח בארץ - חברות והמרה-תל בונד שקלי-תל בונד- שקלי | N13: לא | O13: ILS | P13: 714515 | Q13: 1 | R13: 4502.02 | S13: 0 | T13: 32167.608 | U13: 0.018313036 | V13: 0.074079417 | W13: =T13/'סכום נכסים'!$B$30 -> 0.005791434
... A17: 13908 | B17: 13908 | C17: קסם קרנות נאמנות בע"מ | D17: 510938608 | E17: ח.פ. | F17: CSI300.קסם | G17: IL0011627838 | H17: ISIN | I17: עוקב אחר מדדי מניות בחו"ל | J17: ישראל | K17: סין | L17: TASE | M17: מניות בחו"ל - מניות גיאוגרפי - חשופת מט"ח-אסיה - מדד אחר | N17: לא | O17: ILS | P17: 3801 | Q17: 1 | R17: 28170 | S17: 0 | T17: 1070.7417 | U17: 0.0013229382 | V17: 0.0024658321 | W17: =T17/'סכום נכסים'!$B$30 -> 0.0001927756
A18: 13908 | B18: 13908 | C18: Invesco QQQ Trust Series 1 | D18: ECPGFXU8A2SHKVVGJI15 | E18: LEI | F18: INVESCO QQQ TRUST SERIES 1 | G18: US46090E1038 | H18: ISIN | I18: עוקב אחר מדדי מניות בחו"ל | J18: חו"ל | K18: ארה"ב | L18: NASDAQ | M18: Equity Funds | N18: לא | O18: USD | P18: 750 | Q18: 2.978 | R18: 73640 | S18: 0.61012089 | T18: 1646.5663 | U18: 1.1269722e-06 | V18: 0.00379191 | W18: =T18/'סכום נכסים'!$B$30 -> 0.00029644667
A19: 13908 | B19: 13908 | C19: ISHARES EXPANDED TECH-SOFTWA | D19: 529900VBK42Y5HHRMD23 | E19: LEI | F19: ISHARES SEMICONDUCTOR | G19: US4642875235 | H19: ISIN | I19: עוקב אחר מדדי מניות בחו"ל | J19: חו"ל | K19: ארה"ב | L19: NASDAQ | M19: Equity Funds | N19: לא | O19: USD | P19: 3330 | Q19: 2.978 | R19: 64076 | S19: 0 | T19: 6354.2503 | U19: 4.4608171e-05 | V19: 0.014633328 | W19: =T19/'סכום נכסים'!$B$30 -> 0.0011440148
A20: 13908 | B20: 13908 | C20: Ishares iBoxx $ Investment | D20: 78005 | E20: מספר מנפיק | F20: ISHARES IBOXX H/Y CORP BOND | G20: US4642885135 | H20: ISIN | I20: עוקב אחר מדדים אחרים בחו"ל | J20: חו"ל | K20: ארה"ב | L20: NYSE | M20: Bond/Fixed Income Funds | N20: לא | O20: USD | P20: 42400 | Q20: 2.978 | R20: 7997 | S20: 0 | T20: 10097.588 | U20: 0.00019220308 | V20: 0.023253934 | W20: =T20/'סכום נכסים'!$B$30 -> 0.0018179628

Sheet קרנות נאמנות
A1: מספר קופה/קרן/ח.פ. עבור חברת ביטוח | B1: מספר מסלול | C1: שם מנפיק | D1: מספר מנפיק | E1: סוג מספר מזהה מנפיק | F1: שם נייר ערך | G1: מספר נייר ערך | H1: סוג מספר נייר ערך | I1: מאפיין עיקרי | J1: ישראל/חו"ל | K1: מדינה לפי חשיפה כלכלית | L1: סטאטוס סחירות | M1: זירת מסחר | N1: סיווג הקרן | O1: בעל עניין/צד קשור | P1: מטבע פעילות | Q1: ערך נקוב (יחידות) | R1: שער חליפין | S1: שער נייר הערך | T1: שווי הוגן (באלפי ש"ח) | U1: שיעור מערך נקוב מונפק | V1: שיעור מנכסי אפיק ההשקעה | W1: שיעור מסך נכסי ההשקעה
A2: 13908 | B2: 13908 | C2: מיטב קרנות נאמנות בע"מ | D2: 513534974 | E2: ח.פ. | F2: SP 500 תכלית | G2: IL0051139983 | H2: ISIN | I2: מניות | J2: ישראל | K2: ארה"ב | L2: סחיר | M2: TASE | N2: S&P 500 - מניות בחו"ל - מניות גיאוגרפי - חשופת מט"ח-ארה"ב | O2: לא | P2: ILS | Q2: 16874000 | R2: 1 | S2: 792.53 | T2: 133731.51 | U2: 0.013597696 | V2: 0.19861317 | W2: =T2/'סכום נכסים'!$B$30 -> 0.024076929
A3: 13908 | B3: 13908 | C3: מיטב קרנות נאמנות בע"מ | D3: 513534974 | E3: ח.פ. | F3: תכלית ת"א 125 | G3: IL0051146574 | H3: ISIN | I3: מניות | J3: ישראל | K3: ישראל | L3: סחיר | M3: TASE | N3: Large & Mid Cap מניות בארץ - מניות לפי שווי שוק-מניות | O3: לא | P3: ILS | Q3: 20431000 | R3: 1 | S3: 353.59 | T3: 72241.973 | U3: 0.008316307 | V3: 0.10729115 | W3: =T3/'סכום נכסים'!$B$30 -> 0.013006395
A4: 13908 | B4: 13908 | C4: מיטב קרנות נאמנות בע"מ | D4: 513534974 | E4: ח.פ. | F4: תכ.TTFתלבונד20 | G4: IL0051154727 | H4: ISIN | I4: אג"ח קונצרני | J4: ישראל | K4: ישראל | L4: סחיר | M4: TASE | N4: 20 אג"ח בארץ - חברות והמרה-תל בונד צמוד מדד-תל בונד | O4: לא | P4: ILS | Q4: 43850136 | R4: 1 | S4: 113.54 | T4: 49787.444 | U4: 0.22278908 | V4: 0.073942498 | W4: =T4/'סכום נכסים'!$B$30 -> 0.0089636972
A5: 13908 | B5: 13908 | C5: קסם קרנות נאמנות בע"מ | D5: 510938608 | E5: ח.פ. | F5: קסם תל בונד 20 | G5: IL0051155898 | H5: ISIN | I5: אג"ח קונצרני | J5: ישראל | K5: ישראל | L5: סחיר | M5: TASE | N5: 20 אג"ח בארץ - חברות והמרה-תל בונד צמוד מדד-תל בונד | O5: לא | P5: ILS | Q5: 19016000 | R5: 1 | S5: 155.66 | T5: 29600.306 | U5: 0.058702184 | V5: 0.043961295 | W5: =T5/'סכום נכסים'!$B$30 -> 0.0053292186
A6: 13908 | B6: 13908 | C6: הראל קרנות נאמנות בע"מ | D6: 511776783 | E6: ח.פ. | F6: הרל.תלבנד 20 צמ | G6: IL0051172703 | H6: ISIN | I6: אג"ח קונצרני | J6: ישראל | K6: ישראל | L6: סחיר | M6: TASE | N6: אג"ח בארץ - חברות והמרה-תל בונד צמוד מדד-תל בונד צמודות | O6: לא | P6: ILS | Q6: 34768000 | R6: 1 | S6: 151.47 | T6: 52663.09 | U6: 0.051118812 | V6: 0.078213302 | W6: =T6/'סכום נכסים'!$B$30 -> 0.0094814263
A7: 13908 | B7: 13908 | C7: מגדל קרנות נאמנות בע"מ | D7: 511303661 | E7: ח.פ. | F7: S&P 500 מח MTF | G7: IL0051226277 | H7: ISIN | I7: מניות | J7: ישראל | K7: ארה"ב | L7: סחיר | M7: TASE | N7: S&P 500 - מניות בחו"ל - מניות גיאוגרפי - חשופת מט"ח-ארה"ב | O7: לא | P7: ILS | Q7: 31459071 | R7: 1 | S7: 319.28 | T7: 100442.52 | U7: 0.016070705 | V7: 0.14917357 | W7: =T7/'סכום נכסים'!$B$30 -> 0.018083602
A8: 13908 | B8: 13908 | C8: קסם קרנות נאמנות בע"מ | D8: 510938608 | E8: ח.פ. | F8: S&P 500 קסם | G8: IL0051244825 | H8: ISIN | I8: מניות | J8: ישראל | K8: ארה"ב | L8: סחיר | M8: TASE | N8: S&P 500 - מניות בחו"ל - מניות גיאוגרפי - חשופת מט"ח-ארה"ב | O8: לא | P8: ILS | Q8: 23113000 | R8: 1 | S8: 303.78 | T8: 70212.671 | U8: 0.0060566678 | V8: 0.1042773 | W8: =T8/'סכום נכסים'!$B$30 -> 0.012641041
A9: 13908 | B9: 13908 | C9: אי.בי.אי קרנות נאמנות בעמ | D9: 513765339 | E9: ח.פ. | F9: S&P 500י.IBI | G9: IL0051274699 | H9: ISIN | I9: מניות | J9: ישראל | K9: ארה"ב | L9: סחיר | M9: TASE | N9: S&P 500 - מניות בחו"ל - מניות גיאוגרפי - חשופת מט"ח-ארה"ב | O9: לא | P9: ILS | Q9: 17528160 | R9: 1 | S9: 250.35 | T9: 43881.749 | U9: 0.014784492 | V9: 0.065171574 | W9: =T9/'סכום נכסים'!$B$30 -> 0.0079004398
A10: 13908 | B10: 13908 | C10: אי.בי.אי קרנות נאמנות בעמ | D10: 513765339 | E10: ח.פ. | F10: NASDAQ 100י.IBI | G10: IL0051277668 | H10: ISIN | I10: מניות | J10: ישראל | K10: ארה"ב | L10: סחיר | M10: TASE | N10: NASDAQ 100 - מניות בחו"ל - מניות גיאוגרפי - מנוטרלת מט"ח-ארה"ב | O10: לא | P10: ILS | Q10: 13119174 | R10: 1 | S10: 343.68 | T10: 45087.977 | U10: 0.017008663 | V10: 0.066963021 | W10: =T10/'סכום נכסים'!$B$30 -> 0.0081176083
A11: 13908 | B11: 13908 | C11: הראל קרנות נאמנות בע"מ | D11: 511776783 | E11: ח.פ. | F11: NASDAQ 100 הראל | G11: IL0051292832 | H11: ISIN | I11: מניות | J11: ישראל | K11: ארה"ב | L11: סחיר | M11: TASE | N11: מניות בחו"ל - מניות גיאוגרפי - חשופת מט"ח-ארה"ב - מדד אחר | O11: לא | P11: ILS | Q11: 13860000 | R11: 1 | S11: 360.67 | T11: 49988.862 | U11: 0.0093238609 | V11: 0.074241636 | W11: =T11/'סכום נכסים'!$B$30 -> 0.0089999603
A12: 13908 | B12: 13908 | C12: אי.בי.אי קרנות נאמנות בעמ | D12: 513765339 | E12: ח.פ. | F12: STOXX-E600י.IBI | G12: IL0051307523 | H12: ISIN | I12: מניות | J12: ישראל | K12: אירופה | L12: סחיר | M12: TASE | N12: STOXX EUROPE 600 - מניות בחו"ל - מניות גיאוגרפי - מנוטרלת מט"ח-אירופה כללי | O12: לא | P12: ILS | Q12: 15622700 | R12: 1 | S12: 164.43 | T12: 25688.406 | U12: 0.10761057 | V12: 0.038151484 | W12: =T12/'סכום נכסים'!$B$30 -> 0.0046249228

Sheet כתבי אופציה
A1: מספר קופה/קרן/ח.פ. עבור חברת ביטוח | B1: מספר מסלול | C1: שם מנפיק | D1: מספר מנפיק | E1: סוג מספר מזהה מנפיק | F1: שם נייר ערך | G1: מספר נייר ערך | H1: סוג מספר נייר ערך | I1: ישראל/חו"ל | J1: מדינה לפי חשיפה כלכלית | K1: סטאטוס סחירות | L1: זירת מסחר | M1: נכס בסיס (כתב אופציה) | N1: ענף מסחר | O1: תאריך פקיעה | P1: בעל עניין/צד קשור | Q1: מטבע פעילות | R1: שער מימוש | S1: יחס המרה | T1: ערך נקוב (יחידות) | U1: שער חליפין | V1: שער נייר הערך | W1: שווי הוגן (באלפי ש"ח) | X1: שיעור מנכסי אפיק ההשקעה | Y1: שיעור מסך נכסי ההשקעה
A2: 13908 | B2: 13908 | C2: אלומיי קפיטל בע"מ | D2: 520039868 | E2: ח.פ. | F2: אלומיי אפ 2 | G2: IL0012030826 | H2: ISIN | I2: ישראל | J2: ישראל | K2: סחיר | L2: TASE | M2: IL0010826357 | N2: אנרגיה מתחדשת | O2: 46757 | P2: לא | Q2: ILS | R2: 8000 | S2: 1 | T2: 2304 | U2: 1 | V2: 513.4 | W2: 11.82874 | X2: 0.0025446949 | Y2: =W2/'סכום נכסים'!$B$30 -> 2.1296382e-06
A3: 13908 | B3: 13908 | C3: מיטב טרייד השקעות בע"מ | D3: 516854239 | E3: ח.פ. | F3: מיטב טרייד אפ 1 | G3: IL0012031998 | H3: ISIN | I3: ישראל | J3: ישראל | K3: סחיר | L3: TASE | M3: IL0012031816 | N3: שרותים פיננסיים | O3: 46770 | P3: לא | Q3: ILS | R3: 673.666 | S3: 1 | T3: 192000 | U3: 1 | V3: 1846 | W3: 3544.32 | X3: 0.76248299 | Y3: =W3/'סכום נכסים'!$B$30 -> 0.00063811693
A4: 13908 | B4: 13908 | C4: שובל הנדסה ובניין בע"מ | D4: 512951518 | E4: ח.פ. | F4: שובל הנדסה אפ 1 | G4: IL0012159617 | H4: ISIN | I4: ישראל | J4: ישראל | K4: סחיר | L4: TASE | M4: IL0012079682 | N4: בנייה | O4: 46398 | P4: לא | Q4: ILS | R4: 1023 | S4: 1 | T4: 2500 | U4: 1 | V4: 53 | W4: 1.325 | X4: 0.00028504479 | Y4: =W4/'סכום נכסים'!$B$30 -> 2.3855209e-07
