Workbook
Name Companies: #REF!
Name Company_Name: הנחיות!$M$3:$M$27
Name Date_Current: [1]Config!$C$6
Name Date_Current_1: [2]Config!$C$8
Name date1: [3]Information!$R$4
Name date2: [3]Information!$R$3
Name date3: [3]Information!$R$2
Name Period: #REF!
Name Quarter: הנחיות!$J$4:$J$7
Name Year: הנחיות!$I$4:$I$19
Name yearA: [3]Information!$S$4
Name yearB: [3]Information!$S$3

Sheet הנחיות
A1: סוג דיווח | B1: מספר הערה | C1: עמודה | D1: הנחיה | M1: NostroYield_B
A2: הנחיות כלליות לדיווח | B2: 1 | C2: מטרה | D2: דיווח בגין יתרות הנכסים הרבעוניות של חברות ביטוח בציון תרומתו של כל אפיק השקעה להכנסות מהשקעות בגין התחייבויות אלו. | K2: =RIGHT(J3,2) -> 22 | L2: =VLOOKUP(B22,J4:K7,2,0) -> 3 | M2: =C3 -> מועד דיווח | N2: =VLOOKUP($B$21,$M$3:$O$27,2,0) -> Clal | O2: =VLOOKUP($B$21,$M$3:$O$27,3,0) -> 520024647
B3: 2 | C3: מועד דיווח | D3: במקביל למועדי פרסום רשימת נכסים ברמת הנכס הבודד באתר החברה. | I3: Year | J3: =B20 -> 2022 | M3: דוח תשואה נוסטרו | N3: Nostro | O3: 123456789
B4: 3 | C4: קובץ הדיווח | D4: לפני כל הגשת דיווח, יש להוריד מהאתר קובץ דיווח מעודכן. לא יתקבל קובץ סרוק או מועתק משנה אחרת, קובץ שנבנה באופן עצמאי או קובץ PDF. | I4: 2022 | J4: =CONCATENATE($L$4,RIGHT($J$3,2)) -> 31.03.22 | K4: 1 | L4: 31.03. | M4: איי.אי.ג'י נוסטרו | N4: AIG | O4: 512304882
B5: 4 | C5: שם הקובץ | D5: NostroYield_B_xxxxxxxxx_qyy.xlsx | I5: =I4+1 -> 2023 | J5: =CONCATENATE($L$5,RIGHT($J$3,2)) -> 30.06.22 | K5: 2 | L5: 30.06. | M5: איילון ביטוח נוסטרו | N5: Ayalon | O5: 520030677
D6: NostroYield | I6: =I5+1 -> 2024 | J6: =CONCATENATE($L$6,RIGHT($J$3,2)) -> 30.09.22 | K6: 3 | L6: 30.09. | M6: אשרא נוסטרו | N6: Ashra | O6: 520021916
D7: מציין שמדובר בדיווח של חברת ביטוח B | I7: =I6+1 -> 2025 | J7: =CONCATENATE($L$7,RIGHT($J$3,2)) -> 31.12.22 | K7: 4 | L7: 31.12. | M7: ביטוח חקלאי נוסטרו | N7: Haklai | O7: 570003152
D8: מציין את מספר ח.פ. של החברה xxxxxxxxx | I8: =I7+1 -> 2026 | K8: =K4 -> 1 | M8: ביטוח ישיר נוסטרו | N8: Dirin | O8: 513910703
D9: ציון מספר הרבעון המדווח (1,2,3,4) - q | I9: =I8+1 -> 2027 | K9: =K5 -> 2 | M9: בססח נוסטרו | N9: BSSCH | O9: 520044025
D10: yy - ציון השנה המדווחת | I10: =I9+1 -> 2028 | K10: =K6 -> 3 | M10: דיוויד שילד | N10: David | O10: 515859379
D11: סיומת הקובץ תהיה .xlsx | I11: =I10+1 -> 2029 | K11: =K7 -> 4 | M11: הכשרה ביטוח נוסטרו | N11: ILD | O11: 520042177
D12: לדוגמה, שם קובץ של חברת ביטוח בגין דיווח עבור רבעון שלישי שנת 2022 | I12: =I11+1 -> 2030 | K12: =K8 -> 1 | M12: הפניקס ביטוח נוסטרו | N12: Pheonix | O12: 520023185
D13: NostroYield_B_123456789_322 | I13: =I12+1 -> 2031 | K13: =K9 -> 2 | M13: הראל ביטוח נוסטרו | N13: Harel | O13: 520004078
B14: 5 | C14: אופן הדיווח | D14: באמצעות פורטל אותות. | I14: =I13+1 -> 2032 | K14: =K10 -> 3 | M14: ווישור נוסטרו | N14: Wesure | O14: 515764868
A15: הנחיות לעניין אופן הזנת נתונים | B15: 6 | D15: ערכים בשקלים ידווחו באלפי ₪. | I15: =I14+1 -> 2033 | K15: =K11 -> 4 | M15: כלל אשראי נוסטרו | N15: Credit | O15: 510888985
B16: 7 | D16: שיעור תרומה ידווח באחוזים. | I16: =I15+1 -> 2034 | K16: =K12 -> 1 | M16: כלל ביטוח נוסטרו | N16: Clal | O16: 520024647
B17: 8 | D17: חברות ללא התחייבויות בביטוח חיים גיליון כללי והון יהיה שווה לגיליון סה"כ נוסטרו. | I17: =I16+1 -> 2035 | K17: =K13 -> 2 | M17: ליבורה נוסטרו | N17: Libra | O17: 515761625
I18: =I17+1 -> 2036 | K18: =K14 -> 3 | M18: מגדל ביטוח נוסטרו | N18: Migdal | O18: 520004896
I19: =I18+1 -> 2037 | K19: =K15 -> 4 | M19: מנורה ביטוח נוסטרו | N19: Menorah | O19: 520042540
A20: דיווח לשנת | B20: 2022 | M20: עזר נוסטרו | N20: Ezer | O20: 512310509
A21: חברה | B21: כלל ביטוח נוסטרו | M21: ענבל נוסטרו | N21: Ynbal | O21: 520031030
A22: תקופה | B22: 30.09.22 | M22: קרן נזקי טבע נוסטרו | N22: Teva | O22: 520027848
A23: שם הקובץ לשמירה | B23: =CONCATENATE("NostroYield_B_",O2,J20,"_",L2,K2,".xlsx") -> NostroYield_B_520024647_322.xlsx | M23: קרנית נוסטרו | N23: Karnit | O23: 500500376
M24: ש שלמה נוסטרו | N24: Shlomo | O24: 513879189
M25: שומרה נוסטרו | N25: Shomera | O25: 510015951
M26: חברה חדשה | N26: New | O26: 123456789
M27: חברה חדשה | N27: New | O27: 123456789

Sheet נוסטרו חיים
B1: פירוט תרומת אפיקי ההשקעה לתשואה הכוללת
B2: =הנחיות!B21 -> כלל ביטוח נוסטרו
B3: נוסטרו חיים | C3: פירוט תרומת אפיקי השקעה בגין התחייבויות מסוג 10,30,50
B5: נתונים לרבעון בשנת : | C5: רבעון 1 | I5: רבעון 2 | O5: רבעון 3 | U5: רבעון 4
B6: =CONCATENATE("20",RIGHT(הנחיות!B20,2)) -> 2022 | C6: תרומה להכנסות מהשקעות (רווח/הפסד) | E6: תרומה להכנסה הכוללת (הון עצמי) | G6: סך נכסים | I6: תרומה להכנסות מהשקעות (רווח/הפסד) | K6: תרומה להכנסה הכוללת (הון עצמי) | M6: סך נכסים | O6: תרומה להכנסות מהשקעות (רווח/הפסד) | Q6: תרומה להכנסה הכוללת (הון עצמי) | S6: סך נכסים | U6: תרומה להכנסות מהשקעות (רווח/הפסד) | W6: תרומה להכנסה הכוללת (הון עצמי) | Y6: סך נכסים
C7: (באלפי ש"ח) | D7: (באחוזים) | E7: (באלפי ש"ח) | F7: (באחוזים) | G7: (באלפי ש"ח) | H7: (באחוזים) | I7: (באלפי ש"ח) | J7: (באחוזים) | K7: (באלפי ש"ח) | L7: (באחוזים) | M7: (באלפי ש"ח) | N7: (באחוזים) | O7: (באלפי ש"ח) | P7: (באחוזים) | Q7: (באלפי ש"ח) | R7: (באחוזים) | S7: (באלפי ש"ח) | T7: (באחוזים) | U7: (באלפי ש"ח) | V7: (באחוזים) | W7: (באלפי ש"ח) | X7: (באחוזים) | Y7: (באלפי ש"ח) | Z7: (באחוזים)
B8: מזומנים ושווי מזומנים | C8: 634 | D8: =IFERROR(C8/C$23,"") -> 0.0014305216 | E8: 634 | F8: =IFERROR(E8/E$23,"") -> 0.0014783965 | G8: 604211.28 | H8: =IFERROR(G8/G$23,"") -> 0.025760387 | I8: 12120 | J8: =IFERROR(I8/I$23,"") -> 0.028515165 | K8: 12120 | L8: =IFERROR(K8/K$23,"") -> 0.024718249 | M8: 624211.28 | N8: =IFERROR(M8/M$23,"") -> 0.026535682 | O8: 4807 | P8: =IFERROR(O8/O$23,"") -> 0.011805387 | Q8: 4807 | R8: =IFERROR(Q8/Q$23,"") -> 0.011292626 | S8: 653879.28 | T8: =IFERROR(S8/S$23,"") -> 0.027434738 | V8: =IFERROR(U8/U$23,"") | X8: =IFERROR(W8/W$23,"") | Z8: =IFERROR(Y8/Y$23,"")
B9: אג"ח ממשלתיות סחירות | C9: 1469 | D9: =IFERROR(C9/C$23,"") -> 0.0033145681 | E9: -2391 | F9: =IFERROR(E9/E$23,"") -> -0.005575467 | G9: 161367 | H9: =IFERROR(G9/G$23,"") -> 0.0068798391 | I9: 2219 | J9: =IFERROR(I9/I$23,"") -> 0.005220722 | K9: -2371 | L9: =IFERROR(K9/K$23,"") -> -0.0048355584 | M9: 142810 | N9: =IFERROR(M9/M$23,"") -> 0.0060709585 | O9: 1224 | P9: =IFERROR(O9/O$23,"") -> 0.0030059899 | Q9: -2128 | R9: =IFERROR(Q9/Q$23,"") -> -0.0049991073 | S9: 105428 | T9: =IFERROR(S9/S$23,"") -> 0.0044234305 | V9: =IFERROR(U9/U$23,"") | X9: =IFERROR(W9/W$23,"") | Z9: =IFERROR(Y9/Y$23,"")
B10: אג"ח מיועדות | C10: 333836 | D10: =IFERROR(C10/C$23,"") -> 0.75324857 | E10: 333836 | F10: =IFERROR(E10/E$23,"") -> 0.77845738 | G10: 14032048 | H10: =IFERROR(G10/G$23,"") -> 0.59825263 | I10: 444623 | J10: =IFERROR(I10/I$23,"") -> 1.0460807 | K10: 444623 | L10: =IFERROR(K10/K$23,"") -> 0.90679058 | M10: 13965497 | N10: =IFERROR(M10/M$23,"") -> 0.59368359 | O10: 343868 | P10: =IFERROR(O10/O$23,"") -> 0.84449651 | Q10: 343868 | R10: =IFERROR(Q10/Q$23,"") -> 0.80781627 | S10: 14305070 | T10: =IFERROR(S10/S$23,"") -> 0.60019618 | V10: =IFERROR(U10/U$23,"") | X10: =IFERROR(W10/W$23,"") | Z10: =IFERROR(Y10/Y$23,"")
B11: אג"ח קונצרניות סחירות | C11: 23835 | D11: =IFERROR(C11/C$23,"") -> 0.053779939 | E11: -32908 | F11: =IFERROR(E11/E$23,"") -> -0.076736708 | G11: 734842 | H11: =IFERROR(G11/G$23,"") -> 0.031329793 | I11: 13422 | J11: =IFERROR(I11/I$23,"") -> 0.031578427 | K11: -15932 | L11: =IFERROR(K11/K$23,"") -> -0.032492668 | M11: 851785 | N11: =IFERROR(M11/M$23,"") -> 0.036210009 | O11: 9450 | P11: =IFERROR(O11/O$23,"") -> 0.02320801 | Q11: -21192 | R11: =IFERROR(Q11/Q$23,"") -> -0.049784343 | S11: 825600 | T11: =IFERROR(S11/S$23,"") -> 0.034639605 | V11: =IFERROR(U11/U$23,"") | X11: =IFERROR(W11/W$23,"") | Z11: =IFERROR(Y11/Y$23,"")
B12: אג"ח קונצרניות לא סחירות | C12: 6537 | D12: =IFERROR(C12/C$23,"") -> 0.014749715 | E12: 6537 | F12: =IFERROR(E12/E$23,"") -> 0.015243341 | G12: 221917 | H12: =IFERROR(G12/G$23,"") -> 0.0094613723 | I12: 8780 | J12: =IFERROR(I12/I$23,"") -> 0.020657025 | K12: 8780 | L12: =IFERROR(K12/K$23,"") -> 0.017906454 | M12: 223202 | N12: =IFERROR(M12/M$23,"") -> 0.0094884818 | O12: 6116 | P12: =IFERROR(O12/O$23,"") -> 0.015020126 | Q12: 6116 | R12: =IFERROR(Q12/Q$23,"") -> 0.014367735 | S12: 213642 | T12: =IFERROR(S12/S$23,"") -> 0.0089637529 | V12: =IFERROR(U12/U$23,"") | X12: =IFERROR(W12/W$23,"") | Z12: =IFERROR(Y12/Y$23,"")
B13: מניות | C13: 1275 | D13: =IFERROR(C13/C$23,"") -> 0.0028768375 | E13: 5657 | F13: =IFERROR(E13/E$23,"") -> 0.013191308 | G13: 430853 | H13: =IFERROR(G13/G$23,"") -> 0.018369303 | I13: 9853 | J13: =IFERROR(I13/I$23,"") -> 0.023181511 | K13: 6036 | L13: =IFERROR(K13/K$23,"") -> 0.012310177 | M13: 464681 | N13: =IFERROR(M13/M$23,"") -> 0.019753932 | O13: 3203 | P13: =IFERROR(O13/O$23,"") -> 0.0078661647 | Q13: 65711 | R13: =IFERROR(Q13/Q$23,"") -> 0.15436858 | S13: 507031 | T13: =IFERROR(S13/S$23,"") -> 0.021273442 | V13: =IFERROR(U13/U$23,"") | X13: =IFERROR(W13/W$23,"") | Z13: =IFERROR(Y13/Y$23,"")
B14: תעודות סל | C14: -17763 | D14: =IFERROR(C14/C$23,"") -> -0.040079423 | E14: -23019 | F14: =IFERROR(E14/E$23,"") -> -0.053676987 | G14: 448290 | H14: =IFERROR(G14/G$23,"") -> 0.019112725 | I14: -1375 | J14: =IFERROR(I14/I$23,"") -> -0.0032350125 | K14: -29057 | L14: =IFERROR(K14/K$23,"") -> -0.059260574 | M14: 371993 | N14: =IFERROR(M14/M$23,"") -> 0.015813697 | O14: -50295 | P14: =IFERROR(O14/O$23,"") -> -0.12351819 | Q14: -18398 | R14: =IFERROR(Q14/Q$23,"") -> -0.043220665 | S14: 331610 | T14: =IFERROR(S14/S$23,"") -> 0.013913323 | V14: =IFERROR(U14/U$23,"") | X14: =IFERROR(W14/W$23,"") | Z14: =IFERROR(Y14/Y$23,"")
B15: קרנות נאמנות | C15: 6736 | D15: =IFERROR(C15/C$23,"") -> 0.015198727 | E15: 6736 | F15: =IFERROR(E15/E$23,"") -> 0.01570738 | G15: 138609 | H15: =IFERROR(G15/G$23,"") -> 0.0059095578 | I15: 8418 | J15: =IFERROR(I15/I$23,"") -> 0.019805335 | K15: 8418 | L15: =IFERROR(K15/K$23,"") -> 0.01716817 | M15: 63980 | N15: =IFERROR(M15/M$23,"") -> 0.002719837 | O15: 1291 | P15: =IFERROR(O15/O$23,"") -> 0.0031705334 | Q15: 1291 | R15: =IFERROR(Q15/Q$23,"") -> 0.0030328231 | S15: 20957 | T15: =IFERROR(S15/S$23,"") -> 0.00087929045 | V15: =IFERROR(U15/U$23,"") | X15: =IFERROR(W15/W$23,"") | Z15: =IFERROR(Y15/Y$23,"")
B16: הלוואות | C16: 69689 | D16: =IFERROR(C16/C$23,"") -> 0.1572423 | E16: 69689 | F16: =IFERROR(E16/E$23,"") -> 0.16250469 | G16: 3674686 | H16: =IFERROR(G16/G$23,"") -> 0.15666926 | I16: 108369 | J16: =IFERROR(I16/I$23,"") -> 0.25496369 | K16: 108369 | L16: =IFERROR(K16/K$23,"") -> 0.22101418 | M16: 3880900 | N16: =IFERROR(M16/M$23,"") -> 0.16497992 | O16: 81693 | P16: =IFERROR(O16/O$23,"") -> 0.20062772 | Q16: 81693 | R16: =IFERROR(Q16/Q$23,"") -> 0.19191357 | S16: 4004118 | T16: =IFERROR(S16/S$23,"") -> 0.16800032 | V16: =IFERROR(U16/U$23,"") | X16: =IFERROR(W16/W$23,"") | Z16: =IFERROR(Y16/Y$23,"")
B17: פיקדונות (שאינם מובנים) | C17: 6628 | D17: =IFERROR(C17/C$23,"") -> 0.014955042 | E17: 6628 | F17: =IFERROR(E17/E$23,"") -> 0.01545554 | G17: 330428 | H17: =IFERROR(G17/G$23,"") -> 0.01408771 | I17: 9090 | J17: =IFERROR(I17/I$23,"") -> 0.021386373 | K17: 9090 | L17: =IFERROR(K17/K$23,"") -> 0.018538687 | M17: 332752 | N17: =IFERROR(M17/M$23,"") -> 0.014145533 | O17: 6618 | P17: =IFERROR(O17/O$23,"") -> 0.016252975 | Q17: 6618 | R17: =IFERROR(Q17/Q$23,"") -> 0.015547036 | S17: 327463 | T17: =IFERROR(S17/S$23,"") -> 0.013739328 | V17: =IFERROR(U17/U$23,"") | X17: =IFERROR(W17/W$23,"") | Z17: =IFERROR(Y17/Y$23,"")
B18: חוזים עתידיים | C18: -33786 | D18: =IFERROR(C18/C$23,"") -> -0.076232809 | E18: -33786 | F18: =IFERROR(E18/E$23,"") -> -0.078784077 | G18: 107931 | H18: =IFERROR(G18/G$23,"") -> 0.0046016095 | I18: -232953 | J18: =IFERROR(I18/I$23,"") -> -0.54807699 | K18: -232953 | L18: =IFERROR(K18/K$23,"") -> -0.4750982 | M18: -177715 | N18: =IFERROR(M18/M$23,"") -> -0.0075547958 | O18: -53167 | P18: =IFERROR(O18/O$23,"") -> -0.13057146 | Q18: -53167 | R18: =IFERROR(Q18/Q$23,"") -> -0.12490016 | S18: -220307 | T18: =IFERROR(S18/S$23,"") -> -0.0092433956 | V18: =IFERROR(U18/U$23,"") | X18: =IFERROR(W18/W$23,"") | Z18: =IFERROR(Y18/Y$23,"")
B19: השקעה בחברות מוחזקות | C19: -1977 | D19: =IFERROR(C19/C$23,"") -> -0.0044607904 | E19: -1683 | F19: =IFERROR(E19/E$23,"") -> -0.0039245132 | G19: 53763 | H19: =IFERROR(G19/G$23,"") -> 0.0022921712 | I19: 3428 | J19: =IFERROR(I19/I$23,"") -> 0.0080651802 | K19: 5594 | L19: =IFERROR(K19/K$23,"") -> 0.011408736 | M19: 59292 | N19: =IFERROR(M19/M$23,"") -> 0.0025205467 | O19: 650 | P19: =IFERROR(O19/O$23,"") -> 0.0015963182 | Q19: 592 | R19: =IFERROR(Q19/Q$23,"") -> 0.0013907291 | S19: 40201 | T19: =IFERROR(S19/S$23,"") -> 0.0016867088 | V19: =IFERROR(U19/U$23,"") | X19: =IFERROR(W19/W$23,"") | Z19: =IFERROR(Y19/Y$23,"")
... B22: נכסים אחרים | C22: 409 | D22: =IFERROR(C22/C$23,"") -> 0.00092284435 | E22: 409 | F22: =IFERROR(E22/E$23,"") -> 0.00095372899 | G22: 0 | H22: =IFERROR(G22/G$23,"") -> 0 | I22: 722 | J22: =IFERROR(I22/I$23,"") -> 0.0016986756 | K22: 722 | L22: =IFERROR(K22/K$23,"") -> 0.0014724897 | M22: 0 | N22: =IFERROR(M22/M$23,"") -> 0 | O22: -169 | P22: =IFERROR(O22/O$23,"") -> -0.00041504272 | Q22: -169 | R22: =IFERROR(Q22/Q$23,"") -> -0.00039701557 | S22: 0 | T22: =IFERROR(S22/S$23,"") -> 0 | V22: =IFERROR(U22/U$23,"") | X22: =IFERROR(W22/W$23,"") | Z22: =IFERROR(Y22/Y$23,"")
B23: סה"כ | C23: =SUM(C8:C22) -> 443195 | D23: =IFERROR(C23/C$23,"") -> 1 | E23: =SUM(E8:E22) -> 428843 | F23: =IFERROR(E23/E$23,"") -> 1 | G23: =SUM(G8:G22) -> 23455054 | H23: =IFERROR(G23/G$23,"") -> 1 | I23: =SUM(I8:I22) -> 425037 | J23: =IFERROR(I23/I$23,"") -> 1 | K23: =SUM(K8:K22) -> 490326 | L23: =IFERROR(K23/K$23,"") -> 1 | M23: =SUM(M8:M22) -> 23523468 | N23: =IFERROR(M23/M$23,"") -> 1 | O23: =SUM(O8:O22) -> 407187 | P23: =IFERROR(O23/O$23,"") -> 1 | Q23: =SUM(Q8:Q22) -> 425676 | R23: =IFERROR(Q23/Q$23,"") -> 1 | S23: =SUM(S8:S22) -> 23833990 | T23: =IFERROR(S23/S$23,"") -> 1 | U23: =SUM(U8:U22) -> 0 | V23: =IFERROR(U23/U$23,"") | W23: =SUM(W8:W22) -> 0 | X23: =IFERROR(W23/W$23,"") | Y23: =SUM(Y8:Y22) -> 0 | Z23: =IFERROR(Y23/Y$23,"")
B25: נכסים בארץ | C25: 481647 | D25: =IFERROR(C25/C$27,"") -> 1.0867609 | E25: 417136 | F25: =IFERROR(E25/E$27,"") -> 0.97270097 | G25: 20946797 | H25: =IFERROR(G25/G$27,"") -> 0.89306113 | I25: 535163 | J25: =IFERROR(I25/I$27,"") -> 1.2590974 | K25: 480586 | L25: =IFERROR(K25/K$27,"") -> 0.98013566 | M25: 21054262 | N25: =IFERROR(M25/M$27,"") -> 0.89503223 | O25: 471623 | P25: =IFERROR(O25/O$27,"") -> 1.1582467 | Q25: 433148 | R25: =IFERROR(Q25/Q$27,"") -> 1.0175533 | S25: 21480119 | T25: =IFERROR(S25/S$27,"") -> 0.9012389 | V25: =IFERROR(U25/U$27,"") | X25: =IFERROR(W25/W$27,"") | Z25: =IFERROR(Y25/Y$27,"")
B26: נכסים בחו"ל | C26: -38452 | D26: =IFERROR(C26/C$27,"") -> -0.086760907 | E26: 11707 | F26: =IFERROR(E26/E$27,"") -> 0.027299035 | G26: 2508257 | H26: =IFERROR(G26/G$27,"") -> 0.10693887 | I26: -110126 | J26: =IFERROR(I26/I$27,"") -> -0.25909744 | K26: 9740 | L26: =IFERROR(K26/K$27,"") -> 0.019864335 | M26: 2469206 | N26: =IFERROR(M26/M$27,"") -> 0.10496777 | O26: -64436 | P26: =IFERROR(O26/O$27,"") -> -0.1582467 | Q26: -7472 | R26: =IFERROR(Q26/Q$27,"") -> -0.017553256 | S26: 2353871 | T26: =IFERROR(S26/S$27,"") -> 0.098761096 | V26: =IFERROR(U26/U$27,"") | X26: =IFERROR(W26/W$27,"") | Z26: =IFERROR(Y26/Y$27,"")
B27: סה"כ | C27: =SUM(C25:C26) -> 443195 | D27: =IFERROR(C27/C$27,"") -> 1 | E27: =SUM(E25:E26) -> 428843 | F27: =IFERROR(E27/E$27,"") -> 1 | G27: =SUM(G25:G26) -> 23455054 | H27: =IFERROR(G27/G$27,"") -> 1 | I27: =SUM(I25:I26) -> 425037 | J27: =IFERROR(I27/I$27,"") -> 1 | K27: =SUM(K25:K26) -> 490326 | L27: =IFERROR(K27/K$27,"") -> 1 | M27: =SUM(M25:M26) -> 23523468 | N27: =IFERROR(M27/M$27,"") -> 1 | O27: =SUM(O25:O26) -> 407187 | P27: =IFERROR(O27/O$27,"") -> 1 | Q27: =SUM(Q25:Q26) -> 425676 | R27: =IFERROR(Q27/Q$27,"") -> 1 | S27: =SUM(S25:S26) -> 23833990 | T27: =IFERROR(S27/S$27,"") -> 1 | U27: =SUM(U25:U26) -> 0 | V27: =IFERROR(U27/U$27,"") | W27: =SUM(W25:W26) -> 0 | X27: =IFERROR(W27/W$27,"") | Y27: =SUM(Y25:Y26) -> 0 | Z27: =IFERROR(Y27/Y$27,"")
B29: נכסים סחירים ונזילים | C29: 22481 | D29: =IFERROR(C29/C$31,"") -> 0.05072485 | E29: -47858 | F29: =IFERROR(E29/E$31,"") -> -0.11159795 | G29: 2400079.3 | H29: =IFERROR(G29/G$31,"") -> 0.10232674 | I29: 45733 | J29: =IFERROR(I29/I$31,"") -> 0.10759769 | K29: -42941 | L29: =IFERROR(K29/K$31,"") -> -0.087576429 | M29: 2186210.3 | N29: =IFERROR(M29/M$31,"") -> 0.092937413 | O29: -50064 | P29: =IFERROR(O29/O$31,"") -> -0.12295088 | Q29: -55799 | R29: =IFERROR(Q29/Q$31,"") -> -0.13108327 | S29: 2012831.3 | T29: =IFERROR(S29/S$31,"") -> 0.084452132 | V29: =IFERROR(U29/U$31,"") | X29: =IFERROR(W29/W$31,"") | Z29: =IFERROR(Y29/Y$31,"")
B30: נכסים לא סחירים | C30: 420714 | D30: =IFERROR(C30/C$31,"") -> 0.94927515 | E30: 476701 | F30: =IFERROR(E30/E$31,"") -> 1.111598 | G30: 21054975 | H30: =IFERROR(G30/G$31,"") -> 0.89767326 | I30: 379304 | J30: =IFERROR(I30/I$31,"") -> 0.89240231 | K30: 533267 | L30: =IFERROR(K30/K$31,"") -> 1.0875764 | M30: 21337258 | N30: =IFERROR(M30/M$31,"") -> 0.90706259 | O30: 457251 | P30: =IFERROR(O30/O$31,"") -> 1.1229509 | Q30: 481475 | R30: =IFERROR(Q30/Q$31,"") -> 1.1310833 | S30: 21821159 | T30: =IFERROR(S30/S$31,"") -> 0.91554787 | V30: =IFERROR(U30/U$31,"") | X30: =IFERROR(W30/W$31,"") | Z30: =IFERROR(Y30/Y$31,"")
B31: סה"כ | C31: =SUM(C29:C30) -> 443195 | D31: =IFERROR(C31/C$31,"") -> 1 | E31: =SUM(E29:E30) -> 428843 | F31: =IFERROR(E31/E$31,"") -> 1 | G31: =SUM(G29:G30) -> 23455054 | H31: =IFERROR(G31/G$31,"") -> 1 | I31: =SUM(I29:I30) -> 425037 | J31: =IFERROR(I31/I$31,"") -> 1 | K31: =SUM(K29:K30) -> 490326 | L31: =IFERROR(K31/K$31,"") -> 1 | M31: =SUM(M29:M30) -> 23523468 | N31: =IFERROR(M31/M$31,"") -> 1 | O31: =SUM(O29:O30) -> 407187 | P31: =IFERROR(O31/O$31,"") -> 1 | Q31: =SUM(Q29:Q30) -> 425676 | R31: =IFERROR(Q31/Q$31,"") -> 1 | S31: =SUM(S29:S30) -> 23833990 | T31: =IFERROR(S31/S$31,"") -> 1 | U31: =SUM(U29:U30) -> 0 | V31: =IFERROR(U31/U$31,"") | W31: =SUM(W29:W30) -> 0 | X31: =IFERROR(W31/W$31,"") | Y31: =SUM(Y29:Y30) -> 0 | Z31: =IFERROR(Y31/Y$31,"")
B33: נתונים מצטברים בשנת : | C33: רבעון 1 | I33: רבעון 1+2 | O33: רבעון 1+2+3 | U33: רבעון 1+2+3+4
B34: =CONCATENATE("20",RIGHT(הנחיות!B20,2)) -> 2022 | C34: תרומה להכנסות מהשקעות (רווח/הפסד) | E34: תרומה להכנסה הכוללת (הון עצמי) | G34: סך נכסים | I34: תרומה להכנסות מהשקעות (רווח/הפסד) | K34: תרומה להכנסה הכוללת (הון עצמי) | M34: סך נכסים | O34: תרומה להכנסות מהשקעות (רווח/הפסד) | Q34: תרומה להכנסה הכוללת (הון עצמי) | S34: סך נכסים | U34: תרומה להכנסות מהשקעות (רווח/הפסד) | W34: תרומה להכנסה הכוללת (הון עצמי) | Y34: סך נכסים
C35: (באלפי ש"ח) | D35: (באחוזים) | E35: (באלפי ש"ח) | F35: (באחוזים) | G35: (באלפי ש"ח) | H35: (באחוזים) | I35: (באלפי ש"ח) | J35: (באחוזים) | K35: (באלפי ש"ח) | L35: (באחוזים) | M35: (באלפי ש"ח) | N35: (באחוזים) | O35: (באלפי ש"ח) | P35: (באחוזים) | Q35: (באלפי ש"ח) | R35: (באחוזים) | S35: (באלפי ש"ח) | T35: (באחוזים) | U35: (באלפי ש"ח) | V35: (באחוזים) | W35: (באלפי ש"ח) | X35: (באחוזים) | Y35: (באלפי ש"ח) | Z35: (באחוזים)
B36: מזומנים ושווי מזומנים | C36: =C8 -> 634 | D36: =IFERROR(C36/C$51,"") -> 0.0014305216 | E36: =E8 -> 634 | F36: =IFERROR(E36/E$51,"") -> 0.0014783965 | G36: =G8 -> 604211.28 | H36: =IFERROR(G36/G$51,"") -> 0.025760387 | I36: =IF(I$23=0,"",I8+C36) -> 12754 | J36: =IFERROR(I36/I$51,"") -> 0.014689622 | K36: =IF(K$23=0,"",K8+E36) -> 12754 | L36: =IFERROR(K36/K$51,"") -> 0.013875577 | M36: =M8 -> 624211.28 | N36: =IFERROR(M36/M$51,"") -> 0.026535682 | O36: =IF(O$23=0,"",O8+I36) -> 17561 | P36: =IFERROR(O36/O$51,"") -> 0.013768809 | Q36: =IF(Q$23=0,"",Q8+K36) -> 17561 | R36: =IFERROR(Q36/Q$51,"") -> 0.01305801 | S36: =S8 -> 653879.28 | T36: =IFERROR(S36/S$51,"") -> 0.027434738 | U36: =IF(U$23=0,"",U8+O36) | V36: =IFERROR(U36/U$51,"") | W36: =IF(W$23=0,"",W8+Q36) | X36: =IFERROR(W36/W$51,"") | Y36: =Y8 -> 0 | Z36: =IFERROR(Y36/Y$51,"")
B37: אג"ח ממשלתיות סחירות | C37: =C9 -> 1469 | D37: =IFERROR(C37/C$51,"") -> 0.0033145681 | E37: =E9 -> -2391 | F37: =IFERROR(E37/E$51,"") -> -0.005575467 | G37: =G9 -> 161367 | H37: =IFERROR(G37/G$51,"") -> 0.0068798391 | I37: =IF(I$23=0,"",I9+C37) -> 3688 | J37: =IFERROR(I37/I$51,"") -> 0.0042477126 | K37: =IF(K$23=0,"",K9+E37) -> -4762 | L37: =IFERROR(K37/K$51,"") -> -0.0051807665 | M37: =M9 -> 142810 | N37: =IFERROR(M37/M$51,"") -> 0.0060709585 | O37: =IF(O$23=0,"",O9+I37) -> 4912 | P37: =IFERROR(O37/O$51,"") -> 0.0038512834 | Q37: =IF(Q$23=0,"",Q9+K37) -> -6890 | R37: =IFERROR(Q37/Q$51,"") -> -0.005123267 | S37: =S9 -> 105428 | T37: =IFERROR(S37/S$51,"") -> 0.0044234305 | U37: =IF(U$23=0,"",U9+O37) | V37: =IFERROR(U37/U$51,"") | W37: =IF(W$23=0,"",W9+Q37) | X37: =IFERROR(W37/W$51,"") | Y37: =Y9 -> 0 | Z37: =IFERROR(Y37/Y$51,"")
B38: אג"ח מיועדות | C38: =C10 -> 333836 | D38: =IFERROR(C38/C$51,"") -> 0.75324857 | E38: =E10 -> 333836 | F38: =IFERROR(E38/E$51,"") -> 0.77845738 | G38: =G10 -> 14032048 | H38: =IFERROR(G38/G$51,"") -> 0.59825263 | I38: =IF(I$23=0,"",I10+C38) -> 778459 | J38: =IFERROR(I38/I$51,"") -> 0.89660252 | K38: =IF(K$23=0,"",K10+E38) -> 778459 | L38: =IFERROR(K38/K$51,"") -> 0.84691607 | M38: =M10 -> 13965497 | N38: =IFERROR(M38/M$51,"") -> 0.59368359 | O38: =IF(O$23=0,"",O10+I38) -> 1122327 | P38: =IFERROR(O38/O$51,"") -> 0.87996729 | Q38: =IF(Q$23=0,"",Q10+K38) -> 1122327 | R38: =IFERROR(Q38/Q$51,"") -> 0.83454004 | S38: =S10 -> 14305070 | T38: =IFERROR(S38/S$51,"") -> 0.60019618 | U38: =IF(U$23=0,"",U10+O38) | V38: =IFERROR(U38/U$51,"") | W38: =IF(W$23=0,"",W10+Q38) | X38: =IFERROR(W38/W$51,"") | Y38: =Y10 -> 0 | Z38: =IFERROR(Y38/Y$51,"")
B39: אג"ח קונצרניות סחירות | C39: =C11 -> 23835 | D39: =IFERROR(C39/C$51,"") -> 0.053779939 | E39: =E11 -> -32908 | F39: =IFERROR(E39/E$51,"") -> -0.076736708 | G39: =G11 -> 734842 | H39: =IFERROR(G39/G$51,"") -> 0.031329793 | I39: =IF(I$23=0,"",I11+C39) -> 37257 | J39: =IFERROR(I39/I$51,"") -> 0.042911342 | K39: =IF(K$23=0,"",K11+E39) -> -48840 | L39: =IFERROR(K39/K$51,"") -> -0.053134951 | M39: =M11 -> 851785 | N39: =IFERROR(M39/M$51,"") -> 0.036210009 | O39: =IF(O$23=0,"",O11+I39) -> 46707 | P39: =IFERROR(O39/O$51,"") -> 0.036620907 | Q39: =IF(Q$23=0,"",Q11+K39) -> -70032 | R39: =IFERROR(Q39/Q$51,"") -> -0.052074403 | S39: =S11 -> 825600 | T39: =IFERROR(S39/S$51,"") -> 0.034639605 | U39: =IF(U$23=0,"",U11+O39) | V39: =IFERROR(U39/U$51,"") | W39: =IF(W$23=0,"",W11+Q39) | X39: =IFERROR(W39/W$51,"") | Y39: =Y11 -> 0 | Z39: =IFERROR(Y39/Y$51,"")
B40: אג"ח קונצרניות לא סחירות | C40: =C12 -> 6537 | D40: =IFERROR(C40/C$51,"") -> 0.014749715 | E40: =E12 -> 6537 | F40: =IFERROR(E40/E$51,"") -> 0.015243341 | G40: =G12 -> 221917 | H40: =IFERROR(G40/G$51,"") -> 0.0094613723 | I40: =IF(I$23=0,"",I12+C40) -> 15317 | J40: =IFERROR(I40/I$51,"") -> 0.017641598 | K40: =IF(K$23=0,"",K12+E40) -> 15317 | L40: =IFERROR(K40/K$51,"") -> 0.016663965 | M40: =M12 -> 223202 | N40: =IFERROR(M40/M$51,"") -> 0.0094884818 | O40: =IF(O$23=0,"",O12+I40) -> 21433 | P40: =IFERROR(O40/O$51,"") -> 0.016804674 | Q40: =IF(Q$23=0,"",Q12+K40) -> 21433 | R40: =IFERROR(Q40/Q$51,"") -> 0.015937153 | S40: =S12 -> 213642 | T40: =IFERROR(S40/S$51,"") -> 0.0089637529 | U40: =IF(U$23=0,"",U12+O40) | V40: =IFERROR(U40/U$51,"") | W40: =IF(W$23=0,"",W12+Q40) | X40: =IFERROR(W40/W$51,"") | Y40: =Y12 -> 0 | Z40: =IFERROR(Y40/Y$51,"")
B41: מניות | C41: =C13 -> 1275 | D41: =IFERROR(C41/C$51,"") -> 0.0028768375 | E41: =E13 -> 5657 | F41: =IFERROR(E41/E$51,"") -> 0.013191308 | G41: =G13 -> 430853 | H41: =IFERROR(G41/G$51,"") -> 0.018369303 | I41: =IF(I$23=0,"",I13+C41) -> 11128 | J41: =IFERROR(I41/I$51,"") -> 0.012816851 | K41: =IF(K$23=0,"",K13+E41) -> 11693 | L41: =IFERROR(K41/K$51,"") -> 0.012721273 | M41: =M13 -> 464681 | N41: =IFERROR(M41/M$51,"") -> 0.019753932 | O41: =IF(O$23=0,"",O13+I41) -> 14331 | P41: =IFERROR(O41/O$51,"") -> 0.011236307 | Q41: =IF(Q$23=0,"",Q13+K41) -> 77404 | R41: =IFERROR(Q41/Q$51,"") -> 0.057556075 | S41: =S13 -> 507031 | T41: =IFERROR(S41/S$51,"") -> 0.021273442 | U41: =IF(U$23=0,"",U13+O41) | V41: =IFERROR(U41/U$51,"") | W41: =IF(W$23=0,"",W13+Q41) | X41: =IFERROR(W41/W$51,"") | Y41: =Y13 -> 0 | Z41: =IFERROR(Y41/Y$51,"")
B42: תעודות סל | C42: =C14 -> -17763 | D42: =IFERROR(C42/C$51,"") -> -0.040079423 | E42: =E14 -> -23019 | F42: =IFERROR(E42/E$51,"") -> -0.053676987 | G42: =G14 -> 448290 | H42: =IFERROR(G42/G$51,"") -> 0.019112725 | I42: =IF(I$23=0,"",I14+C42) -> -19138 | J42: =IFERROR(I42/I$51,"") -> -0.022042496 | K42: =IF(K$23=0,"",K14+E42) -> -52076 | L42: =IFERROR(K42/K$51,"") -> -0.056655523 | M42: =M14 -> 371993 | N42: =IFERROR(M42/M$51,"") -> 0.015813697 | O42: =IF(O$23=0,"",O14+I42) -> -69433 | P42: =IFERROR(O42/O$51,"") -> -0.054439365 | Q42: =IF(Q$23=0,"",Q14+K42) -> -70474 | R42: =IFERROR(Q42/Q$51,"") -> -0.052403065 | S42: =S14 -> 331610 | T42: =IFERROR(S42/S$51,"") -> 0.013913323 | U42: =IF(U$23=0,"",U14+O42) | V42: =IFERROR(U42/U$51,"") | W42: =IF(W$23=0,"",W14+Q42) | X42: =IFERROR(W42/W$51,"") | Y42: =Y14 -> 0 | Z42: =IFERROR(Y42/Y$51,"")
B43: קרנות נאמנות | C43: =C15 -> 6736 | D43: =IFERROR(C43/C$51,"") -> 0.015198727 | E43: =E15 -> 6736 | F43: =IFERROR(E43/E$51,"") -> 0.01570738 | G43: =G15 -> 138609 | H43: =IFERROR(G43/G$51,"") -> 0.0059095578 | I43: =IF(I$23=0,"",I15+C43) -> 15154 | J43: =IFERROR(I43/I$51,"") -> 0.01745386 | K43: =IF(K$23=0,"",K15+E43) -> 15154 | L43: =IFERROR(K43/K$51,"") -> 0.016486631 | M43: =M15 -> 63980 | N43: =IFERROR(M43/M$51,"") -> 0.002719837 | O43: =IF(O$23=0,"",O15+I43) -> 16445 | P43: =IFERROR(O43/O$51,"") -> 0.012893802 | Q43: =IF(Q$23=0,"",Q15+K43) -> 16445 | R43: =IFERROR(Q43/Q$51,"") -> 0.012228175 | S43: =S15 -> 20957 | T43: =IFERROR(S43/S$51,"") -> 0.00087929045 | U43: =IF(U$23=0,"",U15+O43) | V43: =IFERROR(U43/U$51,"") | W43: =IF(W$23=0,"",W15+Q43) | X43: =IFERROR(W43/W$51,"") | Y43: =Y15 -> 0 | Z43: =IFERROR(Y43/Y$51,"")
B44: הלוואות | C44: =C16 -> 69689 | D44: =IFERROR(C44/C$51,"") -> 0.1572423 | E44: =E16 -> 69689 | F44: =IFERROR(E44/E$51,"") -> 0.16250469 | G44: =G16 -> 3674686 | H44: =IFERROR(G44/G$51,"") -> 0.15666926 | I44: =IF(I$23=0,"",I16+C44) -> 178058 | J44: =IFERROR(I44/I$51,"") -> 0.20508113 | K44: =IF(K$23=0,"",K16+E44) -> 178058 | L44: =IFERROR(K44/K$51,"") -> 0.19371628 | M44: =M16 -> 3880900 | N44: =IFERROR(M44/M$51,"") -> 0.16497992 | O44: =IF(O$23=0,"",O16+I44) -> 259751 | P44: =IFERROR(O44/O$51,"") -> 0.20365935 | Q44: =IF(Q$23=0,"",Q16+K44) -> 259751 | R44: =IFERROR(Q44/Q$51,"") -> 0.19314568 | S44: =S16 -> 4004118 | T44: =IFERROR(S44/S$51,"") -> 0.16800032 | U44: =IF(U$23=0,"",U16+O44) | V44: =IFERROR(U44/U$51,"") | W44: =IF(W$23=0,"",W16+Q44) | X44: =IFERROR(W44/W$51,"") | Y44: =Y16 -> 0 | Z44: =IFERROR(Y44/Y$51,"")
B45: פיקדונות (שאינם מובנים) | C45: =C17 -> 6628 | D45: =IFERROR(C45/C$51,"") -> 0.014955042 | E45: =E17 -> 6628 | F45: =IFERROR(E45/E$51,"") -> 0.01545554 | G45: =G17 -> 330428 | H45: =IFERROR(G45/G$51,"") -> 0.01408771 | I45: =IF(I$23=0,"",I17+C45) -> 15718 | J45: =IFERROR(I45/I$51,"") -> 0.018103456 | K45: =IF(K$23=0,"",K17+E45) -> 15718 | L45: =IFERROR(K45/K$51,"") -> 0.017100229 | M45: =M17 -> 332752 | N45: =IFERROR(M45/M$51,"") -> 0.014145533 | O45: =IF(O$23=0,"",O17+I45) -> 22336 | P45: =IFERROR(O45/O$51,"") -> 0.017512676 | Q45: =IF(Q$23=0,"",Q17+K45) -> 22336 | R45: =IFERROR(Q45/Q$51,"") -> 0.016608605 | S45: =S17 -> 327463 | T45: =IFERROR(S45/S$51,"") -> 0.013739328 | U45: =IF(U$23=0,"",U17+O45) | V45: =IFERROR(U45/U$51,"") | W45: =IF(W$23=0,"",W17+Q45) | X45: =IFERROR(W45/W$51,"") | Y45: =Y17 -> 0 | Z45: =IFERROR(Y45/Y$51,"")
B46: חוזים עתידיים | C46: =C18 -> -33786 | D46: =IFERROR(C46/C$51,"") -> -0.076232809 | E46: =E18 -> -33786 | F46: =IFERROR(E46/E$51,"") -> -0.078784077 | G46: =G18 -> 107931 | H46: =IFERROR(G46/G$51,"") -> 0.0046016095 | I46: =IF(I$23=0,"",I18+C46) -> -266739 | J46: =IFERROR(I46/I$51,"") -> -0.30722088 | K46: =IF(K$23=0,"",K18+E46) -> -266739 | L46: =IFERROR(K46/K$51,"") -> -0.29019582 | M46: =M18 -> -177715 | N46: =IFERROR(M46/M$51,"") -> -0.0075547958 | O46: =IF(O$23=0,"",O18+I46) -> -319906 | P46: =IFERROR(O46/O$51,"") -> -0.25082424 | Q46: =IF(Q$23=0,"",Q18+K46) -> -319906 | R46: =IFERROR(Q46/Q$51,"") -> -0.23787574 | S46: =S18 -> -220307 | T46: =IFERROR(S46/S$51,"") -> -0.0092433956 | U46: =IF(U$23=0,"",U18+O46) | V46: =IFERROR(U46/U$51,"") | W46: =IF(W$23=0,"",W18+Q46) | X46: =IFERROR(W46/W$51,"") | Y46: =Y18 -> 0 | Z46: =IFERROR(Y46/Y$51,"")
...

Sheet כללי והון
B1: פירוט תרומת אפיקי ההשקעה לתשואה הכוללת
B2: =הנחיות!B21 -> כלל ביטוח נוסטרו
B3: נוסטרו כללי והון
B5: נתונים לרבעון בשנת : | C5: רבעון 1 | I5: רבעון 2 | O5: רבעון 3 | U5: רבעון 4
B6: =CONCATENATE("20",RIGHT(הנחיות!B20,2)) -> 2022 | C6: תרומה להכנסות מהשקעות (רווח/הפסד) | E6: תרומה להכנסה הכוללת (הון עצמי) | G6: סך נכסים | I6: תרומה להכנסות מהשקעות (רווח/הפסד) | K6: תרומה להכנסה הכוללת (הון עצמי) | M6: סך נכסים | O6: תרומה להכנסות מהשקעות (רווח/הפסד) | Q6: תרומה להכנסה הכוללת (הון עצמי) | S6: סך נכסים | U6: תרומה להכנסות מהשקעות (רווח/הפסד) | W6: תרומה להכנסה הכוללת (הון עצמי) | Y6: סך נכסים
C7: (באלפי ש"ח) | D7: (באחוזים) | E7: (באלפי ש"ח) | F7: (באחוזים) | G7: (באלפי ש"ח) | H7: (באחוזים) | I7: (באלפי ש"ח) | J7: (באחוזים) | K7: (באלפי ש"ח) | L7: (באחוזים) | M7: (באלפי ש"ח) | N7: (באחוזים) | O7: (באלפי ש"ח) | P7: (באחוזים) | Q7: (באלפי ש"ח) | R7: (באחוזים) | S7: (באלפי ש"ח) | T7: (באחוזים) | U7: (באלפי ש"ח) | V7: (באחוזים) | W7: (באלפי ש"ח) | X7: (באחוזים) | Y7: (באלפי ש"ח) | Z7: (באחוזים)
B8: מזומנים ושווי מזומנים | C8: 2962 | D8: =IFERROR(C8/C$23,"") -> 0.0179538 | E8: 2962 | F8: =IFERROR(E8/E$23,"") -> -0.041521812 | G8: 2791078.7 | H8: =IFERROR(G8/G$23,"") -> 0.21755585 | I8: 27975 | J8: =IFERROR(I8/I$23,"") -> -0.74147208 | K8: 27975 | L8: =IFERROR(K8/K$23,"") -> -0.14787504 | M8: 3209251.7 | N8: =IFERROR(M8/M$23,"") -> 0.24717051 | O8: 5260 | P8: =IFERROR(O8/O$23,"") -> 0.044114194 | Q8: 5260 | R8: =IFERROR(Q8/Q$23,"") -> -0.11810405 | S8: 2753447.7 | T8: =IFERROR(S8/S$23,"") -> 0.2184996 | V8: =IFERROR(U8/U$23,"") | X8: =IFERROR(W8/W$23,"") | Z8: =IFERROR(Y8/Y$23,"")
B9: אג"ח ממשלתיות סחירות | C9: 19850 | D9: =IFERROR(C9/C$23,"") -> 0.12031834 | E9: -87192 | F9: =IFERROR(E9/E$23,"") -> 1.2222721 | G9: 2277459 | H9: =IFERROR(G9/G$23,"") -> 0.1775208 | I9: 45137 | J9: =IFERROR(I9/I$23,"") -> -1.1963476 | K9: -46216 | L9: =IFERROR(K9/K$23,"") -> 0.24429644 | M9: 3044565 | N9: =IFERROR(M9/M$23,"") -> 0.23448665 | O9: 34512 | P9: =IFERROR(O9/O$23,"") -> 0.28944279 | Q9: -80995 | R9: =IFERROR(Q9/Q$23,"") -> 1.8186003 | S9: 2905577 | T9: =IFERROR(S9/S$23,"") -> 0.2305718 | V9: =IFERROR(U9/U$23,"") | X9: =IFERROR(W9/W$23,"") | Z9: =IFERROR(Y9/Y$23,"")
B10: אג"ח מיועדות | C10: 0 | D10: =IFERROR(C10/C$23,"") -> 0 | E10: 0 | F10: =IFERROR(E10/E$23,"") -> 0 | G10: 0 | H10: =IFERROR(G10/G$23,"") -> 0 | I10: 0 | J10: =IFERROR(I10/I$23,"") -> 0 | K10: 0 | L10: =IFERROR(K10/K$23,"") -> 0 | M10: 0 | N10: =IFERROR(M10/M$23,"") -> 0 | O10: 0 | P10: =IFERROR(O10/O$23,"") -> 0 | Q10: 0 | R10: =IFERROR(Q10/Q$23,"") -> 0 | S10: 0 | T10: =IFERROR(S10/S$23,"") -> 0 | V10: =IFERROR(U10/U$23,"") | X10: =IFERROR(W10/W$23,"") | Z10: =IFERROR(Y10/Y$23,"")
B11: אג"ח קונצרניות סחירות | C11: 29642 | D11: =IFERROR(C11/C$23,"") -> 0.17967135 | E11: -66576 | F11: =IFERROR(E11/E$23,"") -> 0.93327352 | G11: 1698473 | H11: =IFERROR(G11/G$23,"") -> 0.13239065 | I11: -5150 | J11: =IFERROR(I11/I$23,"") -> 0.13649977 | K11: -56458 | L11: =IFERROR(K11/K$23,"") -> 0.29843535 | M11: 1385087 | N11: =IFERROR(M11/M$23,"") -> 0.10667679 | O11: 13836 | P11: =IFERROR(O11/O$23,"") -> 0.11603878 | Q11: -35915 | R11: =IFERROR(Q11/Q$23,"") -> 0.80640816 | S11: 1659553 | T11: =IFERROR(S11/S$23,"") -> 0.13169368 | V11: =IFERROR(U11/U$23,"") | X11: =IFERROR(W11/W$23,"") | Z11: =IFERROR(Y11/Y$23,"")
B12: אג"ח קונצרניות לא סחירות | C12: 4394 | D12: =IFERROR(C12/C$23,"") -> 0.026633693 | E12: 4394 | F12: =IFERROR(E12/E$23,"") -> -0.061595828 | G12: 163318 | H12: =IFERROR(G12/G$23,"") -> 0.012730127 | I12: 5906 | J12: =IFERROR(I12/I$23,"") -> -0.15653741 | K12: 5906 | L12: =IFERROR(K12/K$23,"") -> -0.031218945 | M12: 132518 | N12: =IFERROR(M12/M$23,"") -> 0.010206286 | O12: 2136 | P12: =IFERROR(O12/O$23,"") -> 0.017914053 | Q12: 2136 | R12: =IFERROR(Q12/Q$23,"") -> -0.047960123 | S12: 94258 | T12: =IFERROR(S12/S$23,"") -> 0.0074798351 | V12: =IFERROR(U12/U$23,"") | X12: =IFERROR(W12/W$23,"") | Z12: =IFERROR(Y12/Y$23,"")
B13: מניות | C13: 76485 | D13: =IFERROR(C13/C$23,"") -> 0.46360446 | E13: 18582 | F13: =IFERROR(E13/E$23,"") -> -0.26048559 | G13: 1664164 | H13: =IFERROR(G13/G$23,"") -> 0.12971637 | I13: -24219 | J13: =IFERROR(I13/I$23,"") -> 0.64192001 | K13: -145352 | L13: =IFERROR(K13/K$23,"") -> 0.76832646 | M13: 1445071 | N13: =IFERROR(M13/M$23,"") -> 0.11129664 | O13: 39208 | P13: =IFERROR(O13/O$23,"") -> 0.32882686 | Q13: 3157 | R13: =IFERROR(Q13/Q$23,"") -> -0.070884882 | S13: 1392389 | T13: =IFERROR(S13/S$23,"") -> 0.1104929 | V13: =IFERROR(U13/U$23,"") | X13: =IFERROR(W13/W$23,"") | Z13: =IFERROR(Y13/Y$23,"")
B14: תעודות סל | C14: 11371 | D14: =IFERROR(C14/C$23,"") -> 0.068923924 | E14: -7168 | F14: =IFERROR(E14/E$23,"") -> 0.10048222 | G14: 147443 | H14: =IFERROR(G14/G$23,"") -> 0.01149272 | I14: -448 | J14: =IFERROR(I14/I$23,"") -> 0.011874155 | K14: -9745 | L14: =IFERROR(K14/K$23,"") -> 0.051511788 | M14: 126277 | N14: =IFERROR(M14/M$23,"") -> 0.0097256163 | O14: -17692 | P14: =IFERROR(O14/O$23,"") -> -0.14837801 | Q14: -3215 | R14: =IFERROR(Q14/Q$23,"") -> 0.07218717 | S14: 88369 | T14: =IFERROR(S14/S$23,"") -> 0.007012514 | V14: =IFERROR(U14/U$23,"") | X14: =IFERROR(W14/W$23,"") | Z14: =IFERROR(Y14/Y$23,"")
B15: קרנות נאמנות | C15: 6370 | D15: =IFERROR(C15/C$23,"") -> 0.038610975 | E15: 6370 | F15: =IFERROR(E15/E$23,"") -> -0.089295727 | G15: 328668 | H15: =IFERROR(G15/G$23,"") -> 0.025618641 | I15: 18652 | J15: =IFERROR(I15/I$23,"") -> -0.49436773 | K15: 18652 | L15: =IFERROR(K15/K$23,"") -> -0.098593932 | M15: 192839 | N15: =IFERROR(M15/M$23,"") -> 0.014852096 | O15: -4216 | P15: =IFERROR(O15/O$23,"") -> -0.035358449 | Q15: -4216 | R15: =IFERROR(Q15/Q$23,"") -> 0.094662865 | S15: 133759 | T15: =IFERROR(S15/S$23,"") -> 0.010614433 | V15: =IFERROR(U15/U$23,"") | X15: =IFERROR(W15/W$23,"") | Z15: =IFERROR(Y15/Y$23,"")
B16: הלוואות | C16: 14577 | D16: =IFERROR(C16/C$23,"") -> 0.0883567 | E16: 14577 | F16: =IFERROR(E16/E$23,"") -> -0.20434283 | G16: 1308247 | H16: =IFERROR(G16/G$23,"") -> 0.10197376 | I16: 23386 | J16: =IFERROR(I16/I$23,"") -> -0.6198415 | K16: 23386 | L16: =IFERROR(K16/K$23,"") -> -0.12361772 | M16: 1300001 | N16: =IFERROR(M16/M$23,"") -> 0.10012362 | O16: 16866 | P16: =IFERROR(O16/O$23,"") -> 0.14145057 | Q16: 16866 | R16: =IFERROR(Q16/Q$23,"") -> -0.37869636 | S16: 1390936 | T16: =IFERROR(S16/S$23,"") -> 0.1103776 | V16: =IFERROR(U16/U$23,"") | X16: =IFERROR(W16/W$23,"") | Z16: =IFERROR(Y16/Y$23,"")
B17: פיקדונות (שאינם מובנים) | C17: 3159 | D17: =IFERROR(C17/C$23,"") -> 0.019147892 | E17: 3159 | F17: =IFERROR(E17/E$23,"") -> -0.044283391 | G17: 506157 | H17: =IFERROR(G17/G$23,"") -> 0.039453353 | I17: 4273 | J17: =IFERROR(I17/I$23,"") -> -0.11325506 | K17: 4273 | L17: =IFERROR(K17/K$23,"") -> -0.022586954 | M17: 163777 | N17: =IFERROR(M17/M$23,"") -> 0.012613795 | O17: 3067 | P17: =IFERROR(O17/O$23,"") -> 0.025722097 | Q17: 3067 | R17: =IFERROR(Q17/Q$23,"") -> -0.068864091 | S17: 165064 | T17: =IFERROR(S17/S$23,"") -> 0.013098639 | V17: =IFERROR(U17/U$23,"") | X17: =IFERROR(W17/W$23,"") | Z17: =IFERROR(Y17/Y$23,"")
B18: חוזים עתידיים | C18: -5369 | D18: =IFERROR(C18/C$23,"") -> -0.032543536 | E18: -5369 | F18: =IFERROR(E18/E$23,"") -> 0.075263542 | G18: 40165 | H18: =IFERROR(G18/G$23,"") -> 0.003130736 | I18: -136668 | J18: =IFERROR(I18/I$23,"") -> 3.6223595 | K18: -136668 | L18: =IFERROR(K18/K$23,"") -> 0.72242309 | M18: -164831 | N18: =IFERROR(M18/M$23,"") -> -0.012694973 | O18: -24767 | P18: =IFERROR(O18/O$23,"") -> -0.20771411 | Q18: -24767 | R18: =IFERROR(Q18/Q$23,"") -> 0.55609942 | S18: -174267 | T18: =IFERROR(S18/S$23,"") -> -0.013828942 | V18: =IFERROR(U18/U$23,"") | X18: =IFERROR(W18/W$23,"") | Z18: =IFERROR(Y18/Y$23,"")
B19: השקעה בחברות מוחזקות | C19: -1815 | D19: =IFERROR(C19/C$23,"") -> -0.0110014 | E19: -1642 | F19: =IFERROR(E19/E$23,"") -> 0.023017831 | G19: 26306 | H19: =IFERROR(G19/G$23,"") -> 0.0020504703 | I19: 962 | J19: =IFERROR(I19/I$23,"") -> -0.025497628 | K19: 2153 | L19: =IFERROR(K19/K$23,"") -> -0.011380696 | M19: 28509 | N19: =IFERROR(M19/M$23,"") -> 0.0021957094 | O19: 673 | P19: =IFERROR(O19/O$23,"") -> 0.0056442685 | Q19: -347 | R19: =IFERROR(Q19/Q$23,"") -> 0.0077912747 | S19: 19246 | T19: =IFERROR(S19/S$23,"") -> 0.0015272646 | V19: =IFERROR(U19/U$23,"") | X19: =IFERROR(W19/W$23,"") | Z19: =IFERROR(Y19/Y$23,"")
... B22: נכסים אחרים | C22: -15336 | D22: =IFERROR(C22/C$23,"") -> -0.092957285 | E22: -15336 | F22: =IFERROR(E22/E$23,"") -> 0.21498262 | G22: 0 | H22: =IFERROR(G22/G$23,"") -> 0 | I22: -4451 | J22: =IFERROR(I22/I$23,"") -> 0.11797291 | K22: -4451 | L22: =IFERROR(K22/K$23,"") -> 0.023527857 | M22: 0 | N22: =IFERROR(M22/M$23,"") -> 0 | O22: 19365 | P22: =IFERROR(O22/O$23,"") -> 0.162409 | Q22: 19365 | R22: =IFERROR(Q22/Q$23,"") -> -0.43480701 | S22: 0 | T22: =IFERROR(S22/S$23,"") -> 0 | V22: =IFERROR(U22/U$23,"") | X22: =IFERROR(W22/W$23,"") | Z22: =IFERROR(Y22/Y$23,"")
B23: סה"כ | C23: =SUM(C8:C22) -> 164979 | D23: =IFERROR(C23/C$23,"") -> 1 | E23: =SUM(E8:E22) -> -71336 | F23: =IFERROR(E23/E$23,"") -> 1 | G23: =SUM(G8:G22) -> 12829252 | H23: =IFERROR(G23/G$23,"") -> 1 | I23: =SUM(I8:I22) -> -37729 | J23: =IFERROR(I23/I$23,"") -> 1 | K23: =SUM(K8:K22) -> -189180 | L23: =IFERROR(K23/K$23,"") -> 1 | M23: =SUM(M8:M22) -> 12983959 | N23: =IFERROR(M23/M$23,"") -> 1 | O23: =SUM(O8:O22) -> 119236 | P23: =IFERROR(O23/O$23,"") -> 1 | Q23: =SUM(Q8:Q22) -> -44537 | R23: =IFERROR(Q23/Q$23,"") -> 1 | S23: =SUM(S8:S22) -> 12601615 | T23: =IFERROR(S23/S$23,"") -> 1 | U23: =SUM(U8:U22) -> 0 | V23: =IFERROR(U23/U$23,"") | W23: =SUM(W8:W22) -> 0 | X23: =IFERROR(W23/W$23,"") | Y23: =SUM(Y8:Y22) -> 0 | Z23: =IFERROR(Y23/Y$23,"")
B25: נכסים בארץ | C25: 137443 | D25: =IFERROR(C25/C$27,"") -> 0.83309391 | E25: -125065 | F25: =IFERROR(E25/E$27,"") -> 1.7531821 | G25: 11020014 | H25: =IFERROR(G25/G$27,"") -> 0.85897556 | I25: 56324 | J25: =IFERROR(I25/I$27,"") -> -1.492857 | K25: -129910 | L25: =IFERROR(K25/K$27,"") -> 0.6867005 | M25: 11374171 | N25: =IFERROR(M25/M$27,"") -> 0.87601717 | O25: 137565 | P25: =IFERROR(O25/O$27,"") -> 1.1537204 | Q25: -74208 | R25: =IFERROR(Q25/Q$27,"") -> 1.6662101 | S25: 11078607 | T25: =IFERROR(S25/S$27,"") -> 0.87914184 | V25: =IFERROR(U25/U$27,"") | X25: =IFERROR(W25/W$27,"") | Z25: =IFERROR(Y25/Y$27,"")
B26: נכסים בחו"ל | C26: 27536 | D26: =IFERROR(C26/C$27,"") -> 0.16690609 | E26: 53729 | F26: =IFERROR(E26/E$27,"") -> -0.75318212 | G26: 1809238 | H26: =IFERROR(G26/G$27,"") -> 0.14102444 | I26: -94053 | J26: =IFERROR(I26/I$27,"") -> 2.492857 | K26: -59270 | L26: =IFERROR(K26/K$27,"") -> 0.3132995 | M26: 1609788 | N26: =IFERROR(M26/M$27,"") -> 0.12398283 | O26: -18329 | P26: =IFERROR(O26/O$27,"") -> -0.15372035 | Q26: 29671 | R26: =IFERROR(Q26/Q$27,"") -> -0.66621012 | S26: 1523008 | T26: =IFERROR(S26/S$27,"") -> 0.12085816 | V26: =IFERROR(U26/U$27,"") | X26: =IFERROR(W26/W$27,"") | Z26: =IFERROR(Y26/Y$27,"")
B27: סה"כ | C27: =SUM(C25:C26) -> 164979 | D27: =IFERROR(C27/C$27,"") -> 1 | E27: =SUM(E25:E26) -> -71336 | F27: =IFERROR(E27/E$27,"") -> 1 | G27: =SUM(G25:G26) -> 12829252 | H27: =IFERROR(G27/G$27,"") -> 1 | I27: =SUM(I25:I26) -> -37729 | J27: =IFERROR(I27/I$27,"") -> 1 | K27: =SUM(K25:K26) -> -189180 | L27: =IFERROR(K27/K$27,"") -> 1 | M27: =SUM(M25:M26) -> 12983959 | N27: =IFERROR(M27/M$27,"") -> 1 | O27: =SUM(O25:O26) -> 119236 | P27: =IFERROR(O27/O$27,"") -> 1 | Q27: =SUM(Q25:Q26) -> -44537 | R27: =IFERROR(Q27/Q$27,"") -> 1 | S27: =SUM(S25:S26) -> 12601615 | T27: =IFERROR(S27/S$27,"") -> 1 | U27: =SUM(U25:U26) -> 0 | V27: =IFERROR(U27/U$27,"") | W27: =SUM(W25:W26) -> 0 | X27: =IFERROR(W27/W$27,"") | Y27: =SUM(Y25:Y26) -> 0 | Z27: =IFERROR(Y27/Y$27,"")
B29: נכסים סחירים ונזילים | C29: 145779 | D29: =IFERROR(C29/C$31,"") -> 0.88362155 | E29: -141550 | F29: =IFERROR(E29/E$31,"") -> 1.9842716 | G29: 9121578.7 | H29: =IFERROR(G29/G$31,"") -> 0.7109985 | I29: 77451 | J29: =IFERROR(I29/I$31,"") -> -2.0528241 | K29: -219818 | L29: =IFERROR(K29/K$31,"") -> 1.1619516 | M29: 9345835.7 | N29: =IFERROR(M29/M$31,"") -> 0.71979863 | O29: 54584 | P29: =IFERROR(O29/O$31,"") -> 0.45778121 | Q29: -175937 | R29: =IFERROR(Q29/Q$31,"") -> 3.9503559 | S29: 8639802.7 | T29: =IFERROR(S29/S$31,"") -> 0.68561077 | V29: =IFERROR(U29/U$31,"") | X29: =IFERROR(W29/W$31,"") | Z29: =IFERROR(Y29/Y$31,"")
B30: נכסים לא סחירים | C30: 19200 | D30: =IFERROR(C30/C$31,"") -> 0.11637845 | E30: 70214 | F30: =IFERROR(E30/E$31,"") -> -0.98427162 | G30: 3707673 | H30: =IFERROR(G30/G$31,"") -> 0.2890015 | I30: -115180 | J30: =IFERROR(I30/I$31,"") -> 3.0528241 | K30: 30638 | L30: =IFERROR(K30/K$31,"") -> -0.16195158 | M30: 3638123 | N30: =IFERROR(M30/M$31,"") -> 0.28020137 | O30: 64652 | P30: =IFERROR(O30/O$31,"") -> 0.54221879 | Q30: 131400 | R30: =IFERROR(Q30/Q$31,"") -> -2.9503559 | S30: 3961812 | T30: =IFERROR(S30/S$31,"") -> 0.31438923 | V30: =IFERROR(U30/U$31,"") | X30: =IFERROR(W30/W$31,"") | Z30: =IFERROR(Y30/Y$31,"")
B31: סה"כ | C31: =SUM(C29:C30) -> 164979 | D31: =IFERROR(C31/C$31,"") -> 1 | E31: =SUM(E29:E30) -> -71336 | F31: =IFERROR(E31/E$31,"") -> 1 | G31: =SUM(G29:G30) -> 12829252 | H31: =IFERROR(G31/G$31,"") -> 1 | I31: =SUM(I29:I30) -> -37729 | J31: =IFERROR(I31/I$31,"") -> 1 | K31: =SUM(K29:K30) -> -189180 | L31: =IFERROR(K31/K$31,"") -> 1 | M31: =SUM(M29:M30) -> 12983959 | N31: =IFERROR(M31/M$31,"") -> 1 | O31: =SUM(O29:O30) -> 119236 | P31: =IFERROR(O31/O$31,"") -> 1 | Q31: =SUM(Q29:Q30) -> -44537 | R31: =IFERROR(Q31/Q$31,"") -> 1 | S31: =SUM(S29:S30) -> 12601615 | T31: =IFERROR(S31/S$31,"") -> 1 | U31: =SUM(U29:U30) -> 0 | V31: =IFERROR(U31/U$31,"") | W31: =SUM(W29:W30) -> 0 | X31: =IFERROR(W31/W$31,"") | Y31: =SUM(Y29:Y30) -> 0 | Z31: =IFERROR(Y31/Y$31,"")
B33: נתונים מצטברים בשנת : | C33: רבעון 1 | I33: רבעון 1+2 | O33: רבעון 1+2+3 | U33: רבעון 1+2+3+4
B34: =CONCATENATE("20",RIGHT(הנחיות!B20,2)) -> 2022 | C34: תרומה להכנסות מהשקעות (רווח/הפסד) | E34: תרומה להכנסה הכוללת (הון עצמי) | G34: סך נכסים | I34: תרומה להכנסות מהשקעות (רווח/הפסד) | K34: תרומה להכנסה הכוללת (הון עצמי) | M34: סך נכסים | O34: תרומה להכנסות מהשקעות (רווח/הפסד) | Q34: תרומה להכנסה הכוללת (הון עצמי) | S34: סך נכסים | U34: תרומה להכנסות מהשקעות (רווח/הפסד) | W34: תרומה להכנסה הכוללת (הון עצמי) | Y34: סך נכסים
C35: (באלפי ש"ח) | D35: (באחוזים) | E35: (באלפי ש"ח) | F35: (באחוזים) | G35: (באלפי ש"ח) | H35: (באחוזים) | I35: (באלפי ש"ח) | J35: (באחוזים) | K35: (באלפי ש"ח) | L35: (באחוזים) | M35: (באלפי ש"ח) | N35: (באחוזים) | O35: (באלפי ש"ח) | P35: (באחוזים) | Q35: (באלפי ש"ח) | R35: (באחוזים) | S35: (באלפי ש"ח) | T35: (באחוזים) | U35: (באלפי ש"ח) | V35: (באחוזים) | W35: (באלפי ש"ח) | X35: (באחוזים) | Y35: (באלפי ש"ח) | Z35: (באחוזים)
B36: מזומנים ושווי מזומנים | C36: =C8 -> 2962 | D36: =IFERROR(C36/C$51,"") -> 0.0179538 | E36: =E8 -> 2962 | F36: =IFERROR(E36/E$51,"") -> -0.041521812 | G36: =G8 -> 2791078.7 | H36: =IFERROR(G36/G$51,"") -> 0.21755585 | I36: =IF(I$23=0,"",I8+C36) -> 30937 | J36: =IFERROR(I36/I$51,"") -> 0.24311984 | K36: =IF(K$23=0,"",K8+E36) -> 30937 | L36: =IFERROR(K36/K$51,"") -> -0.11875278 | M36: =M8 -> 3209251.7 | N36: =IFERROR(M36/M$51,"") -> 0.24717051 | O36: =IF(O$23=0,"",O8+I36) -> 36197 | P36: =IFERROR(O36/O$51,"") -> 0.14685215 | Q36: =IF(Q$23=0,"",Q8+K36) -> 36197 | R36: =IFERROR(Q36/Q$51,"") -> -0.11865807 | S36: =S8 -> 2753447.7 | T36: =IFERROR(S36/S$51,"") -> 0.2184996 | U36: =IF(U$23=0,"",U8+O36) | V36: =IFERROR(U36/U$51,"") | W36: =IF(W$23=0,"",W8+Q36) | X36: =IFERROR(W36/W$51,"") | Y36: =Y8 -> 0 | Z36: =IFERROR(Y36/Y$51,"")
B37: אג"ח ממשלתיות סחירות | C37: =C9 -> 19850 | D37: =IFERROR(C37/C$51,"") -> 0.12031834 | E37: =E9 -> -87192 | F37: =IFERROR(E37/E$51,"") -> 1.2222721 | G37: =G9 -> 2277459 | H37: =IFERROR(G37/G$51,"") -> 0.1775208 | I37: =IF(I$23=0,"",I9+C37) -> 64987 | J37: =IFERROR(I37/I$51,"") -> 0.51070334 | K37: =IF(K$23=0,"",K9+E37) -> -133408 | L37: =IFERROR(K37/K$51,"") -> 0.51209139 | M37: =M9 -> 3044565 | N37: =IFERROR(M37/M$51,"") -> 0.23448665 | O37: =IF(O$23=0,"",O9+I37) -> 99499 | P37: =IFERROR(O37/O$51,"") -> 0.40366999 | Q37: =IF(Q$23=0,"",Q9+K37) -> -214403 | R37: =IFERROR(Q37/Q$51,"") -> 0.70283852 | S37: =S9 -> 2905577 | T37: =IFERROR(S37/S$51,"") -> 0.2305718 | U37: =IF(U$23=0,"",U9+O37) | V37: =IFERROR(U37/U$51,"") | W37: =IF(W$23=0,"",W9+Q37) | X37: =IFERROR(W37/W$51,"") | Y37: =Y9 -> 0 | Z37: =IFERROR(Y37/Y$51,"")
B38: אג"ח מיועדות | C38: =C10 -> 0 | D38: =IFERROR(C38/C$51,"") -> 0 | E38: =E10 -> 0 | F38: =IFERROR(E38/E$51,"") -> 0 | G38: =G10 -> 0 | H38: =IFERROR(G38/G$51,"") -> 0 | I38: =IF(I$23=0,"",I10+C38) -> 0 | J38: =IFERROR(I38/I$51,"") -> 0 | K38: =IF(K$23=0,"",K10+E38) -> 0 | L38: =IFERROR(K38/K$51,"") -> 0 | M38: =M10 -> 0 | N38: =IFERROR(M38/M$51,"") -> 0 | O38: =IF(O$23=0,"",O10+I38) -> 0 | P38: =IFERROR(O38/O$51,"") -> 0 | Q38: =IF(Q$23=0,"",Q10+K38) -> 0 | R38: =IFERROR(Q38/Q$51,"") -> 0 | S38: =S10 -> 0 | T38: =IFERROR(S38/S$51,"") -> 0 | U38: =IF(U$23=0,"",U10+O38) | V38: =IFERROR(U38/U$51,"") | W38: =IF(W$23=0,"",W10+Q38) | X38: =IFERROR(W38/W$51,"") | Y38: =Y10 -> 0 | Z38: =IFERROR(Y38/Y$51,"")
B39: אג"ח קונצרניות סחירות | C39: =C11 -> 29642 | D39: =IFERROR(C39/C$51,"") -> 0.17967135 | E39: =E11 -> -66576 | F39: =IFERROR(E39/E$51,"") -> 0.93327352 | G39: =G11 -> 1698473 | H39: =IFERROR(G39/G$51,"") -> 0.13239065 | I39: =IF(I$23=0,"",I11+C39) -> 24492 | J39: =IFERROR(I39/I$51,"") -> 0.19247151 | K39: =IF(K$23=0,"",K11+E39) -> -123034 | L39: =IFERROR(K39/K$51,"") -> 0.47227042 | M39: =M11 -> 1385087 | N39: =IFERROR(M39/M$51,"") -> 0.10667679 | O39: =IF(O$23=0,"",O11+I39) -> 38328 | P39: =IFERROR(O39/O$51,"") -> 0.15549768 | Q39: =IF(Q$23=0,"",Q11+K39) -> -158949 | R39: =IFERROR(Q39/Q$51,"") -> 0.52105372 | S39: =S11 -> 1659553 | T39: =IFERROR(S39/S$51,"") -> 0.13169368 | U39: =IF(U$23=0,"",U11+O39) | V39: =IFERROR(U39/U$51,"") | W39: =IF(W$23=0,"",W11+Q39) | X39: =IFERROR(W39/W$51,"") | Y39: =Y11 -> 0 | Z39: =IFERROR(Y39/Y$51,"")
B40: אג"ח קונצרניות לא סחירות | C40: =C12 -> 4394 | D40: =IFERROR(C40/C$51,"") -> 0.026633693 | E40: =E12 -> 4394 | F40: =IFERROR(E40/E$51,"") -> -0.061595828 | G40: =G12 -> 163318 | H40: =IFERROR(G40/G$51,"") -> 0.012730127 | I40: =IF(I$23=0,"",I12+C40) -> 10300 | J40: =IFERROR(I40/I$51,"") -> 0.080943026 | K40: =IF(K$23=0,"",K12+E40) -> 10300 | L40: =IFERROR(K40/K$51,"") -> -0.039536919 | M40: =M12 -> 132518 | N40: =IFERROR(M40/M$51,"") -> 0.010206286 | O40: =IF(O$23=0,"",O12+I40) -> 12436 | P40: =IFERROR(O40/O$51,"") -> 0.05045317 | Q40: =IF(Q$23=0,"",Q12+K40) -> 12436 | R40: =IFERROR(Q40/Q$51,"") -> -0.040766686 | S40: =S12 -> 94258 | T40: =IFERROR(S40/S$51,"") -> 0.0074798351 | U40: =IF(U$23=0,"",U12+O40) | V40: =IFERROR(U40/U$51,"") | W40: =IF(W$23=0,"",W12+Q40) | X40: =IFERROR(W40/W$51,"") | Y40: =Y12 -> 0 | Z40: =IFERROR(Y40/Y$51,"")
B41: מניות | C41: =C13 -> 76485 | D41: =IFERROR(C41/C$51,"") -> 0.46360446 | E41: =E13 -> 18582 | F41: =IFERROR(E41/E$51,"") -> -0.26048559 | G41: =G13 -> 1664164 | H41: =IFERROR(G41/G$51,"") -> 0.12971637 | I41: =IF(I$23=0,"",I13+C41) -> 52266 | J41: =IFERROR(I41/I$51,"") -> 0.41073477 | K41: =IF(K$23=0,"",K13+E41) -> -126770 | L41: =IFERROR(K41/K$51,"") -> 0.48661119 | M41: =M13 -> 1445071 | N41: =IFERROR(M41/M$51,"") -> 0.11129664 | O41: =IF(O$23=0,"",O13+I41) -> 91474 | P41: =IFERROR(O41/O$51,"") -> 0.37111236 | Q41: =IF(Q$23=0,"",Q13+K41) -> -123613 | R41: =IFERROR(Q41/Q$51,"") -> 0.40521811 | S41: =S13 -> 1392389 | T41: =IFERROR(S41/S$51,"") -> 0.1104929 | U41: =IF(U$23=0,"",U13+O41) | V41: =IFERROR(U41/U$51,"") | W41: =IF(W$23=0,"",W13+Q41) | X41: =IFERROR(W41/W$51,"") | Y41: =Y13 -> 0 | Z41: =IFERROR(Y41/Y$51,"")
B42: תעודות סל | C42: =C14 -> 11371 | D42: =IFERROR(C42/C$51,"") -> 0.068923924 | E42: =E14 -> -7168 | F42: =IFERROR(E42/E$51,"") -> 0.10048222 | G42: =G14 -> 147443 | H42: =IFERROR(G42/G$51,"") -> 0.01149272 | I42: =IF(I$23=0,"",I14+C42) -> 10923 | J42: =IFERROR(I42/I$51,"") -> 0.0858389 | K42: =IF(K$23=0,"",K14+E42) -> -16913 | L42: =IFERROR(K42/K$51,"") -> 0.064921156 | M42: =M14 -> 126277 | N42: =IFERROR(M42/M$51,"") -> 0.0097256163 | O42: =IF(O$23=0,"",O14+I42) -> -6769 | P42: =IFERROR(O42/O$51,"") -> -0.027462006 | Q42: =IF(Q$23=0,"",Q14+K42) -> -20128 | R42: =IFERROR(Q42/Q$51,"") -> 0.065981977 | S42: =S14 -> 88369 | T42: =IFERROR(S42/S$51,"") -> 0.007012514 | U42: =IF(U$23=0,"",U14+O42) | V42: =IFERROR(U42/U$51,"") | W42: =IF(W$23=0,"",W14+Q42) | X42: =IFERROR(W42/W$51,"") | Y42: =Y14 -> 0 | Z42: =IFERROR(Y42/Y$51,"")
B43: קרנות נאמנות | C43: =C15 -> 6370 | D43: =IFERROR(C43/C$51,"") -> 0.038610975 | E43: =E15 -> 6370 | F43: =IFERROR(E43/E$51,"") -> -0.089295727 | G43: =G15 -> 328668 | H43: =IFERROR(G43/G$51,"") -> 0.025618641 | I43: =IF(I$23=0,"",I15+C43) -> 25022 | J43: =IFERROR(I43/I$51,"") -> 0.19663654 | K43: =IF(K$23=0,"",K15+E43) -> 25022 | L43: =IFERROR(K43/K$51,"") -> -0.096047844 | M43: =M15 -> 192839 | N43: =IFERROR(M43/M$51,"") -> 0.014852096 | O43: =IF(O$23=0,"",O15+I43) -> 20806 | P43: =IFERROR(O43/O$51,"") -> 0.084410474 | Q43: =IF(Q$23=0,"",Q15+K43) -> 20806 | R43: =IFERROR(Q43/Q$51,"") -> -0.068204542 | S43: =S15 -> 133759 | T43: =IFERROR(S43/S$51,"") -> 0.010614433 | U43: =IF(U$23=0,"",U15+O43) | V43: =IFERROR(U43/U$51,"") | W43: =IF(W$23=0,"",W15+Q43) | X43: =IFERROR(W43/W$51,"") | Y43: =Y15 -> 0 | Z43: =IFERROR(Y43/Y$51,"")
B44: הלוואות | C44: =C16 -> 14577 | D44: =IFERROR(C44/C$51,"") -> 0.0883567 | E44: =E16 -> 14577 | F44: =IFERROR(E44/E$51,"") -> -0.20434283 | G44: =G16 -> 1308247 | H44: =IFERROR(G44/G$51,"") -> 0.10197376 | I44: =IF(I$23=0,"",I16+C44) -> 37963 | J44: =IFERROR(I44/I$51,"") -> 0.29833399 | K44: =IF(K$23=0,"",K16+E44) -> 37963 | L44: =IFERROR(K44/K$51,"") -> -0.14572234 | M44: =M16 -> 1300001 | N44: =IFERROR(M44/M$51,"") -> 0.10012362 | O44: =IF(O$23=0,"",O16+I44) -> 54829 | P44: =IFERROR(O44/O$51,"") -> 0.22244265 | Q44: =IF(Q$23=0,"",Q16+K44) -> 54829 | R44: =IFERROR(Q44/Q$51,"") -> -0.17973598 | S44: =S16 -> 1390936 | T44: =IFERROR(S44/S$51,"") -> 0.1103776 | U44: =IF(U$23=0,"",U16+O44) | V44: =IFERROR(U44/U$51,"") | W44: =IF(W$23=0,"",W16+Q44) | X44: =IFERROR(W44/W$51,"") | Y44: =Y16 -> 0 | Z44: =IFERROR(Y44/Y$51,"")
B45: פיקדונות (שאינם מובנים) | C45: =C17 -> 3159 | D45: =IFERROR(C45/C$51,"") -> 0.019147892 | E45: =E17 -> 3159 | F45: =IFERROR(E45/E$51,"") -> -0.044283391 | G45: =G17 -> 506157 | H45: =IFERROR(G45/G$51,"") -> 0.039453353 | I45: =IF(I$23=0,"",I17+C45) -> 7432 | J45: =IFERROR(I45/I$51,"") -> 0.058404715 | K45: =IF(K$23=0,"",K17+E45) -> 7432 | L45: =IFERROR(K45/K$51,"") -> -0.028527998 | M45: =M17 -> 163777 | N45: =IFERROR(M45/M$51,"") -> 0.012613795 | O45: =IF(O$23=0,"",O17+I45) -> 10499 | P45: =IFERROR(O45/O$51,"") -> 0.042594711 | Q45: =IF(Q$23=0,"",Q17+K45) -> 10499 | R45: =IFERROR(Q45/Q$51,"") -> -0.03441697 | S45: =S17 -> 165064 | T45: =IFERROR(S45/S$51,"") -> 0.013098639 | U45: =IF(U$23=0,"",U17+O45) | V45: =IFERROR(U45/U$51,"") | W45: =IF(W$23=0,"",W17+Q45) | X45: =IFERROR(W45/W$51,"") | Y45: =Y17 -> 0 | Z45: =IFERROR(Y45/Y$51,"")
B46: חוזים עתידיים | C46: =C18 -> -5369 | D46: =IFERROR(C46/C$51,"") -> -0.032543536 | E46: =E18 -> -5369 | F46: =IFERROR(E46/E$51,"") -> 0.075263542 | G46: =G18 -> 40165 | H46: =IFERROR(G46/G$51,"") -> 0.003130736 | I46: =IF(I$23=0,"",I18+C46) -> -142037 | J46: =IFERROR(I46/I$51,"") -> -1.1162043 | K46: =IF(K$23=0,"",K18+E46) -> -142037 | L46: =IFERROR(K46/K$51,"") -> 0.54521411 | M46: =M18 -> -164831 | N46: =IFERROR(M46/M$51,"") -> -0.012694973 | O46: =IF(O$23=0,"",O18+I46) -> -166804 | P46: =IFERROR(O46/O$51,"") -> -0.67672809 | Q46: =IF(Q$23=0,"",Q18+K46) -> -166804 | R46: =IFERROR(Q46/Q$51,"") -> 0.54680334 | S46: =S18 -> -174267 | T46: =IFERROR(S46/S$51,"") -> -0.013828942 | U46: =IF(U$23=0,"",U18+O46) | V46: =IFERROR(U46/U$51,"") | W46: =IF(W$23=0,"",W18+Q46) | X46: =IFERROR(W46/W$51,"") | Y46: =Y18 -> 0 | Z46: =IFERROR(Y46/Y$51,"")
...

Sheet נוסטרו סיכום
B1: פירוט תרומת אפיקי ההשקעה לתשואה הכוללת
B2: =הנחיות!B21 -> כלל ביטוח נוסטרו
B3: נוסטרו סה"כ
B5: נתונים לרבעון בשנת : | C5: רבעון 1 | I5: רבעון 2 | O5: רבעון 3 | U5: רבעון 4
B6: =CONCATENATE("20",RIGHT(הנחיות!B20,2)) -> 2022 | C6: תרומה להכנסות מהשקעות (רווח/הפסד) | E6: תרומה להכנסה הכוללת (הון עצמי) | G6: סך נכסים | I6: תרומה להכנסות מהשקעות (רווח/הפסד) | K6: תרומה להכנסה הכוללת (הון עצמי) | M6: סך נכסים | O6: תרומה להכנסות מהשקעות (רווח/הפסד) | Q6: תרומה להכנסה הכוללת (הון עצמי) | S6: סך נכסים | U6: תרומה להכנסות מהשקעות (רווח/הפסד) | W6: תרומה להכנסה הכוללת (הון עצמי) | Y6: סך נכסים
C7: (באלפי ש"ח) | D7: (באחוזים) | E7: (באלפי ש"ח) | F7: (באחוזים) | G7: (באלפי ש"ח) | H7: (באחוזים) | I7: (באלפי ש"ח) | J7: (באחוזים) | K7: (באלפי ש"ח) | L7: (באחוזים) | M7: (באלפי ש"ח) | N7: (באחוזים) | O7: (באלפי ש"ח) | P7: (באחוזים) | Q7: (באלפי ש"ח) | R7: (באחוזים) | S7: (באלפי ש"ח) | T7: (באחוזים) | U7: (באלפי ש"ח) | V7: (באחוזים) | W7: (באלפי ש"ח) | X7: (באחוזים) | Y7: (באלפי ש"ח) | Z7: (באחוזים)
B8: מזומנים ושווי מזומנים | C8: ='נוסטרו חיים'!C8+'כללי והון'!C8 -> 3596 | D8: =IFERROR(C8/C$23,"") -> 0.0059127815 | E8: ='נוסטרו חיים'!E8+'כללי והון'!E8 -> 3596 | F8: =IFERROR(E8/E$23,"") -> 0.010058544 | G8: ='נוסטרו חיים'!G8+'כללי והון'!G8 -> 3395290 | H8: =IFERROR(G8/G$23,"") -> 0.093574616 | I8: ='נוסטרו חיים'!I8+'כללי והון'!I8 -> 40095 | J8: =IFERROR(I8/I$23,"") -> 0.10352226 | K8: ='נוסטרו חיים'!K8+'כללי והון'!K8 -> 40095 | L8: =IFERROR(K8/K$23,"") -> 0.1331414 | M8: ='נוסטרו חיים'!M8+'כללי והון'!M8 -> 3833463 | N8: =IFERROR(M8/M$23,"") -> 0.10500502 | O8: ='נוסטרו חיים'!O8+'כללי והון'!O8 -> 10067 | P8: =IFERROR(O8/O$23,"") -> 0.019123405 | Q8: ='נוסטרו חיים'!Q8+'כללי והון'!Q8 -> 10067 | R8: =IFERROR(Q8/Q$23,"") -> 0.026412936 | S8: ='נוסטרו חיים'!S8+'כללי והון'!S8 -> 3407327 | T8: =IFERROR(S8/S$23,"") -> 0.093516411 | U8: ='נוסטרו חיים'!U8+'כללי והון'!U8 -> 0 | V8: =IFERROR(U8/U$23,"") | W8: ='נוסטרו חיים'!W8+'כללי והון'!W8 -> 0 | X8: =IFERROR(W8/W$23,"") | Y8: ='נוסטרו חיים'!Y8+'כללי והון'!Y8 -> 0 | Z8: =IFERROR(Y8/Y$23,"")
B9: אג"ח ממשלתיות סחירות | C9: ='נוסטרו חיים'!C9+'כללי והון'!C9 -> 21319 | D9: =IFERROR(C9/C$23,"") -> 0.035054113 | E9: ='נוסטרו חיים'!E9+'כללי והון'!E9 -> -89583 | F9: =IFERROR(E9/E$23,"") -> -0.25057691 | G9: ='נוסטרו חיים'!G9+'כללי והון'!G9 -> 2438826 | H9: =IFERROR(G9/G$23,"") -> 0.067214349 | I9: ='נוסטרו חיים'!I9+'כללי והון'!I9 -> 47356 | J9: =IFERROR(I9/I$23,"") -> 0.12226961 | K9: ='נוסטרו חיים'!K9+'כללי והון'!K9 -> -48587 | L9: =IFERROR(K9/K$23,"") -> -0.16134035 | M9: ='נוסטרו חיים'!M9+'כללי והון'!M9 -> 3187375 | N9: =IFERROR(M9/M$23,"") -> 0.087307577 | O9: ='נוסטרו חיים'!O9+'כללי והון'!O9 -> 35736 | P9: =IFERROR(O9/O$23,"") -> 0.067884572 | Q9: ='נוסטרו חיים'!Q9+'כללי והון'!Q9 -> -83123 | R9: =IFERROR(Q9/Q$23,"") -> -0.21809104 | S9: ='נוסטרו חיים'!S9+'כללי והון'!S9 -> 3011005 | T9: =IFERROR(S9/S$23,"") -> 0.082639083 | U9: ='נוסטרו חיים'!U9+'כללי והון'!U9 -> 0 | V9: =IFERROR(U9/U$23,"") | W9: ='נוסטרו חיים'!W9+'כללי והון'!W9 -> 0 | X9: =IFERROR(W9/W$23,"") | Y9: ='נוסטרו חיים'!Y9+'כללי והון'!Y9 -> 0 | Z9: =IFERROR(Y9/Y$23,"")
B10: אג"ח מיועדות | C10: ='נוסטרו חיים'!C10+'כללי והון'!C10 -> 333836 | D10: =IFERROR(C10/C$23,"") -> 0.54891528 | E10: ='נוסטרו חיים'!E10+'כללי והון'!E10 -> 333836 | F10: =IFERROR(E10/E$23,"") -> 0.93378871 | G10: ='נוסטרו חיים'!G10+'כללי והון'!G10 -> 14032048 | H10: =IFERROR(G10/G$23,"") -> 0.38672499 | I10: ='נוסטרו חיים'!I10+'כללי והון'!I10 -> 444623 | J10: =IFERROR(I10/I$23,"") -> 1.147983 | K10: ='נוסטרו חיים'!K10+'כללי והון'!K10 -> 444623 | L10: =IFERROR(K10/K$23,"") -> 1.4764367 | M10: ='נוסטרו חיים'!M10+'כללי והון'!M10 -> 13965497 | N10: =IFERROR(M10/M$23,"") -> 0.38253852 | O10: ='נוסטרו חיים'!O10+'כללי והון'!O10 -> 343868 | P10: =IFERROR(O10/O$23,"") -> 0.65321614 | Q10: ='נוסטרו חיים'!Q10+'כללי והון'!Q10 -> 343868 | R10: =IFERROR(Q10/Q$23,"") -> 0.90221153 | S10: ='נוסטרו חיים'!S10+'כללי והון'!S10 -> 14305070 | T10: =IFERROR(S10/S$23,"") -> 0.39261239 | U10: ='נוסטרו חיים'!U10+'כללי והון'!U10 -> 0 | V10: =IFERROR(U10/U$23,"") | W10: ='נוסטרו חיים'!W10+'כללי והון'!W10 -> 0 | X10: =IFERROR(W10/W$23,"") | Y10: ='נוסטרו חיים'!Y10+'כללי והון'!Y10 -> 0 | Z10: =IFERROR(Y10/Y$23,"")
B11: אג"ח קונצרניות סחירות | C11: ='נוסטרו חיים'!C11+'כללי והון'!C11 -> 53477 | D11: =IFERROR(C11/C$23,"") -> 0.087930428 | E11: ='נוסטרו חיים'!E11+'כללי והון'!E11 -> -99484 | F11: =IFERROR(E11/E$23,"") -> -0.27827147 | G11: ='נוסטרו חיים'!G11+'כללי והון'!G11 -> 2433315 | H11: =IFERROR(G11/G$23,"") -> 0.067062465 | I11: ='נוסטרו חיים'!I11+'כללי והון'!I11 -> 8272 | J11: =IFERROR(I11/I$23,"") -> 0.021357679 | K11: ='נוסטרו חיים'!K11+'כללי והון'!K11 -> -72390 | L11: =IFERROR(K11/K$23,"") -> -0.24038174 | M11: ='נוסטרו חיים'!M11+'כללי והון'!M11 -> 2236872 | N11: =IFERROR(M11/M$23,"") -> 0.061271697 | O11: ='נוסטרו חיים'!O11+'כללי והון'!O11 -> 23286 | P11: =IFERROR(O11/O$23,"") -> 0.044234389 | Q11: ='נוסטרו חיים'!Q11+'כללי והון'!Q11 -> -57107 | R11: =IFERROR(Q11/Q$23,"") -> -0.14983248 | S11: ='נוסטרו חיים'!S11+'כללי והון'!S11 -> 2485153 | T11: =IFERROR(S11/S$23,"") -> 0.068206717 | U11: ='נוסטרו חיים'!U11+'כללי והון'!U11 -> 0 | V11: =IFERROR(U11/U$23,"") | W11: ='נוסטרו חיים'!W11+'כללי והון'!W11 -> 0 | X11: =IFERROR(W11/W$23,"") | Y11: ='נוסטרו חיים'!Y11+'כללי והון'!Y11 -> 0 | Z11: =IFERROR(Y11/Y$23,"")
B12: אג"ח קונצרניות לא סחירות | C12: ='נוסטרו חיים'!C12+'כללי והון'!C12 -> 10931 | D12: =IFERROR(C12/C$23,"") -> 0.017973475 | E12: ='נוסטרו חיים'!E12+'כללי והון'!E12 -> 10931 | F12: =IFERROR(E12/E$23,"") -> 0.030575625 | G12: ='נוסטרו חיים'!G12+'כללי והון'!G12 -> 385235 | H12: =IFERROR(G12/G$23,"") -> 0.010617125 | I12: ='נוסטרו חיים'!I12+'כללי והון'!I12 -> 14686 | J12: =IFERROR(I12/I$23,"") -> 0.037918143 | K12: ='נוסטרו חיים'!K12+'כללי והון'!K12 -> 14686 | L12: =IFERROR(K12/K$23,"") -> 0.048767043 | M12: ='נוסטרו חיים'!M12+'כללי והון'!M12 -> 355720 | N12: =IFERROR(M12/M$23,"") -> 0.0097437708 | O12: ='נוסטרו חיים'!O12+'כללי והון'!O12 -> 8252 | P12: =IFERROR(O12/O$23,"") -> 0.015675607 | Q12: ='נוסטרו חיים'!Q12+'כללי והון'!Q12 -> 8252 | R12: =IFERROR(Q12/Q$23,"") -> 0.021650894 | S12: ='נוסטרו חיים'!S12+'כללי והון'!S12 -> 307900 | T12: =IFERROR(S12/S$23,"") -> 0.0084505252 | U12: ='נוסטרו חיים'!U12+'כללי והון'!U12 -> 0 | V12: =IFERROR(U12/U$23,"") | W12: ='נוסטרו חיים'!W12+'כללי והון'!W12 -> 0 | X12: =IFERROR(W12/W$23,"") | Y12: ='נוסטרו חיים'!Y12+'כללי והון'!Y12 -> 0 | Z12: =IFERROR(Y12/Y$23,"")
B13: מניות | C13: ='נוסטרו חיים'!C13+'כללי והון'!C13 -> 77760 | D13: =IFERROR(C13/C$23,"") -> 0.12785815 | E13: ='נוסטרו חיים'!E13+'כללי והון'!E13 -> 24239 | F13: =IFERROR(E13/E$23,"") -> 0.067800071 | G13: ='נוסטרו חיים'!G13+'כללי והון'!G13 -> 2095017 | H13: =IFERROR(G13/G$23,"") -> 0.05773893 | I13: ='נוסטרו חיים'!I13+'כללי והון'!I13 -> -14366 | J13: =IFERROR(I13/I$23,"") -> -0.037091927 | K13: ='נוסטרו חיים'!K13+'כללי והון'!K13 -> -139316 | L13: =IFERROR(K13/K$23,"") -> -0.46261946 | M13: ='נוסטרו חיים'!M13+'כללי והון'!M13 -> 1909752 | N13: =IFERROR(M13/M$23,"") -> 0.052311328 | O13: ='נוסטרו חיים'!O13+'כללי והון'!O13 -> 42411 | P13: =IFERROR(O13/O$23,"") -> 0.080564489 | Q13: ='נוסטרו חיים'!Q13+'כללי והון'!Q13 -> 68868 | R13: =IFERROR(Q13/Q$23,"") -> 0.18068998 | S13: ='נוסטרו חיים'!S13+'כללי והון'!S13 -> 1899420 | T13: =IFERROR(S13/S$23,"") -> 0.052130876 | U13: ='נוסטרו חיים'!U13+'כללי והון'!U13 -> 0 | V13: =IFERROR(U13/U$23,"") | W13: ='נוסטרו חיים'!W13+'כללי והון'!W13 -> 0 | X13: =IFERROR(W13/W$23,"") | Y13: ='נוסטרו חיים'!Y13+'כללי והון'!Y13 -> 0 | Z13: =IFERROR(Y13/Y$23,"")
