Workbook
Name Additional_Factor: 'אפשרויות בחירה'!$C$701:$C$850
Name Amoritization: 'אפשרויות בחירה'!$C$546:$C$550
Name Capsule: 'אפשרויות בחירה'!$C$926:$C$928
Name Company_Name: 'File Name Info'!$A$34:$A$120
Name Company_Name_ID: 'File Name Info'!$A$34:$B$120
Name Consortium: 'אפשרויות בחירה'!$C$514:$C$515
Name Country_list: 'אפשרויות בחירה'!$C$4:$C$85
Name Country_list_funds: 'אפשרויות בחירה'!$C$4:$C$103
Name CSA: 'אפשרויות בחירה'!$C$688:$C$689
Name Delivery: 'אפשרויות בחירה'!$C$666:$C$667
Name Dependence_Independence: 'אפשרויות בחירה'!$C$654:$C$655
Name Duration_Underlying_Interest_Rate: 'אפשרויות בחירה'!$C$680:$C$687
Name File_Type: 'File Name Info'!$A$10:$A$12
Name Full_File_Type: 'File Name Info'!$A$11:$B$13
Name Full_Type: 'File Name Info'!$A$2:$B$8
Name Full_Type_Nostro: 'File Name Info'!$A$3:$B$6
Name Full_Year: 'File Name Info'!$A$22:$B$31
Name Fund_Strategy: 'אפשרויות בחירה'!$C$597:$C$621
Name Fund_type: 'אפשרויות בחירה'!$C$328:$C$498
Name Holding_interest: 'אפשרויות בחירה'!$C$146:$C$147
Name In_the_books: 'אפשרויות בחירה'!$C$656:$C$657
Name Industry_Sector: 'אפשרויות בחירה'!$C$1129:$C$1245
Name Industry_sector_all: 'אפשרויות בחירה'!$C$202:$C$327
Name Industry_sectors: 'אפשרויות בחירה'!$C$202:$C$327
Name israel_abroad: 'אפשרויות בחירה'!$C$2:$C$3
Name Issuer_Number_Banks: 'אפשרויות בחירה'!$C$111:$C$113
Name Issuer_Number_Fund: 'אפשרויות בחירה'!$C$114:$C$117
Name issuer_number_loan: 'אפשרויות בחירה'!$C$118:$C$126
Name Issuer_Number_Type: 'אפשרויות בחירה'!$C$104:$C$110
Name Issuer_Number_Type_2: 'אפשרויות בחירה'!$C$1076:$C$1079
Name Issuer_Number_Type_3: 'אפשרויות בחירה'!$C$1081:$C$1085
Name Issuer_Number_Type_V2: 'אפשרויות בחירה'!$C$104:$C$110
Name Issuer_Type_TFunds: 'אפשרויות בחירה'!$C$1087:$C$1089
Name Leading_factor: 'אפשרויות בחירה'!$C$692:$C$700
Name Linked_Type: 'אפשרויות בחירה'!$C$516:$C$519
Name other_investments: 'אפשרויות בחירה'!$C$1000:$C$1033
Name Penalty: 'אפשרויות בחירה'!$C$851:$C$852
Name QTR: 'File Name Info'!$A$15:$A$19
Name Rating_Agency: 'אפשרויות בחירה'!$C$188:$C$201
Name real_estate_lifestage: 'אפשרויות בחירה'!$C$634:$C$642
Name real_estate_loans: 'אפשרויות בחירה'!$C$553:$C$591
Name Real_Estate_Main_Use: 'אפשרויות בחירה'!$C$622:$C$633
Name Recourse_Nonrecourse: 'אפשרויות בחירה'!$C$544:$C$545
Name Repayment_Rights: 'אפשרויות בחירה'!$C$551:$C$552
Name Reset_frequency: 'אפשרויות בחירה'!$C$658:$C$665
Name Security_ID_Number_Type: 'אפשרויות בחירה'!$C$1113:$C$1116
Name Security_Number_Loans: 'אפשרויות בחירה'!$C$131
Name Stock_Exchange: 'אפשרויות בחירה'!$C$1283:$C$1315
Name Stock_Exchange_Gov_Bonds: 'אפשרויות בחירה'!$C$148:$C$181
Name Subordination_Risk: 'אפשרויות בחירה'!$C$186:$C$187
Name Tradeable_Status: 'אפשרויות בחירה'!$C$1272:$C$1281
Name Tradeable_Status_All: 'אפשרויות בחירה'!$C$135:$C$145
Name tradeable_status_bonds: 'אפשרויות בחירה'!$C$1248:$C$1253
Name tradeable_status_funds: 'אפשרויות בחירה'!$C$1118:$C$1119
Name tradeable_status_stock: 'אפשרויות בחירה'!$C$1255:$C$1259
Name Tradeable_Status_v2: 'אפשרויות בחירה'!$C$1121:$C$1126
Name tradeable_status_warrants: 'אפשרויות בחירה'!$C$1261:$C$1265
Name tradeable_status_warrants_v2: 'אפשרויות בחירה'!$C$1267:$C$1269
Name Transaction: 'אפשרויות בחירה'!$C$643:$C$646
Name Type: 'File Name Info'!$A$2:$A$8

Sheet עמוד פתיחה
A1: קובץ דיווח עבור רשימת נכסים ברמת הנכס הבודד (חוזר גופים מוסדיים 2015-9-14)
A3: יש לבחור תחום: | D3: נכסי עמיתים - קרנות פנסיה
A5: האם מדובר בקובץ לממומנה או לציבור: | D5: לציבור
A7: יש לבחור את רבעון הדיווח: | D7: Q1
A9: יש לבחור את שנת הדיווח: | D9: 2025
A11: יש לבחור את הגוף המוסדי: | D11: מור פנסיה נכסים
A13: ח.פ. הגוף המוסדי: | D13: 514956465
A15: שם קובץ לשמירה | D15: =IF(D5="לממונה",CONCATENATE(D13, "_",VLOOKUP(D3,Full_Type,2,0),"_",D7,VLOOKUP(D9,Full_Year,2,0),".xlxs"),IF(D5="לציבור",CONCATENATE(D13,"_",VLOOKUP(D3,Full_Type_Nostro,2,0),"_",VLOOKUP(D5,Full_File_Type,2,0),"_",D7,VLOOKUP(D9,Full_Year,2,0),".xlsx"),"שם קובץ לשמירה")) -> 514956465_pn_p_Q125.xlsx
A17: פרטי האחראי על הדיווח בגוף המוסדי | B17: שם: | D17: סיוון לוי, רו"ח
B19: מספר טלפון:
B21: כתובת מייל:
A23: הוראות למילוי הדיווח: | D23: יש לדווח לפי ההנחיות בחלק ג' לנספח 5.4.3.2 שבפרק 3 שבחלק 4 לשער 5 בחוזר המאוחד - "רשימת נכסים ברמת הנכס הבודד".

Sheet סכום נכסים
C1: ידווח בקבצי נכסי הנוסטרו בלבד
B2: שווי הוגן | C2: עלות מופחתת | D2: השיטה שיושמה בדוח הכספי | E2: שיעור מסך נכסי השקעה
A3: מזומנים ושווי מזומנים | B3: 2094300 | E3: =+B3/$B$30 -> 0.19096883
A4: איגרות חוב ממשלתיות | B4: 1711552 | E4: =+B4/$B$30 -> 0.15606794
A5: ניירות ערך מסחריים | B5: 6047.535 | E5: =+B5/$B$30 -> 0.00055144472
A6: איגרות חוב | B6: 1290790.9 | E6: =+B6/$B$30 -> 0.11770082
A7: מניות, מניות בכורה ויחידות השתתפות | B7: 1561297.5 | E7: =+B7/$B$30 -> 0.14236697
A8: קרנות סל | B8: 226765.35 | E8: =+B8/$B$30 -> 0.020677608
A9: קרנות נאמנות | B9: =SUM('קרנות נאמנות'!T:T) -> 373786.8 | E9: =+B9/$B$30 -> 0.034083764
A10: כתבי אופציה | B10: 20380.259 | E10: =+B10/$B$30 -> 0.0018583747
A11: אופציות | B11: 0 | E11: =+B11/$B$30 -> 0
A12: חוזים עתידיים | B12: -71145.368 | E12: =+B12/$B$30 -> -0.0064873932
A13: מוצרים מובנים | B13: 238.56796 | E13: =+B13/$B$30 -> 2.1753829e-05
A14: לא סחיר איגרות חוב ממשלתיות | B14: 0 | E14: =+B14/$B$30 -> 0
A15: לא סחיר איגרות חוב מיועדות | B15: 197260.09 | E15: =+B15/$B$30 -> 0.01798717
A16: אפיק השקעה מובטח תשואה | B16: 2854013.5 | E16: =+B16/$B$30 -> 0.26024334
A17: לא סחיר ניירות ערך מסחריים | B17: 14281.02 | E17: =+B17/$B$30 -> 0.0013022154
A18: לא סחיר איגרות חוב | B18: 158740.63 | E18: =+B18/$B$30 -> 0.014474771
A19: לא סחיר מניות, מניות בכורה ויחידות השתתפות | B19: 54112.782 | E19: =+B19/$B$30 -> 0.0049342762
A20: קרנות השקעה | B20: 310819.53 | E20: =+B20/$B$30 -> 0.028342092
A21: לא סחיר כתבי אופציה | B21: 8363.9073 | E21: =+B21/$B$30 -> 0.00076266322
... A23: לא סחיר נגזרים אחרים | B23: 6219.0533 | E23: =+B23/$B$30 -> 0.00056708463
A24: הלוואות | B24: =SUM(הלוואות!AT:AT) -> 99475.038 | E24: =+B24/$B$30 -> 0.0090706353
A25: לא סחיר מוצרים מובנים | B25: 11439.529 | E25: =+B25/$B$30 -> 0.0010431139
A26: פיקדונות מעל 3 חודשים | B26: 0 | E26: =+B26/$B$30 -> 0
A27: זכויות מקרקעין | B27: 33410.519 | E27: =+B27/$B$30 -> 0.0030465395
A28: השקעה בחברות מוחזקות | B28: 0 | E28: =+B28/$B$30 -> 0
A29: נכסים אחרים | B29: =SUM('נכסים אחרים'!N:N) -> 4562.0069 | E29: =+B29/$B$30 -> 0.00041598679
A30: סך הכל נכסים | B30: =SUM(B3:B29) -> 10966711 | E30: =SUM(E3:E29) -> 1
A31: מסגרות אשראי | B31: =+SUM('מסגרות אשראי'!S:S) -> 142676.91
A32: יתרות התחייבויות להשקעה | B32: =+SUM('יתרות התחייבות להשקעה'!O:O) -> 187879.46

Sheet מזומנים ושווי מזומנים
A1: מספר קופה/קרן/ח.פ. עבור חברת ביטוח | B1: מספר מסלול | C1: שם הבנק | D1: מספר מזהה בנק | E1: סוג מספר מזהה בנק | F1: מאפיין עיקרי | G1: ישראל/חו"ל | H1: בעל עניין/צד קשור | I1: דירוג הבנק | J1: שם מדרג | K1: מטבע פעילות | L1: שווי מטבעי | M1: שער חליפין | N1: שיעור ריבית | O1: שווי הוגן (באלפי ש"ח) | P1: שיעור מנכסי אפיק ההשקעה | Q1: שיעור מסך נכסי ההשקעה
A2: 13908 | B2: 13909 | C2: בנק הבינלאומי הראשון בע"מ | D2: 31 | E2: סימול בנק | F2: מזומן ועו"ש בש"ח | G2: ישראל | H2: לא | I2: ilAAA | J2: S&P מעלות | K2: ILS | L2: -1e-05 | M2: 1 | O2: -1e-05 | P2: -1.2322235e-11 | Q2: -2.4364448e-12
A3: 13908 | B3: 13909 | C3: בנק הבינלאומי הראשון בע"מ | D3: 31 | E3: סימול בנק | F3: מזומן ועו"ש בש"ח | G3: ישראל | H3: לא | I3: ilAAA | J3: S&P מעלות | K3: ILS | L3: 417024.65 | M3: 1 | O3: 417024.65 | P3: 0.51386756 | Q3: 0.10160576
A4: 13908 | B4: 13909 | C4: בנק המזרחי המאוחד בע"מ | D4: 20 | E4: סימול בנק | F4: מזומן ועו"ש בש"ח | G4: ישראל | H4: לא | I4: ilAAA | J4: S&P מעלות | K4: ILS | L4: 263.94606 | M4: 1 | O4: 263.94606 | P4: 0.00032524053 | Q4: 6.4309002e-05
A5: 13908 | B5: 13909 | C5: בנק הבינלאומי הראשון בע"מ | D5: 31 | E5: סימול בנק | F5: מזומן ועו"ש נקוב במט"ח | G5: ישראל | H5: לא | I5: ilAAA | J5: S&P מעלות | K5: USD | L5: 96449.892 | M5: 3.718 | O5: 358600.7 | P5: 0.4418762 | Q5: 0.087371083
A6: 13908 | B6: 13909 | C6: בנק המזרחי המאוחד בע"מ | D6: 20 | E6: סימול בנק | F6: מזומן ועו"ש נקוב במט"ח | G6: ישראל | H6: לא | I6: ilAAA | J6: S&P מעלות | K6: USD | L6: 0.00025013448 | M6: 3.718 | O6: 0.00093 | P6: 1.1459678e-09 | Q6: 2.2658937e-10
A7: 13908 | B7: 13909 | C7: בנק הבינלאומי הראשון בע"מ | D7: 31 | E7: סימול בנק | F7: מזומן ועו"ש נקוב במט"ח | G7: ישראל | H7: לא | I7: ilAAA | J7: S&P מעלות | K7: CHF | L7: 54.34228 | M7: 4.2171 | O7: 229.16683 | P7: 0.00028238475 | Q7: 5.5835234e-05
A8: 13908 | B8: 13909 | C8: בנק הבינלאומי הראשון בע"מ | D8: 31 | E8: סימול בנק | F8: מזומן ועו"ש נקוב במט"ח | G8: ישראל | H8: לא | I8: ilAAA | J8: S&P מעלות | K8: GBP | L8: 693.79711 | M8: 4.8108 | O8: 3337.7191 | P8: 0.0041128159 | Q8: 0.00081321686
A9: 13908 | B9: 13909 | C9: בנק הבינלאומי הראשון בע"מ | D9: 31 | E9: סימול בנק | F9: מזומן ועו"ש נקוב במט"ח | G9: ישראל | H9: לא | I9: ilAAA | J9: S&P מעלות | K9: JPY | L9: 87393.79 | M9: 0.024893 | O9: 2175.4936 | P9: 0.0026806943 | Q9: 0.00053004702
A10: 13908 | B10: 13909 | C10: בנק המזרחי המאוחד בע"מ | D10: 20 | E10: סימול בנק | F10: מזומן ועו"ש נקוב במט"ח | G10: ישראל | H10: לא | I10: ilAAA | J10: S&P מעלות | K10: JPY | L10: 0.00080343872 | M10: 0.024893 | O10: 2e-05 | P10: 2.4644469e-11 | Q10: 4.8728897e-12
A11: 13908 | B11: 13909 | C11: בנק הבינלאומי הראשון בע"מ | D11: 31 | E11: סימול בנק | F11: מזומן ועו"ש נקוב במט"ח | G11: ישראל | H11: לא | I11: ilAAA | J11: S&P מעלות | K11: CAD | L11: 311.6101 | M11: 2.589 | O11: 806.75855 | P11: 0.00099410682 | Q11: 0.00019656227
A12: 13908 | B12: 13909 | C12: בנק הבינלאומי הראשון בע"מ | D12: 31 | E12: סימול בנק | F12: מזומן ועו"ש נקוב במט"ח | G12: ישראל | H12: לא | I12: ilAAA | J12: S&P מעלות | K12: EUR | L12: 7153.9733 | M12: 4.0219 | O12: 28772.565 | P12: 0.03545423 | Q12: 0.0070102768
A13: 13908 | B13: 13909 | C13: בנק הבינלאומי הראשון בע"מ | D13: 31 | E13: סימול בנק | F13: מזומן ועו"ש נקוב במט"ח | G13: ישראל | H13: לא | I13: ilAAA | J13: S&P מעלות | K13: USD | L13: -9.9480689 | M13: 3.718 | O13: -36.98692 | P13: -4.5576151e-05 | Q13: -9.0116591e-06
... A237: 13918 | B237: 15273 | C237: בנק הבינלאומי הראשון בע"מ | D237: 31 | E237: סימול בנק | F237: מזומן ועו"ש נקוב במט"ח | G237: ישראל | H237: לא | I237: ilAAA | J237: S&P מעלות | K237: USD | L237: -0.039661108 | M237: 3.718 | O237: -0.14746 | P237: -2.2053101e-05 | Q237: -6.1912642e-06
A238: 13908 | B238: 15267
A239: 13918 | B239: 15274

Sheet איגרות חוב ממשלתיות
A1: מספר קופה/קרן/ח.פ. עבור חברת ביטוח | B1: מספר מסלול | C1: שם מנפיק | D1: שם נייר ערך | E1: מספר נייר ערך | F1: מאפיין עיקרי | G1: ישראל/חו"ל | H1: מדינה לפי חשיפה כלכלית | I1: זירת מסחר | J1: דירוג | K1: שם מדרג | L1: מטבע פעילות | M1: מח"מ | N1: מועד פדיון | O1: שיעור ריבית | P1: תשואה לפדיון | Q1: סכום לקבל (במטבע הפעילות) | R1: ערך נקוב (יחידות) | S1: שער חליפין | T1: שער נייר הערך | U1: שווי הוגן (באלפי ש"ח) | V1: עלות מופחתת (באלפי ש"ח) | W1: השיטה שיושמה בדוח הכספי | X1: שיעור מערך נקוב מונפק | Y1: שיעור מנכסי אפיק ההשקעה | Z1: שיעור מסך נכסי ההשקעה
A2: 13908 | B2: 13909 | C2: מדינת ישראל | D2: ממשל צמודה 1025 | E2: IL0011359127 | F2: צמוד למדד המחירים לצרכן בריבית קבועה | G2: ישראל | H2: ישראל | I2: TASE | J2: NR | K2: NR | L2: ILS | M2: 0.584 | N2: 31/10/2025 | O2: 0.0075 | P2: 0.0124 | Q2: 0 | R2: 32061125 | S2: 1 | T2: 116.16 | U2: 37242.203 | W2: שווי הוגן | X2: 0.0014772855 | Y2: 0.09128584 | Z2: 0.0090738573
A3: 13908 | B3: 13909 | C3: מדינת ישראל | D3: ממשל שקלית 0327 | E3: IL0011393449 | F3: לא צמוד למדד המחירים לצרכן ריבית קבועה | G3: ישראל | H3: ישראל | I3: TASE | J3: NR | K3: NR | L3: ILS | M3: 1.977 | N3: 31/03/2027 | O3: 0.02 | P3: 0.0422 | Q3: 0 | R3: 15425980 | S3: 1 | T3: 95.83 | U3: 14782.717 | W3: שווי הוגן | X3: 0.00054647033 | Y3: 0.036234503 | Z3: 0.0036017274
A4: 13908 | B4: 13909 | C4: מדינת ישראל | D4: ממשל שקלית 0347 | E4: IL0011401937 | F4: לא צמוד למדד המחירים לצרכן ריבית קבועה | G4: ישראל | H4: ישראל | I4: TASE | J4: NR | K4: NR | L4: ILS | M4: 14.743 | N4: 31/03/2047 | O4: 0.0375 | P4: 0.0486 | Q4: 0 | R4: 6360000 | S4: 1 | T4: 85.21 | U4: 5419.356 | W4: שווי הוגן | X4: 0.00024231946 | Y4: 0.013283598 | Z4: 0.0013203962
A5: 13908 | B5: 13909 | C5: מדינת ישראל | D5: ממשל צמודה 0527 | E5: IL0011408478 | F5: צמוד למדד המחירים לצרכן בריבית קבועה | G5: ישראל | H5: ישראל | I5: TASE | J5: NR | K5: NR | L5: ILS | M5: 2.142 | N5: 31/05/2027 | O5: 0.0075 | P5: 0.0194 | Q5: 0 | R5: 44377464 | S5: 1 | T5: 114.63 | U5: 50869.887 | W5: שווי הוגן | X5: 0.0018219999 | Y5: 0.1246892 | Z5: 0.012394167
A6: 13908 | B6: 13909 | C6: מדינת ישראל | D6: ממשל שקלית 0928 | E6: IL0011508798 | F6: לא צמוד למדד המחירים לצרכן ריבית קבועה | G6: ישראל | H6: ישראל | I6: TASE | J6: NR | K6: NR | L6: ILS | M6: 3.36 | N6: 28/09/2028 | O6: 0.0225 | P6: 0.0426 | Q6: 0 | R6: 27884049 | S6: 1 | T6: 94.71 | U6: 26408.983 | W6: שווי הוגן | X6: 0.00080307685 | Y6: 0.064732105 | Z6: 0.006434403
A7: 13908 | B7: 13909 | C7: מדינת ישראל | D7: ממשל צמודה 0529 | E7: IL0011570236 | F7: צמוד למדד המחירים לצרכן בריבית קבועה | G7: ישראל | H7: ישראל | I7: TASE | J7: NR | K7: NR | L7: ILS | M7: 4.115 | N7: 31/05/2029 | O7: 0.005 | P7: 0.0197 | Q7: 0 | R7: 15612315 | S7: 1 | T7: 109.42 | U7: 17082.995 | W7: שווי הוגן | X7: 0.0005679711 | Y7: 0.041872807 | Z7: 0.0041621775
A8: 13908 | B8: 13909 | C8: מדינת ישראל | D8: ממשל שקלית 0330 | E8: IL0011609851 | F8: לא צמוד למדד המחירים לצרכן ריבית קבועה | G8: ישראל | H8: ישראל | I8: TASE | J8: NR | K8: NR | L8: ILS | M8: 4.892 | N8: 31/03/2030 | O8: 0.01 | P8: 0.0429 | Q8: 0 | R8: 423156 | S8: 1 | T8: 85.48 | U8: 361.71375 | W8: שווי הוגן | X8: 1.1207812e-05 | Y8: 0.00088661092 | Z8: 8.812956e-05
A9: 13908 | B9: 13909 | C9: מדינת ישראל | D9: ממשל שקלית 0537 | E9: IL0011661803 | F9: לא צמוד למדד המחירים לצרכן ריבית קבועה | G9: ישראל | H9: ישראל | I9: TASE | J9: NR | K9: NR | L9: ILS | M9: 10.807 | N9: 31/05/2037 | O9: 0.015 | P9: 0.0461 | Q9: 0 | R9: 3150000 | S9: 1 | T9: 72.72 | U9: 2290.68 | W9: שווי הוגן | X9: 9.6430962e-05 | Y9: 0.0056147766 | Z9: 0.00055811155
A10: 13908 | B10: 13909 | C10: מדינת ישראל | D10: ממשל צמודה 0726 | E10: IL0011695645 | F10: צמוד למדד המחירים לצרכן בריבית קבועה | G10: ישראל | H10: ישראל | I10: TASE | J10: NR | K10: NR | L10: ILS | M10: 1.33 | N10: 31/07/2026 | O10: 0.001 | P10: 0.0196 | Q10: 0 | R10: 49712765 | S10: 1 | T10: 112.95 | U10: 56150.568 | W10: שווי הוגן | X10: 0.0024604719 | Y10: 0.13763288 | Z10: 0.013680776
A11: 13908 | B11: 13909 | C11: מדינת ישראל | D11: ממשל צמודה 1131 | E11: IL0011722209 | F11: צמוד למדד המחירים לצרכן בריבית קבועה | G11: ישראל | H11: ישראל | I11: TASE | J11: NR | K11: NR | L11: ILS | M11: 6.646 | N11: 30/11/2031 | O11: 0.001 | P11: 0.0203 | Q11: 0 | R11: 29107525 | S11: 1 | T11: 101.91 | U11: 29663.479 | W11: שווי הוגן | X11: 0.00094800192 | Y11: 0.072709329 | Z11: 0.007227343
A12: 13908 | B12: 13909 | C12: מדינת ישראל | D12: ממשל שקלית 0432 | E12: IL0011806606 | F12: לא צמוד למדד המחירים לצרכן ריבית קבועה | G12: ישראל | H12: ישראל | I12: TASE | J12: NR | K12: NR | L12: ILS | M12: 6.681 | N12: 30/04/2032 | O12: 0.013 | P12: 0.0438 | Q12: 0 | R12: 6000000 | S12: 1 | T12: 82.78 | U12: 4966.8 | W12: שווי הוגן | X12: 0.0001733631 | Y12: 0.01217432 | Z12: 0.0012101334
A13: 13908 | B13: 13909 | C13: מדינת ישראל | D13: ממשל שקלית 1152 | E13: IL0011840761 | F13: לא צמוד למדד המחירים לצרכן ריבית קבועה | G13: ישראל | H13: ישראל | I13: TASE | J13: NR | K13: NR | L13: ILS | M13: 17.432 | N13: 29/11/2052 | O13: 0.028 | P13: 0.0494 | Q13: 0 | R13: 300000 | S13: 1 | T13: 68.95 | U13: 206.85 | W13: שווי הוגן | X13: 1.2954577e-05 | Y13: 0.00050701824 | Z13: 5.0397862e-05
... A18: 13908 | B18: 13909 | C18: מדינת ישראל | D18: ממשל צמודה 1033 | E18: IL0012043795 | F18: צמוד למדד המחירים לצרכן בריבית קבועה | G18: ישראל | H18: ישראל | I18: TASE | J18: NR | K18: NR | L18: ILS | M18: 8.028 | N18: 31/10/2033 | O18: 0.016 | P18: 0.021 | Q18: 0 | R18: 14429000 | S18: 1 | T18: 100.49 | U18: 14499.702 | W18: שווי הוגן | X18: 0.00071543051 | Y18: 0.035540795 | Z18: 0.0035327724
A19: 13908 | B19: 13909 | C19: STATE OF ISRAEL | D19: ISRAEL 6.5 31 | E19: XS2715285230 | F19: נקוב במט"ח | G19: חו"ל | H19: ישראל | I19: LSE | J19: A2 | K19: Moodys | L19: USD | M19: 5.37 | N19: 48010 | O19: 0.065 | P19: 0.05395 | Q19: 0 | R19: 100000 | S19: 3.718 | T19: 108.7112 | U19: 404.18824 | W19: שווי הוגן | X19: 6.6666667e-05 | Y19: 0.00099072182 | Z19: 9.8478235e-05
A20: 13908 | B20: 13909 | C20: STATE OF ISRAEL | D20: ISRAEL 5.75 54 | E20: US46514BRM18 | F20: נקוב במט"ח | G20: חו"ל | H20: ישראל | I20: NR | J20: A2 | K20: Moodys | L20: USD | M20: 13.788 | N20: 56586 | O20: 0.0575 | P20: 0.06361 | Q20: 0 | R20: 600000 | S20: 3.718 | T20: 92.2754 | U20: 2058.4796 | W20: שווי הוגן | X20: 0.0002 | Y20: 0.005045621 | Z20: 0.00050153721
A21: 13908 | B21: 13909 | C21: STATE OF ISRAEL | D21: ISRAEL 5.5 34 | E21: US46514BRL35 | F21: נקוב במט"ח | G21: חו"ל | H21: ישראל | I21: NR | J21: A2 | K21: Moodys | L21: USD | M21: 7.153 | N21: 49281 | O21: 0.055 | P21: 0.05617 | Q21: 0 | R21: 2229000 | S21: 3.718 | T21: 99.4856 | U21: 8244.7915 | W21: שווי הוגן | X21: 0.000743 | Y21: 0.020209135 | Z21: 0.002008798
A22: 13908 | B22: 13909 | C22: STATE OF ISRAEL | D22: ISRAEL 5.375 29 | E22: US46514BRN90 | F22: נקוב במט"ח | G22: חו"ל | H22: ישראל | I22: NR | J22: A2 | K22: Moodys | L22: USD | M22: 3.598 | N22: 47455 | O22: 0.05375 | P22: 0.05129 | Q22: 0 | R22: 633000 | S22: 3.718 | T22: 101.1626 | U22: 2380.8557 | W22: שווי הוגן | X22: 0.0003165 | Y22: 0.0058358099 | Z22: 0.00058008237
A23: 13908 | B23: 13909 | C23: STATE OF ISRAEL | D23: ISRAEL 5.625 2/35 | E23: US46514Y8B63 | F23: נקוב במט"ח | G23: חו"ל | H23: ישראל | I23: LSE | J23: Baa1 | K23: Moodys | L23: USD | M23: 7.655 | N23: 19/02/2035 | O23: 0.05625 | P23: 0.05703 | Q23: 0 | R23: 5863000 | S23: 3.718 | T23: 100.0819 | U23: 21816.487 | W23: שווי הוגן | X23: 0.0023452 | Y23: 0.053475257 | Z23: 0.0053154668
A24: 13908 | B24: 13910 | C24: מדינת ישראל | D24: ממשל שקלית 0142 | E24: IL0011254005 | F24: לא צמוד למדד המחירים לצרכן ריבית קבועה | G24: ישראל | H24: ישראל | I24: TASE | J24: NR | K24: NR | L24: ILS | M24: 11.556 | N24: 31/01/2042 | O24: 0.055 | P24: 0.0473 | Q24: 0 | R24: 300000 | S24: 1 | T24: 109.69 | U24: 329.07 | W24: שווי הוגן | X24: 1.1053939e-05 | Y24: 0.0013655706 | Z24: 0.00017501462
A25: 13908 | B25: 13910 | C25: מדינת ישראל | D25: ממשל צמודה 1025 | E25: IL0011359127 | F25: צמוד למדד המחירים לצרכן בריבית קבועה | G25: ישראל | H25: ישראל | I25: TASE | J25: NR | K25: NR | L25: ILS | M25: 0.584 | N25: 31/10/2025 | O25: 0.0075 | P25: 0.0124 | Q25: 0 | R25: 18111670 | S25: 1 | T25: 116.16 | U25: 21038.516 | W25: שווי הוגן | X25: 0.00083453426 | Y25: 0.08730537 | Z25: 0.011189254
A26: 13908 | B26: 13910 | C26: מדינת ישראל | D26: ממשל שקלית 0327 | E26: IL0011393449 | F26: לא צמוד למדד המחירים לצרכן ריבית קבועה | G26: ישראל | H26: ישראל | I26: TASE | J26: NR | K26: NR | L26: ILS | M26: 1.977 | N26: 31/03/2027 | O26: 0.02 | P26: 0.0422 | Q26: 0 | R26: 5256000 | S26: 1 | T26: 95.83 | U26: 5036.8248 | W26: שווי הוגן | X26: 0.0001861955 | Y26: 0.020901753 | Z26: 0.0026788159
A27: 13908 | B27: 13910 | C27: מדינת ישראל | D27: ממשל שקלית 0347 | E27: IL0011401937 | F27: לא צמוד למדד המחירים לצרכן ריבית קבועה | G27: ישראל | H27: ישראל | I27: TASE | J27: NR | K27: NR | L27: ILS | M27: 14.743 | N27: 31/03/2047 | O27: 0.0375 | P27: 0.0486 | Q27: 0 | R27: 3380897 | S27: 1 | T27: 85.21 | U27: 2880.8623 | W27: שווי הוגן | X27: 0.00012881401 | Y27: 0.011954966 | Z27: 0.0015321756
A28: 13908 | B28: 13910 | C28: מדינת ישראל | D28: ממשל צמודה 0527 | E28: IL0011408478 | F28: צמוד למדד המחירים לצרכן בריבית קבועה | G28: ישראל | H28: ישראל | I28: TASE | J28: NR | K28: NR | L28: ILS | M28: 2.142 | N28: 31/05/2027 | O28: 0.0075 | P28: 0.0194 | Q28: 0 | R28: 20461660 | S28: 1 | T28: 114.63 | U28: 23455.201 | W28: שווי הוגן | X28: 0.00084009175 | Y28: 0.097334099 | Z28: 0.012474558
A29: 13908 | B29: 13910 | C29: מדינת ישראל | D29: ממשל שקלית 0928 | E29: IL0011508798 | F29: לא צמוד למדד המחירים לצרכן ריבית קבועה | G29: ישראל | H29: ישראל | I29: TASE | J29: NR | K29: NR | L29: ILS | M29: 3.36 | N29: 28/09/2028 | O29: 0.0225 | P29: 0.0426 | Q29: 0 | R29: 15536870 | S29: 1 | T29: 94.71 | U29: 14714.97 | W29: שווי הוגן | X29: 0.0004474709 | Y29: 0.061063997 | Z29: 0.0078261
A30: 13908 | B30: 13910 | C30: מדינת ישראל | D30: ממשל צמודה 0529 | E30: IL0011570236 | F30: צמוד למדד המחירים לצרכן בריבית קבועה | G30: ישראל | H30: ישראל | I30: TASE | J30: NR | K30: NR | L30: ILS | M30: 4.115 | N30: 31/05/2029 | O30: 0.005 | P30: 0.0197 | Q30: 0 | R30: 4869210 | S30: 1 | T30: 109.42 | U30: 5327.8896 | W30: שווי הוגן | X30: 0.00017714033 | Y30: 0.02210961 | Z30: 0.0028336176
A31: 13908 | B31: 13910 | C31: מדינת ישראל | D31: ממשל שקלית 0330 | E31: IL0011609851 | F31: לא צמוד למדד המחירים לצרכן ריבית קבועה | G31: ישראל | H31: ישראל | I31: TASE | J31: NR | K31: NR | L31: ILS | M31: 4.892 | N31: 31/03/2030 | O31: 0.01 | P31: 0.0429 | Q31: 0 | R31: 665765 | S31: 1 | T31: 85.48 | U31: 569.09592 | W31: שווי הוגן | X31: 1.7633613e-05 | Y31: 0.0023616271 | Z31: 0.00030267148
A32: 13908 | B32: 13910 | C32: מדינת ישראל | D32: ממשל שקלית 0537 | E32: IL0011661803 | F32: לא צמוד למדד המחירים לצרכן ריבית קבועה | G32: ישראל | H32: ישראל | I32: TASE | J32: NR | K32: NR | L32: ILS | M32: 10.807 | N32: 31/05/2037 | O32: 0.015 | P32: 0.0461 | Q32: 0 | R32: 9800000 | S32: 1 | T32: 72.72 | U32: 7126.56 | W32: שווי הוגן | X32: 0.00030000744 | Y32: 0.02957371 | Z32: 0.0037902336
A33: 13908 | B33: 13910 | C33: מדינת ישראל | D33: ממשל צמודה 0726 | E33: IL0011695645 | F33: צמוד למדד המחירים לצרכן בריבית קבועה | G33: ישראל | H33: ישראל | I33: TASE | J33: NR | K33: NR | L33: ILS | M33: 1.33 | N33: 31/07/2026 | O33: 0.001 | P33: 0.0196 | Q33: 0 | R33: 24047400 | S33: 1 | T33: 112.95 | U33: 27161.538 | W33: שווי הוגן | X33: 0.0011901964 | Y33: 0.11271461 | Z33: 0.01444576
A34: 13908 | B34: 13910 | C34: מדינת ישראל | D34: ממשל צמודה 1131 | E34: IL0011722209 | F34: צמוד למדד המחירים לצרכן בריבית קבועה | G34: ישראל | H34: ישראל | I34: TASE | J34: NR | K34: NR | L34: ILS | M34: 6.646 | N34: 30/11/2031 | O34: 0.001 | P34: 0.0203 | Q34: 0 | R34: 16340000 | S34: 1 | T34: 101.91 | U34: 16652.094 | W34: שווי הוגן | X34: 0.00053217686 | Y34: 0.069102651 | Z34: 0.0088563522
... A41: 13908 | B41: 13910 | C41: מדינת ישראל | D41: ממשל צמודה 1033 | E41: IL0012043795 | F41: צמוד למדד המחירים לצרכן בריבית קבועה | G41: ישראל | H41: ישראל | I41: TASE | J41: NR | K41: NR | L41: ILS | M41: 8.028 | N41: 31/10/2033 | O41: 0.016 | P41: 0.021 | Q41: 0 | R41: 13535000 | S41: 1 | T41: 100.49 | U41: 13601.322 | W41: שווי הוגן | X41: 0.00067110347 | Y41: 0.056442594 | Z41: 0.0072338106
A42: 13908 | B42: 13910 | C42: STATE OF ISRAEL | D42: ISRAEL 6.5 31 | E42: XS2715285230 | F42: נקוב במט"ח | G42: חו"ל | H42: ישראל | I42: LSE | J42: A2 | K42: Moodys | L42: USD | M42: 5.37 | N42: 48010 | O42: 0.065 | P42: 0.05395 | Q42: 0 | R42: 180000 | S42: 3.718 | T42: 108.7112 | U42: 727.53883 | W42: שווי הוגן | X42: 0.00012 | Y42: 0.0030191315 | Z42: 0.00038693873
A43: 13908 | B43: 13910 | C43: STATE OF ISRAEL | D43: ISRAEL 5.75 54 | E43: US46514BRM18 | F43: נקוב במט"ח | G43: חו"ל | H43: ישראל | I43: NR | J43: A2 | K43: Moodys | L43: USD | M43: 13.788 | N43: 56586 | O43: 0.0575 | P43: 0.06361 | Q43: 0 | R43: 400000 | S43: 3.718 | T43: 92.2754 | U43: 1372.3198 | W43: שווי הוגן | X43: 0.00013333333 | Y43: 0.0056948353 | Z43: 0.00072986299
A44: 13908 | B44: 13910 | C44: STATE OF ISRAEL | D44: ISRAEL 5.5 34 | E44: US46514BRL35 | F44: נקוב במט"ח | G44: חו"ל | H44: ישראל | I44: NR | J44: A2 | K44: Moodys | L44: USD | M44: 7.153 | N44: 49281 | O44: 0.055 | P44: 0.05617 | Q44: 0 | R44: 900000 | S44: 3.718 | T44: 99.4856 | U44: 3328.9871 | W44: שווי הוגן | X44: 0.0003 | Y44: 0.013814589 | Z44: 0.001770509
A45: 13908 | B45: 13910 | C45: STATE OF ISRAEL | D45: ISRAEL 5.375 29 | E45: US46514BRN90 | F45: נקוב במט"ח | G45: חו"ל | H45: ישראל | I45: NR | J45: A2 | K45: Moodys | L45: USD | M45: 3.598 | N45: 47455 | O45: 0.05375 | P45: 0.05129 | Q45: 0 | R45: 313000 | S45: 3.718 | T45: 101.1626 | U45: 1177.2636 | W45: שווי הוגן | X45: 0.0001565 | Y45: 0.0048853936 | Z45: 0.00062612311
A46: 13908 | B46: 13910 | C46: STATE OF ISRAEL | D46: ISRAEL 5.625 2/35 | E46: US46514Y8B63 | F46: נקוב במט"ח | G46: חו"ל | H46: ישראל | I46: LSE | J46: Baa1 | K46: Moodys | L46: USD | M46: 7.655 | N46: 19/02/2035 | O46: 0.05625 | P46: 0.05703 | Q46: 0 | R46: 3688000 | S46: 3.718 | T46: 100.0819 | U46: 13723.214 | W46: שווי הוגן | X46: 0.0014752 | Y46: 0.056948422 | Z46: 0.0072986387
A47: 13908 | B47: 13911 | C47: מדינת ישראל | D47: ממשל שקלית 0142 | E47: IL0011254005 | F47: לא צמוד למדד המחירים לצרכן ריבית קבועה | G47: ישראל | H47: ישראל | I47: TASE | J47: NR | K47: NR | L47: ILS | M47: 11.556 | N47: 31/01/2042 | O47: 0.055 | P47: 0.0473 | Q47: 0 | R47: 1750000 | S47: 1 | T47: 109.69 | U47: 1919.575 | W47: שווי הוגן | X47: 6.448131e-05 | Y47: 0.014860825 | Z47: 0.0032111644
A48: 13908 | B48: 13911 | C48: מדינת ישראל | D48: ממשל צמודה 1025 | E48: IL0011359127 | F48: צמוד למדד המחירים לצרכן בריבית קבועה | G48: ישראל | H48: ישראל | I48: TASE | J48: NR | K48: NR | L48: ILS | M48: 0.584 | N48: 31/10/2025 | O48: 0.0075 | P48: 0.0124 | Q48: 0 | R48: 7654972 | S48: 1 | T48: 116.16 | U48: 8892.0155 | W48: שווי הוגן | X48: 0.00035271935 | Y48: 0.068839552 | Z48: 0.014875024
A49: 13908 | B49: 13911 | C49: מדינת ישראל | D49: ממשל שקלית 0327 | E49: IL0011393449 | F49: לא צמוד למדד המחירים לצרכן ריבית קבועה | G49: ישראל | H49: ישראל | I49: TASE | J49: NR | K49: NR | L49: ILS | M49: 1.977 | N49: 31/03/2027 | O49: 0.02 | P49: 0.0422 | Q49: 0 | R49: 3048450 | S49: 1 | T49: 95.83 | U49: 2921.3296 | W49: שווי הוגן | X49: 0.00010799233 | Y49: 0.022616135 | Z49: 0.0048869513
A50: 13908 | B50: 13911 | C50: מדינת ישראל | D50: ממשל שקלית 0347 | E50: IL0011401937 | F50: לא צמוד למדד המחירים לצרכן ריבית קבועה | G50: ישראל | H50: ישראל | I50: TASE | J50: NR | K50: NR | L50: ILS | M50: 14.743 | N50: 31/03/2047 | O50: 0.0375 | P50: 0.0486 | Q50: 0 | R50: 1000000 | S50: 1 | T50: 85.21 | U50: 852.1 | W50: שווי הוגן | X50: 3.8100544e-05 | Y50: 0.0065967251 | Z50: 0.001425437
...

Sheet ניירות ערך מסחריים
A1: מספר קופה/קרן/ח.פ. עבור חברת ביטוח | B1: מספר מסלול | C1: שם מנפיק | D1: מספר מנפיק | E1: סוג מספר מזהה מנפיק | F1: שם נייר ערך | G1: מספר נייר ערך | H1: סוג מספר נייר ערך | I1: מאפיין עיקרי | J1: ישראל/חו"ל | K1: מדינה לפי חשיפה כלכלית | L1: זירת מסחר | M1: ענף מסחר | N1: בעל עניין/צד קשור | O1: דירוג | P1: שם מדרג | Q1: דירוג נייר הערך/המנפיק | R1: מטבע פעילות | S1: מח"מ | T1: ריבית עוגן | U1: מועד פדיון | V1: שיעור ריבית | W1: תשואה לפדיון | X1: נחיתות חוזית | Y1: האם סווג כחוב בעייתי | Z1: ערך נקוב (יחידות) | AA1: שער חליפין | AB1: שער נייר הערך | AC1: סכום לקבל (במטבע הפעילות) | AD1: שווי הוגן (באלפי ש"ח) | AE1: עלות מופחתת (באלפי ש"ח) | AF1: עלות מופחתת (במטבע הפעילות) | AG1: השיטה שיושמה בדוח הכספי | AH1: שיעור מערך נקוב מונפק | AI1: שיעור מנכסי אפיק ההשקעה | AJ1: שיעור מסך נכסי ההשקעה
A2: 13908 | B2: 13912 | C2: קבוצת עזריאלי בע"מ | D2: 510960719 | E2: ח.פ. | F2: עזריאלי מסחרי 1 | G2: IL0012086281 | H2: ISIN | I2: לא צמוד למדד המחירים לצרכן ריבית קבועה | J2: ישראל | K2: ישראל | L2: TASE | M2: נדל"ן מניב בישראל | N2: לא | O2: Aa1.il | P2: מידרוג Moodys | Q2: נייר ערך | R2: ILS | S2: 0.268 | T2: ללא | U2: 45876 | V2: 0.0462 | W2: 0.0468 | X2: החוב לא נחות | Z2: 164800 | AA2: 1 | AB2: 1033.3 | AC2: 0 | AD2: 1702.8784 | AG2: שווי הוגן | AH2: 0.0025830033 | AI2: 0.33318286 | AJ2: 0.00070112803
A3: 13908 | B3: 13912 | C3: חברת גב ים לקרקעות בע"מ | D3: 520001736 | E3: ח.פ. | F3: גב ים מסחרי 2 | G3: IL0012086448 | H3: ISIN | I3: לא צמוד למדד המחירים לצרכן ריבית קבועה | J3: ישראל | K3: ישראל | L3: TASE | M3: נדל"ן מניב בישראל | N3: לא | O3: ilA-1+ | P3: S&P מעלות | Q3: נייר ערך | R3: ILS | S3: 0.268 | T3: ללא | U3: 45876 | V3: 0.0466 | W3: 0.0494 | X3: החוב לא נחות | Z3: 164800 | AA3: 1 | AB3: 1033 | AC3: 0 | AD3: 1702.384 | AG3: שווי הוגן | AH3: 0.0054933333 | AI3: 0.33308613 | AJ3: 0.00070092447
A4: 13908 | B4: 13912 | C4: אפי נכסים בע"מ | D4: 510560188 | E4: ח.פ. | F4: אפי נכס מסחרי 4 | G4: IL0012086513 | H4: ISIN | I4: לא צמוד למדד המחירים לצרכן ריבית קבועה | J4: ישראל | K4: ישראל | L4: TASE | M4: נדל"ן מניב בחו"ל | N4: לא | O4: ilA-1 | P4: S&P מעלות | Q4: נייר ערך | R4: ILS | S4: 0.266 | T4: ללא | U4: 45845 | V4: 0.0495 | W4: 0.0527 | X4: החוב לא נחות | Z4: 164800 | AA4: 1 | AB4: 1035 | AC4: 0 | AD4: 1705.68 | AG4: שווי הוגן | AH4: 0.010069903 | AI4: 0.33373102 | AJ4: 0.00070228153
A5: 13918 | B5: 13922 | C5: קבוצת עזריאלי בע"מ | D5: 510960719 | E5: ח.פ. | F5: עזריאלי מסחרי 1 | G5: IL0012086281 | H5: ISIN | I5: לא צמוד למדד המחירים לצרכן ריבית קבועה | J5: ישראל | K5: ישראל | L5: TASE | M5: נדל"ן מניב בישראל | N5: לא | O5: Aa1.il | P5: מידרוג Moodys | Q5: נייר ערך | R5: ILS | S5: 0.268 | T5: ללא | U5: 45876 | V5: 0.0462 | W5: 0.0468 | X5: החוב לא נחות | Z5: 30000 | AA5: 1 | AB5: 1033.3 | AC5: 0 | AD5: 309.99 | AG5: שווי הוגן | AH5: 0.00047020691 | AI5: 0.33318286 | AJ5: 0.0027296241
A6: 13918 | B6: 13922 | C6: חברת גב ים לקרקעות בע"מ | D6: 520001736 | E6: ח.פ. | F6: גב ים מסחרי 2 | G6: IL0012086448 | H6: ISIN | I6: לא צמוד למדד המחירים לצרכן ריבית קבועה | J6: ישראל | K6: ישראל | L6: TASE | M6: נדל"ן מניב בישראל | N6: לא | O6: ilA-1+ | P6: S&P מעלות | Q6: נייר ערך | R6: ILS | S6: 0.268 | T6: ללא | U6: 45876 | V6: 0.0466 | W6: 0.0494 | X6: החוב לא נחות | Z6: 30000 | AA6: 1 | AB6: 1033 | AC6: 0 | AD6: 309.9 | AG6: שווי הוגן | AH6: 0.001 | AI6: 0.33308613 | AJ6: 0.0027288316
A7: 13918 | B7: 13922 | C7: אפי נכסים בע"מ | D7: 510560188 | E7: ח.פ. | F7: אפי נכס מסחרי 4 | G7: IL0012086513 | H7: ISIN | I7: לא צמוד למדד המחירים לצרכן ריבית קבועה | J7: ישראל | K7: ישראל | L7: TASE | M7: נדל"ן מניב בחו"ל | N7: לא | O7: ilA-1 | P7: S&P מעלות | Q7: נייר ערך | R7: ILS | S7: 0.266 | T7: ללא | U7: 45845 | V7: 0.0495 | W7: 0.0527 | X7: החוב לא נחות | Z7: 30000 | AA7: 1 | AB7: 1035 | AC7: 0 | AD7: 310.5 | AG7: שווי הוגן | AH7: 0.0018331134 | AI7: 0.33373102 | AJ7: 0.002734115
A8: 13918 | B8: 13926 | C8: קבוצת עזריאלי בע"מ | D8: 510960719 | E8: ח.פ. | F8: עזריאלי מסחרי 1 | G8: IL0012086281 | H8: ISIN | I8: לא צמוד למדד המחירים לצרכן ריבית קבועה | J8: ישראל | K8: ישראל | L8: TASE | M8: נדל"ן מניב בישראל | N8: לא | O8: Aa1.il | P8: מידרוג Moodys | Q8: נייר ערך | R8: ILS | S8: 0.268 | T8: ללא | U8: 45876 | V8: 0.0462 | W8: 0.0468 | X8: החוב לא נחות | Z8: 200 | AA8: 1 | AB8: 1033.3 | AC8: 0 | AD8: 2.0666 | AG8: שווי הוגן | AH8: 3.1347127e-06 | AI8: 0.33318286 | AJ8: 0.0019892988
A9: 13918 | B9: 13926 | C9: חברת גב ים לקרקעות בע"מ | D9: 520001736 | E9: ח.פ. | F9: גב ים מסחרי 2 | G9: IL0012086448 | H9: ISIN | I9: לא צמוד למדד המחירים לצרכן ריבית קבועה | J9: ישראל | K9: ישראל | L9: TASE | M9: נדל"ן מניב בישראל | N9: לא | O9: ilA-1+ | P9: S&P מעלות | Q9: נייר ערך | R9: ILS | S9: 0.268 | T9: ללא | U9: 45876 | V9: 0.0466 | W9: 0.0494 | X9: החוב לא נחות | Z9: 200 | AA9: 1 | AB9: 1033 | AC9: 0 | AD9: 2.066 | AG9: שווי הוגן | AH9: 6.6666667e-06 | AI9: 0.33308613 | AJ9: 0.0019887212
A10: 13918 | B10: 13926 | C10: אפי נכסים בע"מ | D10: 510560188 | E10: ח.פ. | F10: אפי נכס מסחרי 4 | G10: IL0012086513 | H10: ISIN | I10: לא צמוד למדד המחירים לצרכן ריבית קבועה | J10: ישראל | K10: ישראל | L10: TASE | M10: נדל"ן מניב בחו"ל | N10: לא | O10: ilA-1 | P10: S&P מעלות | Q10: נייר ערך | R10: ILS | S10: 0.266 | T10: ללא | U10: 45845 | V10: 0.0495 | W10: 0.0527 | X10: החוב לא נחות | Z10: 200 | AA10: 1 | AB10: 1035 | AC10: 0 | AD10: 2.07 | AG10: שווי הוגן | AH10: 1.2220756e-05 | AI10: 0.33373102 | AJ10: 0.0019925716

Sheet איגרות חוב
A1: מספר קופה/קרן/ח.פ. עבור חברת ביטוח | B1: מספר מסלול | C1: שם מנפיק | D1: מספר מנפיק | E1: סוג מספר מזהה מנפיק | F1: שם נייר ערך | G1: מספר נייר ערך | H1: סוג מספר נייר ערך | I1: מאפיין עיקרי | J1: ישראל/חו"ל | K1: מדינה לפי חשיפה כלכלית | L1: סטאטוס סחירות | M1: זירת מסחר | N1: ענף מסחר | O1: בעל עניין/צד קשור | P1: דירוג | Q1: שם מדרג | R1: דירוג נייר הערך/המנפיק | S1: מטבע פעילות | T1: מח"מ | U1: מועד פדיון | V1: שיעור ריבית | W1: תשואה לפדיון | X1: נחיתות חוזית | Y1: האם סווג כחוב בעייתי | Z1: ערך נקוב (יחידות) | AA1: שער חליפין | AB1: שער נייר הערך | AC1: סכום לקבל (במטבע הפעילות) | AD1: שווי הוגן (באלפי ש"ח) | AE1: עלות מופחתת (באלפי ש"ח) | AF1: עלות מופחתת (במטבע הפעילות) | AG1: השיטה שיושמה בדוח הכספי | AH1: שיעור מערך נקוב מונפק | AI1: שיעור מנכסי אפיק ההשקעה | AJ1: שיעור מסך נכסי ההשקעה
A2: 13908 | B2: 13909 | C2: אדמה פתרונות לחקלאות בע"מ | D2: 520043605 | E2: ח.פ. | F2: אדמה אגח ב | G2: IL0011109159 | H2: ISIN | I2: צמוד למדד המחירים לצרכן | J2: ישראל | K2: ישראל | L2: סחיר | M2: TASE | N2: כימיה, גומי ופלסטיק | O2: לא | P2: ilAA- | Q2: S&P מעלות | R2: נייר ערך | S2: ILS | T2: 5.128 | U2: 30/11/2036 | V2: 0.0515 | W2: 0.0452 | X2: החוב לא נחות | Z2: 1491473.2 | AA2: 1 | AB2: 146.6 | AC2: 0 | AD2: 2186.4997 | AG2: שווי הוגן | AH2: 0.00058227654 | AI2: 0.0042161231 | AJ2: 0.00053291107
A3: 13908 | B3: 13909 | C3: שיכון ובינוי בע"מ | D3: 520036104 | E3: ח.פ. | F3: שכון ובי אגח 6 | G3: IL0011297335 | H3: ISIN | I3: צמוד למדד המחירים לצרכן | J3: ישראל | K3: ישראל | L3: סחיר | M3: TASE | N3: בנייה | O3: לא | P3: ilA | Q3: S&P מעלות | R3: נייר ערך | S3: ILS | T3: 0 | U3: 45748 | V3: 0.0434 | W3: 0 | X3: החוב לא נחות | Z3: 779945.16 | AA3: 1 | AB3: 117.97 | AC3: 0.65938 | AD3: 920.76069 | AG3: שווי הוגן | AH3: 0.0017930608 | AI3: 0.0017754589 | AJ3: 0.0002244151
A4: 13908 | B4: 13909 | C4: שיכון ובינוי בע"מ | D4: 520036104 | E4: ח.פ. | F4: שכון ובי אגח 7 | G4: IL0011297418 | H4: ISIN | I4: לא צמוד למדד המחירים לצרכן | J4: ישראל | K4: ישראל | L4: סחיר | M4: TASE | N4: בנייה | O4: לא | P4: ilA | Q4: S&P מעלות | R4: נייר ערך | S4: ILS | T4: 0 | U4: 45748 | V4: 0.0623 | W4: 0 | X4: החוב לא נחות | Z4: 50000 | AA4: 1 | AB4: 103 | AC4: 0.0575 | AD4: 51.5575 | AG4: שווי הוגן | AH4: 0.00031442409 | AI4: 9.9415868e-05 | AJ4: 1.2566003e-05
A5: 13908 | B5: 13909 | C5: אמות השקעות בע"מ | D5: 520026683 | E5: ח.פ. | F5: אמות אגח ד | G5: IL0011331498 | H5: ISIN | I5: צמוד למדד המחירים לצרכן | J5: ישראל | K5: ישראל | L5: סחיר | M5: TASE | N5: נדל"ן מניב בישראל | O5: לא | P5: ilAA | Q5: S&P מעלות | R5: נייר ערך | S5: ILS | T5: 1.682 | U5: 46790 | V5: 0.032 | W5: 0.0275 | X5: החוב לא נחות | Z5: 180800 | AA5: 1 | AB5: 118.93 | AC5: 0 | AD5: 215.02544 | AG5: שווי הוגן | AH5: 0.00032745662 | AI5: 0.0004146233 | AJ5: 5.2407707e-05
A6: 13908 | B6: 13909 | C6: איירפורט סיטי בע"מ | D6: 511659401 | E6: ח.פ. | F6: ארפורט אגח ה | G6: IL0011334872 | H6: ISIN | I6: צמוד למדד המחירים לצרכן | J6: ישראל | K6: ישראל | L6: סחיר | M6: TASE | N6: נדל"ן מניב בישראל | O6: לא | P6: ilAA | Q6: S&P מעלות | R6: נייר ערך | S6: ILS | T6: 2.267 | U6: 28/02/2029 | V6: 0.0234 | W6: 0.028 | X6: החוב לא נחות | Z6: 2764493.6 | AA6: 1 | AB6: 114.39 | AC6: 0 | AD6: 3162.3042 | AG6: שווי הוגן | AH6: 0.0016958915 | AI6: 0.0060977204 | AJ6: 0.00077074188
A7: 13908 | B7: 13909 | C7: קבוצת עזריאלי בע"מ | D7: 510960719 | E7: ח.פ. | F7: עזריאלי אגח ב | G7: IL0011344368 | H7: ISIN | I7: צמוד למדד המחירים לצרכן | J7: ישראל | K7: ישראל | L7: סחיר | M7: TASE | N7: נדל"ן מניב בישראל | O7: לא | P7: ilAA+ | Q7: S&P מעלות | R7: נייר ערך | S7: ILS | T7: 0 | U7: 45748 | V7: 0.0065 | W7: 0 | X7: החוב לא נחות | Z7: 2120924 | AA7: 1 | AB7: 115.85 | AC7: 1.54187 | AD7: 2458.6323 | AG7: שווי הוגן | AH7: 0.0038852685 | AI7: 0.0047408634 | AJ7: 0.00059923738
A8: 13908 | B8: 13909 | C8: שיכון ובינוי בע"מ | D8: 520036104 | E8: ח.פ. | F8: שכון ובי אגח 8 | G8: IL0011358889 | H8: ISIN | I8: צמוד למדד המחירים לצרכן | J8: ישראל | K8: ישראל | L8: סחיר | M8: TASE | N8: בנייה | O8: לא | P8: ilA | Q8: S&P מעלות | R8: נייר ערך | S8: ILS | T8: 2.348 | U8: 47123 | V8: 0.039 | W8: 0.0384 | X8: החוב לא נחות | Z8: 851325.76 | AA8: 1 | AB8: 118.27 | AC8: 0 | AD8: 1006.863 | AG8: שווי הוגן | AH8: 0.00059686902 | AI8: 0.0019414859 | AJ8: 0.00024540064
A9: 13908 | B9: 13909 | C9: קרסו מוטורס בע"מ | D9: 514065283 | E9: ח.פ. | F9: קרסו מוט' אגח א | G9: IL0011364648 | H9: ISIN | I9: לא צמוד למדד המחירים לצרכן | J9: ישראל | K9: ישראל | L9: סחיר | M9: TASE | N9: מסחר | O9: לא | P9: ilAA- | Q9: S&P מעלות | R9: נייר ערך | S9: ILS | T9: 0.909 | U9: 46031 | V9: 0.0275 | W9: 0.0519 | X9: החוב לא נחות | Z9: 1004385.9 | AA9: 1 | AB9: 98.12 | AC9: 0 | AD9: 985.50346 | AG9: שווי הוגן | AH9: 0.0074077448 | AI9: 0.0019002993 | AJ9: 0.00024019473
A10: 13908 | B10: 13909 | C10: ריט 1 בע"מ | D10: 513821488 | E10: ח.פ. | F10: ריט 1 אגח ה | G10: IL0011367534 | H10: ISIN | I10: צמוד למדד המחירים לצרכן | J10: ישראל | K10: ישראל | L10: סחיר | M10: TASE | N10: נדל"ן מניב בישראל | O10: לא | P10: ilAA | Q10: S&P מעלות | R10: נייר ערך | S10: ILS | T10: 1.906 | U10: 20/09/2028 | V10: 0.04 | W10: 0.0281 | X10: החוב לא נחות | Z10: 1639791.7 | AA10: 1 | AB10: 119.04 | AC10: 0 | AD10: 1952.008 | AG10: שווי הוגן | AH10: 0.0019469552 | AI10: 0.0037639639 | AJ10: 0.00047575888
A11: 13908 | B11: 13909 | C11: אמות השקעות בע"מ | D11: 520026683 | E11: ח.פ. | F11: אמות אגח ה | G11: IL0011381147 | H11: ISIN | I11: לא צמוד למדד המחירים לצרכן | J11: ישראל | K11: ישראל | L11: סחיר | M11: TASE | N11: נדל"ן מניב בישראל | O11: לא | P11: ilAA | Q11: S&P מעלות | R11: נייר ערך | S11: ILS | T11: 0.762 | U11: 46113 | V11: 0.0339 | W11: 0.0446 | X11: החוב לא נחות | Z11: 2500 | AA11: 1 | AB11: 100.01 | AC11: 0 | AD11: 2.50025 | AG11: שווי הוגן | AH11: 1.5301799e-05 | AI11: 4.8211128e-06 | AJ11: 6.0938077e-07
A12: 13908 | B12: 13909 | C12: ריט 1 בע"מ | D12: 513821488 | E12: ח.פ. | F12: ריט 1 אגח ו | G12: IL0011385445 | H12: ISIN | I12: צמוד למדד המחירים לצרכן | J12: ישראל | K12: ישראל | L12: סחיר | M12: TASE | N12: נדל"ן מניב בישראל | O12: לא | P12: ilAA | Q12: S&P מעלות | R12: נייר ערך | S12: ILS | T12: 3.261 | U12: 21/09/2031 | V12: 0.035 | W12: 0.0294 | X12: החוב לא נחות | Z12: 492735.01 | AA12: 1 | AB12: 119.75 | AC12: 0 | AD12: 590.05017 | AG12: שווי הוגן | AH12: 0.00061622559 | AI12: 0.0011377656 | AJ12: 0.00014381171
A13: 13908 | B13: 13909 | C13: קבוצת עזריאלי בע"מ | D13: 510960719 | E13: ח.פ. | F13: עזריאלי אגח ד | G13: IL0011386500 | H13: ISIN | I13: צמוד למדד המחירים לצרכן | J13: ישראל | K13: ישראל | L13: סחיר | M13: TASE | N13: נדל"ן מניב בישראל | O13: לא | P13: Aa1.il | Q13: מידרוג Moodys | R13: נייר ערך | S13: ILS | T13: 2.662 | U13: 47610 | V13: 0.0134 | W13: 0.0281 | X13: החוב לא נחות | Z13: 7492038.8 | AA13: 1 | AB13: 113.01 | AC13: 0 | AD13: 8466.753 | AG13: שווי הוגן | AH13: 0.0030834279 | AI13: 0.016326036 | AJ13: 0.0020635842
A14: 13908 | B14: 13909 | C14: ביג מרכזי קניות בע"מ | D14: 513623314 | E14: ח.פ. | F14: ביג אגח ח | G14: IL0011389249 | H14: ISIN | I14: צמוד למדד המחירים לצרכן | J14: ישראל | K14: ישראל | L14: סחיר | M14: TASE | N14: נדל"ן מניב בישראל | O14: לא | P14: ilAA | Q14: S&P מעלות | R14: נייר ערך | S14: ILS | T14: 0.937 | U14: 46360 | V14: 0.0134 | W14: 0.0281 | X14: החוב לא נחות | Z14: 314571.42 | AA14: 1 | AB14: 115.87 | AC14: 0 | AD14: 364.4939 | AG14: שווי הוגן | AH14: 0.00063915349 | AI14: 0.0007028362 | AJ14: 8.8837346e-05
A15: 13908 | B15: 13909 | C15: סלע קפיטל נדל"ן בע"מ | D15: 513992529 | E15: ח.פ. | F15: סלע נדלן אגח ג | G15: IL0011389736 | H15: ISIN | I15: צמוד למדד המחירים לצרכן | J15: ישראל | K15: ישראל | L15: סחיר | M15: TASE | N15: נדל"ן מניב בישראל | O15: לא | P15: Aa3.il | Q15: מידרוג Moodys | R15: נייר ערך | S15: ILS | T15: 2.439 | U15: 13/04/2029 | V15: 0.0196 | W15: 0.0288 | X15: החוב לא נחות | Z15: 144000 | AA15: 1 | AB15: 114.79 | AC15: 0 | AD15: 165.2976 | AG15: שווי הוגן | AH15: 0.00012575403 | AI15: 0.00031873548 | AJ15: 4.0287643e-05
A16: 13908 | B16: 13909 | C16: הפניקס גיוסי הון (2009)בע"מ | D16: 514290345 | E16: ח.פ. | F16: פניקס הון אגח ח | G16: IL0011398158 | H16: ISIN | I16: לא צמוד למדד המחירים לצרכן | J16: ישראל | K16: ישראל | L16: סחיר | M16: TASE | N16: ביטוח | O16: לא | P16: ilAA | Q16: S&P מעלות | R16: נייר ערך | S16: ILS | T16: 0.332 | U16: 31/07/2028 | V16: 0.0361 | W16: 0.0507 | X16: החוב לא נחות | Z16: 1000000 | AA16: 1 | AB16: 100.15 | AC16: 0 | AD16: 1001.5 | AG16: שווי הוגן | AH16: 0.0013029316 | AI16: 0.0019311447 | AJ16: 0.00024409353
A17: 13908 | B17: 13909 | C17: קבוצת אשטרום בע"מ | D17: 510381601 | E17: ח.פ. | F17: אשטרום קב אגח ג | G17: IL0011401028 | H17: ISIN | I17: לא צמוד למדד המחירים לצרכן | J17: ישראל | K17: ישראל | L17: סחיר | M17: TASE | N17: בנייה | O17: לא | P17: ilA | Q17: S&P מעלות | R17: נייר ערך | S17: ILS | T17: 1.919 | U17: 15/01/2029 | V17: 0.043 | W17: 0.0552 | X17: החוב לא נחות | Z17: 1232720 | AA17: 1 | AB17: 98.75 | AC17: 0 | AD17: 1217.311 | AG17: שווי הוגן | AH17: 0.001526832 | AI17: 0.0023472828 | AJ17: 0.0002966927
A18: 13908 | B18: 13909 | C18: רבוע כחול נדל"ן בע"מ | D18: 513765859 | E18: ח.פ. | F18: רבוע נדלן אגח ו | G18: IL0011406076 | H18: ISIN | I18: צמוד למדד המחירים לצרכן | J18: ישראל | K18: ישראל | L18: סחיר | M18: TASE | N18: נדל"ן מניב בישראל | O18: לא | P18: ilAA- | Q18: S&P מעלות | R18: נייר ערך | S18: ILS | T18: 1.146 | U18: 30/11/2026 | V18: 0.0215 | W18: 0.0282 | X18: החוב לא נחות | Z18: 571428.57 | AA18: 1 | AB18: 117.16 | AC18: 0 | AD18: 669.48571 | AG18: שווי הוגן | AH18: 0.00040789289 | AI18: 0.0012909374 | AJ18: 0.00016317237
A19: 13908 | B19: 13909 | C19: תמר פטרוליום בע"מ | D19: 515334662 | E19: ח.פ. | F19: תמר פטרו אגח א | G19: IL0011413320 | H19: ISIN | I19: צמוד למט"ח | J19: ישראל | K19: ישראל | L19: סחיר | M19: TASE | N19: חיפושי נפט וגז | O19: לא | P19: A1.il | Q19: מידרוג Moodys | R19: נייר ערך | S19: ILS | T19: 2.673 | U19: 30/08/2028 | V19: 0.0469 | W19: 0.0664 | X19: החוב לא נחות | Z19: 4117405.9 | AA19: 1 | AB19: 101 | AC19: 0 | AD19: 4158.58 | AG19: שווי הוגן | AH19: 0.0031805405 | AI19: 0.0080187914 | AJ19: 0.0010135621
A20: 13908 | B20: 13909 | C20: קרסו מוטורס בע"מ | D20: 514065283 | E20: ח.פ. | F20: קרסו מוט' אגח ג | G20: IL0011418295 | H20: ISIN | I20: לא צמוד למדד המחירים לצרכן | J20: ישראל | K20: ישראל | L20: סחיר | M20: TASE | N20: מסחר | O20: לא | P20: ilAA- | Q20: S&P מעלות | R20: נייר ערך | S20: ILS | T20: 1.518 | U20: 46396 | V20: 0.023 | W20: 0.0516 | X20: החוב לא נחות | Z20: 1392201 | AA20: 1 | AB20: 96.07 | AC20: 0 | AD20: 1337.4875 | AG20: שווי הוגן | AH20: 0.0012866991 | AI20: 0.0025790133 | AJ20: 0.00032598307
A21: 13908 | B21: 13909 | C21: תמר פטרוליום בע"מ | D21: 515334662 | E21: ח.פ. | F21: תמר פטרו אגח ב | G21: IL0011435935 | H21: ISIN | I21: צמוד למט"ח | J21: ישראל | K21: ישראל | L21: סחיר | M21: TASE | N21: חיפושי נפט וגז | O21: לא | P21: A1.il | Q21: מידרוג Moodys | R21: נייר ערך | S21: ILS | T21: 2.832 | U21: 30/08/2028 | V21: 0.0469 | W21: 0.0656 | X21: החוב לא נחות | Z21: 1524701.6 | AA21: 1 | AB21: 102.77 | AC21: 0 | AD21: 1566.9358 | AG21: שווי הוגן | AH21: 0.0013821036 | AI21: 0.0030214476 | AJ21: 0.00038190603
A22: 13908 | B22: 13909 | C22: חברת נמלי ישראל-פיתוח נכסים בע | D22: 513569780 | E22: ח.פ. | F22: נמלי ישראל אגחב | G22: IL0011455727 | H22: ISIN | I22: צמוד למדד המחירים לצרכן | J22: ישראל | K22: ישראל | L22: סחיר | M22: TASE | N22: נדל"ן מניב בישראל | O22: לא | P22: ilAAA | Q22: S&P מעלות | R22: נייר ערך | S22: ILS | T22: 4.536 | U22: 31/12/2031 | V22: 0.0165 | W22: 0.0258 | X22: החוב לא נחות | Z22: 3686848 | AA22: 1 | AB22: 112.36 | AC22: 0 | AD22: 4142.5424 | AG22: שווי הוגן | AH22: 0.0017426764 | AI22: 0.0079878669 | AJ22: 0.0010096533
A23: 13908 | B23: 13909 | C23: נתיבי הגז הטבעי לישראל בע"מ | D23: 513436394 | E23: ח.פ. | F23: נתיבי גז אגח ד | G23: IL0011475030 | H23: ISIN | I23: צמוד למדד המחירים לצרכן | J23: ישראל | K23: ישראל | L23: סחיר | M23: TASE | N23: שירותים | O23: לא | P23: Aa1.il | Q23: מידרוג Moodys | R23: נייר ערך | S23: ILS | T23: 5.093 | U23: 30/06/2033 | V23: 0.0265 | W23: 0.0255 | X23: החוב לא נחות | Z23: 3473570.7 | AA23: 1 | AB23: 117.66 | AC23: 0 | AD23: 4087.0032 | AG23: שווי הוגן | AH23: 0.0023782499 | AI23: 0.0078807734 | AJ23: 0.00099611687
A24: 13908 | B24: 13909 | C24: מגה אור החזקות בע"מ | D24: 513257873 | E24: ח.פ. | F24: מגה אור אגח ח | G24: IL0011476020 | H24: ISIN | I24: צמוד למדד המחירים לצרכן | J24: ישראל | K24: ישראל | L24: סחיר | M24: TASE | N24: נדל"ן מניב בישראל | O24: לא | P24: ilAA- | Q24: S&P מעלות | R24: נייר ערך | S24: ILS | T24: 1.646 | U24: 31/03/2027 | V24: 0.014 | W24: 0.0266 | X24: החוב לא נחות | Z24: 42592.8 | AA24: 1 | AB24: 113.81 | AC24: 0 | AD24: 48.47487 | AG24: שווי הוגן | AH24: 7.0382709e-05 | AI24: 9.347178e-05 | AJ24: 1.181468e-05
A25: 13908 | B25: 13909 | C25: פתאל החזקות (1998) בע"מ | D25: 512607888 | E25: ח.פ. | F25: פתאל החז אגח ב | G25: IL0011508129 | H25: ISIN | I25: לא צמוד למדד המחירים לצרכן | J25: ישראל | K25: ישראל | L25: סחיר | M25: TASE | N25: מלונאות ותיירות | O25: לא | P25: A2.il | Q25: מידרוג Moodys | R25: נייר ערך | S25: ILS | T25: 0.972 | U25: 31/12/2026 | V25: 0.0325 | W25: 0.0571 | X25: החוב לא נחות | Z25: 472230.06 | AA25: 1 | AB25: 98.55 | AC25: 0 | AD25: 465.38272 | AG25: שווי הוגן | AH25: 0.0022350901 | AI25: 0.0008973753 | AJ25: 0.00011342677
A26: 13908 | B26: 13909 | C26: ביג מרכזי קניות בע"מ | D26: 513623314 | E26: ח.פ. | F26: ביג אגח יא | G26: IL0011511172 | H26: ISIN | I26: צמוד למדד המחירים לצרכן | J26: ישראל | K26: ישראל | L26: סחיר | M26: TASE | N26: נדל"ן מניב בישראל | O26: לא | P26: ilAA | Q26: S&P מעלות | R26: נייר ערך | S26: ILS | T26: 2.421 | U26: 20/10/2027 | V26: 0.0182 | W26: 0.026 | X26: החוב לא נחות | Z26: 870738.97 | AA26: 1 | AB26: 114.28 | AC26: 0 | AD26: 995.08049 | AG26: שווי הוגן | AH26: 0.0017398707 | AI26: 0.0019187662 | AJ26: 0.00024252891
A27: 13908 | B27: 13909 | C27: מניבים קרן הריט החדשה בע"מ | D27: 515327120 | E27: ח.פ. | F27: מניבים ריט אגחב | G27: IL0011559288 | H27: ISIN | I27: צמוד למדד המחירים לצרכן | J27: ישראל | K27: ישראל | L27: סחיר | M27: TASE | N27: נדל"ן מניב בישראל | O27: לא | P27: Aa3.il | Q27: מידרוג Moodys | R27: נייר ערך | S27: ILS | T27: 2.473 | U27: 31/12/2027 | V27: 0.0275 | W27: 0.0274 | X27: החוב לא נחות | Z27: 643446.9 | AA27: 1 | AB27: 115.76 | AC27: 0 | AD27: 744.85413 | AG27: שווי הוגן | AH27: 0.001262776 | AI27: 0.0014362667 | AJ27: 0.00018154176
A28: 13908 | B28: 13909 | C28: שמוס אינטרנשיונל לימיטד | D28: 633896 | E28: LEI | F28: שמוס אגח א | G28: IL0011559510 | H28: ISIN | I28: צמוד למט"ח | J28: ישראל | K28: בריטניה | L28: סחיר | M28: TASE | N28: נדל"ן מניב בחו"ל | O28: לא | P28: Aa3.il | Q28: מידרוג Moodys | R28: נייר ערך | S28: ILS | T28: 2.611 | U28: 47033 | V28: 0.043 | W28: 0.0861 | X28: החוב לא נחות | Z28: 2050344.4 | AA28: 1 | AB28: 91.56 | AC28: 0 | AD28: 1877.2954 | AG28: שווי הוגן | AH28: 0.0019150525 | AI28: 0.0036198991 | AJ28: 0.00045754933
A29: 13908 | B29: 13909 | C29: חברת פרטנר תקשורת בע"מ | D29: 520044314 | E29: ח.פ. | F29: פרטנר אגח ז | G29: IL0011563975 | H29: ISIN | I29: לא צמוד למדד המחירים לצרכן | J29: ישראל | K29: ישראל | L29: סחיר | M29: TASE | N29: תקשורת ומדיה | O29: לא | P29: ilAA- | Q29: S&P מעלות | R29: נייר ערך | S29: ILS | T29: 1.58 | U29: 25/06/2027 | V29: 0.04 | W29: 0.0493 | X29: החוב לא נחות | Z29: 1680000 | AA29: 1 | AB29: 101.61 | AC29: 0 | AD29: 1707.048 | AG29: שווי הוגן | AH29: 0.0028207598 | AI29: 0.0032916192 | AJ29: 0.00041605529
A30: 13908 | B30: 13909 | C30: קבוצת עזריאלי בע"מ | D30: 510960719 | E30: ח.פ. | F30: עזריאלי אגח ה | G30: IL0011566036 | H30: ISIN | I30: צמוד למדד המחירים לצרכן | J30: ישראל | K30: ישראל | L30: סחיר | M30: TASE | N30: נדל"ן מניב בישראל | O30: לא | P30: Aa1.il | Q30: מידרוג Moodys | R30: נייר ערך | S30: ILS | T30: 2.068 | U30: 30/06/2028 | V30: 0.0177 | W30: 0.0275 | X30: החוב לא נחות | Z30: 1301721.2 | AA30: 1 | AB30: 113.81 | AC30: 0 | AD30: 1481.4889 | AG30: שווי הוגן | AH30: 0.00050168221 | AI30: 0.0028566845 | AJ30: 0.00036108025
A31: 13908 | B31: 13909 | C31: קבוצת עזריאלי בע"מ | D31: 510960719 | E31: ח.פ. | F31: עזריאלי אגח ו | G31: IL0011566119 | H31: ISIN | I31: צמוד למדד המחירים לצרכן | J31: ישראל | K31: ישראל | L31: סחיר | M31: TASE | N31: נדל"ן מניב בישראל | O31: לא | P31: Aa1.il | Q31: מידרוג Moodys | R31: נייר ערך | S31: ILS | T31: 5.046 | U31: 31/12/2032 | V31: 0.0248 | W31: 0.0294 | X31: החוב לא נחות | Z31: 989000 | AA31: 1 | AB31: 113.77 | AC31: 0 | AD31: 1125.1853 | AG31: שווי הוגן | AH31: 0.00030019821 | AI31: 0.0021696411 | AJ31: 0.00027423909
A32: 13908 | B32: 13909 | C32: רבוע כחול נדל"ן בע"מ | D32: 513765859 | E32: ח.פ. | F32: רבוע נדלן אגח ח | G32: IL0011575698 | H32: ISIN | I32: צמוד למדד המחירים לצרכן | J32: ישראל | K32: ישראל | L32: סחיר | M32: TASE | N32: נדל"ן מניב בישראל | O32: לא | P32: ilAA | Q32: S&P מעלות | R32: נייר ערך | S32: ILS | T32: 2.289 | U32: 31/10/2028 | V32: 0.0142 | W32: 0.0279 | X32: החוב לא נחות | Z32: 750987.44 | AA32: 1 | AB32: 112.72 | AC32: 0 | AD32: 846.51304 | AG32: שווי הוגן | AH32: 0.0007395515 | AI32: 0.0016322907 | AJ32: 0.00020631888
A33: 13908 | B33: 13909 | C33: ש.י.ר שלמה נדל"ן בע"מ | D33: 513957472 | E33: ח.פ. | F33: שלמה נדלן אגח ד | G33: IL0011576688 | H33: ISIN | I33: לא צמוד למדד המחירים לצרכן | J33: ישראל | K33: ישראל | L33: סחיר | M33: TASE | N33: נדל"ן מניב בישראל | O33: לא | P33: A3.il | Q33: מידרוג Moodys | R33: נייר ערך | S33: ILS | T33: 2.787 | U33: 31/10/2030 | V33: 0.041 | W33: 0.0563 | X33: החוב לא נחות | Z33: 1176100 | AA33: 1 | AB33: 97.74 | AC33: 0 | AD33: 1149.5201 | AG33: שווי הוגן | AH33: 0.0025767482 | AI33: 0.0022165649 | AJ33: 0.00028017017
A34: 13908 | B34: 13909 | C34: מקורות חברת מים בע"מ | D34: 520010869 | E34: ח.פ. | F34: מקורות אגח 11 | G34: IL0011584765 | H34: ISIN | I34: צמוד למדד המחירים לצרכן | J34: ישראל | K34: ישראל | L34: סחיר | M34: TASE | N34: שירותים | O34: לא | P34: ilAAA | Q34: S&P מעלות | R34: נייר ערך | S34: ILS | T34: 11.713 | U34: 31/12/2053 | V34: 0.0207 | W34: 0.0299 | X34: החוב לא נחות | Z34: 3046153.9 | AA34: 1 | AB34: 102.91 | AC34: 0 | AD34: 3134.7969 | AG34: שווי הוגן | AH34: 0.00055717912 | AI34: 0.0060446794 | AJ34: 0.00076403759
A35: 13908 | B35: 13909 | C35: חלל-תקשורת בע"מ | D35: 511396046 | E35: ח.פ. | F35: חלל תקש אגח יח | G35: IL0011585184 | H35: ISIN | I35: צמוד למדד המחירים לצרכן | J35: ישראל | K35: ישראל | L35: סחיר | M35: TASE | N35: תקשורת ומדיה | O35: לא | P35: NR | Q35: NR | R35: נייר ערך | S35: ILS | T35: 1.751 | U35: 31/12/2026 | V35: 0.053 | W35: 0.05 | X35: החוב לא נחות | Z35: 437500 | AA35: 1 | AB35: 104.53 | AC35: 0 | AD35: 457.31875 | AG35: שווי הוגן | AH35: 0.0029069767 | AI35: 0.00088182593 | AJ35: 0.00011146136
A36: 13908 | B36: 13909 | C36: אמות השקעות בע"מ | D36: 520026683 | E36: ח.פ. | F36: אמות אגח ו | G36: IL0011586091 | H36: ISIN | I36: צמוד למדד המחירים לצרכן | J36: ישראל | K36: ישראל | L36: סחיר | M36: TASE | N36: נדל"ן מניב בישראל | O36: לא | P36: ilAA | Q36: S&P מעלות | R36: נייר ערך | S36: ILS | T36: 2.83 | U36: 47187 | V36: 0.0114 | W36: 0.0279 | X36: החוב לא נחות | Z36: 2965559 | AA36: 1 | AB36: 109.34 | AC36: 0 | AD36: 3242.5422 | AG36: שווי הוגן | AH36: 0.0012550065 | AI36: 0.0062524395 | AJ36: 0.00079029812
A37: 13908 | B37: 13909 | C37: אלבר שירותי מימונית בע"מ | D37: 512025891 | E37: ח.פ. | F37: אלבר אגח יז | G37: IL0011587321 | H37: ISIN | I37: צמוד למדד המחירים לצרכן | J37: ישראל | K37: ישראל | L37: סחיר | M37: TASE | N37: שירותים | O37: לא | P37: ilA+ | Q37: S&P מעלות | R37: נייר ערך | S37: ILS | T37: 0.915 | U37: 20/01/2027 | V37: 0.0185 | W37: 0.0304 | X37: החוב לא נחות | Z37: 59228.34 | AA37: 1 | AB37: 113.07 | AC37: 0 | AD37: 66.96948 | AG37: שווי הוגן | AH37: 0.00013359319 | AI37: 0.00012913405 | AJ37: 1.6322333e-05
A38: 13908 | B38: 13909 | C38: אלבר שירותי מימונית בע"מ | D38: 512025891 | E38: ח.פ. | F38: אלבר אגח יח | G38: IL0011587404 | H38: ISIN | I38: לא צמוד למדד המחירים לצרכן | J38: ישראל | K38: ישראל | L38: סחיר | M38: TASE | N38: שירותים | O38: לא | P38: ilA+ | Q38: S&P מעלות | R38: נייר ערך | S38: ILS | T38: 0.884 | U38: 13/01/2027 | V38: 0.0325 | W38: 0.056 | X38: החוב לא נחות | Z38: 48808.14 | AA38: 1 | AB38: 98.74 | AC38: 0 | AD38: 48.19316 | AG38: שווי הוגן | AH38: 0.00014962465 | AI38: 9.2928572e-05 | AJ38: 1.1746019e-05
A39: 13908 | B39: 13909 | C39: אלומיי קפיטל בע"מ | D39: 520039868 | E39: ח.פ. | F39: אלומיי אגח ג | G39: IL0011593758 | H39: ISIN | I39: לא צמוד למדד המחירים לצרכן | J39: ישראל | K39: ישראל | L39: סחיר | M39: TASE | N39: אנרגיה מתחדשת | O39: לא | P39: NR | Q39: NR | R39: נייר ערך | S39: ILS | T39: 0.247 | U39: 30/06/2025 | V39: 0.0355 | W39: 0.0674 | X39: החוב לא נחות | Z39: 304501 | AA39: 1 | AB39: 100.15 | AC39: 0 | AD39: 304.95775 | AG39: שווי הוגן | AH39: 0.0021263858 | AI39: 0.00058803548 | AJ39: 7.4326723e-05
A40: 13908 | B40: 13909 | C40: ביג מרכזי קניות בע"מ | D40: 513623314 | E40: ח.פ. | F40: ביג אגח יג | G40: IL0011595167 | H40: ISIN | I40: צמוד למדד המחירים לצרכן | J40: ישראל | K40: ישראל | L40: סחיר | M40: TASE | N40: נדל"ן מניב בישראל | O40: לא | P40: ilAA | Q40: S&P מעלות | R40: נייר ערך | S40: ILS | T40: 3.19 | U40: 25/03/2029 | V40: 0.0078 | W40: 0.0279 | X40: החוב לא נחות | Z40: 151000.15 | AA40: 1 | AB40: 107.52 | AC40: 0 | AD40: 162.35536 | AG40: שווי הוגן | AH40: 0.00026036394 | AI40: 0.0003130621 | AJ40: 3.9570537e-05
...

Sheet מניות מבכ ויהש
A1: מספר קופה/קרן/ח.פ. עבור חברת ביטוח | B1: מספר מסלול | C1: שם מנפיק | D1: מספר מנפיק | E1: סוג מספר מזהה מנפיק | F1: שם נייר ערך | G1: מספר נייר ערך | H1: סוג מספר נייר ערך | I1: מאפיין עיקרי | J1: ישראל/חו"ל | K1: מדינה לפי חשיפה כלכלית | L1: סטאטוס סחירות | M1: זירת מסחר | N1: ענף מסחר | O1: בעל עניין/צד קשור | P1: מטבע פעילות | Q1: ערך נקוב (יחידות) | R1: שער חליפין | S1: שער נייר הערך | T1: סכום לקבל (במטבע הפעילות) | U1: שווי הוגן (באלפי ש"ח) | V1: שיעור מערך נקוב מונפק | W1: שיעור מנכסי אפיק ההשקעה | X1: שיעור מסך נכסי ההשקעה
A2: 13908 | B2: 13909 | C2: ג'י סיטי בע"מ | D2: 520033234 | E2: ח.פ. | F2: ג'י סיטי | G2: IL0001260111 | H2: ISIN | I2: מניות | J2: ישראל | K2: ישראל | L2: בהשאלה | M2: TASE | N2: נדל"ן מניב בחו"ל | O2: לא | P2: ILS | Q2: 115000 | R2: 1 | S2: -1139 | T2: 0 | U2: -1309.85 | V2: 0.00057709078 | W2: -0.0021643988 | X2: -0.00031924704
A3: 13908 | B3: 13909 | C3: להב אל.אר רילאסטייט בע"מ | D3: 520034257 | E3: ח.פ. | F3: להב | G3: IL0001360101 | H3: ISIN | I3: מניות | J3: ישראל | K3: ישראל | L3: סחיר | M3: TASE | N3: השקעה ואחזקות | O3: לא | P3: ILS | Q3: 4000820 | R3: 1 | S3: 461 | T3: 0 | U3: 18443.78 | V3: 0.014954446 | W3: 0.030476539 | X3: 0.0044952645
A4: 13908 | B4: 13909 | C4: וואן טכנולוגיות תוכנה בע"מ | D4: 520034695 | E4: ח.פ. | F4: וואן טכנולוגיות | G4: IL0001610182 | H4: ISIN | I4: מניות | J4: ישראל | K4: ישראל | L4: סחיר | M4: TASE | N4: שירותי מידע | O4: לא | P4: ILS | Q4: 42688 | R4: 1 | S4: 6861 | T4: 26.59729 | U4: 2955.421 | V4: 0.00059635183 | W4: 0.0048835435 | X4: 0.00072031866
A5: 13908 | B5: 13909 | C5: איילון חברה לביטוח בע"מ | D5: 520030677 | E5: ח.פ. | F5: איילון | G5: IL0002090152 | H5: ISIN | I5: מניות | J5: ישראל | K5: ישראל | L5: סחיר | M5: TASE | N5: ביטוח | O5: לא | P5: ILS | Q5: 60000 | R5: 1 | S5: 4458 | T5: 72.11848 | U5: 2746.9185 | V5: 0.0024039495 | W5: 0.0045390136 | X5: 0.00066950077
A6: 13908 | B6: 13909 | C6: כלל החזקות עסקי ביטוח בע"מ | D6: 520036120 | E6: ח.פ. | F6: כלל עסקי ביטוח | G6: IL0002240146 | H6: ISIN | I6: מניות | J6: ישראל | K6: ישראל | L6: סחיר | M6: TASE | N6: ביטוח | O6: לא | P6: ILS | Q6: 161622 | R6: 1 | S6: 9094 | T6: 0 | U6: 14697.905 | V6: 0.0020327801 | W6: 0.024286847 | X6: 0.00358229
A7: 13908 | B7: 13909 | C7: מבנה נדל"ן (כ.ד) בע"מ | D7: 520024126 | E7: ח.פ. | F7: מבנה | G7: IL0002260193 | H7: ISIN | I7: מניות | J7: ישראל | K7: ישראל | L7: סחיר | M7: TASE | N7: נדל"ן מניב בישראל | O7: לא | P7: ILS | Q7: 510967 | R7: 1 | S7: 992.1 | T7: 48.51805 | U7: 5117.8217 | V7: 0.00069317601 | W7: 0.0084566988 | X7: 0.0012473561
A8: 13908 | B8: 13909 | C8: בזק החברה הישראלית לתקשורת בע" | D8: 520031931 | E8: ח.פ. | F8: בזק | G8: IL0002300114 | H8: ISIN | I8: מניות | J8: ישראל | K8: ישראל | L8: סחיר | M8: TASE | N8: תקשורת ומדיה | O8: לא | P8: ILS | Q8: 3358705 | R8: 1 | S8: 546.6 | T8: 0 | U8: 18358.682 | V8: 0.001212138 | W8: 0.030335922 | X8: 0.0044745236
A9: 13908 | B9: 13909 | C9: ישראמקו נגב 2 שותפות מוגבלת | D9: 550010003 | E9: ח.פ. | F9: ישראמקו יהש | G9: IL0002320179 | H9: ISIN | I9: יחידות השתתפות | J9: ישראל | K9: ישראל | L9: סחיר | M9: TASE | N9: חיפושי נפט וגז | O9: לא | P9: ILS | Q9: 1960119 | R9: 1 | S9: 203 | T9: 0 | U9: 3979.0416 | V9: 0.00075394476 | W9: 0.0065749763 | X9: 0.00096980359
A10: 13908 | B10: 13909 | C10: פורמולה מערכות (1985)בע"מ | D10: 520036690 | E10: ח.פ. | F10: פורמולה מערכות | G10: IL0002560162 | H10: ISIN | I10: מניות | J10: ישראל | K10: ישראל | L10: סחיר | M10: TASE | N10: שירותי מידע | O10: לא | P10: ILS | Q10: 3955 | R10: 1 | S10: 32170 | T10: 0 | U10: 1272.3235 | V10: 0.00025794599 | W10: 0.0021023899 | X10: 0.00031010078
A11: 13908 | B11: 13909 | C11: אורביט טכנולוג'יס בע"מ | D11: 520036153 | E11: ח.פ. | F11: אורביט | G11: IL0002650179 | H11: ISIN | I11: מניות | J11: ישראל | K11: ישראל | L11: סחיר | M11: TASE | N11: ביטחוניות | O11: לא | P11: ILS | Q11: 130200 | R11: 1 | S11: 3094 | T11: 0 | U11: 4028.388 | V11: 0.0051713888 | W11: 0.0066565164 | X11: 0.0009818307
A12: 13908 | B12: 13909 | C12: נייס בע"מ | D12: 520036872 | E12: ח.פ. | F12: נייס | G12: IL0002730112 | H12: ISIN | I12: מניות | J12: ישראל | K12: ישראל | L12: סחיר | M12: TASE | N12: תוכנה ואינטרנט | O12: לא | P12: ILS | Q12: 13701 | R12: 1 | S12: 56600 | T12: 0 | U12: 7754.766 | V12: 0.000217929 | W12: 0.012813991 | X12: 0.0018900531
A13: 13908 | B13: 13909 | C13: איי.סי.אל גרופ בע"מ | D13: 520027830 | E13: ח.פ. | F13: איי.סי.אל | G13: IL0002810146 | H13: ISIN | I13: מניות | J13: ישראל | K13: ישראל | L13: סחיר | M13: TASE | N13: כימיה, גומי ופלסטיק | O13: לא | P13: ILS | Q13: 321215 | R13: 1 | S13: 2089 | T13: 0 | U13: 6710.1813 | V13: 0.00024891452 | W13: 0.011087917 | X13: 0.0016354587
... A1469: 13918 | B1469: 15271 | C1469: קבוצת אקרו בע"מ | D1469: 511996803 | E1469: ח.פ. | F1469: אקרו2 - חסום | G1469: IL0011849028 | H1469: ISIN | I1469: מניות | J1469: ישראל | K1469: ישראל | L1469: חסום | M1469: TASE | N1469: בנייה | O1469: לא | P1469: ILS | Q1469: 20 | R1469: 1 | S1469: 4480.5667 | T1469: 0 | U1469: 0.89611 | V1469: 3.172408e-07 | W1469: 0.033255265 | X1469: 0.00086209915

Sheet קרנות סל
A1: מספר קופה/קרן/ח.פ. עבור חברת ביטוח | B1: מספר מסלול | C1: שם מנפיק | D1: מספר מנפיק | E1: סוג מספר מזהה מנפיק | F1: שם נייר ערך | G1: מספר נייר ערך | H1: סוג מספר נייר ערך | I1: מאפיין עיקרי | J1: ישראל/חו"ל | K1: מדינה לפי חשיפה כלכלית | L1: זירת מסחר | M1: סיווג הקרן | N1: בעל עניין/צד קשור | O1: מטבע פעילות | P1: ערך נקוב (יחידות) | Q1: שער חליפין | R1: שער נייר הערך | S1: סכום לקבל (במטבע הפעילות) | T1: שווי הוגן (באלפי ש"ח) | U1: שיעור מערך נקוב מונפק | V1: שיעור מנכסי אפיק ההשקעה | W1: שיעור מסך נכסי ההשקעה
A2: 13908 | B2: 13909 | C2: מיטב קרנות נאמנות בע"מ | D2: 513534974 | E2: ח.פ. | F2: תכ.תלבונד60 | G2: IL0011451015 | H2: ISIN | I2: עוקב אחר מדדים אחרים בישראל | J2: ישראל | K2: ישראל | L2: TASE | M2: 60 אג"ח בארץ - חברות והמרה-תל בונד צמוד מדד-תל בונד | N2: לא | O2: ILS | P2: 4538180 | Q2: 1 | R2: 373.81 | S2: 0 | T2: 16964.171 | U2: 0.0033326905 | V2: 0.28459376 | W2: 0.0041346423
A3: 13908 | B3: 13909 | C3: קסם קרנות נאמנות בע"מ | D3: 510938608 | E3: ח.פ. | F3: קסם.תלבונד 20 צ | G3: IL0011459604 | H3: ISIN | I3: עוקב אחר מדדים אחרים בישראל | J3: ישראל | K3: ישראל | L3: TASE | M3: 20 אג"ח בארץ - חברות והמרה-תל בונד צמוד מדד-תל בונד | N3: לא | O3: ILS | P3: 7700 | Q3: 1 | R3: 3786.32 | S3: 0 | T3: 291.54664 | U3: 0.00014758256 | V3: 0.0048910352 | W3: 7.1058061e-05
A4: 13908 | B4: 13909 | C4: אי.בי.אי קרנות נאמנות בעמ | D4: 513765339 | E4: ח.פ. | F4: IBI.תלבונד 60צד | G4: IL0011480063 | H4: ISIN | I4: עוקב אחר מדדים אחרים בישראל | J4: ישראל | K4: ישראל | L4: TASE | M4: 60 אג"ח בארץ - חברות והמרה-תל בונד צמוד מדד-תל בונד | N4: לא | O4: ILS | P4: 7718742 | Q4: 1 | R4: 374.2 | S4: 0 | T4: 28883.533 | U4: 0.0056148101 | V4: 0.48455497 | W4: 0.0070397238
A5: 13908 | B5: 13909 | C5: מגדל קרנות נאמנות בע"מ | D5: 511303661 | E5: ח.פ. | F5: SP500.MTF | G5: IL0011503336 | H5: ISIN | I5: עוקב אחר מדדי מניות בחו"ל | J5: ישראל | K5: ארה"ב | L5: TASE | M5: S&P 500 - מניות בחו"ל - מניות גיאוגרפי - חשופת מט"ח-ארה"ב | N5: לא | O5: ILS | P5: 18000 | Q5: 1 | R5: 8809 | S5: 0 | T5: 1585.62 | U5: 0.00020618557 | V5: 0.026600626 | W5: 0.00038645989
