Workbook
Name Additional_Factor: 'אפשרויות בחירה'!$C$701:$C$850
Name Amoritization: 'אפשרויות בחירה'!$C$546:$C$550
Name Capsule: 'אפשרויות בחירה'!$C$926:$C$928
Name Company_Name: 'File Name Info'!$A$34:$A$120
Name Company_Name_ID: 'File Name Info'!$A$34:$B$120
Name Consortium: 'אפשרויות בחירה'!$C$514:$C$515
Name Country_list: 'אפשרויות בחירה'!$C$4:$C$85
Name Country_list_funds: 'אפשרויות בחירה'!$C$4:$C$103
Name CSA: 'אפשרויות בחירה'!$C$688:$C$689
Name Delivery: 'אפשרויות בחירה'!$C$666:$C$667
Name Dependence_Independence: 'אפשרויות בחירה'!$C$654:$C$655
Name Duration_Underlying_Interest_Rate: 'אפשרויות בחירה'!$C$680:$C$687
Name File_Type: 'File Name Info'!$A$10:$A$12
Name Full_File_Type: 'File Name Info'!$A$11:$B$13
Name Full_Type: 'File Name Info'!$A$2:$B$8
Name Full_Type_Nostro: 'File Name Info'!$A$3:$B$6
Name Full_Year: 'File Name Info'!$A$22:$B$31
Name Fund_Strategy: 'אפשרויות בחירה'!$C$597:$C$621
Name Fund_type: 'אפשרויות בחירה'!$C$328:$C$498
Name Holding_interest: 'אפשרויות בחירה'!$C$146:$C$147
Name In_the_books: 'אפשרויות בחירה'!$C$656:$C$657
Name Industry_Sector: 'אפשרויות בחירה'!$C$1129:$C$1245
Name Industry_sector_all: 'אפשרויות בחירה'!$C$202:$C$327
Name Industry_sectors: 'אפשרויות בחירה'!$C$202:$C$327
Name israel_abroad: 'אפשרויות בחירה'!$C$2:$C$3
Name Issuer_Number_Banks: 'אפשרויות בחירה'!$C$111:$C$113
Name Issuer_Number_Fund: 'אפשרויות בחירה'!$C$114:$C$117
Name issuer_number_loan: 'אפשרויות בחירה'!$C$118:$C$126
Name Issuer_Number_Type: 'אפשרויות בחירה'!$C$104:$C$110
Name Issuer_Number_Type_2: 'אפשרויות בחירה'!$C$1076:$C$1079
Name Issuer_Number_Type_3: 'אפשרויות בחירה'!$C$1081:$C$1085
Name Issuer_Number_Type_V2: 'אפשרויות בחירה'!$C$104:$C$110
Name Issuer_Type_TFunds: 'אפשרויות בחירה'!$C$1087:$C$1089
Name Leading_factor: 'אפשרויות בחירה'!$C$692:$C$700
Name Linked_Type: 'אפשרויות בחירה'!$C$516:$C$519
Name other_investments: 'אפשרויות בחירה'!$C$1000:$C$1033
Name Penalty: 'אפשרויות בחירה'!$C$851:$C$852
Name QTR: 'File Name Info'!$A$15:$A$19
Name Rating_Agency: 'אפשרויות בחירה'!$C$188:$C$201
Name real_estate_lifestage: 'אפשרויות בחירה'!$C$634:$C$642
Name real_estate_loans: 'אפשרויות בחירה'!$C$553:$C$591
Name Real_Estate_Main_Use: 'אפשרויות בחירה'!$C$622:$C$633
Name Recourse_Nonrecourse: 'אפשרויות בחירה'!$C$544:$C$545
Name Repayment_Rights: 'אפשרויות בחירה'!$C$551:$C$552
Name Reset_frequency: 'אפשרויות בחירה'!$C$658:$C$665
Name Security_ID_Number_Type: 'אפשרויות בחירה'!$C$1113:$C$1116
Name Security_Number_Loans: 'אפשרויות בחירה'!$C$131
Name Stock_Exchange: 'אפשרויות בחירה'!$C$1283:$C$1315
Name Stock_Exchange_Gov_Bonds: 'אפשרויות בחירה'!$C$148:$C$181
Name Subordination_Risk: 'אפשרויות בחירה'!$C$186:$C$187
Name Tradeable_Status: 'אפשרויות בחירה'!$C$1272:$C$1281
Name Tradeable_Status_All: 'אפשרויות בחירה'!$C$135:$C$145
Name tradeable_status_bonds: 'אפשרויות בחירה'!$C$1248:$C$1253
Name tradeable_status_funds: 'אפשרויות בחירה'!$C$1118:$C$1119
Name tradeable_status_stock: 'אפשרויות בחירה'!$C$1255:$C$1259
Name Tradeable_Status_v2: 'אפשרויות בחירה'!$C$1121:$C$1126
Name tradeable_status_warrants: 'אפשרויות בחירה'!$C$1261:$C$1265
Name tradeable_status_warrants_v2: 'אפשרויות בחירה'!$C$1267:$C$1269
Name Transaction: 'אפשרויות בחירה'!$C$643:$C$646
Name Type: 'File Name Info'!$A$2:$A$8

Sheet עמוד פתיחה
A1: קובץ דיווח עבור רשימת נכסים ברמת הנכס הבודד (חוזר גופים מוסדיים 2015-9-14)
A3: יש לבחור תחום: | D3: נכסי עמיתים - קופות גמל
A5: האם מדובר בקובץ לממומנה או לציבור: | D5: לציבור
A7: יש לבחור את רבעון הדיווח: | D7: 01
A9: יש לבחור את שנת הדיווח: | D9: 2025
A11: יש לבחור את הגוף המוסדי: | D11: החברה לניהול קרן ההשתלמות לעובדי המדינה בע"מ
A13: ח.פ. הגוף המוסדי: | D13: =IFERROR(VLOOKUP(D11,'File Name Info'!A35:B121,2,0),"תא מחושב") -> 520032269
A15: שם קובץ לשמירה | D15: =IF(D5="לממונה",CONCATENATE(D13, "_",VLOOKUP(D3,Full_Type,2,0),"_",D7,VLOOKUP(D9,Full_Year,2,0),".xlxs"),IF(D5="לציבור",CONCATENATE(D13,"_",VLOOKUP(D3,Full_Type_Nostro,2,0),"_",VLOOKUP(D5,Full_File_Type,2,0),"_",D7,VLOOKUP(D9,Full_Year,2,0),".xlsx"),"שם קובץ לשמירה")) -> 520032269_gm_p_0125.xlsx
A17: פרטי האחראי על הדיווח בגוף המוסדי | B17: שם: | D17: שירן נזרי
B19: מספר טלפון: | D19: 546481151
B21: כתובת מייל: | D21: shiran@ovdeimedina.co.il
A23: הוראות למילוי הדיווח: | D23: יש לדווח לפי ההנחיות בחלק ג' לנספח 5.4.3.2 שבפרק 3 שבחלק 4 לשער 5 בחוזר המאוחד - "רשימת נכסים ברמת הנכס הבודד".

Sheet סכום נכסים
C1: ידווח בקבצי נכסי הנוסטרו בלבד
B2: שווי הוגן | C2: עלות מופחתת | D2: השיטה שיושמה בדוח הכספי
A3: מזומנים ושווי מזומנים | B3: =SUM('מזומנים ושווי מזומנים'!O:O) -> 45832.806 | D3: =B3+C3 -> 45832.806
A4: איגרות חוב ממשלתיות | B4: =SUM('איגרות חוב ממשלתיות'!U:U) -> 676525.5 | D4: =B4+C4 -> 676525.5
A5: ניירות ערך מסחריים | B5: =SUM('ניירות ערך מסחריים'!AD:AD) -> 0 | D5: =B5+C5 -> 0
A6: איגרות חוב | B6: =SUM('איגרות חוב'!AD:AD) -> 303113.12 | D6: =B6+C6 -> 303113.12
A7: מניות, מניות בכורה ויחידות השתתפות | B7: =SUM('מניות מבכ ויהש'!U:U) -> 420287.74 | D7: =B7+C7 -> 420287.74
A8: קרנות סל | B8: =SUM('קרנות סל'!T:T) -> 913154.63 | D8: =B8+C8 -> 913154.63
A9: קרנות נאמנות | B9: =SUM('קרנות נאמנות'!T:T) -> 106995.01 | D9: =B9+C9 -> 106995.01
A10: כתבי אופציה | B10: =SUM('כתבי אופציה'!W:W) -> 237.854 | D10: =B10+C10 -> 237.854
A11: אופציות | B11: =SUM(אופציות!V:V) -> -17.92 | D11: =B11+C11 -> -17.92
A12: חוזים עתידיים | B12: =SUM('חוזים עתידיים'!R:R) -> -1077.421 | D12: =B12+C12 -> -1077.421
A13: מוצרים מובנים | B13: =SUM('מוצרים מובנים'!Z:Z) -> 0 | D13: =B13+C13 -> 0
A14: לא סחיר איגרות חוב ממשלתיות | B14: =SUM('לא סחיר איגרות חוב ממשלתיות'!U:U) -> 0 | D14: =B14+C14 -> 0
A15: לא סחיר איגרות חוב מיועדות | B15: =SUM('לא סחיר איגרות חוב מיועדות'!N:N) -> 0 | D15: =B15+C15 -> 0
A16: אפיק השקעה מובטח תשואה | B16: =SUM('אפיק השקעה מובטח תשואה'!F:F) -> 0 | D16: =B16+C16 -> 0
A17: לא סחיר ניירות ערך מסחריים | B17: =SUM('לא סחיר ניירות ערך מסחריים'!AI:AI) -> 0 | D17: =B17+C17 -> 0
A18: לא סחיר איגרות חוב | B18: =SUM('לא סחיר איגרות חוב'!AG:AG) -> 18589.276 | D18: =B18+C18 -> 18589.276
A19: לא סחיר מניות, מניות בכורה ויחידות השתתפות | B19: =SUM('לא סחיר מניות מבכ ויהש'!X:X) -> 2852.566 | D19: =B19+C19 -> 2852.566
A20: קרנות השקעה | B20: =SUM('קרנות השקעה'!W:W) -> 465760.12 | D20: =B20+C20 -> 465760.12
A21: לא סחיר כתבי אופציה | B21: =SUM('לא סחיר כתבי אופציה'!Z:Z) -> 0.408 | D21: =B21+C21 -> 0.408
A22: לא סחיר אופציות | B22: =SUM('לא סחיר אופציות'!Z:Z) -> 0 | D22: =B22+C22 -> 0
A23: לא סחיר נגזרים אחרים | B23: =SUM('לא סחיר נגזרים אחרים'!R:R) -> -9048.5812 | D23: =B23+C23 -> -9048.5812
A24: הלוואות | B24: =SUM(הלוואות!AT:AT) -> 88847.242 | D24: =B24+C24 -> 88847.242
A25: לא סחיר מוצרים מובנים | B25: =SUM('לא סחיר מוצרים מובנים'!AB:AB) -> 0 | D25: =B25+C25 -> 0
A26: פיקדונות מעל 3 חודשים | B26: =SUM('פיקדונות מעל 3 חודשים'!T:T) -> 0 | D26: =B26+C26 -> 0
A27: זכויות מקרקעין | B27: =SUM('זכויות מקרקעין'!S:S) -> 0 | D27: =B27+C27 -> 0
A28: השקעה בחברות מוחזקות | B28: =SUM('השקעה בחברות מוחזקות'!U:U) -> 0 | D28: =B28+C28 -> 0
A29: נכסים אחרים | B29: =SUM('נכסים אחרים'!N:N) -> -1028.181 | D29: =B29+C29 -> -1028.181
A30: סך הכל נכסים | B30: =IF(SUM(B3:B29)=0,0.0001,SUM(B3:B29)) -> 3031024.2 | C30: =SUM(C3:C29) -> 0 | D30: =SUM(D3:D29) -> 3031024.2
A31: מסגרות אשראי
A32: יתרות התחייבויות להשקעה | B32: =SUM('יתרות התחייבות להשקעה'!O:O) -> 122295.42

Sheet מזומנים ושווי מזומנים
A1: מספר קופה/קרן/ח.פ. עבור חברת ביטוח | B1: מספר מסלול | C1: שם הבנק | D1: מספר מזהה בנק | E1: סוג מספר מזהה בנק | F1: מאפיין עיקרי | G1: ישראל/חו"ל | H1: בעל עניין/צד קשור | I1: דירוג הבנק | J1: שם מדרג | K1: מטבע פעילות | L1: שווי מטבעי | M1: שער חליפין | N1: שיעור ריבית | O1: שווי הוגן (באלפי ש"ח) | P1: שיעור מנכסי אפיק ההשקעה | Q1: שיעור מסך נכסי ההשקעה
A2: 382 | B2: 382 | C2: בנק לאומי לישראל בע"מ | D2: 10-800 | E2: סימול בנק | F2: מזומן ועו"ש נקוב במט"ח | G2: ישראל | H2: לא | I2: AAA | J2: S&P מעלות | K2: USD | L2: 0.002 | M2: 3.718 | N2: 0 | O2: 0.008 | P2: 2.0234624e-07 | Q2: 2.8420165e-09
A3: 382 | B3: 382 | C3: בנק לאומי לישראל בע"מ | D3: 10-800 | E3: סימול בנק | F3: מזומן ועו"ש בש"ח | G3: ישראל | H3: לא | I3: AAA | J3: S&P מעלות | K3: ILS | L3: 0.002 | M3: 1 | N3: 0 | O3: 0.002 | P3: 4.2356682e-08 | Q3: 5.949129e-10
A4: 382 | B4: 382 | C4: בנק לאומי לישראל בע"מ | D4: 10-800 | E4: סימול בנק | F4: מזומן ועו"ש בש"ח | G4: ישראל | H4: לא | I4: AAA | J4: S&P מעלות | K4: ILS | L4: 0 | M4: 1 | N4: 0.038 | O4: 0 | P4: -5.9102346e-09 | Q4: -8.3011103e-11
A5: 382 | B5: 382 | C5: בנק לאומי לישראל בע"מ | D5: 10-800 | E5: סימול בנק | F5: מזומן ועו"ש נקוב במט"ח | G5: ישראל | H5: לא | I5: AAA | J5: S&P מעלות | K5: USD | L5: 911.862 | M5: 3.718 | N5: 0 | O5: 3390.304 | P5: 0.083489546 | Q5: 0.0011726369
A6: 382 | B6: 382 | C6: בנק לאומי לישראל בע"מ | D6: 10-800 | E6: סימול בנק | F6: מזומן ועו"ש נקוב במט"ח | G6: ישראל | H6: לא | I6: AAA | J6: S&P מעלות | K6: EUR | L6: 6.192 | M6: 4.0219 | N6: 0 | O6: 24.905 | P6: 0.00061329938 | Q6: 8.6139826e-06
A7: 382 | B7: 382 | C7: בנק לאומי לישראל בע"מ | D7: 10-800 | E7: סימול בנק | F7: מזומן ועו"ש נקוב במט"ח | G7: ישראל | H7: לא | I7: AAA | J7: S&P מעלות | K7: JPY | L7: -1.473 | M7: 0.024893 | N7: 0 | O7: -0.037 | P7: -9.0322164e-07 | Q7: -1.2686032e-08
A8: 382 | B8: 382 | C8: בנק לאומי לישראל בע"מ | D8: 10-800 | E8: סימול בנק | F8: מזומן ועו"ש נקוב במט"ח | G8: ישראל | H8: לא | I8: AAA | J8: S&P מעלות | K8: GBP | L8: 0.966 | M8: 4.8108 | N8: 0 | O8: 4.649 | P8: 0.00011448649 | Q8: 1.6079987e-06
A9: 382 | B9: 382 | C9: בנק לאומי לישראל בע"מ | D9: 10-800 | E9: סימול בנק | F9: מזומן ועו"ש בש"ח | G9: ישראל | H9: לא | I9: AAA | J9: S&P מעלות | K9: ILS | L9: 37187.695 | M9: 1 | N9: 0.038 | O9: 37187.695 | P9: 0.91578333 | Q9: 0.012862465
A10: 382 | B10: 382 | C10: בנק לאומי לישראל בע"מ | D10: 10-800 | E10: סימול בנק | F10: מזומן ועו"ש בש"ח | G10: ישראל | H10: לא | I10: AAA | J10: S&P מעלות | K10: ILS | L10: 0 | M10: 1 | N10: 0 | O10: 0 | P10: 2.4625978e-10 | Q10: 3.458796e-12
A11: 382 | B11: 1404 | C11: בנק לאומי לישראל בע"מ | D11: 10-800 | E11: סימול בנק | F11: מזומן ועו"ש בש"ח | G11: ישראל | H11: לא | I11: AAA | J11: S&P מעלות | K11: ILS | L11: 0 | M11: 1 | N11: 0.038 | O11: 0 | P11: -1.9013104e-07 | Q11: -3.7403184e-09
A12: 382 | B12: 1404 | C12: בנק לאומי לישראל בע"מ | D12: 10-800 | E12: סימול בנק | F12: מזומן ועו"ש נקוב במט"ח | G12: ישראל | H12: לא | I12: AAA | J12: S&P מעלות | K12: USD | L12: 8.39 | M12: 3.718 | N12: 0 | O12: 31.196 | P12: 0.059312907 | Q12: 0.0011668224
A13: 382 | B13: 1404 | C13: בנק לאומי לישראל בע"מ | D13: 10-800 | E13: סימול בנק | F13: מזומן ועו"ש בש"ח | G13: ישראל | H13: לא | I13: AAA | J13: S&P מעלות | K13: ILS | L13: 494.757 | M13: 1 | N13: 0.038 | O13: 494.757 | P13: 0.94068728 | Q13: 0.0185055
... A29: 382 | B29: 15404 | C29: בנק לאומי לישראל בע"מ | D29: 10-800 | E29: סימול בנק | F29: מזומן ועו"ש בש"ח | G29: ישראל | H29: לא | I29: AAA | J29: S&P מעלות | K29: ILS | L29: 0 | M29: 1 | N29: 0 | O29: 0 | P29: 1.8566589e-07 | Q29: 2.999459e-09

Sheet איגרות חוב ממשלתיות
A1: מספר קופה/קרן/ח.פ. עבור חברת ביטוח | B1: מספר מסלול | C1: שם מנפיק | D1: שם נייר ערך | E1: מספר נייר ערך | F1: מאפיין עיקרי | G1: ישראל/חו"ל | H1: מדינה לפי חשיפה כלכלית | I1: זירת מסחר | J1: דירוג | K1: שם מדרג | L1: מטבע פעילות | M1: מח"מ | N1: מועד פדיון | O1: שיעור ריבית | P1: תשואה לפדיון | Q1: סכום לקבל (במטבע הפעילות) | R1: ערך נקוב (יחידות) | S1: שער חליפין | T1: שער נייר הערך | U1: שווי הוגן (באלפי ש"ח) | V1: עלות מופחתת (באלפי ש"ח) | W1: השיטה שיושמה בדוח הכספי | X1: שיעור מערך נקוב מונפק | Y1: שיעור מנכסי אפיק ההשקעה | Z1: שיעור מסך נכסי ההשקעה
A2: 382 | B2: 382 | C2: בנק ישראל- מק"מ | D2: מ.ק.מ. 915 | E2: IL0082509121 | F2: מק"מ קצר משנים עשר חודשים | G2: ישראל | H2: ישראל | I2: TASE | J2: RF | K2: פנימי | L2: ILS | M2: 0.425 | N2: 03/09/2025 | O2: 0 | P2: 0.0427 | R2: 31000000 | S2: 1 | T2: 98.24 | U2: 30454.4 | W2: שווי הוגן | X2: 0.002583 | Y2: 0.048577417 | Z2: 0.010533556
A3: 382 | B3: 382 | C3: בנק ישראל- מק"מ | D3: מלווה קצר מועד 1015 | E3: IL0082510194 | F3: מק"מ קצר משנים עשר חודשים | G3: ישראל | H3: ישראל | I3: TASE | J3: RF | K3: פנימי | L3: ILS | M3: 0.507 | N3: 01/10/2025 | O3: 0 | P3: 0.04276 | R3: 6800000 | S3: 1 | T3: 97.9 | U3: 6657.2 | W3: שווי הוגן | X3: 0.000486 | Y3: 0.010618813 | Z3: 0.0023025896
A4: 382 | B4: 382 | C4: בנק ישראל- מק"מ | D4: מלווה קצר מועד 515 | E4: IL0082505160 | F4: מק"מ קצר משנים עשר חודשים | G4: ישראל | H4: ישראל | I4: TASE | J4: RF | K4: פנימי | L4: ILS | M4: 0.099 | N4: 07/05/2025 | O4: 0 | P4: 0.04254 | R4: 84500000 | S4: 1 | T4: 99.59 | U4: 84153.55 | W4: שווי הוגן | X4: 0.002284 | Y4: 0.13423223 | Z4: 0.029106996
A5: 382 | B5: 382 | C5: גליל | D5: ממשל צמודה 0527 | E5: IL0011408478 | F5: צמוד למדד המחירים לצרכן בריבית קבועה | G5: ישראל | H5: ישראל | I5: TASE | J5: RF | K5: פנימי | L5: ILS | M5: 2.142 | N5: 31/05/2027 | O5: 0.0075 | P5: 0.01945 | R5: 46800000 | S5: 1 | T5: 114.63 | U5: 53646.84 | W5: שווי הוגן | X5: 0.001921 | Y5: 0.085571377 | Z5: 0.018555347
A6: 382 | B6: 382 | C6: גליל | D6: ממשל צמודה 1131 | E6: IL0011722209 | F6: צמוד למדד המחירים לצרכן בריבית קבועה | G6: ישראל | H6: ישראל | I6: TASE | J6: RF | K6: פנימי | L6: ILS | M6: 6.646 | N6: 30/11/2031 | O6: 0.001 | P6: 0.02031 | R6: 35675000 | S6: 1 | T6: 101.91 | U6: 36356.393 | W6: שווי הוגן | X6: 0.001162 | Y6: 0.057991609 | Z6: 0.012574934
A7: 382 | B7: 382 | C7: שחר | D7: ממשל שיקלית 0928 | E7: IL0011508798 | F7: לא צמוד למדד המחירים לצרכן ריבית קבועה | G7: ישראל | H7: ישראל | I7: TASE | J7: RF | K7: פנימי | L7: ILS | M7: 3.36 | N7: 28/09/2028 | O7: 0.0225 | P7: 0.04261 | R7: 7510000 | S7: 1 | T7: 94.71 | U7: 7112.721 | W7: שווי הוגן | X7: 0.000216 | Y7: 0.011345409 | Z7: 0.0024601451
A8: 382 | B8: 382 | C8: שחר | D8: ממשל שקלית 0226 | E8: IL0011746976 | F8: לא צמוד למדד המחירים לצרכן ריבית קבועה | G8: ישראל | H8: ישראל | I8: TASE | J8: RF | K8: פנימי | L8: ILS | M8: 0.91 | N8: 27/02/2026 | O8: 0.005 | P8: 0.04161 | R8: 15550000 | S8: 1 | T8: 96.84 | U8: 15058.62 | W8: שווי הוגן | X8: 0.00056 | Y8: 0.024019809 | Z8: 0.0052084694
A9: 382 | B9: 382 | C9: שחר | D9: ממשל שקלית 0335 | E9: IL0012023326 | F9: לא צמוד למדד המחירים לצרכן ריבית קבועה | G9: ישראל | H9: ישראל | I9: TASE | J9: RF | K9: פנימי | L9: ILS | M9: 8.398 | N9: 30/03/2035 | O9: 0.04 | P9: 0.04485 | R9: 34622000 | S9: 1 | T9: 96.17 | U9: 33295.977 | W9: שווי הוגן | X9: 0.00117 | Y9: 0.053109981 | Z9: 0.011516399
A10: 382 | B10: 382 | C10: שחר | D10: ממשל שקלית 0347 | E10: IL0011401937 | F10: לא צמוד למדד המחירים לצרכן ריבית קבועה | G10: ישראל | H10: ישראל | I10: TASE | J10: RF | K10: פנימי | L10: ILS | M10: 14.74 | N10: 31/03/2047 | O10: 0.0375 | P10: 0.0486 | R10: 19320000 | S10: 1 | T10: 85.21 | U10: 16462.572 | W10: שווי הוגן | X10: 0.000736 | Y10: 0.026259235 | Z10: 0.0056940677
A11: 382 | B11: 382 | C11: שחר | D11: ממשלתי שקלית 0142 | E11: IL0011254005 | F11: לא צמוד למדד המחירים לצרכן ריבית קבועה | G11: ישראל | H11: ישראל | I11: TASE | J11: RF | K11: פנימי | L11: ILS | M11: 11.552 | N11: 31/01/2042 | O11: 0.055 | P11: 0.0473 | R11: 18600000 | S11: 1 | T11: 109.69 | U11: 20402.34 | W11: שווי הוגן | X11: 0.000685 | Y11: 0.032543507 | Z11: 0.0070567531
A12: 382 | B12: 382 | C12: גליל | D12: ממשלתית צמודה 0.5% 0529 | E12: IL0011570236 | F12: צמוד למדד המחירים לצרכן בריבית קבועה | G12: ישראל | H12: ישראל | I12: TASE | J12: RF | K12: פנימי | L12: ILS | M12: 4.115 | N12: 31/05/2029 | O12: 0.005 | P12: 0.01969 | R12: 54149000 | S12: 1 | T12: 109.42 | U12: 59249.836 | W12: שווי הוגן | X12: 0.00197 | Y12: 0.094508643 | Z12: 0.020493309
A13: 382 | B13: 382 | C13: גליל | D13: ממשלתית צמודה 0726 | E13: IL0011695645 | F13: צמוד למדד המחירים לצרכן בריבית קבועה | G13: ישראל | H13: ישראל | I13: TASE | J13: RF | K13: פנימי | L13: ILS | M13: 1.331 | N13: 31/07/2026 | O13: 0.001 | P13: 0.0196 | R13: 24007000 | S13: 1 | T13: 112.95 | U13: 27115.907 | W13: שווי הוגן | X13: 0.001188 | Y13: 0.04325223 | Z13: 0.0093788388
... A75: 382 | B75: 11414 | C75: בנק ישראל- מק"מ | D75: מקמ 815 | E75: IL0082508131 | F75: מק"מ קצר משנים עשר חודשים | G75: ישראל | H75: ישראל | I75: TASE | J75: RF | K75: פנימי | L75: ILS | M75: 0.348 | N75: 06/08/2025 | O75: 0 | P75: 0.04287 | R75: 780000 | S75: 1 | T75: 98.55 | U75: 768.69 | W75: שווי הוגן | X75: 6.5e-05 | Y75: 0.073786892 | Z75: 0.049884504

Sheet ניירות ערך מסחריים
A1: מספר קופה/קרן/ח.פ. עבור חברת ביטוח | B1: מספר מסלול | C1: שם מנפיק | D1: מספר מנפיק | E1: סוג מספר מזהה מנפיק | F1: שם נייר ערך | G1: מספר נייר ערך | H1: סוג מספר נייר ערך | I1: מאפיין עיקרי | J1: ישראל/חו"ל | K1: מדינה לפי חשיפה כלכלית | L1: זירת מסחר | M1: ענף מסחר | N1: בעל עניין/צד קשור | O1: דירוג | P1: שם מדרג | Q1: דירוג נייר הערך/המנפיק | R1: מטבע פעילות | S1: מח"מ | T1: ריבית עוגן | U1: מועד פדיון | V1: שיעור ריבית | W1: תשואה לפדיון | X1: נחיתות חוזית | Y1: האם סווג כחוב בעייתי | Z1: ערך נקוב (יחידות) | AA1: שער חליפין | AB1: שער נייר הערך | AC1: סכום לקבל (במטבע הפעילות) | AD1: שווי הוגן (באלפי ש"ח) | AE1: עלות מופחתת (באלפי ש"ח) | AF1: עלות מופחתת (במטבע הפעילות) | AG1: השיטה שיושמה בדוח הכספי | AH1: שיעור מערך נקוב מונפק | AI1: שיעור מנכסי אפיק ההשקעה | AJ1: שיעור מסך נכסי ההשקעה

Sheet איגרות חוב
A1: מספר קופה/קרן/ח.פ. עבור חברת ביטוח | B1: מספר מסלול | C1: שם מנפיק | D1: מספר מנפיק | E1: סוג מספר מזהה מנפיק | F1: שם נייר ערך | G1: מספר נייר ערך | H1: סוג מספר נייר ערך | I1: מאפיין עיקרי | J1: ישראל/חו"ל | K1: מדינה לפי חשיפה כלכלית | L1: סטאטוס סחירות | M1: זירת מסחר | N1: ענף מסחר | O1: בעל עניין/צד קשור | P1: דירוג | Q1: שם מדרג | R1: דירוג נייר הערך/המנפיק | S1: מטבע פעילות | T1: מח"מ | U1: מועד פדיון | V1: שיעור ריבית | W1: תשואה לפדיון | X1: נחיתות חוזית | Y1: האם סווג כחוב בעייתי | Z1: ערך נקוב (יחידות) | AA1: שער חליפין | AB1: שער נייר הערך | AC1: סכום לקבל (במטבע הפעילות) | AD1: שווי הוגן (באלפי ש"ח) | AE1: עלות מופחתת (באלפי ש"ח) | AF1: עלות מופחתת (במטבע הפעילות) | AG1: השיטה שיושמה בדוח הכספי | AH1: שיעור מערך נקוב מונפק | AI1: שיעור מנכסי אפיק ההשקעה | AJ1: שיעור מסך נכסי ההשקעה
A2: 382 | B2: 382 | C2: איירפורט סיטי בע"מ | D2: 511659401 | E2: ח.פ | F2: איירפורט אגח ה | G2: IL0011334872 | H2: ISIN | I2: צמוד למדד המחירים לצרכן | J2: ישראל | K2: ישראל | L2: סחיר | M2: TASE | N2: נדל"ן מניב בישראל | O2: לא | P2: AA | Q2: S&P מעלות | R2: נייר ערך | S2: ILS | T2: 2.267 | U2: 28/02/2029 | V2: 0.0234 | W2: 0.02797 | X2: החוב לא נחות | Y2: לא | Z2: 4080000.3 | AA2: 1 | AB2: 114.39 | AD2: 4667.112 | AG2: שווי הוגן | AH2: 0.002503 | AI2: 0.015874363 | AJ2: 0.0016142589
A3: 382 | B3: 382 | C3: אלוני-חץ נכסים והשקעות בע"מ | D3: 520038506 | E3: ח.פ | F3: אלוני חץ אגח טו | G3: IL0011894149 | H3: ISIN | I3: צמוד למדד המחירים לצרכן | J3: ישראל | K3: ישראל | L3: סחיר | M3: TASE | N3: נדל"ן מניב בישראל | O3: לא | P3: AA- | Q3: S&P מעלות | R3: נייר ערך | S3: ILS | T3: 6.663 | U3: 01/03/2037 | V3: 0.0256 | W3: 0.03503 | X3: החוב לא נחות | Y3: לא | Z3: 2700000 | AA3: 1 | AB3: 101.59 | AD3: 2742.93 | AG3: שווי הוגן | AH3: 0.00257 | AI3: 0.0093295944 | AJ3: 0.00094872352
A4: 382 | B4: 382 | C4: אלוני-חץ נכסים והשקעות בע"מ | D4: 520038506 | E4: ח.פ | F4: אלוני חץ אגח יב | G4: IL0039004952 | H4: ISIN | I4: לא צמוד למדד המחירים לצרכן | J4: ישראל | K4: ישראל | L4: סחיר | M4: TASE | N4: נדל"ן מניב בישראל | O4: לא | P4: AA- | Q4: S&P מעלות | R4: נייר ערך | S4: ILS | T4: 3.951 | U4: 28/02/2031 | V4: 0.0241 | W4: 0.05291 | X4: החוב לא נחות | Y4: לא | Z4: 3685500 | AA4: 1 | AB4: 89.75 | AD4: 3307.736 | AG4: שווי הוגן | AH4: 0.001793 | AI4: 0.011250684 | AJ4: 0.0011440785
A5: 382 | B5: 382 | C5: אלקטרה בע"מ | D5: 520028911 | E5: ח.פ | F5: אלקטרה אגח ד | G5: IL0073901493 | H5: ISIN | I5: לא צמוד למדד המחירים לצרכן | J5: ישראל | K5: ישראל | L5: סחיר | M5: TASE | N5: השקעה ואחזקות | O5: לא | P5: A+ | Q5: S&P מעלות | R5: נייר ערך | S5: ILS | T5: 0.729 | U5: 30/06/2026 | V5: 0.04 | W5: 0.05407 | X5: החוב לא נחות | Y5: לא | Z5: 1166669.5 | AA5: 1 | AB5: 100.05 | AD5: 1167.253 | AG5: שווי הוגן | AH5: 0.008855 | AI5: 0.0039702053 | AJ5: 0.00040372893
A6: 382 | B6: 382 | C6: אלקטרה בע"מ | D6: 520028911 | E6: ח.פ | F6: אלקטרה אגח ה | G6: IL0073902228 | H6: ISIN | I6: לא צמוד למדד המחירים לצרכן | J6: ישראל | K6: ישראל | L6: סחיר | M6: TASE | N6: השקעה ואחזקות | O6: לא | P6: A+ | Q6: S&P מעלות | R6: נייר ערך | S6: ILS | T6: 2.996 | U6: 10/01/2031 | V6: 0.04 | W6: 0.0524 | X6: החוב לא נחות | Y6: לא | Z6: 1950000.6 | AA6: 1 | AB6: 97.45 | AD6: 1900.276 | AG6: שווי הוגן | AH6: 0.003358 | AI6: 0.0064634533 | AJ6: 0.00065726653
A7: 382 | B7: 382 | C7: אמות השקעות בע"מ | D7: 520026683 | E7: ח.פ | F7: אמות אגח ד | G7: IL0011331498 | H7: ISIN | I7: צמוד למדד המחירים לצרכן | J7: ישראל | K7: ישראל | L7: סחיר | M7: TASE | N7: נדל"ן מניב בישראל | O7: לא | P7: AA | Q7: S&P מעלות | R7: נייר ערך | S7: ILS | T7: 1.682 | U7: 02/07/2028 | V7: 0.032 | W7: 0.02754 | X7: החוב לא נחות | Y7: לא | Z7: 3120000 | AA7: 1 | AB7: 118.93 | AD7: 3710.616 | AG7: שווי הוגן | AH7: 0.005651 | AI7: 0.012621008 | AJ7: 0.0012834264
A8: 382 | B8: 382 | C8: אנלייט אנרגיה מתחדשת בע"מ | D8: 520041146 | E8: ח.פ | F8: אנלייט אנר אגח ו | G8: IL0072001733 | H8: ISIN | I8: לא צמוד למדד המחירים לצרכן | J8: ישראל | K8: ארה"ב | L8: סחיר | M8: TASE | N8: אנרגיה מתחדשת | O8: לא | P8: A2 | Q8: מידרוג Moodys | R8: נייר ערך | S8: ILS | T8: 1.261 | U8: 01/09/2026 | V8: 0.0345 | W8: 0.05499 | X8: החוב לא נחות | Y8: לא | Z8: 2608695.5 | AA8: 1 | AB8: 97.86 | AD8: 2552.869 | AG8: שווי הוגן | AH8: 0.004059 | AI8: 0.0086831366 | AJ8: 0.00088298543
A9: 382 | B9: 382 | C9: בתי זקוק לנפט בע"מ | D9: 520036658 | E9: ח.פ | F9: בזן אגח ט | G9: IL0025904611 | H9: ISIN | I9: צמוד למט"ח | J9: ישראל | K9: ישראל | L9: סחיר | M9: TASE | N9: אנרגיה | O9: לא | P9: A+ | Q9: S&P מעלות | R9: נייר ערך | S9: ILS | T9: 0.499 | U9: 30/09/2025 | V9: 0.047 | W9: 0.07732 | X9: החוב לא נחות | Y9: לא | Z9: 563616.51 | AA9: 1 | AB9: 100.8 | AD9: 568.125 | AG9: שווי הוגן | AH9: 0.002298 | AI9: 0.0019323789 | AJ9: 0.000196503
A10: 382 | B10: 382 | C10: ביג מרכזי קניות (2004) בע"מ | D10: 513623314 | E10: ח.פ | F10: ביג אגח ז | G10: IL0011360844 | H10: ISIN | I10: צמוד למדד המחירים לצרכן | J10: ישראל | K10: ישראל | L10: סחיר | M10: TASE | N10: נדל"ן מניב בישראל | O10: לא | P10: AA- | Q10: S&P מעלות | R10: נייר ערך | S10: ILS | T10: 0.11 | U10: 11/05/2025 | V10: 0.025 | W10: 0.03762 | X10: החוב לא נחות | Y10: לא | Z10: 1500379.7 | AA10: 1 | AB10: 116.75 | AD10: 1751.693 | AG10: שווי הוגן | AH10: 0.006371 | AI10: 0.0059580771 | AJ10: 0.00060587499
A11: 382 | B11: 382 | C11: ביג מרכזי קניות (2004) בע"מ | D11: 513623314 | E11: ח.פ | F11: ביג אגח כ | G11: IL0011861882 | H11: ISIN | I11: צמוד למדד המחירים לצרכן | J11: ישראל | K11: ישראל | L11: סחיר | M11: TASE | N11: נדל"ן מניב בישראל | O11: לא | P11: AA- | Q11: S&P מעלות | R11: נייר ערך | S11: ILS | T11: 4.878 | U11: 01/05/2033 | V11: 0.0187 | W11: 0.03163 | X11: החוב לא נחות | Y11: לא | Z11: 6786300 | AA11: 1 | AB11: 105.08 | AD11: 7131.044 | AG11: שווי הוגן | AH11: 0.006631 | AI11: 0.024254993 | AJ11: 0.0024664826
A12: 382 | B12: 382 | C12: הבינלאומי הראשון הנפקות בע"מ | D12: 513141879 | E12: ח.פ | F12: בינל הנפק אגח י | G12: IL0011602906 | H12: ISIN | I12: צמוד למדד המחירים לצרכן | J12: ישראל | K12: ישראל | L12: סחיר | M12: TASE | N12: בנקים | O12: לא | P12: AAA | Q12: S&P מעלות | R12: נייר ערך | S12: ILS | T12: 0.444 | U12: 10/09/2025 | V12: 0.001 | W12: 0.0226 | X12: החוב לא נחות | Y12: לא | Z12: 2000000 | AA12: 1 | AB12: 113.85 | AD12: 2277 | AG12: שווי הוגן | AH12: 0.001333 | AI12: 0.0077448154 | AJ12: 0.00078756784
A13: 382 | B13: 382 | C13: פז בית זיקוק לנפט-אשדוד בע"מ | D13: 513775163 | E13: ח.פ | F13: בית זיקוק אשדוד אגח 2 | G13: IL0011994881 | H13: ISIN | I13: לא צמוד למדד המחירים לצרכן | J13: ישראל | K13: ישראל | L13: סחיר | M13: TASE | N13: אנרגיה | O13: לא | P13: A3 | Q13: מידרוג Moodys | R13: נייר ערך | S13: ILS | T13: 2.621 | U13: 30/04/2029 | V13: 0.0725 | W13: 0.05692 | X13: החוב לא נחות | Y13: לא | Z13: 2150052.3 | AA13: 1 | AB13: 107.37 | AD13: 2308.511 | AG13: שווי הוגן | AH13: 0.002986 | AI13: 0.007851995 | AJ13: 0.0007984669
... A22: 382 | B22: 382 | C22: וילאר אינטרנשיונל בע"מ | D22: 520038910 | E22: ח.פ | F22: וילאר אינטרנ' ח' | G22: IL0041601563 | H22: ISIN | I22: לא צמוד למדד המחירים לצרכן | J22: ישראל | K22: ישראל | L22: סחיר | M22: TASE | N22: נדל"ן מניב בישראל | O22: לא | P22: AA | Q22: S&P מעלות | R22: נייר ערך | S22: ILS | T22: 0.238 | U22: 27/06/2025 | V22: 0.0255 | W22: 0.03017 | X22: החוב לא נחות | Y22: לא | Z22: 1399999.9 | AA22: 1 | AB22: 100.56 | AD22: 1407.84 | AG22: שווי הוגן | AH22: 0.020862 | AI22: 0.0047885201 | AJ22: 0.00048694311
A23: 382 | B23: 382 | C23: חברת החשמל לישראל בע"מ | D23: 520000472 | E23: ח.פ | F23: חשמל אגח 27 | G23: IL0060002107 | H23: ISIN | I23: צמוד למדד המחירים לצרכן | J23: ישראל | K23: ישראל | L23: סחיר | M23: TASE | N23: אנרגיה | O23: לא | P23: AAA | Q23: S&P מעלות | R23: נייר ערך | S23: ILS | T23: 3.022 | U23: 12/04/2029 | V23: 0.0385 | W23: 0.02566 | X23: החוב לא נחות | Y23: לא | Z23: 3719173 | AA23: 1 | AB23: 120.79 | AC23: 131.631 | AD23: 4624.02 | AG23: שווי הוגן | AH23: 0.001456 | AI23: 0.015727793 | AJ23: 0.0015993543
A24: 382 | B24: 382 | C24: חברת החשמל לישראל בע"מ | D24: 520000472 | E24: ח.פ | F24: חשמל אגח 33 | G24: IL0060003923 | H24: ISIN | I24: צמוד למדד המחירים לצרכן | J24: ישראל | K24: ישראל | L24: סחיר | M24: TASE | N24: אנרגיה | O24: לא | P24: AAA | Q24: S&P מעלות | R24: נייר ערך | S24: ILS | T24: 10.281 | U24: 30/05/2036 | V24: 0.0125 | W24: 0.0311 | X24: החוב לא נחות | Y24: לא | Z24: 7800000 | AA24: 1 | AB24: 95.3 | AD24: 7433.4 | AG24: שווי הוגן | AH24: 0.001817 | AI24: 0.025283404 | AJ24: 0.0025710614
A25: 382 | B25: 382 | C25: חברת החשמל לישראל בע"מ | D25: 520000472 | E25: ח.פ | F25: חשמל אגח 34 | G25: IL0011967812 | H25: ISIN | I25: צמוד למדד המחירים לצרכן | J25: ישראל | K25: ישראל | L25: סחיר | M25: TASE | N25: אנרגיה | O25: לא | P25: AAA | Q25: S&P מעלות | R25: נייר ערך | S25: ILS | T25: 7.271 | U25: 12/06/2033 | V25: 0.03 | W25: 0.02951 | X25: החוב לא נחות | Y25: לא | Z25: 6125000 | AA25: 1 | AB25: 106.29 | AD25: 6510.262 | AG25: שווי הוגן | AH25: 0.001501 | AI25: 0.022143514 | AJ25: 0.002251767
A26: 382 | B26: 382 | C26: יוניברסל מוטורס ישראל בע"מ | D26: 511809071 | E26: ח.פ | F26: יוניברסל אגח ד | G26: IL0011722530 | H26: ISIN | I26: לא צמוד למדד המחירים לצרכן | J26: ישראל | K26: ישראל | L26: סחיר | M26: TASE | N26: מסחר | O26: לא | P26: AA- | Q26: S&P מעלות | R26: נייר ערך | S26: ILS | T26: 1.891 | U26: 11/02/2029 | V26: 0.0218 | W26: 0.0518 | X26: החוב לא נחות | Y26: לא | Z26: 3200000 | AA26: 1 | AB26: 94.94 | AD26: 3038.08 | AG26: שווי הוגן | AH26: 0.010508 | AI26: 0.010333495 | AJ26: 0.0010508099
A27: 382 | B27: 382 | C27: בנק לאומי לישראל בע"מ | D27: 520018078 | E27: ח.פ | F27: לאומי אגח 179 | G27: IL0060403727 | H27: ISIN | I27: צמוד למדד המחירים לצרכן | J27: ישראל | K27: ישראל | L27: סחיר | M27: TASE | N27: בנקים | O27: לא | P27: AAA | Q27: S&P מעלות | R27: נייר ערך | S27: ILS | T27: 1.238 | U27: 30/06/2026 | V27: 0.0083 | W27: 0.0229 | X27: החוב לא נחות | Y27: לא | Z27: 7750000 | AA27: 1 | AB27: 114.23 | AD27: 8852.825 | AG27: שווי הוגן | AH27: 0.005096 | AI27: 0.030111329 | AJ27: 0.0030620115
A28: 382 | B28: 382 | C28: בנק לאומי לישראל בע"מ | D28: 520018078 | E28: ח.פ | F28: לאומי אגח 184 | G28: IL0060406043 | H28: ISIN | I28: לא צמוד למדד המחירים לצרכן | J28: ישראל | K28: ישראל | L28: סחיר | M28: TASE | N28: בנקים | O28: לא | P28: AAA | Q28: S&P מעלות | R28: נייר ערך | S28: ILS | T28: 2.663 | U28: 05/05/2030 | V28: 0.0276 | W28: 0.04668 | X28: החוב לא נחות | Y28: לא | Z28: 14500000 | AA28: 1 | AB28: 96.29 | AD28: 13962.05 | AG28: שווי הוגן | AH28: 0.010851 | AI28: 0.04748946 | AJ28: 0.0048291882
A29: 382 | B29: 382 | C29: בנק לאומי לישראל בע"מ | D29: 520018078 | E29: ח.פ | F29: לאומי אגח 186 | G29: IL0012018391 | H29: ISIN | I29: צמוד למדד המחירים לצרכן | J29: ישראל | K29: ישראל | L29: סחיר | M29: TASE | N29: בנקים | O29: לא | P29: AAA | Q29: S&P מעלות | R29: נייר ערך | S29: ILS | T29: 4.597 | U29: 30/11/2033 | V29: 0.0202 | W29: 0.02582 | X29: החוב לא נחות | Y29: לא | Z29: 13300000 | AA29: 1 | AB29: 101.85 | AD29: 13546.05 | AG29: שווי הוגן | AH29: 0.003728 | AI29: 0.046074509 | AJ29: 0.0046853023
A30: 382 | B30: 382 | C30: בנק לאומי לישראל בע"מ | D30: 520018078 | E30: ח.פ | F30: לאומי התח נדח' סד' 405 | G30: IL0060406209 | H30: ISIN | I30: צמוד למדד המחירים לצרכן | J30: ישראל | K30: ישראל | L30: סחיר | M30: TASE | N30: בנקים | O30: לא | P30: AA- | Q30: S&P מעלות | R30: נייר ערך | S30: ILS | T30: 2.944 | U30: 27/03/2028 | V30: 0.015 | W30: 0.03046 | X30: החוב לא נחות | Y30: לא | Z30: 9000000 | AA30: 1 | AB30: 106.7 | AD30: 9603 | AG30: שווי הוגן | AH30: 0.006411 | AI30: 0.032662917 | AJ30: 0.0033214818
A31: 382 | B31: 382 | C31: בנק לאומי לישראל בע"מ | D31: 520018078 | E31: ח.פ | F31: לאומי התח נדח' סד' 406 | G31: IL0012164237 | H31: ISIN | I31: צמוד למדד המחירים לצרכן | J31: ישראל | K31: ישראל | L31: סחיר | M31: TASE | N31: בנקים | O31: לא | P31: AA- | Q31: S&P מעלות | R31: נייר ערך | S31: ILS | T31: 5.481 | U31: 28/02/2036 | V31: 0.031 | W31: 0.03103 | X31: החוב לא נחות | Y31: לא | Z31: 7200000 | AA31: 1 | AB31: 100.81 | AD31: 7258.32 | AG31: שווי הוגן | AH31: 0.00469 | AI31: 0.0246879 | AJ31: 0.0025105048
A32: 382 | B32: 382 | C32: מבנה נדל"ן (כ.ד) בע"מ | D32: 520024126 | E32: ח.פ | F32: מבני תעש אגח כג | G32: IL0022605450 | H32: ISIN | I32: צמוד למדד המחירים לצרכן | J32: ישראל | K32: ישראל | L32: סחיר | M32: TASE | N32: נדל"ן מניב בישראל | O32: לא | P32: AA | Q32: S&P מעלות | R32: נייר ערך | S32: ILS | T32: 1.409 | U32: 30/09/2026 | V32: 0.024 | W32: 0.026 | X32: החוב לא נחות | Y32: לא | Z32: 3221180.4 | AA32: 1 | AB32: 115.95 | AD32: 3734.959 | AG32: שווי הוגן | AH32: 0.005993 | AI32: 0.012703806 | AJ32: 0.001291846
A33: 382 | B33: 382 | C33: מבנה נדל"ן (כ.ד) בע"מ | D33: 520024126 | E33: ח.פ | F33: מבני תעשיה אגח יז | G33: IL0022604461 | H33: ISIN | I33: צמוד למדד המחירים לצרכן | J33: ישראל | K33: ישראל | L33: סחיר | M33: TASE | N33: נדל"ן מניב בישראל | O33: לא | P33: AA | Q33: S&P מעלות | R33: נייר ערך | S33: ILS | T33: 1.683 | U33: 30/06/2028 | V33: 0.037 | W33: 0.02848 | X33: החוב לא נחות | Y33: לא | Z33: 2600000.5 | AA33: 1 | AB33: 118.43 | AD33: 3079.181 | AG33: שווי הוגן | AH33: 0.008645 | AI33: 0.010473292 | AJ33: 0.0010650257
A34: 382 | B34: 382 | C34: מגדל ביטוח גיוס הון בע"מ | D34: 513230029 | E34: ח.פ | F34: מגדל ביטוח הון אגח יד | G34: IL0012075219 | H34: ISIN | I34: לא צמוד למדד המחירים לצרכן | J34: ישראל | K34: ישראל | L34: סחיר | M34: TASE | N34: ביטוח | O34: לא | P34: A1 | Q34: מידרוג Moodys | R34: נייר ערך | S34: ILS | T34: 6.867 | U34: 01/01/2034 | V34: 0.0607 | W34: 0.05528 | X34: החוב לא נחות | Y34: לא | Z34: 1408500 | AA34: 1 | AB34: 105.72 | AD34: 1489.066 | AG34: שווי הוגן | AH34: 0.003112 | AI34: 0.005064797 | AJ34: 0.00051503762
A35: 382 | B35: 382 | C35: מגדל ביטוח גיוס הון בע"מ | D35: 513230029 | E35: ח.פ | F35: מגדל הון אגח יג 31/12/2032 | G35: IL0012075136 | H35: ISIN | I35: לא צמוד למדד המחירים לצרכן | J35: ישראל | K35: ישראל | L35: סחיר | M35: TASE | N35: ביטוח | O35: לא | P35: A+ | Q35: S&P מעלות | R35: נייר ערך | S35: ILS | T35: 6.247 | U35: 31/12/2032 | V35: 0.0607 | W35: 0.05457 | X35: החוב לא נחות | Y35: לא | Z35: 1408500 | AA35: 1 | AB35: 105.78 | AD35: 1489.911 | AG35: שווי הוגן | AH35: 0.003112 | AI35: 0.0050676715 | AJ35: 0.00051532992
... A60: 382 | B60: 382 | C60: שופר-סל בע"מ | D60: 520022732 | E60: ח.פ | F60: שופרסל אגח ו | G60: IL0077702178 | H60: ISIN | I60: צמוד למדד המחירים לצרכן | J60: ישראל | K60: ישראל | L60: סחיר | M60: TASE | N60: רשתות שיווק | O60: לא | P60: AA | Q60: S&P מעלות | R60: נייר ערך | S60: ILS | T60: 1.941 | U60: 08/10/2028 | V60: 0.043 | W60: 0.02547 | X60: החוב לא נחות | Y60: לא | Z60: 1645835.4 | AA60: 1 | AB60: 121.82 | AD60: 2004.957 | AG60: שווי הוגן | AH60: 0.004035 | AI60: 0.0068195078 | AJ60: 0.00069347361
A61: 382 | B61: 382 | C61: שיכון ובינוי בע"מ | D61: 520036104 | E61: ח.פ | F61: שיכון ובינוי אגח 6 | G61: IL0011297335 | H61: ISIN | I61: צמוד למדד המחירים לצרכן | J61: ישראל | K61: ישראל | L61: סחיר | M61: TASE | N61: בנייה | O61: לא | P61: A | Q61: S&P מעלות | R61: נייר ערך | S61: ILS | T61: 0.003 | U61: 01/04/2025 | V61: 0.0434 | W61: 0.29883 | X61: החוב לא נחות | Y61: לא | Z61: 0 | AA61: 1 | AB61: 0 | AC61: 2050.421 | AD61: 2050.421 | AG61: שווי הוגן | AH61: 0 | AI61: 0.0069741464 | AJ61: 0.00070919875
A62: 382 | B62: 382 | C62: שיכון ובינוי אנרגיה בע"מ | D62: 510459928 | E62: ח.פ | F62: שיכון ובינוי אנרגיה אגח א' | G62: IL0011985715 | H62: ISIN | I62: לא צמוד למדד המחירים לצרכן | J62: ישראל | K62: ישראל | L62: סחיר | M62: TASE | N62: אנרגיה | O62: לא | P62: A3 | Q62: מידרוג Moodys | R62: נייר ערך | S62: ILS | T62: 3.958 | U62: 30/06/2034 | V62: 0.0677 | W62: 0.05684 | X62: החוב לא נחות | Y62: לא | Z62: 4900000 | AA62: 1 | AB62: 106.28 | AD62: 5207.72 | AG62: שווי הוגן | AH62: 0.006533 | AI62: 0.017713144 | AJ62: 0.0018012441
A63: 382 | B63: 382 | C63: תומר תמלוגי אנרגיה (2012) בע"מ | D63: 514837111 | E63: ח.פ | F63: תומר אנרגיה אגח א | G63: IL0011474793 | H63: ISIN | I63: צמוד למט"ח | J63: ישראל | K63: ישראל | L63: סחיר | M63: TASE | N63: חיפושי נפט וגז | O63: לא | P63: Aa3 | Q63: מידרוג Moodys | R63: נייר ערך | S63: ILS | T63: 2.477 | U63: 30/08/2028 | V63: 0.0548 | W63: 0.06529 | X63: החוב לא נחות | Y63: לא | Z63: 925100.04 | AA63: 1 | AB63: 102.76 | AD63: 950.633 | AG63: שווי הוגן | AH63: 0.003444 | AI63: 0.0032334104 | AJ63: 0.00032880449
A64: 382 | B64: 382 | C64: תמר פטרוליום בעמ | D64: 515334662 | E64: ח.פ | F64: תמר פטרוליום אגח א | G64: IL0011413320 | H64: ISIN | I64: צמוד למט"ח | J64: ישראל | K64: ישראל | L64: סחיר | M64: TASE | N64: חיפושי נפט וגז | O64: לא | P64: A1 | Q64: מידרוג Moodys | R64: נייר ערך | S64: ILS | T64: 2.672 | U64: 30/08/2028 | V64: 0.0469 | W64: 0.06766 | X64: החוב לא נחות | Y64: לא | Z64: 7076100 | AA64: 1 | AB64: 101 | AD64: 7146.861 | AG64: שווי הוגן | AH64: 0.005237 | AI64: 0.024308792 | AJ64: 0.0024719534
A65: 382 | B65: 382 | C65: בנק הפועלים בע"מ | D65: 520000118 | E65: ח.פ | F65: HAPOAL 3.255 01/21/32 | G65: IL0066204707 | H65: ISIN | I65: צמוד למט"ח | J65: ישראל | K65: ישראל | L65: סחיר | M65: TASE | N65: Banks | O65: לא | P65: BBB- | Q65: S&P | R65: נייר ערך | S65: USD | T65: 1.748 | U65: 21/01/2032 | V65: 0.03255 | W65: 0.06056 | X65: החוב לא נחות | Y65: לא | Z65: 2000000 | AA65: 3.718 | AB65: 96.148 | AD65: 7149.556 | AG65: שווי הוגן | AH65: 0.002 | AI65: 0.024317958 | AJ65: 0.0024728855
A66: 382 | B66: 382 | C66: בנק לאומי לישראל בע"מ | D66: 520018078 | E66: ח.פ | F66: LUMIIT 3.275 01/29/3 | G66: IL0060404899 | H66: ISIN | I66: צמוד למט"ח | J66: ישראל | K66: ישראל | L66: סחיר | M66: TASE | N66: Banks | O66: לא | P66: BBB- | Q66: S&P | R66: נייר ערך | S66: USD | T66: 5.09 | U66: 29/01/2031 | V66: 0.03275 | W66: 0.05732 | X66: החוב לא נחות | Y66: לא | Z66: 1900000 | AA66: 3.718 | AB66: 98.468 | AD66: 6955.985 | AG66: שווי הוגן | AH66: 0.002533 | AI66: 0.023659562 | AJ66: 0.0024059334
A67: 382 | B67: 1404 | C67: איירפורט סיטי בע"מ | D67: 511659401 | E67: ח.פ | F67: איירפורט אגח ה | G67: IL0011334872 | H67: ISIN | I67: צמוד למדד המחירים לצרכן | J67: ישראל | K67: ישראל | L67: סחיר | M67: TASE | N67: נדל"ן מניב בישראל | O67: לא | P67: AA | Q67: S&P מעלות | R67: נייר ערך | S67: ILS | T67: 2.267 | U67: 28/02/2029 | V67: 0.0234 | W67: 0.02797 | X67: החוב לא נחות | Y67: לא | Z67: 50000 | AA67: 1 | AB67: 114.39 | AD67: 57.195 | AG67: שווי הוגן | AH67: 3.1e-05 | AI67: 0.013602703 | AJ67: 0.0021392751
A68: 382 | B68: 1404 | C68: איירפורט סיטי בע"מ | D68: 511659401 | E68: ח.פ | F68: איירפורט אגח י | G68: IL0011959819 | H68: ISIN | I68: לא צמוד למדד המחירים לצרכן | J68: ישראל | K68: ישראל | L68: סחיר | M68: TASE | N68: נדל"ן מניב בישראל | O68: לא | P68: AA | Q68: S&P מעלות | R68: נייר ערך | S68: ILS | T68: 2.256 | U68: 30/04/2029 | V68: 0.05 | W68: 0.05058 | X68: החוב לא נחות | Y68: לא | Z68: 80000 | AA68: 1 | AB68: 102.1 | AD68: 81.68 | AG68: שווי הוגן | AH68: 0.0002 | AI68: 0.019425977 | AJ68: 0.0030550921
A69: 382 | B69: 1404 | C69: אלביט מערכות בע"מ | D69: 520043027 | E69: ח.פ | F69: אלביט מערכות ב' 1.08% | G69: IL0011782351 | H69: ISIN | I69: לא צמוד למדד המחירים לצרכן | J69: ישראל | K69: ישראל | L69: סחיר | M69: TASE | N69: ביטחוניות | O69: לא | P69: AA | Q69: S&P מעלות | R69: נייר ערך | S69: ILS | T69: 2.141 | U69: 01/07/2029 | V69: 0.0108 | W69: 0.04714 | X69: החוב לא נחות | Y69: לא | Z69: 38541.67 | AA69: 1 | AB69: 92.86 | AD69: 35.79 | AG69: שווי הוגן | AH69: 4.1e-05 | AI69: 0.0085118969 | AJ69: 0.0013386523
A70: 382 | B70: 1404 | C70: אלוני-חץ נכסים והשקעות בע"מ | D70: 520038506 | E70: ח.פ | F70: אלוני חץ אגח ט | G70: IL0039003541 | H70: ISIN | I70: לא צמוד למדד המחירים לצרכן | J70: ישראל | K70: ישראל | L70: סחיר | M70: TASE | N70: נדל"ן מניב בישראל | O70: לא | P70: AA- | Q70: S&P מעלות | R70: נייר ערך | S70: ILS | T70: 1.392 | U70: 28/02/2027 | V70: 0.0385 | W70: 0.05029 | X70: החוב לא נחות | Y70: לא | Z70: 47357.15 | AA70: 1 | AB70: 98.76 | AD70: 46.77 | AG70: שווי הוגן | AH70: 0.000152 | AI70: 0.011123303 | AJ70: 0.001749344
A71: 382 | B71: 1404 | C71: אלוני-חץ נכסים והשקעות בע"מ | D71: 520038506 | E71: ח.פ | F71: אלוני חץ אגח טו | G71: IL0011894149 | H71: ISIN | I71: צמוד למדד המחירים לצרכן | J71: ישראל | K71: ישראל | L71: סחיר | M71: TASE | N71: נדל"ן מניב בישראל | O71: לא | P71: AA- | Q71: S&P מעלות | R71: נייר ערך | S71: ILS | T71: 6.663 | U71: 01/03/2037 | V71: 0.0256 | W71: 0.03503 | X71: החוב לא נחות | Y71: לא | Z71: 30000 | AA71: 1 | AB71: 101.59 | AD71: 30.477 | AG71: שווי הוגן | AH71: 2.9e-05 | AI71: 0.0072483534 | AJ71: 0.0011399369
A72: 382 | B72: 1404 | C72: אלוני-חץ נכסים והשקעות בע"מ | D72: 520038506 | E72: ח.פ | F72: אלוני חץ אגח יב | G72: IL0039004952 | H72: ISIN | I72: לא צמוד למדד המחירים לצרכן | J72: ישראל | K72: ישראל | L72: סחיר | M72: TASE | N72: נדל"ן מניב בישראל | O72: לא | P72: AA- | Q72: S&P מעלות | R72: נייר ערך | S72: ILS | T72: 3.951 | U72: 28/02/2031 | V72: 0.0241 | W72: 0.05291 | X72: החוב לא נחות | Y72: לא | Z72: 84240 | AA72: 1 | AB72: 89.75 | AD72: 75.605 | AG72: שווי הוגן | AH72: 4.1e-05 | AI72: 0.017981253 | AJ72: 0.0028278827
...

Sheet מניות מבכ ויהש
A1: מספר קופה/קרן/ח.פ. עבור חברת ביטוח | B1: מספר מסלול | C1: שם מנפיק | D1: מספר מנפיק | E1: סוג מספר מזהה מנפיק | F1: שם נייר ערך | G1: מספר נייר ערך | H1: סוג מספר נייר ערך | I1: מאפיין עיקרי | J1: ישראל/חו"ל | K1: מדינה לפי חשיפה כלכלית | L1: סטאטוס סחירות | M1: זירת מסחר | N1: ענף מסחר | O1: בעל עניין/צד קשור | P1: מטבע פעילות | Q1: ערך נקוב (יחידות) | R1: שער חליפין | S1: שער נייר הערך | T1: סכום לקבל (במטבע הפעילות) | U1: שווי הוגן (באלפי ש"ח) | V1: שיעור מערך נקוב מונפק | W1: שיעור מנכסי אפיק ההשקעה | X1: שיעור מסך נכסי ההשקעה
A2: 382 | B2: 382 | C2: אלביט מערכות בע"מ | D2: 520043027 | E2: ח.פ | F2: אלביט מערכות | G2: IL0010811243 | H2: ISIN | I2: מניות | J2: ישראל | K2: ישראל | L2: סחיר | M2: TASE | N2: ביטחוניות | O2: לא | P2: ILS | Q2: 7450.37 | R2: 1 | S2: 142500 | U2: 10616.777 | V2: 0.000167 | W2: 0.02599331 | X2: 0.0036721266
A3: 382 | B3: 382 | C3: אלוני-חץ נכסים והשקעות בע"מ | D3: 520038506 | E3: ח.פ | F3: אלוני חץ | G3: IL0003900136 | H3: ISIN | I3: מניות | J3: ישראל | K3: ישראל | L3: סחיר | M3: TASE | N3: נדל"ן מניב בישראל | O3: לא | P3: ILS | Q3: 267700 | R3: 1 | S3: 2900 | T3: 64.184 | U3: 7827.484 | V3: 0.001244 | W3: 0.019164216 | X3: 0.0027073669
A4: 382 | B4: 382 | C4: אמות השקעות בע"מ | D4: 520026683 | E4: ח.פ | F4: אמות | G4: IL0010972789 | H4: ISIN | I4: מניות | J4: ישראל | K4: ישראל | L4: סחיר | M4: TASE | N4: נדל"ן מניב בישראל | O4: לא | P4: ILS | Q4: 396470 | R4: 1 | S4: 1796 | U4: 7120.601 | V4: 0.000841 | W4: 0.017433538 | X4: 0.0024628707
A5: 382 | B5: 382 | C5: אנלייט אנרגיה מתחדשת בע"מ | D5: 520041146 | E5: ח.פ | F5: אנלייט אנרגיה | G5: IL0007200111 | H5: ISIN | I5: מניות | J5: ישראל | K5: ארה"ב | L5: סחיר | M5: TASE | N5: אנרגיה מתחדשת | O5: לא | P5: ILS | Q5: 138367.9 | R5: 1 | S5: 5941 | U5: 8220.437 | V5: 0.001162 | W5: 0.020126292 | X5: 0.0028432814
A6: 382 | B6: 382 | C6: אנרג'יקס אנרגיות מתחדשות בע"מ | D6: 513901371 | E6: ח.פ | F6: אנרג'יקס | G6: IL0011233553 | H6: ISIN | I6: מניות | J6: ישראל | K6: ישראל | L6: סחיר | M6: TASE | N6: אנרגיה מתחדשת | O6: לא | P6: ILS | Q6: 885500 | R6: 1 | S6: 1013 | T6: 88.461 | U6: 9058.576 | V6: 0.001611 | W6: 0.022178329 | X6: 0.0031331768
A7: 382 | B7: 382 | C7: בזק החברה הישראלית לתקשורת בע"מ | D7: 520031931 | E7: ח.פ | F7: בזק | G7: IL0002300114 | H7: ISIN | I7: מניות | J7: ישראל | K7: ישראל | L7: סחיר | M7: TASE | N7: תקשורת ומדיה | O7: לא | P7: ILS | Q7: 2201567 | R7: 1 | S7: 546.6 | U7: 12033.765 | V7: 0.000795 | W7: 0.029462555 | X7: 0.0041622338
A8: 382 | B8: 382 | C8: בית וגג יזמות ונדל"ן בע"מ | D8: 516501640 | E8: ח.פ | F8: בית וגג | G8: IL0011853624 | H8: ISIN | I8: מניות | J8: ישראל | K8: ישראל | L8: סחיר | M8: TASE | N8: בנייה | O8: לא | P8: ILS | Q8: 285800 | R8: 1 | S8: 809.9 | U8: 2314.694 | V8: 0.005194 | W8: 0.0056671212 | X8: 0.00080060549
A9: 382 | B9: 382 | C9: אחים דוניץ בע"מ | D9: 520038605 | E9: ח.פ | F9: דוניץ | G9: IL0004000100 | H9: ISIN | I9: מניות | J9: ישראל | K9: ישראל | L9: סחיר | M9: TASE | N9: בנייה | O9: לא | P9: ILS | Q9: 5776 | R9: 1 | S9: 20100 | U9: 1160.976 | V9: 0.00064 | W9: 0.0028424453 | X9: 0.00040155791
A10: 382 | B10: 382 | C10: בנק דיסקונט לישראל בע"מ | D10: 520007030 | E10: ח.פ | F10: דיסקונט | G10: IL0006912120 | H10: ISIN | I10: מניות | J10: ישראל | K10: ישראל | L10: סחיר | M10: TASE | N10: בנקים | O10: לא | P10: ILS | Q10: 1067459.8 | R10: 1 | S10: 2572 | T10: 272.577 | U10: 27727.643 | V10: 0.000863 | W10: 0.067886252 | X10: 0.009590426
A11: 382 | B11: 382 | C11: י.ח.דמרי בניה ופיתוח בע"מ | D11: 511399388 | E11: ח.פ | F11: דמרי | G11: IL0010903156 | H11: ISIN | I11: מניות | J11: ישראל | K11: ישראל | L11: סחיר | M11: TASE | N11: בנייה | O11: לא | P11: ILS | Q11: 31550 | R11: 1 | S11: 30010 | U11: 9468.155 | V11: 0.00151 | W11: 0.02318111 | X11: 0.0032748416
A12: 382 | B12: 382 | C12: הפניקס אחזקות בע"מ | D12: 520017450 | E12: ח.פ | F12: הפניקס | G12: IL0007670123 | H12: ISIN | I12: מניות | J12: ישראל | K12: ישראל | L12: סחיר | M12: TASE | N12: ביטוח | O12: לא | P12: ILS | Q12: 132998 | R12: 1 | S12: 6881 | U12: 9151.592 | V12: 0.000507 | W12: 0.022406063 | X12: 0.0031653491
A13: 382 | B13: 382 | C13: טבע תעשיות פרמצבטיות בע"מ | D13: 520013954 | E13: ח.פ | F13: טבע | G13: IL0006290147 | H13: ISIN | I13: מניות | J13: ישראל | K13: ארה"ב | L13: סחיר | M13: TASE | N13: פארמה | O13: לא | P13: ILS | Q13: 220830 | R13: 1 | S13: 5587 | U13: 12337.772 | V13: 0.000176 | W13: 0.030206863 | X13: 0.0042673836
A14: 382 | B14: 382 | C14: טרמינל איקס אונליין בע"מ | D14: 515722536 | E14: ח.פ | F14: טרמינל איקס אונליין בעמ | G14: IL0011787145 | H14: ISIN | I14: מניות | J14: ישראל | K14: ישראל | L14: סחיר | M14: TASE | N14: רשתות שיווק | O14: לא | P14: ILS | Q14: 170543 | R14: 1 | S14: 443.7 | U14: 756.699 | V14: 0.001345 | W14: 0.001852645 | X14: 0.00026172684
A15: 382 | B15: 382 | C15: ישראל קנדה (ט.ר) בעמ | D15: 520039298 | E15: ח.פ | F15: ישראל קנדה | G15: IL0004340191 | H15: ISIN | I15: מניות | J15: ישראל | K15: ישראל | L15: סחיר | M15: TASE | N15: בנייה | O15: לא | P15: ILS | Q15: 356000 | R15: 1 | S15: 1157 | U15: 4118.92 | V15: 0.001076 | W15: 0.01008445 | X15: 0.0014246504
A16: 382 | B16: 382 | C16: כלל החזקות עסקי ביטוח בע"מ | D16: 520036120 | E16: ח.פ | F16: כלל ביטוח | G16: IL0002240146 | H16: ISIN | I16: מניות | J16: ישראל | K16: ישראל | L16: סחיר | M16: TASE | N16: ביטוח | O16: לא | P16: ILS | Q16: 98550 | R16: 1 | S16: 9094 | U16: 8962.137 | V16: 0.00124 | W16: 0.021942214 | X16: 0.0030998203
A17: 382 | B17: 382 | C17: בנק לאומי לישראל בע"מ | D17: 520018078 | E17: ח.פ | F17: לאומי | G17: IL0006046119 | H17: ISIN | I17: מניות | J17: ישראל | K17: ישראל | L17: סחיר | M17: TASE | N17: בנקים | O17: לא | P17: ILS | Q17: 840606 | R17: 1 | S17: 4982 | U17: 41878.991 | V17: 0.00052 | W17: 0.10253334 | X17: 0.014485088
A18: 382 | B18: 382 | C18: י.ד. מור השקעות בע"מ | D18: 513834606 | E18: ח.פ | F18: מור השקעות | G18: IL0011414641 | H18: ISIN | I18: מניות | J18: ישראל | K18: ישראל | L18: סחיר | M18: TASE | N18: שירותים פיננסיים | O18: לא | P18: ILS | Q18: 350000 | R18: 1 | S18: 1483 | U18: 5190.5 | V18: 0.004904 | W18: 0.012708025 | X18: 0.001795288
A19: 382 | B19: 382 | C19: בנק מזרחי טפחות בע"מ | D19: 520000522 | E19: ח.פ | F19: מזרחי טפחות | G19: IL0006954379 | H19: ISIN | I19: מניות | J19: ישראל | K19: ישראל | L19: סחיר | M19: TASE | N19: בנקים | O19: לא | P19: ILS | Q19: 76569 | R19: 1 | S19: 16650 | U19: 12748.738 | V19: 0.000295 | W19: 0.031213041 | X19: 0.0044095285
A20: 382 | B20: 382 | C20: מליסרון בע"מ | D20: 520037789 | E20: ח.פ | F20: מליסרון | G20: IL0003230146 | H20: ISIN | I20: מניות | J20: ישראל | K20: ישראל | L20: סחיר | M20: TASE | N20: נדל"ן מניב בישראל | O20: לא | P20: ILS | Q20: 26850 | R20: 1 | S20: 28940 | T20: 50.733 | U20: 7821.123 | V20: 0.000564 | W20: 0.019148643 | X20: 0.002705167
A21: 382 | B21: 382 | C21: מניבים קרן הריט החדשה בע"מ | D21: 515327120 | E21: ח.פ | F21: מניבים ריט | G21: IL0011405730 | H21: ISIN | I21: מניות | J21: ישראל | K21: ישראל | L21: סחיר | M21: TASE | N21: נדל"ן מניב בישראל | O21: לא | P21: ILS | Q21: 1349479 | R21: 1 | S21: 184 | U21: 2483.041 | V21: 0.001776 | W21: 0.0060792896 | X21: 0.00085883334
A22: 382 | B22: 382 | C22: נאוויטס פטרוליום, שותפות מוגבלת | D22: 550263107 | E22: מספר שותפות | F22: נאוויטס פט יהש | G22: IL0011419699 | H22: ISIN | I22: מניות | J22: ישראל | K22: ארה"ב | L22: סחיר | M22: TASE | N22: חיפושי נפט וגז | O22: לא | P22: ILS | Q22: 85130 | R22: 1 | S22: 8700 | U22: 7406.31 | V22: 0.000835 | W22: 0.018133046 | X22: 0.0025616915
A23: 382 | B23: 382 | C23: ניו-מד אנרג'י- שותפות מוגבלת | D23: 550013098 | E23: מספר שותפות | F23: ניו-מד אנרג'י יהש | G23: IL0004750209 | H23: ISIN | I23: מניות | J23: ישראל | K23: ישראל | L23: סחיר | M23: TASE | N23: חיפושי נפט וגז | O23: לא | P23: ILS | Q23: 200000 | R23: 1 | S23: 1249 | T23: 37.842 | U23: 2535.842 | V23: 0.00017 | W23: 0.0062085628 | X23: 0.00087709602
A24: 382 | B24: 382 | C24: נייס מערכות בע"מ | D24: 520036872 | E24: ח.פ | F24: נייס | G24: IL0002730112 | H24: ISIN | I24: מניות | J24: ישראל | K24: ארה"ב | L24: סחיר | M24: TASE | N24: תוכנה ואינטרנט | O24: לא | P24: ILS | Q24: 17198 | R24: 1 | S24: 56600 | U24: 9734.068 | V24: 0.00023 | W24: 0.023832152 | X24: 0.0033668155
A25: 382 | B25: 382 | C25: נקסט ויז'ן | D25: 514259019 | E25: ח.פ | F25: נקסט ויז'ן | G25: IL0011765935 | H25: ISIN | I25: מניות | J25: ישראל | K25: ישראל | L25: סחיר | M25: TASE | N25: אלקטרוניקה ואופטיקה | O25: לא | P25: ILS | Q25: 106000 | R25: 1 | S25: 8478 | U25: 8986.68 | V25: 0.001318 | W25: 0.022002304 | X25: 0.0031083092
A26: 382 | B26: 382 | C26: קבוצת עזריאלי בע"מ (לשעבר קנית מימון) | D26: 510960719 | E26: ח.פ | F26: עזריאלי קבוצה | G26: IL0011194789 | H26: ISIN | I26: מניות | J26: ישראל | K26: ישראל | L26: סחיר | M26: TASE | N26: נדל"ן מניב בישראל | O26: לא | P26: ILS | Q26: 29250 | R26: 1 | S26: 24920 | U26: 7289.1 | V26: 0.000241 | W26: 0.017846078 | X26: 0.002521151
A27: 382 | B27: 382 | C27: בנק הפועלים בע"מ | D27: 520000118 | E27: ח.פ | F27: פועלים | G27: IL0006625771 | H27: ISIN | I27: מניות | J27: ישראל | K27: ישראל | L27: סחיר | M27: TASE | N27: בנקים | O27: לא | P27: ILS | Q27: 692368 | R27: 1 | S27: 5008 | U27: 34673.789 | V27: 0.000518 | W27: 0.084892668 | X27: 0.011992956
A28: 382 | B28: 382 | C28: פוקס-ויזל בע"מ | D28: 512157603 | E28: ח.פ | F28: פוקס- ויזל | G28: IL0010870223 | H28: ISIN | I28: מניות | J28: ישראל | K28: ישראל | L28: סחיר | M28: TASE | N28: רשתות שיווק | O28: לא | P28: ILS | Q28: 14950 | R28: 1 | S28: 30240 | U28: 4520.88 | V28: 0.00108 | W28: 0.011068579 | X28: 0.0015636801
A29: 382 | B29: 382 | C29: פורמולה מערכות (1985)בע"מ | D29: 520036690 | E29: ח.פ | F29: פורמולה מערכות | G29: IL0002560162 | H29: ISIN | I29: מניות | J29: ישראל | K29: ישראל | L29: סחיר | M29: TASE | N29: שירותי מידע | O29: לא | P29: ILS | Q29: 16800 | R29: 1 | S29: 32170 | U29: 5404.56 | V29: 0.001057 | W29: 0.013232114 | X29: 0.001869327
A30: 382 | B30: 382 | C30: קבוצת אקרשטיין בע"מ | D30: 512714494 | E30: ח.פ | F30: קבוצת אקרשטיין | G30: IL0011762056 | H30: ISIN | I30: מניות | J30: ישראל | K30: ישראל | L30: סחיר | M30: TASE | N30: מתכת ומוצרי בניה | O30: לא | P30: ILS | Q30: 612206 | R30: 1 | S30: 682.4 | T30: 106.157 | U30: 4283.851 | V30: 0.002125 | W30: 0.010488254 | X30: 0.0014816966
A31: 382 | B31: 382 | C31: שופר-סל בע"מ | D31: 520022732 | E31: ח.פ | F31: שופרסל | G31: IL0007770378 | H31: ISIN | I31: מניות | J31: ישראל | K31: ישראל | L31: סחיר | M31: TASE | N31: רשתות שיווק | O31: לא | P31: ILS | Q31: 107000 | R31: 1 | S31: 3511 | U31: 3756.77 | V31: 0.000389 | W31: 0.0091977899 | X31: 0.0012993901
A32: 382 | B32: 382 | C32: Advanced Micro Devices inc | D32: R2I72C950HOYXII45366 | E32: LEI | F32: Advanced Micro Devices | G32: US0079031078 | H32: ISIN | I32: מניות | J32: חו"ל | K32: אסיה | L32: סחיר | M32: NASDAQ | N32: Semiconductors & Semiconductor Equipment | O32: לא | P32: USD | Q32: 9225 | R32: 3.718 | S32: 10274 | U32: 3523.833 | V32: 6e-06 | W32: 0.0086274847 | X32: 0.0012188219
A33: 382 | B33: 382 | C33: ALPHABET INC | D33: 5493006MHB84DD0ZWV18 | E33: LEI | F33: ALPHABET INC-A | G33: US02079K3059 | H33: ISIN | I33: מניות | J33: חו"ל | K33: ארה"ב | L33: סחיר | M33: NASDAQ | N33: Software | O33: לא | P33: USD | Q33: 23200 | R33: 3.718 | S33: 15464 | U33: 13338.875 | V33: 4e-06 | W33: 0.032657887 | X33: 0.0046136448
A34: 382 | B34: 382 | C34: amazon.com | D34: ZXTILKJKG63JELOEG630 | E34: LEI | F34: Amazon inc | G34: US0231351067 | H34: ISIN | I34: מניות | J34: חו"ל | K34: ארה"ב | L34: סחיר | M34: NASDAQ | N34: Commercial Services & Supplies | O34: לא | P34: USD | Q34: 9950 | R34: 3.718 | S34: 19026 | U34: 7038.497 | V34: 1e-06 | W34: 0.017232522 | X34: 0.0024344727
A35: 382 | B35: 382 | C35: ASML HOLDING NV-NY | D35: 724500Y6DUVHQD6OXN27 | E35: LEI | F35: asml holding nv-ny | G35: USN070592100 | H35: ISIN | I35: מניות | J35: חו"ל | K35: ארה"ב | L35: סחיר | M35: NASDAQ | N35: Semiconductors & Semiconductor Equipment | O35: לא | P35: USD | Q35: 4677 | R35: 3.718 | S35: 66263 | U35: 11522.53 | V35: 1.2e-05 | W35: 0.028210886 | X35: 0.003985408
A36: 382 | B36: 382 | C36: Broadcom Inc | D36: 549300WV6GIDOZJTV909 | E36: LEI | F36: BROADCOM INC | G36: US11135F1012 | H36: ISIN | I36: מניות | J36: חו"ל | K36: ארה"ב | L36: סחיר | M36: NASDAQ | N36: Semiconductors & Semiconductor Equipment | O36: לא | P36: USD | Q36: 7750 | R36: 3.718 | S36: 16743 | T36: 4.572 | U36: 4841.412 | V36: 1.7e-05 | W36: 0.011853346 | X36: 0.0016745457
A37: 382 | B37: 382 | C37: קמטק בע"מ | D37: 511235434 | E37: ח.פ | F37: Camtek Ltd | G37: IL0010952641 | H37: ISIN | I37: מניות | J37: חו"ל | K37: גלובלי | L37: סחיר | M37: NASDAQ | N37: Semiconductors & Semiconductor Equipment | O37: לא | P37: USD | Q37: 28700 | R37: 3.718 | S37: 5863 | U37: 6256.208 | V37: 0.000663 | W37: 0.015317224 | X37: 0.0021638947
A38: 382 | B38: 382 | C38: COSTCO WHOLESAL | D38: 29DX7H14B9S6O3FD6V18 | E38: LEI | F38: COSTCO WHOLESALE CORP | G38: US22160K1051 | H38: ISIN | I38: מניות | J38: חו"ל | K38: ארה"ב | L38: סחיר | M38: NASDAQ | N38: Food & Staples Retailing Consumer Staples Distribution & Retail | O38: לא | P38: USD | Q38: 2180 | R38: 3.718 | S38: 94578 | U38: 7665.774 | V38: 5e-06 | W38: 0.018768298 | X38: 0.0026514348
A39: 382 | B39: 382 | C39: פייבר אינטרנשיונל בע"מ | D39: 514440874 | E39: ח.פ | F39: FIVERR INTERNATI | G39: IL0011582033 | H39: ISIN | I39: מניות | J39: חו"ל | K39: ארה"ב | L39: סחיר | M39: NYSE | N39: Commercial Services & Supplies | O39: לא | P39: USD | Q39: 3797 | R39: 3.718 | S39: 2368 | U39: 334.296 | V39: 9.8e-05 | W39: 0.00081846584 | X39: 0.0001156263
A40: 382 | B40: 382 | C40: JD.com Inc | D40: 549300HVTWB0GJZ16V92 | E40: LEI | F40: JD.COM INC-CL A | G40: KYG8208B1014 | H40: ISIN | I40: מניות | J40: חו"ל | K40: סין | L40: סחיר | M40: HKSE | N40: Textiles, Apparel & Luxury Goods | O40: לא | P40: HKD | Q40: 1964 | R40: 0.4776 | S40: 16080 | U40: 150.831 | V40: 1e-06 | W40: 0.0003692842 | X40: 5.2169514e-05
...

Sheet קרנות סל
A1: מספר קופה/קרן/ח.פ. עבור חברת ביטוח | B1: מספר מסלול | C1: שם מנפיק | D1: מספר מנפיק | E1: סוג מספר מזהה מנפיק | F1: שם נייר ערך | G1: מספר נייר ערך | H1: סוג מספר נייר ערך | I1: מאפיין עיקרי | J1: ישראל/חו"ל | K1: מדינה לפי חשיפה כלכלית | L1: זירת מסחר | M1: סיווג הקרן | N1: בעל עניין/צד קשור | O1: מטבע פעילות | P1: ערך נקוב (יחידות) | Q1: שער חליפין | R1: שער נייר הערך | S1: סכום לקבל (במטבע הפעילות) | T1: שווי הוגן (באלפי ש"ח) | U1: שיעור מערך נקוב מונפק | V1: שיעור מנכסי אפיק ההשקעה | W1: שיעור מסך נכסי ההשקעה
A2: 382 | B2: 382 | C2: מגדל קרנות נאמנות בע"מ | D2: 511303661 | E2: ח.פ | F2: MTF סל Nasdaq 100 (4D) | G2: IL0011813875 | H2: ISIN | I2: עוקב אחר מדדי מניות בחו"ל | J2: ישראל | K2: ארה"ב | L2: TASE | M2: מניות בחו"ל חשופות מט"ח | N2: לא | O2: ILS | P2: 92333.33 | Q2: 1 | R2: 9860 | T2: 9104.066 | U2: 0.009233 | V2: 0.010832848 | W2: 0.0031489108
A3: 382 | B3: 382 | C3: מגדל קרנות נאמנות בע"מ | D3: 511303661 | E3: ח.פ | F3: MTF סל תא 125 | G3: IL0011502833 | H3: ISIN | I3: עוקב אחר מדדי מניות בישראל | J3: ישראל | K3: ישראל | L3: TASE | M3: מניות בישראל | N3: לא | O3: ILS | P3: 789763 | Q3: 1 | R3: 3763 | T3: 29718.782 | U3: 0.009291 | V3: 0.035362115 | W3: 0.01027912
A4: 382 | B4: 382 | C4: מגדל קרנות נאמנות בע"מ | D4: 511303661 | E4: ח.פ | F4: MTF סל תא 90 | G4: IL0011502593 | H4: ISIN | I4: עוקב אחר מדדי מניות בישראל | J4: ישראל | K4: ישראל | L4: TASE | M4: מניות בישראל | N4: לא | O4: ILS | P4: 625000 | Q4: 1 | R4: 3593 | T4: 22456.25 | U4: 0.010417 | V4: 0.026720493 | W4: 0.0077671587
A5: 382 | B5: 382 | C5: הראל קרנות נאמנות בע"מ | D5: 511776783 | E5: ח.פ | F5: הראל סל תא 90 | G5: IL0011489312 | H5: ISIN | I5: עוקב אחר מדדי מניות בישראל | J5: ישראל | K5: ישראל | L5: TASE | M5: מניות בישראל | N5: לא | O5: ILS | P5: 398500 | Q5: 1 | R5: 2395 | T5: 9544.075 | U5: 0.001593 | V5: 0.01135641 | W5: 0.0033011008
A6: 382 | B6: 382 | C6: הראל קרנות נאמנות בע"מ | D6: 511776783 | E6: ח.פ | F6: הראל סל תל בונד שקלי | G6: IL0011505232 | H6: ISIN | I6: עוקב אחר מדדים אחרים בישראל | J6: ישראל | K6: ישראל | L6: TASE | M6: אג"ח בישראל - חברות והמרה | N6: לא | O6: ILS | P6: 7220000 | Q6: 1 | R6: 404.49 | T6: 29204.178 | U6: 0.026452 | V6: 0.034749793 | W6: 0.010101129
A7: 382 | B7: 382 | C7: הראל קרנות נאמנות בע"מ | D7: 511776783 | E7: ח.פ | F7: הראל קרן סל תא 125 | G7: IL0011488991 | H7: ISIN | I7: עוקב אחר מדדי מניות בישראל | J7: ישראל | K7: ישראל | L7: TASE | M7: מניות בישראל | N7: לא | O7: ILS | P7: 477000 | Q7: 1 | R7: 2397 | T7: 11433.69 | U7: 0.00231 | V7: 0.013604847 | W7: 0.0039546801
A8: 382 | B8: 382 | C8: מור ניהול קרנות נאמנות בע"מ | D8: 514884485 | E8: ח.פ | F8: מור סל (A4) ת"א -125 | G8: IL0011961534 | H8: ISIN | I8: עוקב אחר מדדי מניות בישראל | J8: ישראל | K8: ישראל | L8: TASE | M8: מניות בישראל | N8: לא | O8: ILS | P8: 411000 | Q8: 1 | R8: 6632 | T8: 27257.52 | U8: 0.03288 | V8: 0.032433482 | W8: 0.00942782
A9: 382 | B9: 382 | C9: קסם קרנות נאמנות בע"מ | D9: 510938608 | E9: ח.פ | F9: קסם 50 EURO PR STOXX | G9: IL0011464067 | H9: ISIN | I9: עוקב אחר מדדי מניות בחו"ל | J9: ישראל | K9: אירופה | L9: TASE | M9: מניות בחו"ל חשופות מט"ח | N9: לא | O9: ILS | P9: 40000 | Q9: 1 | R9: 22720 | T9: 9088 | U9: 0.014795 | V9: 0.010813731 | W9: 0.0031433538
A10: 382 | B10: 382 | C10: קסם קרנות נאמנות בע"מ | D10: 510938608 | E10: ח.פ | F10: קסם S&P 500 (4D) ETF | G10: IL0011464711 | H10: ISIN | I10: עוקב אחר מדדי מניות בחו"ל | J10: ישראל | K10: ארה"ב | L10: TASE | M10: מניות בחו"ל חשופות מט"ח | N10: לא | O10: ILS | P10: 221380 | Q10: 1 | R10: 22550 | T10: 49921.19 | U10: 0.007541 | V10: 0.059400782 | W10: 0.017266721
A11: 382 | B11: 382 | C11: קסם קרנות נאמנות בע"מ | D11: 510938608 | E11: ח.פ | F11: קסם קרן סל תא 125 | G11: IL0011463564 | H11: ISIN | I11: עוקב אחר מדדי מניות בישראל | J11: ישראל | K11: ישראל | L11: TASE | M11: מניות בישראל | N11: לא | O11: ILS | P11: 42250 | Q11: 1 | R11: 23890 | T11: 10093.525 | U11: 0.001193 | V11: 0.012010196 | W11: 0.0034911443
A12: 382 | B12: 382 | C12: קסם קרנות נאמנות בע"מ | D12: 510938608 | E12: ח.פ | F12: קסם תא 90 | G12: IL0011463317 | H12: ISIN | I12: עוקב אחר מדדי מניות בישראל | J12: ישראל | K12: ישראל | L12: TASE | M12: מניות בישראל | N12: לא | O12: ILS | P12: 61012 | Q12: 1 | R12: 22890 | T12: 13965.647 | U12: 0.002019 | V12: 0.0166176 | W12: 0.0048304323
A13: 382 | B13: 382 | C13: קסם קרנות נאמנות בע"מ | D13: 510938608 | E13: ח.פ | F13: קסם תא נדלן | G13: IL0011465478 | H13: ISIN | I13: עוקב אחר מדדי מניות בישראל | J13: ישראל | K13: ישראל | L13: TASE | M13: מניות בישראל | N13: לא | O13: ILS | P13: 105000 | Q13: 1 | R13: 9440 | T13: 9912 | U13: 0.011467 | V13: 0.011794201 | W13: 0.0034283586
... A17: 382 | B17: 382 | C17: BlackRock Asset Managment | D17: 254900UWHMJRRODS3Z64 | E17: LEI | F17: CEF ishares russell | G17: US4642876555 | H17: ISIN | I17: עוקב אחר מדדי מניות בחו"ל | J17: חו"ל | K17: ארה"ב | L17: NYSE | M17: Equity Funds | N17: לא | O17: USD | P17: 18600 | Q17: 3.718 | R17: 19949 | T17: 13795.691 | U17: 6.5e-05 | V17: 0.016415371 | W17: 0.004771648
A18: 382 | B18: 382 | C18: State Street Corp | D18: 07F5H7W3ET8ZLWNMFP29 | E18: LEI | F18: Financial sel sector spdr | G18: US81369Y6059 | H18: ISIN | I18: עוקב אחר מדדי מניות בחו"ל | J18: חו"ל | K18: ארה"ב | L18: NYSE | M18: Equity Funds | N18: לא | O18: USD | P18: 45500 | Q18: 3.718 | R18: 4981 | S18: 0 | T18: 8426.307 | U18: 5.1e-05 | V18: 0.010026388 | W18: 0.0029144877
A19: 382 | B19: 382 | C19: HSBC Holdings PLC | D19: MLU0ZO3ML4LN2LL2TL39 | E19: LEI | F19: HANG SENG | G19: HK2828013055 | H19: ISIN | I19: עוקב אחר מדדי מניות בחו"ל | J19: חו"ל | K19: סין | L19: HKSE | M19: Equity Funds | N19: לא | O19: HKD | P19: 99000 | Q19: 0.4776 | R19: 8700 | T19: 4113.569 | U19: 0.000209 | V19: 0.0048946991 | W19: 0.0014227995
A20: 382 | B20: 382 | C20: Invesco investment management limited | D20: ECPGFXU8A2SHKVVGJI15 | E20: LEI | F20: INVESCO S&P 500 EQUITY | G20: IE00B3YCGJ38 | H20: ISIN | I20: עוקב אחר מדדי מניות בחו"ל | J20: חו"ל | K20: ארה"ב | L20: LSE | M20: Equity Funds | N20: לא | O20: USD | P20: 1415 | Q20: 3.718 | R20: 109783 | T20: 5775.651 | U20: 6.5e-05 | V20: 0.0068723957 | W20: 0.0019976797
A21: 382 | B21: 382 | C21: BlackRock Asset Managment | D21: 254900UWHMJRRODS3Z64 | E21: LEI | F21: ISH $ CORP BD $A | G21: IE00BYXYYJ35 | H21: ISIN | I21: עוקב אחר מדדים אחרים בחו"ל | J21: חו"ל | K21: גלובלי | L21: LSE | M21: Bond/Fixed Income Funds | N21: לא | O21: USD | P21: 792600 | Q21: 3.718 | R21: 597.45 | T21: 17606.175 | U21: 0.002338 | V21: 0.020949432 | W21: 0.0060896168
A22: 382 | B22: 382 | C22: BlackRock Asset Managment | D22: 254900UWHMJRRODS3Z64 | E22: LEI | F22: ISH CORE ERSTX50 | G22: DE0005933956 | H22: ISIN | I22: עוקב אחר מדדי מניות בחו"ל | J22: חו"ל | K22: אירופה | L22: FWB | M22: Equity Funds | N22: לא | O22: EUR | P22: 204900 | Q22: 4.0219 | R22: 5318 | T22: 43824.963 | U22: 0.001443 | V22: 0.052146936 | W22: 0.015158161
A23: 382 | B23: 382 | C23: BlackRock Asset Managment | D23: 254900UWHMJRRODS3Z64 | E23: LEI | F23: ISH S&P US BANKS | G23: IE00BD3V0B10 | H23: ISIN | I23: עוקב אחר מדדי מניות בחו"ל | J23: חו"ל | K23: ארה"ב | L23: NYSE | M23: Equity Funds | N23: לא | O23: USD | P23: 570320 | Q23: 3.718 | R23: 601.75 | T23: 12759.806 | U23: 0 | V23: 0.015182781 | W23: 0.0044133567
A24: 382 | B24: 382 | C24: BlackRock Asset Managment | D24: 254900UWHMJRRODS3Z64 | E24: LEI | F24: ISH S&P500 | G24: IE00B4LN9N13 | H24: ISIN | I24: עוקב אחר מדדי מניות בחו"ל | J24: חו"ל | K24: ארה"ב | L24: LSE | M24: Equity Funds | N24: לא | O24: USD | P24: 323390 | Q24: 3.718 | R24: 1088.834 | T24: 13091.754 | U24: 0.009859 | V24: 0.015577763 | W24: 0.0045281707
A25: 382 | B25: 382 | C25: BlackRock Asset Managment | D25: 254900UWHMJRRODS3Z64 | E25: LEI | F25: Ishares $ Short Duration Corp Bond | G25: IE00BYXYYP94 | H25: ISIN | I25: עוקב אחר מדדים אחרים בחו"ל | J25: חו"ל | K25: ארה"ב | L25: LSE | M25: Bond/Fixed Income Funds | N25: לא | O25: USD | P25: 260000 | Q25: 3.718 | R25: 605.15 | T25: 5849.864 | U25: 0 | V25: 0.0069607015 | W25: 0.0020233486
