Workbook

Sheet גמל תלוי גיל
B1: מדיניות השקעה צפויה לשנת 2021
B2: הלמן אלדובי גמל מסלול לבני 50 ומטה
B3: אפיק השקעה | C3: שיעור חשיפה נכון 24.11.2020 | D3: שיעור חשיפה צפוי לשנת 2021*** | E3: טווח סטייה %-/+ | F3: גבולות שיעור החשיפה הצפויה | H3: מדד הייחוס (**)
B4: מניות (כולל תעודות סל, אופציות, קרנות נאמנות) | C4: 0.486 | D4: 0.48 | E4: 0.06 | F4: =IF(D4-E4>0,D4-E4,0) -> 0.42 | G4: =D4+E4 -> 0.54 | H4: 42%- מדד ת"א 125, 58%- MSCI WORLD AC
B5: אג"ח ממשלתי (צמוד, שקלי ומט"ח), ממשלות זרות בנטרול חשיפות בנגזרים(*) | C5: 0.176 | D5: 0.12 | E5: 0.05 | F5: =IF(D5-E5>0,D5-E5,0) -> 0.07 | G5: =D5+E5 -> 0.17 | H5: מדד אג"ח ממשלתי כללי
B6: אג"ח קונצרני (קרנות נאמנות, תעודות סל, הלוואות לעמיתים) | C6: 0.3156 | D6: 0.29 | E6: 0.06 | F6: =IF(D6-E6>0,D6-E6,0) -> 0.23 | G6: =D6+E6 -> 0.35 | H6: 35% - תל בונד כללי , 20% - תל בונד 60 , 15% - תל בונד 50 , 15% - IBOXX HY - 15%, IBOXX IG
B7: נדל"ן | C7: 0.038 | D7: 0.01 | E7: 0.05 | F7: =IF(D7-E7>0,D7-E7,0) -> 0 | G7: =D7+E7 -> 0.06
B8: קרנות השקעה | C8: 0.065 | D8: 0.04 | E8: 0.05 | F8: =IF(D8-E8>0,D8-E8,0) -> 0 | G8: =D8+E8 -> 0.09
B9: אחר (Co Invest,תשתיות, גידור) | C9: 0.037 | D9: 0.03 | E9: 0.05 | F9: =IF(D9-E9>0,D9-E9,0) -> 0 | G9: =D9+E9 -> 0.08
B10: מזומנים (*) | C10: 0.0378 | D10: 0.03
B11: סה"כ | C11: =SUM(C4:C10) -> 1.1554 | D11: =SUM(D4:D10) -> 1
B12: חשיפה למט"ח | C12: 0.249 | D12: 0.21 | E12: 0.06 | F12: =IF(D12-E12>0,D12-E12,0) -> 0.15 | G12: =D12+E12 -> 0.27
B15: הלמן-אלדובי גמל מסלול לבני 50 עד 60
B16: אפיק השקעה | C16: =C3 -> שיעור חשיפה נכון 24.11.2020 | D16: שיעור חשיפה צפוי לשנת 2021**** | E16: טווח סטייה %-/+ | F16: גבולות שיעור החשיפה הצפויה | H16: מדד הייחוס (**)
B17: מניות (כולל תעודות סל, אופציות, קרנות נאמנות) | C17: 0.427 | D17: 0.4 | E17: 0.06 | F17: =IF(D17-E17>0,D17-E17,0) -> 0.34 | G17: =D17+E17 -> 0.46 | H17: 42%- מדד ת"א 125, 58%- MSCI WORLD AC
B18: אג"ח ממשלתי (צמוד, שקלי ומט"ח), ממשלות זרות בנטרול חשיפות בנגזרים(*) | C18: 0.245 | D18: 0.2 | E18: 0.05 | F18: =IF(D18-E18>0,D18-E18,0) -> 0.15 | G18: =D18+E18 -> 0.25 | H18: מדד אג"ח ממשלתי כללי
B19: אג"ח קונצרני (קרנות נאמנות, תעודות סל, הלוואות לעמיתים) | C19: 0.316 | D19: 0.29 | E19: 0.06 | F19: =IF(D19-E19>0,D19-E19,0) -> 0.23 | G19: =D19+E19 -> 0.35 | H19: 35% - תל בונד כללי , 20% - תל בונד 60 , 15% - תל בונד 50 , 15% - IBOXX HY - 15%, IBOXX IG
B20: נדל"ן | C20: 0.005 | D20: 0.01 | E20: 0.05 | F20: =IF(D20-E20>0,D20-E20,0) -> 0 | G20: =D20+E20 -> 0.06
B21: אחר (קרנות השקעה,Co Invest ,תשתיות, גידור) | C21: 0.075 | D21: 0.05 | E21: 0.05 | F21: =IF(D21-E21>0,D21-E21,0) -> 0 | G21: =D21+E21 -> 0.1
B22: מזומנים (*) | C22: 0.023 | D22: 0.05
B23: סה"כ | C23: =SUM(C16:C22) -> 1.091 | D23: =SUM(D16:D22) -> 1
B24: חשיפה למט"ח | C24: 0.231 | D24: 0.21 | E24: 0.06 | F24: =IF(D24-E24>0,D24-E24,0) -> 0.15 | G24: =D24+E24 -> 0.27
B27: הלמן אלדובי גמל מסלול לבני 60 ומעלה
B28: אפיק השקעה | C28: =C16 -> שיעור חשיפה נכון 24.11.2020 | D28: שיעור חשיפה צפוי לשנת 2021***** | E28: טווח סטייה %-/+ | F28: גבולות שיעור החשיפה הצפויה | H28: מדד הייחוס (**)
B29: מניות (כולל תעודות סל, אופציות, קרנות נאמנות) | C29: 0.253 | D29: 0.22 | E29: 0.06 | F29: =IF(D29-E29>0,D29-E29,0) -> 0.16 | G29: =D29+E29 -> 0.28 | H29: 42%- מדד ת"א 125, 58%- MSCI WORLD AC
B30: אג"ח ממשלתי (צמוד, שקלי ומט"ח), ממשלות זרות בנטרול חשיפות בנגזרים(*) | C30: 0.381 | D30: 0.3 | E30: 0.05 | F30: =IF(D30-E30>0,D30-E30,0) -> 0.25 | G30: =D30+E30 -> 0.35 | H30: מדד אג"ח ממשלתי כללי
B31: אג"ח קונצרני (קרנות נאמנות, תעודות סל, הלוואות לעמיתים) | C31: 0.325 | D31: 0.4 | E31: 0.06 | F31: =IF(D31-E31>0,D31-E31,0) -> 0.34 | G31: =D31+E31 -> 0.46 | H31: 35% - תל בונד כללי , 20% - תל בונד 60 , 15% - תל בונד 50 , 15% - IBOXX HY - 15%, IBOXX IG
B32: נדל"ן | C32: 0.008 | D32: 0.01 | E32: 0.05 | F32: =IF(D32-E32>0,D32-E32,0) -> 0 | G32: =D32+E32 -> 0.06
B33: אחר (קרנות השקעה,Co Invest ,תשתיות, גידור) | C33: 0.043 | D33: 0.04 | E33: 0.05 | F33: =IF(D33-E33>0,D33-E33,0) -> 0 | G33: =D33+E33 -> 0.09
B34: מזומנים (*) | C34: 0.031 | D34: 0.03
B35: סה"כ | C35: =SUM(C29:C34) -> 1.041 | D35: =SUM(D29:D34) -> 1
B36: חשיפה למט"ח | C36: 0.174 | D36: 0.16 | E36: 0.06 | F36: =IF(D36-E36>0,D36-E36,0) -> 0.1 | G36: =D36+E36 -> 0.22
B39: הלמן-אלדובי גמל כללי
B40: אפיק השקעה | C40: =C28 -> שיעור חשיפה נכון 24.11.2020 | D40: שיעור חשיפה צפוי לשנת 2021****** | E40: טווח סטייה %-/+ | F40: גבולות שיעור החשיפה הצפויה | H40: מדד הייחוס (**)
B41: מניות (כולל תעודות סל, אופציות, קרנות נאמנות) | C41: 0.433 | D41: 0.4 | E41: 0.06 | F41: =IF(D41-E41>0,D41-E41,0) -> 0.34 | G41: =D41+E41 -> 0.46 | H41: 42%- מדד ת"א 125, 58%- MSCI WORLD AC
B42: אג"ח ממשלתי (צמוד, שקלי ומט"ח), ממשלות זרות בנטרול חשיפות בנגזרים(*) | C42: 0.242 | D42: 0.2 | E42: 0.05 | F42: =IF(D42-E42>0,D42-E42,0) -> 0.15 | G42: =D42+E42 -> 0.25 | H42: מדד אג"ח ממשלתי כללי
B43: אג"ח קונצרני (קרנות נאמנות, תעודות סל, הלוואות לעמיתים) | C43: 0.291 | D43: 0.29 | E43: 0.06 | F43: =IF(D43-E43>0,D43-E43,0) -> 0.23 | G43: =D43+E43 -> 0.35 | H43: 35% - תל בונד כללי , 20% - תל בונד 60 , 15% - תל בונד 50 , 15% - IBOXX HY - 15%, IBOXX IG
B44: נדל"ן | C44: 0.052 | D44: 0.05 | E44: 0.05 | F44: =IF(D44-E44>0,D44-E44,0) -> 0 | G44: =D44+E44 -> 0.1
B45: אחר (קרנות השקעה,Co Invest ,תשתיות, גידור) | C45: 0.079 | D45: 0.05 | E45: 0.05 | F45: =IF(D45-E45>0,D45-E45,0) -> 0 | G45: =D45+E45 -> 0.1
B46: מזומנים (*) | C46: 0.008 | D46: 0.01
...

Sheet מסלולים מתמחים גמל
C1: מדיניות השקעה צפויה לשנת 2021
B2: מסלולים מתמחים - גמל
B3: שם המסלול | C3: מדיניות ההשקעה | E3: מדד הייחוס (*)
C4: נכסי המסלול יהיו חשופים לנכסים הבאים: אג"ח סחירות ושאינן סחירות של חברות, ני"ע מסחריים, הלוואות שאינן סחירות לחברות, אג"ח להמרה, פקדונות, אג"ח של ממשלת ישראל או אג"ח של ממשלות אחרות. חשיפה לנכסי אג"ח תהיה בשיעור שלא יפחת מ-75% ולא יעלה על 120% מנכסי המסלול.חשיפה למניות תהיה בשיעור של 0% מנכסי המסלול. חשיפה לנכסים כאמור לעיל תושג הן באמצעות השקעה במישרין והן באמצעות השקעה בנגזרים, בתעודות סל, בקרנות נאמנות או בקרנות השקעה. חשיפה לנכסים שאינם נכסי אג"ח ואינם מניות תהיה על פי שיקול דעתה של וועדת ההשקעות ובכפוף לכל דין. | D4: 0.38 | E4: מדד אג"ח ממשלתי כללי
B5: הלמן אלדובי גמל אג''ח ללא מניות** | D5: 0.21 | E5: תל בונד כללי
D6: 0.12 | E6: תל בונד 60
D7: 0.08 | E7: תל בונד 50
D8: 0.08 | E8: IBOXX HY
D9: 0.08 | E9: IBOXX IG
D10: 0.05 | E10: מזומן / פח"ק
C12: נכסי המסלול יהיו חשופים לנכסים הבאים: אג"ח סחירות ושאינן סחירות של חברות, ני"ע מסחריים, הלוואות שאינן סחירות לחברות, אג"ח להמרה, פקדונות, אג"ח של ממשלת ישראל | D12: 0.23 | E12: מדד אג"ח ממשלתי כללי
B13: הלמן אלדובי גמל אג''ח עד 25% מניות*** | C13: או אג"ח של ממשלות אחרות. חשיפה לנכסי אג"ח תהיה בשיעור שלא יפחת מ-75% ולא יעלה על 120% מנכסי המסלול. חשיפה למניות תהיה בשיעור שלא יעלה על 20%. חשיפה לנכסים | D13: 0.2 | E13: תל בונד כללי
C14: כאמור לעיל תושג הן באמצעות השקעה במישרין והן באמצעות השקעה בנגזרים, בתעודות סל, בקרנות נאמנות או בקרנות השקעה. חשיפה לנכסים שאינם נכסי אג"ח ואינם מניות תהיה | D14: 0.11 | E14: תל בונד 60
C15: על פי שיקול דעתה של ועדת ההשקעות ובכפוף לכל דין. | D15: 0.08 | E15: תל בונד 50
D16: 0.08 | E16: IBOXX HY
D17: 0.08 | E17: IBOXX IG
D18: 0.08 | E18: תל אביב 125
D19: 0.12 | E19: MSCI WORLD AC
D20: 0.02 | E20: מזומן / פח"ק
B22: הלמןן אלדובי גמל ישראל**** | C22: נכסי המסלול יהיו חשופים לנכסים שהונפקו בישראל לרבות מניות, אגח סחיר ולא סחיר, | D22: 0.23 | E22: תל אביב 125
C23: הלוואות ועוד, בשיעור חשיפה שלא יפחת מ-75% ולא יעלה על 120% מנכסי המסלול. | D23: 0.17 | E23: MSCI WORLD AC
C24: חשיפה לנכסים כאמור תושג באמצעות השקעה במישרין, בנגזרים, בתעודות סל, | D24: 0.32 | E24: מדד אג"ח ממשלתי כללי
C25: בקרנות נאמנות או בקרנות השקעה. יתרת הנכסים תושקע בכפוף להוראות הדין, | D25: 0.14 | E25: בונד כללי
C26: ובכפוף לשיקול דעתה של ועדת ההשקעות. | D26: 0.08 | E26: בונד 60
D27: 0.06 | E27: בונד 50
B28: הלמן אלדובי פסיבי מדדי אג"ח ממשלת ישראל***** | C28: נכסי המסלול יהיו חשופים למדדי אג"ח של ממשלת ישראל בשיעור חשיפה שלא יפחת מ-75% ולא יעלה על 100% מנכסי המסלול. יתרת הנכסים, למעט שיעור מהנכסים אשר יושקע במזומנים לצורך טיפול בהפקדות, משיכות והעברות כספים, תהיה חשופה למדדים שונים, בכפוף להוראות הדין, ובכפוף לשיקול דעתה של ועדת השקעות. | D28: 0.2 | E28: משקל גליל 2-5
D29: 0.25 | E29: משקל גליל 5-10
D30: 0.35 | E30: משקל שחר 2-5
D31: 0.2 | E31: +משקל שחר 5
B32: הלמן אלדובי פסיבי מדדי מניות חו"ל****** | C32: נכסי המסלול יהיו חשופים למדדי מניות שנסחרות בחו"ל בשיעור חשיפה שלא יפחת מ-75% ולא יעלה על 100% מנכסי המסלול. יתרת הנכסים, למעט שיעור מהנכסים אשר יושקע במזומנים לצורך טיפול בהפקדות, משיכות והעברות כספים, תהיה חשופה למדדים שונים, בכפוף להוראות הדין, ובכפוף לשיקול דעתה של ועדת השקעות. | D32: 0.56 | E32: S&P500
D33: 0.2 | E33: SXXR
D34: 0.1 | E34: TPX
D35: 0.14 | E35: MSCI EM
B36: הלמן אלדובי גמל מניות******* | C36: נכסי המסלול יהיו חשופים למניות בארץ ובחו"ל, בשיעור חשיפה שלא יפחת מ-75% ולא יעלה על 120% מנכסי המסלול. חשיפה לנכסים כאמור תושג באמצעות השקעה במישרין, בנגזרים, בתעודות סל, בקרנות נאמנות או בקרנות השקעה. יתרת הנכסים תושקע בכפוף להוראות הדין, ובכפוף לשיקול דעתה של ועדת ההשקעות. | D36: 42%- מדד ת"א 125, 58%- MSCI WORLD AC
B37: הלמן אלדובי גמל מחקה מדד S&P 500 | C37: נכסי המסלול יעקבו אחר מדד S&P500 בשיעור חשיפה של 100% מנכסי המסלול. נכסי המסלול העוקבים אחר המדד כמפורט לעיל יהיו כל נכסי המסלול למעט שיעור מהנכסים אשר יושקע במזומנים לצורך טיפול בהפקדות, משיכות והעברות כספים. | D37: 1 | E37: S&P500
D38: 0.24 | E38: S&P500
D39: 0.16 | E39: ת''א 125
B40: הלמן-אלדובי גמל שריעה******** | C40: נכסי המסלול יהיו חשופים לנכסים מסוגים שונים בכפוף להוראות הדין ובכפוף לכללי השריעה האסלאמית בלבד. ההשקעות במסלול תהיינה בסמכותה ובאחריותה הבלעדית של ועדת ההשקעות והחברה המנהלת תהיה חייבת לפעול בנאמנות על פי העמיתים במסלול זה. השאת התשואה במסלול מוגבלת בכך שההשקעות בו כפופות לכללי השריעה האסלאמית | D40: 0.6 | E40: DJSUKUK Index
D41: 0.05 | E41: משקל גליל 2-5
D42: 0.1 | E42: משקל גליל 5-10
...

Sheet השתלמות כללי
B1: ='גמל תלוי גיל'!B1:H1 -> מדיניות השקעה צפויה לשנת 2021
B2: הלמן אלדובי השתלמות כללי
B3: אפיק השקעה | C3: ='גמל תלוי גיל'!C3 -> שיעור חשיפה נכון 24.11.2020 | D3: ='גמל תלוי גיל'!D3 -> שיעור חשיפה צפוי לשנת 2021*** | E3: טווח סטייה %-/+ | F3: גבולות שיעור החשיפה הצפויה | H3: מדד הייחוס (**)
B4: מניות (כולל תעודות סל, אופציות, קרנות נאמנות) | C4: 0.408 | D4: 0.4 | E4: 0.06 | F4: =IF(D4-E4>0,D4-E4,0) -> 0.34 | G4: =D4+E4 -> 0.46 | H4: 42%- מדד ת"א 125, 58%- MSCI WORLD AC
B5: אג"ח ממשלתי (צמוד, שקלי ומט"ח), ממשלות זרות בנטרול חשיפות בנגזרים(*) | C5: 0.166 | D5: 0.18 | E5: 0.05 | F5: =IF(D5-E5>0,D5-E5,0) -> 0.13 | G5: =D5+E5 -> 0.23 | H5: מדד אג"ח ממשלתי כללי
B6: אג"ח קונצרני (קרנות נאמנות, תעודות סל, הלוואות לעמיתים) | C6: 0.323 | D6: 0.31 | E6: 0.06 | F6: =IF(D6-E6>0,D6-E6,0) -> 0.25 | G6: =D6+E6 -> 0.37 | H6: 35% - תל בונד כללי , 20% - תל בונד 60 , 15% - תל בונד 50 , 15% - IBOXX HY - 15%, IBOXX IG
B7: נדל"ן | C7: 0.046 | D7: 0.02 | E7: 0.05 | F7: =IF(D7-E7>0,D7-E7,0) -> 0 | G7: =D7+E7 -> 0.07
B8: אחר (קרנות השקעה,Co Invest ,תשתיות, גידור) | C8: 0.078 | D8: 0.07 | E8: 0.05 | F8: =IF(D8-E8>0,D8-E8,0) -> 0.02 | G8: =D8+E8 -> 0.12
B9: מזומנים (*) | C9: 0.03 | D9: 0.02
B10: סה"כ | C10: =SUM(C4:C9) -> 1.051 | D10: =SUM(D4:D9) -> 1
B11: חשיפה למט"ח | C11: 0.233 | D11: 0.21 | E11: 0.06 | F11: =IF(D11-E11>0,D11-E11,0) -> 0.15 | G11: =D11+E11 -> 0.27
B13: * מוצג בנטרול תוספת החשיפה הנובעת מהשקעה בנגזרים
B14: ** מובהר כי תיק הנכסים אינו תואם בהכרח במלואו להרכב מדד הייחוס. אין בציון מדד הייחוס בכדי להוות מצג, הצהרה או התחייבות כלשהי לגבי התשואה שתושג בפועל בתיק
B15: החל מתאריך 24/03/2021 השתנו מדדי הייחוס :
B16: אפיק מנייתי- מ 40% ת''א 125 ו60% MSCI W למדדים המוצגים בטבלה
B17: אפיק ממשלתי- מ-40% ממשלתי שקלי 2-5 , 10% ממשלתי שקלי 5+ , 40% ממשלתי צמוד 2-5 , 10% ממשלתי צמוד 5-10 למדד המוצג בטבלה
B18: אפיק קונצרני- מ-50% תל בונד 60 ו50% תל בונד שקלי 50 למדדים המוצגים בטבלה
B20: ***החל מתאריך 24/03/2021 עודכן שיעור החשיפה הצפוי לשנת 2020, להלן השינויים שבוצעו:
B21: שיעור החשיפה הצפויה לאפיק האג''ח הממשלתי עודכן מ - 20% ל - 18%.
B22: שיעור החשיפה הצפויה לאפיק אג''ח קונצרני עודכן מ - 27% ל - 31%.
B23: שיעור החשיפה הצפויה לאפיק נדל''ן עודכן מ-4% ל2%
B24: שיעור החשיפה הצפויה לאפיק "אחר" עודכן מ8% ל-7%
B25: שיעור החשיפה הצפויה למזומנים עודכן עודכן מ 5% ל-2%
B26: שיעור החשיפה הצפויה למט''ח עודכנה מ-20% ל21%

Sheet  השתלמות פאסיבי כללי
B2: ='גמל תלוי גיל'!B1:H1 -> מדיניות השקעה צפויה לשנת 2021
B3: הלמן אלדובי- השתלמות פאסיבי כללי
B4: אפיק השקעה | C4: ='גמל תלוי גיל'!C3 -> שיעור חשיפה נכון 24.11.2020 | D4: ='גמל תלוי גיל'!D3 -> שיעור חשיפה צפוי לשנת 2021*** | E4: ='גמל תלוי גיל'!E3 -> טווח סטייה %-/+ | F4: גבולות שיעור החשיפה הצפויה | H4: מדד ייחוס (**)
H5: 0.32 | I5: S&P500
H6: 0.12 | I6: SXXR
B7: מניות (תעודות סל, אופציות, קרנות נאמנות) | C7: 0.362 | D7: 0.47 | E7: 0.06 | F7: =D7-E7 -> 0.41 | G7: =D7+E7 -> 0.53 | H7: 0.08 | I7: MSCI EM
H8: 0.06 | I8: TPX
H9: 0.38 | I9: תל אביב 125
H10: 0.02 | I10: ת"א SME60
H11: 0.02 | I11: BlueStar TA-BIG Tech Israel Tech
H12: 0.2 | I12: משקל גליל 2-5
B13: אג"ח ממשלתי (צמוד, שקלי ומט"ח), ממשלות | C13: 0.283 | D13: 0.18 | E13: 0.05 | F13: =D13-E13 -> 0.13 | G13: =D13+E13 -> 0.23 | H13: 0.25 | I13: משקל גליל 5-10
B14: זרות בנטרול חשיפות בנגזרים | H14: 0.35 | I14: משקל שחר 2-5
H15: 0.2 | I15: +משקל שחר 5
H16: 0.126 | I16: IBOXX HY
H17: 0.072 | I17: IBXXC1D1
H18: 0.045 | I18: JGENUUG
B19: אג"ח קונצרני (קרנות נאמנות, תעודות סל) | C19: 0.299 | D19: 0.33 | E19: 0.06 | F19: =D19-E19 -> 0.27 | G19: =D19+E19 -> 0.39 | H19: 0.018 | I19: JCMBCOMP
H20: 0.039 | I20: IBOXIG
H21: 0.32 | I21: משקל תל בונד 60
H22: 0.25 | I22: משקל תל בונד שקלי
H23: 0.1 | I23: משקל תל בונד תשואות
H24: 0.03 | I24: משקל תל בונד תשואות שיקלי
B25: אחר | C25: 0 | D25: 0 | E25: 0.05 | F25: =IF((D25-E25)<0,0,D25-E25) -> 0 | G25: =D25+E25 -> 0.05
B26: מזומנים (*) | C26: 0.057 | D26: 0.02 | H26: 1 | I26: ריבית פח"ק
B27: סה"כ | C27: =SUM(C5:C26) -> 1.001 | D27: =SUM(D5:D26) -> 1
B28: חשיפה למט"ח | C28: 0.197 | D28: 0.21 | E28: 0.06 | F28: =D28-E28 -> 0.15 | G28: =D28+E28 -> 0.27
B30: * מוצג בנטרול תוספת החשיפה הנובעת מהשקעה בנגזרים
B31: ** מובהר כי תיק הנכסים אינו תואם בהכרח במלואו להרכב מדד הייחוס. אין בציון מדד הייחוס בכדי להוות מצג, הצהרה או התחייבות כלשהי לגבי התשואה שתושג בפועל בתיק
B32: החל מתאריך 24/03/2021 השתנו מדדי הייחוס :
B33: אפיק מנייתי- מ 30% SP500, ו18% STOXX600 , ו13% MSCI EM, ו40% תל אביב 125 למדדים המוצגים בטבלה
B34: אפיק ממשלתי- מ-100% מדד אג''ח ממשלתי כללי למדדים המוצג בטבלה
B35: אפיק קונצרני- מ-50% תל בונד צמודות ו50% תל בונד שקלי 50 למדדים המוצגים בטבלה
B38: ***החל מתאריך 24/03/2021 עודכן שיעור החשיפה הצפוי לשנת 2020, להלן השינויים שבוצעו:
B39: שיעור החשיפה הצפויה לאפיק המנייתי עודכן מ - 33% ל - 47%.
B40: שיעור החשיפה הצפויה לאפיק האג''ח הממשלתי עודכן מ - 32% ל - 18%.
B41: שיעור החשיפה הצפויה לאפיק אג''ח קונצרני עודכן מ - 30% ל - 33%.
B42: שיעור החשיפה הצפויה למזומנים עודכן עודכן מ 3% ל-2%
B43: שיעור החשיפה הצפויה למט''ח עודכנה מ-20% ל21%

Sheet מסלולים מתמחים השתלמות 
C1: מדיניות השקעה צפויה לשנת 2021
B2: מסלולים מתמחים - השתלמות
B3: שם המסלול | C3: מדיניות ההשקעה | E3: מדד ייחוס (*)
D4: 0.38 | E4: מדד אג"ח ממשלתי כללי
B5: הלמן אלדובי השתלמות אג''ח ללא מניות** | C5: נכסי המסלול יהיו חשופים לנכסים הבאים: אג"ח סחירות ושאינן סחירות של חברות, ני"ע מסחריים, הלוואות שאינן סחירות לחברות, אג"ח להמרה, פקדונות, אג"ח של ממשלת ישראל או אג"ח של ממשלות אחרות. חשיפה לנכסי אג"ח תהיה בשיעור שלא יפחת מ-75% ולא יעלה על 120% מנכסי המסלול.חשיפה למניות תהיה בשיעור של 0% מנכסי המסלול. חשיפה לנכסים כאמור לעיל תושג הן באמצעות השקעה במישרין והן באמצעות השקעה בנגזרים, בתעודות סל, בקרנות נאמנות או בקרנות השקעה. חשיפה לנכסים שאינם נכסי אג"ח ואינם מניות תהיה על פי שיקול דעתה של וועדת ההשקעות ובכפוף לכל דין. | D5: 0.21 | E5: תל בונד כללי
D6: 0.12 | E6: תל בונד 60
D7: 0.08 | E7: תל בונד 50
D8: 0.08 | E8: IBOXX HY
D9: 0.08 | E9: IBOXX IG
D10: 0.05 | E10: מזומן / פח"ק
D13: 0.5 | E13: מדד אג"ח ממשלתי כללי
D14: 0.14 | E14: תל בונד כללי
D15: 0.08 | E15: תל בונד 60
B16: הלמן אלדובי השתלמות אג''ח עד 10% במניות*** | C16: נכסי המסלול יהיו חשופים לנכסים הבאים: אג"ח סחירות ושאינן סחירות של חברות, ני"ע מסחריים, הלוואות שאינן סחירות לחברות, אג"ח להמרה, פקדונות, אג"ח של ממשלת ישראל או אג"ח של ממשלות אחרות. חשיפה לנכסי אג"ח תהיה בשיעור שלא יפחת מ-75% ולא יעלה על 100% מנכסי המסלול. חשיפה למניות תהיה בשיעור שלא יעלה על 10% מנכסי המסלול. חשיפה לנכסים כאמור לעיל תושג הן באמצעות השקעה במישרין והן באמצעות השקעה בנגזרים, בתעודות סל, בקרנות נאמנות או בקרנות השקעה. חשיפה לנכסים שאינם נכסי אג"ח ואינם מניות תהיה על פי שיקול דעתה של וועדת ההשקעות ובכפוף לכל דין. | D16: 0.06 | E16: תל בונד 50
D17: 0.06 | E17: IBOXX HY
D18: 0.06 | E18: IBOXX IG
D19: 0.04 | E19: תל אביב 125
D20: 0.06 | E20: MSCI WORLD AC
D22: 0.23 | E22: מדד אג"ח ממשלתי כללי
B23: הלמן אלדובי השתלמות אג''ח עד 25% במניות**** | C23: נכסי המסלול יהיו חשופים לנכסים הבאים: אג"ח סחירות ושאינן סחירות של חברות, ני"ע מסחריים, הלוואות שאינן סחירות לחברות, אג"ח להמרה, פקדונות, אג"ח של ממשלת ישראל או אג"ח של ממשלות אחרות. חשיפה לנכסי אג"ח תהיה בשיעור שלא יפחת מ-75% ולא יעלה על 120% מנכסי המסלול. חשיפה למניות תהיה בשיעור שלא יעלה על 25% מנכסי המסלול. חשיפה לנכסים כאמור לעיל תושג הן באמצעות השקעה במישרין והן באמצעות השקעה בנגזרים, בתעודות סל, בקרנות נאמנות או בקרנות השקעה. חשיפה לנכסים שאינם נכסי אג"ח ואינם מניות תהיה על פי שיקול דעתה של ועדת ההשקעות ובכפוף לכל דין. | D23: 0.2 | E23: תל בונד כללי
D24: 0.11 | E24: תל בונד 60
D25: 0.08 | E25: תל בונד 50
D26: 0.08 | E26: IBOXX HY
D27: 0.08 | E27: IBOXX IG
D28: 0.08 | E28: תל אביב 125
D29: 0.12 | E29: MSCI WORLD AC
D30: 0.02 | E30: מזומן / פח"ק
B32: הלמן אלדובי השתלמות מניות***** | C32: נכסי המסלול יהיו חשופים למניות בארץ ובחו"ל, בשיעור חשיפה שלא יפחת מ-75% ולא יעלה על 120% מנכסי המסלול. חשיפה לנכסים כאמור תושג באמצעות השקעה במישרין, בנגזרים, בתעודות סל, בקרנות נאמנות או בקרנות השקעה. יתרת הנכסים תושקע בכפוף להוראות הדין, ובכפוף לשיקול דעתה של ועדת ההשקעות. | E32: 42%- מדד ת"א 125, 58%- MSCI WORLD AC
B33: הלמן אלדובי השתלמות מחקה מדד S&P 500 | C33: נכסי המסלול יעקבו אחר מדד S&P500 בשיעור חשיפה של 100% מנכסי המסלול. נכסי המסלול העוקבים אחר המדד כמפורט לעיל יהיו כל נכסי המסלול למעט שיעור מהנכסים אשר יושקע במזומנים לצורך טיפול בהפקדות, משיכות והעברות כספים. | D33: 1 | E33: S&P500
D35: 0.05 | E35: משקל גליל 2-5
D36: 0.1 | E36: משקל גליל 5-10
B37: הלמן אלדובי השתלמות פאסיבי משולב עד 25% מניות****** | C37: נכסי המסלול, בשיעור שלא יפחת מ-75% ולא יעלה על 100%, יושקעו במדדי אג"ח. חשיפה למדדי מניות לא תעלה על 25% מנכסי המסלול. יתרת הנכסים, למעט שיעור מהנכסים אשר יושקע במזומנים לצורך טיפול בהפקדות, משיכות והעברות כספים, תושקע במדדים שונים בכפוף להוראות הדין, ובכפוף לשיקול דעתה של ועדת השקעות. | D37: 0.06 | E37: משקל שחר 2-5
D38: 0.02 | E38: +משקל שחר 5
D39: 0.0672 | E39: IBOXX HY
D40: 0.0384 | E40: IBXXC1D1
D41: 0.024 | E41: JGENUUG
D42: 0.0096 | E42: JCMBCOMP
D43: 0.0208 | E43: IBOXIG
D44: 0.1755 | E44: משקל תל בונד 60
D45: 0.1365 | E45: משקל תל בונד שקלי
...

Sheet מרכזית לפיצויים
B1: ='גמל תלוי גיל'!B1:H1 -> מדיניות השקעה צפויה לשנת 2021
B2: הלמן אלדובי מרכזית לפיצויים מסלול כללי
B3: אפיק השקעה | C3: ='גמל תלוי גיל'!C40 -> שיעור חשיפה נכון 24.11.2020 | D3: שיעור חשיפה צפוי לשנת 2021*** | E3: טווח סטייה %-/+ | F3: גבולות שיעור החשיפה הצפויה | H3: מדד הייחוס (**)
B4: מניות (כולל תעודות סל, אופציות, קרנות נאמנות) | C4: 0.417 | D4: 0.36 | E4: 0.06 | F4: =IF(D4-E4>0,D4-E4,0) -> 0.3 | G4: =D4+E4 -> 0.42 | H4: 42%- מדד ת"א 125, 58%- MSCI WORLD AC
B5: אג"ח ממשלתי (צמוד, שקלי ומט"ח), ממשלות זרות בנטרול חשיפות בנגזרים(*) | C5: 0.245 | D5: 0.22 | E5: 0.05 | F5: =IF(D5-E5>0,D5-E5,0) -> 0.17 | G5: =D5+E5 -> 0.27 | H5: מדד אג"ח ממשלתי כללי
B6: אג"ח קונצרני (קרנות נאמנות, תעודות סל) | C6: 0.283 | D6: 0.31 | E6: 0.06 | F6: =IF(D6-E6>0,D6-E6,0) -> 0.25 | G6: =D6+E6 -> 0.37 | H6: 35% - תל בונד כללי , 20% - תל בונד 60 , 15% - תל בונד 50 , 15% - IBOXX HY - 15%, IBOXX IG
B7: נדל"ן | C7: 0.018 | D7: 0.02 | E7: 0.05 | F7: =IF(D7-E7>0,D7-E7,0) -> 0 | G7: =D7+E7 -> 0.07
B8: אחר (קרנות השקעה,Co Invest ,תשתיות, גידור) | C8: 0.055 | D8: 0.06 | E8: 0.05 | F8: =IF(D8-E8>0,D8-E8,0) -> 0.01 | G8: =D8+E8 -> 0.11
B9: מזומנים (*) | C9: 0.063 | D9: 0.03
B10: סה"כ | C10: =SUM(C4:C9) -> 1.081 | D10: =SUM(D4:D9) -> 1
B11: חשיפה למט"ח | C11: 0.236 | D11: 0.21 | E11: 0.06 | F11: =IF(D11-E11>0,D11-E11,0) -> 0.15 | G11: =D11+E11 -> 0.27
B13: הלמן-אלדובי קופה לתשלום דמי מחלה
B14: אפיק השקעה | C14: =C3 -> שיעור חשיפה נכון 24.11.2020 | D14: שיעור חשיפה צפוי לשנת 2021**** | E14: טווח סטייה %-/+ | F14: גבולות שיעור החשיפה הצפויה | H14: מדד הייחוס (**)
B15: מניות (כולל תעודות סל, אופציות, קרנות נאמנות) | C15: 0.3 | D15: 0.27 | E15: 0.06 | F15: =IF(D15-E15>0,D15-E15,0) -> 0.21 | G15: =D15+E15 -> 0.33 | H15: 42%- מדד ת"א 125, 58%- MSCI WORLD AC
B16: אג"ח ממשלתי (צמוד, שקלי ומט"ח), ממשלות זרות בנטרול חשיפות בנגזרים(*) | C16: 0.344 | D16: 0.35 | E16: 0.05 | F16: =IF(D16-E16>0,D16-E16,0) -> 0.3 | G16: =D16+E16 -> 0.4 | H16: מדד אג"ח ממשלתי כללי
B17: אג"ח קונצרני (קרנות נאמנות, תעודות סל) | C17: 0.192 | D17: 0.19 | E17: 0.06 | F17: =IF(D17-E17>0,D17-E17,0) -> 0.13 | G17: =D17+E17 -> 0.25 | H17: 35% - תל בונד כללי , 20% - תל בונד 60 , 15% - תל בונד 50 , 15% - IBOXX HY - 15%, IBOXX IG
B18: נדל"ן | C18: 0 | D18: 0 | E18: 0.05 | F18: =IF(D18-E18>0,D18-E18,0) -> 0 | G18: =D18+E18 -> 0.05
B19: אחר (קרנות השקעה,Co Invest ,תשתיות, גידור) | C19: 0.097 | D19: 0.12 | E19: 0.05 | F19: =IF(D19-E19>0,D19-E19,0) -> 0.07 | G19: =D19+E19 -> 0.17
B20: מזומנים (*) | C20: 0.068 | D20: 0.07
B21: סה"כ | C21: =SUM(C15:C20) -> 1.001 | D21: =SUM(D15:D20) -> 1
B22: חשיפה למט"ח | C22: 0.219 | D22: 0.21 | E22: 0.06 | F22: =IF(D22-E22>0,D22-E22,0) -> 0.15 | G22: =D22+E22 -> 0.27
B24: הלמן-אלדובי קופת גמל מרכזית להשתתפות בפנסיה תקציבית
B25: אפיק השקעה | C25: =C14 -> שיעור חשיפה נכון 24.11.2020 | D25: שיעור חשיפה צפוי לשנת 2021 | E25: טווח סטייה %-/+ | F25: גבולות שיעור החשיפה הצפויה | H25: מדד הייחוס (**)
B26: מניות (כולל תעודות סל, אופציות, קרנות נאמנות) | C26: 0 | D26: 0 | E26: 0.06 | F26: =IF(D26-E26>0,D26-E26,0) -> 0 | G26: =D26+E26 -> 0.06 | H26: 42%- מדד ת"א 125, 58%- MSCI WORLD AC
B27: אג"ח ממשלתי (צמוד, שקלי ומט"ח), ממשלות זרות בנטרול חשיפות בנגזרים(*) | C27: 0.424 | D27: 0.42 | E27: 0.05 | F27: =IF(D27-E27>0,D27-E27,0) -> 0.37 | G27: =D27+E27 -> 0.47 | H27: מדד אג"ח ממשלתי כללי
B28: אג"ח קונצרני (קרנות נאמנות, תעודות סל) | C28: 0.5 | D28: 0.52 | E28: 0.06 | F28: =IF(D28-E28>0,D28-E28,0) -> 0.46 | G28: =D28+E28 -> 0.58 | H28: 35% - תל בונד כללי , 20% - תל בונד 60 , 15% - תל בונד 50 , 15% - IBOXX HY - 15%, IBOXX IG
B29: נדל"ן | C29: 0 | D29: 0 | E29: 0.05 | F29: =IF(D29-E29>0,D29-E29,0) -> 0 | G29: =D29+E29 -> 0.05
B30: אחר (קרנות השקעה,Co Invest ,תשתיות, גידור) | C30: 0 | D30: 0.01 | E30: 0.05 | F30: =IF(D30-E30>0,D30-E30,0) -> 0 | G30: =D30+E30 -> 0.06
B31: מזומנים (*) | C31: 0.076 | D31: 0.05
B32: סה"כ | C32: =SUM(C26:C31) -> 1 | D32: =SUM(D26:D31) -> 1
B33: חשיפה למט"ח | C33: 0.005 | D33: 0.01 | E33: 0.06 | F33: =IF(D33-E33>0,D33-E33,0) -> 0 | G33: =D33+E33 -> 0.07
B36: * מוצג בנטרול תוספת החשיפה הנובעת מהשקעה בנגזרים
B37: ** מובהר כי תיק הנכסים אינו תואם בהכרח במלואו להרכב מדד הייחוס. אין בציון מדד הייחוס בכדי להוות מצג, הצהרה או התחייבות כלשהי לגבי התשואה שתושג בפועל בתיק
B38: החל מתאריך 24/03/2021 השתנו מדדי הייחוס :
B39: אפיק מנייתי- מ 40% ת''א 125 ו60% MSCI W למדדים המוצגים בטבלה
B40: אפיק ממשלתי- מ-40% ממשלתי שקלי 2-5 , 10% ממשלתי שקלי 5+ , 40% ממשלתי צמוד 2-5 , 10% ממשלתי צמוד 5-10 למדד המוצג בטבלה
B41: אפיק קונצרני- מ-50% תל בונד 60 ו50% תל בונד שקלי 50 למדדים המוצגים בטבלה
B44: ***החל מתאריך 24/03/2021 עודכן שיעור החשיפה הצפוי לשנת 2020, להלן השינויים שבוצעו:
B45: שיעור החשיפה הצפויה לאפיק האג''ח הממשלתי עודכן מ - 24% ל - 22%.
B46: שיעור החשיפה הצפויה לאפיק אג''ח קונצרני עודכן מ - 27% ל - 31%.
...

Sheet מסלולים מתמחים-מרכזית לפיצויים
B1: ='גמל תלוי גיל'!B1:H1 -> מדיניות השקעה צפויה לשנת 2021
C2: מסלולים מתמחים - מרכזיות לפיצויים
B3: שם המסלול | C3: מדיניות ההשקעה | D3: מדד הייחוס (**)
D4: 0.38 | E4: מדד אג"ח ממשלתי כללי
B5: סנונית קופה מסלולית לפיצויים, מסלול "הלמן-אלדובי מסלול אג"ח" | C5: במסלול זה יושקעו לפחות 50% מכספי המסלול באג"חים, ובכפוף להוראות ההסדר התחיקתי ולמגבלות שנקבעו על פיו. | D5: 0.21 | E5: תל בונד כללי
D6: 0.12 | E6: תל בונד 60
D7: 0.08 | E7: תל בונד 50
D8: 0.08 | E8: IBOXX HY
D9: 0.08 | E9: IBOXX IG
D10: 0.05 | E10: מזומן / פח"ק
B12: ** מובהר כי תיק הנכסים אינו תואם בהכרח במלואו להרכב מדד הייחוס. אין בציון מדד הייחוס בכדי להוות מצג, הצהרה או התחייבות כלשהי לגבי התשואה שתושג בפועל בתיק
B13: החל מתאריך 24/03/2021- שונה מדד הייחוס מ-100% מדד אג''ח כללי למדדי הייחוס המוצגים בטבלה

Sheet חיסכון לכל ילד - מסלולים מתמחים
B1: ='גמל תלוי גיל'!B1:H1 -> מדיניות השקעה צפויה לשנת 2021
B3: מסלולים מתמחים - חיסכון לכל ילד
B4: שם המסלול | C4: מדיניות ההשקעה | D4: מדד הייחוס (*)
B5: הלמן-אלדובי חיסכון לילד, "הלמן-אלדובי חיסכון לילד- חוסכים המעדיפים סיכון מועט" | C5: נכסי המסלול יהיו חשופים לנכסים מסוגים שונים בכפוף להוראות הדין ובכפוף לשיקול דעתה של ועדת ההשקעות, בהתחשב, בין היתר, ברמת הסיכון המועטה שנקבעה למסלול. | D5: 0.38 | E5: מדד אג"ח ממשלתי כללי
D6: 0.21 | E6: תל בונד כללי
D7: 0.12 | E7: תל בונד 60
D8: 0.08 | E8: תל בונד 50
D9: 0.08 | E9: IBOXX HY
D10: 0.08 | E10: IBOXX IG
D11: 0.05 | E11: מזומן / פח"ק
B12: הלמן-אלדובי חיסכון לילד, "הלמן-אלדובי חיסכון לילד- לחוסכים המעדיפים סיכון בינוני"*** | C12: נכסי המסלול יהיו חשופים לנכסים מסוגים שונים בכפוף להוראות הדין ובכפוף לשיקול דעתה של ועדת ההשקעות, בהתחשב, בין היתר, ברמת הסיכון הבינונית שנקבעה למסלול. | D12: 0.24 | E12: MSCI WORLD AC
D13: 0.17 | E13: תל אביב 125
D14: 0.21 | E14: מדד אג"ח ממשלתי כללי
D15: 0.06 | E15: IBOXX HY
D16: 0.06 | E16: IBOXX IG
D17: 0.13 | E17: בונד כללי
D18: 0.07 | E18: בונד 60
D19: 0.06 | E19: בונד 50
B20: הלמן-אלדובי חיסכון לילד, "הלמן-אלדובי חיסכון לילד- חוסכים המעדיפים סיכון מוגבר"**** | C20: נכסי המסלול יהיו חשופים לנכסים מסוגים שונים בכפוף להוראות הדין ובכפוף לשיקול דעתה של ועדת ההשקעות, בהתחשב, בין היתר, ברמת הסיכון הגבוהה שנקבעה למסלול. | D20: 0.31 | E20: S&P500
D21: 0.11 | E21: SXXR
D22: 0.08 | E22: MSCI EM
D23: 0.06 | E23: TPX
D24: 0.36 | E24: תל אביב 125
D25: 0.02 | E25: ת"א SME60
D26: 0.02 | E26: BlueStar TA-BIG Tech Israel Tech
D27: 0.04 | E27: מזומן / פח"ק
B28: הלמן-אלדובי חיסכון לילד, "הלמן-אלדובי חיסכון לילד- שריעה"****** | C28: נכסי המסלול יהיו חשופים לנכסים מסוגים שונים בכפוף להוראות הדין ובכפוף לכללי השריעה האסלאמית בלבד. ההשקעות במסלול תהיינה בסמכותה ובאחריותה הבלעדית של ועדת ההשקעות והחברה המנהלת תהיה חייבת לפעול בנאמנות על פי העמיתים במסלול זה. השאת התשואה במסלול מוגבלת בכך שההשקעות בו כפופות לכללי השריעה האסלאמית | D28: 0.24 | E28: S&P500
D29: 0.16 | E29: ת''א 125
D30: 0.6 | E30: DJSUKUK Index
B31: הלמן-אלדובי חיסכון לילד, "הלמן-אלדובי חיסכון לילד- הלכה"***** | C31: נכסי המסלול יהיו חשופים לנכסים מסוגים שונים בכפוף להוראות הדין ובכפוף לכללי ההלכה היהודית בלבד. ההשקעות במסלול תהיינה בסמכותה ובאחריותה הבלעדית של ועדת ההשקעות והחברה המנהלת תהיה חייבת לפעול בנאמנות על פי העמיתים במסלול זה. השאת התשואה במסלול מוגבלת בכך שההשקעות בו כפופות לכללי ההלכה היהודית. | D31: 0.24 | E31: MSCI WORLD AC
D32: 0.17 | E32: תל אביב 125
D33: 0.21 | E33: מדד אג"ח ממשלתי כללי
D34: 0.25 | E34: בונד 60
D35: 0.13 | E35: BarCap Global Corporate Total Return Bond Index UnHedged
B36: * מובהר כי תיק הנכסים אינו תואם בהכרח במלואו להרכב מדד הייחוס. אין בציון מדד הייחוס בכדי להוות מצג, הצהרה או התחייבות כלשהי לגבי התשואה שתושג בפועל בתיק
B37: ** החל מתאריך 24/03/2021- שונו מדדי הייחוס מ73% מדד ממשלתי כללי, 15% תל בונד 60 , 7% MSCI WORLD AC ו5% מדד ת''א 125 למדדי הייחוס המוצגים בטבלה
B38: *** החל מתאריך 24/03/2021- שונו מדדי הייחוס מ34% מדד ממשלתי כללי, 30% תל בונד 60 , 24% MSCI WORLD AC ו12% מדד ת''א 125 למדדי הייחוס המוצגים בטבלה
B39: **** החל מתאריך 24/03/2021- שונו מדדי הייחוס מ 60% MSCI WORLD AC ו40% מדד ת''א 125 למדדי הייחוס המוצגים בטבלה
B40: ***** החל מתאריך 24/03/2021- שונו מדדי הייחוס מ24% מדד ממשלתי כללי, 42% תל בונד 60 , 21% MSCI WORLD AC ו13% מדד ת''א 125 למדדי הייחוס המוצגים בטבלה
B41: ****** החל מתאריך 22/08/2021- שונו מדדי הייחוס מ-95% DJSUKUK Index ו 5% MSCI WORLD AC ל- 16% ת''א 125, 24% SP500 ו 60% DJSUKUK index

Sheet  גמל להשקעה כללי 
B1: מדיניות השקעה צפויה לשנת 2021
B2: הלמן-אלדובי גמל להשקעה כללי
B3: אפיק השקעה | C3: שיעור חשיפה עדכני | D3: שיעור חשיפה צפוי לשנת 2021*** | E3: טווח סטייה %-/+ | F3: גבולות שיעור החשיפה הצפויה | H3: מדד הייחוס (**) | I3: מגדל | J3: מנורה
B4: מניות (תעודות סל, אופציות, קרנות נאמנות) | C4: 0.424 | D4: 0.4 | E4: 0.06 | F4: =IF(D4-E4>0,D4-E4,0) -> 0.34 | G4: =D4+E4 -> 0.46 | H4: 42%- מדד ת"א 125 , 58%- MSCI WORLD AC | I4: חשיפה למניות סחיר ולא סחיר | J4: סה"כ מניות (כולל תעודות סל, אופציות וקרנות נאמנות)
B5: אג"ח ממשלתי (צמוד, שקלי ומט"ח), ממשלות זרות בנטרול חשיפות בנגזרים | C5: 0.303 | D5: 0.21 | E5: 0.05 | F5: =IF(D5-E5>0,D5-E5,0) -> 0.16 | G5: =D5+E5 -> 0.26 | H5: מדד אג"ח ממשלתי כללי | I5: חשיפה לאגח ממשלתי (כולל אגח ממשלות זרות) | J5: *מיועדות
B6: אג"ח קונצרני (קרנות נאמנות, תעודות סל) | C6: 0.269 | D6: 0.35 | E6: 0.06 | F6: =IF(D6-E6>0,D6-E6,0) -> 0.29 | G6: =D6+E6 -> 0.41 | H6: 35% - תל בונד כללי , 20% - תל בונד 60 , 15% - תל בונד 50 , 15% - IBOXX HY - 15%, IBOXX IG | I6: חשיפה לאגח קונצרני סחיר ולא סחיר (כולל בחו"ל וכולל הלוואות) | J6: אג"ח קונצרני
B7: נדל"ן | C7: 0 | D7: 0 | E7: 0.05 | F7: =IF(D7-E7>0,D7-E7,0) -> 0 | G7: =D7+E7 -> 0.05 | I7: אחר | J7: פקדונות ארוכים בבנקים
B8: אחר (קרנות השקעה, Co Invest, תשתיות, גידור) | C8: 0.007 | D8: 0 | E8: 0.05 | F8: =IF(D8-E8>0,D8-E8,0) -> 0 | G8: =D8+E8 -> 0.05 | I8: סה"כ | J8: קרנות השקעה ללא קרנות נדל"ן
B9: מזומנים (*) | C9: 0.034 | D9: 0.04 | I9: חשיפה למטח | J9: ***סה"כ אחר ומזומן
B10: סה"כ | C10: =SUM(C4:C9) -> 1.037 | D10: =SUM(D4:D9) -> 1 | J10: סה"כ תיק
B11: חשיפה למט"ח | C11: 0.217 | D11: 0.21 | E11: 0.06 | F11: =IF(D11-E11>0,D11-E11,0) -> 0.15 | G11: =D11+E11 -> 0.27 | J11: חשיפה למט"ח
B13: * מוצג בנטרול תוספת החשיפה הנובעת מהשקעה בנגזרים
B14: ** מובהר כי תיק הנכסים אינו תואם בהכרח במלואו להרכב מדד הייחוס. אין בציון מדד הייחוס בכדי להוות מצג, הצהרה או התחייבות כלשהי לגבי התשואה שתושג בפועל בתיק
B15: החל מתאריך 24/03/2021 השתנו מדדי הייחוס :
B16: אפיק מנייתי- מ 40% ת''א 125 ו60% MSCI W למדדים המוצגים בטבלה
B17: אפיק ממשלתי- מ-40% ממשלתי שקלי 2-5 , 10% ממשלתי שקלי 5+ , 40% ממשלתי צמוד 2-5 , 10% ממשלתי צמוד 5-10 למדד המוצג בטבלה
B18: אפיק קונצרני- מ-50% תל בונד 60 ו50% תל בונד שקלי 50 למדדים המוצגים בטבלה
B21: ***החל מתאריך 24/03/2021 עודכן שיעור החשיפה הצפוי לשנת 2020, להלן השינויים שבוצעו:
B22: שיעור החשיפה הצפויה לאפיק האג''ח הממשלתי עודכן מ - 30% ל - 21%.
B23: שיעור החשיפה הצפויה לאפיק אג''ח קונצרני עודכן מ - 27% ל - 35%.
B24: שיעור החשיפה הצפויה למזומנים עודכן עודכן מ 6% ל-4%
B25: שיעור החשיפה הצפויה למט''ח עודכנה מ-20% ל21%

Sheet גמל להשקעה כללי פאסיבי
B1: =' גמל להשקעה כללי '!B1:H1 -> מדיניות השקעה צפויה לשנת 2021
B2: הלמן-אלדובי להשקעה פאסיבי-כללי
B3: אפיק השקעה | C3: שיעור חשיפה עדכני | D3: שיעור חשיפה צפוי לשנת 2021*** | E3: טווח סטייה %-/+ | F3: גבולות שיעור החשיפה הצפויה | H3: מדד הייחוס (**)
B4: מניות (תעודות סל, אופציות, קרנות נאמנות) | C4: 0.364 | D4: 0.4 | E4: 0.06 | F4: =IF(D4-E4>0,D4-E4,0) -> 0.34 | G4: =D4+E4 -> 0.46 | H4: 0.32 | I4: S&P500
H5: 0.12 | I5: SXXR
H6: 0.08 | I6: MSCI EM
H7: 0.06 | I7: TPX
H8: 0.38 | I8: תל אביב 125
H9: 0.02 | I9: ת"א SME60
H10: 0.02 | I10: BlueStar TA-BIG Tech Israel Tech
B11: אג"ח ממשלתי (צמוד, שקלי ומט"ח), ממשלות זרות בנטרול חשיפות בנגזרים | C11: 0.284 | D11: 0.21 | E11: 0.05 | F11: =IF(D11-E11>0,D11-E11,0) -> 0.16 | G11: =D11+E11 -> 0.26 | H11: 0.2 | I11: משקל גליל 2-5
H12: 0.25 | I12: משקל גליל 5-10
H13: 0.35 | I13: משקל שחר 2-5
H14: 0.2 | I14: +משקל שחר 5
H15: 0.126 | I15: IBOXX HY
H16: 0.072 | I16: IBXXC1D1
H17: 0.045 | I17: JGENUUG
B18: אג"ח קונצרני (קרנות נאמנות, תעודות סל) | C18: 0.3 | D18: 0.35 | E18: 0.06 | F18: =IF((D18-E18)<0,0,D18-E18) -> 0.29 | G18: =D18+E18 -> 0.41 | H18: 0.018 | I18: JCMBCOMP
H19: 0.039 | I19: IBOXIG
H20: 0.32 | I20: משקל תל בונד 60
H21: 0.25 | I21: משקל תל בונד שקלי
H22: 0.1 | I22: משקל תל בונד תשואות
H23: 0.03 | I23: משקל תל בונד תשואות שיקלי
B24: אחר | C24: 0 | D24: 0 | E24: 0.05 | F24: =IF((D24-E24)<0,0,D24-E24) -> 0 | G24: =D24+E24 -> 0.05
B25: מזומנים (*) | C25: 0.053 | D25: 0.04 | H25: 1 | I25: ריבית פח"ק
B26: סה"כ | C26: =SUM(C4:C25) -> 1.001 | D26: =SUM(D4:D25) -> 1
B27: חשיפה למט"ח | C27: 0.204 | D27: 0.21 | E27: 0.06 | F27: =IF(D27-E27>0,D27-E27,0) -> 0.15 | G27: =D27+E27 -> 0.27
B28: * מוצג בנטרול תוספת החשיפה הנובעת מהשקעה בנגזרים
B29: ** מובהר כי תיק הנכסים אינו תואם בהכרח במלואו להרכב מדד הייחוס. אין בציון מדד הייחוס בכדי להוות מצג, הצהרה או התחייבות כלשהי לגבי התשואה שתושג בפועל בתיק
B30: החל מתאריך 24/03/2021 השתנו מדדי הייחוס :
B31: אפיק מנייתי- מ 30% SP500, ו18% STOXX600 , ו13% MSCI EM, ו40% תל אביב 125 למדדים המוצגים בטבלה
B32: אפיק ממשלתי- מ-100% מדד אג''ח ממשלתי כללי למדדים המוצג בטבלה
B33: אפיק קונצרני- מ-50% תל בונד צמודות ו50% תל בונד שקלי 50 למדדים המוצגים בטבלה
B35: ***החל מתאריך 24/03/2021 עודכן שיעור החשיפה הצפוי לשנת 2020, להלן השינויים שבוצעו:
B36: שיעור החשיפה הצפויה לאפיק המנייתי עודכן מ - 33% ל - 40%.
B37: שיעור החשיפה הצפויה לאפיק האג''ח הממשלתי עודכן מ - 35% ל - 21%.
B38: שיעור החשיפה הצפויה לאפיק אג''ח קונצרני עודכן מ - 30% ל - 35%.
B39: שיעור החשיפה הצפויה למזומנים עודכן עודכן מ 2% ל-4%
B40: שיעור החשיפה הצפויה למט''ח עודכנה מ-20% ל21%

Sheet גמל להשקעה - מסלולים מתמחים 
B1: =' גמל להשקעה כללי '!B1:H1 -> מדיניות השקעה צפויה לשנת 2021
B3: מסלולים מתמחים - גמל להשקעה
B4: שם המסלול | C4: מדיניות ההשקעה | D4: מדד ייחוס (*)
B5: הלמן-אלדובי להשקעה, "הלמן-אלדובי גמל להשקעה פסיבי עד 10% במדדי מניות"** | C5: נכסי המסלול יהיו חשופים לנכסים הבאים: אג"ח סחירות ושאינן סחירות של חברות, ני"ע מסחריים, הלוואות שאינן סחירות לחברות, אג"ח להמרה, פקדונות, אג"ח של ממשלת ישראל או אג"ח של ממשלות אחרות. חשיפה לנכסי אג"ח תהיה בשיעור שלא יפחת מ-75% ולא יעלה על 120% מנכסי המסלול. חשיפה למניות תהיה בשיעור שלא יעלה על 15%. חשיפה לנכסים כאמור לעיל תושג הן באמצעות השקעה במישרין והן באמצעות השקעה בנגזרים, בתעודות סל, בקרנות נאמנות או בקרנות השקעה. חשיפה לנכסים שאינם נכסי אג"ח ואינם מניות תהיה על פי שיקול דעתה של ועדת ההשקעות ובכפוף לכל דין. | D5: 0.08 | E5: משקל גליל 2-5
D6: 0.1 | E6: משקל גליל 5-10
D7: 0.14 | E7: משקל שחר 2-5
D8: 0.08 | E8: +משקל שחר 5
D9: 0.1575 | E9: משקל תל בונד 60
D10: 0.1225 | E10: משקל תל בונד שקלי
D11: 0.0525 | E11: משקל תל בונד תשואות
D12: 0.0175 | E12: משקל תל בונד תשואות שקלי
D13: 0.063 | E13: IBOXX HY
D14: 0.036 | E14: IBXXC1D1
D15: 0.0225 | E15: JGENUUG
D16: 0.009 | E16: JCMBCOMP
D17: 0.0195 | E17: IBOXIG
... D22: 0.0084 | E22: MSCI EM
B23: הלמן-אלדובי להשקעה, "הלמן-אלדובי גמל להשקעה פסיבי מדדי מניות"***
D24: 0.31 | E24: S&P500
D25: 0.11 | E25: SXXR
C26: נכסי המסלול, בשיעור שלא יפחת מ-75% ולא יעלה על 100% יושקעו במדדי מניות. יתרת הנכסים, למעט שיעור מהנכסים אשר יושקע במזומנים לצורך טיפול בהפקדות, משיכות והעברות כספים, תושקע במדדים שונים, בכפוף להוראות הדין, ובכפוף לשיקול דעתה של ועדת ההשקעות. | D26: 0.08 | E26: MSCI EM
D27: 0.06 | E27: TPX
D28: 0.36 | E28: תל אביב 125
D29: 0.02 | E29: ת"א SME60
D30: 0.02 | E30: BlueStar TA-BIG Tech Israel Tech
D31: 0.04 | E31: מזומן / פח"ק
B32: הלמן-אלדובי להשקעה, "הלמן-אלדובי להשקעה מניות"**** | C32: נכסי המסלול יהיו חשופים למניות בארץ ובחו"ל, בשיעור חשיפה שלא יפחת מ-75% ולא יעלה על 120% מנכסי המסלול. חשיפה לנכסים כאמור תושג באמצעות השקעה במישרין, בנגזרים, בתעודות סל, בקרנות נאמנות או בקרנות השקעה. יתרת הנכסים תושקע בכפוף להוראות הדין, ובכפוף לשיקול דעתה של ועדת ההשקעות. | E32: 42%- מדד ת"א 125, 58%- MSCI WORLD AC
B33: הלמן-אלדובי להשקעה, "הלמן-אלדובי להשקעה שריעה" | C33: נכסי המסלול יהיו חשופים לנכסים מסוגים שונים בכפוף להוראות הדין ובכפוף לכללי השריעה האסלאמית בלבד. ההשקעות במסלול תהיינה בסמכותה ובאחריותה הבלעדית של ועדת ההשקעות והחברה המנהלת תהיה חייבת לפעול בנאמנות על פי העמיתים במסלול זה. השאת התשואה במסלול מוגבלת בכך שההשקעות בו כפופות לכללי השריעה האסלאמית | E33: 95%- DJSUKUK Index, 5%- MSCI WORLD AC
B34: הלמן-אלדובי להשקעה, "הלמן-אלדובי גמל להשקעה מחקה מדד S&P500" | C34: נכסי המסלול יעקבו אחר מדד S&P500 בשיעור חשיפה של 100% מנכסי המסלול. נכסי המסלול העוקבים אחר המדד כמפורט לעיל יהיו כל נכסי המסלול למעט שיעור מהנכסים אשר יושקע במזומנים לצורך טיפול בהפקדות, משיכות והעברות כספים. | D34: 1 | E34: S&P500
B35: * מובהר כי תיק הנכסים אינו תואם בהכרח במלואו להרכב מדד הייחוס. אין בציון מדד הייחוס בכדי להוות מצג, הצהרה או התחייבות כלשהי לגבי התשואה שתושג בפועל בתיק
B36: ** החל מתאריך 24/03/2021- שונו מדדי הייחוס מsp500- 3% , eurostoxx 600 2% , MSCI EM 1% ,ממשלתי כללי 40% , ת''א 125 4% , תל בונד צמודות 25% ותל בונד שקלי 50 25% למדדי הייחוס המוצגים בטבלה
B37: *** החל מתאריך 24/03/2021- שונו מדדי הייחוס מsp500- 30% , eurostoxx 600 18% , MSCI EM 8%,NIKKEI 4% למדדי הייחוס המוצגים בטבלה
B38: **** החל מתאריך 24/03/2021- שונו מדדי הייחוס מ40% מדד ת''א 125 ו60% מדד MSCI WORLD AC למדדי הייחוס המוצגים בטבלה

Sheet מגן
B1: מדיניות השקעה צפויה לשנת 2021
B2: מגן קרן פנסיה ותיקה
B3: אפיק השקעה | C3: שיעור חשיפה עדכני | D3: שיעור חשיפה צפוי לשנת 2021*** | E3: טווח סטייה %-/+ | F3: גבולות שיעור החשיפה הצפויה | H3: מדד הייחוס (**)
B4: מניות (תעודות סל, אופציות, קרנות נאמנות) | C4: 0.14 | D4: 0.1 | E4: 0.06 | F4: =IF(D4-E4>0,D4-E4,0) -> 0.04 | G4: =D4+E4 -> 0.16 | H4: 42%- מדד ת"א 125 , 58%- MSCI WORLD AC
B5: אג"ח ממשלתי (צמוד, שקלי ומט"ח), ממשלות זרות בנטרול חשיפות בנגזרים | C5: 0.259 | D5: 0.27 | E5: 0.05 | F5: =IF(D5-E5>0,D5-E5,0) -> 0.22 | G5: =D5+E5 -> 0.32 | H5: מדד אג"ח ממשלתי כללי
B6: אג''ח מיועדות | C6: 0.397 | D6: 0.38 | E6: 0.05 | F6: =IF(D6-E6>0,D6-E6,0) -> 0.33 | G6: =D6+E6 -> 0.43
B7: אג"ח קונצרני (קרנות נאמנות, תעודות סל) | C7: 0.102 | D7: 0.13 | E7: 0.06 | F7: =IF(D7-E7>0,D7-E7,0) -> 0.07 | G7: =D7+E7 -> 0.19 | H7: 35% - תל בונד כללי , 20% - תל בונד 60 , 15% - תל בונד 50 , 15% - IBOXX HY - 15%, IBOXX IG
B8: נדל"ן | C8: 0.033 | D8: 0 | E8: 0.05 | F8: =IF(D8-E8>0,D8-E8,0) -> 0 | G8: =D8+E8 -> 0.05
B9: אחר (קרנות השקעה, Co Invest, תשתיות, גידור) | C9: 0.045 | D9: 0.07 | E9: 0.05 | F9: =IF(D9-E9>0,D9-E9,0) -> 0.02 | G9: =D9+E9 -> 0.12
B10: מזומנים (*) | C10: 0.014 | D10: 0.05
B11: סה"כ | C11: =SUM(C4:C10) -> 0.99 | D11: =SUM(D4:D10) -> 1
B12: חשיפה למט"ח | C12: 0.134 | D12: 0.12 | E12: 0.06 | F12: =IF(D12-E12>0,D12-E12,0) -> 0.06 | G12: =D12+E12 -> 0.18
B14: * מוצג בנטרול תוספת החשיפה הנובעת מהשקעה בנגזרים
B15: ** מובהר כי תיק הנכסים אינו תואם בהכרח במלואו להרכב מדד הייחוס. אין בציון מדד הייחוס בכדי להוות מצג, הצהרה או התחייבות כלשהי לגבי התשואה שתושג בפועל בתיק
B16: החל מתאריך 24/03/2021 השתנו מדדי הייחוס :
B17: אפיק מנייתי- מ 40% ת''א 125 ו60% MSCI W למדדים המוצגים בטבלה
B18: אפיק ממשלתי- מ-40% ממשלתי שקלי 2-5 , 10% ממשלתי שקלי 5+ , 40% ממשלתי צמוד 2-5 , 10% ממשלתי צמוד 5-10 למדד המוצג בטבלה
B19: אפיק קונצרני- מ-50% תל בונד 60 ו50% תל בונד שקלי 50 למדדים המוצגים בטבלה
B22: ****החל מתאריך 24/03/2021 עודכן שיעור החשיפה הצפוי לשנת 2020, להלן השינויים שבוצעו:
B23: שיעור החשיפה הצפויה למט''ח עודכנה מ-10% ל12%

Sheet קרן גמלאות של עורכי דין
B1: מדיניות השקעה צפויה לשנת 2021
B2: קרן גמלאות של עורכי דין
B3: אפיק השקעה | C3: שיעור חשיפה עדכני | D3: שיעור חשיפה צפוי לשנת 2021*** | E3: טווח סטייה %-/+ | F3: גבולות שיעור החשיפה הצפויה | H3: מדד הייחוס (**) | I3: מגדל | J3: מנורה
B4: מניות (תעודות סל, אופציות, קרנות נאמנות) | C4: 0.146 | D4: 0.1 | E4: 0.06 | F4: =IF(D4-E4>0,D4-E4,0) -> 0.04 | G4: =D4+E4 -> 0.16 | H4: 42%- מדד ת"א 125 , 58%- MSCI WORLD AC | I4: חשיפה למניות סחיר ולא סחיר | J4: סה"כ מניות (כולל תעודות סל, אופציות וקרנות נאמנות)
B5: אג"ח ממשלתי (צמוד, שקלי ומט"ח), ממשלות זרות בנטרול חשיפות בנגזרים | C5: 0.287 | D5: 0.31 | E5: 0.05 | F5: =IF(D5-E5>0,D5-E5,0) -> 0.26 | G5: =D5+E5 -> 0.36 | H5: מדד אג"ח ממשלתי כללי | I5: חשיפה לאגח ממשלתי (כולל אגח ממשלות זרות) | J5: *מיועדות
B6: אג''ח מיועדות | C6: 0.391 | D6: 0.38 | E6: 0.05 | F6: =IF(D6-E6>0,D6-E6,0) -> 0.33 | G6: =D6+E6 -> 0.43
B7: אג"ח קונצרני (קרנות נאמנות, תעודות סל) | C7: 0.073 | D7: 0.11 | E7: 0.06 | F7: =IF(D7-E7>0,D7-E7,0) -> 0.05 | G7: =D7+E7 -> 0.17 | H7: 35% - תל בונד כללי , 20% - תל בונד 60 , 15% - תל בונד 50 , 15% - IBOXX HY - 15%, IBOXX IG | I7: חשיפה לאגח קונצרני סחיר ולא סחיר (כולל בחו"ל וכולל הלוואות) | J7: אג"ח קונצרני
B8: נדל"ן | C8: 0.013 | D8: 0 | E8: 0.05 | F8: =IF(D8-E8>0,D8-E8,0) -> 0 | G8: =D8+E8 -> 0.05 | I8: אחר | J8: פקדונות ארוכים בבנקים
B9: אחר (קרנות השקעה, Co Invest, תשתיות, גידור) | C9: 0.035 | D9: 0.05 | E9: 0.05 | F9: =IF(D9-E9>0,D9-E9,0) -> 0 | G9: =D9+E9 -> 0.1 | I9: סה"כ | J9: קרנות השקעה ללא קרנות נדל"ן
B10: מזומנים (*) | C10: 0.043 | D10: 0.05 | I10: חשיפה למטח | J10: ***סה"כ אחר ומזומן
B11: סה"כ | C11: =SUM(C4:C10) -> 0.988 | D11: =SUM(D4:D10) -> 1 | J11: סה"כ תיק
B12: חשיפה למט"ח | C12: 0.121 | D12: 0.12 | E12: 0.06 | F12: =IF(D12-E12>0,D12-E12,0) -> 0.06 | G12: =D12+E12 -> 0.18 | J12: חשיפה למט"ח
B14: * מוצג בנטרול תוספת החשיפה הנובעת מהשקעה בנגזרים
B15: ** מובהר כי תיק הנכסים אינו תואם בהכרח במלואו להרכב מדד הייחוס. אין בציון מדד הייחוס בכדי להוות מצג, הצהרה או התחייבות כלשהי לגבי התשואה שתושג בפועל בתיק
B16: החל מתאריך 24/03/2021 השתנו מדדי הייחוס :
B17: אפיק מנייתי- מ 40% ת''א 125 ו60% MSCI W למדדים המוצגים בטבלה
B18: אפיק ממשלתי- מ-40% ממשלתי שקלי 2-5 , 10% ממשלתי שקלי 5+ , 40% ממשלתי צמוד 2-5 , 10% ממשלתי צמוד 5-10 למדד המוצג בטבלה
B19: אפיק קונצרני- מ-50% תל בונד 60 ו50% תל בונד שקלי 50 למדדים המוצגים בטבלה
B22: ***החל מתאריך 24/03/2021 עודכן שיעור החשיפה הצפוי לשנת 2020, להלן השינויים שבוצעו:
B23: שיעור החשיפה הצפויה לאפיק האג''ח הממשלתי עודכן מ - 29% ל - 31%.
B24: שיעור החשיפה הצפויה למט''ח עודכנה מ-10% ל12%
