Workbook
Name Additional_Factor: 'אפשרויות בחירה'!$C$701:$C$850
Name Amoritization: 'אפשרויות בחירה'!$C$546:$C$550
Name Capsule: 'אפשרויות בחירה'!$C$926:$C$928
Name Company_Name: 'File Name Info'!$A$34:$A$120
Name Company_Name_ID: 'File Name Info'!$A$34:$B$120
Name Consortium: 'אפשרויות בחירה'!$C$514:$C$515
Name Country_list: 'אפשרויות בחירה'!$C$4:$C$85
Name Country_list_funds: 'אפשרויות בחירה'!$C$4:$C$103
Name CSA: 'אפשרויות בחירה'!$C$688:$C$689
Name Delivery: 'אפשרויות בחירה'!$C$666:$C$667
Name Dependence_Independence: 'אפשרויות בחירה'!$C$654:$C$655
Name Duration_Underlying_Interest_Rate: 'אפשרויות בחירה'!$C$680:$C$687
Name File_Type: 'File Name Info'!$A$10:$A$12
Name Full_File_Type: 'File Name Info'!$A$11:$B$13
Name Full_Type: 'File Name Info'!$A$2:$B$8
Name Full_Type_Nostro: 'File Name Info'!$A$3:$B$6
Name Full_Year: 'File Name Info'!$A$22:$B$31
Name Fund_Strategy: 'אפשרויות בחירה'!$C$597:$C$621
Name Fund_type: 'אפשרויות בחירה'!$C$328:$C$498
Name Holding_interest: 'אפשרויות בחירה'!$C$146:$C$147
Name In_the_books: 'אפשרויות בחירה'!$C$656:$C$657
Name Industry_Sector: 'אפשרויות בחירה'!$C$1129:$C$1245
Name Industry_sector_all: 'אפשרויות בחירה'!$C$202:$C$327
Name Industry_sectors: 'אפשרויות בחירה'!$C$202:$C$327
Name israel_abroad: 'אפשרויות בחירה'!$C$2:$C$3
Name Issuer_Number_Banks: 'אפשרויות בחירה'!$C$111:$C$113
Name Issuer_Number_Fund: 'אפשרויות בחירה'!$C$114:$C$117
Name issuer_number_loan: 'אפשרויות בחירה'!$C$118:$C$126
Name Issuer_Number_Type: 'אפשרויות בחירה'!$C$104:$C$110
Name Issuer_Number_Type_2: 'אפשרויות בחירה'!$C$1076:$C$1079
Name Issuer_Number_Type_3: 'אפשרויות בחירה'!$C$1081:$C$1085
Name Issuer_Number_Type_V2: 'אפשרויות בחירה'!$C$104:$C$110
Name Issuer_Type_TFunds: 'אפשרויות בחירה'!$C$1087:$C$1089
Name Leading_factor: 'אפשרויות בחירה'!$C$692:$C$700
Name Linked_Type: 'אפשרויות בחירה'!$C$516:$C$519
Name other_investments: 'אפשרויות בחירה'!$C$1000:$C$1033
Name Penalty: 'אפשרויות בחירה'!$C$851:$C$852
Name QTR: 'File Name Info'!$A$15:$A$19
Name Rating_Agency: 'אפשרויות בחירה'!$C$188:$C$201
Name real_estate_lifestage: 'אפשרויות בחירה'!$C$634:$C$642
Name real_estate_loans: 'אפשרויות בחירה'!$C$553:$C$591
Name Real_Estate_Main_Use: 'אפשרויות בחירה'!$C$622:$C$633
Name Recourse_Nonrecourse: 'אפשרויות בחירה'!$C$544:$C$545
Name Repayment_Rights: 'אפשרויות בחירה'!$C$551:$C$552
Name Reset_frequency: 'אפשרויות בחירה'!$C$658:$C$665
Name Security_ID_Number_Type: 'אפשרויות בחירה'!$C$1113:$C$1116
Name Security_Number_Loans: 'אפשרויות בחירה'!$C$131
Name Stock_Exchange: 'אפשרויות בחירה'!$C$1283:$C$1315
Name Stock_Exchange_Gov_Bonds: 'אפשרויות בחירה'!$C$148:$C$181
Name Subordination_Risk: 'אפשרויות בחירה'!$C$186:$C$187
Name Tradeable_Status: 'אפשרויות בחירה'!$C$1272:$C$1281
Name Tradeable_Status_All: 'אפשרויות בחירה'!$C$135:$C$145
Name tradeable_status_bonds: 'אפשרויות בחירה'!$C$1248:$C$1253
Name tradeable_status_funds: 'אפשרויות בחירה'!$C$1118:$C$1119
Name tradeable_status_stock: 'אפשרויות בחירה'!$C$1255:$C$1259
Name Tradeable_Status_v2: 'אפשרויות בחירה'!$C$1121:$C$1126
Name tradeable_status_warrants: 'אפשרויות בחירה'!$C$1261:$C$1265
Name tradeable_status_warrants_v2: 'אפשרויות בחירה'!$C$1267:$C$1269
Name Transaction: 'אפשרויות בחירה'!$C$643:$C$646
Name Type: 'File Name Info'!$A$2:$A$8

Sheet עמוד פתיחה
A1: קובץ דיווח עבור רשימת נכסים ברמת הנכס הבודד (חוזר גופים מוסדיים 2015-9-14)
A3: יש לבחור תחום: | D3: נכסי עמיתים - קופות גמל
A5: האם מדובר בקובץ לממומנה או לציבור: | D5: לציבור
A7: יש לבחור את רבעון הדיווח: | D7: 02
A9: יש לבחור את שנת הדיווח: | D9: 2025
A11: יש לבחור את הגוף המוסדי: | D11: חברה לניהול קופות גמל של העובדים בעיריית תל - אביב יפו בע"מ
A13: ח.פ. הגוף המוסדי: | D13: =IFERROR(VLOOKUP(D11,'File Name Info'!A35:B121,2,0),"תא מחושב") -> 513452003
A15: שם קובץ לשמירה | D15: =IF(D5="לממונה",CONCATENATE(D13, "_",VLOOKUP(D3,Full_Type,2,0),"_",D7,VLOOKUP(D9,Full_Year,2,0),".xlxs"),IF(D5="לציבור",CONCATENATE(D13,"_",VLOOKUP(D3,Full_Type_Nostro,2,0),"_",VLOOKUP(D5,Full_File_Type,2,0),"_",D7,VLOOKUP(D9,Full_Year,2,0),".xlsx"),"שם קובץ לשמירה")) -> 513452003_gm_p_0225.xlsx
A17: פרטי האחראי על הדיווח בגוף המוסדי | B17: שם: | D17: צביקה שמיר , מנכ"ל
B19: מספר טלפון: | D19: 03-5210603
B21: כתובת מייל: | D21: zvi-sha@ovdim-tlv.org.il

Sheet סכום נכסים
C1: ידווח בקבצי נכסי הנוסטרו בלבד
B2: שווי הוגן | C2: עלות מופחתת | D2: השיטה שיושמה בדוח הכספי | E2: שיעור מסך נכסי השקעה
A3: מזומנים ושווי מזומנים | B3: =SUM('מזומנים ושווי מזומנים'!O:O) -> 4743.67 | E3: =SUM('מזומנים ושווי מזומנים'!O:O)/B29 -> 0.030567204
A4: איגרות חוב ממשלתיות | B4: =SUM('איגרות חוב ממשלתיות'!U:U) -> 29527.347 | E4: =SUM('איגרות חוב ממשלתיות'!U:U)/B29 -> 0.19026796
A5: ניירות ערך מסחריים | B5: =SUM('ניירות ערך מסחריים'!AD:AD) -> 0 | E5: =SUM('ניירות ערך מסחריים'!AD:AD)/B29 -> 0
A6: איגרות חוב | B6: =SUM('איגרות חוב'!AD:AD) -> 27965.09 | E6: =SUM('איגרות חוב'!AD:AD)/B29 -> 0.18020111
A7: מניות, מניות בכורה ויחידות השתתפות | B7: =SUM('מניות מבכ ויהש'!U:U) -> 32927.007 | E7: =SUM('מניות מבכ ויהש'!U:U)/B29 -> 0.21217465
A8: קרנות סל | B8: =SUM('קרנות סל'!T:T) -> 31331.432 | E8: =SUM('קרנות סל'!T:T)/B29 -> 0.2018931
A9: קרנות נאמנות | B9: =SUM('קרנות נאמנות'!T:T) -> 1019.059 | E9: =SUM('קרנות נאמנות'!T:T)/B29 -> 0.0065666001
A10: כתבי אופציה | B10: =SUM('כתבי אופציה'!W:W) -> 37.714 | E10: =SUM('כתבי אופציה'!W:W)/B29 -> 0.00024302102
A11: חוזים עתידיים | B11: =SUM('חוזים עתידיים'!R:R) -> 477.517 | E11: =SUM('חוזים עתידיים'!R:R)/B29 -> 0.0030770183
A12: מוצרים מובנים | B12: =SUM('מוצרים מובנים'!Z:Z) -> 0 | E12: =SUM('מוצרים מובנים'!Z:Z)/B29 -> 0
A13: לא סחיר איגרות חוב ממשלתיות | B13: =SUM('לא סחיר איגרות חוב ממשלתיות'!U:U) -> 0 | E13: =SUM('לא סחיר איגרות חוב ממשלתיות'!U:U)/B29 -> 0
A14: לא סחיר איגרות חוב מיועדות | B14: =SUM('לא סחיר איגרות חוב מיועדות'!N:N) -> 0 | E14: =SUM('לא סחיר איגרות חוב מיועדות'!N:N)/B29 -> 0
A15: אפיק השקעה מובטח תשואה | B15: =SUM('אפיק השקעה מובטח תשואה'!F:F) -> 0 | E15: =SUM('אפיק השקעה מובטח תשואה'!F:F)/B29 -> 0
A16: לא סחיר ניירות ערך מסחריים | B16: =SUM('לא סחיר ניירות ערך מסחריים'!AI:AI) -> 0 | E16: =SUM('לא סחיר ניירות ערך מסחריים'!AI:AI)/B29 -> 0
A17: לא סחיר איגרות חוב | B17: =SUM('לא סחיר איגרות חוב'!AG:AG) -> 1748.616 | E17: =SUM('לא סחיר איגרות חוב'!AG:AG)/B29 -> 0.011267711
A18: לא סחיר מניות, מניות בכורה ויחידות השתתפות | B18: =SUM('לא סחיר מניות מבכ ויהש'!X:X) -> 1924.192 | E18: =SUM('לא סחיר מניות מבכ ויהש'!X:X)/B29 -> 0.012399085
A19: קרנות השקעה | B19: =SUM('קרנות השקעה'!W:W) -> 22490.382 | E19: =SUM('קרנות השקעה'!W:W)/B29 -> 0.14492325
A20: לא סחיר כתבי אופציה | B20: =SUM('לא סחיר כתבי אופציה'!Z:Z) -> 0 | E20: =SUM('לא סחיר כתבי אופציה'!Z:Z)/B29 -> 0
A21: לא סחיר אופציות | B21: =SUM('לא סחיר אופציות'!Z:Z) -> 0 | E21: =SUM('לא סחיר אופציות'!Z:Z)/B29 -> 0
A22: לא סחיר נגזרים אחרים | B22: =SUM('לא סחיר נגזרים אחרים'!R:R) -> 1146.421 | E22: =SUM('לא סחיר נגזרים אחרים'!R:R)/B29 -> 0.0073872939
A23: הלוואות | B23: =SUM(הלוואות!AT:AT) -> 0 | E23: =SUM(הלוואות!AT:AT)/B29 -> 0
A24: לא סחיר מוצרים מובנים | B24: =SUM('לא סחיר מוצרים מובנים'!AB:AB) -> 0 | E24: =SUM('לא סחיר מוצרים מובנים'!AB:AB)/B29 -> 0
A25: פיקדונות מעל 3 חודשים | B25: =SUM('פיקדונות מעל 3 חודשים'!T:T) -> 0 | E25: =SUM('פיקדונות מעל 3 חודשים'!T:T)/B29 -> 0
A26: זכויות מקרקעין | B26: =SUM('זכויות מקרקעין'!S:S) -> 0 | E26: =SUM('זכויות מקרקעין'!S:S)/B29 -> 0
A27: השקעה בחברות מוחזקות | B27: =SUM('השקעה בחברות מוחזקות'!U:U) -> 0 | E27: =SUM('השקעה בחברות מוחזקות'!U:U)/B29 -> 0
A28: נכסים אחרים | B28: =SUM('נכסים אחרים'!N:N) -> -150.22495 | E28: =SUM('נכסים אחרים'!N:N)/B29 -> -0.00096801773
A29: סך הכל נכסים | B29: =IF(SUM(B3:B28)=0,0.0001,SUM(B3:B28)) -> 155188.22 | C29: 0 | D29: 0 | E29: =SUM(E3:E28) -> 1
A30: מסגרות אשראי
A31: יתרות התחייבויות להשקעה | B31: =SUM('יתרות התחייבות להשקעה'!O:O) -> 6394.0616 | E31: =B31/B29 -> 0.041201978

Sheet מזומנים ושווי מזומנים
A1: מספר קופה/קרן/ח.פ. עבור חברת ביטוח | B1: מספר מסלול | C1: שם הבנק | D1: מספר מזהה בנק | E1: סוג מספר מזהה בנק | F1: מאפיין עיקרי | G1: ישראל/חו"ל | H1: בעל עניין/צד קשור | I1: דירוג הבנק | J1: שם מדרג | K1: מטבע פעילות | L1: שווי מטבעי | M1: שער חליפין | N1: שיעור ריבית | O1: שווי הוגן (באלפי ש"ח) | P1: שיעור מנכסי אפיק ההשקעה | Q1: שיעור מסך נכסי ההשקעה
A2: 891 | B2: 9956 | C2: בנק לאומי לישראל בע"מ | D2: 10-800 | E2: סימול בנק | F2: מזומן ועו"ש בש"ח | G2: ישראל | H2: לא | I2: AAA | J2: S&P מעלות | K2: ILS | L2: 0 | M2: 1 | N2: 0 | O2: 0 | P2: 1 | Q2: 1
A3: 891 | B3: 9957 | C3: בנק לאומי לישראל בע"מ | D3: 10-800 | E3: סימול בנק | F3: מזומן ועו"ש בש"ח | G3: ישראל | H3: לא | I3: AAA | J3: S&P מעלות | K3: ILS | L3: 236.673 | M3: 1 | N3: 0.0403 | O3: 236.673 | P3: 0.049892312 | Q3: 0.0015363917
A4: 891 | B4: 9957 | C4: פועלים | D4: 12-591 | E4: סימול בנק | F4: מזומן ועו"ש נקוב במט"ח | G4: ישראל | H4: לא | I4: AAA | J4: S&P מעלות | K4: USD | L4: 694.231 | M4: 3.372 | N4: SOFR-1.5% | O4: 2340.946 | P4: 0.49348854 | Q4: 0.015196564
A5: 891 | B5: 9957 | C5: פועלים | D5: 12-591 | E5: סימול בנק | F5: מזומן ועו"ש נקוב במט"ח | G5: ישראל | H5: לא | I5: AAA | J5: S&P מעלות | K5: HKD | L5: 0.001 | M5: 0.429 | N5: 0 | O5: 0.001 | P5: 1.1015147e-07 | Q5: 3.3920217e-09
A6: 891 | B6: 9957 | C6: פועלים | D6: 12-591 | E6: סימול בנק | F6: מזומן ועו"ש נקוב במט"ח | G6: ישראל | H6: לא | I6: AAA | J6: S&P מעלות | K6: EUR | L6: 262.551 | M6: 3.9552 | N6: 0 | O6: 1038.441 | P6: 0.21891091 | Q6: 0.0067411769
A7: 891 | B7: 9957 | C7: פועלים | D7: 12-591 | E7: סימול בנק | F7: מזומן ועו"ש נקוב במט"ח | G7: ישראל | H7: לא | I7: AAA | J7: S&P מעלות | K7: JPY | L7: 183.401 | M7: 0.023369 | N7: 0 | O7: 4.286 | P7: 0.00090350077 | Q7: 2.7822544e-05
A8: 891 | B8: 9957 | C8: פועלים | D8: 12-591 | E8: סימול בנק | F8: מזומן ועו"ש נקוב במט"ח | G8: ישראל | H8: לא | I8: AAA | J8: S&P מעלות | K8: DKK | L8: 0 | M8: 0.5301 | N8: 0 | O8: 0 | P8: -1.1174897e-09 | Q8: -3.4412153e-11
A9: 891 | B9: 9957 | C9: פועלים | D9: 12-591 | E9: סימול בנק | F9: מזומן ועו"ש נקוב במט"ח | G9: חו"ל | H9: לא | I9: AAA | J9: S&P מעלות | K9: sek | L9: 0 | M9: 0.355 | N9: 0 | O9: 0 | P9: -7.4836605e-10 | Q9: -2.3045302e-11
A10: 891 | B10: 9957 | C10: פועלים | D10: 12-591 | E10: סימול בנק | F10: מזומן ועו"ש נקוב במט"ח | G10: ישראל | H10: לא | I10: AAA | J10: S&P מעלות | K10: GBP | L10: 12.772 | M10: 4.6236 | N10: 0 | O10: 59.053 | P10: 0.012448774 | Q10: 0.00038334951
A11: 891 | B11: 9957 | C11: פועלים | D11: 12-591 | E11: סימול בנק | F11: מזומן ועו"ש בש"ח | G11: ישראל | H11: לא | I11: AAA | J11: S&P מעלות | K11: ILS | L11: 982.895 | M11: 1 | N11: 0 | O11: 982.895 | P11: 0.20720151 | Q11: 0.0063805957
A12: 891 | B12: 9957 | C12: פועלים | D12: 12-591 | E12: סימול בנק | F12: מזומן ועו"ש נקוב במט"ח | G12: ישראל | H12: לא | I12: AAA | J12: S&P מעלות | K12: CHF | L12: 19.231 | M12: 4.2314 | N12: 0 | O12: 81.375 | P12: 0.017154346 | Q12: 0.00052825361
A13: 891 | B13: 9958 | C13: בנק לאומי לישראל בע"מ | D13: 10-800 | E13: סימול בנק | F13: מזומן ועו"ש בש"ח | G13: ישראל | H13: לא | I13: AAA | J13: S&P מעלות | K13: ILS | L13: 0 | M13: 1 | N13: 0 | O13: 0 | P13: 1 | Q13: 1

Sheet איגרות חוב ממשלתיות
A1: מספר קופה/קרן/ח.פ. עבור חברת ביטוח | B1: מספר מסלול | C1: שם מנפיק | D1: שם נייר ערך | E1: מספר נייר ערך | F1: מאפיין עיקרי | G1: ישראל/חו"ל | H1: מדינה לפי חשיפה כלכלית | I1: זירת מסחר | J1: דירוג | K1: שם מדרג | L1: מטבע פעילות | M1: מח"מ | N1: מועד פדיון | O1: שיעור ריבית | P1: תשואה לפדיון | Q1: סכום לקבל (במטבע הפעילות) | R1: ערך נקוב (יחידות) | S1: שער חליפין | T1: שער נייר הערך | U1: שווי הוגן (באלפי ש"ח) | V1: עלות מופחתת (באלפי ש"ח) | W1: השיטה שיושמה בדוח הכספי | X1: שיעור מערך נקוב מונפק | Y1: שיעור מנכסי אפיק ההשקעה | Z1: שיעור מסך נכסי ההשקעה
A2: 891 | B2: 9957 | C2: גליל | D2: ממשל צמודה 0527 | E2: IL0011408478 | F2: צמוד למדד המחירים לצרכן בריבית קבועה | G2: ישראל | H2: ישראל | I2: TASE | J2: RF | K2: פנימי | L2: ILS | M2: 1.905 | N2: 31/05/2027 | O2: 0.0075 | P2: 0.02096 | R2: 2122291 | S2: 1 | T2: 115.45 | U2: 2450.185 | W2: שווי הוגן | X2: 8.7e-05 | Y2: 0.082980193 | Z2: 0.015905705
A3: 891 | B3: 9957 | C3: גליל | D3: ממשל צמודה 0545 | E3: IL0011348658 | F3: צמוד למדד המחירים לצרכן בריבית קבועה | G3: ישראל | H3: ישראל | I3: TASE | J3: RF | K3: פנימי | L3: ILS | M3: 17.932 | N3: 31/05/2045 | O3: 0.01 | P3: 0.02023 | R3: 1000000 | S3: 1 | T3: 98.54 | U3: 985.4 | W3: שווי הוגן | X3: 4.4e-05 | Y3: 0.033372453 | Z3: 0.0063968564
A4: 891 | B4: 9957 | C4: גליל | D4: ממשל צמודה 1025 | E4: IL0011359127 | F4: צמוד למדד המחירים לצרכן בריבית קבועה | G4: ישראל | H4: ישראל | I4: TASE | J4: RF | K4: פנימי | L4: ILS | M4: 0.332 | N4: 31/10/2025 | O4: 0.0075 | P4: 0.00599 | R4: 2029976 | S4: 1 | T4: 118.26 | U4: 2400.65 | W4: שווי הוגן | X4: 0.00016 | Y4: 0.081302584 | Z4: 0.015584139
A5: 891 | B5: 9957 | C5: שחר | D5: ממשל שיקלית 0928 | E5: IL0011508798 | F5: לא צמוד למדד המחירים לצרכן ריבית קבועה | G5: ישראל | H5: ישראל | I5: TASE | J5: RF | K5: פנימי | L5: ILS | M5: 3.109 | N5: 28/09/2028 | O5: 0.0225 | P5: 0.03952 | R5: 1521608 | S5: 1 | T5: 96.6 | U5: 1469.873 | W5: שווי הוגן | X5: 4.4e-05 | Y5: 0.049780067 | Z5: 0.00954188
A6: 891 | B6: 9957 | C6: שחר | D6: ממשל שקלית 0927 | E6: IL0012035791 | F6: לא צמוד למדד המחירים לצרכן ריבית קבועה | G6: ישראל | H6: ישראל | I6: TASE | J6: RF | K6: פנימי | L6: ILS | M6: 2.139 | N6: 30/09/2027 | O6: 0.0375 | P6: 0.03974 | R6: 2062192 | S6: 1 | T6: 102.34 | U6: 2110.447 | W6: שווי הוגן | X6: 5.8e-05 | Y6: 0.071474328 | Z6: 0.013700252
A7: 891 | B7: 9957 | C7: שחר | D7: ממשל שקלית 0229 | E7: IL0011948028 | F7: לא צמוד למדד המחירים לצרכן ריבית קבועה | G7: ישראל | H7: ישראל | I7: TASE | J7: RF | K7: פנימי | L7: ILS | M7: 3.45 | N7: 28/02/2029 | O7: 0.0375 | P7: 0.03943 | R7: 1975189 | S7: 1 | T7: 100.61 | U7: 1987.238 | W7: שווי הוגן | X7: 5.6e-05 | Y7: 0.067301598 | Z7: 0.01290042
A8: 891 | B8: 9957 | C8: שחר | D8: ממשל שקלית 0335 | E8: IL0012023326 | F8: לא צמוד למדד המחירים לצרכן ריבית קבועה | G8: ישראל | H8: ישראל | I8: TASE | J8: RF | K8: פנימי | L8: ILS | M8: 8.174 | N8: 30/03/2035 | O8: 0.04 | P8: 0.04114 | R8: 5725974 | S8: 1 | T8: 100.1 | U8: 5731.7 | W8: שווי הוגן | X8: 0.000172 | Y8: 0.19411497 | Z8: 0.0372081
A9: 891 | B9: 9957 | C9: שחר | D9: ממשל שקלית 0347 | E9: IL0011401937 | F9: לא צמוד למדד המחירים לצרכן ריבית קבועה | G9: ישראל | H9: ישראל | I9: TASE | J9: RF | K9: פנימי | L9: ILS | M9: 14.709 | N9: 31/03/2047 | O9: 0.0375 | P9: 0.0447 | R9: 595000 | S9: 1 | T9: 91.05 | U9: 541.747 | W9: שווי הוגן | X9: 2.3e-05 | Y9: 0.018347314 | Z9: 0.0035168266
A10: 891 | B10: 9957 | C10: שחר | D10: ממשלתי שקלית 0142 | E10: IL0011254005 | F10: לא צמוד למדד המחירים לצרכן ריבית קבועה | G10: ישראל | H10: ישראל | I10: TASE | J10: RF | K10: פנימי | L10: ILS | M10: 11.421 | N10: 31/01/2042 | O10: 0.055 | P10: 0.04352 | R10: 5814603 | S10: 1 | T10: 115.63 | U10: 6723.425 | W10: שווי הוגן | X10: 0.000202 | Y10: 0.22770164 | Z10: 0.043646019
A11: 891 | B11: 9957 | C11: גליל | D11: ממשלתית צמודה 0726 | E11: IL0011695645 | F11: צמוד למדד המחירים לצרכן בריבית קבועה | G11: ישראל | H11: ישראל | I11: TASE | J11: RF | K11: פנימי | L11: ILS | M11: 1.078 | N11: 31/07/2026 | O11: 0.001 | P11: 0.02338 | R11: 265000 | S11: 1 | T11: 114.5 | U11: 303.425 | W11: שווי הוגן | X11: 1.3e-05 | Y11: 0.010276067 | Z11: 0.0019697241
A12: 891 | B12: 9957 | C12: שחר | D12: ממשלתית שקלית 0537 | E12: IL0011661803 | F12: לא צמוד למדד המחירים לצרכן ריבית קבועה | G12: ישראל | H12: ישראל | I12: TASE | J12: RF | K12: פנימי | L12: ILS | M12: 10.803 | N12: 31/05/2037 | O12: 0.015 | P12: 0.04253 | R12: 560815 | S12: 1 | T12: 74.8 | U12: 419.49 | W12: שווי הוגן | X12: 1.5e-05 | Y12: 0.014206817 | Z12: 0.0027231732
A13: 891 | B13: 9957 | C13: שחר | D13: ממשלתית שקלית 1.00% 03/30 | E13: IL0011609851 | F13: לא צמוד למדד המחירים לצרכן ריבית קבועה | G13: ישראל | H13: ישראל | I13: TASE | J13: RF | K13: פנימי | L13: ILS | M13: 4.641 | N13: 31/03/2030 | O13: 0.01 | P13: 0.03969 | R13: 3037907 | S13: 1 | T13: 87.63 | U13: 2662.118 | W13: שווי הוגן | X13: 8e-05 | Y13: 0.090157707 | Z13: 0.017281496
A14: 891 | B14: 9957 | C14: שחר | D14: ממשלתית שקלית 1.3% 04/32 | E14: IL0011806606 | F14: לא צמוד למדד המחירים לצרכן ריבית קבועה | G14: ישראל | H14: ישראל | I14: TASE | J14: RF | K14: פנימי | L14: ILS | M14: 6.538 | N14: 30/04/2032 | O14: 0.013 | P14: 0.04048 | R14: 2070926 | S14: 1 | T14: 84.1 | U14: 1741.649 | W14: שווי הוגן | X14: 5.8e-05 | Y14: 0.058984262 | Z14: 0.011306147

Sheet ניירות ערך מסחריים
A1: מספר קופה/קרן/ח.פ. עבור חברת ביטוח | B1: מספר מסלול | C1: שם מנפיק | D1: מספר מנפיק | E1: סוג מספר מזהה מנפיק | F1: שם נייר ערך | G1: מספר נייר ערך | H1: סוג מספר נייר ערך | I1: מאפיין עיקרי | J1: ישראל/חו"ל | K1: מדינה לפי חשיפה כלכלית | L1: זירת מסחר | M1: ענף מסחר | N1: בעל עניין/צד קשור | O1: דירוג | P1: שם מדרג | Q1: דירוג נייר הערך/המנפיק | R1: מטבע פעילות | S1: מח"מ | T1: ריבית עוגן | U1: מועד פדיון | V1: שיעור ריבית | W1: תשואה לפדיון | X1: נחיתות חוזית | Y1: האם סווג כחוב בעייתי | Z1: ערך נקוב (יחידות) | AA1: שער חליפין | AB1: שער נייר הערך | AC1: סכום לקבל (במטבע הפעילות) | AD1: שווי הוגן (באלפי ש"ח) | AE1: עלות מופחתת (באלפי ש"ח) | AF1: עלות מופחתת (במטבע הפעילות) | AG1: השיטה שיושמה בדוח הכספי | AH1: שיעור מערך נקוב מונפק | AI1: שיעור מנכסי אפיק ההשקעה | AJ1: שיעור מסך נכסי ההשקעה
A2: 891 | B2: 9957

Sheet איגרות חוב
A1: מספר קופה/קרן/ח.פ. עבור חברת ביטוח | B1: מספר מסלול | C1: שם מנפיק | D1: מספר מנפיק | E1: סוג מספר מזהה מנפיק | F1: שם נייר ערך | G1: מספר נייר ערך | H1: סוג מספר נייר ערך | I1: מאפיין עיקרי | J1: ישראל/חו"ל | K1: מדינה לפי חשיפה כלכלית | L1: סטאטוס סחירות | M1: זירת מסחר | N1: ענף מסחר | O1: בעל עניין/צד קשור | P1: דירוג | Q1: שם מדרג | R1: דירוג נייר הערך/המנפיק | S1: מטבע פעילות | T1: מח"מ | U1: מועד פדיון | V1: שיעור ריבית | W1: תשואה לפדיון | X1: נחיתות חוזית | Y1: האם סווג כחוב בעייתי | Z1: ערך נקוב (יחידות) | AA1: שער חליפין | AB1: שער נייר הערך | AC1: סכום לקבל (במטבע הפעילות) | AD1: שווי הוגן (באלפי ש"ח) | AE1: עלות מופחתת (באלפי ש"ח) | AF1: עלות מופחתת (במטבע הפעילות) | AG1: השיטה שיושמה בדוח הכספי | AH1: שיעור מערך נקוב מונפק | AI1: שיעור מנכסי אפיק ההשקעה | AJ1: שיעור מסך נכסי ההשקעה
A2: 891 | B2: 9957 | C2: לוויתן בונד בע"מ | D2: 516223864 | E2: ח.פ | F2: LVIATH 6.125% 6/25 | G2: IL0011677742 | H2: ISIN | I2: צמוד למט"ח | J2: חו"ל | K2: ישראל | L2: סחיר | M2: אחר | N2: חיפושי נפט וגז | O2: לא | P2: BB- | Q2: S&P | R2: נייר ערך | S2: USD | T2: 0.133 | U2: 30/06/2025 | V2: 0.06125 | W2: 0.23773 | X2: החוב לא נחות | Y2: לא | Z2: 0 | AA2: 3.372 | AB2: 0 | AC2: 1.296 | AD2: 4.372 | AG2: שווי הוגן | AH2: 0 | AI2: 0.00015632453 | AJ2: 2.8379501e-05
A3: 891 | B3: 9957 | C3: אאורה השקעות בע"מ | D3: 520038274 | E3: ח.פ | F3: אאורה אגח טז | G3: IL0037305799 | H3: ISIN | I3: לא צמוד למדד המחירים לצרכן | J3: ישראל | K3: ישראל | L3: סחיר | M3: TASE | N3: בנייה | O3: לא | P3: A2 | Q3: מידרוג Moodys | R3: נייר ערך | S3: ILS | T3: 1.207 | U3: 30/09/2027 | V3: 0.035 | W3: 0.04885 | X3: החוב לא נחות | Y3: לא | Z3: 155124 | AA3: 1 | AB3: 99.31 | AD3: 154.054 | AG3: שווי הוגן | AH3: 0.001116 | AI3: 0.0055087845 | AJ3: 0.0010000769
A4: 891 | B4: 9957 | C4: אאורה השקעות בע"מ | D4: 520038274 | E4: ח.פ | F4: אאורה אגח יז %3.85 31/01/2029 | G4: IL0011935801 | H4: ISIN | I4: צמוד למדד המחירים לצרכן | J4: ישראל | K4: ישראל | L4: סחיר | M4: TASE | N4: בנייה | O4: לא | P4: A2 | Q4: מידרוג Moodys | R4: נייר ערך | S4: ILS | T4: 2.116 | U4: 31/01/2029 | V4: 0.0385 | W4: 0.03237 | X4: החוב לא נחות | Y4: לא | Z4: 245000 | AA4: 1 | AB4: 111.11 | AD4: 272.219 | AG4: שווי הוגן | AH4: 0.000817 | AI4: 0.0097342621 | AJ4: 0.0017671795
A5: 891 | B5: 9957 | C5: אדמה פתרונות לחקלאות בע"מ | D5: 520043605 | E5: ח.פ | F5: אדמה אגח ב | G5: IL0011109159 | H5: ISIN | I5: צמוד למדד המחירים לצרכן | J5: ישראל | K5: ישראל | L5: סחיר | M5: TASE | N5: כימיה, גומי ופלסטיק | O5: לא | P5: AA- | Q5: S&P מעלות | R5: נייר ערך | S5: ILS | T5: 5.037 | U5: 30/11/2036 | V5: 0.0515 | W5: 0.04176 | X5: החוב לא נחות | Y5: לא | Z5: 0.22 | AA5: 1 | AB5: 148.91 | AD5: 0 | AG5: שווי הוגן | AH5: 0 | AI5: 1.1714678e-08 | AJ5: 2.1267085e-09
A6: 891 | B6: 9957 | C6: או.פי.סי. אנרגיה בע"מ | D6: 514401702 | E6: ח.פ | F6: או פי סי אגח ב' | G6: IL0011660573 | H6: ISIN | I6: צמוד למדד המחירים לצרכן | J6: ישראל | K6: ישראל | L6: סחיר | M6: TASE | N6: אנרגיה | O6: לא | P6: A+ | Q6: S&P מעלות | R6: נייר ערך | S6: ILS | T6: 2.472 | U6: 01/10/2028 | V6: 0.0275 | W6: 0.03084 | X6: החוב לא נחות | Y6: לא | Z6: 337462.57 | AA6: 1 | AB6: 116.37 | AD6: 392.705 | AG6: שווי הוגן | AH6: 0.000453 | AI6: 0.014042695 | AJ6: 0.0025493418
A7: 891 | B7: 9957 | C7: איי.סי.אל גרופ בע"מ (דואלי) | D7: 520027830 | E7: ח.פ | F7: אייסיאל אגח ז | G7: IL0028103724 | H7: ISIN | I7: לא צמוד למדד המחירים לצרכן | J7: ישראל | K7: ישראל | L7: סחיר | M7: TASE | N7: כימיה, גומי ופלסטיק | O7: לא | P7: AA | Q7: S&P מעלות | R7: נייר ערך | S7: ILS | T7: 7.331 | U7: 30/12/2034 | V7: 0.024 | W7: 0.04694 | X7: החוב לא נחות | Y7: לא | Z7: 300000 | AA7: 1 | AB7: 84.92 | AD7: 254.76 | AG7: שווי הוגן | AH7: 0.000191 | AI7: 0.0091099301 | AJ7: 0.0016538368
A8: 891 | B8: 9957 | C8: איירפורט סיטי בע"מ | D8: 511659401 | E8: ח.פ | F8: איירפורט אגח ה | G8: IL0011334872 | H8: ISIN | I8: צמוד למדד המחירים לצרכן | J8: ישראל | K8: ישראל | L8: סחיר | M8: TASE | N8: נדל"ן מניב בישראל | O8: לא | P8: AA | Q8: S&P מעלות | R8: נייר ערך | S8: ILS | T8: 2.014 | U8: 28/02/2029 | V8: 0.0234 | W8: 0.02872 | X8: החוב לא נחות | Y8: לא | Z8: 251891.89 | AA8: 1 | AB8: 116.49 | AD8: 293.429 | AG8: שווי הוגן | AH8: 0.000155 | AI8: 0.010492685 | AJ8: 0.0019048652
A9: 891 | B9: 9957 | C9: אלבר שירותי מימונית בע"מ | D9: 512025891 | E9: ח.פ | F9: אלבר אגח יט | G9: IL0011918245 | H9: ISIN | I9: צמוד למדד המחירים לצרכן | J9: ישראל | K9: ישראל | L9: סחיר | M9: TASE | N9: שירותים | O9: לא | P9: A+ | Q9: S&P מעלות | R9: נייר ערך | S9: ILS | T9: 1.451 | U9: 15/05/2028 | V9: 0.032 | W9: 0.03223 | X9: החוב לא נחות | Y9: לא | Z9: 85200 | AA9: 1 | AB9: 109.13 | AD9: 92.979 | AG9: שווי הוגן | AH9: 0.000129 | AI9: 0.0033248155 | AJ9: 0.00060359436
A10: 891 | B10: 9957 | C10: אלבר שירותי מימונית בע"מ | D10: 512025891 | E10: ח.פ | F10: אלבר אגח כ | G10: IL0011918328 | H10: ISIN | I10: לא צמוד למדד המחירים לצרכן | J10: ישראל | K10: ישראל | L10: סחיר | M10: TASE | N10: שירותים | O10: לא | P10: A+ | Q10: S&P מעלות | R10: נייר ערך | S10: ILS | T10: 1.518 | U10: 20/06/2028 | V10: 0.057 | W10: 0.05189 | X10: החוב לא נחות | Y10: לא | Z10: 83400 | AA10: 1 | AB10: 101.09 | AD10: 84.309 | AG10: שווי הוגן | AH10: 0.000106 | AI10: 0.0030147968 | AJ10: 0.00054731288
A11: 891 | B11: 9957 | C11: אלדן תחבורה בע"מ | D11: 510454333 | E11: ח.פ | F11: אלדן תחבורה אגח ח | G11: IL0011924425 | H11: ISIN | I11: צמוד למדד המחירים לצרכן | J11: ישראל | K11: ישראל | L11: סחיר | M11: TASE | N11: שירותים | O11: לא | P11: A+ | Q11: S&P מעלות | R11: נייר ערך | S11: ILS | T11: 2.168 | U11: 30/09/2029 | V11: 0.0323 | W11: 0.02972 | X11: החוב לא נחות | Y11: לא | Z11: 117600 | AA11: 1 | AB11: 110.07 | AD11: 129.442 | AG11: שווי הוגן | AH11: 0.000228 | AI11: 0.0046287113 | AJ11: 0.00084030648
A12: 891 | B12: 9957 | C12: אלה ר. הנדסת בנין והשקעות בע"מ | D12: 520040015 | E12: ח.פ | F12: אלה ר השקע אגח א | G12: IL0011899502 | H12: ISIN | I12: צמוד למדד המחירים לצרכן | J12: ישראל | K12: ישראל | L12: סחיר | M12: TASE | N12: נדל"ן מניב בישראל | O12: לא | P12: A | Q12: S&P מעלות | R12: נייר ערך | S12: ILS | T12: 2.176 | U12: 01/07/2029 | V12: 0.0249 | W12: 0.03135 | X12: החוב לא נחות | Y12: לא | Z12: 232000 | AA12: 1 | AB12: 108.03 | AD12: 250.63 | AG12: שווי הוגן | AH12: 0.001244 | AI12: 0.0089622317 | AJ12: 0.0016270233
A13: 891 | B13: 9957 | C13: אלומיי קפיטל בע"מ | D13: 520039868 | E13: ח.פ | F13: אלומיי אגח ו | G13: IL0012030743 | H13: ISIN | I13: לא צמוד למדד המחירים לצרכן | J13: ישראל | K13: ישראל | L13: סחיר | M13: TASE | N13: אנרגיה מתחדשת | O13: לא | P13: NR | Q13: NR | R13: NR | S13: ILS | T13: 2.733 | U13: 31/03/2030 | V13: 0.055 | W13: 0.06331 | X13: החוב לא נחות | Y13: לא | Z13: 79000 | AA13: 1 | AB13: 99.42 | AD13: 78.542 | AG13: שווי הוגן | AH13: 0.000241 | AI13: 0.0028085661 | AJ13: 0.0005098733
A14: 891 | B14: 9957 | C14: אלקו בע"מ | D14: 520025370 | E14: ח.פ | F14: אלקו אגח יד 30/05/2032 5.98% | G14: IL0012077520 | H14: ISIN | I14: לא צמוד למדד המחירים לצרכן | J14: ישראל | K14: ישראל | L14: סחיר | M14: TASE | N14: השקעה ואחזקות | O14: לא | P14: AA- | Q14: S&P מעלות | R14: נייר ערך | S14: ILS | T14: 3.801 | U14: 30/05/2032 | V14: 0.0299 | W14: 0.04685 | X14: החוב לא נחות | Y14: לא | Z14: 300000 | AA14: 1 | AB14: 105.62 | AD14: 316.86 | AG14: שווי הוגן | AH14: 0.0015 | AI14: 0.011330556 | AJ14: 0.0020569742
... A52: 891 | B52: 9957 | C52: יו.אמ.איץ' פרופרטיס אינק. | D52: 221890929 | E52: מספר תאגיד או שותפות בחו"ל | F52: יו.אמ.איץ' אגח א | G52: IL0011841678 | H52: ISIN | I52: צמוד למט"ח | J52: ישראל | K52: ארה"ב | L52: סחיר | M52: TASE | N52: נדל"ן מניב בחו"ל | O52: לא | P52: AA- | Q52: S&P מעלות | R52: נייר ערך | S52: USD | T52: 1.592 | U52: 28/02/2027 | V52: 0.0472 | W52: 0.05895 | X52: החוב לא נחות | Y52: לא | Z52: 233000 | AA52: 3.372 | AB52: 31.234 | AD52: 245.396 | AG52: שווי הוגן | AH52: 0.000708 | AI52: 0.0087750697 | AJ52: 0.0015930456
A53: 891 | B53: 9957 | C53: קבוצת יובלים השקעות בע"מ | D53: 514625094 | E53: ח.פ | F53: יובלים אגח ב | G53: IL0011869075 | H53: ISIN | I53: לא צמוד למדד המחירים לצרכן | J53: ישראל | K53: ישראל | L53: סחיר | M53: TASE | N53: בנייה | O53: לא | P53: NR | Q53: NR | R53: NR | S53: ILS | T53: 0.995 | U53: 05/07/2026 | V53: 0.056 | W53: 0.05842 | X53: החוב לא נחות | Y53: לא | Z53: 155378.4 | AA53: 1 | AB53: 99.8 | AC53: 44.283 | AD53: 199.35 | AG53: שווי הוגן | AH53: 0.001142 | AI53: 0.0071285483 | AJ53: 0.0012941324
A54: 891 | B54: 9957 | C54: ירושלים מימון והנפקות (2005) בע"מ | D54: 513682146 | E54: ח.פ | F54: ירושלים הנפ אגח יט | G54: IL0012014333 | H54: ISIN | I54: צמוד למדד המחירים לצרכן | J54: ישראל | K54: ישראל | L54: סחיר | M54: TASE | N54: בנקים | O54: לא | P54: AA- | Q54: S&P מעלות | R54: נייר ערך | S54: ILS | T54: 3.874 | U54: 31/01/2031 | V54: 0.0259 | W54: 0.02747 | X54: החוב לא נחות | Y54: לא | Z54: 134000 | AA54: 1 | AB54: 105.24 | AD54: 141.022 | AG54: שווי הוגן | AH54: 0.000196 | AI54: 0.0050427733 | AJ54: 0.00091547621
A55: 891 | B55: 9957 | C55: ישפרו בע"מ | D55: 516291754 | E55: ח.פ | F55: ישפרו אגח א | G55: IL0012022906 | H55: ISIN | I55: צמוד למדד המחירים לצרכן | J55: ישראל | K55: ישראל | L55: סחיר | M55: TASE | N55: נדל"ן מניב בישראל | O55: לא | P55: NR | Q55: NR | R55: NR | S55: ILS | T55: 2.361 | U55: 31/12/2027 | V55: 0.045 | W55: 0.03339 | X55: החוב לא נחות | Y55: לא | Z55: 215000 | AA55: 1 | AB55: 108.49 | AD55: 233.254 | AG55: שווי הוגן | AH55: 0.000219 | AI55: 0.008340882 | AJ55: 0.0015142221
A56: 891 | B56: 9957 | C56: ישרס חברה להשקעות בע"מ | D56: 520017807 | E56: ח.פ | F56: ישרס אגח טו | G56: IL0061302076 | H56: ISIN | I56: צמוד למדד המחירים לצרכן | J56: ישראל | K56: ישראל | L56: סחיר | M56: TASE | N56: נדל"ן מניב בישראל | O56: לא | P56: AA | Q56: S&P מעלות | R56: נייר ערך | S56: ILS | T56: 1.757 | U56: 16/05/2027 | V56: 0.0158 | W56: 0.02779 | X56: החוב לא נחות | Y56: לא | Z56: 106953 | AA56: 1 | AB56: 116.04 | AD56: 124.108 | AG56: שווי הוגן | AH56: 0.000272 | AI56: 0.0044379714 | AJ56: 0.00080567913
A57: 891 | B57: 9957 | C57: ישרס חברה להשקעות בע"מ | D57: 520017807 | E57: ח.פ | F57: ישרס אגח יח | G57: IL0061302803 | H57: ISIN | I57: צמוד למדד המחירים לצרכן | J57: ישראל | K57: ישראל | L57: סחיר | M57: TASE | N57: נדל"ן מניב בישראל | O57: לא | P57: AA | Q57: S&P מעלות | R57: נייר ערך | S57: ILS | T57: 4.224 | U57: 10/04/2030 | V57: 0.0084 | W57: 0.02787 | X57: החוב לא נחות | Y57: לא | Z57: 272747.26 | AA57: 1 | AB57: 107.28 | AD57: 292.603 | AG57: שווי הוגן | AH57: 0.000356 | AI57: 0.010463162 | AJ57: 0.0018995056
A58: 891 | B58: 9957 | C58: כלל החזקות עסקי ביטוח בע"מ | D58: 520036120 | E58: ח.פ | F58: כלל ביטוח אגח ג | G58: IL0012013913 | H58: ISIN | I58: לא צמוד למדד המחירים לצרכן | J58: ישראל | K58: ישראל | L58: סחיר | M58: TASE | N58: ביטוח | O58: לא | P58: AA- | Q58: S&P מעלות | R58: נייר ערך | S58: ILS | T58: 4.694 | U58: 02/11/2031 | V58: 0.0525 | W58: 0.04653 | X58: החוב לא נחות | Y58: לא | Z58: 204000 | AA58: 1 | AB58: 103.89 | AD58: 211.936 | AG58: שווי הוגן | AH58: 0.000408 | AI58: 0.0075785779 | AJ58: 0.0013758318
A59: 891 | B59: 9957 | C59: כללביט מימון בע"מ | D59: 513754069 | E59: ח.פ | F59: כלל הון אגח יד | G59: IL0012205246 | H59: ISIN | I59: לא צמוד למדד המחירים לצרכן | J59: ישראל | K59: ישראל | L59: סחיר | M59: TASE | N59: ביטוח | O59: לא | P59: AA- | Q59: S&P מעלות | R59: נייר ערך | S59: ILS | T59: 8.511 | U59: 30/09/2039 | V59: 0.0551 | W59: 0.05145 | X59: החוב לא נחות | Y59: לא | Z59: 299000 | AA59: 1 | AB59: 104.59 | AD59: 312.724 | AG59: שווי הוגן | AH59: 0.000598 | AI59: 0.011182661 | AJ59: 0.002030125
A60: 891 | B60: 9957 | C60: בנק לאומי לישראל בע"מ | D60: 520018078 | E60: ח.פ | F60: לאומי אגח 185 | G60: IL0012018219 | H60: ISIN | I60: צמוד למדד המחירים לצרכן | J60: ישראל | K60: ישראל | L60: סחיר | M60: TASE | N60: בנקים | O60: לא | P60: AAA | Q60: S&P מעלות | R60: נייר ערך | S60: ILS | T60: 2.092 | U60: 31/08/2029 | V60: 0.0186 | W60: 0.02568 | X60: החוב לא נחות | Y60: לא | Z60: 193500 | AA60: 1 | AB60: 104.2 | AD60: 201.627 | AG60: שווי הוגן | AH60: 6.7e-05 | AI60: 0.007209954 | AJ60: 0.001308911
A61: 891 | B61: 9957 | C61: בנק לאומי לישראל בע"מ | D61: 520018078 | E61: ח.פ | F61: לאומי אגח 182 | G61: IL0060405391 | H61: ISIN | I61: צמוד למדד המחירים לצרכן | J61: ישראל | K61: ישראל | L61: סחיר | M61: TASE | N61: בנקים | O61: לא | P61: AAA | Q61: S&P מעלות | R61: נייר ערך | S61: ILS | T61: 2.397 | U61: 25/11/2027 | V61: 0.001 | W61: 0.02497 | X61: החוב לא נחות | Y61: לא | Z61: 229000 | AA61: 1 | AB61: 107.95 | AD61: 247.206 | AG61: שווי הוגן | AH61: 7.3e-05 | AI61: 0.0088397897 | AJ61: 0.001604795
A62: 891 | B62: 9957 | C62: בנק לאומי לישראל בע"מ | D62: 520018078 | E62: ח.פ | F62: לאומי אגח 186 | G62: IL0012018391 | H62: ISIN | I62: צמוד למדד המחירים לצרכן | J62: ישראל | K62: ישראל | L62: סחיר | M62: TASE | N62: בנקים | O62: לא | P62: AAA | Q62: S&P מעלות | R62: נייר ערך | S62: ILS | T62: 4.388 | U62: 30/11/2033 | V62: 0.0202 | W62: 0.02636 | X62: החוב לא נחות | Y62: לא | Z62: 656000 | AA62: 1 | AB62: 102.52 | AD62: 672.531 | AG62: שווי הוגן | AH62: 0.000184 | AI62: 0.024048957 | AJ62: 0.0043659008
A63: 891 | B63: 9957 | C63: בנק לאומי לישראל בע"מ | D63: 520018078 | E63: ח.פ | F63: לאומי התח נדח' סד' 405 | G63: IL0060406209 | H63: ISIN | I63: צמוד למדד המחירים לצרכן | J63: ישראל | K63: ישראל | L63: סחיר | M63: TASE | N63: בנקים | O63: לא | P63: AA- | Q63: S&P מעלות | R63: נייר ערך | S63: ILS | T63: 2.692 | U63: 27/03/2028 | V63: 0.015 | W63: 0.02954 | X63: החוב לא נחות | Y63: לא | Z63: 300000 | AA63: 1 | AB63: 109.15 | AD63: 327.45 | AG63: שווי הוגן | AH63: 0.000214 | AI63: 0.011709243 | AJ63: 0.0021257218
A64: 891 | B64: 9957 | C64: בנק לאומי לישראל בע"מ | D64: 520018078 | E64: ח.פ | F64: לאומי התח נדח' סד' 406 | G64: IL0012164237 | H64: ISIN | I64: צמוד למדד המחירים לצרכן | J64: ישראל | K64: ישראל | L64: סחיר | M64: TASE | N64: בנקים | O64: לא | P64: AA- | Q64: S&P מעלות | R64: נייר ערך | S64: ILS | T64: 5.232 | U64: 28/02/2036 | V64: 0.031 | W64: 0.02937 | X64: החוב לא נחות | Y64: לא | Z64: 294000 | AA64: 1 | AB64: 103.76 | AD64: 305.054 | AG64: שווי הוגן | AH64: 0.000192 | AI64: 0.010908401 | AJ64: 0.0019803352
A65: 891 | B65: 9957 | C65: לוזון רונסון | D65: 560040545 | E65: ח.פ | F65: לוזון רונסון אגח א 8.15% 25/09/2030 | G65: IL0012023409 | H65: ISIN | I65: לא צמוד למדד המחירים לצרכן | J65: ישראל | K65: ישראל | L65: סחיר | M65: TASE | N65: בנייה | O65: לא | P65: NR | Q65: NR | R65: NR | S65: ILS | T65: 2.842 | U65: 25/09/2030 | V65: 0.0815 | W65: 0.05673 | X65: החוב לא נחות | Y65: לא | Z65: 143000 | AA65: 1 | AB65: 109.5 | AD65: 156.585 | AG65: שווי הוגן | AH65: 0.000693 | AI65: 0.0055993029 | AJ65: 0.0010165098
... A69: 891 | B69: 9957 | C69: מגה אור החזקות בע"מ | D69: 513257873 | E69: ח.פ | F69: מגה אור אגח יא | G69: IL0011783755 | H69: ISIN | I69: צמוד למדד המחירים לצרכן | J69: ישראל | K69: ישראל | L69: סחיר | M69: TASE | N69: נדל"ן מניב בישראל | O69: לא | P69: A+ | Q69: S&P מעלות | R69: נייר ערך | S69: ILS | T69: 5.11 | U69: 31/03/2032 | V69: 0.0097 | W69: 0.03203 | X69: החוב לא נחות | Y69: לא | Z69: 213529.41 | AA69: 1 | AB69: 103.36 | AD69: 220.704 | AG69: שווי הוגן | AH69: 0.000355 | AI69: 0.0078921259 | AJ69: 0.001432754
A70: 891 | B70: 9957 | C70: מזרחי טפחות חברה להנפקות בע"מ | D70: 520032046 | E70: ח.פ | F70: מז טפ הנפק 52 | G70: IL0023103810 | H70: ISIN | I70: צמוד למדד המחירים לצרכן | J70: ישראל | K70: ישראל | L70: סחיר | M70: TASE | N70: בנקים | O70: לא | P70: AAA | Q70: S&P מעלות | R70: נייר ערך | S70: ILS | T70: 4.979 | U70: 01/07/2030 | V70: 0.002 | W70: 0.02616 | X70: החוב לא נחות | Y70: לא | Z70: 300000 | AA70: 1 | AB70: 104.05 | AC70: 0.703 | AD70: 312.853 | AG70: שווי הוגן | AH70: 8.7e-05 | AI70: 0.011187268 | AJ70: 0.0020309613
A71: 891 | B71: 9957 | C71: מזרחי טפחות חברה להנפקות בע"מ | D71: 520032046 | E71: ח.פ | F71: מזרחי טפ הנפק התח 69 | G71: IL0012021593 | H71: ISIN | I71: צמוד למדד המחירים לצרכן | J71: ישראל | K71: ישראל | L71: סחיר | M71: TASE | N71: בנקים | O71: לא | P71: AA- | Q71: S&P מעלות | R71: נייר ערך | S71: ILS | T71: 3.795 | U71: 25/06/2029 | V71: 0.0336 | W71: 0.02733 | X71: החוב לא נחות | Y71: לא | Z71: 42000 | AA71: 1 | AB71: 107.56 | AD71: 45.175 | AG71: שווי הוגן | AH71: 3.6e-05 | AI71: 0.0016154142 | AJ71: 0.00029326586
A72: 891 | B72: 9957 | C72: מזרחי טפחות חברה להנפקות בע"מ | D72: 520032046 | E72: ח.פ | F72: מזרחי טפחות הנפק 49 | G72: IL0023102820 | H72: ISIN | I72: צמוד למדד המחירים לצרכן | J72: ישראל | K72: ישראל | L72: סחיר | M72: TASE | N72: בנקים | O72: לא | P72: AAA | Q72: S&P מעלות | R72: נייר ערך | S72: ILS | T72: 0.975 | U72: 23/06/2026 | V72: 0.0038 | W72: 0.02561 | X72: החוב לא נחות | Y72: לא | Z72: 413357 | AA72: 1 | AB72: 112.93 | AD72: 466.804 | AG72: שווי הוגן | AH72: 0.000138 | AI72: 0.016692386 | AJ72: 0.0030303727
A73: 891 | B73: 9957 | C73: מימון ישיר מקבוצת ישיר 2006 בע"מ | D73: 513893123 | E73: ח.פ | F73: מימון ישיר אגח ה | G73: IL0011828311 | H73: ISIN | I73: צמוד למדד המחירים לצרכן | J73: ישראל | K73: ישראל | L73: סחיר | M73: TASE | N73: אשראי חוץ בנקאי | O73: לא | P73: A1 | Q73: מידרוג Moodys | R73: נייר ערך | S73: ILS | T73: 2.782 | U73: 31/07/2031 | V73: 0.01 | W73: 0.03107 | X73: החוב לא נחות | Y73: לא | Z73: 325402.5 | AA73: 1 | AB73: 108.19 | AD73: 352.053 | AG73: שווי הוגן | AH73: 0.000181 | AI73: 0.012589017 | AJ73: 0.0022854379
A74: 891 | B74: 9957 | C74: מימון ישיר מקבוצת ישיר 2006 בע"מ | D74: 513893123 | E74: ח.פ | F74: מימון ישיר אגח ו | G74: IL0011916595 | H74: ISIN | I74: צמוד למדד המחירים לצרכן | J74: ישראל | K74: ישראל | L74: סחיר | M74: TASE | N74: אשראי חוץ בנקאי | O74: לא | P74: A1 | Q74: מידרוג Moodys | R74: נייר ערך | S74: ILS | T74: 1.056 | U74: 31/03/2027 | V74: 0.0354 | W74: 0.03425 | X74: החוב לא נחות | Y74: לא | Z74: 226800 | AA74: 1 | AB74: 109.8 | AD74: 249.026 | AG74: שווי הוגן | AH74: 0.000226 | AI74: 0.0089049031 | AJ74: 0.0016166158
A75: 891 | B75: 9957 | C75: מימון ישיר מקבוצת ישיר 2006 בע"מ | D75: 513893123 | E75: ח.פ | F75: מימון ישיר ד | G75: IL0011756603 | H75: ISIN | I75: צמוד למדד המחירים לצרכן | J75: ישראל | K75: ישראל | L75: סחיר | M75: TASE | N75: אשראי חוץ בנקאי | O75: לא | P75: A1 | Q75: מידרוג Moodys | R75: נייר ערך | S75: ILS | T75: 0.179 | U75: 01/02/2026 | V75: 0.01 | W75: 0.03569 | X75: החוב לא נחות | Y75: לא | Z75: 121882.57 | AA75: 1 | AB75: 115.84 | AD75: 141.189 | AG75: שווי הוגן | AH75: 0.000721 | AI75: 0.0050487511 | AJ75: 0.00091656143
A76: 891 | B76: 9957 | C76: מליסרון בע"מ | D76: 520037789 | E76: ח.פ | F76: מליסרון אגח יט | G76: IL0032303989 | H76: ISIN | I76: צמוד למדד המחירים לצרכן | J76: ישראל | K76: ישראל | L76: סחיר | M76: TASE | N76: נדל"ן מניב בישראל | O76: לא | P76: AA | Q76: S&P מעלות | R76: נייר ערך | S76: ILS | T76: 3.744 | U76: 01/07/2029 | V76: 0.0143 | W76: 0.0281 | X76: החוב לא נחות | Y76: לא | Z76: 515317.27 | AA76: 1 | AB76: 111.28 | AC76: 11.062 | AD76: 584.507 | AG76: שווי הוגן | AH76: 0.000267 | AI76: 0.020901295 | AJ76: 0.0037944673
A77: 891 | B77: 9957 | C77: מליסרון בע"מ | D77: 520037789 | E77: ח.פ | F77: מליסרון אגח כא | G77: IL0011946386 | H77: ISIN | I77: צמוד למדד המחירים לצרכן | J77: ישראל | K77: ישראל | L77: סחיר | M77: TASE | N77: נדל"ן מניב בישראל | O77: לא | P77: AA | Q77: S&P מעלות | R77: נייר ערך | S77: ILS | T77: 5.598 | U77: 01/01/2037 | V77: 0.0361 | W77: 0.02928 | X77: החוב לא נחות | Y77: לא | Z77: 292500 | AA77: 1 | AB77: 111.6 | AC77: 6.49 | AD77: 332.92 | AG77: שווי הוגן | AH77: 0.000187 | AI77: 0.011904856 | AJ77: 0.0021612339
A78: 891 | B78: 9957 | C78: מליסרון בע"מ | D78: 520037789 | E78: ח.פ | F78: מליסרון אגח כ | G78: IL0032304227 | H78: ISIN | I78: צמוד למדד המחירים לצרכן | J78: ישראל | K78: ישראל | L78: סחיר | M78: TASE | N78: נדל"ן מניב בישראל | O78: לא | P78: AA | Q78: S&P מעלות | R78: נייר ערך | S78: ILS | T78: 4.692 | U78: 01/07/2030 | V78: 0.0025 | W78: 0.02702 | X78: החוב לא נחות | Y78: לא | Z78: 228593.93 | AA78: 1 | AB78: 102.52 | AC78: 3.385 | AD78: 237.739 | AG78: שווי הוגן | AH78: 0.000171 | AI78: 0.0085012929 | AJ78: 0.0015433435
A79: 891 | B79: 9957 | C79: מנורה מבטחים גיוס הון בע"מ | D79: 513937714 | E79: ח.פ | F79: מנורה הון התח סד' ט | G79: IL0012193699 | H79: ISIN | I79: לא צמוד למדד המחירים לצרכן | J79: ישראל | K79: ישראל | L79: סחיר | M79: TASE | N79: ביטוח | O79: לא | P79: Aa3 | Q79: מידרוג Moodys | R79: נייר ערך | S79: ILS | T79: 6.099 | U79: 30/09/2035 | V79: 0.0502 | W79: 0.04789 | X79: החוב לא נחות | Y79: לא | Z79: 220000 | AA79: 1 | AB79: 103.09 | AD79: 226.798 | AG79: שווי הוגן | AH79: 0.00055 | AI79: 0.0081100406 | AJ79: 0.0014723147
A80: 891 | B80: 9957 | C80: מניף - שירותים פיננסים בע"מ | D80: 512764408 | E80: ח.פ | F80: מניף אגח א | G80: IL0011858839 | H80: ISIN | I80: לא צמוד למדד המחירים לצרכן | J80: ישראל | K80: ישראל | L80: סחיר | M80: TASE | N80: אשראי חוץ בנקאי | O80: לא | P80: A3 | Q80: מידרוג Moodys | R80: נייר ערך | S80: ILS | T80: 0.731 | U80: 30/09/2026 | V80: 0.114 | W80: 0.0591 | X80: החוב לא נחות | Y80: לא | Z80: 196310 | AA80: 1 | AB80: 102.52 | AD80: 201.257 | AG80: שווי הוגן | AH80: 0.000812 | AI80: 0.0071967236 | AJ80: 0.0013065091
...

Sheet מניות מבכ ויהש
A1: מספר קופה/קרן/ח.פ. עבור חברת ביטוח | B1: מספר מסלול | C1: שם מנפיק | D1: מספר מנפיק | E1: סוג מספר מזהה מנפיק | F1: שם נייר ערך | G1: מספר נייר ערך | H1: סוג מספר נייר ערך | I1: מאפיין עיקרי | J1: ישראל/חו"ל | K1: מדינה לפי חשיפה כלכלית | L1: סטאטוס סחירות | M1: זירת מסחר | N1: ענף מסחר | O1: בעל עניין/צד קשור | P1: מטבע פעילות | Q1: ערך נקוב (יחידות) | R1: שער חליפין | S1: שער נייר הערך | T1: סכום לקבל (במטבע הפעילות) | U1: שווי הוגן (באלפי ש"ח) | V1: שיעור מערך נקוב מונפק | W1: שיעור מנכסי אפיק ההשקעה | X1: שיעור מסך נכסי ההשקעה
A2: 891 | B2: 9957 | C2: או.פי.סי. אנרגיה בע"מ | D2: 514401702 | E2: ח.פ | F2: או פי סי אנרגיה | G2: IL0011415713 | H2: ISIN | I2: מניות | J2: ישראל | K2: ישראל | L2: סחיר | M2: TASE | N2: אנרגיה | O2: לא | P2: ILS | Q2: 9723 | R2: 1 | S2: 4100 | U2: 398.643 | V2: 3.5e-05 | W2: 0.01210687 | X2: 0.0025878445
A3: 891 | B3: 9957 | C3: אורמת טכנולגיות אינק | D3: 5493000TSHHWY24VHM09 | E3: LEI | F3: אורמת טכנולוגיות | G3: US6866881021 | H3: ISIN | I3: מניות | J3: ישראל | K3: ארה"ב | L3: סחיר | M3: TASE | N3: אנרגיה מתחדשת | O3: לא | P3: ILS | Q3: 1457 | R3: 1 | S3: 27780 | U3: 404.755 | V3: 2.6e-05 | W3: 0.01229248 | X3: 0.0026275188
A4: 891 | B4: 9957 | C4: איי.סי.אל גרופ בע"מ (דואלי) | D4: 520027830 | E4: ח.פ | F4: איי.סי.אל | G4: IL0002810146 | H4: ISIN | I4: מניות | J4: ישראל | K4: ישראל | L4: סחיר | M4: TASE | N4: כימיה, גומי ופלסטיק | O4: לא | P4: ILS | Q4: 25440 | R4: 1 | S4: 2309 | U4: 587.41 | V4: 1.9e-05 | W4: 0.01783975 | X4: 0.0038132483
A5: 891 | B5: 9957 | C5: אינרום תעשיות בנייה בע"מ | D5: 515001659 | E5: ח.פ | F5: אינרום | G5: IL0011323560 | H5: ISIN | I5: מניות | J5: ישראל | K5: ישראל | L5: סחיר | M5: TASE | N5: מתכת ומוצרי בניה | O5: לא | P5: ILS | Q5: 12000 | R5: 1 | S5: 2100 | U5: 252 | V5: 8.1e-05 | W5: 0.0076532917 | X5: 0.0016358918
A6: 891 | B6: 9957 | C6: אלביט מערכות בע"מ | D6: 520043027 | E6: ח.פ | F6: אלביט מערכות | G6: IL0010811243 | H6: ISIN | I6: מניות | J6: ישראל | K6: ישראל | L6: סחיר | M6: TASE | N6: ביטחוניות | O6: לא | P6: ILS | Q6: 806 | R6: 1 | S6: 149800 | T6: 1.705 | U6: 1209.093 | V6: 1.7e-05 | W6: 0.036720393 | X6: 0.0078489875
A7: 891 | B7: 9957 | C7: אלוני-חץ נכסים והשקעות בע"מ | D7: 520038506 | E7: ח.פ | F7: אלוני חץ | G7: IL0003900136 | H7: ISIN | I7: מניות | J7: ישראל | K7: ישראל | L7: סחיר | M7: TASE | N7: נדל"ן מניב בישראל | O7: לא | P7: ILS | Q7: 9180 | R7: 1 | S7: 3489 | U7: 320.29 | V7: 4.3e-05 | W7: 0.0097272791 | X7: 0.0020792068
A8: 891 | B8: 9957 | C8: אלקטרה נדל"ן בע"מ | D8: 510607328 | E8: ח.פ | F8: אלקטרה נדלן | G8: IL0010940448 | H8: ISIN | I8: מניות | J8: ישראל | K8: ישראל | L8: סחיר | M8: TASE | N8: נדל"ן מניב בחו"ל | O8: לא | P8: ILS | Q8: 2562 | R8: 1 | S8: 5007 | U8: 128.279 | V8: 3.9e-05 | W8: 0.0038958699 | X8: 0.00083274256
A9: 891 | B9: 9957 | C9: אמות השקעות בע"מ | D9: 520026683 | E9: ח.פ | F9: אמות | G9: IL0010972789 | H9: ISIN | I9: מניות | J9: ישראל | K9: ישראל | L9: סחיר | M9: TASE | N9: נדל"ן מניב בישראל | O9: לא | P9: ILS | Q9: 13336 | R9: 1 | S9: 2281 | U9: 304.194 | V9: 2.8e-05 | W9: 0.0092384391 | X9: 0.0019747172
A10: 891 | B10: 9957 | C10: אנלייט אנרגיה מתחדשת בע"מ | D10: 520041146 | E10: ח.פ | F10: אנלייט אנרגיה | G10: IL0007200111 | H10: ISIN | I10: מניות | J10: ישראל | K10: ארה"ב | L10: סחיר | M10: TASE | N10: אנרגיה מתחדשת | O10: לא | P10: ILS | Q10: 2775.4 | R10: 1 | S10: 7640 | U10: 212.041 | V10: 2.3e-05 | W10: 0.0064397153 | X10: 0.0013764898
A11: 891 | B11: 9957 | C11: Energean plc | D11: 98450044QACBL3F8EB03 | E11: LEI | F11: אנרג'יאן | G11: GB00BG12Y042 | H11: ISIN | I11: מניות | J11: ישראל | K11: בריטניה | L11: סחיר | M11: TASE | N11: חיפושי נפט וגז | O11: לא | P11: ILS | Q11: 8728 | R11: 1 | S11: 4272 | T11: 8.829 | U11: 381.689 | V11: 4.7e-05 | W11: 0.011591986 | X11: 0.002477788
A12: 891 | B12: 9957 | C12: אנרג'יקס אנרגיות מתחדשות בע"מ | D12: 513901371 | E12: ח.פ | F12: אנרג'יקס | G12: IL0011233553 | H12: ISIN | I12: מניות | J12: ישראל | K12: ישראל | L12: סחיר | M12: TASE | N12: אנרגיה מתחדשת | O12: לא | P12: ILS | Q12: 11984 | R12: 1 | S12: 1244 | U12: 149.081 | V12: 2.2e-05 | W12: 0.0045276193 | X12: 0.00096777906
A13: 891 | B13: 9957 | C13: אר פי אופטיקל לאב בעמ | D13: 514454701 | E13: ח.פ | F13: אר פי אופטיקל לאב | G13: IL0012224627 | H13: ISIN | I13: מניות | J13: ישראל | K13: ישראל | L13: סחיר | M13: TASE | N13: ביטחוניות | O13: לא | P13: ILS | Q13: 6000 | R13: 1 | S13: 1336 | U13: 80.16 | V13: 8.1e-05 | W13: 0.0024344756 | X13: 0.0005203694
A14: 891 | B14: 9957 | C14: ארגו פרופרטיז אן. וי | D14: 70252750 | E14: מספר תאגיד או שותפות בחו"ל | F14: ארגו פרופרטיז אן. וי | G14: NL0015000D84 | H14: ISIN | I14: מניות | J14: ישראל | K14: גרמניה | L14: סחיר | M14: TASE | N14: נדל"ן מניב בחו"ל | O14: לא | P14: ILS | Q14: 2139 | R14: 1 | S14: 12250 | U14: 262.027 | V14: 9.8e-05 | W14: 0.0079578289 | X14: 0.0017009867
A15: 891 | B15: 9957 | C15: קבוצת אשטרום | D15: 510381601 | E15: ח.פ | F15: אשטרום קבוצה | G15: IL0011323156 | H15: ISIN | I15: מניות | J15: ישראל | K15: ישראל | L15: סחיר | M15: TASE | N15: בנייה | O15: לא | P15: ILS | Q15: 3000 | R15: 1 | S15: 7670 | U15: 230.1 | V15: 2.7e-05 | W15: 0.0069881842 | X15: 0.001493725
A16: 891 | B16: 9957 | C16: בזק החברה הישראלית לתקשורת בע"מ | D16: 520031931 | E16: ח.פ | F16: בזק | G16: IL0002300114 | H16: ISIN | I16: מניות | J16: ישראל | K16: ישראל | L16: סחיר | M16: TASE | N16: תקשורת ומדיה | O16: לא | P16: ILS | Q16: 74329 | R16: 1 | S16: 575 | U16: 427.392 | V16: 2.7e-05 | W16: 0.012979975 | X16: 0.0027744709
A17: 891 | B17: 9957 | C17: ביג מרכזי קניות (2004) בע"מ | D17: 513623314 | E17: ח.פ | F17: ביג | G17: IL0010972607 | H17: ISIN | I17: מניות | J17: ישראל | K17: ישראל | L17: סחיר | M17: TASE | N17: נדל"ן מניב בישראל | O17: לא | P17: ILS | Q17: 1367 | R17: 1 | S17: 64490 | U17: 881.578 | V17: 5.5e-05 | W17: 0.026773714 | X17: 0.0057228839
A18: 891 | B18: 9957 | C18: הבנק הבינלאומי הראשון לישראל בע"מ | D18: 520029083 | E18: ח.פ | F18: בינלאומי 5 | G18: IL0005930388 | H18: ISIN | I18: מניות | J18: ישראל | K18: ישראל | L18: סחיר | M18: TASE | N18: בנקים | O18: לא | P18: ILS | Q18: 2503 | R18: 1 | S18: 24370 | U18: 609.981 | V18: 2.5e-05 | W18: 0.018525251 | X18: 0.0039597742
A19: 891 | B19: 9957 | C19: בית בכפר בע"מ | D19: 511605719 | E19: ח.פ | F19: בית בכפר | G19: IL0011836561 | H19: ISIN | I19: מניות | J19: ישראל | K19: ישראל | L19: סחיר | M19: TASE | N19: נדל"ן מניב בישראל | O19: לא | P19: ILS | Q19: 10069 | R19: 1 | S19: 1506 | U19: 151.639 | V19: 0.000144 | W19: 0.0046053118 | X19: 0.00098438583
A20: 891 | B20: 9957 | C20: מנועי בית שמש אחזקות (1997) בע"מ | D20: 520043480 | E20: ח.פ | F20: בית שמש | G20: IL0010815616 | H20: ISIN | I20: מניות | J20: ישראל | K20: ישראל | L20: סחיר | M20: TASE | N20: מתכת ומוצרי בניה | O20: לא | P20: ILS | Q20: 1344 | R20: 1 | S20: 56070 | U20: 753.581 | V20: 0.000148 | W20: 0.022886404 | X20: 0.0048919709
A21: 891 | B21: 9957 | C21: חברת גב-ים לקרקעות בע"מ | D21: 520001736 | E21: ח.פ | F21: גב ים | G21: IL0007590198 | H21: ISIN | I21: מניות | J21: ישראל | K21: ישראל | L21: סחיר | M21: TASE | N21: נדל"ן מניב בישראל | O21: לא | P21: ILS | Q21: 6272 | R21: 1 | S21: 3685 | U21: 231.123 | V21: 2.8e-05 | W21: 0.007019259 | X21: 0.0015003673
A22: 891 | B22: 9957 | C22: קבוצת דוראל משאבי אנרגיה מתחדשת בעמ | D22: 515364891 | E22: ח.פ | F22: דוראל אנרגיה | G22: IL0011667685 | H22: ISIN | I22: מניות | J22: ישראל | K22: ישראל | L22: סחיר | M22: TASE | N22: אנרגיה מתחדשת | O22: לא | P22: ILS | Q22: 10141 | R22: 1 | S22: 1532 | U22: 155.36 | V22: 5.7e-05 | W22: 0.0047183187 | X22: 0.0010085411
A23: 891 | B23: 9957 | C23: בנק דיסקונט לישראל בע"מ | D23: 520007030 | E23: ח.פ | F23: דיסקונט | G23: IL0006912120 | H23: ISIN | I23: מניות | J23: ישראל | K23: ישראל | L23: סחיר | M23: TASE | N23: בנקים | O23: לא | P23: ILS | Q23: 19618 | R23: 1 | S23: 3356 | U23: 658.38 | V23: 1.6e-05 | W23: 0.019995138 | X23: 0.0042739627
... A27: 891 | B27: 9957 | C27: הבורסה לניירות ערך בתל-אביב בע"מ | D27: 520020033 | E27: ח.פ | F27: הבורסה לניע בתא | G27: IL0011590291 | H27: ISIN | I27: מניות | J27: ישראל | K27: ישראל | L27: סחיר | M27: TASE | N27: שירותים פיננסיים | O27: לא | P27: ILS | Q27: 1778 | R27: 1 | S27: 6510 | U27: 115.748 | V27: 1.7e-05 | W27: 0.0035152844 | X27: 0.00075139238
A28: 891 | B28: 9957 | C28: הולמס פלייס אינטרנשיונל בע"מ | D28: 512466723 | E28: ח.פ | F28: הולמס פלייס | G28: IL0011425878 | H28: ISIN | I28: מניות | J28: ישראל | K28: ישראל | L28: סחיר | M28: TASE | N28: שירותים | O28: לא | P28: ILS | Q28: 44000 | R28: 1 | S28: 732.6 | T28: 5.273 | U28: 327.617 | V28: 0.000479 | W28: 0.0099497925 | X28: 0.0021267691
A29: 891 | B29: 9957 | C29: חברת הכשרת הישוב בישראל- אנרגיה בע"מ | D29: 514423474 | E29: ח.פ | F29: הכשרה התפתחות עירונית | G29: IL0011214744 | H29: ISIN | I29: מניות | J29: ישראל | K29: ישראל | L29: סחיר | M29: TASE | N29: בנייה | O29: לא | P29: ILS | Q29: 27000 | R29: 1 | S29: 711.9 | U29: 192.213 | V29: 0.000309 | W29: 0.0058375483 | X29: 0.0012477765
A30: 891 | B30: 9957 | C30: הפניקס אחזקות בע"מ | D30: 520017450 | E30: ח.פ | F30: הפניקס | G30: IL0007670123 | H30: ISIN | I30: מניות | J30: ישראל | K30: ישראל | L30: סחיר | M30: TASE | N30: ביטוח | O30: לא | P30: ILS | Q30: 6229 | R30: 1 | S30: 9745 | U30: 607.016 | V30: 2.4e-05 | W30: 0.018435202 | X30: 0.0039405262
A31: 891 | B31: 9957 | C31: הראל השקעות בביטוח ושרותים פיננסים בע"מ | D31: 520033986 | E31: ח.פ | F31: הראל השקעות | G31: IL0005850180 | H31: ISIN | I31: מניות | J31: ישראל | K31: ישראל | L31: סחיר | M31: TASE | N31: ביטוח | O31: לא | P31: ILS | Q31: 10085 | R31: 1 | S31: 9432 | U31: 951.217 | V31: 4.5e-05 | W31: 0.028888662 | X31: 0.0061749541
A32: 891 | B32: 9957 | C32: וואן טכנולוגיות תוכנה(או.אס.טי)בע"מ | D32: 520034695 | E32: ח.פ | F32: וואן טכנולוגיות תוכנה | G32: IL0001610182 | H32: ISIN | I32: מניות | J32: ישראל | K32: ישראל | L32: סחיר | M32: TASE | N32: שירותי מידע | O32: לא | P32: ILS | Q32: 1520 | R32: 1 | S32: 8680 | U32: 131.936 | V32: 2.1e-05 | W32: 0.0040069234 | X32: 0.00085648026
A33: 891 | B33: 9957 | C33: החברה לישראל בע"מ | D33: 520028010 | E33: ח.פ | F33: חברה לישראל | G33: IL0005760173 | H33: ISIN | I33: מניות | J33: ישראל | K33: ישראל | L33: סחיר | M33: TASE | N33: השקעה ואחזקות | O33: לא | P33: ILS | Q33: 175 | R33: 1 | S33: 112370 | U33: 196.648 | V33: 2.3e-05 | W33: 0.0059722249 | X33: 0.0012765636
A34: 891 | B34: 9957 | C34: חילן בע"מ | D34: 520039942 | E34: ח.פ | F34: חילן | G34: IL0010846983 | H34: ISIN | I34: מניות | J34: ישראל | K34: ישראל | L34: סחיר | M34: TASE | N34: שירותי מידע | O34: לא | P34: ILS | Q34: 761 | R34: 1 | S34: 28610 | U34: 217.722 | V34: 3.3e-05 | W34: 0.0066122649 | X34: 0.0014133722
A35: 891 | B35: 9957 | C35: קבוצת חמת בע"מ | D35: 520038530 | E35: ח.פ | F35: חמת | G35: IL0003840167 | H35: ISIN | I35: מניות | J35: ישראל | K35: ישראל | L35: סחיר | M35: TASE | N35: מתכת ומוצרי בניה | O35: לא | P35: ILS | Q35: 6747 | R35: 1 | S35: 1866 | T35: 2.762 | U35: 128.661 | V35: 0.000183 | W35: 0.0039074573 | X35: 0.00083521937
A36: 891 | B36: 9957 | C36: טאואר סמיקונדקטור בע"מ | D36: 520041997 | E36: ח.פ | F36: טאואר | G36: IL0010823792 | H36: ISIN | I36: מניות | J36: ישראל | K36: גלובלי | L36: סחיר | M36: TASE | N36: מוליכים למחצה | O36: לא | P36: ILS | Q36: 2003 | R36: 1 | S36: 14620 | U36: 292.839 | V36: 1.8e-05 | W36: 0.0088935684 | X36: 0.0019010011
A37: 891 | B37: 9957 | C37: טבע תעשיות פרמצבטיות בע"מ | D37: 520013954 | E37: ח.פ | F37: טבע | G37: IL0006290147 | H37: ISIN | I37: מניות | J37: ישראל | K37: ארה"ב | L37: סחיר | M37: TASE | N37: פארמה | O37: לא | P37: ILS | Q37: 27613 | R37: 1 | S37: 5699 | U37: 1573.665 | V37: 2.2e-05 | W37: 0.047792525 | X37: 0.010215657
A38: 891 | B38: 9957 | C38: טיב טעם הולדינגס 1 בע"מ | D38: 520041187 | E38: ח.פ | F38: טיב טעם | G38: IL0001030100 | H38: ISIN | I38: מניות | J38: ישראל | K38: ישראל | L38: סחיר | M38: TASE | N38: רשתות שיווק | O38: לא | P38: ILS | Q38: 25353 | R38: 1 | S38: 810 | U38: 205.359 | V38: 0.000233 | W38: 0.0062368041 | X38: 0.0013331175
A39: 891 | B39: 9957 | C39: ישראמקו נגב 2 שותפות מוגבלת | D39: 550010003 | E39: מספר שותפות | F39: ישראמקו יהש | G39: IL0002320179 | H39: ISIN | I39: מניות | J39: ישראל | K39: ישראל | L39: סחיר | M39: TASE | N39: חיפושי נפט וגז | O39: לא | P39: ILS | Q39: 111900 | R39: 1 | S39: 229.9 | U39: 257.258 | V39: 4.3e-05 | W39: 0.0078129813 | X39: 0.0016700255
A40: 891 | B40: 9957 | C40: כלל החזקות עסקי ביטוח בע"מ | D40: 520036120 | E40: ח.פ | F40: כלל ביטוח | G40: IL0002240146 | H40: ISIN | I40: מניות | J40: ישראל | K40: ישראל | L40: סחיר | M40: TASE | N40: ביטוח | O40: לא | P40: ILS | Q40: 4988 | R40: 1 | S40: 14880 | U40: 742.214 | V40: 6.3e-05 | W40: 0.022541204 | X40: 0.0048181844
A41: 891 | B41: 9957 | C41: בנק לאומי לישראל בע"מ | D41: 520018078 | E41: ח.פ | F41: לאומי | G41: IL0006046119 | H41: ISIN | I41: מניות | J41: ישראל | K41: ישראל | L41: סחיר | M41: TASE | N41: בנקים | O41: לא | P41: ILS | Q41: 30015 | R41: 1 | S41: 6262 | U41: 1879.539 | V41: 1.9e-05 | W41: 0.057081994 | X41: 0.012201282
A42: 891 | B42: 9957 | C42: יוחננוף | D42: 511344186 | E42: ח.פ | F42: מ. יוחננוף | G42: IL0011612640 | H42: ISIN | I42: מניות | J42: ישראל | K42: ישראל | L42: סחיר | M42: TASE | N42: רשתות שיווק | O42: לא | P42: ILS | Q42: 939 | R42: 1 | S42: 30850 | U42: 289.682 | V42: 6.5e-05 | W42: 0.0087976866 | X42: 0.0018805063
A43: 891 | B43: 9957 | C43: מבנה נדל"ן (כ.ד) בע"מ | D43: 520024126 | E43: ח.פ | F43: מבנה | G43: IL0002260193 | H43: ISIN | I43: מניות | J43: ישראל | K43: ישראל | L43: סחיר | M43: TASE | N43: נדל"ן מניב בישראל | O43: לא | P43: ILS | Q43: 13606.16 | R43: 1 | S43: 1262 | U43: 171.71 | V43: 1.9e-05 | W43: 0.00521486 | X43: 0.0011146768
...

Sheet קרנות סל
A1: מספר קופה/קרן/ח.פ. עבור חברת ביטוח | B1: מספר מסלול | C1: שם מנפיק | D1: מספר מנפיק | E1: סוג מספר מזהה מנפיק | F1: שם נייר ערך | G1: מספר נייר ערך | H1: סוג מספר נייר ערך | I1: מאפיין עיקרי | J1: ישראל/חו"ל | K1: מדינה לפי חשיפה כלכלית | L1: זירת מסחר | M1: סיווג הקרן | N1: בעל עניין/צד קשור | O1: מטבע פעילות | P1: ערך נקוב (יחידות) | Q1: שער חליפין | R1: שער נייר הערך | S1: סכום לקבל (במטבע הפעילות) | T1: שווי הוגן (באלפי ש"ח) | U1: שיעור מערך נקוב מונפק | V1: שיעור מנכסי אפיק ההשקעה | W1: שיעור מסך נכסי ההשקעה
A2: 891 | B2: 9957 | C2: מגדל קרנות נאמנות בע"מ | D2: 511303661 | E2: ח.פ | F2: MTF סל (S&P 500 (4D | G2: IL0011503336 | H2: ISIN | I2: עוקב אחר מדדי מניות בחו"ל | J2: ישראל | K2: ארה"ב | L2: TASE | M2: מניות בחו"ל חשופות מט"ח | N2: לא | O2: ILS | P2: 1747 | Q2: 1 | R2: 8961 | T2: 156.549 | U2: 2e-05 | V2: 0.0049965371 | W2: 0.0010162567
A3: 891 | B3: 9957 | C3: מגדל קרנות נאמנות בע"מ | D3: 511303661 | E3: ח.פ | F3: MTF500SP ממ | G3: IL0011505729 | H3: ISIN | I3: עוקב אחר מדדי מניות בחו"ל | J3: ישראל | K3: ארה"ב | L3: TASE | M3: מניות בחו"ל משולבת | N3: לא | O3: ILS | P3: 31179 | Q3: 1 | R3: 7820 | T3: 2438.198 | U3: 0.001279 | V3: 0.077819542 | W3: 0.015827888
A4: 891 | B4: 9957 | C4: הראל קרנות נאמנות בע"מ | D4: 511776783 | E4: ח.פ | F4: הראל סל (4A) MSCI AC World מנ | G4: IL0011502007 | H4: ISIN | I4: עוקב אחר מדדי מניות בחו"ל | J4: ישראל | K4: גלובלי | L4: TASE | M4: מניות בחו"ל חשופות מט"ח | N4: לא | O4: ILS | P4: 222910 | Q4: 1 | R4: 864.7 | T4: 1927.503 | U4: 0.000443 | V4: 0.061519776 | W4: 0.012512643
A5: 891 | B5: 9957 | C5: הראל קרנות נאמנות בע"מ | D5: 511776783 | E5: ח.פ | F5: הראל סל תא 90 | G5: IL0011489312 | H5: ISIN | I5: עוקב אחר מדדי מניות בישראל | J5: ישראל | K5: ישראל | L5: TASE | M5: מניות בישראל | N5: לא | O5: ILS | P5: 23148 | Q5: 1 | R5: 3032 | T5: 701.847 | U5: 9.3e-05 | V5: 0.022400742 | W5: 0.0045561364
A6: 891 | B6: 9957 | C6: הראל קרנות נאמנות בע"מ | D6: 511776783 | E6: ח.פ | F6: הראל קרן סל 4AׂSTOXX EUROPE 600ממ | G6: IL0011498891 | H6: ISIN | I6: עוקב אחר מדדי מניות בחו"ל | J6: ישראל | K6: אירופה | L6: TASE | M6: מניות בחו"ל משולבת | N6: לא | O6: ILS | P6: 171631 | Q6: 1 | R6: 699.4 | T6: 1200.387 | U6: 0.000727 | V6: 0.038312553 | W6: 0.0077924747
A7: 891 | B7: 9957 | C7: הראל קרנות נאמנות בע"מ | D7: 511776783 | E7: ח.פ | F7: הראל.DAX 30 ממ | G7: IL0011491607 | H7: ISIN | I7: עוקב אחר מדדי מניות בחו"ל | J7: ישראל | K7: גרמניה | L7: TASE | M7: מניות בחו"ל משולבת | N7: לא | O7: ILS | P7: 2287 | Q7: 1 | R7: 20650 | T7: 472.265 | U7: 0.0002 | V7: 0.015073217 | W7: 0.0030657749
A8: 891 | B8: 9957 | C8: קסם קרנות נאמנות בע"מ | D8: 510938608 | E8: ח.פ | F8: ממEURO STOXX 50 (4A) ETF.קסם | G8: IL0011459521 | H8: ISIN | I8: עוקב אחר מדדי מניות בחו"ל | J8: ישראל | K8: אירופה | L8: TASE | M8: מניות בחו"ל משולבת | N8: לא | O8: ILS | P8: 22280 | Q8: 1 | R8: 7493 | T8: 1669.44 | U8: 0.0016 | V8: 0.053283243 | W8: 0.010837396
A9: 891 | B9: 9957 | C9: קסם קרנות נאמנות בע"מ | D9: 510938608 | E9: ח.פ | F9: קסם תל בונד שקלי | G9: IL0011464141 | H9: ISIN | I9: עוקב אחר מדדים אחרים בישראל | J9: ישראל | K9: ישראל | L9: TASE | M9: אג"ח בישראל - חברות והמרה | N9: לא | O9: ILS | P9: 99385 | Q9: 1 | R9: 4144.02 | T9: 4118.534 | U9: 0.00184 | V9: 0.13145055 | W9: 0.026736018
A10: 891 | B10: 9957 | C10: Amundi Asset Management | D10: 213800VZW861M5FHMD50 | E10: LEI | F10: AMUNDI MSCI EMERGING MARKETS I | G10: LU2573967036 | H10: ISIN | I10: עוקב אחר מדדי מניות בחו"ל | J10: חו"ל | K10: שווקים מתעוררים | L10: NASDAQ | M10: Equity Funds | N10: לא | O10: USD | P10: 13433 | Q10: 3.372 | R10: 6036 | T10: 2734.071 | U10: 0 | V10: 0.087262881 | W10: 0.01774859
A11: 891 | B11: 9957 | C11: BlackRock Asset Managment | D11: 254900UWHMJRRODS3Z64 | E11: LEI | F11: Cef Ishares Russell iwm | G11: US4642876555 | H11: ISIN | I11: עוקב אחר מדדי מניות בחו"ל | J11: חו"ל | K11: ארה"ב | L11: NYSE | M11: Equity Funds | N11: לא | O11: USD | P11: 1932 | Q11: 3.372 | R11: 21579 | T11: 1405.808 | U11: 7e-06 | V11: 0.044868932 | W11: 0.0091259912
A12: 891 | B12: 9957 | C12: BlackRock Asset Managment | D12: 254900UWHMJRRODS3Z64 | E12: LEI | F12: IGV US_ISHARES EXPANDED TECH | G12: US4642875151 | H12: ISIN | I12: עוקב אחר מדדי מניות בחו"ל | J12: חו"ל | K12: ארה"ב | L12: CBOE | M12: Equity Funds | N12: לא | O12: USD | P12: 775 | Q12: 3.372 | R12: 10950 | T12: 286.156 | U12: 7e-06 | V12: 0.0091332032 | W12: 0.0018576224
A13: 891 | B13: 9957 | C13: BlackRock Asset Managment | D13: 254900UWHMJRRODS3Z64 | E13: LEI | F13: Ishares iboxx h/y corp | G13: US4642885135 | H13: ISIN | I13: עוקב אחר מדדים אחרים בחו"ל | J13: חו"ל | K13: ארה"ב | L13: NYSE | M13: Bond/Fixed Income Funds | N13: לא | O13: USD | P13: 1580 | Q13: 3.372 | R13: 8065 | T13: 429.684 | U13: 5e-06 | V13: 0.013714146 | W13: 0.0027893504
... A15: 891 | B15: 9957 | C15: BlackRock Asset Managment | D15: 254900UWHMJRRODS3Z64 | E15: LEI | F15: MCHI_Ishares Msci Chaina Etf | G15: US46429B6719 | H15: ISIN | I15: עוקב אחר מדדי מניות בחו"ל | J15: חו"ל | K15: סין | L15: NASDAQ | M15: Equity Funds | N15: לא | O15: USD | P15: 2900 | Q15: 3.372 | R15: 5510 | T15: 538.812 | U15: 1.8e-05 | V15: 0.017197167 | W15: 0.0034977697
A16: 891 | B16: 9957 | C16: Invesco investment management limited | D16: ECPGFXU8A2SHKVVGJI15 | E16: LEI | F16: Powershares QQQ NAS1 | G16: US46090E1038 | H16: ISIN | I16: עוקב אחר מדדי מניות בחו"ל | J16: חו"ל | K16: ארה"ב | L16: NASDAQ | M16: Equity Funds | N16: לא | O16: USD | P16: 1072 | Q16: 3.372 | R16: 55164 | S16: 0.318 | T16: 1995.133 | U16: 2e-06 | V16: 0.063678329 | W16: 0.012951676
A17: 891 | B17: 9957 | C17: Invesco investment management limited | D17: ECPGFXU8A2SHKVVGJI15 | E17: LEI | F17: SOURCE S&P 500 UCITS EFT | G17: IE00B3YCGJ38 | H17: ISIN | I17: עוקב אחר מדדי מניות בחו"ל | J17: חו"ל | K17: ארה"ב | L17: LSE | M17: Equity Funds | N17: לא | O17: USD | P17: 988 | Q17: 3.372 | R17: 122758 | T17: 4089.727 | U17: 0.000195 | V17: 0.13053112 | W17: 0.026549012
A18: 891 | B18: 9957 | C18: State Street Corp | D18: 07F5H7W3ET8ZLWNMFP29 | E18: LEI | F18: SPDR BLOOMBERG SASB U.S. HIGH | G18: IE0004TYCC17 | H18: ISIN | I18: עוקב אחר מדדים אחרים בחו"ל | J18: חו"ל | K18: ארה"ב | L18: NYSE | M18: Bond/Fixed Income Funds | N18: לא | O18: USD | P18: 31999 | Q18: 3.372 | R18: 1125.9 | T18: 1214.853 | U18: 0 | V18: 0.038774261 | W18: 0.0078863824
A19: 891 | B19: 9957 | C19: State Street Corp | D19: 07F5H7W3ET8ZLWNMFP29 | E19: LEI | F19: SPDR S&P 500 ETF TRUST | G19: US78462F1030 | H19: ISIN | I19: עוקב אחר מדדי מניות בחו"ל | J19: חו"ל | K19: ארה"ב | L19: NYSE | M19: Equity Funds | N19: לא | O19: USD | P19: 338 | Q19: 3.372 | R19: 61785 | S19: 0.446 | T19: 705.69 | U19: 0 | V19: 0.022523385 | W19: 0.004581081
A20: 891 | B20: 9957 | C20: Van Eck ETF | D20: 549300ZLFKNTXC51ZN76 | E20: LEI | F20: VANECK VECTORS SEMICONDUCTOR | G20: US92189F6768 | H20: ISIN | I20: עוקב אחר מדדי מניות בחו"ל | J20: חו"ל | K20: ארה"ב | L20: NASDAQ | M20: Equity Funds | N20: לא | O20: USD | P20: 357 | Q20: 3.372 | R20: 27888 | T20: 335.717 | U20: 1.6e-05 | V20: 0.010715018 | W20: 0.0021793511
A21: 891 | B21: 9957 | C21: Vanguard Group | D21: 549300Y88GQ3VLJIBX57 | E21: LEI | F21: VANGUARD S&P 500 | G21: us9229083632 | H21: ISIN | I21: עוקב אחר מדדי מניות בחו"ל | J21: חו"ל | K21: ארה"ב | L21: NYSE | M21: Equity Funds | N21: לא | O21: USD | P21: 2400 | Q21: 3.372 | R21: 56803 | S21: 3.138 | T21: 4607.533 | U21: 3e-06 | V21: 0.14705785 | W21: 0.029910422

Sheet קרנות נאמנות
A1: מספר קופה/קרן/ח.פ. עבור חברת ביטוח | B1: מספר מסלול | C1: שם מנפיק | D1: מספר מנפיק | E1: סוג מספר מזהה מנפיק | F1: שם נייר ערך | G1: מספר נייר ערך | H1: סוג מספר נייר ערך | I1: מאפיין עיקרי | J1: ישראל/חו"ל | K1: מדינה לפי חשיפה כלכלית | L1: סטאטוס סחירות | M1: זירת מסחר | N1: סיווג הקרן | O1: בעל עניין/צד קשור | P1: מטבע פעילות | Q1: ערך נקוב (יחידות) | R1: שער חליפין | S1: שער נייר הערך | T1: שווי הוגן (באלפי ש"ח) | U1: שיעור מערך נקוב מונפק | V1: שיעור מנכסי אפיק ההשקעה | W1: שיעור מסך נכסי ההשקעה
A2: 891 | B2: 9957 | C2: אי בי אי ניהול קרנות נאמנות בע"מ | D2: 510791031 | E2: ח.פ | F2: איביאי טכנולגיית עילית | G2: IL0011425381 | H2: ISIN | I2: מניות | J2: ישראל | K2: ישראל | L2: סחיר | M2: TASE | N2: מניות בישראל | O2: לא | P2: ILS | Q2: 295799.52 | R2: 1 | S2: 74.8 | T2: 221.258 | U2: 0.000955 | V2: 0.21712003 | W2: 0.0014363263
