Workbook
Name Additional_Factor: 'אפשרויות בחירה'!$C$701:$C$850
Name Amoritization: 'אפשרויות בחירה'!$C$546:$C$550
Name Capsule: 'אפשרויות בחירה'!$C$926:$C$928
Name Company_Name: 'File Name Info'!$A$34:$A$130
Name Company_Name_ID: 'File Name Info'!$A$34:$B$130
Name Consortium: 'אפשרויות בחירה'!$C$514:$C$515
Name Country_list: 'אפשרויות בחירה'!$C$4:$C$85
Name Country_list_funds: 'אפשרויות בחירה'!$C$4:$C$103
Name CSA: 'אפשרויות בחירה'!$C$688:$C$689
Name Delivery: 'אפשרויות בחירה'!$C$666:$C$667
Name Dependence_Independence: 'אפשרויות בחירה'!$C$654:$C$655
Name Duration_Underlying_Interest_Rate: 'אפשרויות בחירה'!$C$680:$C$687
Name File_Type: 'File Name Info'!$A$10:$A$12
Name Full_File_Type: 'File Name Info'!$A$11:$B$13
Name Full_Type: 'File Name Info'!$A$2:$B$8
Name Full_Type_Nostro: 'File Name Info'!$A$3:$B$6
Name Full_Year: 'File Name Info'!$A$22:$B$31
Name Fund_Strategy: 'אפשרויות בחירה'!$C$597:$C$621
Name Fund_type: 'אפשרויות בחירה'!$C$328:$C$498
Name Holding_interest: 'אפשרויות בחירה'!$C$146:$C$147
Name In_the_books: 'אפשרויות בחירה'!$C$656:$C$657
Name Industry_Sector: 'אפשרויות בחירה'!$C$1129:$C$1245
Name Industry_sector_all: 'אפשרויות בחירה'!$C$202:$C$327
Name Industry_sectors: 'אפשרויות בחירה'!$C$202:$C$327
Name israel_abroad: 'אפשרויות בחירה'!$C$2:$C$3
Name Issuer_Number_Banks: 'אפשרויות בחירה'!$C$111:$C$113
Name Issuer_Number_Fund: 'אפשרויות בחירה'!$C$114:$C$117
Name issuer_number_loan: 'אפשרויות בחירה'!$C$118:$C$126
Name Issuer_Number_Type: 'אפשרויות בחירה'!$C$104:$C$110
Name Issuer_Number_Type_2: 'אפשרויות בחירה'!$C$1076:$C$1079
Name Issuer_Number_Type_3: 'אפשרויות בחירה'!$C$1081:$C$1085
Name Issuer_Number_Type_V2: 'אפשרויות בחירה'!$C$104:$C$110
Name Issuer_Type_TFunds: 'אפשרויות בחירה'!$C$1087:$C$1089
Name Leading_factor: 'אפשרויות בחירה'!$C$692:$C$700
Name Linked_Type: 'אפשרויות בחירה'!$C$516:$C$519
Name other_investments: 'אפשרויות בחירה'!$C$1000:$C$1033
Name Penalty: 'אפשרויות בחירה'!$C$851:$C$852
Name QTR: 'File Name Info'!$A$15:$A$19
Name Rating_Agency: 'אפשרויות בחירה'!$C$188:$C$201
Name real_estate_lifestage: 'אפשרויות בחירה'!$C$634:$C$642
Name real_estate_loans: 'אפשרויות בחירה'!$C$553:$C$591
Name Real_Estate_Main_Use: 'אפשרויות בחירה'!$C$622:$C$633
Name Recourse_Nonrecourse: 'אפשרויות בחירה'!$C$544:$C$545
Name Repayment_Rights: 'אפשרויות בחירה'!$C$551:$C$552
Name Reset_frequency: 'אפשרויות בחירה'!$C$658:$C$665
Name Security_ID_Number_Type: 'אפשרויות בחירה'!$C$1113:$C$1116
Name Security_Number_Loans: 'אפשרויות בחירה'!$C$131
Name Stock_Exchange: 'אפשרויות בחירה'!$C$1283:$C$1315
Name Stock_Exchange_Gov_Bonds: 'אפשרויות בחירה'!$C$148:$C$181
Name Subordination_Risk: 'אפשרויות בחירה'!$C$186:$C$187
Name Tradeable_Status: 'אפשרויות בחירה'!$C$1272:$C$1281
Name Tradeable_Status_All: 'אפשרויות בחירה'!$C$135:$C$145
Name tradeable_status_bonds: 'אפשרויות בחירה'!$C$1248:$C$1253
Name tradeable_status_funds: 'אפשרויות בחירה'!$C$1118:$C$1119
Name tradeable_status_stock: 'אפשרויות בחירה'!$C$1255:$C$1259
Name Tradeable_Status_v2: 'אפשרויות בחירה'!$C$1121:$C$1126
Name tradeable_status_warrants: 'אפשרויות בחירה'!$C$1261:$C$1265
Name tradeable_status_warrants_v2: 'אפשרויות בחירה'!$C$1267:$C$1269
Name Transaction: 'אפשרויות בחירה'!$C$643:$C$646
Name Type: 'File Name Info'!$A$2:$A$8

Sheet עמוד פתיחה
A1: קובץ דיווח עבור רשימת נכסים ברמת הנכס הבודד (חוזר גופים מוסדיים 2015-9-14)
A3: יש לבחור תחום: | D3: נכסי עמיתים - קרנות פנסיה
A5: האם מדובר בקובץ לממומנה או לציבור: | D5: לציבור
A7: יש לבחור את רבעון הדיווח: | D7: 2
A9: יש לבחור את שנת הדיווח: | D9: 2025
A11: יש לבחור את הגוף המוסדי: | D11: קופת הפנסיה לעובדי הדסה בעמ
A13: ח.פ. הגוף המוסדי: | D13: 520022963
A15: שם קובץ לשמירה | D15: 520022963_pn_p_0225.xlsx
A17: פרטי האחראי על הדיווח בגוף המוסדי | B17: שם: | D17: יגאל שלפר
B19: מספר טלפון: | D19: 054-5565745
B21: כתובת מייל: | D21: shlefer@amitim.com
A23: הוראות למילוי הדיווח: | D23: יש לדווח לפי ההנחיות בחלק ג' לנספח 5.4.3.2 שבפרק 3 שבחלק 4 לשער 5 בחוזר המאוחד - "רשימת נכסים ברמת הנכס הבודד".

Sheet סכום נכסים
C1: ידווח בקבצי נכסי הנוסטרו בלבד
B2: שווי הוגן | C2: עלות מופחתת | D2: השיטה שיושמה בדוח הכספי | E2: שיעור מסך נכסי השקעה
A3: מזומנים ושווי מזומנים | B3: =SUM('מזומנים ושווי מזומנים'!O:O) -> 87277.433 | E3: =IFERROR(B3/$B$30,0) -> 0.021204737
A4: איגרות חוב ממשלתיות | B4: =SUM('איגרות חוב ממשלתיות'!U:U) -> 508720.69 | E4: =IFERROR(B4/$B$30,0) -> 0.12359768
A5: ניירות ערך מסחריים | B5: =SUM('ניירות ערך מסחריים'!AD:AD) -> 0 | E5: =IFERROR(B5/$B$30,0) -> 0
A6: איגרות חוב | B6: =SUM('איגרות חוב'!AD:AD) -> 106156.44 | E6: =IFERROR(B6/$B$30,0) -> 0.02579154
A7: מניות, מניות בכורה ויחידות השתתפות | B7: =SUM('מניות מבכ ויהש'!U:U) -> 86195.319 | E7: =IFERROR(B7/$B$30,0) -> 0.020941829
A8: קרנות סל | B8: =SUM('קרנות סל'!T:T) -> 313738.07 | E8: =IFERROR(B8/$B$30,0) -> 0.076225126
A9: קרנות נאמנות | B9: =SUM('קרנות נאמנות'!T:T) -> 29971.416 | E9: =IFERROR(B9/$B$30,0) -> 0.0072817907
A10: כתבי אופציה | B10: =SUM('כתבי אופציה'!W:W) -> 23.9499 | E10: =IFERROR(B10/$B$30,0) -> 5.8188161e-06
A11: אופציות | B11: =SUM(אופציות!V:V) -> 0 | E11: =IFERROR(B11/$B$30,0) -> 0
A12: חוזים עתידיים | B12: =SUM('חוזים עתידיים'!R:R) -> 0 | E12: =IFERROR(B12/$B$30,0) -> 0
A13: מוצרים מובנים | B13: =SUM('מוצרים מובנים'!Z:Z) -> 0 | E13: =IFERROR(B13/$B$30,0) -> 0
A14: לא סחיר איגרות חוב ממשלתיות | B14: =SUM('לא סחיר איגרות חוב ממשלתיות'!U:U) -> 0 | E14: =IFERROR(B14/$B$30,0) -> 0
A15: לא סחיר איגרות חוב מיועדות | B15: =SUM('לא סחיר איגרות חוב מיועדות'!N:N) -> 815615.47 | E15: =IFERROR(B15/$B$30,0) -> 0.19816018
A16: אפיק השקעה מובטח תשואה | B16: =SUM('אפיק השקעה מובטח תשואה'!F:F) -> 0 | E16: =IFERROR(B16/$B$30,0) -> 0
A17: לא סחיר ניירות ערך מסחריים | B17: =SUM('לא סחיר ניירות ערך מסחריים'!AI:AI) -> 0 | E17: =IFERROR(B17/$B$30,0) -> 0
A18: לא סחיר איגרות חוב | B18: =SUM('לא סחיר איגרות חוב'!AG:AG) -> 14159.775 | E18: =IFERROR(B18/$B$30,0) -> 0.0034402284
A19: לא סחיר מניות, מניות בכורה ויחידות השתתפות | B19: =SUM('לא סחיר מניות מבכ ויהש'!X:X) -> 0 | E19: =IFERROR(B19/$B$30,0) -> 0
A20: קרנות השקעה | B20: =SUM('קרנות השקעה'!W:W) -> 2505.418 | E20: =IFERROR(B20/$B$30,0) -> 0.00060871095
A21: לא סחיר כתבי אופציה | B21: =SUM('לא סחיר כתבי אופציה'!Z:Z) -> 0 | E21: =IFERROR(B21/$B$30,0) -> 0
A22: לא סחיר אופציות | B22: =SUM('לא סחיר אופציות'!Z:Z) -> 0 | E22: =IFERROR(B22/$B$30,0) -> 0
A23: לא סחיר נגזרים אחרים | B23: =SUM('לא סחיר נגזרים אחרים'!R:R) -> 3782.4278 | E23: =IFERROR(B23/$B$30,0) -> 0.00091897051
A24: הלוואות | B24: =SUM(הלוואות!AT:AT) -> 18338.508 | E24: =IFERROR(B24/$B$30,0) -> 0.0044554844
A25: לא סחיר מוצרים מובנים | B25: =SUM('לא סחיר מוצרים מובנים'!AB:AB) -> 0 | E25: =IFERROR(B25/$B$30,0) -> 0
A26: פיקדונות מעל 3 חודשים | B26: =SUM('פיקדונות מעל 3 חודשים'!T:T) -> 27874.718 | E26: =IFERROR(B26/$B$30,0) -> 0.0067723815
A27: זכויות מקרקעין | B27: =SUM('זכויות מקרקעין'!S:S) -> 0 | E27: =IFERROR(B27/$B$30,0) -> 0
A28: השקעה בחברות מוחזקות | B28: =SUM('השקעה בחברות מוחזקות'!U:U) -> 0 | E28: =IFERROR(B28/$B$30,0) -> 0
A29: נכסים אחרים | B29: =SUM('נכסים אחרים'!N:N) -> 2101580.7 | E29: =IFERROR(B29/$B$30,0) -> 0.51059552
A30: סך הכל נכסים | B30: =SUM(B3:B29) -> 4115940.3 | E30: =SUM(E3:E29) -> 1
A31: מסגרות אשראי | B31: 65.318
A32: יתרות התחייבויות להשקעה

Sheet מזומנים ושווי מזומנים
A1: מספר קופה/קרן/ח.פ. עבור חברת ביטוח | B1: מספר מסלול | C1: שם הבנק | D1: מספר מזהה בנק | E1: סוג מספר מזהה בנק | F1: מאפיין עיקרי | G1: ישראל/חו"ל | H1: בעל עניין/צד קשור | I1: דירוג הבנק | J1: שם מדרג | K1: מטבע פעילות | L1: שווי מטבעי | M1: שער חליפין | N1: שיעור ריבית | O1: שווי הוגן (באלפי ש"ח) | P1: שיעור מנכסי אפיק ההשקעה | Q1: שיעור מסך נכסי ההשקעה
A2: 274 | B2: 274 | C2: בנק מזרחי | D2: 20-21 | E2: סימול בנק | F2: מזומן ועו"ש נקוב במט"ח | G2: ישראל | H2: לא | I2: ilAAA | J2: S&P מעלות | K2: USD | L2: 218.92736 | M2: 3.372 | O2: 738.22306 | P2: 0.008458 | Q2: 0.000179
A3: 274 | B3: 274 | C3: בנק הפועלים | D3: 12-600 | E3: סימול בנק | F3: מזומן ועו"ש נקוב במט"ח | G3: ישראל | H3: לא | I3: ilAAA | J3: S&P מעלות | K3: DKK | L3: 319.44623 | M3: 0.5301 | O3: 169.33845 | P3: 0.00194 | Q3: 4.1e-05
A4: 274 | B4: 274 | C4: בנק הפועלים | D4: 12-600 | E4: סימול בנק | F4: מזומן ועו"ש נקוב במט"ח | G4: ישראל | H4: לא | I4: ilAAA | J4: S&P מעלות | K4: USD | L4: 3729.4615 | M4: 3.372 | O4: 12575.744 | P4: 0.144089 | Q4: 0.003055
A5: 274 | B5: 274 | C5: בנק הפועלים | D5: 12-600 | E5: סימול בנק | F5: מזומן ועו"ש בש"ח | G5: ישראל | H5: לא | I5: ilAAA | J5: S&P מעלות | K5: ILS | L5: 27349.785 | M5: 1 | O5: 27349.785 | P5: 0.313365 | Q5: 0.006644
A6: 274 | B6: 274 | C6: יו-בנק | D6: 26-273 | E6: סימול בנק | F6: מזומן ועו"ש בש"ח | G6: ישראל | H6: לא | I6: ilAAA | J6: S&P מעלות | K6: ILS | L6: 128.85152 | M6: 1 | O6: 128.85152 | P6: 0.001476 | Q6: 3.1e-05
A7: 274 | B7: 274 | C7: בנק לאומי | D7: 10-800 | E7: סימול בנק | F7: מזומן ועו"ש נקוב במט"ח | G7: ישראל | H7: לא | I7: ilAAA | J7: S&P מעלות | K7: GBP | L7: 138.9235 | M7: 4.6236 | O7: 642.32669 | P7: 0.007359 | Q7: 0.000156
A8: 274 | B8: 274 | C8: בנק דיסקונט | D8: 11-10 | E8: סימול בנק | F8: מזומן ועו"ש נקוב במט"ח | G8: ישראל | H8: לא | I8: ilAAA | J8: S&P מעלות | K8: USD | L8: 23.56657 | M8: 3.372 | O8: 79.46647 | P8: 0.00091 | Q8: 1.9e-05
A9: 274 | B9: 274 | C9: בנק לאומי | D9: 10-800 | E9: סימול בנק | F9: מזומן ועו"ש נקוב במט"ח | G9: ישראל | H9: לא | I9: ilAAA | J9: S&P מעלות | K9: DKK | L9: 14.03109 | M9: 0.5301 | O9: 7.43788 | P9: 8.5e-05 | Q9: 1e-06
A10: 274 | B10: 274 | C10: בנק הפועלים | D10: 12-600 | E10: סימול בנק | F10: מזומן ועו"ש נקוב במט"ח | G10: ישראל | H10: לא | I10: ilAAA | J10: S&P מעלות | K10: CAD | L10: 18.88165 | M10: 2.4674 | O10: 46.58858 | P10: 0.000533 | Q10: 1.1e-05
A11: 274 | B11: 274 | C11: בנק הפועלים | D11: 12-600 | E11: סימול בנק | F11: מזומן ועו"ש נקוב במט"ח | G11: ישראל | H11: לא | I11: ilAAA | J11: S&P מעלות | K11: GBP | L11: 16.01492 | M11: 4.6236 | O11: 74.04658 | P11: 0.000848 | Q11: 1.7e-05
A12: 274 | B12: 274 | C12: יו-בנק | D12: 26-273 | E12: סימול בנק | F12: מזומן ועו"ש נקוב במט"ח | G12: ישראל | H12: לא | I12: ilAAA | J12: S&P מעלות | K12: USD | L12: 21.19476 | M12: 3.372 | O12: 71.46873 | P12: 0.000818 | Q12: 1.7e-05
A13: 274 | B13: 274 | C13: בנק מזרחי | D13: 20-21 | E13: סימול בנק | F13: פח"ק/פר"י | G13: ישראל | H13: לא | I13: ilAAA | J13: S&P מעלות | K13: ILS | L13: 8354.7344 | M13: 1 | O13: 8354.7344 | P13: 0.095726 | Q13: 0.002029
... A28: 274 | B28: 274 | C28: בנק לאומי | D28: 10-800 | E28: סימול בנק | F28: מזומן ועו"ש נקוב במט"ח | G28: ישראל | H28: לא | I28: ilAAA | J28: S&P מעלות | K28: EUR | L28: 22.92477 | M28: 3.9552 | O28: 90.67205 | P28: 0.001038 | Q28: 2.2e-05

Sheet איגרות חוב ממשלתיות
A1: מספר קופה/קרן/ח.פ. עבור חברת ביטוח | B1: מספר מסלול | C1: שם מנפיק | D1: שם נייר ערך | E1: מספר נייר ערך | F1: מאפיין עיקרי | G1: ישראל/חו"ל | H1: מדינה לפי חשיפה כלכלית | I1: זירת מסחר | J1: דירוג | K1: שם מדרג | L1: מטבע פעילות | M1: מח"מ | N1: מועד פדיון | O1: שיעור ריבית | P1: תשואה לפדיון | Q1: סכום לקבל (במטבע הפעילות) | R1: ערך נקוב (יחידות) | S1: שער חליפין | T1: שער נייר הערך | U1: שווי הוגן (באלפי ש"ח) | V1: עלות מופחתת (באלפי ש"ח) | W1: השיטה שיושמה בדוח הכספי | X1: שיעור מערך נקוב מונפק | Y1: שיעור מנכסי אפיק ההשקעה | Z1: שיעור מסך נכסי ההשקעה
A2: 274 | B2: 274 | C2: ממשלת ישראל | D2: ממשלתי שקלי 142 | E2: IL0011254005 | F2: לא צמוד למדד המחירים לצרכן ריבית קבועה | G2: ישראל | H2: ישראל | I2: TASE | J2: ilRF | K2: S&P מעלות | L2: ILS | M2: 11.43 | N2: 51897 | O2: 0.055 | P2: 0.0435 | R2: 1808829 | S2: 1 | T2: 115.63 | U2: 2091.549 | X2: 6.2e-05 | Y2: 0.004111 | Z2: 0.000508
A3: 274 | B3: 274 | C3: ממשלת ישראל | D3: ממשל צמודה 0726 | E3: IL0011695645 | F3: צמוד למדד המחירים לצרכן בריבית קבועה | G3: ישראל | H3: ישראל | I3: TASE | J3: ilRF | K3: S&P מעלות | L3: ILS | M3: 1.08 | N3: 46234 | O3: 0.001 | P3: 0.0233 | R3: 5313038 | S3: 1 | T3: 114.5 | U3: 6083.4285 | X3: 0.000262 | Y3: 0.011958 | Z3: 0.001478
A4: 274 | B4: 274 | C4: ממשלת ישראל | D4: ממשל צמודה 1033 | E4: IL0012043795 | F4: צמוד למדד המחירים לצרכן בריבית קבועה | G4: ישראל | H4: ישראל | I4: TASE | J4: ilRF | K4: S&P מעלות | L4: ILS | M4: 7.78 | N4: 48883 | O4: 0.016 | P4: 0.0197 | R4: 10973000 | S4: 1 | T4: 103.3 | U4: 11335.109 | X4: 0.000463 | Y4: 0.022281 | Z4: 0.002753
A5: 274 | B5: 274 | C5: ממשלת ישראל | D5: ממשל שקלית 0330 | E5: IL0011609851 | F5: לא צמוד למדד המחירים לצרכן ריבית קבועה | G5: ישראל | H5: ישראל | I5: TASE | J5: ilRF | K5: S&P מעלות | L5: ILS | M5: 4.64 | N5: 47573 | O5: 0.01 | P5: 0.0397 | R5: 756821 | S5: 1 | T5: 87.63 | U5: 663.20224 | X5: 2e-05 | Y5: 0.001303 | Z5: 0.000161
A6: 274 | B6: 274 | C6: ממשלת ישראל | D6: ממשלתי צמוד 0841 | E6: IL0011205833 | F6: צמוד למדד המחירים לצרכן בריבית קבועה | G6: ישראל | H6: ישראל | I6: TASE | J6: ilRF | K6: S&P מעלות | L6: ILS | M6: 13.17 | N6: 51744 | O6: 0.0275 | P6: 0.0196 | R6: 39630164 | S6: 1 | T6: 141.8 | U6: 56195.573 | X6: 0.001964 | Y6: 0.110464 | Z6: 0.013653
A7: 274 | B7: 274 | C7: ממשלת ישראל | D7: ממשלתי 0928 | E7: IL0011508798 | F7: לא צמוד למדד המחירים לצרכן ריבית קבועה | G7: ישראל | H7: ישראל | I7: TASE | J7: ilRF | K7: S&P מעלות | L7: ILS | M7: 3.11 | N7: 47024 | O7: 0.0225 | P7: 0.0395 | R7: 45103 | S7: 1 | T7: 96.6 | U7: 43.5695 | X7: 1e-06 | Y7: 8.5e-05 | Z7: 1e-05
A8: 274 | B8: 274 | C8: ממשלת ישראל | D8: ממשלתי משתנה 0526 | E8: IL0011417958 | F8: לא צמוד למדד המחירים לצרכן ריבית משתנה | G8: ישראל | H8: ישראל | I8: TASE | J8: ilRF | K8: S&P מעלות | L8: ILS | M8: 0.9 | N8: 46173 | O8: 0 | P8: 0.0432 | R8: 2118357 | S8: 1 | T8: 100.22 | U8: 2123.0174 | X8: 9.9e-05 | Y8: 0.004173 | Z8: 0.000515
A9: 274 | B9: 274 | C9: ממשלת ישראל | D9: ממשלתי שקלי 1152 | E9: IL0011840761 | F9: לא צמוד למדד המחירים לצרכן ריבית קבועה | G9: ישראל | H9: ישראל | I9: TASE | J9: ilRF | K9: S&P מעלות | L9: ILS | M9: 17.52 | N9: 55852 | O9: 0.028 | P9: 0.0459 | R9: 39981728 | S9: 1 | T9: 73.98 | U9: 29578.482 | X9: 0.001553 | Y9: 0.058142 | Z9: 0.007186
A10: 274 | B10: 274 | C10: ממשלת ישראל | D10: ממשלתי צמוד 0545 | E10: IL0011348658 | F10: צמוד למדד המחירים לצרכן בריבית קבועה | G10: ישראל | H10: ישראל | I10: TASE | J10: ilRF | K10: S&P מעלות | L10: ILS | M10: 17.94 | N10: 53113 | O10: 0.01 | P10: 0.0202 | R10: 53418839 | S10: 1 | T10: 98.54 | U10: 52638.924 | X10: 0.002339 | Y10: 0.103473 | Z10: 0.012789
A11: 274 | B11: 274 | C11: ממשלת ישראל | D11: ממשלתי 0327 | E11: IL0011393449 | F11: לא צמוד למדד המחירים לצרכן ריבית קבועה | G11: ישראל | H11: ישראל | I11: TASE | J11: ilRF | K11: S&P מעלות | L11: ILS | M11: 1.73 | N11: 46477 | O11: 0.02 | P11: 0.04 | R11: 13296396 | S11: 1 | T11: 97.19 | U11: 12922.767 | X11: 0.000471 | Y11: 0.025402 | Z11: 0.003139
A12: 274 | B12: 274 | C12: ממשלת ישראל | D12: ממשלתי צמוד 0536 | E12: IL0010977085 | F12: צמוד למדד המחירים לצרכן בריבית קבועה | G12: ישראל | H12: ישראל | I12: TASE | J12: ilRF | K12: S&P מעלות | L12: ILS | M12: 9.22 | N12: 49825 | O12: 0.04 | P12: 0.0194 | R12: 61925738 | S12: 1 | T12: 167.7 | U12: 103849.46 | X12: 0.003886 | Y12: 0.204138 | Z12: 0.025231
A13: 274 | B13: 274 | C13: ממשלת ישראל | D13: ממשלתי צמוד 1151 | E13: IL0011683013 | F13: צמוד למדד המחירים לצרכן בריבית קבועה | G13: ישראל | H13: ישראל | I13: TASE | J13: ilRF | K13: S&P מעלות | L13: ILS | M13: 24.26 | N13: 55487 | O13: 0.005 | P13: 0.021 | R13: 164086445 | S13: 1 | T13: 79.6 | U13: 130612.81 | X13: 0.005383 | Y13: 0.256747 | Z13: 0.031733
... A20: 274 | B20: 274 | C20: US Government | D20: B 0 08/21/25 (p) | E20: US912797PP64 | F20: מק"מ קצר משנים עשר חודשים | G20: חו"ל | H20: ארה"ב | I20: אחר | J20: Aa1 | K20: Moodys | L20: USD | M20: 0.14 | N20: 45890 | O20: 0 | P20: 0.0437 | R20: 52000 | S20: 3.372 | T20: 99.3927 | U20: 174.27914 | X20: 0 | Y20: 0.000342 | Z20: 4.2e-05

Sheet ניירות ערך מסחריים
A1: מספר קופה/קרן/ח.פ. עבור חברת ביטוח | B1: מספר מסלול | C1: שם מנפיק | D1: מספר מנפיק | E1: סוג מספר מזהה מנפיק | F1: שם נייר ערך | G1: מספר נייר ערך | H1: סוג מספר נייר ערך | I1: מאפיין עיקרי | J1: ישראל/חו"ל | K1: מדינה לפי חשיפה כלכלית | L1: זירת מסחר | M1: ענף מסחר | N1: בעל עניין/צד קשור | O1: דירוג | P1: שם מדרג | Q1: דירוג נייר הערך/המנפיק | R1: מטבע פעילות | S1: מח"מ | T1: ריבית עוגן | U1: מועד פדיון | V1: שיעור ריבית | W1: תשואה לפדיון | X1: נחיתות חוזית | Y1: האם סווג כחוב בעייתי | Z1: ערך נקוב (יחידות) | AA1: שער חליפין | AB1: שער נייר הערך | AC1: סכום לקבל (במטבע הפעילות) | AD1: שווי הוגן (באלפי ש"ח) | AE1: עלות מופחתת (באלפי ש"ח) | AF1: עלות מופחתת (במטבע הפעילות) | AG1: השיטה שיושמה בדוח הכספי | AH1: שיעור מערך נקוב מונפק | AI1: שיעור מנכסי אפיק ההשקעה | AJ1: שיעור מסך נכסי ההשקעה
A2: 274 | B2: 274

Sheet איגרות חוב
A1: מספר קופה/קרן/ח.פ. עבור חברת ביטוח | B1: מספר מסלול | C1: שם מנפיק | D1: מספר מנפיק | E1: סוג מספר מזהה מנפיק | F1: שם נייר ערך | G1: מספר נייר ערך | H1: סוג מספר נייר ערך | I1: מאפיין עיקרי | J1: ישראל/חו"ל | K1: מדינה לפי חשיפה כלכלית | L1: סטאטוס סחירות | M1: זירת מסחר | N1: ענף מסחר | O1: בעל עניין/צד קשור | P1: דירוג | Q1: שם מדרג | R1: דירוג נייר הערך/המנפיק | S1: מטבע פעילות | T1: מח"מ | U1: מועד פדיון | V1: שיעור ריבית | W1: תשואה לפדיון | X1: נחיתות חוזית | Y1: האם סווג כחוב בעייתי | Z1: ערך נקוב (יחידות) | AA1: שער חליפין | AB1: שער נייר הערך | AC1: סכום לקבל (במטבע הפעילות) | AD1: שווי הוגן (באלפי ש"ח) | AE1: עלות מופחתת (באלפי ש"ח) | AF1: עלות מופחתת (במטבע הפעילות) | AG1: השיטה שיושמה בדוח הכספי | AH1: שיעור מערך נקוב מונפק | AI1: שיעור מנכסי אפיק ההשקעה | AJ1: שיעור מסך נכסי ההשקעה
A2: 274 | B2: 274 | C2: מזרחי טפחות הנפקות | D2: 520032046 | E2: ח.פ. | F2: מזרחי טפחות הנפקות 49 | G2: IL0023102820 | H2: ISIN | I2: צמוד למדד המחירים לצרכן | J2: ישראל | K2: ישראל | L2: סחיר | M2: TASE | N2: בנקים | O2: לא | P2: ilAAA | Q2: S&P מעלות | R2: נייר ערך | S2: ILS | T2: 0.98 | U2: 46196 | V2: 0.0038 | W2: 0.0255 | X2: החוב לא נחות | Z2: 750000 | AA2: 1 | AB2: 112.93 | AD2: 846.975 | AH2: 0.00025 | AI2: 0.007978 | AJ2: 0.000205
A3: 274 | B3: 274 | C3: חברת החשמל לישראל בע"מ | D3: 520000472 | E3: ח.פ. | F3: חשמל 35 | G3: IL0011967994 | H3: ISIN | I3: צמוד למדד המחירים לצרכן | J3: ישראל | K3: ישראל | L3: סחיר | M3: TASE | N3: אנרגיה | O3: לא | P3: ilAAA | Q3: S&P מעלות | R3: נייר ערך | S3: ILS | T3: 10.06 | U3: 50203 | V3: 0.032 | W3: 0.0279 | X3: החוב לא נחות | Z3: 1287000 | AA3: 1 | AB3: 110.87 | AD3: 1426.8969 | AH3: 0.000261 | AI3: 0.013441 | AJ3: 0.000346
A4: 274 | B4: 274 | C4: בנק הפועלים | D4: 520000118 | E4: ח.פ. | F4: פועלים אגח 201 | G4: IL0011913451 | H4: ISIN | I4: צמוד למדד המחירים לצרכן | J4: ישראל | K4: ישראל | L4: סחיר | M4: TASE | N4: בנקים | O4: לא | P4: Aaa.il | Q4: מידרוג Moodys | R4: נייר ערך | S4: ILS | T4: 3.72 | U4: 48547 | V4: 0.0139 | W4: 0.0251 | X4: החוב לא נחות | Z4: 114400 | AA4: 1 | AB4: 105.13 | AD4: 120.26872 | AH4: 7.1e-05 | AI4: 0.001132 | AJ4: 2.9e-05
A5: 274 | B5: 274 | C5: בנק הפועלים | D5: 520000118 | E5: ח.פ. | F5: פועלים אגח 202 | G5: IL0011998502 | H5: ISIN | I5: צמוד למדד המחירים לצרכן | J5: ישראל | K5: ישראל | L5: סחיר | M5: TASE | N5: בנקים | O5: לא | P5: Aaa.il | Q5: מידרוג Moodys | R5: נייר ערך | S5: ILS | T5: 1.81 | U5: 46872 | V5: 0.006 | W5: 0.0247 | X5: החוב לא נחות | Z5: 386700 | AA5: 1 | AB5: 114.32 | AD5: 442.07544 | AH5: 0.000579 | AI5: 0.004164 | AJ5: 0.000107
A6: 274 | B6: 274 | C6: בנק הפועלים | D6: 520000118 | E6: ח.פ. | F6: פועלים התח נד ז | G6: IL0011913295 | H6: ISIN | I6: צמוד למדד המחירים לצרכן | J6: ישראל | K6: ישראל | L6: סחיר | M6: TASE | N6: בנקים | O6: לא | P6: ilAA- | Q6: S&P מעלות | R6: נייר ערך | S6: ILS | T6: 3.24 | U6: 47086 | V6: 0.0309 | W6: 0.0298 | X6: החוב לא נחות | Z6: 600000 | AA6: 1 | AB6: 110.98 | AD6: 665.88 | AH6: 0.000631 | AI6: 0.006272 | AJ6: 0.000161
A7: 274 | B7: 274 | C7: חברת החשמל לישראל בע"מ | D7: 520000472 | E7: ח.פ. | F7: חשמל אגח 33 | G7: IL0060003923 | H7: ISIN | I7: צמוד למדד המחירים לצרכן | J7: ישראל | K7: ישראל | L7: סחיר | M7: TASE | N7: אנרגיה | O7: לא | P7: ilAAA | Q7: S&P מעלות | R7: נייר ערך | S7: ILS | T7: 10.2 | U7: 49825 | V7: 0.0125 | W7: 0.0279 | X7: החוב לא נחות | Z7: 586000 | AA7: 1 | AB7: 98.88 | AD7: 579.4368 | AH7: 0.000136 | AI7: 0.005458 | AJ7: 0.00014
A8: 274 | B8: 274 | C8: קבוצת עזריאלי בע"מ | D8: 510960719 | E8: ח.פ. | F8: עזריאלי אגח ד | G8: IL0011386500 | H8: ISIN | I8: צמוד למדד המחירים לצרכן | J8: ישראל | K8: ישראל | L8: סחיר | M8: TASE | N8: נדל"ן מניב בישראל | O8: לא | P8: Aa1.il | Q8: מידרוג Moodys | R8: נייר ערך | S8: ILS | T8: 2.68 | U8: 47669 | V8: 0.0134 | W8: 0.028 | X8: החוב לא נחות | Z8: 41086.65 | AA8: 1 | AB8: 114.07 | AC8: 5.23046 | AD8: 52.098 | AH8: 1.8e-05 | AI8: 0.000489 | AJ8: 1.2e-05
A9: 274 | B9: 274 | C9: מזרחי טפחות הנפקות | D9: 520032046 | E9: ח.פ. | F9: מזרחי טפחות הנפקות 64 | G9: IL0023105559 | H9: ISIN | I9: צמוד למדד המחירים לצרכן | J9: ישראל | K9: ישראל | L9: סחיר | M9: TASE | N9: בנקים | O9: לא | P9: ilAAA | Q9: S&P מעלות | R9: נייר ערך | S9: ILS | T9: 3.21 | U9: 47950 | V9: 0.001 | W9: 0.0258 | X9: החוב לא נחות | Z9: 1473407 | AA9: 1 | AB9: 104.36 | AD9: 1537.6475 | AH9: 0.00066 | AI9: 0.014484 | AJ9: 0.000373
A10: 274 | B10: 274 | C10: לאומי | D10: 520018078 | E10: ח.פ. | F10: לאומי מימון 179 | G10: IL0060403727 | H10: ISIN | I10: צמוד למדד המחירים לצרכן | J10: ישראל | K10: ישראל | L10: סחיר | M10: TASE | N10: בנקים | O10: לא | P10: ilAAA | Q10: S&P מעלות | R10: נייר ערך | S10: ILS | T10: 1 | U10: 46203 | V10: 0.0083 | W10: 0.0248 | X10: החוב לא נחות | Z10: 377569 | AA10: 1 | AB10: 115.16 | AD10: 434.80846 | AH10: 0.000248 | AI10: 0.004095 | AJ10: 0.000105
A11: 274 | B11: 274 | C11: נתיבי הגז הטבעי לישראל בע"מ | D11: 513436394 | E11: ח.פ. | F11: נתיבי גז אגח ד | G11: IL0011475030 | H11: ISIN | I11: צמוד למדד המחירים לצרכן | J11: ישראל | K11: ישראל | L11: סחיר | M11: TASE | N11: שירותים | O11: לא | P11: Aa1.il | Q11: מידרוג Moodys | R11: נייר ערך | S11: ILS | T11: 5.05 | U11: 48760 | V11: 0.0295 | W11: 0.0252 | X11: החוב לא נחות | Z11: 3888057.3 | AA11: 1 | AB11: 118.55 | AD11: 4609.2919 | AH11: 0.002736 | AI11: 0.043419 | AJ11: 0.001119
A12: 274 | B12: 274 | C12: דיסקונט מנפיקים בע"מ | D12: 520029935 | E12: ח.פ. | F12: דיסקונט מנפיקים אגח טו | G12: IL0074803045 | H12: ISIN | I12: צמוד למדד המחירים לצרכן | J12: ישראל | K12: ישראל | L12: סחיר | M12: TASE | N12: בנקים | O12: לא | P12: ilAAA | Q12: S&P מעלות | R12: נייר ערך | S12: ILS | T12: 3.5 | U12: 48441 | V12: 0.002 | W12: 0.026 | X12: החוב לא נחות | Z12: 4495158.2 | AA12: 1 | AB12: 105.05 | AD12: 4722.1637 | AH12: 0.001318 | AI12: 0.044483 | AJ12: 0.001147
A13: 274 | B13: 274 | C13: בנק הפועלים | D13: 520000118 | E13: ח.פ. | F13: פועלים התח נד ה | G13: IL0066204624 | H13: ISIN | I13: צמוד למדד המחירים לצרכן | J13: ישראל | K13: ישראל | L13: סחיר | M13: TASE | N13: בנקים | O13: לא | P13: ilAA- | Q13: S&P מעלות | R13: נייר ערך | S13: ILS | T13: 1.1 | U13: 46251 | V13: 0.0297 | W13: 0.0303 | X13: החוב לא נחות | Z13: 300000 | AA13: 1 | AB13: 119.99 | AD13: 359.97 | AH13: 0.000428 | AI13: 0.00339 | AJ13: 8.7e-05
A14: 274 | B14: 274 | C14: בנק הפועלים | D14: 520000118 | E14: ח.פ. | F14: פועלים 200 | G14: IL0066204962 | H14: ISIN | I14: צמוד למדד המחירים לצרכן | J14: ישראל | K14: ישראל | L14: סחיר | M14: TASE | N14: בנקים | O14: לא | P14: Aaa.il | Q14: מידרוג Moodys | R14: נייר ערך | S14: ILS | T14: 3.34 | U14: 48191 | V14: 0.001 | W14: 0.0257 | X14: החוב לא נחות | Z14: 465458.7 | AA14: 1 | AB14: 105.19 | AD14: 489.61601 | AH14: 0.000472 | AI14: 0.004612 | AJ14: 0.000118
A15: 274 | B15: 274 | C15: בנק הפועלים | D15: 520000118 | E15: ח.פ. | F15: פועלים אגח 203 | G15: IL0011998684 | H15: ISIN | I15: צמוד למדד המחירים לצרכן | J15: ישראל | K15: ישראל | L15: סחיר | M15: TASE | N15: בנקים | O15: לא | P15: Aaa.il | Q15: מידרוג Moodys | R15: נייר ערך | S15: ILS | T15: 2.81 | U15: 47819 | V15: 0.0175 | W15: 0.0244 | X15: החוב לא נחות | Z15: 766449.9 | AA15: 1 | AB15: 115.29 | AD15: 883.64009 | AH15: 0.000343 | AI15: 0.008323 | AJ15: 0.000214
A16: 274 | B16: 274 | C16: בזק החברה הישראלית לתקשורת בע"מ | D16: 520031931 | E16: ח.פ. | F16: בזק 9 | G16: IL0023001766 | H16: ISIN | I16: לא צמוד למדד המחירים לצרכן | J16: ישראל | K16: ישראל | L16: סחיר | M16: TASE | N16: תקשורת ומדיה | O16: לא | P16: Aa2.il | Q16: מידרוג Moodys | R16: נייר ערך | S16: ILS | T16: 0.42 | U16: 45992 | V16: 0.0365 | W16: 0.0448 | X16: החוב לא נחות | Z16: 176220.85 | AA16: 1 | AB16: 99.97 | AD16: 176.16798 | AH16: 0.00033 | AI16: 0.001659 | AJ16: 4.2e-05
A17: 274 | B17: 274 | C17: לאומי | D17: 520018078 | E17: ח.פ. | F17: לאומי 183 | G17: IL0060405474 | H17: ISIN | I17: צמוד למדד המחירים לצרכן | J17: ישראל | K17: ישראל | L17: סחיר | M17: TASE | N17: בנקים | O17: לא | P17: ilAAA | Q17: S&P מעלות | R17: נייר ערך | S17: ILS | T17: 4.39 | U17: 47447 | V17: 0.001 | W17: 0.0258 | X17: החוב לא נחות | Z17: 2394730 | AA17: 1 | AB17: 102.6 | AD17: 2456.993 | AH17: 0.000558 | AI17: 0.023145 | AJ17: 0.000596
A18: 274 | B18: 274 | C18: חברת החשמל לישראל בע"מ | D18: 520000472 | E18: ח.פ. | F18: חשמל אגח 27 | G18: IL0060002107 | H18: ISIN | I18: צמוד למדד המחירים לצרכן | J18: ישראל | K18: ישראל | L18: סחיר | M18: TASE | N18: אנרגיה | O18: לא | P18: ilAAA | Q18: S&P מעלות | R18: נייר ערך | S18: ILS | T18: 2.77 | U18: 47220 | V18: 0.0385 | W18: 0.0246 | X18: החוב לא נחות | Z18: 11402090 | AA18: 1 | AB18: 123.46 | AD18: 14077.02 | AH18: 0.004511 | AI18: 0.132606 | AJ18: 0.00342
A19: 274 | B19: 274 | C19: הראל ביטוח מימון והנפקות בע"מ | D19: 513834200 | E19: ח.פ. | F19: הראל שטר הון נדחה יג 2029 3.95% | G19: IL0011381717 | H19: ISIN | I19: לא צמוד למדד המחירים לצרכן | J19: ישראל | K19: ישראל | L19: סחיר | M19: TASE | N19: ביטוח | O19: לא | P19: Aa3.il | Q19: מידרוג Moodys | R19: נייר ערך | S19: ILS | T19: 4.17 | U19: 47483 | V19: 0.0395 | W19: 0.0448 | X19: החוב לא נחות | Z19: 26066 | AA19: 1 | AB19: 98.06 | AD19: 25.56032 | AH19: 0.000108 | AI19: 0.00024 | AJ19: 6e-06
A20: 274 | B20: 274 | C20: מקורות חברת מים בע"מ | D20: 520010869 | E20: ח.פ. | F20: מקורות סדרה 10 | G20: IL0011584682 | H20: ISIN | I20: צמוד למדד המחירים לצרכן | J20: ישראל | K20: ישראל | L20: סחיר | M20: TASE | N20: שירותים | O20: לא | P20: ilAAA | Q20: S&P מעלות | R20: נייר ערך | S20: ILS | T20: 1.48 | U20: 46752 | V20: 0.001 | W20: 0.026 | X20: החוב לא נחות | Z20: 967200 | AA20: 1 | AB20: 111.15 | AD20: 1075.0428 | AH20: 0.001505 | AI20: 0.010126 | AJ20: 0.000261
... A26: 274 | B26: 274 | C26: מימון ישיר | D26: 513893123 | E26: ח.פ. | F26: מימון ישיר אגח ד | G26: IL0011756603 | H26: ISIN | I26: צמוד למדד המחירים לצרכן | J26: ישראל | K26: ישראל | L26: סחיר | M26: TASE | N26: אשראי חוץ בנקאי | O26: לא | P26: A1.il | Q26: מידרוג Moodys | R26: נייר ערך | S26: ILS | T26: 0.18 | U26: 46054 | V26: 0.01 | W26: 0.0353 | X26: החוב לא נחות | Z26: 138232.86 | AA26: 1 | AB26: 115.84 | AD26: 160.12895 | AH26: 0.000817 | AI26: 0.001508 | AJ26: 3.8e-05
A27: 274 | B27: 274 | C27: מזרחי טפחות הנפקות | D27: 520032046 | E27: ח.פ. | F27: מזרחי טפחות הנפקות 52 | G27: IL0023103810 | H27: ISIN | I27: צמוד למדד המחירים לצרכן | J27: ישראל | K27: ישראל | L27: סחיר | M27: TASE | N27: בנקים | O27: לא | P27: ilAAA | Q27: S&P מעלות | R27: נייר ערך | S27: ILS | T27: 4.98 | U27: 47665 | V27: 0.002 | W27: 0.0261 | X27: החוב לא נחות | Z27: 2913500 | AA27: 1 | AB27: 104.05 | AC27: 6.82661 | AD27: 3038.3234 | AH27: 0.000842 | AI27: 0.02862 | AJ27: 0.000737
A28: 274 | B28: 274 | C28: קבוצת עזריאלי בע"מ | D28: 510960719 | E28: ח.פ. | F28: עזריאלי אגח ט | G28: IL0012092537 | H28: ISIN | I28: צמוד למדד המחירים לצרכן | J28: ישראל | K28: ישראל | L28: סחיר | M28: TASE | N28: נדל"ן מניב בישראל | O28: לא | P28: Aa1.il | Q28: מידרוג Moodys | R28: נייר ערך | S28: ILS | T28: 11.94 | U28: 53329 | V28: 0.0367 | W28: 0.0316 | X28: החוב לא נחות | Z28: 1882000 | AA28: 1 | AB28: 109.54 | AC28: 35.56791 | AD28: 2097.1107 | AH28: 0.000573 | AI28: 0.019754 | AJ28: 0.000508
A29: 274 | B29: 274 | C29: חברת החשמל לישראל בע"מ | D29: 520000472 | E29: ח.פ. | F29: חשמל 34 | G29: IL0011967812 | H29: ISIN | I29: צמוד למדד המחירים לצרכן | J29: ישראל | K29: ישראל | L29: סחיר | M29: TASE | N29: אנרגיה | O29: לא | P29: ilAAA | Q29: S&P מעלות | R29: נייר ערך | S29: ILS | T29: 7.14 | U29: 48742 | V29: 0.03 | W29: 0.026 | X29: החוב לא נחות | Z29: 1976000 | AA29: 1 | AB29: 109.5 | AD29: 2163.72 | AH29: 0.000484 | AI29: 0.020382 | AJ29: 0.000525
A30: 274 | B30: 274 | C30: מזרחי טפחות הנפקות | D30: 520032046 | E30: ח.פ. | F30: מזרחי טפחות הנפקות 46 | G30: IL0023102259 | H30: ISIN | I30: צמוד למדד המחירים לצרכן | J30: ישראל | K30: ישראל | L30: סחיר | M30: TASE | N30: בנקים | O30: לא | P30: ilAAA | Q30: S&P מעלות | R30: נייר ערך | S30: ILS | T30: 2.21 | U30: 46658 | V30: 0.0122 | W30: 0.0251 | X30: החוב לא נחות | Z30: 7934990 | AA30: 1 | AB30: 116.02 | AD30: 9206.1754 | AH30: 0.002631 | AI30: 0.086722 | AJ30: 0.002236
A31: 274 | B31: 274 | C31: חברת החשמל לישראל בע"מ | D31: 520000472 | E31: ח.פ. | F31: חשמל 31 | G31: IL0060002859 | H31: ISIN | I31: צמוד למדד המחירים לצרכן | J31: ישראל | K31: ישראל | L31: סחיר | M31: TASE | N31: אנרגיה | O31: לא | P31: ilAAA | Q31: S&P מעלות | R31: נייר ערך | S31: ILS | T31: 5.12 | U31: 48112 | V31: 0.0239 | W31: 0.0262 | X31: החוב לא נחות | Z31: 3431000 | AA31: 1 | AB31: 116.21 | AD31: 3987.1651 | AH31: 0.000882 | AI31: 0.037559 | AJ31: 0.000968
A32: 274 | B32: 274 | C32: מימון ישיר | D32: 513893123 | E32: ח.פ. | F32: מימון ישיר קבוצה ו | G32: IL0011916595 | H32: ISIN | I32: צמוד למדד המחירים לצרכן | J32: ישראל | K32: ישראל | L32: סחיר | M32: TASE | N32: אשראי חוץ בנקאי | O32: לא | P32: A1.il | Q32: מידרוג Moodys | R32: נייר ערך | S32: ILS | T32: 1.06 | U32: 46477 | V32: 0.0354 | W32: 0.0342 | X32: החוב לא נחות | Z32: 271737.9 | AA32: 1 | AB32: 109.8 | AD32: 298.36821 | AH32: 0.00027 | AI32: 0.00281 | AJ32: 7.2e-05
A33: 274 | B33: 274 | C33: איידיאיי הנפקות | D33: 514486042 | E33: ח.פ. | F33: אידיאי הנפקות שטר הון נדחה ה 3.27% 15.11.25 רובד2 | G33: IL0011558785 | H33: ISIN | I33: לא צמוד למדד המחירים לצרכן | J33: ישראל | K33: ישראל | L33: סחיר | M33: TASE | N33: ביטוח | O33: לא | P33: A2.il | Q33: מידרוג Moodys | R33: נייר ערך | S33: ILS | T33: 0.4 | U33: 45976 | V33: 0.0327 | W33: 0.0507 | X33: החוב לא נחות | Z33: 516000 | AA33: 1 | AB33: 99.72 | AD33: 514.5552 | AH33: 0.001635 | AI33: 0.004847 | AJ33: 0.000125
A34: 274 | B34: 274 | C34: קבוצת עזריאלי בע"מ | D34: 510960719 | E34: ח.פ. | F34: עזריאלי אגח ה | G34: IL0011566036 | H34: ISIN | I34: צמוד למדד המחירים לצרכן | J34: ישראל | K34: ישראל | L34: סחיר | M34: TASE | N34: נדל"ן מניב בישראל | O34: לא | P34: Aa1.il | Q34: מידרוג Moodys | R34: נייר ערך | S34: ILS | T34: 1.96 | U34: 46934 | V34: 0.0177 | W34: 0.0282 | X34: החוב לא נחות | Z34: 1145250 | AA34: 1 | AB34: 114.73 | AD34: 1313.9453 | AH34: 0.00047 | AI34: 0.012377 | AJ34: 0.000319
A35: 274 | B35: 274 | C35: מזרחי טפחות הנפקות | D35: 520032046 | E35: ח.פ. | F35: מזרחי טפחות הנפקות אגח 62 | G35: IL0023104982 | H35: ISIN | I35: צמוד למדד המחירים לצרכן | J35: ישראל | K35: ישראל | L35: סחיר | M35: TASE | N35: בנקים | O35: לא | P35: ilAAA | Q35: S&P מעלות | R35: נייר ערך | S35: ILS | T35: 3.3 | U35: 47048 | V35: 0.001 | W35: 0.0258 | X35: החוב לא נחות | Z35: 8521952 | AA35: 1 | AB35: 105.48 | AD35: 8988.955 | AH35: 0.002523 | AI35: 0.084676 | AJ35: 0.002183
A36: 274 | B36: 274 | C36: מימון ישיר | D36: 513893123 | E36: ח.פ. | F36: הפחתה בגין קניה בהנפקה מימון ישיר ו 12.9.23 | G36: IL0011916595 | H36: ISIN | I36: צמוד למדד המחירים לצרכן | J36: ישראל | K36: ישראל | L36: סחיר | M36: TASE | N36: אשראי חוץ בנקאי | O36: לא | P36: A1.il | Q36: מידרוג Moodys | R36: נייר ערך | S36: ILS | T36: 1.04 | U36: 46477 | V36: 0.0354 | W36: 0.1305 | X36: החוב לא נחות | Z36: -264.67 | AA36: 1 | AB36: 100 | AD36: -0.26467 | AH36: 0 | AI36: -2e-06 | AJ36: 0
A37: 274 | B37: 274 | C37: מזרחי טפחות הנפקות | D37: 520032046 | E37: ח.פ. | F37: מזרחי טפ הנ אגח 68 | G37: IL0012021429 | H37: ISIN | I37: צמוד למדד המחירים לצרכן | J37: ישראל | K37: ישראל | L37: סחיר | M37: TASE | N37: בנקים | O37: לא | P37: ilAAA | Q37: S&P מעלות | R37: נייר ערך | S37: ILS | T37: 4.2 | U37: 48938 | V37: 0.0199 | W37: 0.0258 | X37: החוב לא נחות | Z37: 3780000 | AA37: 1 | AB37: 103.57 | AD37: 3914.946 | AH37: 0.001555 | AI37: 0.036879 | AJ37: 0.000951
A38: 274 | B38: 274 | C38: הראל ביטוח מימון והנפקות בע"מ | D38: 513834200 | E38: ח.פ. | F38: הראל הנפק אגח ט | G38: IL0011340309 | H38: ISIN | I38: צמוד למדד המחירים לצרכן | J38: ישראל | K38: ישראל | L38: סחיר | M38: TASE | N38: ביטוח | O38: לא | P38: Aa3.il | Q38: מידרוג Moodys | R38: נייר ערך | S38: ILS | T38: 0.5 | U38: 46022 | V38: 0.024 | W38: 0.0288 | X38: החוב לא נחות | Z38: 34548 | AA38: 1 | AB38: 116.76 | AD38: 40.33824 | AH38: 0.000117 | AI38: 0.000379 | AJ38: 9e-06
A39: 274 | B39: 274 | C39: HF SINCLAIR CORP | D39: 98840072S6T63E2V1291 | E39: LEI | F39: DINO 4 1/2 10/01/30 | G39: US403949AC48 | H39: ISIN | I39: צמוד למט"ח | J39: חו"ל | K39: ארה"ב | L39: סחיר | M39: אחר | N39: Energy Equipment & Services | O39: לא | P39: BBB- | Q39: S&P | R39: נייר ערך | S39: USD | T39: 4.68 | U39: 47757 | V39: 0.045 | W39: 0.0523 | X39: החוב לא נחות | Z39: 12000 | AA39: 3.372 | AB39: 98.0653 | AD39: 39.68114 | AH39: 3.6e-05 | AI39: 0.000373 | AJ39: 9e-06
A40: 274 | B40: 274 | C40: Micron Technology Inc | D40: B3DXGBC8GAIYWI2Z0172 | E40: LEI | F40: MU 5 7.8 09.15.33 | G40: US595112CB74 | H40: ISIN | I40: צמוד למט"ח | J40: חו"ל | K40: ארה"ב | L40: סחיר | M40: אחר | N40: Technology Hardware, Storage & Peripherals | O40: לא | P40: Baa3 | Q40: Moodys | R40: נייר ערך | S40: USD | T40: 6.57 | U40: 48837 | V40: 0.05875 | W40: 0.0524 | X40: החוב לא נחות | Z40: 18000 | AA40: 3.372 | AB40: 106.2952 | AD40: 64.51693 | AH40: 2e-05 | AI40: 0.000607 | AJ40: 1.5e-05
A41: 274 | B41: 274 | C41: Hong Kong Airport Authority | D41: 549300DSMAD69T7GGN13 | E41: LEI | F41: HKAA 2.4 PERP | G41: XS2264055182 | H41: ISIN | I41: צמוד למט"ח | J41: חו"ל | K41: הונג קונג | L41: סחיר | M41: HKSE | N41: Other | O41: לא | P41: AA | Q41: S&P | R41: נייר ערך | S41: USD | T41: 2.61 | U41: 46820 | V41: 0.024 | W41: 0.0477 | X41: החוב לא נחות | Z41: 45000 | AA41: 3.372 | AB41: 94.363 | AD41: 143.18642 | AH41: 6e-05 | AI41: 0.001348 | AJ41: 3.4e-05
A42: 274 | B42: 274 | C42: Tapestry | D42: 549300LJNVY5SW3VTN33 | E42: LEI | F42: TPR 4 1/8 07/15/27 | G42: US189754AC88 | H42: ISIN | I42: צמוד למט"ח | J42: חו"ל | K42: ארה"ב | L42: סחיר | M42: NYSE | N42: Personal Care Products | O42: לא | P42: BBB | Q42: S&P | R42: נייר ערך | S42: USD | T42: 1.94 | U42: 46583 | V42: 0.04125 | W42: 0.0456 | X42: החוב לא נחות | Z42: 5000 | AA42: 3.372 | AB42: 101.1551 | AD42: 17.05475 | AH42: 1.2e-05 | AI42: 0.00016 | AJ42: 4e-06
A43: 274 | B43: 274 | C43: POSCO | D43: 988400E5HRVX81AYLM04 | E43: LEI | F43: POHANG 5.75 01/17/28 | G43: USY7S272AG74 | H43: ISIN | I43: צמוד למט"ח | J43: חו"ל | K43: Developed Markets - Pacific | L43: סחיר | M43: FWB | N43: Metals & Mining | O43: לא | P43: Baa1 | Q43: Moodys | R43: נייר ערך | S43: USD | T43: 2.35 | U43: 46769 | V43: 0.0575 | W43: 0.0473 | X43: החוב לא נחות | Z43: 26000 | AA43: 3.372 | AB43: 105.141 | AD43: 92.17922 | AH43: 2.6e-05 | AI43: 0.000868 | AJ43: 2.2e-05
A44: 274 | B44: 274 | C44: valero energy corp | D44: 549300XTO5VR8SKV1V74 | E44: LEI | F44: VLO 5.15 02/15/30 | G44: US91913YBF60 | H44: ISIN | I44: צמוד למט"ח | J44: חו"ל | K44: ארה"ב | L44: סחיר | M44: אחר | N44: Energy Equipment & Services | O44: לא | P44: Baa2 | Q44: Moodys | R44: נייר ערך | S44: USD | T44: 4.1 | U44: 47529 | V44: 0.0515 | W44: 0.0467 | X44: החוב לא נחות | Z44: 24000 | AA44: 3.372 | AB44: 104.2507 | AD44: 84.36801 | AH44: 3.6e-05 | AI44: 0.000794 | AJ44: 2e-05
A45: 274 | B45: 274 | C45: Verisign | D45: LMPL4N8ZOJRMF0KOF759 | E45: LEI | F45: VRSN 2.7 06/15/31 | G45: US92343EAM49 | H45: ISIN | I45: צמוד למט"ח | J45: חו"ל | K45: ארה"ב | L45: סחיר | M45: אחר | N45: Software | O45: לא | P45: Baa3 | Q45: Moodys | R45: נייר ערך | S45: USD | T45: 5.51 | U45: 48014 | V45: 0.027 | W45: 0.0482 | X45: החוב לא נחות | Z45: 25000 | AA45: 3.372 | AB45: 89.4923 | AD45: 75.44201 | AH45: 3.3e-05 | AI45: 0.00071 | AJ45: 1.8e-05
...

Sheet מניות מבכ ויהש
A1: מספר קופה/קרן/ח.פ. עבור חברת ביטוח | B1: מספר מסלול | C1: שם מנפיק | D1: מספר מנפיק | E1: סוג מספר מזהה מנפיק | F1: שם נייר ערך | G1: מספר נייר ערך | H1: סוג מספר נייר ערך | I1: מאפיין עיקרי | J1: ישראל/חו"ל | K1: מדינה לפי חשיפה כלכלית | L1: סטאטוס סחירות | M1: זירת מסחר | N1: ענף מסחר | O1: בעל עניין/צד קשור | P1: מטבע פעילות | Q1: ערך נקוב (יחידות) | R1: שער חליפין | S1: שער נייר הערך | T1: סכום לקבל (במטבע הפעילות) | U1: שווי הוגן (באלפי ש"ח) | V1: שיעור מערך נקוב מונפק | W1: שיעור מנכסי אפיק ההשקעה | X1: שיעור מסך נכסי ההשקעה
A2: 274 | B2: 274 | C2: שפיר הנדסה ותעשיה בע"מ | D2: 514892801 | E2: ח.פ. | F2: שפיר הנדסה ותעשיה בע"מ | G2: IL0011338758 | H2: ISIN | I2: מניות | J2: ישראל | K2: ישראל | L2: סחיר | M2: TASE | N2: מתכת ומוצרי בניה | O2: לא | P2: ILS | Q2: 25075 | R2: 1 | S2: 3000 | U2: 752.25 | V2: 7e-05 | W2: 0.008727 | X2: 0.000182
A3: 274 | B3: 274 | C3: הפניקס אחזקות | D3: 520017450 | E3: ח.פ. | F3: הפניקס 1 | G3: IL0007670123 | H3: ISIN | I3: מניות | J3: ישראל | K3: ישראל | L3: סחיר | M3: TASE | N3: ביטוח | O3: לא | P3: ILS | Q3: 26458 | R3: 1 | S3: 9745 | U3: 2578.3321 | V3: 0.0001 | W3: 0.029912 | X3: 0.000626
A4: 274 | B4: 274 | C4: אר פי אופטיקל לאב בע"מ | D4: 514454701 | E4: ח.פ. | F4: אר פי אופטיקל | G4: IL0012224627 | H4: ISIN | I4: מניות | J4: ישראל | K4: ישראל | L4: סחיר | M4: TASE | N4: ביטחוניות | O4: לא | P4: ILS | Q4: 16000 | R4: 1 | S4: 1336 | U4: 213.76 | V4: 0.000215 | W4: 0.002479 | X4: 5.1e-05
A5: 274 | B5: 274 | C5: מליסרון | D5: 520037789 | E5: ח.פ. | F5: מליסרון | G5: IL0003230146 | H5: ISIN | I5: מניות | J5: ישראל | K5: ישראל | L5: סחיר | M5: TASE | N5: נדל"ן מניב בישראל | O5: לא | P5: ILS | Q5: 2485 | R5: 1 | S5: 38400 | U5: 954.24 | V5: 5.2e-05 | W5: 0.01107 | X5: 0.000231
A6: 274 | B6: 274 | C6: אנרג'יאן נפט וגז פי אל סי | D6: 560033185 | E6: ח.פ. | F6: אנרג'יאן | G6: GB00BG12Y042 | H6: ISIN | I6: מניות | J6: ישראל | K6: ישראל | L6: סחיר | M6: TASE | N6: חיפושי נפט וגז | O6: לא | P6: ILS | Q6: 9090 | R6: 1 | S6: 4272 | T6: 9.98955 | U6: 398.31435 | V6: 4.9e-05 | W6: 0.00462 | X6: 9.6e-05
A7: 274 | B7: 274 | C7: פתאל החזקות | D7: 512607888 | E7: ח.פ. | F7: פתאל החזקות | G7: IL0011434292 | H7: ISIN | I7: מניות | J7: ישראל | K7: ישראל | L7: סחיר | M7: TASE | N7: מלונאות ותיירות | O7: לא | P7: ILS | Q7: 1432 | R7: 1 | S7: 58480 | U7: 837.4336 | V7: 8.6e-05 | W7: 0.009715 | X7: 0.000203
A8: 274 | B8: 274 | C8: כלל חברה לביטוח | D8: 520036120 | E8: ח.פ. | F8: כלל עסקי ביטוח | G8: IL0002240146 | H8: ISIN | I8: מניות | J8: ישראל | K8: ישראל | L8: סחיר | M8: TASE | N8: ביטוח | O8: לא | P8: ILS | Q8: 9728 | R8: 1 | S8: 14880 | U8: 1447.5264 | V8: 0.000122 | W8: 0.016793 | X8: 0.000351
A9: 274 | B9: 274 | C9: נובה מכשירי מדידה | D9: 511812463 | E9: ח.פ. | F9: נובה | G9: IL0010845571 | H9: ISIN | I9: מניות | J9: ישראל | K9: ישראל | L9: סחיר | M9: TASE | N9: מוליכים למחצה | O9: לא | P9: ILS | Q9: 2728 | R9: 1 | S9: 95280 | U9: 2599.2384 | V9: 9.3e-05 | W9: 0.030155 | X9: 0.000631
A10: 274 | B10: 274 | C10: הראל השקעות | D10: 520033986 | E10: ח.פ. | F10: הראל השקעות | G10: IL0005850180 | H10: ISIN | I10: מניות | J10: ישראל | K10: ישראל | L10: סחיר | M10: TASE | N10: ביטוח | O10: לא | P10: ILS | Q10: 19904 | R10: 1 | S10: 9432 | U10: 1877.3453 | V10: 8.8e-05 | W10: 0.02178 | X10: 0.000456
A11: 274 | B11: 274 | C11: החברה לישראל | D11: 520028010 | E11: ח.פ. | F11: חברה לישראל | G11: IL0005760173 | H11: ISIN | I11: מניות | J11: ישראל | K11: ישראל | L11: סחיר | M11: TASE | N11: השקעה ואחזקות | O11: לא | P11: ILS | Q11: 693 | R11: 1 | S11: 112370 | U11: 778.7241 | V11: 8.9e-05 | W11: 0.009034 | X11: 0.000189
A12: 274 | B12: 274 | C12: אנלייט אנרגיה | D12: 520041146 | E12: ח.פ. | F12: אנלייט אנרגיה | G12: IL0007200111 | H12: ISIN | I12: מניות | J12: ישראל | K12: ישראל | L12: סחיר | M12: TASE | N12: אנרגיה מתחדשת | O12: לא | P12: ILS | Q12: 8738.4 | R12: 1 | S12: 7640 | U12: 667.61376 | V12: 7.3e-05 | W12: 0.007745 | X12: 0.000162
A13: 274 | B13: 274 | C13: טאואר | D13: 520041997 | E13: ח.פ. | F13: טאואר | G13: IL0010823792 | H13: ISIN | I13: מניות | J13: ישראל | K13: ישראל | L13: סחיר | M13: TASE | N13: מוליכים למחצה | O13: לא | P13: ILS | Q13: 9225.76 | R13: 1 | S13: 14620 | U13: 1348.8061 | V13: 8.2e-05 | W13: 0.015648 | X13: 0.000327
A14: 274 | B14: 274 | C14: ביג מרכזי קניות | D14: 513623314 | E14: ח.פ. | F14: ביג | G14: IL0010972607 | H14: ISIN | I14: מניות | J14: ישראל | K14: ישראל | L14: סחיר | M14: TASE | N14: נדל"ן מניב בישראל | O14: לא | P14: ILS | Q14: 1865 | R14: 1 | S14: 64490 | U14: 1202.7385 | V14: 7.4e-05 | W14: 0.013953 | X14: 0.000292
A15: 274 | B15: 274 | C15: טבע | D15: 520013954 | E15: ח.פ. | F15: טבע | G15: IL0006290147 | H15: ISIN | I15: מניות | J15: ישראל | K15: ישראל | L15: סחיר | M15: TASE | N15: פארמה | O15: לא | P15: ILS | Q15: 66101 | R15: 1 | S15: 5699 | U15: 3767.096 | V15: 5.2e-05 | W15: 0.043704 | X15: 0.000915
A16: 274 | B16: 274 | C16: בנק הפועלים | D16: 520000118 | E16: ח.פ. | F16: פועלים | G16: IL0006625771 | H16: ISIN | I16: מניות | J16: ישראל | K16: ישראל | L16: סחיר | M16: TASE | N16: בנקים | O16: לא | P16: ILS | Q16: 92545.18 | R16: 1 | S16: 6462 | U16: 5980.2695 | V16: 6.9e-05 | W16: 0.06938 | X16: 0.001452
A17: 274 | B17: 274 | C17: שיכון ובינוי | D17: 520036104 | E17: ח.פ. | F17: שיכון ובינוי | G17: IL0010819428 | H17: ISIN | I17: מניות | J17: ישראל | K17: ישראל | L17: סחיר | M17: TASE | N17: בנייה | O17: לא | P17: ILS | Q17: 19914.6 | R17: 1 | S17: 1690 | U17: 336.55674 | V17: 3.5e-05 | W17: 0.003904 | X17: 8.1e-05
A18: 274 | B18: 274 | C18: נאוויטס פטרוליום, שותפות מוגבלת | D18: 550263107 | E18: מספר שותפות | F18: נאוויטס פטר יהש | G18: IL0011419699 | H18: ISIN | I18: מניות | J18: ישראל | K18: ישראל | L18: סחיר | M18: TASE | N18: חיפושי נפט וגז | O18: לא | P18: ILS | Q18: 13908 | R18: 1 | S18: 9900 | U18: 1376.892 | V18: 0.000133 | W18: 0.015974 | X18: 0.000334
... A36: 274 | B36: 274 | C36: פרטנר | D36: 520044314 | E36: ח.פ. | F36: פרטנר | G36: IL0010834849 | H36: ISIN | I36: מניות | J36: ישראל | K36: ישראל | L36: סחיר | M36: TASE | N36: מסחר | O36: לא | P36: ILS | Q36: 20423 | R36: 1 | S36: 2555 | U36: 521.80765 | V36: 0.000106 | W36: 0.006053 | X36: 0.000126
A37: 274 | B37: 274 | C37: אלביט מערכות | D37: 520043027 | E37: ח.פ. | F37: אלביט מערכות | G37: IL0010811243 | H37: ISIN | I37: מניות | J37: ישראל | K37: ישראל | L37: סחיר | M37: TASE | N37: ביטחוניות | O37: לא | P37: ILS | Q37: 3354 | R37: 1 | S37: 149800 | T37: 6.85222 | U37: 5031.1442 | V37: 7.2e-05 | W37: 0.058368 | X37: 0.001221
A38: 274 | B38: 274 | C38: קבוצת דלק בע"מ | D38: 520044322 | E38: ח.פ. | F38: דלק קבוצה | G38: IL0010841281 | H38: ISIN | I38: מניות | J38: ישראל | K38: ישראל | L38: סחיר | M38: TASE | N38: חיפושי נפט וגז | O38: לא | P38: ILS | Q38: 809 | R38: 1 | S38: 69740 | U38: 564.1966 | V38: 4.3e-05 | W38: 0.006545 | X38: 0.000137
A39: 274 | B39: 274 | C39: שופרסל | D39: 520022732 | E39: ח.פ. | F39: שופרסל | G39: IL0007770378 | H39: ISIN | I39: מניות | J39: ישראל | K39: ישראל | L39: סחיר | M39: TASE | N39: רשתות שיווק | O39: לא | P39: ILS | Q39: 31033 | R39: 1 | S39: 3869 | U39: 1200.6668 | V39: 0.000112 | W39: 0.013929 | X39: 0.000291
A40: 274 | B40: 274 | C40: כיל | D40: 520027830 | E40: ח.פ. | F40: אי.סי. אל - כיל | G40: IL0002810146 | H40: ISIN | I40: מניות | J40: ישראל | K40: ישראל | L40: סחיר | M40: TASE | N40: כימיה, גומי ופלסטיק | O40: לא | P40: ILS | Q40: 132612 | R40: 1 | S40: 2309 | U40: 3062.0111 | V40: 0.0001 | W40: 0.035524 | X40: 0.000743
A41: 274 | B41: 274 | C41: קבוצת עזריאלי בע"מ | D41: 510960719 | E41: ח.פ. | F41: עזריאלי קבוצה | G41: IL0011194789 | H41: ISIN | I41: מניות | J41: ישראל | K41: ישראל | L41: סחיר | M41: TASE | N41: נדל"ן מניב בישראל | O41: לא | P41: ILS | Q41: 5978 | R41: 1 | S41: 30970 | U41: 1851.3866 | V41: 4.9e-05 | W41: 0.021478 | X41: 0.000449
A42: 274 | B42: 274 | C42: ריט 1 | D42: 513821488 | E42: ח.פ. | F42: ריט 1 | G42: IL0010989205 | H42: ISIN | I42: מניות | J42: ישראל | K42: ישראל | L42: סחיר | M42: TASE | N42: נדל"ן מניב בישראל | O42: לא | P42: ILS | Q42: 20598 | R42: 1 | S42: 2261 | U42: 465.72078 | V42: 0.000105 | W42: 0.005403 | X42: 0.000113
A43: 274 | B43: 274 | C43: לאומי | D43: 520018078 | E43: ח.פ. | F43: לאומי | G43: IL0006046119 | H43: ISIN | I43: מניות | J43: ישראל | K43: ישראל | L43: סחיר | M43: TASE | N43: בנקים | O43: לא | P43: ILS | Q43: 90757.21 | R43: 1 | S43: 6262 | U43: 5683.2165 | V43: 5.6e-05 | W43: 0.065934 | X43: 0.00138
A44: 274 | B44: 274 | C44: נייס | D44: 520036872 | E44: ח.פ. | F44: נייס | G44: IL0002730112 | H44: ISIN | I44: מניות | J44: ישראל | K44: ישראל | L44: סחיר | M44: TASE | N44: תוכנה ואינטרנט | O44: לא | P44: ILS | Q44: 8124 | R44: 1 | S44: 57150 | U44: 4642.866 | V44: 0.000108 | W44: 0.053864 | X44: 0.001128
A45: 274 | B45: 274 | C45: בנק דיסקונט | D45: 520007030 | E45: ח.פ. | F45: דיסקונט א | G45: IL0006912120 | H45: ISIN | I45: מניות | J45: ישראל | K45: ישראל | L45: סחיר | M45: TASE | N45: בנקים | O45: לא | P45: ILS | Q45: 200641.49 | R45: 1 | S45: 3356 | U45: 6733.5284 | V45: 0.000162 | W45: 0.078119 | X45: 0.001635
A46: 274 | B46: 274 | C46: נובה מכשירי מדידה | D46: 511812463 | E46: ח.פ. | F46: NVMI US (POALIM) | G46: IL0010845571 | H46: ISIN | I46: מניות | J46: חו"ל | K46: ישראל | L46: סחיר | M46: NASDAQ | N46: Semiconductors & Semiconductor Equipment | O46: לא | P46: USD | Q46: 1961 | R46: 3.372 | S46: 27520 | U46: 1819.7578 | V46: 6.6e-05 | W46: 0.021112 | X46: 0.000442
A47: 274 | B47: 274 | C47: נייס | D47: 520036872 | E47: ח.פ. | F47: NICE US ( poalim) | G47: US6536561086 | H47: ISIN | I47: מניות | J47: חו"ל | K47: ישראל | L47: סחיר | M47: NASDAQ | N47: Software | O47: לא | P47: USD | Q47: 928 | R47: 3.372 | S47: 16891 | U47: 528.55587 | V47: 1.4e-05 | W47: 0.006132 | X47: 0.000128
A48: 274 | B48: 274 | C48: טבע | D48: 520013954 | E48: ח.פ. | F48: Teva US(poalim) | G48: US8816242098 | H48: ISIN | I48: מניות | J48: חו"ל | K48: ישראל | L48: סחיר | M48: NYSE | N48: Pharmaceuticals | O48: לא | P48: USD | Q48: 24264 | R48: 3.372 | S48: 1676 | U48: 1371.2732 | V48: 2.1e-05 | W48: 0.015908 | X48: 0.000333
A49: 274 | B49: 274 | C49: Taiwan Semiconductor | D49: 549300KB6NK5SBD14S87 | E49: LEI | F49: TSM - Taiwan Semiconductor (P) | G49: US8740391003 | H49: ISIN | I49: מניות | J49: חו"ל | K49: גלובלי | L49: סחיר | M49: NYSE | N49: Semiconductors & Semiconductor Equipment | O49: לא | P49: USD | Q49: 552 | R49: 3.372 | S49: 22649 | T49: 0.41508 | U49: 422.97545 | V49: 0 | W49: 0.004906 | X49: 0.000102
A50: 274 | B50: 274 | C50: InMode | D50: 549300TTHIODYMGND828 | E50: LEI | F50: INMD - InMode (POALIM) | G50: IL0011595993 | H50: ISIN | I50: מניות | J50: חו"ל | K50: ארה"ב | L50: סחיר | M50: NASDAQ | N50: Health Care Providers & Services | O50: לא | P50: USD | Q50: 6133 | R50: 3.372 | S50: 1444 | U50: 298.62607 | V50: 9.7e-05 | W50: 0.003464 | X50: 7.2e-05
A51: 274 | B51: 274 | C51: GOLDMAN | D51: 784F5XWPLTWKTBV3E584 | E51: LEI | F51: GS - Goldman Sachs (P) | G51: US38141G1040 | H51: ISIN | I51: מניות | J51: חו"ל | K51: ארה"ב | L51: סחיר | M51: NYSE | N51: Banks | O51: לא | P51: USD | Q51: 182 | R51: 3.372 | S51: 70775 | U51: 434.34901 | V51: 0 | W51: 0.005039 | X51: 0.000105
A52: 274 | B52: 274 | C52: Lam Research Corp | D52: 549300I4GMO6D34U1T02 | E52: LEI | F52: LRCX - Lam Research (P) | G52: US5128071082 | H52: ISIN | I52: מניות | J52: חו"ל | K52: ארה"ב | L52: סחיר | M52: NASDAQ | N52: Semiconductors & Semiconductor Equipment | O52: לא | P52: USD | Q52: 624 | R52: 3.372 | S52: 9734 | T52: 0.14351 | U52: 205.29974 | V52: 0 | W52: 0.002381 | X52: 4.9e-05
A53: 274 | B53: 274 | C53: GOOGLE INC | D53: 5493006MHB84DD0ZWV18 | E53: LEI | F53: GOOG- Alphabet (p) | G53: US02079K1079 | H53: ISIN | I53: מניות | J53: חו"ל | K53: ארה"ב | L53: סחיר | M53: NASDAQ | N53: Diversified Telecommunication Services | O53: לא | P53: USD | Q53: 777 | R53: 3.372 | S53: 17739 | U53: 464.76961 | V53: 0 | W53: 0.005392 | X53: 0.000112
A54: 274 | B54: 274 | C54: ASML | D54: 724500Y6DUVHQD6OXN27 | E54: LEI | F54: ASML NA - ASML Holding (P) | G54: NL0010273215 | H54: ISIN | I54: מניות | J54: חו"ל | K54: אירופה | L54: סחיר | M54: אחר | N54: Technology Hardware, Storage & Peripherals | O54: לא | P54: EUR | Q54: 75 | R54: 3.9552 | S54: 67760 | U54: 201.00326 | V54: 0 | W54: 0.002331 | X54: 4.8e-05
A55: 274 | B55: 274 | C55: קמטק | D55: 511235434 | E55: ח.פ. | F55: camt-קמטק חול(poalim) | G55: IL0010952641 | H55: ISIN | I55: מניות | J55: חו"ל | K55: ישראל | L55: סחיר | M55: NYSE | N55: Semiconductors & Semiconductor Equipment | O55: לא | P55: USD | Q55: 462 | R55: 3.372 | S55: 8456 | U55: 131.73298 | V55: 1e-05 | W55: 0.001528 | X55: 3.2e-05
A56: 274 | B56: 274 | C56: אנלייט אנרגיה | D56: 520041146 | E56: ח.פ. | F56: ENLIGHT RENEWABLE ENERGY LTD(poalim) | G56: IL0007200111 | H56: ISIN | I56: מניות | J56: חו"ל | K56: ישראל | L56: סחיר | M56: NASDAQ | N56: Energy Equipment & Services | O56: לא | P56: USD | Q56: 3164 | R56: 3.372 | S56: 2273 | U56: 242.50655 | V56: 2.6e-05 | W56: 0.002813 | X56: 5.8e-05
A57: 274 | B57: 274 | C57: NVIDIA Corporation | D57: 549300S4KLFTLO7GSQ80 | E57: LEI | F57: NVDA - NVIDIA (P) | G57: US67066G1040 | H57: ISIN | I57: מניות | J57: חו"ל | K57: ארה"ב | L57: סחיר | M57: NASDAQ | N57: Semiconductors & Semiconductor Equipment | O57: לא | P57: USD | Q57: 1105 | R57: 3.372 | S57: 15799 | T57: 0.01105 | U57: 588.71748 | V57: 0 | W57: 0.006829 | X57: 0.000143
...

Sheet קרנות סל
A1: מספר קופה/קרן/ח.פ. עבור חברת ביטוח | B1: מספר מסלול | C1: שם מנפיק | D1: מספר מנפיק | E1: סוג מספר מזהה מנפיק | F1: שם נייר ערך | G1: מספר נייר ערך | H1: סוג מספר נייר ערך | I1: מאפיין עיקרי | J1: ישראל/חו"ל | K1: מדינה לפי חשיפה כלכלית | L1: זירת מסחר | M1: סיווג הקרן | N1: בעל עניין/צד קשור | O1: מטבע פעילות | P1: ערך נקוב (יחידות) | Q1: שער חליפין | R1: שער נייר הערך | S1: סכום לקבל (במטבע הפעילות) | T1: שווי הוגן (באלפי ש"ח) | U1: שיעור מערך נקוב מונפק | V1: שיעור מנכסי אפיק ההשקעה | W1: שיעור מסך נכסי ההשקעה
A2: 274 | B2: 274 | C2: מגדל קרנות נאמנות בע"מ | D2: 511303661 | E2: ח.פ. | F2: MTF סל (00) תל בונד 20 | G2: IL0011499881 | H2: ISIN | I2: עוקב אחר מדדים אחרים בישראל | J2: ישראל | K2: ישראל | L2: TASE | M2: 20 אג"ח בארץ - חברות והמרה-תל בונד צמוד מדד-תל בונד | N2: לא | O2: ILS | P2: 33000 | Q2: 1 | R2: 486.63 | T2: 160.5879 | U2: 0.000138 | V2: 0.000511 | W2: 3.9e-05
A3: 274 | B3: 274 | C3: קסם קרנות נאמנות בע"מ | D3: 510938608 | E3: ח.פ. | F3: קסם ETF תלבונד 20 | G3: IL0011459604 | H3: ISIN | I3: עוקב אחר מדדים אחרים בישראל | J3: ישראל | K3: ישראל | L3: TASE | M3: 20 אג"ח בארץ - חברות והמרה-תל בונד צמוד מדד-תל בונד | N3: לא | O3: ILS | P3: 5930.5 | Q3: 1 | R3: 3896.38 | T3: 231.07482 | U3: 0.000113 | V3: 0.000736 | W3: 5.6e-05
A4: 274 | B4: 274 | C4: מיטב תכלית קרנות נאמנות בע"מ | D4: 513534974 | E4: ח.פ. | F4: תכלית סל (00) תל בונד 40 | G4: IL0011450934 | H4: ISIN | I4: עוקב אחר מדדים אחרים בישראל | J4: ישראל | K4: ישראל | L4: TASE | M4: 40 אג"ח בארץ - חברות והמרה-תל בונד צמוד מדד-תל בונד | N4: לא | O4: ILS | P4: 351755 | Q4: 1 | R4: 373.55 | T4: 1313.9808 | U4: 0.000612 | V4: 0.004188 | W4: 0.000319
A5: 274 | B5: 274 | C5: הראל קרנות נאמנות בע"מ | D5: 511776783 | E5: ח.פ. | F5: הראל סל תא 35 | G5: IL0011489072 | H5: ISIN | I5: עוקב אחר מדדי מניות בישראל | J5: ישראל | K5: ישראל | L5: TASE | M5: 35 מניות בארץ - מניות כללי-ת"א | N5: לא | O5: ILS | P5: 152802 | Q5: 1 | R5: 2915 | T5: 4454.1783 | U5: 0.001793 | V5: 0.014197 | W5: 0.001082
A6: 274 | B6: 274 | C6: מגדל קרנות נאמנות בע"מ | D6: 511303661 | E6: ח.פ. | F6: MTF סל תל בונד 60 | G6: IL0011499964 | H6: ISIN | I6: עוקב אחר מדדים אחרים בישראל | J6: ישראל | K6: ישראל | L6: TASE | M6: 60 אג"ח בארץ - חברות והמרה-תל בונד צמוד מדד-תל בונד | N6: לא | O6: ILS | P6: 1818503 | Q6: 1 | R6: 488.99 | T6: 8892.2978 | U6: 0.008659 | V6: 0.028343 | W6: 0.00216
A7: 274 | B7: 274 | C7: מיטב תכלית קרנות נאמנות בע"מ | D7: 513534974 | E7: ח.פ. | F7: תכלית סל תא 35 | G7: IL0011437006 | H7: ISIN | I7: עוקב אחר מדדי מניות בישראל | J7: ישראל | K7: ישראל | L7: TASE | M7: 35 מניות בארץ - מניות כללי-ת"א | N7: לא | O7: ILS | P7: 46030 | Q7: 1 | R7: 2913 | T7: 1340.8539 | U7: 0.000179 | V7: 0.004273 | W7: 0.000325
A8: 274 | B8: 274 | C8: מגדל קרנות נאמנות בע"מ | D8: 511303661 | E8: ח.פ. | F8: MTF סל (4A) ת"א 35 | G8: IL0011501843 | H8: ISIN | I8: עוקב אחר מדדי מניות בישראל | J8: ישראל | K8: ישראל | L8: TASE | M8: 35 מניות בארץ - מניות כללי-ת"א | N8: לא | O8: ILS | P8: 189694 | Q8: 1 | R8: 3968 | T8: 7527.0579 | U8: 0.002709 | V8: 0.023991 | W8: 0.001828
A9: 274 | B9: 274 | C9: קסם קרנות נאמנות בע"מ | D9: 510938608 | E9: ח.פ. | F9: קסם ETF תא 35 | G9: IL0011465700 | H9: ISIN | I9: עוקב אחר מדדי מניות בישראל | J9: ישראל | K9: ישראל | L9: TASE | M9: 35 מניות בארץ - מניות כללי-ת"א | N9: לא | O9: ILS | P9: 9711.81 | Q9: 1 | R9: 28980 | T9: 2814.4825 | U9: 0.000502 | V9: 0.00897 | W9: 0.000683
A10: 274 | B10: 274 | C10: הראל קרנות נאמנות בע"מ | D10: 511776783 | E10: ח.פ. | F10: הראל סל תלבונד 20 | G10: IL0011504409 | H10: ISIN | I10: עוקב אחר מדדים אחרים בישראל | J10: ישראל | K10: ישראל | L10: TASE | M10: 20 אג"ח בארץ - חברות והמרה-תל בונד צמוד מדד-תל בונד | N10: לא | O10: ILS | P10: 68800 | Q10: 1 | R10: 393.25 | T10: 270.556 | U10: 0.000282 | V10: 0.000862 | W10: 6.5e-05
A11: 274 | B11: 274 | C11: State Street | D11: 549300ZFEEJ2IP5VME73 | E11: LEI | F11: XLU US (p) | G11: US81369Y8865 | H11: ISIN | I11: עוקב אחר מדדי מניות בחו"ל | J11: חו"ל | K11: ארה"ב | L11: NYSE | M11: Equity Funds | N11: לא | O11: USD | P11: 698 | Q11: 3.372 | R11: 8166 | T11: 192.19955 | U11: 2e-06 | V11: 0.000612 | W11: 4.6e-05
A12: 274 | B12: 274 | C12: VanEck | D12: 549300MJTG2N9QRH7I02 | E12: LEI | F12: SMH- VanEck Semiconductor -POALIM | G12: US92189F6768 | H12: ISIN | I12: עוקב אחר מדדי מניות בחו"ל | J12: חו"ל | K12: ארה"ב | L12: NASDAQ | M12: Equity Funds | N12: לא | O12: USD | P12: 695 | Q12: 3.372 | R12: 27888 | T12: 653.56644 | U12: 7e-06 | V12: 0.002083 | W12: 0.000158
A13: 274 | B13: 274 | C13: AMUNDI INVT SOLUTIONS | D13: 549300FMBJ5S1PXQ2305 | E13: LEI | F13: U127 LN - MSCI Emerging Markets (P) | G13: LU2573966905 | H13: ISIN | I13: עוקב אחר מדדי מניות בחו"ל | J13: חו"ל | K13: גלובלי | L13: LSE | M13: Equity Funds | N13: לא | O13: USD | P13: 136677 | Q13: 3.372 | R13: 5416 | T13: 24960.982 | U13: 0.002289 | V13: 0.079559 | W13: 0.006064
A14: 274 | B14: 274 | C14: State Street | D14: 549300ZFEEJ2IP5VME73 | E14: LEI | F14: XLC US - Communication Services (P) | G14: US81369Y8527 | H14: ISIN | I14: עוקב אחר מדדי מניות בחו"ל | J14: חו"ל | K14: ארה"ב | L14: NYSE | M14: Equity Funds | N14: לא | O14: USD | P14: 3998 | Q14: 3.372 | R14: 10853 | T14: 1463.1207 | U14: 1.7e-05 | V14: 0.004663 | W14: 0.000355
A15: 274 | B15: 274 | C15: INVESCO | D15: ECPGFXU8A2SHKVVGJI15 | E15: LEI | F15: MUNI LN | G15: IE00BNG70R26 | H15: ISIN | I15: אחר | J15: חו"ל | K15: ארה"ב | L15: LSE | M15: אג"ח בחו"ל - אג"ח חשופת מט"ח | N15: לא | O15: USD | P15: 6600 | Q15: 3.372 | R15: 3180 | T15: 707.71536 | U15: 0.008816 | V15: 0.002255 | W15: 0.000171
A16: 274 | B16: 274 | C16: INVESCO | D16: ECPGFXU8A2SHKVVGJI15 | E16: LEI | F16: PPA - Invesco Aerospace & Defense (p) | G16: US46137V1008 | H16: ISIN | I16: עוקב אחר מדדי מניות בחו"ל | J16: חו"ל | K16: ארה"ב | L16: NYSE | M16: Equity Funds | N16: לא | O16: USD | P16: 819 | Q16: 3.372 | R16: 14169 | T16: 391.30074 | U16: 2e-05 | V16: 0.001247 | W16: 9.5e-05
A17: 274 | B17: 274 | C17: AMUNDI INVT SOLUTIONS | D17: 549300FMBJ5S1PXQ2305 | E17: LEI | F17: CEU FP - MSCI EUROPE ESG (P) | G17: LU1681042609 | H17: ISIN | I17: עוקב אחר מדדי מניות בחו"ל | J17: חו"ל | K17: Developed Markets - Europe | L17: NYSE | M17: Equity Funds | N17: לא | O17: EUR | P17: 3346 | Q17: 3.9552 | R17: 36108.52 | T17: 4778.6373 | U17: 0.000597 | V17: 0.015231 | W17: 0.001161
A18: 274 | B18: 274 | C18: Tabula | D18: 635400BK5J6GBMBFNG77 | E18: LEI | F18: TAHY LN - Asia USD HY | G18: IE000LZC9M0 | H18: ISIN | I18: אחר | J18: חו"ל | K18: אסיה | L18: LSE | M18: אג"ח בחו"ל - אג"ח חשופת מט"ח | N18: לא | O18: USD | P18: 10550 | Q18: 3.372 | R18: 775.1 | T18: 275.73872 | U18: 0.000546 | V18: 0.000878 | W18: 6.6e-05
A19: 274 | B19: 274 | C19: DWS | D19: 7LTWFZYICNSX8D621K86 | E19: LEI | F19: XDWD LN - MSCI World (P) | G19: IE00BJ0KDQ92 | H19: ISIN | I19: עוקב אחר מדדי מניות בחו"ל | J19: חו"ל | K19: אסיה | L19: LSE | M19: Equity Funds | N19: לא | O19: USD | P19: 51959 | Q19: 3.372 | R19: 12865.5 | T19: 22541.096 | U19: 0.000402 | V19: 0.071846 | W19: 0.005476
A20: 274 | B20: 274 | C20: INVESCO MARKETS PLC | D20: ECPGFXU8A2SHKVVGJI15 | E20: LEI | F20: MXWO LN - MSCI World (P) | G20: IE00B60SX394 | H20: ISIN | I20: עוקב אחר מדדי מניות בחו"ל | J20: חו"ל | K20: אסיה | L20: LSE | M20: Equity Funds | N20: לא | O20: USD | P20: 20140 | Q20: 3.372 | R20: 12626 | T20: 8574.5792 | U20: 0.000368 | V20: 0.02733 | W20: 0.002083
A21: 274 | B21: 274 | C21: DWS | D21: 7LTWFZYICNSX8D621K86 | E21: LEI | F21: XDJP GR - Nikkei 225 (P) | G21: LU0839027447 | H21: ISIN | I21: עוקב אחר מדדי מניות בחו"ל | J21: חו"ל | K21: יפן | L21: FWB | M21: Equity Funds | N21: לא | O21: EUR | P21: 18776 | Q21: 3.9552 | R21: 2459 | T21: 1826.1231 | U21: 0.000355 | V21: 0.00582 | W21: 0.000443
A22: 274 | B22: 274 | C22: AMUNDI INVT SOLUTIONS | D22: 549300FMBJ5S1PXQ2305 | E22: LEI | F22: SP5C LN - S&P 500 (P) | G22: LU1135865084 | H22: ISIN | I22: עוקב אחר מדדי מניות בחו"ל | J22: חו"ל | K22: ארה"ב | L22: LSE | M22: Equity Funds | N22: לא | O22: USD | P22: 14942 | Q22: 3.372 | R22: 44471 | T22: 22406.457 | U22: 0.000574 | V22: 0.071417 | W22: 0.005443
... A45: 274 | B45: 274 | C45: ISHARES | D45: 549300LRIF3NWCU26A80 | E45: LEI | F45: MUSD NA - MSCI USA (P) | G45: IE0002W8NB38 | H45: ISIN | I45: עוקב אחר מדדי מניות בחו"ל | J45: חו"ל | K45: ארה"ב | L45: אחר | M45: Equity Funds | N45: לא | O45: USD | P45: 675112 | Q45: 3.372 | R45: 842.93 | T45: 19189.113 | U45: 0.003747 | V45: 0.061162 | W45: 0.004662

Sheet קרנות נאמנות
A1: מספר קופה/קרן/ח.פ. עבור חברת ביטוח | B1: מספר מסלול | C1: שם מנפיק | D1: מספר מנפיק | E1: סוג מספר מזהה מנפיק | F1: שם נייר ערך | G1: מספר נייר ערך | H1: סוג מספר נייר ערך | I1: מאפיין עיקרי | J1: ישראל/חו"ל | K1: מדינה לפי חשיפה כלכלית | L1: סטאטוס סחירות | M1: זירת מסחר | N1: סיווג הקרן | O1: בעל עניין/צד קשור | P1: מטבע פעילות | Q1: ערך נקוב (יחידות) | R1: שער חליפין | S1: שער נייר הערך | T1: שווי הוגן (באלפי ש"ח) | U1: שיעור מערך נקוב מונפק | V1: שיעור מנכסי אפיק ההשקעה | W1: שיעור מסך נכסי ההשקעה
A2: 274 | B2: 274 | C2: Nomura Asset Management UK | D2: 549300B3CEAHYG7K8164 | E2: LEI | F2: Nomura US HY | G2: IE00B3RW8498 | H2: ISIN | I2: אג"ח קונצרני | J2: חו"ל | K2: ארה"ב | L2: סחיר | M2: אחר | N2: אג"ח בחו"ל - אג"ח חשופת מט"ח | O2: לא | P2: USD | Q2: 1180 | R2: 3.372 | S2: 41914.19 | T2: 1667.7488 | U2: 4.5e-05 | V2: 0.055644 | W2: 0.000405
A3: 274 | B3: 274 | C3: Liontrust | D3: 549300XVXU6S7PLCL855 | E3: LEI | F3: Liontrust European Dynamic | G3: GB00BKPQVT86 | H3: ISIN | I3: מניות | J3: חו"ל | K3: אירופה | L3: סחיר | M3: אחר | N3: Equity Funds | O3: לא | P3: GBP | Q3: 391485 | R3: 4.6236 | S3: 145.78 | T3: 2638.6905 | U3: 0.000756 | V3: 0.08804 | W3: 0.000641
A4: 274 | B4: 274 | C4: Pinebridge | D4: 549300KM5F6LSTMERC50 | E4: LEI | F4: PineBridge US IG | G4: IE00BD82R632 | H4: ISIN | I4: אג"ח קונצרני | J4: חו"ל | K4: ארה"ב | L4: סחיר | M4: ISE | N4: אג"ח בחו"ל - אג"ח חשופת מט"ח | O4: לא | P4: USD | Q4: 1346.3 | R4: 3.372 | S4: 12289 | T4: 557.88663 | U4: 1e-06 | V4: 0.018613 | W4: 0.000135
A5: 274 | B5: 274 | C5: Daiwa | D5: 2138008IOOVSKCGISQ06 | E5: LEI | F5: DAIWA SBI JAPAN SC | G5: LU1907539057 | H5: ISIN | I5: מניות | J5: חו"ל | K5: יפן | L5: סחיר | M5: אחר | N5: Equity Funds | O5: לא | P5: JPY | Q5: 2993 | R5: 0.023369 | S5: 2244699 | T5: 1570.0192 | U5: 0.010712 | V5: 0.052383 | W5: 0.000381
A6: 274 | B6: 274 | C6: Lazard Inc | D6: 254900RIBCDJSUFG1A11 | E6: LEI | F6: Lazard Japanese Strategic Equity | G6: IE000UTYHEP1 | H6: ISIN | I6: מניות | J6: חו"ל | K6: יפן | L6: סחיר | M6: אחר | N6: Equity Funds | O6: לא | P6: JPY | Q6: 3326 | R6: 0.023369 | S6: 1453342.8 | T6: 1129.6149 | U6: 0.003314 | V6: 0.037689 | W6: 0.000274
A7: 274 | B7: 274 | C7: Ninety One | D7: 549300G0TJCT3K15ZG14 | E7: LEI | F7: N91 EM IG | G7: LU1275256334 | H7: ISIN | I7: אג"ח קונצרני | J7: חו"ל | K7: גלובלי | L7: סחיר | M7: אחר | N7: אג"ח בחו"ל - אג"ח חשופת מט"ח | O7: לא | P7: USD | Q7: 4808.92 | R7: 3.372 | S7: 2925 | T7: 474.30859 | U7: 0.000928 | V7: 0.015825 | W7: 0.000115
