Workbook
Name Additional_Factor: 'אפשרויות בחירה'!$C$701:$C$850
Name Amoritization: 'אפשרויות בחירה'!$C$546:$C$550
Name Capsule: 'אפשרויות בחירה'!$C$926:$C$928
Name Company_Name: 'File Name Info'!$A$34:$A$130
Name Company_Name_ID: 'File Name Info'!$A$34:$B$130
Name Consortium: 'אפשרויות בחירה'!$C$514:$C$515
Name Country_list: 'אפשרויות בחירה'!$C$4:$C$85
Name Country_list_funds: 'אפשרויות בחירה'!$C$4:$C$103
Name CSA: 'אפשרויות בחירה'!$C$688:$C$689
Name Delivery: 'אפשרויות בחירה'!$C$666:$C$667
Name Dependence_Independence: 'אפשרויות בחירה'!$C$654:$C$655
Name Duration_Underlying_Interest_Rate: 'אפשרויות בחירה'!$C$680:$C$687
Name File_Type: 'File Name Info'!$A$10:$A$12
Name Full_File_Type: 'File Name Info'!$A$11:$B$13
Name Full_Type: 'File Name Info'!$A$2:$B$8
Name Full_Type_Nostro: 'File Name Info'!$A$3:$B$6
Name Full_Year: 'File Name Info'!$A$22:$B$31
Name Fund_Strategy: 'אפשרויות בחירה'!$C$597:$C$621
Name Fund_type: 'אפשרויות בחירה'!$C$328:$C$498
Name Holding_interest: 'אפשרויות בחירה'!$C$146:$C$147
Name In_the_books: 'אפשרויות בחירה'!$C$656:$C$657
Name Industry_Sector: 'אפשרויות בחירה'!$C$1129:$C$1245
Name Industry_sector_all: 'אפשרויות בחירה'!$C$202:$C$327
Name Industry_sectors: 'אפשרויות בחירה'!$C$202:$C$327
Name israel_abroad: 'אפשרויות בחירה'!$C$2:$C$3
Name Issuer_Number_Banks: 'אפשרויות בחירה'!$C$111:$C$113
Name Issuer_Number_Fund: 'אפשרויות בחירה'!$C$114:$C$117
Name issuer_number_loan: 'אפשרויות בחירה'!$C$118:$C$126
Name Issuer_Number_Type: 'אפשרויות בחירה'!$C$104:$C$110
Name Issuer_Number_Type_2: 'אפשרויות בחירה'!$C$1076:$C$1079
Name Issuer_Number_Type_3: 'אפשרויות בחירה'!$C$1081:$C$1085
Name Issuer_Number_Type_V2: 'אפשרויות בחירה'!$C$104:$C$110
Name Issuer_Type_TFunds: 'אפשרויות בחירה'!$C$1087:$C$1089
Name Leading_factor: 'אפשרויות בחירה'!$C$692:$C$700
Name Linked_Type: 'אפשרויות בחירה'!$C$516:$C$519
Name other_investments: 'אפשרויות בחירה'!$C$1000:$C$1033
Name Penalty: 'אפשרויות בחירה'!$C$851:$C$852
Name QTR: 'File Name Info'!$A$15:$A$19
Name Rating_Agency: 'אפשרויות בחירה'!$C$188:$C$201
Name real_estate_lifestage: 'אפשרויות בחירה'!$C$634:$C$642
Name real_estate_loans: 'אפשרויות בחירה'!$C$553:$C$591
Name Real_Estate_Main_Use: 'אפשרויות בחירה'!$C$622:$C$633
Name Recourse_Nonrecourse: 'אפשרויות בחירה'!$C$544:$C$545
Name Repayment_Rights: 'אפשרויות בחירה'!$C$551:$C$552
Name Reset_frequency: 'אפשרויות בחירה'!$C$658:$C$665
Name Security_ID_Number_Type: 'אפשרויות בחירה'!$C$1113:$C$1116
Name Security_Number_Loans: 'אפשרויות בחירה'!$C$131
Name Stock_Exchange: 'אפשרויות בחירה'!$C$1283:$C$1315
Name Stock_Exchange_Gov_Bonds: 'אפשרויות בחירה'!$C$148:$C$181
Name Subordination_Risk: 'אפשרויות בחירה'!$C$186:$C$187
Name Tradeable_Status: 'אפשרויות בחירה'!$C$1272:$C$1281
Name Tradeable_Status_All: 'אפשרויות בחירה'!$C$135:$C$145
Name tradeable_status_bonds: 'אפשרויות בחירה'!$C$1248:$C$1253
Name tradeable_status_funds: 'אפשרויות בחירה'!$C$1118:$C$1119
Name tradeable_status_stock: 'אפשרויות בחירה'!$C$1255:$C$1259
Name Tradeable_Status_v2: 'אפשרויות בחירה'!$C$1121:$C$1126
Name tradeable_status_warrants: 'אפשרויות בחירה'!$C$1261:$C$1265
Name tradeable_status_warrants_v2: 'אפשרויות בחירה'!$C$1267:$C$1269
Name Transaction: 'אפשרויות בחירה'!$C$643:$C$646
Name Type: 'File Name Info'!$A$2:$A$8

Sheet עמוד פתיחה
A1: קובץ דיווח עבור רשימת נכסים ברמת הנכס הבודד (חוזר גופים מוסדיים 2015-9-14)
A3: יש לבחור תחום: | D3: נכסי עמיתים - קופות גמל
A5: האם מדובר בקובץ לממומנה או לציבור: | D5: לציבור
A7: יש לבחור את רבעון הדיווח: | D7: 02
A9: יש לבחור את שנת הדיווח: | D9: 2025
A11: יש לבחור את הגוף המוסדי: | D11: תגמולים של עובדים בעירית ת"א-יפו א.ש. בע"מ
A13: ח.פ. הגוף המוסדי: | D13: =IFERROR(VLOOKUP(D11,'[1]File Name Info'!A35:B121,2,0),"תא מחושב") -> 570002618
A15: שם קובץ לשמירה | D15: =IF(D5="לממונה",CONCATENATE(D13, "_",VLOOKUP(D3,Full_Type,2,0),"_",D7,VLOOKUP(D9,Full_Year,2,0),".xlxs"),IF(D5="לציבור",CONCATENATE(D13,"_",VLOOKUP(D3,Full_Type_Nostro,2,0),"_",VLOOKUP(D5,Full_File_Type,2,0),"_",D7,VLOOKUP(D9,Full_Year,2,0),".xlsx"),"שם קובץ לשמירה")) -> 570002618_gm_p_0225.xlsx
A17: פרטי האחראי על הדיווח בגוף המוסדי | B17: שם: | D17: צביקה שמיר , מנכ"ל
B19: מספר טלפון: | D19: 03-5210603
B21: כתובת מייל: | D21: zvi-sha@ovdim-tlv.org.il

Sheet סכום נכסים
C1: ידווח בקבצי נכסי הנוסטרו בלבד
B2: שווי הוגן | C2: עלות מופחתת | D2: השיטה שיושמה בדוח הכספי | E2: שיעור מסך נכסי השקעה
A3: מזומנים ושווי מזומנים | B3: =SUM('מזומנים ושווי מזומנים'!O:O) -> 43747.862 | E3: =SUM('[1]מזומנים ושווי מזומנים'!O:O)/B30 -> 0.03544885
A4: איגרות חוב ממשלתיות | B4: =SUM('איגרות חוב ממשלתיות'!U:U) -> 263457.41 | E4: =SUM('[1]איגרות חוב ממשלתיות'!U:U)/B30 -> 0.21347929
A5: ניירות ערך מסחריים | B5: =SUM('ניירות ערך מסחריים'!AD:AD) -> 0 | E5: =SUM('[1]ניירות ערך מסחריים'!AD:AD)/B30 -> 0
A6: איגרות חוב | B6: =SUM('איגרות חוב'!AD:AD) -> 206889.14 | E6: =SUM('[1]איגרות חוב'!AD:AD)/B30 -> 0.16764207
A7: מניות, מניות בכורה ויחידות השתתפות | B7: =SUM('מניות מבכ ויהש'!U:U) -> 250049.68 | E7: =SUM('[1]מניות מבכ ויהש'!U:U)/B30 -> 0.20261501
A8: קרנות סל | B8: =SUM('קרנות סל'!T:T) -> 228466.79 | E8: =SUM('[1]קרנות סל'!T:T)/B30 -> 0.18512642
A9: קרנות נאמנות | B9: =SUM('קרנות נאמנות'!T:T) -> 8363.206 | E9: =SUM('[1]קרנות נאמנות'!T:T)/B30 -> 0.0067766977
A10: כתבי אופציה | B10: =SUM('כתבי אופציה'!W:W) -> 508.51 | E10: =SUM('[1]כתבי אופציה'!W:W)/B30 -> 0.00041204516
A11: אופציות | B11: =SUM(אופציות!V:V) -> 0 | E11: =SUM([1]אופציות!V:V)/B30 -> 0
A12: חוזים עתידיים | B12: =SUM('חוזים עתידיים'!R:R) -> 4396.952 | E12: =SUM('[1]חוזים עתידיים'!R:R)/B30 -> 0.0035628459
A13: מוצרים מובנים | B13: =SUM('מוצרים מובנים'!Z:Z) -> 0 | E13: =SUM('[1]מוצרים מובנים'!Z:Z)/B30 -> 0
A14: לא סחיר איגרות חוב ממשלתיות | B14: =SUM('לא סחיר איגרות חוב ממשלתיות'!U:U) -> 0 | E14: =SUM('[1]לא סחיר איגרות חוב ממשלתיות'!U:U)/B30 -> 0
A15: לא סחיר איגרות חוב מיועדות | B15: =SUM('לא סחיר איגרות חוב מיועדות'!N:N) -> 0 | E15: =SUM('[1]לא סחיר איגרות חוב מיועדות'!N:N)/B30 -> 0
A16: אפיק השקעה מובטח תשואה | B16: =SUM('אפיק השקעה מובטח תשואה'!F:F) -> 0 | E16: =SUM('[1]אפיק השקעה מובטח תשואה'!F:F)/B30 -> 0
A17: לא סחיר ניירות ערך מסחריים | B17: =SUM('לא סחיר ניירות ערך מסחריים'!AI:AI) -> 0 | E17: =SUM('[1]לא סחיר ניירות ערך מסחריים'!AI:AI)/B30 -> 0
A18: לא סחיר איגרות חוב | B18: =SUM('לא סחיר איגרות חוב'!AG:AG) -> 13089.55 | E18: =SUM('[1]לא סחיר איגרות חוב'!AG:AG)/B30 -> 0.01060645
A19: לא סחיר מניות, מניות בכורה ויחידות השתתפות | B19: =SUM('לא סחיר מניות מבכ ויהש'!X:X) -> 14657.946 | E19: =SUM('[1]לא סחיר מניות מבכ ויהש'!X:X)/B30 -> 0.011877319
A20: קרנות השקעה | B20: =SUM('קרנות השקעה'!W:W) -> 147922.38 | E20: =SUM('[1]קרנות השקעה'!W:W)/B30 -> 0.11986136
A21: לא סחיר כתבי אופציה | B21: =SUM('לא סחיר כתבי אופציה'!Z:Z) -> 0 | E21: =SUM('[1]לא סחיר כתבי אופציה'!Z:Z)/B30 -> 0
A22: לא סחיר אופציות | B22: =SUM('לא סחיר אופציות'!Z:Z) -> 0 | E22: =SUM('[1]לא סחיר אופציות'!Z:Z)/B30 -> 0
A23: לא סחיר נגזרים אחרים | B23: =SUM('לא סחיר נגזרים אחרים'!R:R) -> 7090.775 | E23: =SUM('[1]לא סחיר נגזרים אחרים'!R:R)/B30 -> 0.0057456481
A24: הלוואות | B24: =SUM(הלוואות!AT:AT) -> 42244.724 | E24: =SUM([1]הלוואות!AT:AT)/B30 -> 0.034230859
A25: לא סחיר מוצרים מובנים | B25: =SUM('לא סחיר מוצרים מובנים'!AB:AB) -> 0 | E25: =SUM('[1]לא סחיר מוצרים מובנים'!AB:AB)/B30 -> 0
A26: פיקדונות מעל 3 חודשים | B26: =SUM('פיקדונות מעל 3 חודשים'!T:T) -> 0 | E26: =SUM('[1]פיקדונות מעל 3 חודשים'!T:T)/B30 -> 0
A27: זכויות מקרקעין | B27: =SUM('זכויות מקרקעין'!S:S) -> 5100 | E27: =SUM('[1]זכויות מקרקעין'!S:S)/B30 -> 0.004132525
A28: השקעה בחברות מוחזקות | B28: =SUM('השקעה בחברות מוחזקות'!U:U) -> 0 | E28: =SUM('[1]השקעה בחברות מוחזקות'!U:U)/B30 -> 0
A29: נכסים אחרים | B29: =SUM('נכסים אחרים'!N:N) -> -1872.62 | E29: =SUM('[1]נכסים אחרים'!N:N)/B30 -> -0.0015173822
A30: סך הכל נכסים | B30: =IF(SUM(B3:B29)=0,0.0001,SUM(B3:B29)) -> 1234112.3 | C30: =SUM(C3:C29) -> 0 | D30: =SUM(D3:D29) -> 0 | E30: =SUM(E3:E29) -> 1
A31: מסגרות אשראי
A32: יתרות התחייבויות להשקעה | B32: =SUM('[1]יתרות התחייבות להשקעה'!O:O) -> 41332.228 | E32: =B32/D30 -> #DIV/0!

Sheet מזומנים ושווי מזומנים
A1: מספר קופה/קרן/ח.פ. עבור חברת ביטוח | B1: מספר מסלול | C1: שם הבנק | D1: מספר מזהה בנק | E1: סוג מספר מזהה בנק | F1: מאפיין עיקרי | G1: ישראל/חו"ל | H1: בעל עניין/צד קשור | I1: דירוג הבנק | J1: שם מדרג | K1: מטבע פעילות | L1: שווי מטבעי | M1: שער חליפין | N1: שיעור ריבית | O1: שווי הוגן (באלפי ש"ח) | P1: שיעור מנכסי אפיק ההשקעה | Q1: שיעור מסך נכסי ההשקעה
A2: 337 | B2: 1405 | C2: בנק לאומי לישראל בע"מ | D2: 10-800 | E2: סימול בנק | F2: מזומן ועו"ש בש"ח | G2: ישראל | H2: לא | I2: AAA | J2: S&P מעלות | K2: ILS | L2: 128.862 | M2: 1 | N2: 0 | O2: 128.862 | P2: 0.17416081 | Q2: 0.014290384
A3: 337 | B3: 1405 | C3: פועלים | D3: 12-591 | E3: סימול בנק | F3: מזומן ועו"ש נקוב במט"ח | G3: ישראל | H3: לא | I3: AAA | J3: S&P מעלות | K3: USD | L3: 92.893 | M3: 3.372 | N3: SOFR-1.5% | O3: 313.234 | P3: 0.42334558 | Q3: 0.034736694
A4: 337 | B4: 1405 | C4: פועלים | D4: 12-591 | E4: סימול בנק | F4: מזומן ועו"ש נקוב במט"ח | G4: ישראל | H4: לא | I4: AAA | J4: S&P מעלות | K4: EUR | L4: 5.182 | M4: 3.9552 | N4: 0 | O4: 20.498 | P4: 0.027703314 | Q4: 0.0022731348
A5: 337 | B5: 1405 | C5: פועלים | D5: 12-591 | E5: סימול בנק | F5: מזומן ועו"ש בש"ח | G5: ישראל | H5: לא | I5: AAA | J5: S&P מעלות | K5: ILS | L5: 277.304 | M5: 1 | N5: 0.0403 | O5: 277.304 | P5: 0.37478427 | Q5: 0.030752103
A6: 337 | B6: 1405 | C6: בנק לאומי לישראל בע"מ | D6: 10-800 | E6: סימול בנק | F6: מזומן ועו"ש בש"ח | G6: ישראל | H6: לא | I6: AAA | J6: S&P מעלות | K6: ILS | L6: 0.004 | M6: 1 | N6: 0 | O6: 0.004 | P6: 6.0278231e-06 | Q6: 4.9459983e-07
A7: 337 | B7: 1477 | C7: בנק לאומי לישראל בע"מ | D7: 10-800 | E7: סימול בנק | F7: מזומן ועו"ש בש"ח | G7: ישראל | H7: לא | I7: AAA | J7: S&P מעלות | K7: ILS | L7: 603.083 | M7: 1 | N7: 0 | O7: 603.083 | P7: 0.37332678 | Q7: 0.034711146
A8: 337 | B8: 1477 | C8: פועלים | D8: 12-591 | E8: סימול בנק | F8: מזומן ועו"ש נקוב במט"ח | G8: ישראל | H8: לא | I8: AAA | J8: S&P מעלות | K8: USD | L8: 38.502 | M8: 3.372 | N8: SOFR-1.5% | O8: 129.829 | P8: 0.080367862 | Q8: 0.0074724363
A9: 337 | B9: 1477 | C9: פועלים | D9: 12-591 | E9: סימול בנק | F9: מזומן ועו"ש נקוב במט"ח | G9: ישראל | H9: לא | I9: AAA | J9: S&P מעלות | K9: HKD | L9: 2.916 | M9: 0.429 | N9: 0 | O9: 1.251 | P9: 0.00077425223 | Q9: 7.1988358e-05
A10: 337 | B10: 1477 | C10: פועלים | D10: 12-591 | E10: סימול בנק | F10: מזומן ועו"ש נקוב במט"ח | G10: ישראל | H10: לא | I10: AAA | J10: S&P מעלות | K10: EUR | L10: 106.806 | M10: 3.9552 | N10: 0 | O10: 422.44 | P10: 0.26150327 | Q10: 0.024314029
A11: 337 | B11: 1477 | C11: פועלים | D11: 12-591 | E11: סימול בנק | F11: מזומן ועו"ש נקוב במט"ח | G11: ישראל | H11: לא | I11: AAA | J11: S&P מעלות | K11: JPY | L11: 88.168 | M11: 0.023369 | N11: 0 | O11: 2.06 | P11: 0.0012754542 | Q11: 0.00011858908
A12: 337 | B12: 1477 | C12: פועלים | D12: 12-591 | E12: סימול בנק | F12: מזומן ועו"ש נקוב במט"ח | G12: ישראל | H12: לא | I12: AAA | J12: S&P מעלות | K12: GBP | L12: 0.521 | M12: 4.6236 | N12: 0 | O12: 2.409 | P12: 0.0014909511 | Q12: 0.00013862553
A13: 337 | B13: 1477 | C13: פועלים | D13: 12-591 | E13: סימול בנק | F13: מזומן ועו"ש בש"ח | G13: ישראל | H13: לא | I13: AAA | J13: S&P מעלות | K13: ILS | L13: 448.595 | M13: 1 | N13: 0.0403 | O13: 448.595 | P13: 0.27769394 | Q13: 0.025819404
A14: 337 | B14: 1477 | C14: פועלים | D14: 12-591 | E14: סימול בנק | F14: פח"ק/פר"י | G14: ישראל | H14: לא | I14: AAA | J14: S&P מעלות | K14: ILS | L14: 0.237 | M14: 1 | N14: 0.0403 | O14: 0.237 | P14: 0.00014678454 | Q14: 1.364772e-05
A15: 337 | B15: 1477 | C15: פועלים | D15: 12-591 | E15: סימול בנק | F15: מזומן ועו"ש נקוב במט"ח | G15: ישראל | H15: לא | I15: AAA | J15: S&P מעלות | K15: CHF | L15: 1.306 | M15: 4.2314 | N15: 0 | O15: 5.526 | P15: 0.0034207088 | Q15: 0.00031805038
A16: 337 | B16: 9962 | C16: בנק לאומי לישראל בע"מ | D16: 10-800 | E16: סימול בנק | F16: מזומן ועו"ש בש"ח | G16: ישראל | H16: לא | I16: AAA | J16: S&P מעלות | K16: ILS | L16: 283.855 | M16: 1 | N16: 0 | O16: 283.855 | P16: 0.14743132 | Q16: 0.0066718397
A17: 337 | B17: 9962 | C17: פועלים | D17: 12-591 | E17: סימול בנק | F17: מזומן ועו"ש נקוב במט"ח | G17: ישראל | H17: לא | I17: AAA | J17: S&P מעלות | K17: USD | L17: 49.248 | M17: 3.372 | N17: SOFR-1.5% | O17: 166.065 | P17: 0.086252547 | Q17: 0.0039032626
A18: 337 | B18: 9962 | C18: פועלים | D18: 12-591 | E18: סימול בנק | F18: מזומן ועו"ש נקוב במט"ח | G18: ישראל | H18: לא | I18: AAA | J18: S&P מעלות | K18: HKD | L18: 0.908 | M18: 0.429 | N18: 0 | O18: 0.389 | P18: 0.00020225877 | Q18: 9.1529946e-06
A19: 337 | B19: 9962 | C19: פועלים | D19: 12-591 | E19: סימול בנק | F19: מזומן ועו"ש נקוב במט"ח | G19: ישראל | H19: לא | I19: AAA | J19: S&P מעלות | K19: EUR | L19: 89.39 | M19: 3.9552 | N19: 0 | O19: 353.556 | P19: 0.18363316 | Q19: 0.0083101134
A20: 337 | B20: 9962 | C20: פועלים | D20: 12-591 | E20: סימול בנק | F20: מזומן ועו"ש נקוב במט"ח | G20: ישראל | H20: לא | I20: AAA | J20: S&P מעלות | K20: JPY | L20: 99.373 | M20: 0.023369 | N20: 0 | O20: 2.322 | P20: 0.001206157 | Q20: 5.4583285e-05
A21: 337 | B21: 9962 | C21: פועלים | D21: 12-591 | E21: סימול בנק | F21: מזומן ועו"ש נקוב במט"ח | G21: ישראל | H21: לא | I21: AAA | J21: S&P מעלות | K21: GBP | L21: 0.703 | M21: 4.6236 | N21: 0 | O21: 3.252 | P21: 0.0016889161 | Q21: 7.6430011e-05
A22: 337 | B22: 9962 | C22: פועלים | D22: 12-591 | E22: סימול בנק | F22: מזומן ועו"ש בש"ח | G22: ישראל | H22: לא | I22: AAA | J22: S&P מעלות | K22: ILS | L22: 1104.74 | M22: 1 | N22: 0.0403 | O22: 1104.74 | P22: 0.57379064 | Q22: 0.025966254
A23: 337 | B23: 9962 | C23: פועלים | D23: 12-591 | E23: סימול בנק | F23: מזומן ועו"ש נקוב במט"ח | G23: ישראל | H23: לא | I23: AAA | J23: S&P מעלות | K23: CHF | L23: 2.637 | M23: 4.2314 | N23: 0 | O23: 11.157 | P23: 0.0057949943 | Q23: 0.00026224599
A24: 337 | B24: 9963 | C24: בנק לאומי לישראל בע"מ | D24: 10-800 | E24: סימול בנק | F24: מזומן ועו"ש בש"ח | G24: ישראל | H24: לא | I24: AAA | J24: S&P מעלות | K24: ILS | L24: 1411.249 | M24: 1 | N24: 0 | O24: 1411.249 | P24: 0.03731159 | Q24: 0.0012683887
A25: 337 | B25: 9963 | C25: פועלים | D25: 12-591 | E25: סימול בנק | F25: מזומן ועו"ש נקוב במט"ח | G25: ישראל | H25: לא | I25: AAA | J25: S&P מעלות | K25: USD | L25: 3928.299 | M25: 3.372 | N25: SOFR-1.5% | O25: 13246.225 | P25: 0.3502129 | Q25: 0.011905311
A26: 337 | B26: 9963 | C26: פועלים | D26: 12-591 | E26: סימול בנק | F26: מזומן ועו"ש נקוב במט"ח | G26: ישראל | H26: לא | I26: AAA | J26: S&P מעלות | K26: HKD | L26: 87.459 | M26: 0.429 | N26: 0 | O26: 37.52 | P26: 0.00099198179 | Q26: 3.372192e-05
A27: 337 | B27: 9963 | C27: פועלים | D27: 12-591 | E27: סימול בנק | F27: מזומן ועו"ש נקוב במט"ח | G27: ישראל | H27: לא | I27: AAA | J27: S&P מעלות | K27: CAD | L27: 7.495 | M27: 2.4674 | N27: 0 | O27: 18.494 | P27: 0.00048895075 | Q27: 1.6621634e-05
A28: 337 | B28: 9963 | C28: פועלים | D28: 12-591 | E28: סימול בנק | F28: מזומן ועו"ש נקוב במט"ח | G28: ישראל | H28: לא | I28: AAA | J28: S&P מעלות | K28: EUR | L28: 1666.009 | M28: 3.9552 | N28: 0 | O28: 6589.398 | P28: 0.17421509 | Q28: 0.005922354
A29: 337 | B29: 9963 | C29: פועלים | D29: 12-591 | E29: סימול בנק | F29: מזומן ועו"ש נקוב במט"ח | G29: ישראל | H29: לא | I29: AAA | J29: S&P מעלות | K29: JPY | L29: 57.023 | M29: 0.023369 | N29: 0 | O29: 1.333 | P29: 3.5231307e-05 | Q29: 1.1976705e-06
A30: 337 | B30: 9963 | C30: פועלים | D30: 12-591 | E30: סימול בנק | F30: מזומן ועו"ש נקוב במט"ח | G30: ישראל | H30: לא | I30: AAA | J30: S&P מעלות | K30: GBP | L30: 10.005 | M30: 4.6236 | N30: 0 | O30: 46.261 | P30: 0.0012230723 | Q30: 4.1577724e-05
A31: 337 | B31: 9963 | C31: פועלים | D31: 12-591 | E31: סימול בנק | F31: מזומן ועו"ש בש"ח | G31: ישראל | H31: לא | I31: AAA | J31: S&P מעלות | K31: ILS | L31: 14210.135 | M31: 1 | N31: 0.0403 | O31: 14210.135 | P31: 0.37569742 | Q31: 0.012771644
A32: 337 | B32: 9963 | C32: פועלים | D32: 12-591 | E32: סימול בנק | F32: מזומן ועו"ש נקוב במט"ח | G32: ישראל | H32: לא | I32: AAA | J32: S&P מעלות | K32: CHF | L32: 9.414 | M32: 4.2314 | N32: 0 | O32: 39.833 | P32: 0.0010531382 | Q32: 3.5800902e-05
A33: 337 | B33: 9963 | C33: בנק לאומי לישראל בע"מ | D33: 10-800 | E33: סימול בנק | F33: מזומן ועו"ש בש"ח | G33: ישראל | H33: לא | I33: AAA | J33: S&P מעלות | K33: ILS | L33: 1906.459 | M33: 1 | N33: 0 | O33: 1906.459 | P33: 0.05040429 | Q33: 0.0017134684
A34: 337 | B34: 9963 | C34: בנק לאומי לישראל בע"מ | D34: 10-800 | E34: סימול בנק | F34: מזומן ועו"ש בש"ח | G34: ישראל | H34: לא | I34: AAA | J34: S&P מעלות | K34: ILS | L34: 309.109 | M34: 1 | N34: 0 | O34: 309.109 | P34: 0.0081724307 | Q34: 0.00027781765
A35: 337 | B35: 9963 | C35: פועלים | D35: 12-591 | E35: סימול בנק | F35: מזומן ועו"ש בש"ח | G35: ישראל | H35: לא | I35: AAA | J35: S&P מעלות | K35: ILS | L35: 0 | M35: 1 | N35: 0.0403 | O35: 0 | P35: 3.1726434e-09 | Q35: 1.0785241e-10
A36: 337 | B36: 9963 | C36: בנק לאומי לישראל בע"מ | D36: 10-800 | E36: סימול בנק | F36: מזומן ועו"ש בש"ח | G36: ישראל | H36: לא | I36: AAA | J36: S&P מעלות | K36: ILS | L36: 7.334 | M36: 1 | N36: 0 | O36: 7.334 | P36: 0.0001939006 | Q36: 6.5915528e-06
A37: 337 | B37: 9964 | C37: בנק לאומי לישראל בע"מ | D37: 10-800 | E37: סימול בנק | F37: מזומן ועו"ש בש"ח | G37: ישראל | H37: לא | I37: AAA | J37: S&P מעלות | K37: ILS | L37: 285.307 | M37: 1 | N37: 0 | O37: 285.307 | P37: 0.17866912 | Q37: 0.0073479158
A38: 337 | B38: 9964 | C38: פועלים | D38: 12-591 | E38: סימול בנק | F38: מזומן ועו"ש נקוב במט"ח | G38: ישראל | H38: לא | I38: AAA | J38: S&P מעלות | K38: USD | L38: 107.552 | M38: 3.372 | N38: SOFR-1.5% | O38: 362.665 | P38: 0.22711348 | Q38: 0.0093402304
A39: 337 | B39: 9964 | C39: פועלים | D39: 12-591 | E39: סימול בנק | F39: מזומן ועו"ש נקוב במט"ח | G39: ישראל | H39: לא | I39: AAA | J39: S&P מעלות | K39: HKD | L39: 3.056 | M39: 0.429 | N39: 0 | O39: 1.311 | P39: 0.0008210819 | Q39: 3.3767674e-05
A40: 337 | B40: 9964 | C40: פועלים | D40: 12-591 | E40: סימול בנק | F40: מזומן ועו"ש נקוב במט"ח | G40: ישראל | H40: לא | I40: AAA | J40: S&P מעלות | K40: EUR | L40: 75.393 | M40: 3.9552 | N40: 0 | O40: 298.195 | P40: 0.18674047 | Q40: 0.0076798566
...

Sheet איגרות חוב ממשלתיות
A1: מספר קופה/קרן/ח.פ. עבור חברת ביטוח | B1: מספר מסלול | C1: שם מנפיק | D1: שם נייר ערך | E1: מספר נייר ערך | F1: מאפיין עיקרי | G1: ישראל/חו"ל | H1: מדינה לפי חשיפה כלכלית | I1: זירת מסחר | J1: דירוג | K1: שם מדרג | L1: מטבע פעילות | M1: מח"מ | N1: מועד פדיון | O1: שיעור ריבית | P1: תשואה לפדיון | Q1: סכום לקבל (במטבע הפעילות) | R1: ערך נקוב (יחידות) | S1: שער חליפין | T1: שער נייר הערך | U1: שווי הוגן (באלפי ש"ח) | V1: עלות מופחתת (באלפי ש"ח) | W1: השיטה שיושמה בדוח הכספי | X1: שיעור מערך נקוב מונפק | Y1: שיעור מנכסי אפיק ההשקעה | Z1: שיעור מסך נכסי ההשקעה
A2: 337 | B2: 1405 | C2: גליל | D2: ממשל צמודה 0527 | E2: IL0011408478 | F2: צמוד למדד המחירים לצרכן בריבית קבועה | G2: ישראל | H2: ישראל | I2: TASE | J2: RF | K2: פנימי | L2: ILS | M2: 1.905 | N2: 31/05/2027 | O2: 0.0075 | P2: 0.02096 | R2: 320378 | S2: 1 | T2: 115.45 | U2: 369.876 | W2: שווי הוגן | X2: 1.3e-05 | Y2: 0.096282126 | Z2: 0.041018118
A3: 337 | B3: 1405 | C3: שחר | D3: ממשל שיקלית 0928 | E3: IL0011508798 | F3: לא צמוד למדד המחירים לצרכן ריבית קבועה | G3: ישראל | H3: ישראל | I3: TASE | J3: RF | K3: פנימי | L3: ILS | M3: 3.109 | N3: 28/09/2028 | O3: 0.0225 | P3: 0.03952 | R3: 703616 | S3: 1 | T3: 96.6 | U3: 679.693 | W3: שווי הוגן | X3: 2e-05 | Y3: 0.17693016 | Z3: 0.0753758
A4: 337 | B4: 1405 | C4: שחר | D4: ממשל שקלית 0327 | E4: IL0011393449 | F4: לא צמוד למדד המחירים לצרכן ריבית קבועה | G4: ישראל | H4: ישראל | I4: TASE | J4: RF | K4: פנימי | L4: ILS | M4: 1.725 | N4: 31/03/2027 | O4: 0.02 | P4: 0.04003 | R4: 186178 | S4: 1 | T4: 97.19 | U4: 180.946 | W4: שווי הוגן | X4: 7e-06 | Y4: 0.047101961 | Z4: 0.020066381
A5: 337 | B5: 1405 | C5: שחר | D5: ממשל שקלית 0335 | E5: IL0012023326 | F5: לא צמוד למדד המחירים לצרכן ריבית קבועה | G5: ישראל | H5: ישראל | I5: TASE | J5: RF | K5: פנימי | L5: ILS | M5: 8.174 | N5: 30/03/2035 | O5: 0.04 | P5: 0.04114 | R5: 210941 | S5: 1 | T5: 100.1 | U5: 211.152 | W5: שווי הוגן | X5: 6e-06 | Y5: 0.054964734 | Z5: 0.023416079
A6: 337 | B6: 1405 | C6: שחר | D6: ממשל שקלית 4.60% 8/29 | E6: IL0012128935 | F6: לא צמוד למדד המחירים לצרכן ריבית קבועה | G6: ישראל | H6: ישראל | I6: TASE | J6: RF | K6: פנימי | L6: ILS | M6: 3.781 | N6: 31/08/2029 | O6: 0.046 | P6: 0.03939 | R6: 97599 | S6: 1 | T6: 105.5 | U6: 102.967 | W6: שווי הוגן | X6: 6e-06 | Y6: 0.026803214 | Z6: 0.011418707
A7: 337 | B7: 1405 | C7: שחר | D7: ממשלתי שקלית 0142 | E7: IL0011254005 | F7: לא צמוד למדד המחירים לצרכן ריבית קבועה | G7: ישראל | H7: ישראל | I7: TASE | J7: RF | K7: פנימי | L7: ILS | M7: 11.421 | N7: 31/01/2042 | O7: 0.055 | P7: 0.04352 | R7: 736311 | S7: 1 | T7: 115.63 | U7: 851.396 | W7: שווי הוגן | X7: 2.6e-05 | Y7: 0.22162608 | Z7: 0.094417157
A8: 337 | B8: 1405 | C8: גליל | D8: ממשלתית צמודה 0726 | E8: IL0011695645 | F8: צמוד למדד המחירים לצרכן בריבית קבועה | G8: ישראל | H8: ישראל | I8: TASE | J8: RF | K8: פנימי | L8: ILS | M8: 1.078 | N8: 31/07/2026 | O8: 0.001 | P8: 0.02338 | R8: 116422 | S8: 1 | T8: 114.5 | U8: 133.303 | W8: שווי הוגן | X8: 6e-06 | Y8: 0.034700009 | Z8: 0.0147829
A9: 337 | B9: 1405 | C9: גליל | D9: ממשלתית צמודה 1.10% 1028 | E9: IL0011973265 | F9: צמוד למדד המחירים לצרכן בריבית קבועה | G9: ישראל | H9: ישראל | I9: TASE | J9: RF | K9: פנימי | L9: ILS | M9: 3.268 | N9: 31/10/2028 | O9: 0.011 | P9: 0.02053 | R9: 176782 | S9: 1 | T9: 103.51 | U9: 182.987 | W9: שווי הוגן | X9: 6e-06 | Y9: 0.047633161 | Z9: 0.020292682
A10: 337 | B10: 1405 | C10: שחר | D10: ממשלתית שקלית 0537 | E10: IL0011661803 | F10: לא צמוד למדד המחירים לצרכן ריבית קבועה | G10: ישראל | H10: ישראל | I10: TASE | J10: RF | K10: פנימי | L10: ILS | M10: 10.803 | N10: 31/05/2037 | O10: 0.015 | P10: 0.04253 | R10: 109758 | S10: 1 | T10: 74.8 | U10: 82.099 | W10: שווי הוגן | X10: 3e-06 | Y10: 0.021371098 | Z10: 0.0091045165
A11: 337 | B11: 1405 | C11: שחר | D11: ממשלתית שקלית 1.00% 03/30 | E11: IL0011609851 | F11: לא צמוד למדד המחירים לצרכן ריבית קבועה | G11: ישראל | H11: ישראל | I11: TASE | J11: RF | K11: פנימי | L11: ILS | M11: 4.641 | N11: 31/03/2030 | O11: 0.01 | P11: 0.03969 | R11: 975818 | S11: 1 | T11: 87.63 | U11: 855.109 | W11: שווי הוגן | X11: 2.6e-05 | Y11: 0.22259258 | Z11: 0.094828906
A12: 337 | B12: 1405 | C12: US Govt | D12: T 3.875% 08/34 | E12: US91282CLF67 | F12: צמוד מט"ח בריבית קבועה | G12: חו"ל | H12: ארה"ב | I12: FOREIGN_GOV_SEC | J12: AA+ | K12: Fitch | L12: USD | M12: 7.638 | N12: 15/08/2034 | O12: 0.03875 | P12: 0.0424 | R12: 27500 | S12: 3.372 | T12: 99.135 | U12: 91.928 | W12: שווי הוגן | X12: 0 | Y12: 0.023929745 | Z12: 0.010194552
A13: 337 | B13: 1405 | C13: US Govt | D13: T-3 3/8 15/05/33 | E13: US91282CHC82 | F13: צמוד מט"ח בריבית קבועה | G13: חו"ל | H13: ארה"ב | I13: FOREIGN_GOV_SEC | J13: AA+ | K13: Fitch | L13: USD | M13: 6.921 | N13: 15/05/2033 | O13: 0.03375 | P13: 0.04125 | R13: 31000 | S13: 3.372 | T13: 95.79 | U13: 100.132 | W13: שווי הוגן | X13: 0 | Y13: 0.026065127 | Z13: 0.011104267
... A50: 337 | B50: 9964 | C50: US Govt | D50: T-3 3/8 15/05/33 | E50: US91282CHC82 | F50: צמוד מט"ח בריבית קבועה | G50: חו"ל | H50: ארה"ב | I50: FOREIGN_GOV_SEC | J50: AA+ | K50: Fitch | L50: USD | M50: 6.921 | N50: 15/05/2033 | O50: 0.03375 | P50: 0.04125 | R50: 282000 | S50: 3.372 | T50: 95.79 | U50: 910.874 | W50: שווי הוגן | X50: 3e-06 | Y50: 0.052587269 | Z50: 0.023459046

Sheet ניירות ערך מסחריים
A1: מספר קופה/קרן/ח.פ. עבור חברת ביטוח | B1: מספר מסלול | C1: שם מנפיק | D1: מספר מנפיק | E1: סוג מספר מזהה מנפיק | F1: שם נייר ערך | G1: מספר נייר ערך | H1: סוג מספר נייר ערך | I1: מאפיין עיקרי | J1: ישראל/חו"ל | K1: מדינה לפי חשיפה כלכלית | L1: זירת מסחר | M1: ענף מסחר | N1: בעל עניין/צד קשור | O1: דירוג | P1: שם מדרג | Q1: דירוג נייר הערך/המנפיק | R1: מטבע פעילות | S1: מח"מ | T1: ריבית עוגן | U1: מועד פדיון | V1: שיעור ריבית | W1: תשואה לפדיון | X1: נחיתות חוזית | Y1: האם סווג כחוב בעייתי | Z1: ערך נקוב (יחידות) | AA1: שער חליפין | AB1: שער נייר הערך | AC1: סכום לקבל (במטבע הפעילות) | AD1: שווי הוגן (באלפי ש"ח) | AE1: עלות מופחתת (באלפי ש"ח) | AF1: עלות מופחתת (במטבע הפעילות) | AG1: השיטה שיושמה בדוח הכספי | AH1: שיעור מערך נקוב מונפק | AI1: שיעור מנכסי אפיק ההשקעה | AJ1: שיעור מסך נכסי ההשקעה
A2: 337 | B2: 1405
A3: 337 | B3: 1477
A4: 337 | B4: 9962
A5: 337 | B5: 9963
A6: 337 | B6: 9964
A7: 337 | B7: 15372

Sheet איגרות חוב
A1: מספר קופה/קרן/ח.פ. עבור חברת ביטוח | B1: מספר מסלול | C1: שם מנפיק | D1: מספר מנפיק | E1: סוג מספר מזהה מנפיק | F1: שם נייר ערך | G1: מספר נייר ערך | H1: סוג מספר נייר ערך | I1: מאפיין עיקרי | J1: ישראל/חו"ל | K1: מדינה לפי חשיפה כלכלית | L1: סטאטוס סחירות | M1: זירת מסחר | N1: ענף מסחר | O1: בעל עניין/צד קשור | P1: דירוג | Q1: שם מדרג | R1: דירוג נייר הערך/המנפיק | S1: מטבע פעילות | T1: מח"מ | U1: מועד פדיון | V1: שיעור ריבית | W1: תשואה לפדיון | X1: נחיתות חוזית | Y1: האם סווג כחוב בעייתי | Z1: ערך נקוב (יחידות) | AA1: שער חליפין | AB1: שער נייר הערך | AC1: סכום לקבל (במטבע הפעילות) | AD1: שווי הוגן (באלפי ש"ח) | AE1: עלות מופחתת (באלפי ש"ח) | AF1: עלות מופחתת (במטבע הפעילות) | AG1: השיטה שיושמה בדוח הכספי | AH1: שיעור מערך נקוב מונפק | AI1: שיעור מנכסי אפיק ההשקעה | AJ1: שיעור מסך נכסי ההשקעה
A2: 337 | B2: 1405 | C2: לוויתן בונד בע"מ | D2: 516223864 | E2: ח.פ | F2: LVIATH 6.125% 6/25 | G2: IL0011677742 | H2: ISIN | I2: צמוד למט"ח | J2: חו"ל | K2: ישראל | L2: סחיר | M2: אחר | N2: חיפושי נפט וגז | O2: לא | P2: BB- | Q2: S&P | R2: נייר ערך | S2: USD | T2: 0.133 | U2: 30/06/2025 | V2: 0.06125 | W2: 0.23773 | X2: החוב לא נחות | Y2: לא | Z2: 0 | AA2: 3.372 | AB2: 0 | AC2: 0.061 | AD2: 0.207 | AG2: שווי הוגן | AH2: 0 | AI2: 5.6765712e-05 | AJ2: 2.2904631e-05
A3: 337 | B3: 1405 | C3: אאורה השקעות בע"מ | D3: 520038274 | E3: ח.פ | F3: אאורה אגח טז | G3: IL0037305799 | H3: ISIN | I3: לא צמוד למדד המחירים לצרכן | J3: ישראל | K3: ישראל | L3: סחיר | M3: TASE | N3: בנייה | O3: לא | P3: A2 | Q3: מידרוג Moodys | R3: נייר ערך | S3: ILS | T3: 1.207 | U3: 30/09/2027 | V3: 0.035 | W3: 0.04885 | X3: החוב לא נחות | Y3: לא | Z3: 28912 | AA3: 1 | AB3: 99.31 | AD3: 28.713 | AG3: שווי הוגן | AH3: 0.000208 | AI3: 0.0078915724 | AJ3: 0.003184203
A4: 337 | B4: 1405 | C4: אאורה השקעות בע"מ | D4: 520038274 | E4: ח.פ | F4: אאורה אגח יז %3.85 31/01/2029 | G4: IL0011935801 | H4: ISIN | I4: צמוד למדד המחירים לצרכן | J4: ישראל | K4: ישראל | L4: סחיר | M4: TASE | N4: בנייה | O4: לא | P4: A2 | Q4: מידרוג Moodys | R4: נייר ערך | S4: ILS | T4: 2.116 | U4: 31/01/2029 | V4: 0.0385 | W4: 0.03237 | X4: החוב לא נחות | Y4: לא | Z4: 19000 | AA4: 1 | AB4: 111.11 | AD4: 21.111 | AG4: שווי הוגן | AH4: 6.3e-05 | AI4: 0.0058022866 | AJ4: 0.0023411885
A5: 337 | B5: 1405 | C5: אדגר השקעות ופיתוח בע"מ | D5: 520035171 | E5: ח.פ | F5: אדגר אגח סד יא | G5: IL0018202817 | H5: ISIN | I5: צמוד למדד המחירים לצרכן | J5: ישראל | K5: גלובלי | L5: סחיר | M5: TASE | N5: נדל"ן מניב בחו"ל | O5: לא | P5: A2 | Q5: מידרוג Moodys | R5: נייר ערך | S5: ILS | T5: 2.624 | U5: 31/03/2030 | V5: 0.0245 | W5: 0.03057 | X5: החוב לא נחות | Y5: לא | Z5: 4565.22 | AA5: 1 | AB5: 115.76 | AD5: 5.285 | AG5: שווי הוגן | AH5: 1e-05 | AI5: 0.0014524883 | AJ5: 0.0005860705
A6: 337 | B6: 1405 | C6: אדמה פתרונות לחקלאות בע"מ | D6: 520043605 | E6: ח.פ | F6: אדמה אגח ב | G6: IL0011109159 | H6: ISIN | I6: צמוד למדד המחירים לצרכן | J6: ישראל | K6: ישראל | L6: סחיר | M6: TASE | N6: כימיה, גומי ופלסטיק | O6: לא | P6: AA- | Q6: S&P מעלות | R6: נייר ערך | S6: ILS | T6: 5.037 | U6: 30/11/2036 | V6: 0.0515 | W6: 0.04176 | X6: החוב לא נחות | Y6: לא | Z6: 0.77 | AA6: 1 | AB6: 148.91 | AD6: 0.001 | AG6: שווי הוגן | AH6: 0 | AI6: 3.1514253e-07 | AJ6: 1.2715816e-07
A7: 337 | B7: 1405 | C7: או.פי.סי. אנרגיה בע"מ | D7: 514401702 | E7: ח.פ | F7: או פי סי אגח ב' | G7: IL0011660573 | H7: ISIN | I7: צמוד למדד המחירים לצרכן | J7: ישראל | K7: ישראל | L7: סחיר | M7: TASE | N7: אנרגיה | O7: לא | P7: A+ | Q7: S&P מעלות | R7: נייר ערך | S7: ILS | T7: 2.472 | U7: 01/10/2028 | V7: 0.0275 | W7: 0.03084 | X7: החוב לא נחות | Y7: לא | Z7: 32076.49 | AA7: 1 | AB7: 116.37 | AD7: 37.327 | AG7: שווי הוגן | AH7: 4.3e-05 | AI7: 0.010259361 | AJ7: 0.0041395917
A8: 337 | B8: 1405 | C8: איי.סי.אל גרופ בע"מ (דואלי) | D8: 520027830 | E8: ח.פ | F8: אייסיאל אגח ז | G8: IL0028103724 | H8: ISIN | I8: לא צמוד למדד המחירים לצרכן | J8: ישראל | K8: ישראל | L8: סחיר | M8: TASE | N8: כימיה, גומי ופלסטיק | O8: לא | P8: AA | Q8: S&P מעלות | R8: נייר ערך | S8: ILS | T8: 7.331 | U8: 30/12/2034 | V8: 0.024 | W8: 0.04694 | X8: החוב לא נחות | Y8: לא | Z8: 57491 | AA8: 1 | AB8: 84.92 | AD8: 48.821 | AG8: שווי הוגן | AH8: 3.7e-05 | AI8: 0.013418448 | AJ8: 0.0054142646
A9: 337 | B9: 1405 | C9: איירפורט סיטי בע"מ | D9: 511659401 | E9: ח.פ | F9: איירפורט אגח ה | G9: IL0011334872 | H9: ISIN | I9: צמוד למדד המחירים לצרכן | J9: ישראל | K9: ישראל | L9: סחיר | M9: TASE | N9: נדל"ן מניב בישראל | O9: לא | P9: AA | Q9: S&P מעלות | R9: נייר ערך | S9: ILS | T9: 2.014 | U9: 28/02/2029 | V9: 0.0234 | W9: 0.02872 | X9: החוב לא נחות | Y9: לא | Z9: 44835.17 | AA9: 1 | AB9: 116.49 | AD9: 52.228 | AG9: שווי הוגן | AH9: 2.8e-05 | AI9: 0.014354891 | AJ9: 0.005792114
A10: 337 | B10: 1405 | C10: איסתא בע"מ | D10: 520042763 | E10: ח.פ | F10: איסתא אגח א להמרה | G10: IL0011971285 | H10: ISIN | I10: אג"ח להמרה לא צמוד למדד המחירים לצרכן | J10: ישראל | K10: ישראל | L10: סחיר | M10: TASE | N10: מלונאות ותיירות | O10: לא | P10: NR | Q10: NR | R10: NR | S10: ILS | T10: 2.839 | U10: 30/06/2028 | V10: 0.0485 | W10: 0.0001 | X10: החוב לא נחות | Y10: לא | Z10: 13000 | AA10: 1 | AB10: 115 | AD10: 14.95 | AG10: שווי הוגן | AH10: 4.3e-05 | AI10: 0.0041089761 | AJ10: 0.0016579477
A11: 337 | B11: 1405 | C11: אלבר שירותי מימונית בע"מ | D11: 512025891 | E11: ח.פ | F11: אלבר אגח יט | G11: IL0011918245 | H11: ISIN | I11: צמוד למדד המחירים לצרכן | J11: ישראל | K11: ישראל | L11: סחיר | M11: TASE | N11: שירותים | O11: לא | P11: A+ | Q11: S&P מעלות | R11: נייר ערך | S11: ILS | T11: 1.451 | U11: 15/05/2028 | V11: 0.032 | W11: 0.03223 | X11: החוב לא נחות | Y11: לא | Z11: 6000 | AA11: 1 | AB11: 109.13 | AD11: 6.548 | AG11: שווי הוגן | AH11: 9e-06 | AI11: 0.0017996491 | AJ11: 0.00072614782
A12: 337 | B12: 1405 | C12: אלבר שירותי מימונית בע"מ | D12: 512025891 | E12: ח.פ | F12: אלבר אגח כ | G12: IL0011918328 | H12: ISIN | I12: לא צמוד למדד המחירים לצרכן | J12: ישראל | K12: ישראל | L12: סחיר | M12: TASE | N12: שירותים | O12: לא | P12: A+ | Q12: S&P מעלות | R12: נייר ערך | S12: ILS | T12: 1.518 | U12: 20/06/2028 | V12: 0.057 | W12: 0.05189 | X12: החוב לא נחות | Y12: לא | Z12: 7200 | AA12: 1 | AB12: 101.09 | AD12: 7.278 | AG12: שווי הוגן | AH12: 9e-06 | AI12: 0.002000475 | AJ12: 0.00080717987
A13: 337 | B13: 1405 | C13: אלדן תחבורה בע"מ | D13: 510454333 | E13: ח.פ | F13: אלדן תחבורה אגח ח | G13: IL0011924425 | H13: ISIN | I13: צמוד למדד המחירים לצרכן | J13: ישראל | K13: ישראל | L13: סחיר | M13: TASE | N13: שירותים | O13: לא | P13: A+ | Q13: S&P מעלות | R13: נייר ערך | S13: ILS | T13: 2.168 | U13: 30/09/2029 | V13: 0.0323 | W13: 0.02972 | X13: החוב לא נחות | Y13: לא | Z13: 10080 | AA13: 1 | AB13: 110.07 | AD13: 11.095 | AG13: שווי הוגן | AH13: 2e-05 | AI13: 0.0030494529 | AJ13: 0.0012304363
A14: 337 | B14: 1405 | C14: אלה ר. הנדסת בנין והשקעות בע"מ | D14: 520040015 | E14: ח.פ | F14: אלה ר השקע אגח א | G14: IL0011899502 | H14: ISIN | I14: צמוד למדד המחירים לצרכן | J14: ישראל | K14: ישראל | L14: סחיר | M14: TASE | N14: נדל"ן מניב בישראל | O14: לא | P14: A | Q14: S&P מעלות | R14: נייר ערך | S14: ILS | T14: 2.176 | U14: 01/07/2029 | V14: 0.0249 | W14: 0.03135 | X14: החוב לא נחות | Y14: לא | Z14: 18400 | AA14: 1 | AB14: 108.03 | AD14: 19.878 | AG14: שווי הוגן | AH14: 9.9e-05 | AI14: 0.0054632947 | AJ14: 0.0022044073
... A61: 337 | B61: 1405 | C61: יו.אמ.איץ' פרופרטיס אינק. | D61: 221890929 | E61: מספר תאגיד או שותפות בחו"ל | F61: יו.אמ.איץ' אגח א | G61: IL0011841678 | H61: ISIN | I61: צמוד למט"ח | J61: ישראל | K61: ארה"ב | L61: סחיר | M61: TASE | N61: נדל"ן מניב בחו"ל | O61: לא | P61: AA- | Q61: S&P מעלות | R61: נייר ערך | S61: USD | T61: 1.592 | U61: 28/02/2027 | V61: 0.0472 | W61: 0.05895 | X61: החוב לא נחות | Y61: לא | Z61: 18000 | AA61: 3.372 | AB61: 31.234 | AD61: 18.958 | AG61: שווי הוגן | AH61: 5.5e-05 | AI61: 0.0052104566 | AJ61: 0.0021023886
A62: 337 | B62: 1405 | C62: קבוצת יובלים השקעות בע"מ | D62: 514625094 | E62: ח.פ | F62: יובלים אגח ב | G62: IL0011869075 | H62: ISIN | I62: לא צמוד למדד המחירים לצרכן | J62: ישראל | K62: ישראל | L62: סחיר | M62: TASE | N62: בנייה | O62: לא | P62: NR | Q62: NR | R62: NR | S62: ILS | T62: 0.995 | U62: 05/07/2026 | V62: 0.056 | W62: 0.05842 | X62: החוב לא נחות | Y62: לא | Z62: 13600 | AA62: 1 | AB62: 99.8 | AC62: 3.876 | AD62: 17.449 | AG62: שווי הוגן | AH62: 0.0001 | AI62: 0.0047957661 | AJ62: 0.0019350634
A63: 337 | B63: 1405 | C63: יוחננוף | D63: 511344186 | E63: ח.פ | F63: יוחננוף אגח א | G63: IL0011874182 | H63: ISIN | I63: לא צמוד למדד המחירים לצרכן | J63: ישראל | K63: ישראל | L63: סחיר | M63: TASE | N63: רשתות שיווק | O63: לא | P63: A1 | Q63: מידרוג Moodys | R63: נייר ערך | S63: ILS | T63: 3.431 | U63: 01/07/2032 | V63: 0.0394 | W63: 0.04604 | X63: החוב לא נחות | Y63: לא | Z63: 1264.2 | AA63: 1 | AB63: 97.95 | AC63: 0.117 | AD63: 1.355 | AG63: שווי הוגן | AH63: 9e-06 | AI63: 0.00037249144 | AJ63: 0.0001502981
A64: 337 | B64: 1405 | C64: ירושלים מימון והנפקות (2005) בע"מ | D64: 513682146 | E64: ח.פ | F64: ירושלים הנפ אגח יט | G64: IL0012014333 | H64: ISIN | I64: צמוד למדד המחירים לצרכן | J64: ישראל | K64: ישראל | L64: סחיר | M64: TASE | N64: בנקים | O64: לא | P64: AA- | Q64: S&P מעלות | R64: נייר ערך | S64: ILS | T64: 3.874 | U64: 31/01/2031 | V64: 0.0259 | W64: 0.02747 | X64: החוב לא נחות | Y64: לא | Z64: 10000 | AA64: 1 | AB64: 105.24 | AD64: 10.524 | AG64: שווי הוגן | AH64: 1.5e-05 | AI64: 0.0028924993 | AJ64: 0.0011671065
A65: 337 | B65: 1405 | C65: ישפרו בע"מ | D65: 516291754 | E65: ח.פ | F65: ישפרו אגח א | G65: IL0012022906 | H65: ISIN | I65: צמוד למדד המחירים לצרכן | J65: ישראל | K65: ישראל | L65: סחיר | M65: TASE | N65: נדל"ן מניב בישראל | O65: לא | P65: NR | Q65: NR | R65: NR | S65: ILS | T65: 2.361 | U65: 31/12/2027 | V65: 0.045 | W65: 0.03339 | X65: החוב לא נחות | Y65: לא | Z65: 16000 | AA65: 1 | AB65: 108.49 | AD65: 17.358 | AG65: שווי הוגן | AH65: 1.6e-05 | AI65: 0.0047709198 | AJ65: 0.0019250381
A66: 337 | B66: 1405 | C66: ישראל קנדה (ט.ר) בעמ | D66: 520039298 | E66: ח.פ | F66: ישראל קנדה אגח ז | G66: IL0043402127 | H66: ISIN | I66: לא צמוד למדד המחירים לצרכן | J66: ישראל | K66: ישראל | L66: סחיר | M66: TASE | N66: בנייה | O66: לא | P66: A- | Q66: S&P מעלות | R66: נייר ערך | S66: ILS | T66: 1.457 | U66: 30/06/2027 | V66: 0.0395 | W66: 0.05565 | X66: החוב לא נחות | Y66: לא | Z66: 20300 | AA66: 1 | AB66: 97.85 | AD66: 19.864 | AG66: שווי הוגן | AH66: 3.5e-05 | AI66: 0.0054594551 | AJ66: 0.002202858
A67: 337 | B67: 1405 | C67: ישראמקו נגב 2 שותפות מוגבלת | D67: 550010003 | E67: מספר שותפות | F67: ישראמקו אגח ג | G67: IL0023202323 | H67: ISIN | I67: לא צמוד למדד המחירים לצרכן | J67: ישראל | K67: ישראל | L67: סחיר | M67: TASE | N67: חיפושי נפט וגז | O67: לא | P67: AA | Q67: S&P מעלות | R67: נייר ערך | S67: ILS | T67: 2.93 | U67: 10/10/2030 | V67: 0.0224 | W67: 0.04589 | X67: החוב לא נחות | Y67: לא | Z67: 47133.71 | AA67: 1 | AB67: 94.01 | AD67: 44.31 | AG67: שווי הוגן | AH67: 8.8e-05 | AI67: 0.012178621 | AJ67: 0.0049140018
A68: 337 | B68: 1405 | C68: ישרס חברה להשקעות בע"מ | D68: 520017807 | E68: ח.פ | F68: ישרס אגח טו | G68: IL0061302076 | H68: ISIN | I68: צמוד למדד המחירים לצרכן | J68: ישראל | K68: ישראל | L68: סחיר | M68: TASE | N68: נדל"ן מניב בישראל | O68: לא | P68: AA | Q68: S&P מעלות | R68: נייר ערך | S68: ILS | T68: 1.757 | U68: 16/05/2027 | V68: 0.0158 | W68: 0.02779 | X68: החוב לא נחות | Y68: לא | Z68: 0.26 | AA68: 1 | AB68: 116.04 | AD68: 0 | AG68: שווי הוגן | AH68: 0 | AI68: 8.2922712e-08 | AJ68: 3.3458826e-08
A69: 337 | B69: 1405 | C69: ישרס חברה להשקעות בע"מ | D69: 520017807 | E69: ח.פ | F69: ישרס אגח טז | G69: IL0061302233 | H69: ISIN | I69: צמוד למדד המחירים לצרכן | J69: ישראל | K69: ישראל | L69: סחיר | M69: TASE | N69: נדל"ן מניב בישראל | O69: לא | P69: AA- | Q69: S&P מעלות | R69: נייר ערך | S69: ILS | T69: 2.975 | U69: 30/07/2031 | V69: 0.024 | W69: 0.02959 | X69: החוב לא נחות | Y69: לא | Z69: 26447.37 | AA69: 1 | AB69: 117.41 | AD69: 31.052 | AG69: שווי הוגן | AH69: 2.2e-05 | AI69: 0.0085345378 | AJ69: 0.0034436358
A70: 337 | B70: 1405 | C70: ישרס חברה להשקעות בע"מ | D70: 520017807 | E70: ח.פ | F70: ישרס אגח יח | G70: IL0061302803 | H70: ISIN | I70: צמוד למדד המחירים לצרכן | J70: ישראל | K70: ישראל | L70: סחיר | M70: TASE | N70: נדל"ן מניב בישראל | O70: לא | P70: AA | Q70: S&P מעלות | R70: נייר ערך | S70: ILS | T70: 4.224 | U70: 10/04/2030 | V70: 0.0084 | W70: 0.02787 | X70: החוב לא נחות | Y70: לא | Z70: 20549.46 | AA70: 1 | AB70: 107.28 | AD70: 22.045 | AG70: שווי הוגן | AH70: 2.7e-05 | AI70: 0.0060591486 | AJ70: 0.0024448308
A71: 337 | B71: 1405 | C71: כלל החזקות עסקי ביטוח בע"מ | D71: 520036120 | E71: ח.פ | F71: כלל ביטוח אגח ג | G71: IL0012013913 | H71: ISIN | I71: לא צמוד למדד המחירים לצרכן | J71: ישראל | K71: ישראל | L71: סחיר | M71: TASE | N71: ביטוח | O71: לא | P71: AA- | Q71: S&P מעלות | R71: נייר ערך | S71: ILS | T71: 4.694 | U71: 02/11/2031 | V71: 0.0525 | W71: 0.04653 | X71: החוב לא נחות | Y71: לא | Z71: 15000 | AA71: 1 | AB71: 103.89 | AD71: 15.584 | AG71: שווי הוגן | AH71: 3e-05 | AI71: 0.0042830923 | AJ71: 0.0017282025
A72: 337 | B72: 1405 | C72: כללביט מימון בע"מ | D72: 513754069 | E72: ח.פ | F72: כלל הון אגח יד | G72: IL0012205246 | H72: ISIN | I72: לא צמוד למדד המחירים לצרכן | J72: ישראל | K72: ישראל | L72: סחיר | M72: TASE | N72: ביטוח | O72: לא | P72: AA- | Q72: S&P מעלות | R72: נייר ערך | S72: ILS | T72: 8.511 | U72: 30/09/2039 | V72: 0.0551 | W72: 0.05145 | X72: החוב לא נחות | Y72: לא | Z72: 17000 | AA72: 1 | AB72: 104.59 | AD72: 17.78 | AG72: שווי הוגן | AH72: 3.4e-05 | AI72: 0.0048868782 | AJ72: 0.0019718266
A73: 337 | B73: 1405 | C73: בנק לאומי לישראל בע"מ | D73: 520018078 | E73: ח.פ | F73: לאומי אגח 185 | G73: IL0012018219 | H73: ISIN | I73: צמוד למדד המחירים לצרכן | J73: ישראל | K73: ישראל | L73: סחיר | M73: TASE | N73: בנקים | O73: לא | P73: AAA | Q73: S&P מעלות | R73: נייר ערך | S73: ILS | T73: 2.092 | U73: 31/08/2029 | V73: 0.0186 | W73: 0.02568 | X73: החוב לא נחות | Y73: לא | Z73: 14400 | AA73: 1 | AB73: 104.2 | AD73: 15.005 | AG73: שווי הוגן | AH73: 5e-06 | AI73: 0.0041240378 | AJ73: 0.001664025
A74: 337 | B74: 1405 | C74: בנק לאומי לישראל בע"מ | D74: 520018078 | E74: ח.פ | F74: לאומי אגח 186 | G74: IL0012018391 | H74: ISIN | I74: צמוד למדד המחירים לצרכן | J74: ישראל | K74: ישראל | L74: סחיר | M74: TASE | N74: בנקים | O74: לא | P74: AAA | Q74: S&P מעלות | R74: נייר ערך | S74: ILS | T74: 4.388 | U74: 30/11/2033 | V74: 0.0202 | W74: 0.02636 | X74: החוב לא נחות | Y74: לא | Z74: 66000 | AA74: 1 | AB74: 102.52 | AD74: 67.663 | AG74: שווי הוגן | AH74: 1.8e-05 | AI74: 0.018597089 | AJ74: 0.0075038158
A75: 337 | B75: 1405 | C75: בנק לאומי לישראל בע"מ | D75: 520018078 | E75: ח.פ | F75: לאומי אגח סד 183 | G75: IL0060405474 | H75: ISIN | I75: צמוד למדד המחירים לצרכן | J75: ישראל | K75: ישראל | L75: סחיר | M75: TASE | N75: בנקים | O75: לא | P75: AAA | Q75: S&P מעלות | R75: נייר ערך | S75: ILS | T75: 4.392 | U75: 25/11/2029 | V75: 0.001 | W75: 0.02581 | X75: החוב לא נחות | Y75: לא | Z75: 79000 | AA75: 1 | AB75: 102.6 | AD75: 81.054 | AG75: שווי הוגן | AH75: 1.8e-05 | AI75: 0.022277522 | AJ75: 0.008988849
... A89: 337 | B89: 1405 | C89: מזרחי טפחות חברה להנפקות בע"מ | D89: 520032046 | E89: ח.פ | F89: מז טפ הנ אגח 67 | G89: IL0011968075 | H89: ISIN | I89: צמוד למדד המחירים לצרכן | J89: ישראל | K89: ישראל | L89: סחיר | M89: TASE | N89: בנקים | O89: לא | P89: AAA | Q89: S&P מעלות | R89: נייר ערך | S89: ILS | T89: 4.216 | U89: 12/06/2033 | V89: 0.0206 | W89: 0.0259 | X89: החוב לא נחות | Y89: לא | Z89: 80000 | AA89: 1 | AB89: 103.97 | AD89: 83.176 | AG89: שווי הוגן | AH89: 5e-05 | AI89: 0.022860749 | AJ89: 0.0092241777
A90: 337 | B90: 1405 | C90: מזרחי טפחות חברה להנפקות בע"מ | D90: 520032046 | E90: ח.פ | F90: מז טפ הנפק 52 | G90: IL0023103810 | H90: ISIN | I90: צמוד למדד המחירים לצרכן | J90: ישראל | K90: ישראל | L90: סחיר | M90: TASE | N90: בנקים | O90: לא | P90: AAA | Q90: S&P מעלות | R90: נייר ערך | S90: ILS | T90: 4.979 | U90: 01/07/2030 | V90: 0.002 | W90: 0.02616 | X90: החוב לא נחות | Y90: לא | Z90: 21000 | AA90: 1 | AB90: 104.05 | AC90: 0.049 | AD90: 21.9 | AG90: שווי הוגן | AH90: 6e-06 | AI90: 0.0060190894 | AJ90: 0.0024286671
A91: 337 | B91: 1405 | C91: מזרחי טפחות חברה להנפקות בע"מ | D91: 520032046 | E91: ח.פ | F91: מזרחי טפחות הנפק אגח 64 | G91: IL0023105559 | H91: ISIN | I91: צמוד למדד המחירים לצרכן | J91: ישראל | K91: ישראל | L91: סחיר | M91: TASE | N91: בנקים | O91: לא | P91: AAA | Q91: S&P מעלות | R91: נייר ערך | S91: ILS | T91: 3.203 | U91: 13/04/2031 | V91: 0.001 | W91: 0.02586 | X91: החוב לא נחות | Y91: לא | Z91: 42858.06 | AA91: 1 | AB91: 104.36 | AD91: 44.727 | AG91: שווי הוגן | AH91: 1.9e-05 | AI91: 0.012293032 | AJ91: 0.004960166
A92: 337 | B92: 1405 | C92: מימון ישיר מקבוצת ישיר 2006 בע"מ | D92: 513893123 | E92: ח.פ | F92: מימון ישיר אגח ה | G92: IL0011828311 | H92: ISIN | I92: צמוד למדד המחירים לצרכן | J92: ישראל | K92: ישראל | L92: סחיר | M92: TASE | N92: אשראי חוץ בנקאי | O92: לא | P92: A1 | Q92: מידרוג Moodys | R92: נייר ערך | S92: ILS | T92: 2.782 | U92: 31/07/2031 | V92: 0.01 | W92: 0.03107 | X92: החוב לא נחות | Y92: לא | Z92: 23828.88 | AA92: 1 | AB92: 108.19 | AD92: 25.78 | AG92: שווי הוגן | AH92: 1.3e-05 | AI92: 0.0070857068 | AJ92: 0.002859041
A93: 337 | B93: 1405 | C93: מימון ישיר מקבוצת ישיר 2006 בע"מ | D93: 513893123 | E93: ח.פ | F93: מימון ישיר אגח ו | G93: IL0011916595 | H93: ISIN | I93: צמוד למדד המחירים לצרכן | J93: ישראל | K93: ישראל | L93: סחיר | M93: TASE | N93: אשראי חוץ בנקאי | O93: לא | P93: A1 | Q93: מידרוג Moodys | R93: נייר ערך | S93: ILS | T93: 1.056 | U93: 31/03/2027 | V93: 0.0354 | W93: 0.03425 | X93: החוב לא נחות | Y93: לא | Z93: 20700 | AA93: 1 | AB93: 109.8 | AD93: 22.729 | AG93: שווי הוגן | AH93: 2.1e-05 | AI93: 0.006246908 | AJ93: 0.0025205906
A94: 337 | B94: 1405 | C94: מימון ישיר מקבוצת ישיר 2006 בע"מ | D94: 513893123 | E94: ח.פ | F94: מימון ישיר ד | G94: IL0011756603 | H94: ISIN | I94: צמוד למדד המחירים לצרכן | J94: ישראל | K94: ישראל | L94: סחיר | M94: TASE | N94: אשראי חוץ בנקאי | O94: לא | P94: A1 | Q94: מידרוג Moodys | R94: נייר ערך | S94: ILS | T94: 0.179 | U94: 01/02/2026 | V94: 0.01 | W94: 0.03569 | X94: החוב לא נחות | Y94: לא | Z94: 16800 | AA94: 1 | AB94: 115.84 | AD94: 19.461 | AG94: שווי הוגן | AH94: 9.9e-05 | AI94: 0.005348848 | AJ94: 0.0021582287
A95: 337 | B95: 1405 | C95: מליסרון בע"מ | D95: 520037789 | E95: ח.פ | F95: מליסרון אגח יט | G95: IL0032303989 | H95: ISIN | I95: צמוד למדד המחירים לצרכן | J95: ישראל | K95: ישראל | L95: סחיר | M95: TASE | N95: נדל"ן מניב בישראל | O95: לא | P95: AA | Q95: S&P מעלות | R95: נייר ערך | S95: ILS | T95: 3.744 | U95: 01/07/2029 | V95: 0.0143 | W95: 0.0281 | X95: החוב לא נחות | Y95: לא | Z95: 66172 | AA95: 1 | AB95: 111.28 | AC95: 1.42 | AD95: 75.057 | AG95: שווי הוגן | AH95: 3.4e-05 | AI95: 0.020629152 | AJ95: 0.0083237415
A96: 337 | B96: 1405 | C96: מליסרון בע"מ | D96: 520037789 | E96: ח.פ | F96: מליסרון אגח כא | G96: IL0011946386 | H96: ISIN | I96: צמוד למדד המחירים לצרכן | J96: ישראל | K96: ישראל | L96: סחיר | M96: TASE | N96: נדל"ן מניב בישראל | O96: לא | P96: AA | Q96: S&P מעלות | R96: נייר ערך | S96: ILS | T96: 5.598 | U96: 01/01/2037 | V96: 0.0361 | W96: 0.02928 | X96: החוב לא נחות | Y96: לא | Z96: 20892.86 | AA96: 1 | AB96: 111.6 | AC96: 0.464 | AD96: 23.78 | AG96: שווי הוגן | AH96: 1.3e-05 | AI96: 0.0065358891 | AJ96: 0.0026371928
A97: 337 | B97: 1405 | C97: מליסרון בע"מ | D97: 520037789 | E97: ח.פ | F97: מליסרון אגח יז | G97: IL0032302734 | H97: ISIN | I97: צמוד למדד המחירים לצרכן | J97: ישראל | K97: ישראל | L97: סחיר | M97: TASE | N97: נדל"ן מניב בישראל | O97: לא | P97: AA | Q97: S&P מעלות | R97: נייר ערך | S97: ILS | T97: 3.33 | U97: 01/01/2032 | V97: 0.0225 | W97: 0.02861 | X97: החוב לא נחות | Y97: לא | Z97: 18870.72 | AA97: 1 | AB97: 116.27 | AC97: 0.6 | AD97: 22.541 | AG97: שווי הוגן | AH97: 1.1e-05 | AI97: 0.0061952823 | AJ97: 0.0024997599
A98: 337 | B98: 1405 | C98: מליסרון בע"מ | D98: 520037789 | E98: ח.פ | F98: מליסרון אגח כ | G98: IL0032304227 | H98: ISIN | I98: צמוד למדד המחירים לצרכן | J98: ישראל | K98: ישראל | L98: סחיר | M98: TASE | N98: נדל"ן מניב בישראל | O98: לא | P98: AA | Q98: S&P מעלות | R98: נייר ערך | S98: ILS | T98: 4.692 | U98: 01/07/2030 | V98: 0.0025 | W98: 0.02702 | X98: החוב לא נחות | Y98: לא | Z98: 42140 | AA98: 1 | AB98: 102.52 | AC98: 0.624 | AD98: 43.826 | AG98: שווי הוגן | AH98: 3.2e-05 | AI98: 0.012045462 | AJ98: 0.0048602729
A99: 337 | B99: 1405 | C99: מנורה מבטחים גיוס הון בע"מ | D99: 513937714 | E99: ח.פ | F99: מנורה הון התח סד' ט | G99: IL0012193699 | H99: ISIN | I99: לא צמוד למדד המחירים לצרכן | J99: ישראל | K99: ישראל | L99: סחיר | M99: TASE | N99: ביטוח | O99: לא | P99: Aa3 | Q99: מידרוג Moodys | R99: נייר ערך | S99: ILS | T99: 6.099 | U99: 30/09/2035 | V99: 0.0502 | W99: 0.04789 | X99: החוב לא נחות | Y99: לא | Z99: 16000 | AA99: 1 | AB99: 103.09 | AD99: 16.494 | AG99: שווי הוגן | AH99: 4e-05 | AI99: 0.0045334512 | AJ99: 0.0018292209
...

Sheet מניות מבכ ויהש
A1: מספר קופה/קרן/ח.פ. עבור חברת ביטוח | B1: מספר מסלול | C1: שם מנפיק | D1: מספר מנפיק | E1: סוג מספר מזהה מנפיק | F1: שם נייר ערך | G1: מספר נייר ערך | H1: סוג מספר נייר ערך | I1: מאפיין עיקרי | J1: ישראל/חו"ל | K1: מדינה לפי חשיפה כלכלית | L1: סטאטוס סחירות | M1: זירת מסחר | N1: ענף מסחר | O1: בעל עניין/צד קשור | P1: מטבע פעילות | Q1: ערך נקוב (יחידות) | R1: שער חליפין | S1: שער נייר הערך | T1: סכום לקבל (במטבע הפעילות) | U1: שווי הוגן (באלפי ש"ח) | V1: שיעור מערך נקוב מונפק | W1: שיעור מנכסי אפיק ההשקעה | X1: שיעור מסך נכסי ההשקעה
A2: 337 | B2: 1477 | C2: או.פי.סי. אנרגיה בע"מ | D2: 514401702 | E2: ח.פ | F2: או פי סי אנרגיה | G2: IL0011415713 | H2: ISIN | I2: מניות | J2: ישראל | K2: ישראל | L2: סחיר | M2: TASE | N2: אנרגיה | O2: לא | P2: ILS | Q2: 2712 | R2: 1 | S2: 4100 | U2: 111.192 | V2: 1e-05 | W2: 0.01466742 | X2: 0.0063998267
A3: 337 | B3: 1477 | C3: אורמת טכנולגיות אינק | D3: 5493000TSHHWY24VHM09 | E3: LEI | F3: אורמת טכנולוגיות | G3: US6866881021 | H3: ISIN | I3: מניות | J3: ישראל | K3: ארה"ב | L3: סחיר | M3: TASE | N3: אנרגיה מתחדשת | O3: לא | P3: ILS | Q3: 425 | R3: 1 | S3: 27780 | U3: 118.065 | V3: 7e-06 | W3: 0.015574043 | X3: 0.0067954127
A4: 337 | B4: 1477 | C4: אזורים-חברה להשקעות בפתוח ובבנין בע"מ | D4: 520025990 | E4: ח.פ | F4: אזורים | G4: IL0007150118 | H4: ISIN | I4: מניות | J4: ישראל | K4: ישראל | L4: סחיר | M4: TASE | N4: בנייה | O4: לא | P4: ILS | Q4: 366 | R4: 1 | S4: 2366 | U4: 8.66 | V4: 2e-06 | W4: 0.0011422891 | X4: 0.0004984143
A5: 337 | B5: 1477 | C5: איי.סי.אל גרופ בע"מ (דואלי) | D5: 520027830 | E5: ח.פ | F5: איי.סי.אל | G5: IL0002810146 | H5: ISIN | I5: מניות | J5: ישראל | K5: ישראל | L5: סחיר | M5: TASE | N5: כימיה, גומי ופלסטיק | O5: לא | P5: ILS | Q5: 6841 | R5: 1 | S5: 2309 | U5: 157.959 | V5: 5e-06 | W5: 0.02083645 | X5: 0.0090915555
A6: 337 | B6: 1477 | C6: אינרום תעשיות בנייה בע"מ | D6: 515001659 | E6: ח.פ | F6: אינרום | G6: IL0011323560 | H6: ISIN | I6: מניות | J6: ישראל | K6: ישראל | L6: סחיר | M6: TASE | N6: מתכת ומוצרי בניה | O6: לא | P6: ILS | Q6: 1000 | R6: 1 | S6: 2100 | U6: 21 | V6: 7e-06 | W6: 0.0027701258 | X6: 0.0012086873
A7: 337 | B7: 1477 | C7: איסתא בע"מ | D7: 520042763 | E7: ח.פ | F7: איסתא | G7: IL0010810740 | H7: ISIN | I7: מניות | J7: ישראל | K7: ישראל | L7: סחיר | M7: TASE | N7: מלונאות ותיירות | O7: לא | P7: ILS | Q7: 113 | R7: 1 | S7: 10930 | U7: 12.351 | V7: 6e-06 | W7: 0.0016292165 | X7: 0.00071087505
A8: 337 | B8: 1477 | C8: אלביט מערכות בע"מ | D8: 520043027 | E8: ח.פ | F8: אלביט מערכות | G8: IL0010811243 | H8: ISIN | I8: מניות | J8: ישראל | K8: ישראל | L8: סחיר | M8: TASE | N8: ביטחוניות | O8: לא | P8: ILS | Q8: 194 | R8: 1 | S8: 149800 | T8: 0.41 | U8: 291.022 | V8: 4e-06 | W8: 0.038388972 | X8: 0.016750237
A9: 337 | B9: 1477 | C9: אלוני-חץ נכסים והשקעות בע"מ | D9: 520038506 | E9: ח.פ | F9: אלוני חץ | G9: IL0003900136 | H9: ISIN | I9: מניות | J9: ישראל | K9: ישראל | L9: סחיר | M9: TASE | N9: נדל"ן מניב בישראל | O9: לא | P9: ILS | Q9: 1419 | R9: 1 | S9: 3489 | U9: 49.509 | V9: 7e-06 | W9: 0.0065307576 | X9: 0.0028495615
A10: 337 | B10: 1477 | C10: אלקטרה נדל"ן בע"מ | D10: 510607328 | E10: ח.פ | F10: אלקטרה נדלן | G10: IL0010940448 | H10: ISIN | I10: מניות | J10: ישראל | K10: ישראל | L10: סחיר | M10: TASE | N10: נדל"ן מניב בחו"ל | O10: לא | P10: ILS | Q10: 830 | R10: 1 | S10: 5007 | U10: 41.558 | V10: 1.3e-05 | W10: 0.0054819603 | X10: 0.0023919404
A11: 337 | B11: 1477 | C11: אמות השקעות בע"מ | D11: 520026683 | E11: ח.פ | F11: אמות | G11: IL0010972789 | H11: ISIN | I11: מניות | J11: ישראל | K11: ישראל | L11: סחיר | M11: TASE | N11: נדל"ן מניב בישראל | O11: לא | P11: ILS | Q11: 1801 | R11: 1 | S11: 2281 | U11: 41.081 | V11: 4e-06 | W11: 0.0054190006 | X11: 0.0023644692
A12: 337 | B12: 1477 | C12: אנלייט אנרגיה מתחדשת בע"מ | D12: 520041146 | E12: ח.פ | F12: אנלייט אנרגיה | G12: IL0007200111 | H12: ISIN | I12: מניות | J12: ישראל | K12: ארה"ב | L12: סחיר | M12: TASE | N12: אנרגיה מתחדשת | O12: לא | P12: ILS | Q12: 1959.3 | R12: 1 | S12: 7640 | U12: 149.691 | V12: 1.6e-05 | W12: 0.019745789 | X12: 0.0086156682
A13: 337 | B13: 1477 | C13: Energean plc | D13: 98450044QACBL3F8EB03 | E13: LEI | F13: אנרג'יאן | G13: GB00BG12Y042 | H13: ISIN | I13: מניות | J13: ישראל | K13: בריטניה | L13: סחיר | M13: TASE | N13: חיפושי נפט וגז | O13: לא | P13: ILS | Q13: 2500 | R13: 1 | S13: 4272 | T13: 2.529 | U13: 109.329 | V13: 1.4e-05 | W13: 0.014421671 | X13: 0.0062925988
A14: 337 | B14: 1477 | C14: אנרג'יקס אנרגיות מתחדשות בע"מ | D14: 513901371 | E14: ח.פ | F14: אנרג'יקס | G14: IL0011233553 | H14: ISIN | I14: מניות | J14: ישראל | K14: ישראל | L14: סחיר | M14: TASE | N14: אנרגיה מתחדשת | O14: לא | P14: ILS | Q14: 1846 | R14: 1 | S14: 1244 | U14: 22.964 | V14: 3e-06 | W14: 0.0030292302 | X14: 0.0013217422
A15: 337 | B15: 1477 | C15: אפריקה ישראל מגורים בע"מ | D15: 520034760 | E15: ח.פ | F15: אפריקה מגורים | G15: IL0010979487 | H15: ISIN | I15: מניות | J15: ישראל | K15: ישראל | L15: סחיר | M15: TASE | N15: בנייה | O15: לא | P15: ILS | Q15: 43 | R15: 1 | S15: 30100 | U15: 12.943 | V15: 3e-06 | W15: 0.0017073209 | X15: 0.00074495428
A16: 337 | B16: 1477 | C16: ארגו פרופרטיז אן. וי | D16: 70252750 | E16: מספר תאגיד או שותפות בחו"ל | F16: ארגו פרופרטיז אן. וי | G16: NL0015000D84 | H16: ISIN | I16: מניות | J16: ישראל | K16: גרמניה | L16: סחיר | M16: TASE | N16: נדל"ן מניב בחו"ל | O16: לא | P16: ILS | Q16: 695 | R16: 1 | S16: 12250 | U16: 85.138 | V16: 3.2e-05 | W16: 0.011230552 | X16: 0.0049002198
A17: 337 | B17: 1477 | C17: קבוצת אשטרום | D17: 510381601 | E17: ח.פ | F17: אשטרום קבוצה | G17: IL0011323156 | H17: ISIN | I17: מניות | J17: ישראל | K17: ישראל | L17: סחיר | M17: TASE | N17: בנייה | O17: לא | P17: ILS | Q17: 1600 | R17: 1 | S17: 7670 | U17: 122.72 | V17: 1.4e-05 | W17: 0.016188088 | X17: 0.0070633384
A18: 337 | B18: 1477 | C18: בזק החברה הישראלית לתקשורת בע"מ | D18: 520031931 | E18: ח.פ | F18: בזק | G18: IL0002300114 | H18: ISIN | I18: מניות | J18: ישראל | K18: ישראל | L18: סחיר | M18: TASE | N18: תקשורת ומדיה | O18: לא | P18: ILS | Q18: 25108 | R18: 1 | S18: 575 | U18: 144.371 | V18: 9e-06 | W18: 0.019044087 | X18: 0.0083094951
A19: 337 | B19: 1477 | C19: ביג מרכזי קניות (2004) בע"מ | D19: 513623314 | E19: ח.פ | F19: ביג | G19: IL0010972607 | H19: ISIN | I19: מניות | J19: ישראל | K19: ישראל | L19: סחיר | M19: TASE | N19: נדל"ן מניב בישראל | O19: לא | P19: ILS | Q19: 307 | R19: 1 | S19: 64490 | U19: 197.984 | V19: 1.2e-05 | W19: 0.026116258 | X19: 0.011395291
A20: 337 | B20: 1477 | C20: הבנק הבינלאומי הראשון לישראל בע"מ | D20: 520029083 | E20: ח.פ | F20: בינלאומי 5 | G20: IL0005930388 | H20: ISIN | I20: מניות | J20: ישראל | K20: ישראל | L20: סחיר | M20: TASE | N20: בנקים | O20: לא | P20: ILS | Q20: 545 | R20: 1 | S20: 24370 | U20: 132.816 | V20: 5e-06 | W20: 0.017519924 | X20: 0.007644458
A21: 337 | B21: 1477 | C21: בית בכפר בע"מ | D21: 511605719 | E21: ח.פ | F21: בית בכפר | G21: IL0011836561 | H21: ISIN | I21: מניות | J21: ישראל | K21: ישראל | L21: סחיר | M21: TASE | N21: נדל"ן מניב בישראל | O21: לא | P21: ILS | Q21: 542 | R21: 1 | S21: 1506 | U21: 8.163 | V21: 8e-06 | W21: 0.0010767242 | X21: 0.0004698064
A22: 337 | B22: 1477 | C22: מנועי בית שמש אחזקות (1997) בע"מ | D22: 520043480 | E22: ח.פ | F22: בית שמש | G22: IL0010815616 | H22: ISIN | I22: מניות | J22: ישראל | K22: ישראל | L22: סחיר | M22: TASE | N22: מתכת ומוצרי בניה | O22: לא | P22: ILS | Q22: 206 | R22: 1 | S22: 56070 | U22: 115.504 | V22: 2.3e-05 | W22: 0.015236246 | X22: 0.006648022
A23: 337 | B23: 1477 | C23: חברת גב-ים לקרקעות בע"מ | D23: 520001736 | E23: ח.פ | F23: גב ים | G23: IL0007590198 | H23: ISIN | I23: מניות | J23: ישראל | K23: ישראל | L23: סחיר | M23: TASE | N23: נדל"ן מניב בישראל | O23: לא | P23: ILS | Q23: 348 | R23: 1 | S23: 3685 | U23: 12.824 | V23: 2e-06 | W23: 0.0016915971 | X23: 0.00073809354
A24: 337 | B24: 1477 | C24: קבוצת דוראל משאבי אנרגיה מתחדשת בעמ | D24: 515364891 | E24: ח.פ | F24: דוראל אנרגיה | G24: IL0011667685 | H24: ISIN | I24: מניות | J24: ישראל | K24: ישראל | L24: סחיר | M24: TASE | N24: אנרגיה מתחדשת | O24: לא | P24: ILS | Q24: 1391 | R24: 1 | S24: 1532 | U24: 21.31 | V24: 8e-06 | W24: 0.002811034 | X24: 0.0012265367
A25: 337 | B25: 1477 | C25: בנק דיסקונט לישראל בע"מ | D25: 520007030 | E25: ח.פ | F25: דיסקונט | G25: IL0006912120 | H25: ISIN | I25: מניות | J25: ישראל | K25: ישראל | L25: סחיר | M25: TASE | N25: בנקים | O25: לא | P25: ILS | Q25: 4067 | R25: 1 | S25: 3356 | U25: 136.489 | V25: 3e-06 | W25: 0.018004303 | X25: 0.0078558068
... A29: 337 | B29: 1477 | C29: הבורסה לניירות ערך בתל-אביב בע"מ | D29: 520020033 | E29: ח.פ | F29: הבורסה לניע בתא | G29: IL0011590291 | H29: ISIN | I29: מניות | J29: ישראל | K29: ישראל | L29: סחיר | M29: TASE | N29: שירותים פיננסיים | O29: לא | P29: ILS | Q29: 485 | R29: 1 | S29: 6510 | U29: 31.573 | V29: 5e-06 | W29: 0.0041648842 | X29: 0.0018172614
A30: 337 | B30: 1477 | C30: הולמס פלייס אינטרנשיונל בע"מ | D30: 512466723 | E30: ח.פ | F30: הולמס פלייס | G30: IL0011425878 | H30: ISIN | I30: מניות | J30: ישראל | K30: ישראל | L30: סחיר | M30: TASE | N30: שירותים | O30: לא | P30: ILS | Q30: 15506 | R30: 1 | S30: 732.6 | T30: 1.858 | U30: 115.455 | V30: 0.000169 | W30: 0.015229779 | X30: 0.0066452003
A31: 337 | B31: 1477 | C31: חברת הכשרת הישוב בישראל- אנרגיה בע"מ | D31: 514423474 | E31: ח.פ | F31: הכשרה התפתחות עירונית | G31: IL0011214744 | H31: ISIN | I31: מניות | J31: ישראל | K31: ישראל | L31: סחיר | M31: TASE | N31: בנייה | O31: לא | P31: ILS | Q31: 5000 | R31: 1 | S31: 711.9 | U31: 35.595 | V31: 5.7e-05 | W31: 0.0046953632 | X31: 0.002048725
A32: 337 | B32: 1477 | C32: הפניקס אחזקות בע"מ | D32: 520017450 | E32: ח.פ | F32: הפניקס | G32: IL0007670123 | H32: ISIN | I32: מניות | J32: ישראל | K32: ישראל | L32: סחיר | M32: TASE | N32: ביטוח | O32: לא | P32: ILS | Q32: 2057 | R32: 1 | S32: 9745 | U32: 200.455 | V32: 8e-06 | W32: 0.026442124 | X32: 0.011537476
A33: 337 | B33: 1477 | C33: הראל השקעות בביטוח ושרותים פיננסים בע"מ | D33: 520033986 | E33: ח.פ | F33: הראל השקעות | G33: IL0005850180 | H33: ISIN | I33: מניות | J33: ישראל | K33: ישראל | L33: סחיר | M33: TASE | N33: ביטוח | O33: לא | P33: ILS | Q33: 2376 | R33: 1 | S33: 9432 | U33: 224.104 | V33: 1.1e-05 | W33: 0.02956177 | X33: 0.012898669
A34: 337 | B34: 1477 | C34: וואן טכנולוגיות תוכנה(או.אס.טי)בע"מ | D34: 520034695 | E34: ח.פ | F34: וואן טכנולוגיות תוכנה | G34: IL0001610182 | H34: ISIN | I34: מניות | J34: ישראל | K34: ישראל | L34: סחיר | M34: TASE | N34: שירותי מידע | O34: לא | P34: ILS | Q34: 794 | R34: 1 | S34: 8680 | U34: 68.919 | V34: 1.1e-05 | W34: 0.0090911836 | X34: 0.0039667506
A35: 337 | B35: 1477 | C35: קבוצת חג'ג' ייזום נדל"ן בע"מ | D35: 520033309 | E35: ח.פ | F35: חג'ג' נדלן | G35: IL0008230133 | H35: ISIN | I35: מניות | J35: ישראל | K35: ישראל | L35: סחיר | M35: TASE | N35: בנייה | O35: לא | P35: ILS | Q35: 1589 | R35: 1 | S35: 2063 | U35: 32.781 | V35: 2.6e-05 | W35: 0.0043241756 | X35: 0.0018867649
A36: 337 | B36: 1477 | C36: חילן בע"מ | D36: 520039942 | E36: ח.פ | F36: חילן | G36: IL0010846983 | H36: ISIN | I36: מניות | J36: ישראל | K36: ישראל | L36: סחיר | M36: TASE | N36: שירותי מידע | O36: לא | P36: ILS | Q36: 87 | R36: 1 | S36: 28610 | U36: 24.891 | V36: 4e-06 | W36: 0.003283351 | X36: 0.0014326225
A37: 337 | B37: 1477 | C37: קבוצת חמת בע"מ | D37: 520038530 | E37: ח.פ | F37: חמת | G37: IL0003840167 | H37: ISIN | I37: מניות | J37: ישראל | K37: ישראל | L37: סחיר | M37: TASE | N37: מתכת ומוצרי בניה | O37: לא | P37: ILS | Q37: 462 | R37: 1 | S37: 1866 | T37: 0.189 | U37: 8.81 | V37: 1.3e-05 | W37: 0.001162139 | X37: 0.00050707541
A38: 337 | B38: 1477 | C38: טאואר סמיקונדקטור בע"מ | D38: 520041997 | E38: ח.פ | F38: טאואר | G38: IL0010823792 | H38: ISIN | I38: מניות | J38: ישראל | K38: גלובלי | L38: סחיר | M38: TASE | N38: מוליכים למחצה | O38: לא | P38: ILS | Q38: 292 | R38: 1 | S38: 14620 | U38: 42.69 | V38: 3e-06 | W38: 0.0056313228 | X38: 0.0024571117
A39: 337 | B39: 1477 | C39: טבע תעשיות פרמצבטיות בע"מ | D39: 520013954 | E39: ח.פ | F39: טבע | G39: IL0006290147 | H39: ISIN | I39: מניות | J39: ישראל | K39: ארה"ב | L39: סחיר | M39: TASE | N39: פארמה | O39: לא | P39: ILS | Q39: 7385 | R39: 1 | S39: 5699 | U39: 420.871 | V39: 6e-06 | W39: 0.05551743 | X39: 0.024223887
A40: 337 | B40: 1477 | C40: טיב טעם הולדינגס 1 בע"מ | D40: 520041187 | E40: ח.פ | F40: טיב טעם | G40: IL0001030100 | H40: ISIN | I40: מניות | J40: ישראל | K40: ישראל | L40: סחיר | M40: TASE | N40: רשתות שיווק | O40: לא | P40: ILS | Q40: 4200 | R40: 1 | S40: 810 | U40: 34.02 | V40: 3.9e-05 | W40: 0.0044876038 | X40: 0.0019580734
A41: 337 | B41: 1477 | C41: ישראמקו נגב 2 שותפות מוגבלת | D41: 550010003 | E41: מספר שותפות | F41: ישראמקו יהש | G41: IL0002320179 | H41: ISIN | I41: מניות | J41: ישראל | K41: ישראל | L41: סחיר | M41: TASE | N41: חיפושי נפט וגז | O41: לא | P41: ILS | Q41: 6100 | R41: 1 | S41: 229.9 | U41: 14.024 | V41: 2e-06 | W41: 0.0018499032 | X41: 0.00080716714
A42: 337 | B42: 1477 | C42: ישרוטל בע"מ | D42: 520042482 | E42: ח.פ | F42: ישרוטל | G42: IL0010809858 | H42: ISIN | I42: מניות | J42: ישראל | K42: ישראל | L42: סחיר | M42: TASE | N42: מלונאות ותיירות | O42: לא | P42: ILS | Q42: 65 | R42: 1 | S42: 9500 | U42: 6.175 | V42: 1e-06 | W42: 0.0008145489 | X42: 0.00035541163
A43: 337 | B43: 1477 | C43: כלל החזקות עסקי ביטוח בע"מ | D43: 520036120 | E43: ח.פ | F43: כלל ביטוח | G43: IL0002240146 | H43: ISIN | I43: מניות | J43: ישראל | K43: ישראל | L43: סחיר | M43: TASE | N43: ביטוח | O43: לא | P43: ILS | Q43: 2074 | R43: 1 | S43: 14880 | U43: 308.611 | V43: 2.6e-05 | W43: 0.040709136 | X43: 0.017762592
...

Sheet קרנות סל
A1: מספר קופה/קרן/ח.פ. עבור חברת ביטוח | B1: מספר מסלול | C1: שם מנפיק | D1: מספר מנפיק | E1: סוג מספר מזהה מנפיק | F1: שם נייר ערך | G1: מספר נייר ערך | H1: סוג מספר נייר ערך | I1: מאפיין עיקרי | J1: ישראל/חו"ל | K1: מדינה לפי חשיפה כלכלית | L1: זירת מסחר | M1: סיווג הקרן | N1: בעל עניין/צד קשור | O1: מטבע פעילות | P1: ערך נקוב (יחידות) | Q1: שער חליפין | R1: שער נייר הערך | S1: סכום לקבל (במטבע הפעילות) | T1: שווי הוגן (באלפי ש"ח) | U1: שיעור מערך נקוב מונפק | V1: שיעור מנכסי אפיק ההשקעה | W1: שיעור מסך נכסי ההשקעה
A2: 337 | B2: 1405 | C2: מגדל קרנות נאמנות בע"מ | D2: 511303661 | E2: ח.פ | F2: MTF.תלבונדשקלי | G2: IL0011500027 | H2: ISIN | I2: עוקב אחר מדדים אחרים בישראל | J2: ישראל | K2: ישראל | L2: TASE | M2: אג"ח בישראל - חברות והמרה | N2: לא | O2: ILS | P2: 12757 | Q2: 1 | R2: 482.69 | T2: 61.577 | U2: 5.2e-05 | V2: 0.10101415 | W2: 0.0068286674
A3: 337 | B3: 1405 | C3: קסם קרנות נאמנות בע"מ | D3: 510938608 | E3: ח.פ | F3: קסם תל בונד שקלי | G3: IL0011464141 | H3: ISIN | I3: עוקב אחר מדדים אחרים בישראל | J3: ישראל | K3: ישראל | L3: TASE | M3: אג"ח בישראל - חברות והמרה | N3: לא | O3: ILS | P3: 10345 | Q3: 1 | R3: 4144.02 | T3: 428.699 | U3: 0.000192 | V3: 0.70326286 | W3: 0.047541342
