Workbook
Name Additional_Factor: 'אפשרויות בחירה'!$C$701:$C$850
Name Amoritization: 'אפשרויות בחירה'!$C$546:$C$550
Name Capsule: 'אפשרויות בחירה'!$C$926:$C$928
Name Company_Name: 'File Name Info'!$A$34:$A$120
Name Company_Name_ID: 'File Name Info'!$A$34:$B$120
Name Consortium: 'אפשרויות בחירה'!$C$514:$C$515
Name Country_list: 'אפשרויות בחירה'!$C$4:$C$85
Name Country_list_funds: 'אפשרויות בחירה'!$C$4:$C$103
Name CSA: 'אפשרויות בחירה'!$C$688:$C$689
Name Delivery: 'אפשרויות בחירה'!$C$666:$C$667
Name Dependence_Independence: 'אפשרויות בחירה'!$C$654:$C$655
Name Duration_Underlying_Interest_Rate: 'אפשרויות בחירה'!$C$680:$C$687
Name File_Type: 'File Name Info'!$A$10:$A$12
Name Full_File_Type: 'File Name Info'!$A$11:$B$13
Name Full_Type: 'File Name Info'!$A$2:$B$8
Name Full_Type_Nostro: 'File Name Info'!$A$3:$B$6
Name Full_Year: 'File Name Info'!$A$22:$B$31
Name Fund_Strategy: 'אפשרויות בחירה'!$C$597:$C$621
Name Fund_type: 'אפשרויות בחירה'!$C$328:$C$498
Name Holding_interest: 'אפשרויות בחירה'!$C$146:$C$147
Name In_the_books: 'אפשרויות בחירה'!$C$656:$C$657
Name Industry_Sector: 'אפשרויות בחירה'!$C$1129:$C$1245
Name Industry_sector_all: 'אפשרויות בחירה'!$C$202:$C$327
Name Industry_sectors: 'אפשרויות בחירה'!$C$202:$C$327
Name israel_abroad: 'אפשרויות בחירה'!$C$2:$C$3
Name Issuer_Number_Banks: 'אפשרויות בחירה'!$C$111:$C$113
Name Issuer_Number_Fund: 'אפשרויות בחירה'!$C$114:$C$117
Name issuer_number_loan: 'אפשרויות בחירה'!$C$118:$C$126
Name Issuer_Number_Type: 'אפשרויות בחירה'!$C$104:$C$110
Name Issuer_Number_Type_2: 'אפשרויות בחירה'!$C$1076:$C$1079
Name Issuer_Number_Type_3: 'אפשרויות בחירה'!$C$1081:$C$1085
Name Issuer_Number_Type_V2: 'אפשרויות בחירה'!$C$104:$C$110
Name Issuer_Type_TFunds: 'אפשרויות בחירה'!$C$1087:$C$1089
Name Leading_factor: 'אפשרויות בחירה'!$C$692:$C$700
Name Linked_Type: 'אפשרויות בחירה'!$C$516:$C$519
Name other_investments: 'אפשרויות בחירה'!$C$1000:$C$1033
Name Penalty: 'אפשרויות בחירה'!$C$851:$C$852
Name QTR: 'File Name Info'!$A$15:$A$19
Name Rating_Agency: 'אפשרויות בחירה'!$C$188:$C$201
Name real_estate_lifestage: 'אפשרויות בחירה'!$C$634:$C$642
Name real_estate_loans: 'אפשרויות בחירה'!$C$553:$C$591
Name Real_Estate_Main_Use: 'אפשרויות בחירה'!$C$622:$C$633
Name Recourse_Nonrecourse: 'אפשרויות בחירה'!$C$544:$C$545
Name Repayment_Rights: 'אפשרויות בחירה'!$C$551:$C$552
Name Reset_frequency: 'אפשרויות בחירה'!$C$658:$C$665
Name Security_ID_Number_Type: 'אפשרויות בחירה'!$C$1113:$C$1116
Name Security_Number_Loans: 'אפשרויות בחירה'!$C$131
Name Stock_Exchange: 'אפשרויות בחירה'!$C$1283:$C$1315
Name Stock_Exchange_Gov_Bonds: 'אפשרויות בחירה'!$C$148:$C$181
Name Subordination_Risk: 'אפשרויות בחירה'!$C$186:$C$187
Name Tradeable_Status: 'אפשרויות בחירה'!$C$1272:$C$1281
Name Tradeable_Status_All: 'אפשרויות בחירה'!$C$135:$C$145
Name tradeable_status_bonds: 'אפשרויות בחירה'!$C$1248:$C$1253
Name tradeable_status_funds: 'אפשרויות בחירה'!$C$1118:$C$1119
Name tradeable_status_stock: 'אפשרויות בחירה'!$C$1255:$C$1259
Name Tradeable_Status_v2: 'אפשרויות בחירה'!$C$1121:$C$1126
Name tradeable_status_warrants: 'אפשרויות בחירה'!$C$1261:$C$1265
Name tradeable_status_warrants_v2: 'אפשרויות בחירה'!$C$1267:$C$1269
Name Transaction: 'אפשרויות בחירה'!$C$643:$C$646
Name Type: 'File Name Info'!$A$2:$A$8

Sheet עמוד פתיחה
A1: קובץ דיווח עבור רשימת נכסים ברמת הנכס הבודד (חוזר גופים מוסדיים 2015-9-14)
A3: יש לבחור תחום: | D3: נכסי עמיתים - קופות גמל
A5: האם מדובר בקובץ לממומנה או לציבור:
A7: יש לבחור את רבעון הדיווח:
A9: יש לבחור את שנת הדיווח:
A11: יש לבחור את הגוף המוסדי:
A13: ח.פ. הגוף המוסדי: | D13: =IFERROR(VLOOKUP(D11,'File Name Info'!A35:B121,2,0),"תא מחושב") -> תא מחושב
A15: שם קובץ לשמירה | D15: =IF(D5="לממונה",CONCATENATE(D13, "_",VLOOKUP(D3,Full_Type,2,0),"_",D7,VLOOKUP(D9,Full_Year,2,0),".xlxs"),IF(D5="לציבור",CONCATENATE(D13,"_",VLOOKUP(D3,Full_Type_Nostro,2,0),"_",VLOOKUP(D5,Full_File_Type,2,0),"_",D7,VLOOKUP(D9,Full_Year,2,0),".xlsx"),"שם קובץ לשמירה")) -> שם קובץ לשמירה
A17: פרטי האחראי על הדיווח בגוף המוסדי | B17: שם:
B19: מספר טלפון:
B21: כתובת מייל:
A23: הוראות למילוי הדיווח: | D23: יש לדווח לפי ההנחיות בחלק ג' לנספח 5.4.3.2 שבפרק 3 שבחלק 4 לשער 5 בחוזר המאוחד - "רשימת נכסים ברמת הנכס הבודד".

Sheet סכום נכסים
C1: ידווח בקבצי נכסי הנוסטרו בלבד
B2: שווי הוגן | C2: עלות מופחתת | D2: השיטה שיושמה בדוח הכספי | E2: שיעור מסך נכסי השקעה
A3: מזומנים ושווי מזומנים | B3: =SUM('מזומנים ושווי מזומנים'!O:O) -> 56141.256 | D3: =B3+C3 -> 56141.256 | E3: =SUM('מזומנים ושווי מזומנים'!O:O)/B30 -> 0.018831201
A4: איגרות חוב ממשלתיות | B4: =SUM('איגרות חוב ממשלתיות'!U:U) -> 377040.49 | D4: =B4+C4 -> 377040.49 | E4: =SUM('איגרות חוב ממשלתיות'!U:U)/B30 -> 0.12646894
A5: ניירות ערך מסחריים | B5: =SUM('ניירות ערך מסחריים'!AD:AD) -> 0 | D5: =B5+C5 -> 0 | E5: =SUM('ניירות ערך מסחריים'!AD:AD)/B30 -> 0
A6: איגרות חוב | B6: =SUM('איגרות חוב'!AD:AD) -> 184393.96 | D6: =B6+C6 -> 184393.96 | E6: =SUM('איגרות חוב'!AD:AD)/B30 -> 0.061850412
A7: מניות, מניות בכורה ויחידות השתתפות | B7: =SUM('מניות מבכ ויהש'!U:U) -> 353483.04 | D7: =B7+C7 -> 353483.04 | E7: =SUM('מניות מבכ ויהש'!U:U)/B30 -> 0.11856718
A8: קרנות סל | B8: =SUM('קרנות סל'!T:T) -> 717037.29 | D8: =B8+C8 -> 717037.29 | E8: =SUM('קרנות סל'!T:T)/B30 -> 0.24051249
A9: קרנות נאמנות | B9: =SUM('קרנות נאמנות'!T:T) -> 121588.34 | D9: =B9+C9 -> 121588.34 | E9: =SUM('קרנות נאמנות'!T:T)/B30 -> 0.040783813
A10: כתבי אופציה | B10: =SUM('כתבי אופציה'!W:W) -> 36.54 | D10: =B10+C10 -> 36.54 | E10: =SUM('כתבי אופציה'!W:W)/B30 -> 1.2256443e-05
A11: אופציות | B11: =SUM(אופציות!V:V) -> 0 | D11: =B11+C11 -> 0 | E11: =SUM(אופציות!V:V)/B30 -> 0
A12: חוזים עתידיים | B12: =SUM('חוזים עתידיים'!R:R) -> 6828.044 | D12: =B12+C12 -> 6828.044 | E12: =SUM('חוזים עתידיים'!R:R)/B30 -> 0.0022902991
A13: מוצרים מובנים | B13: =SUM('מוצרים מובנים'!Z:Z) -> 0 | D13: =B13+C13 -> 0 | E13: =SUM('מוצרים מובנים'!Z:Z)/B30 -> 0
A14: לא סחיר איגרות חוב ממשלתיות | B14: =SUM('לא סחיר איגרות חוב ממשלתיות'!U:U) -> 0 | D14: =B14+C14 -> 0 | E14: =SUM('לא סחיר איגרות חוב ממשלתיות'!U:U)/B30 -> 0
A15: לא סחיר איגרות חוב מיועדות | B15: =SUM('לא סחיר איגרות חוב מיועדות'!N:N) -> 0 | D15: =B15+C15 -> 0 | E15: =SUM('לא סחיר איגרות חוב מיועדות'!N:N)/B30 -> 0
A16: אפיק השקעה מובטח תשואה | B16: =SUM('אפיק השקעה מובטח תשואה'!F:F) -> 0 | D16: =B16+C16 -> 0 | E16: =SUM('אפיק השקעה מובטח תשואה'!F:F)/B30 -> 0
A17: לא סחיר ניירות ערך מסחריים | B17: =SUM('לא סחיר ניירות ערך מסחריים'!AI:AI) -> 0 | D17: =B17+C17 -> 0 | E17: =SUM('לא סחיר ניירות ערך מסחריים'!AI:AI)/B30 -> 0
A18: לא סחיר איגרות חוב | B18: =SUM('לא סחיר איגרות חוב'!AG:AG) -> 8513.34 | D18: =B18+C18 -> 8513.34 | E18: =SUM('לא סחיר איגרות חוב'!AG:AG)/B30 -> 0.0028555901
A19: לא סחיר מניות, מניות בכורה ויחידות השתתפות | B19: =SUM('לא סחיר מניות מבכ ויהש'!X:X) -> 88966.841 | D19: =B19+C19 -> 88966.841 | E19: =SUM('לא סחיר מניות מבכ ויהש'!X:X)/B30 -> 0.029841735
A20: קרנות השקעה | B20: =SUM('קרנות השקעה'!W:W) -> 523732.14 | D20: =B20+C20 -> 523732.14 | E20: =SUM('קרנות השקעה'!W:W)/B30 -> 0.17567304
A21: לא סחיר כתבי אופציה | B21: =SUM('לא סחיר כתבי אופציה'!Z:Z) -> 0.268 | D21: =B21+C21 -> 0.268 | E21: =SUM('לא סחיר כתבי אופציה'!Z:Z)/B30 -> 8.9893997e-08
A22: לא סחיר אופציות | B22: =SUM('לא סחיר אופציות'!Z:Z) -> 0 | D22: =B22+C22 -> 0 | E22: =SUM('לא סחיר אופציות'!Z:Z)/B30 -> 0
A23: לא סחיר נגזרים אחרים | B23: =SUM('לא סחיר נגזרים אחרים'!R:R) -> -285.985 | D23: =B23+C23 -> -285.985 | E23: =SUM('לא סחיר נגזרים אחרים'!R:R)/B30 -> -9.5926622e-05
A24: הלוואות | B24: =SUM(הלוואות!AT:AT) -> 65265.22 | D24: =B24+C24 -> 65265.22 | E24: =SUM(הלוואות!AT:AT)/B30 -> 0.02189161
A25: לא סחיר מוצרים מובנים | B25: =SUM('לא סחיר מוצרים מובנים'!AB:AB) -> 0 | D25: =B25+C25 -> 0 | E25: =SUM('לא סחיר מוצרים מובנים'!AB:AB)/B30 -> 0
A26: פיקדונות מעל 3 חודשים | B26: =SUM('פיקדונות מעל 3 חודשים'!T:T) -> 58489.992 | D26: =B26+C26 -> 58489.992 | E26: =SUM('פיקדונות מעל 3 חודשים'!T:T)/B30 -> 0.019619027
A27: זכויות מקרקעין | B27: =SUM('זכויות מקרקעין'!S:S) -> 419529.71 | D27: =B27+C27 -> 419529.71 | E27: =SUM('זכויות מקרקעין'!S:S)/$B$30 -> 0.14072091
A28: השקעה בחברות מוחזקות | B28: =SUM('השקעה בחברות מוחזקות'!U:U) -> 0 | D28: =B28+C28 -> 0 | E28: =SUM('השקעה בחברות מוחזקות'!U:U)/B30 -> 0
A29: נכסים אחרים | B29: =SUM('נכסים אחרים'!N:N) -> 528.687 | D29: =B29+C29 -> 528.687 | E29: =SUM('נכסים אחרים'!N:N)/B30 -> 0.00017733503
A30: סך הכל נכסים | B30: =IF(SUM(B3:B29)=0,0.0001,SUM(B3:B29)) -> 2981289.2 | C30: =SUM(C3:C29) -> 0 | D30: =SUM(D3:D29) -> 2981289.2 | E30: =SUM(E3:E29) -> 1
A31: מסגרות אשראי
A32: יתרות התחייבויות להשקעה | B32: =SUM('יתרות התחייבות להשקעה'!O:O) -> 210392.99

Sheet מזומנים ושווי מזומנים
A1: מספר קופה/קרן/ח.פ. עבור חברת ביטוח | B1: מספר מסלול | C1: שם הבנק | D1: מספר מזהה בנק | E1: סוג מספר מזהה בנק | F1: מאפיין עיקרי | G1: ישראל/חו"ל | H1: בעל עניין/צד קשור | I1: דירוג הבנק | J1: שם מדרג | K1: מטבע פעילות | L1: שווי מטבעי | M1: שער חליפין | N1: שיעור ריבית | O1: שווי הוגן (באלפי ש"ח) | P1: שיעור מנכסי אפיק ההשקעה | Q1: שיעור מסך נכסי ההשקעה
A2: 1182 | B2: 1182 | C2: בנק לאומי לישראל בע"מ | D2: 10-800 | E2: סימול בנק | F2: מזומן ועו"ש בש"ח | G2: ישראל | H2: לא | I2: AAA | J2: S&P מעלות | K2: ILS | L2: 0 | M2: 1 | N2: 0.0403 | O2: 341.663 | P2: 0.023583541 | Q2: 0.00089948588
A3: 1182 | B3: 1182 | C3: בנק לאומי לישראל בע"מ | D3: 10-800 | E3: סימול בנק | F3: מזומן ועו"ש בש"ח | G3: ישראל | H3: לא | I3: AAA | J3: S&P מעלות | K3: ILS | L3: 0 | M3: 1 | N3: 0.0403 | O3: 1993.559 | P3: 0.13760698 | Q3: 0.0052483863
A4: 1182 | B4: 1182 | C4: בנק לאומי לישראל בע"מ | D4: 10-800 | E4: סימול בנק | F4: מזומן ועו"ש בש"ח | G4: ישראל | H4: לא | I4: AAA | J4: S&P מעלות | K4: ILS | L4: 0 | M4: 1 | N4: 0.0403 | O4: 0.01 | P4: 6.9025798e-07 | Q4: 2.6326722e-08
A5: 1182 | B5: 1182 | C5: גמול פועלים סהר | D5: 33-414 | E5: סימול בנק | F5: מזומן ועו"ש נקוב במט"ח | G5: חו"ל | H5: לא | I5: AAA | J5: S&P מעלות | K5: USD | L5: 47.03 | M5: 3.681 | N5: 0.0384 | O5: 173.117 | P5: 0.01194951 | Q5: 0.00045575921
A6: 1182 | B6: 1182 | C6: גמול פועלים סהר | D6: 33-414 | E6: סימול בנק | F6: מזומן ועו"ש נקוב במט"ח | G6: חו"ל | H6: לא | I6: AAA | J6: S&P מעלות | K6: CAD | L6: 849.473 | M6: 2.712 | N6: 0 | O6: 2303.941 | P6: 0.15903135 | Q6: 0.0060655207
A7: 1182 | B7: 1182 | C7: גמול פועלים סהר | D7: 33-414 | E7: סימול בנק | F7: מזומן ועו"ש נקוב במט"ח | G7: חו"ל | H7: לא | I7: AAA | J7: S&P מעלות | K7: JPY | L7: 2544.117 | M7: 2.433 | N7: 0 | O7: 61.909 | P7: 0.0042732873 | Q7: 0.00016298492
A8: 1182 | B8: 1182 | C8: גמול פועלים סהר | D8: 33-414 | E8: סימול בנק | F8: מזומן ועו"ש נקוב במט"ח | G8: חו"ל | H8: לא | I8: AAA | J8: S&P מעלות | K8: GBP | L8: 6.71 | M8: 4.654 | N8: 0 | O8: 31.223 | P8: 0.0021552043 | Q8: 8.2200371e-05
A9: 1182 | B9: 1182 | C9: גמול פועלים סהר | D9: 33-414 | E9: סימול בנק | F9: מזומן ועו"ש בש"ח | G9: ישראל | H9: לא | I9: AAA | J9: S&P מעלות | K9: ILS | L9: 0 | M9: 1 | N9: 0.0403 | O9: 9581.917 | P9: 0.66139944 | Q9: 0.025226045
A10: 1182 | B10: 14769 | C10: בנק לאומי לישראל בע"מ | D10: 10-800 | E10: סימול בנק | F10: מזומן ועו"ש בש"ח | G10: ישראל | H10: לא | I10: AAA | J10: S&P מעלות | K10: ILS | L10: 0 | M10: 1 | N10: 0.0403 | O10: 96.614 | P10: 0.13536992 | Q10: 0.01238455
A11: 1182 | B11: 14769 | C11: גמול פועלים סהר | D11: 33-414 | E11: סימול בנק | F11: מזומן ועו"ש נקוב במט"ח | G11: חו"ל | H11: לא | I11: AAA | J11: S&P מעלות | K11: USD | L11: 34.435 | M11: 3.681 | N11: 0.0384 | O11: 126.756 | P11: 0.17760182 | Q11: 0.016248208
A12: 1182 | B12: 14769 | C12: גמול פועלים סהר | D12: 33-414 | E12: סימול בנק | F12: מזומן ועו"ש נקוב במט"ח | G12: חו"ל | H12: לא | I12: AAA | J12: S&P מעלות | K12: CAD | L12: -0.9 | M12: 2.712 | N12: 0 | O12: -2.44 | P12: -0.0034188546 | Q12: -0.00031277979
A13: 1182 | B13: 14769 | C13: גמול פועלים סהר | D13: 33-414 | E13: סימול בנק | F13: מזומן ועו"ש נקוב במט"ח | G13: חו"ל | H13: לא | I13: AAA | J13: S&P מעלות | K13: EUR | L13: 2.322 | M13: 3.979 | N13: 0 | O13: 9.239 | P13: 0.012945538 | Q13: 0.0011843448
... A65: 969 | B65: 969 | C65: גמול פועלים סהר | D65: 33-414 | E65: סימול בנק | F65: מזומן ועו"ש בש"ח | G65: ישראל | H65: לא | I65: AAA | J65: S&P מעלות | K65: ILS | L65: 0 | M65: 1 | N65: 0.0403 | O65: 710.241 | P65: 0.31332323 | Q65: 0.0096700746

Sheet איגרות חוב ממשלתיות
A1: מספר קופה/קרן/ח.פ. עבור חברת ביטוח | B1: מספר מסלול | C1: שם מנפיק | D1: שם נייר ערך | E1: מספר נייר ערך | F1: מאפיין עיקרי | G1: ישראל/חו"ל | H1: מדינה לפי חשיפה כלכלית | I1: זירת מסחר | J1: דירוג | K1: שם מדרג | L1: מטבע פעילות | M1: מח"מ | N1: מועד פדיון | O1: שיעור ריבית | P1: תשואה לפדיון | Q1: סכום לקבל (במטבע הפעילות) | R1: ערך נקוב (יחידות) | S1: שער חליפין | T1: שער נייר הערך | U1: שווי הוגן (באלפי ש"ח) | V1: עלות מופחתת (באלפי ש"ח) | W1: השיטה שיושמה בדוח הכספי | X1: שיעור מערך נקוב מונפק | Y1: שיעור מנכסי אפיק ההשקעה | Z1: שיעור מסך נכסי ההשקעה
A2: 1182 | B2: 1182 | C2: בנק ישראל- מק"מ | D2: מ.ק.מ. 414 | E2: IL0082404182 | F2: מק"מ קצר משנים עשר חודשים | G2: ישראל | H2: ישראל | I2: TASE | J2: RF | K2: פנימי | L2: ILS | M2: 0.005 | N2: 03/04/2024 | O2: 0 | P2: 0.05629 | R2: 3718013 | S2: 1 | T2: 99.97 | U2: 3716.898 | W2: שווי הוגן | X2: 0.000186 | Y2: 0.059153818 | Z2: 0.0097853728
A3: 1182 | B3: 1182 | C3: בנק ישראל- מק"מ | D3: מלווה קצר מועד 1014 | E3: IL0082410106 | F3: מק"מ קצר משנים עשר חודשים | G3: ישראל | H3: ישראל | I3: TASE | J3: RF | K3: פנימי | L3: ILS | M3: 0.504 | N3: 02/10/2024 | O3: 0 | P3: 0.04258 | R3: 307125 | S3: 1 | T3: 97.93 | U3: 300.768 | W3: שווי הוגן | X3: 0 | Y3: 0.0047866658 | Z3: 0.00079182225
A4: 1182 | B4: 1182 | C4: בנק ישראל- מק"מ | D4: מלווה קצר מועד 1214 | E4: IL0082412185 | F4: מק"מ קצר משנים עשר חודשים | G4: ישראל | H4: ישראל | I4: TASE | J4: RF | K4: פנימי | L4: ILS | M4: 0.677 | N4: 04/12/2024 | O4: 0 | P4: 0.04238 | R4: 5000000 | S4: 1 | T4: 97.22 | U4: 4861 | W4: שווי הוגן | X4: 0.000357 | Y4: 0.077362021 | Z4: 0.012797419
A5: 1182 | B5: 1182 | C5: גליל | D5: ממשל צמודה 0527 | E5: IL0011408478 | F5: צמוד למדד המחירים לצרכן בריבית קבועה | G5: ישראל | H5: ישראל | I5: TASE | J5: RF | K5: פנימי | L5: ILS | M5: 3.119 | N5: 31/05/2027 | O5: 0.0075 | P5: 0.01152 | R5: 1171463 | S5: 1 | T5: 111.88 | U5: 1310.633 | W5: שווי הוגן | X5: 5.6e-05 | Y5: 0.020858507 | Z5: 0.0034504665
A6: 1182 | B6: 1182 | C6: גליל | D6: ממשל צמודה 0545 | E6: IL0011348658 | F6: צמוד למדד המחירים לצרכן בריבית קבועה | G6: ישראל | H6: ישראל | I6: TASE | J6: RF | K6: פנימי | L6: ILS | M6: 18.8 | N6: 31/05/2045 | O6: 0.01 | P6: 0.01853 | R6: 1670758 | S6: 1 | T6: 96.44 | U6: 1611.279 | W6: שווי הוגן | X6: 9.2e-05 | Y6: 0.025643242 | Z6: 0.0042419694
A7: 1182 | B7: 1182 | C7: גליל | D7: ממשל צמודה 1025 | E7: IL0011359127 | F7: צמוד למדד המחירים לצרכן בריבית קבועה | G7: ישראל | H7: ישראל | I7: TASE | J7: RF | K7: פנימי | L7: ILS | M7: 1.576 | N7: 31/10/2025 | O7: 0.0075 | P7: 0.00797 | R7: 1346811 | S7: 1 | T7: 112.14 | U7: 1510.314 | W7: שווי הוגן | X7: 6.2e-05 | Y7: 0.024036398 | Z7: 0.0039761612
A8: 1182 | B8: 1182 | C8: גליל | D8: ממשל צמודה 1131 | E8: IL0011722209 | F8: צמוד למדד המחירים לצרכן בריבית קבועה | G8: ישראל | H8: ישראל | I8: TASE | J8: RF | K8: פנימי | L8: ILS | M8: 7.638 | N8: 30/11/2031 | O8: 0.001 | P8: 0.01556 | R8: 202224 | S8: 1 | T8: 99.81 | U8: 201.84 | W8: שווי הוגן | X8: 8e-06 | Y8: 0.003212247 | Z8: 0.00053137795
A9: 1182 | B9: 1182 | C9: שחר | D9: ממשל שיקלית 0928 | E9: IL0011508798 | F9: לא צמוד למדד המחירים לצרכן ריבית קבועה | G9: ישראל | H9: ישראל | I9: TASE | J9: RF | K9: פנימי | L9: ILS | M9: 4.269 | N9: 28/09/2028 | O9: 0.0225 | P9: 0.04072 | R9: 266042 | S9: 1 | T9: 93.79 | U9: 249.521 | W9: שווי הוגן | X9: 1e-05 | Y9: 0.0039710826 | Z9: 0.00065690644
A10: 1182 | B10: 1182 | C10: שחר | D10: ממשל שקלית 0229 | E10: IL0011948028 | F10: לא צמוד למדד המחירים לצרכן ריבית קבועה | G10: ישראל | H10: ישראל | I10: TASE | J10: RF | K10: פנימי | L10: ILS | M10: 4.563 | N10: 28/02/2029 | O10: 0.0375 | P10: 0.04094 | R10: 1799925 | S10: 1 | T10: 98.83 | U10: 1778.866 | W10: שווי הוגן | X10: 0.000141 | Y10: 0.02831036 | Z10: 0.0046831707
A11: 1182 | B11: 1182 | C11: שחר | D11: ממשל שקלית 0327 | E11: IL0011393449 | F11: לא צמוד למדד המחירים לצרכן ריבית קבועה | G11: ישראל | H11: ישראל | I11: TASE | J11: RF | K11: פנימי | L11: ILS | M11: 2.937 | N11: 31/03/2027 | O11: 0.02 | P11: 0.04015 | R11: 528276 | S11: 1 | T11: 94.43 | U11: 498.851 | W11: שווי הוגן | X11: 2.4e-05 | Y11: 0.0079391326 | Z11: 0.0013133112
A12: 1182 | B12: 1182 | C12: שחר | D12: ממשל שקלית 0347 | E12: IL0011401937 | F12: לא צמוד למדד המחירים לצרכן ריבית קבועה | G12: ישראל | H12: ישראל | I12: TASE | J12: RF | K12: פנימי | L12: ILS | M12: 15.141 | N12: 31/03/2047 | O12: 0.0375 | P12: 0.04826 | R12: 1302268 | S12: 1 | T12: 85.26 | U12: 1110.314 | W12: שווי הוגן | X12: 5.2e-05 | Y12: 0.017670461 | Z12: 0.002923092
A13: 1182 | B13: 1182 | C13: גליל | D13: ממשלתי צמוד 841 | E13: IL0011205833 | F13: צמוד למדד המחירים לצרכן בריבית קבועה | G13: ישראל | H13: ישראל | I13: TASE | J13: RF | K13: פנימי | L13: ILS | M13: 14.135 | N13: 30/08/2041 | O13: 0.0275 | P13: 0.01782 | R13: 68189 | S13: 1 | T13: 138.12 | U13: 94.183 | W13: שווי הוגן | X13: 4e-06 | Y13: 0.0014989014 | Z13: 0.00024795203
... A99: 969 | B99: 969 | C99: US TREASURY N/B | D99: T-3 3/8 15/05/33 | E99: US91282CHC82 | F99: צמוד מט"ח בריבית קבועה | G99: חו"ל | H99: ארה"ב | I99: NYSE | J99: Aaa | K99: Moodys | L99: USD | M99: 7.57 | N99: 15/05/2033 | O99: 0.03375 | P99: 0.04409 | R99: 765000 | S99: 3.681 | T99: 95.014 | U99: 2675.555 | W99: שווי הוגן | X99: 7e-06 | Y99: 0.16364508 | Z99: 0.036428227

Sheet ניירות ערך מסחריים
A1: מספר קופה/קרן/ח.פ. עבור חברת ביטוח | B1: מספר מסלול | C1: שם מנפיק | D1: מספר מנפיק | E1: סוג מספר מזהה מנפיק | F1: שם נייר ערך | G1: מספר נייר ערך | H1: סוג מספר נייר ערך | I1: מאפיין עיקרי | J1: ישראל/חו"ל | K1: מדינה לפי חשיפה כלכלית | L1: זירת מסחר | M1: ענף מסחר | N1: בעל עניין/צד קשור | O1: דירוג | P1: שם מדרג | Q1: דירוג נייר הערך/המנפיק | R1: מטבע פעילות | S1: מח"מ | T1: ריבית עוגן | U1: מועד פדיון | V1: שיעור ריבית | W1: תשואה לפדיון | X1: נחיתות חוזית | Y1: האם סווג כחוב בעייתי | Z1: ערך נקוב (יחידות) | AA1: שער חליפין | AB1: שער נייר הערך | AC1: סכום לקבל (במטבע הפעילות) | AD1: שווי הוגן (באלפי ש"ח) | AE1: עלות מופחתת (באלפי ש"ח) | AF1: עלות מופחתת (במטבע הפעילות) | AG1: השיטה שיושמה בדוח הכספי | AH1: שיעור מערך נקוב מונפק | AI1: שיעור מנכסי אפיק ההשקעה | AJ1: שיעור מסך נכסי ההשקעה

Sheet איגרות חוב
A1: מספר קופה/קרן/ח.פ. עבור חברת ביטוח | B1: מספר מסלול | C1: שם מנפיק | D1: מספר מנפיק | E1: סוג מספר מזהה מנפיק | F1: שם נייר ערך | G1: מספר נייר ערך | H1: סוג מספר נייר ערך | I1: מאפיין עיקרי | J1: ישראל/חו"ל | K1: מדינה לפי חשיפה כלכלית | L1: סטאטוס סחירות | M1: זירת מסחר | N1: ענף מסחר | O1: בעל עניין/צד קשור | P1: דירוג | Q1: שם מדרג | R1: דירוג נייר הערך/המנפיק | S1: מטבע פעילות | T1: מח"מ | U1: מועד פדיון | V1: שיעור ריבית | W1: תשואה לפדיון | X1: נחיתות חוזית | Y1: האם סווג כחוב בעייתי | Z1: ערך נקוב (יחידות) | AA1: שער חליפין | AB1: שער נייר הערך | AC1: סכום לקבל (במטבע הפעילות) | AD1: שווי הוגן (באלפי ש"ח) | AE1: עלות מופחתת (באלפי ש"ח) | AF1: עלות מופחתת (במטבע הפעילות) | AG1: השיטה שיושמה בדוח הכספי | AH1: שיעור מערך נקוב מונפק | AI1: שיעור מנכסי אפיק ההשקעה | AJ1: שיעור מסך נכסי ההשקעה
A2: 1182 | B2: 1182 | C2: אדגר השקעות ופיתוח בע"מ | D2: 520035171 | E2: ח.פ | F2: אדגר אגח ט | G2: IL0018201900 | H2: ISIN | I2: צמוד למדד המחירים לצרכן | J2: ישראל | K2: גלובלי | L2: סחיר | M2: TASE | N2: נדל"ן מניב בחו"ל | O2: לא | P2: A2 | Q2: מידרוג Moodys | R2: נייר ערך | S2: ILS | T2: 0.739 | U2: 01/07/2025 | V2: 0.0465 | W2: 0.02557 | X2: החוב לא נחות | Y2: לא | Z2: 97638.4 | AA2: 1 | AB2: 115.33 | AD2: 112.606 | AG2: שווי הוגן | AH2: 0.000227 | AI2: 0.0050809308 | AJ2: 0.00029645565
A3: 1182 | B3: 1182 | C3: אדמה פתרונות לחקלאות בע"מ | D3: 520043605 | E3: ח.פ | F3: אדמה אגח ב | G3: IL0011109159 | H3: ISIN | I3: צמוד למדד המחירים לצרכן | J3: ישראל | K3: ישראל | L3: סחיר | M3: TASE | N3: כימיה, גומי ופלסטיק | O3: לא | P3: AA- | Q3: S&P מעלות | R3: נייר ערך | S3: ILS | T3: 5.674 | U3: 30/11/2036 | V3: 0.0515 | W3: 0.02931 | X3: החוב לא נחות | Y3: לא | Z3: 86702.36 | AA3: 1 | AB3: 154.27 | AD3: 133.756 | AG3: שווי הוגן | AH3: 2.8e-05 | AI3: 0.0060352148 | AJ3: 0.00035213499
A4: 1182 | B4: 1182 | C4: או.פי.סי. אנרגיה בע"מ | D4: 514401702 | E4: ח.פ | F4: או פי סי אגח ב' | G4: IL0011660573 | H4: ISIN | I4: צמוד למדד המחירים לצרכן | J4: ישראל | K4: ישראל | L4: סחיר | M4: TASE | N4: אנרגיה | O4: לא | P4: A- | Q4: S&P מעלות | R4: נייר ערך | S4: ILS | T4: 3.318 | U4: 01/10/2028 | V4: 0.0275 | W4: 0.02769 | X4: החוב לא נחות | Y4: לא | Z4: 195942.09 | AA4: 1 | AB4: 110.77 | AD4: 217.045 | AG4: שווי הוגן | AH4: 0.000217 | AI4: 0.0097933263 | AJ4: 0.00057140847
A5: 1182 | B5: 1182 | C5: או.פי.סי. אנרגיה בע"מ | D5: 514401702 | E5: ח.פ | F5: או.פי.סי אגח ג | G5: IL0011803553 | H5: ISIN | I5: לא צמוד למדד המחירים לצרכן | J5: ישראל | K5: ישראל | L5: סחיר | M5: TASE | N5: אנרגיה | O5: לא | P5: A- | Q5: S&P מעלות | R5: נייר ערך | S5: ILS | T5: 3.532 | U5: 31/08/2030 | V5: 0.025 | W5: 0.05517 | X5: החוב לא נחות | Y5: לא | Z5: 304000 | AA5: 1 | AB5: 90.36 | AD5: 274.694 | AG5: שווי הוגן | AH5: 0.000357 | AI5: 0.012394532 | AJ5: 0.0007231803
A6: 1182 | B6: 1182 | C6: אזורים-חברה להשקעות בפתוח ובבנין בע"מ | D6: 520025990 | E6: ח.פ | F6: אזורים סדרה 14 | G6: IL0071504448 | H6: ISIN | I6: לא צמוד למדד המחירים לצרכן | J6: ישראל | K6: ישראל | L6: סחיר | M6: TASE | N6: בנייה | O6: לא | P6: A2 | Q6: מידרוג Moodys | R6: נייר ערך | S6: ILS | T6: 2.725 | U6: 31/12/2028 | V6: 0.0255 | W6: 0.05373 | X6: החוב לא נחות | Y6: לא | Z6: 393125 | AA6: 1 | AB6: 93.65 | AD6: 368.162 | AG6: שווי הוגן | AH6: 0.000675 | AI6: 0.01661188 | AJ6: 0.00096924869
A7: 1182 | B7: 1182 | C7: איי.די.איי. הנפקות (2010) בע"מ | D7: 514486042 | E7: ח.פ | F7: איידיאיי הנפקות אגח ו | G7: IL0011830374 | H7: ISIN | I7: לא צמוד למדד המחירים לצרכן | J7: ישראל | K7: ישראל | L7: סחיר | M7: TASE | N7: ביטוח | O7: לא | P7: A2 | Q7: מידרוג Moodys | R7: נייר ערך | S7: ILS | T7: 4.451 | U7: 15/12/2028 | V7: 0.0218 | W7: 0.05413 | X7: החוב לא נחות | Y7: לא | Z7: 965867 | AA7: 1 | AB7: 87.63 | AD7: 846.389 | AG7: שווי הוגן | AH7: 0.005875 | AI7: 0.038190072 | AJ7: 0.0022282654
A8: 1182 | B8: 1182 | C8: איירפורט סיטי בע"מ | D8: 511659401 | E8: ח.פ | F8: איירפורט אגח ה | G8: IL0011334872 | H8: ISIN | I8: צמוד למדד המחירים לצרכן | J8: ישראל | K8: ישראל | L8: סחיר | M8: TASE | N8: נדל"ן מניב בישראל | O8: לא | P8: AA | Q8: S&P מעלות | R8: נייר ערך | S8: ILS | T8: 2.698 | U8: 28/02/2029 | V8: 0.0234 | W8: 0.02157 | X8: החוב לא נחות | Y8: לא | Z8: 132000.02 | AA8: 1 | AB8: 111.84 | AD8: 147.629 | AG8: שווי הוגן | AH8: 5.1e-05 | AI8: 0.0066611849 | AJ8: 0.00038865829
A9: 1182 | B9: 1182 | C9: אלוני-חץ נכסים והשקעות בע"מ | D9: 520038506 | E9: ח.פ | F9: אלוני חץ אגח יב | G9: IL0039004952 | H9: ISIN | I9: לא צמוד למדד המחירים לצרכן | J9: ישראל | K9: ישראל | L9: סחיר | M9: TASE | N9: נדל"ן מניב בישראל | O9: לא | P9: AA- | Q9: S&P מעלות | R9: נייר ערך | S9: ILS | T9: 4.837 | U9: 28/02/2031 | V9: 0.0241 | W9: 0.05745 | X9: החוב לא נחות | Y9: לא | Z9: 204444.44 | AA9: 1 | AB9: 85.75 | AD9: 175.311 | AG9: שווי הוגן | AH9: 0.000132 | AI9: 0.0079102419 | AJ9: 0.00046153667
A10: 1182 | B10: 1182 | C10: אלוני-חץ נכסים והשקעות בע"מ | D10: 520038506 | E10: ח.פ | F10: אלוני חץ אגח יג | G10: IL0011894065 | H10: ISIN | I10: לא צמוד למדד המחירים לצרכן | J10: ישראל | K10: ישראל | L10: סחיר | M10: TASE | N10: נדל"ן מניב בישראל | O10: לא | P10: Aa3 | Q10: מידרוג Moodys | R10: נייר ערך | S10: ILS | T10: 6.789 | U10: 01/03/2037 | V10: 0.0494 | W10: 0.06222 | X10: החוב לא נחות | Y10: לא | Z10: 235951 | AA10: 1 | AB10: 92.4 | AD10: 218.019 | AG10: שווי הוגן | AH10: 0.000445 | AI10: 0.0098372595 | AJ10: 0.00057397182
A11: 1182 | B11: 1182 | C11: אלקטרה בע"מ | D11: 520028911 | E11: ח.פ | F11: אלקטרה אגח ה | G11: IL0073902228 | H11: ISIN | I11: לא צמוד למדד המחירים לצרכן | J11: ישראל | K11: ישראל | L11: סחיר | M11: TASE | N11: השקעה ואחזקות | O11: לא | P11: A+ | Q11: S&P מעלות | R11: נייר ערך | S11: ILS | T11: 3.41 | U11: 10/01/2031 | V11: 0.04 | W11: 0.0502 | X11: החוב לא נחות | Y11: לא | Z11: 218750.04 | AA11: 1 | AB11: 97.7 | AD11: 213.719 | AG11: שווי הוגן | AH11: 0.000283 | AI11: 0.0096432414 | AJ11: 0.0005626515
A12: 1182 | B12: 1182 | C12: אפי נכסים בע"מ | D12: 510560188 | E12: ח.פ | F12: אפי נכסים אגח 8 | G12: IL0011422313 | H12: ISIN | I12: צמוד למדד המחירים לצרכן | J12: ישראל | K12: ישראל | L12: סחיר | M12: TASE | N12: נדל"ן מניב בחו"ל | O12: לא | P12: A2 | Q12: מידרוג Moodys | R12: נייר ערך | S12: ILS | T12: 1.943 | U12: 15/10/2026 | V12: 0.0257 | W12: 0.02477 | X12: החוב לא נחות | Y12: לא | Z12: 910740 | AA12: 1 | AB12: 113.66 | AD12: 1035.147 | AG12: שווי הוגן | AH12: 0.00071 | AI12: 0.046707046 | AJ12: 0.0027252029
A13: 1182 | B13: 1182 | C13: אפי נכסים בע"מ | D13: 510560188 | E13: ח.פ | F13: אפי נכסים אגח יד | G13: IL0011845307 | H13: ISIN | I13: צמוד למדד המחירים לצרכן | J13: ישראל | K13: ישראל | L13: סחיר | M13: TASE | N13: נדל"ן מניב בחו"ל | O13: לא | P13: A2 | Q13: מידרוג Moodys | R13: נייר ערך | S13: ILS | T13: 5.621 | U13: 30/03/2031 | V13: 0.0154 | W13: 0.03297 | X13: החוב לא נחות | Y13: לא | Z13: 317000 | AA13: 1 | AB13: 98.44 | AD13: 312.055 | AG13: שווי הוגן | AH13: 0.000906 | AI13: 0.014080277 | AJ13: 0.00082153798
... A371: 969 | B371: 969 | C371: Chamoss International Limited | D371: 633896 | E371: מספר תאגיד או שותפות בחו"ל | F371: שמוס אגח א | G371: IL0011559510 | H371: ISIN | I371: צמוד למט"ח | J371: חו"ל | K371: בריטניה | L371: סחיר | M371: TASE | N371: נדל"ן מניב בחו"ל | O371: לא | P371: Aa3 | Q371: מידרוג Moodys | R371: נייר ערך | S371: ILS | T371: 3.25 | U371: 10/07/2028 | V371: 0.043 | W371: 0.08436 | X371: החוב לא נחות | Y371: לא | Z371: 85751.85 | AA371: 1 | AB371: 86.78 | AD371: 74.415 | AG371: שווי הוגן | AH371: 7.4e-05 | AI371: 0.012149967 | AJ371: 0.0010131815

Sheet מניות מבכ ויהש
A1: מספר קופה/קרן/ח.פ. עבור חברת ביטוח | B1: מספר מסלול | C1: שם מנפיק | D1: מספר מנפיק | E1: סוג מספר מזהה מנפיק | F1: שם נייר ערך | G1: מספר נייר ערך | H1: סוג מספר נייר ערך | I1: מאפיין עיקרי | J1: ישראל/חו"ל | K1: מדינה לפי חשיפה כלכלית | L1: סטאטוס סחירות | M1: זירת מסחר | N1: ענף מסחר | O1: בעל עניין/צד קשור | P1: מטבע פעילות | Q1: ערך נקוב (יחידות) | R1: שער חליפין | S1: שער נייר הערך | T1: סכום לקבל (במטבע הפעילות) | U1: שווי הוגן (באלפי ש"ח) | V1: שיעור מערך נקוב מונפק | W1: שיעור מנכסי אפיק ההשקעה | X1: שיעור מסך נכסי ההשקעה
A2: 1182 | B2: 1182 | C2: אורמת טכנולגיות אינק | D2: 5493000TSHHWY24VHM09 | E2: LEI | F2: אורמת טכנולוגיות | G2: US6866881021 | H2: ISIN | I2: מניות | J2: חו"ל | K2: ארה"ב | L2: סחיר | M2: TASE | N2: אנרגיה מתחדשת | O2: לא | P2: ILS | Q2: 2795.5 | R2: 1 | S2: 24060 | U2: 672.597 | V2: 5e-05 | W2: 0.016620469 | X2: 0.0017707282
A3: 1182 | B3: 1182 | C3: איי.סי.אל גרופ בע"מ (דואלי) | D3: 520027830 | E3: ח.פ | F3: איי.סי.אל | G3: IL0002810146 | H3: ISIN | I3: מניות | J3: ישראל | K3: ישראל | L3: סחיר | M3: TASE | N3: כימיה, גומי ופלסטיק | O3: לא | P3: ILS | Q3: 36441 | R3: 1 | S3: 1951 | U3: 710.964 | V3: 2.8e-05 | W3: 0.017568542 | X3: 0.0018717349
A4: 1182 | B4: 1182 | C4: איי.די.איי. חברה לביטוח בע"מ | D4: 513910703 | E4: ח.פ | F4: איידיאיי ביטוח | G4: IL0011295016 | H4: ISIN | I4: מניות | J4: ישראל | K4: ישראל | L4: סחיר | M4: TASE | N4: ביטוח | O4: לא | P4: ILS | Q4: 2680 | R4: 1 | S4: 10700 | U4: 286.76 | V4: 0.000183 | W4: 0.0070860912 | X4: 0.00075494507
A5: 1182 | B5: 1182 | C5: אינרום תעשיות בנייה בע"מ | D5: 515001659 | E5: ח.פ | F5: אינרום | G5: IL0011323560 | H5: ISIN | I5: מניות | J5: ישראל | K5: ישראל | L5: סחיר | M5: TASE | N5: מתכת ומוצרי בניה | O5: לא | P5: ILS | Q5: 15773 | R5: 1 | S5: 1180 | U5: 186.121 | V5: 0.000126 | W5: 0.0045992231 | X5: 0.00048999663
A6: 1182 | B6: 1182 | C6: אל על נתיבי אויר לישראל בע"מ | D6: 520017146 | E6: פנימי | F6: אל על | G6: IL0010878242 | H6: ISIN | I6: מניות | J6: ישראל | K6: ישראל | L6: סחיר | M6: TASE | N6: שירותים | O6: לא | P6: ILS | Q6: 0 | R6: 1 | S6: 499.9 | T6: 0.001 | U6: 0.001 | W6: 1.2849656e-08 | X6: 1.3689895e-09
A7: 1182 | B7: 1182 | C7: אלביט מערכות בע"מ | D7: 520043027 | E7: ח.פ | F7: אלביט מערכות | G7: IL0010811243 | H7: ISIN | I7: מניות | J7: ישראל | K7: ישראל | L7: סחיר | M7: TASE | N7: ביטחוניות | O7: לא | P7: ILS | Q7: 1175 | R7: 1 | S7: 77500 | U7: 910.625 | V7: 2.6e-05 | W7: 0.022502343 | X7: 0.0023973771
A8: 1182 | B8: 1182 | C8: אלקטרה בע"מ | D8: 520028911 | E8: ח.פ | F8: אלקטרה | G8: IL0007390375 | H8: ISIN | I8: מניות | J8: ישראל | K8: ישראל | L8: סחיר | M8: TASE | N8: השקעה ואחזקות | O8: לא | P8: ILS | Q8: 283 | R8: 1 | S8: 158340 | U8: 448.102 | V8: 7.4e-05 | W8: 0.011072998 | X8: 0.0011797062
A9: 1182 | B9: 1182 | C9: אנלייט אנרגיה מתחדשת בע"מ | D9: 520041146 | E9: ח.פ | F9: אנלייט אנרגיה | G9: IL0007200111 | H9: ISIN | I9: מניות | J9: ישראל | K9: ארה"ב | L9: סחיר | M9: TASE | N9: אנרגיה מתחדשת | O9: לא | P9: ILS | Q9: 6025.5 | R9: 1 | S9: 6299 | U9: 379.546 | V9: 5.1e-05 | W9: 0.0093789207 | X9: 0.00099922083
A10: 1182 | B10: 1182 | C10: Energean plc | D10: 549300RVMKU0CYUZBB05 | E10: LEI | F10: אנרג'יאן | G10: GB00BG12Y042 | H10: ISIN | I10: מניות | J10: חו"ל | K10: בריטניה | L10: סחיר | M10: TASE | N10: חיפושי נפט וגז | O10: לא | P10: ILS | Q10: 5585 | R10: 1 | S10: 5008 | T10: 6.132 | U10: 285.829 | V10: 3.2e-05 | W10: 0.0070630885 | X10: 0.00075249439
A11: 1182 | B11: 1182 | C11: אפריקה ישראל תעשיות בע"מ | D11: 520026618 | E11: ח.פ | F11: אפריקה תעשיות | G11: IL0008000114 | H11: ISIN | I11: מניות | J11: ישראל | K11: ישראל | L11: סחיר | M11: TASE | N11: מתכת ומוצרי בניה | O11: לא | P11: ILS | Q11: 250 | R11: 1 | S11: 0 | U11: 0 | V11: 0 | W11: 6.1777193e-12 | X11: 6.5816804e-13
A12: 1182 | B12: 1182 | C12: קבוצת אשטרום | D12: 510381601 | E12: ח.פ | F12: אשטרום קבוצה | G12: IL0011323156 | H12: ISIN | I12: מניות | J12: ישראל | K12: ישראל | L12: סחיר | M12: TASE | N12: בנייה | O12: לא | P12: ILS | Q12: 12160 | R12: 1 | S12: 5478 | U12: 666.125 | V12: 0.00012 | W12: 0.016460528 | X12: 0.0017536882
A13: 1182 | B13: 1182 | C13: בוליגו קפיטל בע"מ | D13: 514766195 | E13: ח.פ | F13: בוליגו | G13: IL0011805954 | H13: ISIN | I13: מניות | J13: ישראל | K13: ארה"ב | L13: סחיר | M13: TASE | N13: נדל"ן מניב בחו"ל | O13: לא | P13: ILS | Q13: 9400 | R13: 1 | S13: 755 | U13: 70.97 | V13: 0.00017 | W13: 0.001753731 | X13: 0.00018684074
A14: 1182 | B14: 1182 | C14: בתי זקוק לנפט בע"מ | D14: 520036658 | E14: ח.פ | F14: בזן | G14: IL0025902482 | H14: ISIN | I14: מניות | J14: ישראל | K14: ישראל | L14: סחיר | M14: TASE | N14: אנרגיה | O14: לא | P14: ILS | Q14: 136064 | R14: 1 | S14: 122 | T14: 22.649 | U14: 188.647 | V14: 4.3e-05 | W14: 0.00466164 | X14: 0.00049664647
A15: 1182 | B15: 1182 | C15: בזק החברה הישראלית לתקשורת בע"מ | D15: 520031931 | E15: ח.פ | F15: בזק | G15: IL0002300114 | H15: ISIN | I15: מניות | J15: ישראל | K15: ישראל | L15: סחיר | M15: TASE | N15: תקשורת ומדיה | O15: לא | P15: ILS | Q15: 145858 | R15: 1 | S15: 473 | U15: 689.908 | V15: 5.3e-05 | W15: 0.01704824 | X15: 0.0018163025
A16: 1182 | B16: 1182 | C16: ביג מרכזי קניות (2004) בע"מ | D16: 513623314 | E16: ח.פ | F16: ביג | G16: IL0010972607 | H16: ISIN | I16: מניות | J16: ישראל | K16: ישראל | L16: סחיר | M16: TASE | N16: נדל"ן מניב בישראל | O16: לא | P16: ILS | Q16: 1178.76 | R16: 1 | S16: 41030 | U16: 483.645 | V16: 4.8e-05 | W16: 0.011951298 | X16: 0.0012732793
A17: 1182 | B17: 1182 | C17: הבנק הבינלאומי הראשון לישראל בע"מ | D17: 520029083 | E17: ח.פ | F17: בינלאומי 5 | G17: IL0005930388 | H17: ISIN | I17: מניות | J17: ישראל | K17: ישראל | L17: סחיר | M17: TASE | N17: בנקים | O17: לא | P17: ILS | Q17: 501 | R17: 1 | S17: 15440 | U17: 77.354 | V17: 5e-06 | W17: 0.0019114951 | X17: 0.00020364877
A18: 1182 | B18: 1182 | C18: בית-הזהב בע"מ | D18: 520034562 | E18: ח.פ | F18: בית הזהב | G18: IL0002350101 | H18: ISIN | I18: מניות | J18: ישראל | K18: ישראל | L18: סחיר | M18: TASE | N18: נדל"ן מניב בישראל | O18: לא | P18: ILS | Q18: 6000 | R18: 1 | S18: 2015 | U18: 120.9 | V18: 0.000334 | W18: 0.0029875451 | X18: 0.00031829006
A19: 1182 | B19: 1182 | C19: בנק דיסקונט לישראל בע"מ | D19: 520007030 | E19: ח.פ | F19: דיסקונט | G19: IL0006912120 | H19: ISIN | I19: מניות | J19: ישראל | K19: ישראל | L19: סחיר | M19: TASE | N19: בנקים | O19: לא | P19: ILS | Q19: 19245 | R19: 1 | S19: 1946 | T19: 2.86 | U19: 377.367 | V19: 1.6e-05 | W19: 0.0093250745 | X19: 0.00099348412
A20: 1182 | B20: 1182 | C20: דלתא-גליל תעשיות בע"מ | D20: 520025602 | E20: ח.פ | F20: דלתא גליל | G20: IL0006270347 | H20: ISIN | I20: מניות | J20: ישראל | K20: ישראל | L20: סחיר | M20: TASE | N20: אופנה והלבשה | O20: לא | P20: ILS | Q20: 4338 | R20: 1 | S20: 16390 | U20: 710.998 | V20: 0.000169 | W20: 0.017569389 | X20: 0.0018718252
A21: 1182 | B21: 1182 | C21: הפניקס אחזקות בע"מ | D21: 520017450 | E21: ח.פ | F21: הפניקס | G21: IL0007670123 | H21: ISIN | I21: מניות | J21: ישראל | K21: ישראל | L21: סחיר | M21: TASE | N21: ביטוח | O21: לא | P21: ILS | Q21: 11560 | R21: 1 | S21: 3810 | U21: 440.436 | V21: 4.5e-05 | W21: 0.01088356 | X21: 0.0011595236
A22: 1182 | B22: 1182 | C22: הראל השקעות בביטוח ושרותים פיננסים בע"מ | D22: 520033986 | E22: ח.פ | F22: הראל השקעות | G22: IL0005850180 | H22: ISIN | I22: מניות | J22: ישראל | K22: ישראל | L22: סחיר | M22: TASE | N22: ביטוח | O22: לא | P22: ILS | Q22: 14508 | R22: 1 | S22: 3510 | U22: 509.231 | V22: 7e-05 | W22: 0.01258354 | X22: 0.0013406377
A23: 1182 | B23: 1182 | C23: החברה לישראל בע"מ | D23: 520028010 | E23: ח.פ | F23: חברה לישראל | G23: IL0005760173 | H23: ISIN | I23: מניות | J23: ישראל | K23: ישראל | L23: סחיר | M23: TASE | N23: השקעה ואחזקות | O23: לא | P23: ILS | Q23: 190 | R23: 1 | S23: 100120 | U23: 190.228 | V23: 2.5e-05 | W23: 0.0047007008 | X23: 0.00050080796
A24: 1182 | B24: 1182 | C24: חילן בע"מ | D24: 520039942 | E24: ח.פ | F24: חילן | G24: IL0010846983 | H24: ISIN | I24: מניות | J24: ישראל | K24: ישראל | L24: סחיר | M24: TASE | N24: שירותי מידע | O24: לא | P24: ILS | Q24: 1406 | R24: 1 | S24: 23460 | U24: 329.848 | V24: 6e-05 | W24: 0.0081508235 | X24: 0.00086838059
A25: 1182 | B25: 1182 | C25: חלל-תקשורת בע"מ | D25: 511396046 | E25: ח.פ | F25: חלל תקשורת | G25: IL0010923451 | H25: ISIN | I25: מניות | J25: ישראל | K25: ישראל | L25: סחיר | M25: TASE | N25: תקשורת ומדיה | O25: לא | P25: ILS | Q25: 15254 | R25: 1 | S25: 58.7 | U25: 8.954 | V25: 0.000481 | W25: 0.00022126362 | X25: 2.3573204e-05
A26: 1182 | B26: 1182 | C26: טאואר סמיקונדקטור בע"מ | D26: 520041997 | E26: ח.פ | F26: טאואר | G26: IL0010823792 | H26: ISIN | I26: מניות | J26: ישראל | K26: גלובלי | L26: סחיר | M26: TASE | N26: מוליכים למחצה | O26: לא | P26: ILS | Q26: 2951 | R26: 1 | S26: 12310 | U26: 363.268 | V26: 2.7e-05 | W26: 0.0089766734 | X26: 0.00095636581
A27: 1182 | B27: 1182 | C27: טבע תעשיות פרמצבטיות בע"מ | D27: 520013954 | E27: ח.פ | F27: טבע | G27: IL0006290147 | H27: ISIN | I27: מניות | J27: ישראל | K27: ארה"ב | L27: סחיר | M27: TASE | N27: פארמה | O27: לא | P27: ILS | Q27: 29888 | R27: 1 | S27: 5173 | U27: 1546.106 | V27: 2.7e-05 | W27: 0.038205641 | X27: 0.0040703908
A28: 1182 | B28: 1182 | C28: טיב טעם הולדינגס 1 בע"מ | D28: 520041187 | E28: ח.פ | F28: טיב טעם | G28: IL0001030100 | H28: ISIN | I28: מניות | J28: ישראל | K28: ישראל | L28: סחיר | M28: TASE | N28: רשתות שיווק | O28: לא | P28: ILS | Q28: 47850 | R28: 1 | S28: 511 | U28: 244.513 | V28: 0.000449 | W28: 0.0060421431 | X28: 0.00064372388
A29: 1182 | B29: 1182 | C29: ישראכרט בע"מ | D29: 510706153 | E29: ח.פ | F29: ישראכרט | G29: IL0011574030 | H29: ISIN | I29: מניות | J29: ישראל | K29: ישראל | L29: סחיר | M29: TASE | N29: שירותים פיננסיים | O29: לא | P29: ILS | Q29: 29655 | R29: 1 | S29: 1476 | T29: 6.794 | U29: 444.502 | V29: 0.000148 | W29: 0.010984036 | X29: 0.0011702282
A30: 1182 | B30: 1182 | C30: כלל החזקות עסקי ביטוח בע"מ | D30: 520036120 | E30: ח.פ | F30: כלל ביטוח | G30: IL0002240146 | H30: ISIN | I30: מניות | J30: ישראל | K30: ישראל | L30: סחיר | M30: TASE | N30: ביטוח | O30: לא | P30: ILS | Q30: 11533 | R30: 1 | S30: 6569 | U30: 757.603 | V30: 0.000146 | W30: 0.018721029 | X30: 0.0019945197
A31: 1182 | B31: 1182 | C31: בנק לאומי לישראל בע"מ | D31: 520018078 | E31: ח.פ | F31: לאומי | G31: IL0006046119 | H31: ISIN | I31: מניות | J31: ישראל | K31: ישראל | L31: סחיר | M31: TASE | N31: בנקים | O31: לא | P31: ILS | Q31: 44013 | R31: 1 | S31: 3100 | T31: 10.55 | U31: 1374.953 | V31: 2.7e-05 | W31: 0.033976301 | X31: 0.0036198011
A32: 1182 | B32: 1182 | C32: מגדלי הים התיכון | D32: 512719485 | E32: ח.פ | F32: מגדלי תיכון | G32: IL0011315236 | H32: ISIN | I32: מניות | J32: ישראל | K32: ישראל | L32: סחיר | M32: TASE | N32: נדל"ן מניב בישראל | O32: לא | P32: ILS | Q32: 12893 | R32: 1 | S32: 962.6 | U32: 124.108 | V32: 8.6e-05 | W32: 0.003066818 | X32: 0.00032673572
A33: 1182 | B33: 1182 | C33: מהדרין בע"מ | D33: 520018482 | E33: ח.פ | F33: מהדרין | G33: IL0006860147 | H33: ISIN | I33: מניות | J33: ישראל | K33: ישראל | L33: סחיר | M33: TASE | N33: מזון | O33: לא | P33: ILS | Q33: 1860 | R33: 1 | S33: 15760 | U33: 293.136 | V33: 0.000559 | W33: 0.0072436477 | X33: 0.00077173098
A34: 1182 | B34: 1182 | C34: מטריקס אי.טי בע"מ | D34: 520039413 | E34: ח.פ | F34: מטריקס | G34: IL0004450156 | H34: ISIN | I34: מניות | J34: ישראל | K34: ישראל | L34: סחיר | M34: TASE | N34: שירותי מידע | O34: לא | P34: ILS | Q34: 3508 | R34: 1 | S34: 8160 | T34: 4.455 | U34: 290.708 | V34: 5.5e-05 | W34: 0.0071836487 | X34: 0.00076533875
A35: 1182 | B35: 1182 | C35: מליסרון בע"מ | D35: 520037789 | E35: ח.פ | F35: מליסרון | G35: IL0003230146 | H35: ISIN | I35: מניות | J35: ישראל | K35: ישראל | L35: סחיר | M35: TASE | N35: נדל"ן מניב בישראל | O35: לא | P35: ILS | Q35: 777.75 | R35: 1 | S35: 26900 | T35: 1.964 | U35: 211.179 | V35: 1.6e-05 | W35: 0.0052184114 | X35: 0.00055596434
A36: 1182 | B36: 1182 | C36: מנורה מבטחים החזקות בע"מ | D36: 520007469 | E36: ח.פ | F36: מנורה מבטחים החזקות | G36: IL0005660183 | H36: ISIN | I36: מניות | J36: ישראל | K36: ישראל | L36: סחיר | M36: TASE | N36: ביטוח | O36: לא | P36: ILS | Q36: 7832 | R36: 1 | S36: 9800 | U36: 767.536 | V36: 0.000127 | W36: 0.018966488 | X36: 0.0020206707
A37: 1182 | B37: 1182 | C37: מניף - שירותים פיננסים בע"מ | D37: 512764408 | E37: ח.פ | F37: מניף | G37: IL0011708935 | H37: ISIN | I37: מניות | J37: ישראל | K37: ישראל | L37: סחיר | M37: TASE | N37: אשראי חוץ בנקאי | O37: לא | P37: ILS | Q37: 60804 | R37: 1 | S37: 1207 | U37: 733.904 | V37: 0.001005 | W37: 0.018135419 | X37: 0.0019321294
A38: 1182 | B38: 1182 | C38: מקס סטוק בע"מ | D38: 513618967 | E38: ח.פ | F38: מקס סטוק | G38: IL0011685588 | H38: ISIN | I38: מניות | J38: ישראל | K38: ישראל | L38: סחיר | M38: TASE | N38: רשתות שיווק | O38: לא | P38: ILS | Q38: 47143 | R38: 1 | S38: 841.6 | U38: 396.755 | V38: 0.000339 | W38: 0.0098041762 | X38: 0.0010445271
A39: 1182 | B39: 1182 | C39: ניו-מד אנרג'י- שותפות מוגבלת | D39: 550013098 | E39: ח.פ | F39: ניו-מד אנרג'י יהש | G39: IL0004750209 | H39: ISIN | I39: מניות | J39: ישראל | K39: ישראל | L39: סחיר | M39: TASE | N39: חיפושי נפט וגז | O39: לא | P39: ILS | Q39: 21816.21 | R39: 1 | S39: 935.3 | T39: 4.162 | U39: 208.209 | V39: 1.9e-05 | W39: 0.0051450293 | X39: 0.00054814628
A40: 1182 | B40: 1182 | C40: נייס מערכות בע"מ | D40: 520036872 | E40: ח.פ | F40: נייס | G40: IL0002730112 | H40: ISIN | I40: מניות | J40: ישראל | K40: ארה"ב | L40: סחיר | M40: TASE | N40: תוכנה ואינטרנט | O40: לא | P40: ILS | Q40: 1388 | R40: 1 | S40: 95150 | U40: 1320.682 | V40: 2.2e-05 | W40: 0.032635211 | X40: 0.0034769227
...

Sheet קרנות סל
A1: מספר קופה/קרן/ח.פ. עבור חברת ביטוח | B1: מספר מסלול | C1: שם מנפיק | D1: מספר מנפיק | E1: סוג מספר מזהה מנפיק | F1: שם נייר ערך | G1: מספר נייר ערך | H1: סוג מספר נייר ערך | I1: מאפיין עיקרי | J1: ישראל/חו"ל | K1: מדינה לפי חשיפה כלכלית | L1: זירת מסחר | M1: סיווג הקרן | N1: בעל עניין/צד קשור | O1: מטבע פעילות | P1: ערך נקוב (יחידות) | Q1: שער חליפין | R1: שער נייר הערך | S1: סכום לקבל (במטבע הפעילות) | T1: שווי הוגן (באלפי ש"ח) | U1: שיעור מערך נקוב מונפק | V1: שיעור מנכסי אפיק ההשקעה | W1: שיעור מסך נכסי ההשקעה
A2: 1182 | B2: 1182 | C2: מגדל קרנות נאמנות בע"מ | D2: 511303661 | E2: ח.פ | F2: MTF סל Nasdaq 100 (4D) | G2: IL0011813875 | H2: ISIN | I2: עוקב אחר מדדי מניות בחו"ל | J2: ישראל | K2: ארה"ב | L2: TASE | M2: מניות בחו"ל חשופות מט"ח | N2: לא | O2: ILS | P2: 5380 | Q2: 1 | R2: 9356 | T2: 503.353 | U2: 0.000849 | V2: 0.0054690331 | W2: 0.0013251629
A3: 1182 | B3: 1182 | C3: מגדל קרנות נאמנות בע"מ | D3: 511303661 | E3: ח.פ | F3: MTF סל תא 125 | G3: IL0011502833 | H3: ISIN | I3: עוקב אחר מדדי מניות בישראל | J3: ישראל | K3: ישראל | L3: TASE | M3: מניות בישראל | N3: לא | O3: ILS | P3: 15305 | Q3: 1 | R3: 3157 | T3: 483.179 | U3: 0.000382 | V3: 0.005249839 | W3: 0.0012720515
A4: 1182 | B4: 1182 | C4: מגדל קרנות נאמנות בע"מ | D4: 511303661 | E4: ח.פ | F4: MTF סל תא 35 | G4: IL0011501843 | H4: ISIN | I4: עוקב אחר מדדי מניות בישראל | J4: ישראל | K4: ישראל | L4: TASE | M4: מניות בישראל | N4: לא | O4: ILS | P4: 18700 | Q4: 1 | R4: 2713 | T4: 507.331 | U4: 0.000369 | V4: 0.0055122571 | W4: 0.0013356362
A5: 1182 | B5: 1182 | C5: מגדל קרנות נאמנות בע"מ | D5: 511303661 | E5: ח.פ | F5: MTF סל תא 90 | G5: IL0011502593 | H5: ISIN | I5: עוקב אחר מדדי מניות בישראל | J5: ישראל | K5: ישראל | L5: TASE | M5: מניות בישראל | N5: לא | O5: ILS | P5: 21395 | Q5: 1 | R5: 3091 | T5: 661.319 | U5: 0.000594 | V5: 0.0071853737 | W5: 0.0017410373
A6: 1182 | B6: 1182 | C6: מגדל קרנות נאמנות בע"מ | D6: 511303661 | E6: ח.פ | F6: SpUSA&D.MTF | G6: IL0011503419 | H6: ISIN | I6: עוקב אחר מדדי מניות בחו"ל | J6: ישראל | K6: ארה"ב | L6: TASE | M6: מניות בחו"ל חשופות מט"ח | N6: לא | O6: ILS | P6: 7580 | Q6: 1 | R6: 8701 | T6: 659.536 | U6: 0.002013 | V6: 0.007165994 | W6: 0.0017363415
A7: 1182 | B7: 1182 | C7: הראל קרנות נאמנות בע"מ | D7: 511776783 | E7: ח.פ | F7: הראל סל תא 90 | G7: IL0011489312 | H7: ISIN | I7: עוקב אחר מדדי מניות בישראל | J7: ישראל | K7: ישראל | L7: TASE | M7: מניות בישראל | N7: לא | O7: ILS | P7: 20973 | Q7: 1 | R7: 2053 | T7: 430.576 | U7: 0.00043 | V7: 0.0046782947 | W7: 0.0011335646
A8: 1182 | B8: 1182 | C8: הראל קרנות נאמנות בע"מ | D8: 511776783 | E8: ח.פ | F8: הראל קרן סל תא 125 | G8: IL0011488991 | H8: ISIN | I8: עוקב אחר מדדי מניות בישראל | J8: ישראל | K8: ישראל | L8: TASE | M8: מניות בישראל | N8: לא | O8: ILS | P8: 12121 | Q8: 1 | R8: 2014 | T8: 244.117 | U8: 0.000213 | V8: 0.0026523815 | W8: 0.00064267987
A9: 1182 | B9: 1182 | C9: מור ניהול קרנות נאמנות בע"מ | D9: 514884485 | E9: ח.פ | F9: מור סל )4D(י NASDAQ 100 | G9: IL0011658361 | H9: ISIN | I9: עוקב אחר מדדי מניות בחו"ל | J9: ישראל | K9: ארה"ב | L9: TASE | M9: מניות בחו"ל חשופות מט"ח | N9: לא | O9: ILS | P9: 9311 | Q9: 1 | R9: 10160 | T9: 945.998 | U9: 0.00098 | V9: 0.010278461 | W9: 0.0024905015
A10: 1182 | B10: 1182 | C10: מגדל קרנות נאמנות בע"מ | D10: 511303661 | E10: ח.פ | F10: סל mtf Trave l& Vacation | G10: IL0011675845 | H10: ISIN | I10: עוקב אחר מדדי מניות בחו"ל | J10: ישראל | K10: ארה"ב | L10: TASE | M10: מניות בחו"ל חשופות מט"ח | N10: לא | O10: ILS | P10: 4108 | Q10: 1 | R10: 3141 | T10: 129.032 | U10: 0.000205 | V10: 0.0014019626 | W10: 0.00033969969
A11: 1182 | B11: 1182 | C11: State Street Corp | D11: 549300E2D1JKWI3P9D54 | E11: LEI | F11: .UTILITIES SELECT S | G11: US81369Y8865 | H11: ISIN | I11: עוקב אחר מדדי מניות בחו"ל | J11: חו"ל | K11: ארה"ב | L11: NYSE | M11: Equity Funds | N11: לא | O11: USD | P11: 3240 | Q11: 3.681 | R11: 65.65 | T11: 782.971 | U11: 1.4e-05 | V11: 0.0085071409 | W11: 0.0020613054
A12: 1182 | B12: 1182 | C12: Invesco investment management limited | D12: 635400KFAN415FMIGG54 | E12: LEI | F12: AINVESCO AEROSPACE & DEFENSE ET | G12: US46137V1008 | H12: ISIN | I12: עוקב אחר מדדי מניות בחו"ל | J12: חו"ל | K12: ארה"ב | L12: NYSE | M12: Equity Funds | N12: לא | O12: USD | P12: 1706 | Q12: 3.681 | R12: 10157 | T12: 637.838 | U12: 8.8e-05 | V12: 0.0069302414 | W12: 0.001679218
A13: 1182 | B13: 1182 | C13: CREDIT AGRICOLE SA | D13: 969500TJ5KRTCJQWXH05 | E13: LEI | F13: AMUNDI ETF ICAV - AMUNDI MSCI | G13: 79279501 | H13: פנימי | I13: עוקב אחר מדדי מניות בחו"ל | J13: חו"ל | K13: צרפת | L13: NASDAQ | M13: Equity Funds | N13: לא | O13: USD | P13: 3184 | Q13: 3.681 | R13: 12389 | T13: 1452.028 | U13: 0 | V13: 0.015776592 | W13: 0.0038227149
... A42: 1182 | B42: 1182 | C42: State Street Corp | D42: 549300E2D1JKWI3P9D54 | E42: LEI | F42: NERGY S.SECTOR SPDR | G42: US81369Y5069 | H42: ISIN | I42: עוקב אחר מדדי מניות בחו"ל | J42: חו"ל | K42: ארה"ב | L42: NYSE | M42: Equity Funds | N42: לא | O42: USD | P42: 3507 | Q42: 3.681 | R42: 94.41 | T42: 1218.764 | U42: 8e-06 | V42: 0.013242124 | W42: 0.0032086058
A43: 1182 | B43: 1182 | C43: Invesco investment management limited | D43: 635400KFAN415FMIGG54 | E43: LEI | F43: Powershares QQQ NAS1 | G43: US46090E1038 | H43: ISIN | I43: עוקב אחר מדדי מניות בחו"ל | J43: חו"ל | K43: ארה"ב | L43: NASDAQ | M43: Equity Funds | N43: לא | O43: USD | P43: 1115 | Q43: 3.681 | R43: 444.01 | S43: 0.454 | T43: 1824.027 | U43: 2e-06 | V43: 0.019818437 | W43: 0.0048020658
A44: 1182 | B44: 1182 | C44: State Street Corp | D44: 549300E2D1JKWI3P9D54 | E44: LEI | F44: Real Estate Select Sector SPDR | G44: US81369Y8600 | H44: ISIN | I44: עוקב אחר מדדי מניות בחו"ל | J44: חו"ל | K44: ארה"ב | L44: NYSE | M44: Equity Funds | N44: לא | O44: USD | P44: 4858 | Q44: 3.681 | R44: 39.53 | T44: 706.887 | U44: 7.9e-05 | V44: 0.0076804773 | W44: 0.0018610024
A45: 1182 | B45: 1182 | C45: State Street Corp | D45: 549300E2D1JKWI3P9D54 | E45: LEI | F45: spdr Amex tech sel indx | G45: US81369Y8030 | H45: ISIN | I45: עוקב אחר מדדי מניות בחו"ל | J45: חו"ל | K45: ארה"ב | L45: NYSE | M45: Equity Funds | N45: לא | O45: USD | P45: 4896 | Q45: 3.681 | R45: 208.27 | T45: 3753.479 | U45: 1.6e-05 | V45: 0.040782328 | W45: 0.0098816786
A46: 1182 | B46: 1182 | C46: State Street Corp | D46: 549300E2D1JKWI3P9D54 | E46: LEI | F46: SPDR BL00MBERG SASB U.S HIGH | G46: IE00B99FL386 | H46: ISIN | I46: עוקב אחר מדדים אחרים בחו"ל | J46: חו"ל | K46: ארה"ב | L46: NASDAQ | M46: Bond/Fixed Income Funds | N46: לא | O46: USD | P46: 18000 | Q46: 3.681 | R46: 4007.5 | T46: 2655.289 | U46: 0 | V46: 0.028850272 | W46: 0.0069905063
A47: 1182 | B47: 1182 | C47: Real Estate Credit Investments Pcc ltd | D47: 549300D9O5F5P2DTYB19 | E47: LEI | F47: SPDR BLOOMBERG BAR | G47: US78488R4083 | H47: ISIN | I47: עוקב אחר מדדים אחרים בחו"ל | J47: חו"ל | K47: ארה"ב | L47: אחר | M47: Bond/Fixed Income Funds | N47: לא | O47: USD | P47: 16000 | Q47: 3.681 | R47: 2522 | T47: 1485.357 | U47: 0.000101 | V47: 0.016138715 | W47: 0.0039104583
A48: 1182 | B48: 1182 | C48: Real Estate Credit Investments Pcc ltd | D48: 549300D9O5F5P2DTYB19 | E48: LEI | F48: SPDR MSCI EUROPE CONSUMER DISC | G48: IE00BKWQ0C77 | H48: ISIN | I48: עוקב אחר מדדי מניות בחו"ל | J48: חו"ל | K48: אירופה | L48: EURONEXT | M48: Equity Funds | N48: לא | O48: EUR | P48: 900 | Q48: 3.979 | R48: 18642 | T48: 667.605 | U48: 0.001029 | V48: 0.0072536723 | W48: 0.0017575863
A49: 1182 | B49: 1182 | C49: Van Eck ETF | D49: 549300WSDUDKDJCJOV22 | E49: LEI | F49: VANECK VECTORS SEMICONDUCTOR | G49: US92189F6768 | H49: ISIN | I49: עוקב אחר מדדי מניות בחו"ל | J49: חו"ל | K49: ארה"ב | L49: NASDAQ | M49: Equity Funds | N49: לא | O49: USD | P49: 1043 | Q49: 3.681 | R49: 22499 | T49: 863.8 | U49: 4.6e-05 | V49: 0.0093853702 | W49: 0.0022741029
A50: 1182 | B50: 1182 | C50: Vanguard Group | D50: QS6WHLCJOJSYY4PYNF72 | E50: LEI | F50: VANGUARD S&P MID-CAP 400 ETF | G50: US9219328856 | H50: ISIN | I50: עוקב אחר מדדי מניות בחו"ל | J50: חו"ל | K50: ארה"ב | L50: NYSE | M50: Equity Funds | N50: לא | O50: USD | P50: 8340 | Q50: 3.681 | R50: 10301 | T50: 3162.36 | U50: 0.001046 | V50: 0.034359697 | W50: 0.0083254561
A51: 1182 | B51: 1182 | C51: WisdomTree Europe ltd | D51: 549300R6SLTQ0LZOHH17 | E51: LEI | F51: Wisdomtree em ex-state-owned D E | G51: US97717X5784 | H51: ISIN | I51: עוקב אחר מדדי מניות בחו"ל | J51: חו"ל | K51: גלובלי | L51: NYSE | M51: Equity Funds | N51: לא | O51: USD | P51: 12340 | Q51: 3.681 | R51: 2946 | T51: 1338.177 | U51: 0.000141 | V51: 0.014539577 | W51: 0.0035229826
A52: 1182 | B52: 1182 | C52: WisdomTree Europe ltd | D52: 549300R6SLTQ0LZOHH17 | E52: LEI | F52: WISDOMTREE INDI | G52: US97717W4226 | H52: ISIN | I52: עוקב אחר מדדי מניות בחו"ל | J52: חו"ל | K52: הודו | L52: NYSE | M52: Equity Funds | N52: לא | O52: USD | P52: 17508 | Q52: 3.681 | R52: 43.56 | T52: 2807.309 | U52: 0.000796 | V52: 0.030501998 | W52: 0.0073907244
A53: 1182 | B53: 1182 | C53: DB x TRACKERS | D53: 549300GFAB28PI25Z431 | E53: LEI | F53: XTRXCKERS NIKKEI 225 UCITS ETF | G53: LU0839027447 | H53: ISIN | I53: עוקב אחר מדדי מניות בחו"ל | J53: חו"ל | K53: יפן | L53: FWB | M53: Equity Funds | N53: לא | O53: EUR | P53: 56629 | Q53: 3.979 | R53: 2551.5 | T53: 5749.358 | U53: 0.00095 | V53: 0.062467969 | W53: 0.015136174
A54: 1182 | B54: 14769 | C54: קסם קרנות נאמנות בע"מ | D54: 510938608 | E54: ח.פ | F54: FTSE 100 (4D) ETF קסם | G54: IL0011464976 | H54: ISIN | I54: עוקב אחר מדדי מניות בחו"ל | J54: ישראל | K54: בריטניה | L54: TASE | M54: מניות בחו"ל חשופות מט"ח | N54: לא | O54: ILS | P54: 1098 | Q54: 1 | R54: 4148 | T54: 45.545 | U54: 7e-05 | V54: 0.0088512996 | W54: 0.0058382091
A55: 1182 | B55: 14769 | C55: מגדל קרנות נאמנות בע"מ | D55: 511303661 | E55: ח.פ | F55: MTF סל תא 90 | G55: IL0011502593 | H55: ISIN | I55: עוקב אחר מדדי מניות בישראל | J55: ישראל | K55: ישראל | L55: TASE | M55: מניות בישראל | N55: לא | O55: ILS | P55: 6930 | Q55: 1 | R55: 3091 | T55: 214.206 | U55: 0.000192 | V55: 0.041629212 | W55: 0.02745812
... A63: 1182 | B63: 14769 | C63: קסם קרנות נאמנות בע"מ | D63: 510938608 | E63: ח.פ | F63: קסם S&P 500 (4D) ETF | G63: IL0011464711 | H63: ISIN | I63: עוקב אחר מדדי מניות בחו"ל | J63: ישראל | K63: ארה"ב | L63: TASE | M63: מניות בחו"ל חשופות מט"ח | N63: לא | O63: ILS | P63: 157 | Q63: 1 | R63: 21080 | T63: 33.096 | U63: 1e-05 | V63: 0.0064318545 | W63: 0.0042423727
A64: 1182 | B64: 14769 | C64: קסם קרנות נאמנות בע"מ | D64: 510938608 | E64: ח.פ | F64: קסםXOTS006. | G64: IL0011462087 | H64: ISIN | I64: עוקב אחר מדדי מניות בחו"ל | J64: ישראל | L64: אחר | M64: מניות בחו"ל חשופות מט"ח | N64: לא | O64: ILS | P64: 68 | Q64: 1 | R64: 46860 | T64: 31.865 | U64: 3.5e-05 | V64: 0.0061926587 | W64: 0.0040846021
A65: 1182 | B65: 14769 | C65: State Street Corp | D65: 549300E2D1JKWI3P9D54 | E65: LEI | F65: .UTILITIES SELECT S | G65: US81369Y8865 | H65: ISIN | I65: עוקב אחר מדדי מניות בחו"ל | J65: חו"ל | K65: ארה"ב | L65: NYSE | M65: Equity Funds | N65: לא | O65: USD | P65: 141 | Q65: 3.681 | R65: 65.65 | T65: 34.074 | U65: 1e-06 | V65: 0.0066219456 | W65: 0.0043677545
A66: 1182 | B66: 14769 | C66: Invesco investment management limited | D66: 635400KFAN415FMIGG54 | E66: LEI | F66: AINVESCO AEROSPACE & DEFENSE ET | G66: US46137V1008 | H66: ISIN | I66: עוקב אחר מדדי מניות בחו"ל | J66: חו"ל | K66: ארה"ב | L66: NYSE | M66: Equity Funds | N66: לא | O66: USD | P66: 66 | Q66: 3.681 | R66: 10157 | T66: 24.676 | U66: 3e-06 | V66: 0.0047955802 | W66: 0.0031631061
A67: 1182 | B67: 14769 | C67: CREDIT AGRICOLE SA | D67: 969500TJ5KRTCJQWXH05 | E67: LEI | F67: AMUNDI ETF ICAV - AMUNDI MSCI | G67: 79279501 | H67: פנימי | I67: עוקב אחר מדדי מניות בחו"ל | J67: חו"ל | K67: צרפת | L67: NASDAQ | M67: Equity Funds | N67: לא | O67: USD | P67: 602 | Q67: 3.681 | R67: 12389 | T67: 274.536 | U67: 0 | V67: 0.053353696 | W67: 0.035191446
A68: 1182 | B68: 14769 | C68: Amundi Asset Management | D68: 549300W6M26WPJCWRV83 | E68: LEI | F68: AMUNDI MSCI EMERGING MARKETS I | G68: LU2573967036 | H68: ISIN | I68: עוקב אחר מדדי מניות בחו"ל | J68: חו"ל | K68: שווקים מתעוררים | L68: NASDAQ | M68: Equity Funds | N68: לא | O68: USD | P68: 403 | Q68: 3.681 | R68: 4968.5 | T68: 73.705 | U68: 0 | V68: 0.014323927 | W68: 0.0094478875
A69: 1182 | B69: 14769 | C69: Amundi Asset Management | D69: 549300W6M26WPJCWRV83 | E69: LEI | F69: AMUNDI MSCI EUROPE QUALITY FAC | G69: LU1681041890 | H69: ISIN | I69: עוקב אחר מדדי מניות בחו"ל | J69: חו"ל | K69: צרפת | L69: EURONEXT | M69: Equity Funds | N69: לא | O69: EUR | P69: 132 | Q69: 3.979 | R69: 11016 | T69: 57.861 | U69: 2.6e-05 | V69: 0.01124472 | W69: 0.0074168803
A70: 1182 | B70: 14769 | C70: Amundi Asset Management | D70: 549300W6M26WPJCWRV83 | E70: LEI | F70: AMUNDI US CURVE STEEPENING 2-1 | G70: LU2018762653 | H70: ISIN | I70: עוקב אחר מדדי מניות בחו"ל | J70: חו"ל | K70: ארה"ב | L70: LSE | M70: Equity Funds | N70: לא | O70: USD | P70: 101 | Q70: 3.681 | R70: 9308 | T70: 34.605 | U70: 0 | V70: 0.0067252668 | W70: 0.0044359038
A71: 1182 | B71: 14769 | C71: State Street Corp | D71: 549300E2D1JKWI3P9D54 | E71: LEI | F71: COMMUNICATION SERVICES SELECT | G71: US81369Y8527 | H71: ISIN | I71: עוקב אחר מדדי מניות בחו"ל | J71: חו"ל | K71: ארה"ב | L71: NYSE | M71: Equity Funds | N71: לא | O71: USD | P71: 33 | Q71: 3.681 | R71: 81.66 | T71: 9.919 | U71: 0 | V71: 0.0019277694 | W71: 0.0012715332
A72: 1182 | B72: 14769 | C72: State Street Corp | D72: 549300E2D1JKWI3P9D54 | E72: LEI | F72: Consumer discretionary etf | G72: us81369y4070 | H72: ISIN | I72: עוקב אחר מדדי מניות בחו"ל | J72: חו"ל | K72: ארה"ב | L72: NYSE | M72: Equity Funds | N72: לא | O72: USD | P72: 46 | Q72: 3.681 | R72: 183.89 | T72: 31.137 | U72: 0 | V72: 0.0060512865 | W72: 0.0039913546
A73: 1182 | B73: 14769 | C73: BlackRock Asset Managment | D73: 549300IJBBIPXKWNXJ28 | E73: LEI | F73: DIVORP ERACHTLAEH .S | G73: US4642888287 | H73: ISIN | I73: עוקב אחר מדדי מניות בחו"ל | J73: חו"ל | K73: ארה"ב | L73: NYSE | M73: Equity Funds | N73: לא | O73: USD | P73: 25 | Q73: 3.681 | R73: 5454 | T73: 5.019 | U73: 4e-06 | V73: 0.00097540934 | W73: 0.00064336809
A74: 1182 | B74: 14769 | C74: State Street Corp | D74: 549300E2D1JKWI3P9D54 | E74: LEI | F74: Financial sel sector spdr | G74: US81369Y6059 | H74: ISIN | I74: עוקב אחר מדדי מניות בחו"ל | J74: חו"ל | K74: ארה"ב | L74: NYSE | M74: Equity Funds | N74: לא | O74: USD | P74: 590 | Q74: 3.681 | R74: 42.12 | T74: 91.476 | U74: 1e-06 | V74: 0.01777756 | W74: 0.011725861
A75: 1182 | B75: 14769 | C75: First trust | D75: 549300QT3GGKQPIIB521 | E75: LEI | F75: First Trust Nas | G75: US3373451026 | H75: ISIN | I75: עוקב אחר מדדי מניות בחו"ל | J75: חו"ל | K75: ארה"ב | L75: NASDAQ | M75: Equity Funds | N75: לא | O75: USD | P75: 40 | Q75: 3.681 | R75: 19068 | T75: 28.076 | U75: 3e-06 | V75: 0.0054562832 | W75: 0.0035988978
...

Sheet קרנות נאמנות
A1: מספר קופה/קרן/ח.פ. עבור חברת ביטוח | B1: מספר מסלול | C1: שם מנפיק | D1: מספר מנפיק | E1: סוג מספר מזהה מנפיק | F1: שם נייר ערך | G1: מספר נייר ערך | H1: סוג מספר נייר ערך | I1: מאפיין עיקרי | J1: ישראל/חו"ל | K1: מדינה לפי חשיפה כלכלית | L1: סטאטוס סחירות | M1: זירת מסחר | N1: סיווג הקרן | O1: בעל עניין/צד קשור | P1: מטבע פעילות | Q1: ערך נקוב (יחידות) | R1: שער חליפין | S1: שער נייר הערך | T1: שווי הוגן (באלפי ש"ח) | U1: שיעור מערך נקוב מונפק | V1: שיעור מנכסי אפיק ההשקעה | W1: שיעור מסך נכסי ההשקעה
A2: 1182 | B2: 1182 | C2: Comgest | D2: 635400JYB1RHBTRDH390 | E2: LEI | F2: COMGEST GROWTH PLC - EURO | G2: IE0004766675 | H2: ISIN | I2: מניות | J2: חו"ל | K2: אירופה | L2: סחיר | M2: ISE | N2: Equity Funds | O2: לא | P2: EUR | Q2: 5997.08 | R2: 3.979 | S2: 5063 | T2: 1208.183 | U2: 0.00022 | V2: 0.076617475 | W2: 0.003180749
A3: 1182 | B3: 1182 | C3: Investec | D3: 549300X3ENFKGMH04N42 | E3: LEI | F3: IGS-EMERG MKT CORP DEBT-IUSD | G3: LU0611395327 | H3: ISIN | I3: אג"ח קונצרני | J3: חו"ל | K3: לוכסמבורג | L3: סחיר | M3: אחר | N3: Bond/Fixed Income Funds | O3: לא | P3: USD | Q3: 6970.12 | R3: 3.681 | S3: 3303 | T3: 847.451 | U3: 0.000161 | V3: 0.053741509 | W3: 0.0022310609
A4: 1182 | B4: 1182 | C4: Invesco investment management limited | D4: 635400KFAN415FMIGG54 | E4: LEI | F4: IUSSENG LX Equity | G4: LU0564079282 | H4: ISIN | I4: אג"ח קונצרני | J4: חו"ל | K4: גלובלי | L4: סחיר | M4: ISE | N4: Bond/Fixed Income Funds | O4: לא | P4: USD | Q4: 2848.35 | R4: 3.681 | S4: 17736 | T4: 1859.58 | U4: 0.000313 | V4: 0.11792613 | W4: 0.0048956643
A5: 1182 | B5: 1182 | C5: KBI Global Investors | D5: 635400UCQYVGO94KDT51 | E5: LEI | F5: KBI FUND ICAV -KBI ENERGY SOL | G5: IE00BNGJJ156 | H5: ISIN | I5: מניות | J5: חו"ל | K5: גלובלי | L5: סחיר | M5: ISE | N5: Equity Funds | O5: לא | P5: USD | Q5: 40605.74 | R5: 3.681 | S5: 978.2 | T5: 1462.113 | U5: 0.003214 | V5: 0.092720575 | W5: 0.0038492639
A6: 1182 | B6: 1182 | C6: Kotak | D6: 549300P1V22EKK1UCL34 | E6: LEI | F6: KOTAK FDS-INDIA MIDCAP (S) USD A | G6: LU2126068639 | H6: ISIN | I6: מניות | J6: חו"ל | K6: לוכסמבורג | L6: סחיר | M6: אחר | N6: Equity Funds | O6: לא | P6: USD | Q6: 28772.31 | R6: 3.681 | S6: 1294.89 | T6: 1371.429 | U6: 0 | V6: 0.086969833 | W6: 0.0036105237
A7: 1182 | B7: 1182 | C7: Lombard Odier Funds-Asia Value | D7: 5493001DJ8NYPLGGID75 | E7: LEI | F7: LOMBARD ODIER-ASIA INV.GR.BD(I | G7: LU2083909536 | H7: ISIN | I7: מניות | J7: חו"ל | K7: אסיה | L7: סחיר | M7: אחר | N7: Equity Funds | O7: לא | P7: USD | Q7: 29128.48 | R7: 3.681 | S7: 1045.75 | T7: 1121.273 | U7: 0 | V7: 0.071106078 | W7: 0.0029519452
A8: 1182 | B8: 1182 | C8: LUXEMBOURG LIFE | D8: 89900 | E8: פנימי | F8: LUXEMBOURG LIFE | G8: lu24283023721 | H8: ISIN | I8: מניות | J8: חו"ל | K8: ארה"ב | L8: סחיר | M8: אחר | N8: Equity Funds | O8: לא | P8: USD | Q8: 4000 | R8: 3.681 | S8: 11473 | T8: 1689.285 | U8: 0 | V8: 0.10712677 | W8: 0.0044473323
A9: 1182 | B9: 1182 | D9: GZYUYYBVN9JCLNYWZ615 | E9: LEI | F9: MGLEUCA LX Equity | G9: LU1670632501 | H9: ISIN | I9: אחר | J9: חו"ל | K9: גלובלי | L9: סחיר | M9: אחר | N9: Other | O9: לא | P9: USD | Q9: 59547.05 | R9: 3.681 | S9: 1199.66 | T9: 2629.567 | U9: 0 | V9: 0.16675523 | W9: 0.0069227879
A10: 1182 | B10: 1182 | C10: PRINCIPAL FINANCIAL | D10: 549300MS0GBEZOTILG43 | E10: LEI | F10: PRINCIPAL GLOBAL INVEST | G10: IE00BKDW9G15 | H10: ISIN | I10: אג"ח קונצרני | J10: חו"ל | K10: אירלנד | L10: סחיר | M10: ISE | N10: Bond/Fixed Income Funds | O10: לא | P10: USD | Q10: 85932.43 | R10: 3.681 | S10: 1131.82 | T10: 3580.142 | U10: 0.00348 | V10: 0.2270364 | W10: 0.0094253406
A11: 1182 | B11: 14769 | C11: Invesco investment management limited | D11: 635400KFAN415FMIGG54 | E11: LEI | F11: IUSSENG LX Equity | G11: LU0564079282 | H11: ISIN | I11: אג"ח קונצרני | J11: חו"ל | K11: גלובלי | L11: סחיר | M11: ISE | N11: Bond/Fixed Income Funds | O11: לא | P11: USD | Q11: 17.09 | R11: 3.681 | S11: 17736 | T11: 11.157 | U11: 2e-06 | V11: 0.11335188 | W11: 0.0014302176
A12: 1182 | B12: 14769 | C12: KBI Global Investors | D12: 635400UCQYVGO94KDT51 | E12: LEI | F12: KBI FUND ICAV -KBI ENERGY SOL | G12: IE00BNGJJ156 | H12: ISIN | I12: מניות | J12: חו"ל | K12: גלובלי | L12: סחיר | M12: ISE | N12: Equity Funds | O12: לא | P12: USD | Q12: 999.43 | R12: 3.681 | S12: 978.2 | T12: 35.987 | U12: 7.9e-05 | V12: 0.36560406 | W12: 0.0046130102
A13: 1182 | B13: 14769 | C13: Kotak | D13: 549300P1V22EKK1UCL34 | E13: LEI | F13: KOTAK FDS-INDIA MIDCAP (S) USD A | G13: LU2126068639 | H13: ISIN | I13: מניות | J13: חו"ל | K13: לוכסמבורג | L13: סחיר | M13: אחר | N13: Equity Funds | O13: לא | P13: USD | Q13: 801.55 | R13: 3.681 | S13: 1294.89 | T13: 38.206 | U13: 0 | V13: 0.38814542 | W13: 0.0048974258
A14: 1182 | B14: 14769 | C14: Lombard Odier Funds-Asia Value | D14: 5493001DJ8NYPLGGID75 | E14: LEI | F14: LOMBARD ODIER-ASIA INV.GR.BD(I | G14: LU2083909536 | H14: ISIN | I14: מניות | J14: חו"ל | K14: אסיה | L14: סחיר | M14: אחר | N14: Equity Funds | O14: לא | P14: USD | Q14: 339.83 | R14: 3.681 | S14: 1045.75 | T14: 13.081 | U14: 0 | V14: 0.13289865 | W14: 0.001676849
A15: 12904 | B15: 12905 | C15: Invesco investment management limited | D15: 635400KFAN415FMIGG54 | E15: LEI | F15: INVESCO GLOBAL INVESTMENT GRAD | G15: LU1218206339 | H15: ISIN | I15: אג"ח קונצרני | J15: חו"ל | K15: גלובלי | L15: סחיר | M15: אחר | N15: Bond/Fixed Income Funds | O15: לא | P15: USD | Q15: 2821.86 | R15: 3.681 | S15: 1242.53 | T15: 129.065 | U15: 0 | V15: 0.14267373 | W15: 0.0044578973
A16: 12904 | B16: 12905 | C16: Invesco investment management limited | D16: 635400KFAN415FMIGG54 | E16: LEI | F16: IUSSENG LX Equity | G16: LU0564079282 | H16: ISIN | I16: אג"ח קונצרני | J16: חו"ל | K16: גלובלי | L16: סחיר | M16: ISE | N16: Bond/Fixed Income Funds | O16: לא | P16: USD | Q16: 210.78 | R16: 3.681 | S16: 17736 | T16: 137.61 | U16: 2.3e-05 | V16: 0.15212015 | W16: 0.0047530545
