Workbook
Name Additional_Factor: 'אפשרויות בחירה'!$C$701:$C$850
Name Amoritization: 'אפשרויות בחירה'!$C$546:$C$550
Name Capsule: 'אפשרויות בחירה'!$C$926:$C$928
Name Company_Name: 'File Name Info'!$A$34:$A$120
Name Company_Name_ID: 'File Name Info'!$A$34:$B$120
Name Consortium: 'אפשרויות בחירה'!$C$514:$C$515
Name Country_list: 'אפשרויות בחירה'!$C$4:$C$85
Name Country_list_funds: 'אפשרויות בחירה'!$C$4:$C$103
Name CSA: 'אפשרויות בחירה'!$C$688:$C$689
Name Delivery: 'אפשרויות בחירה'!$C$666:$C$667
Name Dependence_Independence: 'אפשרויות בחירה'!$C$654:$C$655
Name Duration_Underlying_Interest_Rate: 'אפשרויות בחירה'!$C$680:$C$687
Name File_Type: 'File Name Info'!$A$10:$A$12
Name Full_File_Type: 'File Name Info'!$A$11:$B$13
Name Full_Type: 'File Name Info'!$A$2:$B$8
Name Full_Type_Nostro: 'File Name Info'!$A$3:$B$6
Name Full_Year: 'File Name Info'!$A$22:$B$31
Name Fund_Strategy: 'אפשרויות בחירה'!$C$597:$C$621
Name Fund_type: 'אפשרויות בחירה'!$C$328:$C$498
Name Holding_interest: 'אפשרויות בחירה'!$C$146:$C$147
Name In_the_books: 'אפשרויות בחירה'!$C$656:$C$657
Name Industry_Sector: 'אפשרויות בחירה'!$C$1129:$C$1245
Name Industry_sector_all: 'אפשרויות בחירה'!$C$202:$C$327
Name Industry_sectors: 'אפשרויות בחירה'!$C$202:$C$327
Name israel_abroad: 'אפשרויות בחירה'!$C$2:$C$3
Name Issuer_Number_Banks: 'אפשרויות בחירה'!$C$111:$C$113
Name Issuer_Number_Fund: 'אפשרויות בחירה'!$C$114:$C$117
Name issuer_number_loan: 'אפשרויות בחירה'!$C$118:$C$126
Name Issuer_Number_Type: 'אפשרויות בחירה'!$C$104:$C$110
Name Issuer_Number_Type_2: 'אפשרויות בחירה'!$C$1076:$C$1079
Name Issuer_Number_Type_3: 'אפשרויות בחירה'!$C$1081:$C$1085
Name Issuer_Number_Type_V2: 'אפשרויות בחירה'!$C$104:$C$110
Name Issuer_Type_TFunds: 'אפשרויות בחירה'!$C$1087:$C$1089
Name Leading_factor: 'אפשרויות בחירה'!$C$692:$C$700
Name Linked_Type: 'אפשרויות בחירה'!$C$516:$C$519
Name other_investments: 'אפשרויות בחירה'!$C$1000:$C$1033
Name Penalty: 'אפשרויות בחירה'!$C$851:$C$852
Name QTR: 'File Name Info'!$A$15:$A$19
Name Rating_Agency: 'אפשרויות בחירה'!$C$188:$C$201
Name real_estate_lifestage: 'אפשרויות בחירה'!$C$634:$C$642
Name real_estate_loans: 'אפשרויות בחירה'!$C$553:$C$591
Name Real_Estate_Main_Use: 'אפשרויות בחירה'!$C$622:$C$633
Name Recourse_Nonrecourse: 'אפשרויות בחירה'!$C$544:$C$545
Name Repayment_Rights: 'אפשרויות בחירה'!$C$551:$C$552
Name Reset_frequency: 'אפשרויות בחירה'!$C$658:$C$665
Name Security_ID_Number_Type: 'אפשרויות בחירה'!$C$1113:$C$1116
Name Security_Number_Loans: 'אפשרויות בחירה'!$C$131
Name Stock_Exchange: 'אפשרויות בחירה'!$C$1283:$C$1315
Name Stock_Exchange_Gov_Bonds: 'אפשרויות בחירה'!$C$148:$C$181
Name Subordination_Risk: 'אפשרויות בחירה'!$C$186:$C$187
Name Tradeable_Status: 'אפשרויות בחירה'!$C$1272:$C$1281
Name Tradeable_Status_All: 'אפשרויות בחירה'!$C$135:$C$145
Name tradeable_status_bonds: 'אפשרויות בחירה'!$C$1248:$C$1253
Name tradeable_status_funds: 'אפשרויות בחירה'!$C$1118:$C$1119
Name tradeable_status_stock: 'אפשרויות בחירה'!$C$1255:$C$1259
Name Tradeable_Status_v2: 'אפשרויות בחירה'!$C$1121:$C$1126
Name tradeable_status_warrants: 'אפשרויות בחירה'!$C$1261:$C$1265
Name tradeable_status_warrants_v2: 'אפשרויות בחירה'!$C$1267:$C$1269
Name Transaction: 'אפשרויות בחירה'!$C$643:$C$646
Name Type: 'File Name Info'!$A$2:$A$8

Sheet עמוד פתיחה
A1: קובץ דיווח עבור רשימת נכסים ברמת הנכס הבודד (חוזר גופים מוסדיים 2015-9-14)
A3: יש לבחור תחום: | D3: נכסי עמיתים - קופות גמל
A5: האם מדובר בקובץ לממומנה או לציבור:
A7: יש לבחור את רבעון הדיווח:
A9: יש לבחור את שנת הדיווח:
A11: יש לבחור את הגוף המוסדי:
A13: ח.פ. הגוף המוסדי: | D13: =IFERROR(VLOOKUP(D11,'File Name Info'!A35:B121,2,0),"תא מחושב") -> תא מחושב
A15: שם קובץ לשמירה | D15: =IF(D5="לממונה",CONCATENATE(D13, "_",VLOOKUP(D3,Full_Type,2,0),"_",D7,VLOOKUP(D9,Full_Year,2,0),".xlxs"),IF(D5="לציבור",CONCATENATE(D13,"_",VLOOKUP(D3,Full_Type_Nostro,2,0),"_",VLOOKUP(D5,Full_File_Type,2,0),"_",D7,VLOOKUP(D9,Full_Year,2,0),".xlsx"),"שם קובץ לשמירה")) -> שם קובץ לשמירה
A17: פרטי האחראי על הדיווח בגוף המוסדי | B17: שם:
B19: מספר טלפון:
B21: כתובת מייל:
A23: הוראות למילוי הדיווח: | D23: יש לדווח לפי ההנחיות בחלק ג' לנספח 5.4.3.2 שבפרק 3 שבחלק 4 לשער 5 בחוזר המאוחד - "רשימת נכסים ברמת הנכס הבודד".

Sheet סכום נכסים
C1: ידווח בקבצי נכסי הנוסטרו בלבד
B2: שווי הוגן | C2: עלות מופחתת | D2: השיטה שיושמה בדוח הכספי | E2: שיעור מסך נכסי השקעה
A3: מזומנים ושווי מזומנים | B3: =SUM('מזומנים ושווי מזומנים'!O:O) -> 57099.609 | D3: =B3+C3 -> 57099.609 | E3: =SUM('מזומנים ושווי מזומנים'!O:O)/B30 -> 0.049061827
A4: איגרות חוב ממשלתיות | B4: =SUM('איגרות חוב ממשלתיות'!U:U) -> 252168.13 | D4: =B4+C4 -> 252168.13 | E4: =SUM('איגרות חוב ממשלתיות'!U:U)/B30 -> 0.216671
A5: ניירות ערך מסחריים | B5: =SUM('ניירות ערך מסחריים'!AD:AD) -> 931.542 | D5: =B5+C5 -> 931.542 | E5: =SUM('ניירות ערך מסחריים'!AD:AD)/B30 -> 0.00080041095
A6: איגרות חוב | B6: =SUM('איגרות חוב'!AD:AD) -> 179439.1 | D6: =B6+C6 -> 179439.1 | E6: =SUM('איגרות חוב'!AD:AD)/B30 -> 0.15417987
A7: מניות, מניות בכורה ויחידות השתתפות | B7: =SUM('מניות מבכ ויהש'!U:U) -> 168001.35 | D7: =B7+C7 -> 168001.35 | E7: =SUM('מניות מבכ ויהש'!U:U)/B30 -> 0.14435218
A8: קרנות סל | B8: =SUM('קרנות סל'!T:T) -> 250540.48 | D8: =B8+C8 -> 250540.48 | E8: =SUM('קרנות סל'!T:T)/B30 -> 0.21527247
A9: קרנות נאמנות | B9: =SUM('קרנות נאמנות'!T:T) -> 8024.993 | D9: =B9+C9 -> 8024.993 | E9: =SUM('קרנות נאמנות'!T:T)/B30 -> 0.006895333
A10: כתבי אופציה | B10: =SUM('כתבי אופציה'!W:W) -> 281.904 | D10: =B10+C10 -> 281.904 | E10: =SUM('כתבי אופציה'!W:W)/B30 -> 0.00024222102
A11: אופציות | B11: =SUM(אופציות!V:V) -> 0 | D11: =B11+C11 -> 0 | E11: =SUM(אופציות!V:V)/B30 -> 0
A12: חוזים עתידיים | B12: =SUM('חוזים עתידיים'!R:R) -> 4693.77 | D12: =B12+C12 -> 4693.77 | E12: =SUM('חוזים עתידיים'!R:R)/B30 -> 0.0040330387
A13: מוצרים מובנים | B13: =SUM('מוצרים מובנים'!Z:Z) -> 977.187 | D13: =B13+C13 -> 977.187 | E13: =SUM('מוצרים מובנים'!Z:Z)/B30 -> 0.00083963061
A14: לא סחיר איגרות חוב ממשלתיות | B14: =SUM('לא סחיר איגרות חוב ממשלתיות'!U:U) -> 0 | D14: =B14+C14 -> 0 | E14: =SUM('לא סחיר איגרות חוב ממשלתיות'!U:U)/B30 -> 0
A15: לא סחיר איגרות חוב מיועדות | B15: =SUM('לא סחיר איגרות חוב מיועדות'!N:N) -> 0 | D15: =B15+C15 -> 0 | E15: =SUM('לא סחיר איגרות חוב מיועדות'!N:N)/B30 -> 0
A16: אפיק השקעה מובטח תשואה | B16: =SUM('אפיק השקעה מובטח תשואה'!F:F) -> 0 | D16: =B16+C16 -> 0 | E16: =SUM('אפיק השקעה מובטח תשואה'!F:F)/B30 -> 0
A17: לא סחיר ניירות ערך מסחריים | B17: =SUM('לא סחיר ניירות ערך מסחריים'!AI:AI) -> 2240.2 | D17: =B17+C17 -> 2240.2 | E17: =SUM('לא סחיר ניירות ערך מסחריים'!AI:AI)/B30 -> 0.0019248521
A18: לא סחיר איגרות חוב | B18: =SUM('לא סחיר איגרות חוב'!AG:AG) -> 11848.375 | D18: =B18+C18 -> 11848.375 | E18: =SUM('לא סחיר איגרות חוב'!AG:AG)/B30 -> 0.010180506
A19: לא סחיר מניות, מניות בכורה ויחידות השתתפות | B19: =SUM('לא סחיר מניות מבכ ויהש'!X:X) -> 13229.949 | D19: =B19+C19 -> 13229.949 | E19: =SUM('לא סחיר מניות מבכ ויהש'!X:X)/B30 -> 0.011367599
A20: קרנות השקעה | B20: =SUM('קרנות השקעה'!W:W) -> 213737.88 | D20: =B20+C20 -> 213737.88 | E20: =SUM('קרנות השקעה'!W:W)/B30 -> 0.18365049
A21: לא סחיר כתבי אופציה | B21: =SUM('לא סחיר כתבי אופציה'!Z:Z) -> 10.381 | D21: =B21+C21 -> 10.381 | E21: =SUM('לא סחיר כתבי אופציה'!Z:Z)/B30 -> 8.9196903e-06
A22: לא סחיר אופציות | B22: =SUM('לא סחיר אופציות'!Z:Z) -> 0 | D22: =B22+C22 -> 0 | E22: =SUM('לא סחיר אופציות'!Z:Z)/B30 -> 0
A23: לא סחיר נגזרים אחרים | B23: =SUM('לא סחיר נגזרים אחרים'!R:R) -> -766.731 | D23: =B23+C23 -> -766.731 | E23: =SUM('לא סחיר נגזרים אחרים'!R:R)/B30 -> -0.00065880002
A24: הלוואות | B24: =SUM(הלוואות!AT:AT) -> 654.806 | D24: =B24+C24 -> 654.806 | E24: =SUM(הלוואות!AT:AT)/B30 -> 0.00056263045
A25: לא סחיר מוצרים מובנים | B25: =SUM('לא סחיר מוצרים מובנים'!AB:AB) -> 0 | D25: =B25+C25 -> 0 | E25: =SUM('לא סחיר מוצרים מובנים'!AB:AB)/B30 -> 0
A26: פיקדונות מעל 3 חודשים | B26: =SUM('פיקדונות מעל 3 חודשים'!T:T) -> 0 | D26: =B26+C26 -> 0 | E26: =SUM('פיקדונות מעל 3 חודשים'!T:T)/B30 -> 0
A27: זכויות מקרקעין | B27: =SUM('זכויות מקרקעין'!S:S) -> 0 | D27: =B27+C27 -> 0 | E27: =SUM('זכויות מקרקעין'!S:S)/B30 -> 0
A28: השקעה בחברות מוחזקות | B28: =SUM('השקעה בחברות מוחזקות'!U:U) -> 0 | D28: =B28+C28 -> 0 | E28: =SUM('השקעה בחברות מוחזקות'!U:U)/B30 -> 0
A29: נכסים אחרים | B29: =SUM('נכסים אחרים'!N:N) -> 716.716 | D29: =B29+C29 -> 716.716 | E29: =SUM('נכסים אחרים'!N:N)/B30 -> 0.00061582552
A30: סך הכל נכסים | B30: =IF(SUM(B3:B29)=0,0.0001,SUM(B3:B29)) -> 1163829.6 | C30: =SUM(C3:C29) -> 0 | D30: =SUM(D3:D29) -> 1163829.6 | E30: =SUM(E3:E29) -> 1
A31: מסגרות אשראי
A32: יתרות התחייבויות להשקעה | B32: =SUM('יתרות התחייבות להשקעה'!O:O) -> 53859.235

Sheet מזומנים ושווי מזומנים
A1: מספר קופה/קרן/ח.פ. עבור חברת ביטוח | B1: מספר מסלול | C1: שם הבנק | D1: מספר מזהה בנק | E1: סוג מספר מזהה בנק | F1: מאפיין עיקרי | G1: ישראל/חו"ל | H1: בעל עניין/צד קשור | I1: דירוג הבנק | J1: שם מדרג | K1: מטבע פעילות | L1: שווי מטבעי | M1: שער חליפין | N1: שיעור ריבית | O1: שווי הוגן (באלפי ש"ח) | P1: שיעור מנכסי אפיק ההשקעה | Q1: שיעור מסך נכסי ההשקעה
A2: 158 | B2: 1441 | C2: גמול פועלים סהר | D2: 33-414 | E2: סימול בנק | F2: פח"ק/פר"י | G2: ישראל | H2: לא | I2: AAA | J2: S&P מעלות | K2: ILS | L2: 0 | M2: 1 | N2: 0 | O2: 247.038 | P2: 0.88361113 | Q2: 0.022524115
A3: 158 | B3: 1441 | C3: גמול פועלים סהר | D3: 33-414 | E3: סימול בנק | F3: מזומן ועו"ש נקוב במט"ח | G3: חו"ל | H3: לא | I3: AAA | J3: S&P מעלות | K3: USD | L3: 4.321 | M3: 3.681 | N3: 0 | O3: 15.904 | P3: 0.056886521 | Q3: 0.0014500933
A4: 158 | B4: 1441 | C4: גמול פועלים סהר | D4: 33-414 | E4: סימול בנק | F4: מזומן ועו"ש בש"ח | G4: ישראל | H4: לא | I4: AAA | J4: S&P מעלות | K4: ILS | L4: 0 | M4: 1 | N4: 0 | O4: -0.001 | P4: -2.611081e-06 | Q4: -6.6559018e-08
A5: 158 | B5: 1441 | C5: בנק לאומי לישראל בע"מ | D5: 10-800 | E5: סימול בנק | F5: מזומן ועו"ש בש"ח | G5: ישראל | H5: לא | I5: AAA | J5: S&P מעלות | K5: ILS | L5: 0 | M5: 1 | N5: 0 | O5: 16.636 | P5: 0.059504962 | Q5: 0.0015168399
A6: 158 | B6: 1522 | C6: גמול פועלים סהר | D6: 33-414 | E6: סימול בנק | F6: פח"ק/פר"י | G6: ישראל | H6: לא | I6: AAA | J6: S&P מעלות | K6: ILS | L6: 0 | M6: 1 | N6: 0 | O6: 385.696 | P6: 0.85272291 | Q6: 0.038234412
A7: 158 | B7: 1522 | C7: גמול פועלים סהר | D7: 33-414 | E7: סימול בנק | F7: מזומן ועו"ש נקוב במט"ח | G7: ישראל | H7: לא | I7: AAA | J7: S&P מעלות | K7: CHF | L7: 5.046 | M7: 4.074 | N7: 0 | O7: 20.558 | P7: 0.045451821 | Q7: 0.0020379699
A8: 158 | B8: 1522 | C8: גמול פועלים סהר | D8: 33-414 | E8: סימול בנק | F8: מזומן ועו"ש נקוב במט"ח | G8: חו"ל | H8: לא | I8: AAA | J8: S&P מעלות | K8: USD | L8: -3.136 | M8: 3.681 | N8: 0 | O8: -11.544 | P8: -0.025521924 | Q8: -0.0011443527
A9: 158 | B9: 1522 | C9: גמול פועלים סהר | D9: 33-414 | E9: סימול בנק | F9: מזומן ועו"ש נקוב במט"ח | G9: חו"ל | H9: לא | I9: AAA | J9: S&P מעלות | K9: HKD | L9: 2.66 | M9: 0.47 | N9: 0 | O9: 1.251 | P9: 0.0027665278 | Q9: 0.00012404564
A10: 158 | B10: 1522 | C10: גמול פועלים סהר | D10: 33-414 | E10: סימול בנק | F10: מזומן ועו"ש נקוב במט"ח | G10: חו"ל | H10: לא | I10: AAA | J10: S&P מעלות | K10: EUR | L10: 7.205 | M10: 3.979 | N10: 0 | O10: 28.671 | P10: 0.063388048 | Q10: 0.0028421949
A11: 158 | B11: 1522 | C11: גמול פועלים סהר | D11: 33-414 | E11: סימול בנק | F11: מזומן ועו"ש נקוב במט"ח | G11: חו"ל | H11: לא | I11: AAA | J11: S&P מעלות | K11: JPY | L11: 0.67 | M11: 2.433 | N11: 0 | O11: 0.016 | P11: 3.605899e-05 | Q11: 1.6168139e-06
A12: 158 | B12: 1522 | C12: גמול פועלים סהר | D12: 33-414 | E12: סימול בנק | F12: מזומן ועו"ש נקוב במט"ח | G12: חו"ל | H12: לא | I12: AAA | J12: S&P מעלות | K12: GBP | L12: 0.496 | M12: 4.654 | N12: 0 | O12: 2.31 | P12: 0.0051067955 | Q12: 0.00022897863
A13: 158 | B13: 1522 | C13: בנק לאומי לישראל בע"מ | D13: 10-800 | E13: סימול בנק | F13: מזומן ועו"ש בש"ח | G13: ישראל | H13: לא | I13: AAA | J13: S&P מעלות | K13: ILS | L13: 0 | M13: 1 | N13: 0 | O13: 25.352 | P13: 0.056050576 | Q13: 0.0025131972
... A50: 158 | B50: 9937 | C50: בנק לאומי לישראל בע"מ | D50: 10-800 | E50: סימול בנק | F50: מזומן ועו"ש בש"ח | G50: ישראל | H50: לא | I50: AAA | J50: S&P מעלות | K50: ILS | L50: 0 | M50: 1 | N50: 0 | O50: -362.403 | P50: -0.32948435 | Q50: -0.011527074

Sheet איגרות חוב ממשלתיות
A1: מספר קופה/קרן/ח.פ. עבור חברת ביטוח | B1: מספר מסלול | C1: שם מנפיק | D1: שם נייר ערך | E1: מספר נייר ערך | F1: מאפיין עיקרי | G1: ישראל/חו"ל | H1: מדינה לפי חשיפה כלכלית | I1: זירת מסחר | J1: דירוג | K1: שם מדרג | L1: מטבע פעילות | M1: מח"מ | N1: מועד פדיון | O1: שיעור ריבית | P1: תשואה לפדיון | Q1: סכום לקבל (במטבע הפעילות) | R1: ערך נקוב (יחידות) | S1: שער חליפין | T1: שער נייר הערך | U1: שווי הוגן (באלפי ש"ח) | V1: עלות מופחתת (באלפי ש"ח) | W1: השיטה שיושמה בדוח הכספי | X1: שיעור מערך נקוב מונפק | Y1: שיעור מנכסי אפיק ההשקעה | Z1: שיעור מסך נכסי ההשקעה
A2: 158 | B2: 1441 | C2: מדינת ישראל | D2: ISRAEL 2 7/8 03/16/26 | E2: US46513CXR23 | F2: צמוד מט"ח בריבית קבועה | G2: ישראל | H2: ישראל | I2: LSE | J2: A1 | K2: Moodys | L2: USD | M2: 3.22 | N2: 16/03/2026 | O2: 0.02875 | P2: 0.0451 | R2: 100000 | S2: 3.681 | T2: 95.365 | U2: 351.04 | W2: שווי הוגן | X2: 0.1 | Y2: 0.041204084 | Z2: 0.032006651
A3: 158 | B3: 1441 | C3: בנק ישראל- מק"מ | D3: מ.ק.מ. 315 | E3: IL0082503181 | F3: מק"מ קצר משנים עשר חודשים | G3: ישראל | H3: ישראל | I3: TASE | J3: RF | K3: פנימי | L3: ILS | M3: 0.94 | N3: 05/03/2025 | O3: 0 | P3: 0.04096 | R3: 860000 | S3: 1 | T3: 96.38 | U3: 828.868 | W3: שווי הוגן | X3: 0 | Y3: 0.097290276 | Z3: 0.075573479
A4: 158 | B4: 1441 | C4: בנק ישראל- מק"מ | D4: מלווה קצר מועד 1114 | E4: IL0082411195 | F4: מק"מ קצר משנים עשר חודשים | G4: ישראל | H4: ישראל | I4: TASE | J4: RF | K4: פנימי | L4: ILS | M4: 0.6 | N4: 06/11/2024 | O4: 0 | P4: 0.04274 | R4: 30000 | S4: 1 | T4: 97.52 | U4: 29.256 | W4: שווי הוגן | X4: 0 | Y4: 0.0034339899 | Z4: 0.0026674666
A5: 158 | B5: 1441 | C5: בנק ישראל- מק"מ | D5: מלווה קצר מועד 714 | E5: IL0082407151 | F5: מק"מ קצר משנים עשר חודשים | G5: ישראל | H5: ישראל | I5: TASE | J5: RF | K5: פנימי | L5: ILS | M5: 0.255 | N5: 03/07/2024 | O5: 0 | P5: 0.04312 | R5: 60000 | S5: 1 | T5: 98.95 | U5: 59.37 | W5: שווי הוגן | X5: 3e-06 | Y5: 0.0069686895 | Z5: 0.0054131628
A6: 158 | B6: 1441 | C6: בנק ישראל- מק"מ | D6: מלווה קצר מועד 914 | E6: IL0082409132 | F6: מק"מ קצר משנים עשר חודשים | G6: ישראל | H6: ישראל | I6: TASE | J6: RF | K6: פנימי | L6: ILS | M6: 0.427 | N6: 04/09/2024 | O6: 0 | P6: 0.04317 | R6: 125000 | S6: 1 | T6: 98.21 | U6: 122.762 | W6: שווי הוגן | X6: 7e-06 | Y6: 0.014409529 | Z6: 0.011193084
A7: 158 | B7: 1441 | C7: גליל | D7: ממשל צמודה 0527 | E7: IL0011408478 | F7: צמוד למדד המחירים לצרכן בריבית קבועה | G7: ישראל | H7: ישראל | I7: TASE | J7: RF | K7: פנימי | L7: ILS | M7: 3.119 | N7: 31/05/2027 | O7: 0.0075 | P7: 0.01152 | R7: 888842 | S7: 1 | T7: 111.88 | U7: 994.436 | W7: שווי הוגן | X7: 4.2e-05 | Y7: 0.11672425 | Z7: 0.090669468
A8: 158 | B8: 1441 | C8: גליל | D8: ממשל צמודה 1025 | E8: IL0011359127 | F8: צמוד למדד המחירים לצרכן בריבית קבועה | G8: ישראל | H8: ישראל | I8: TASE | J8: RF | K8: פנימי | L8: ILS | M8: 1.576 | N8: 31/10/2025 | O8: 0.0075 | P8: 0.00797 | R8: 1277299 | S8: 1 | T8: 112.14 | U8: 1432.363 | W8: שווי הוגן | X8: 5.9e-05 | Y8: 0.16812689 | Z8: 0.13059819
A9: 158 | B9: 1441 | C9: גליל | D9: ממשל צמודה 1131 | E9: IL0011722209 | F9: צמוד למדד המחירים לצרכן בריבית קבועה | G9: ישראל | H9: ישראל | I9: TASE | J9: RF | K9: פנימי | L9: ILS | M9: 7.638 | N9: 30/11/2031 | O9: 0.001 | P9: 0.01556 | R9: 54000 | S9: 1 | T9: 99.81 | U9: 53.897 | W9: שווי הוגן | X9: 2e-06 | Y9: 0.0063263305 | Z9: 0.004914189
A10: 158 | B10: 1441 | C10: שחר | D10: ממשל שיקלית 0928 | E10: IL0011508798 | F10: לא צמוד למדד המחירים לצרכן ריבית קבועה | G10: ישראל | H10: ישראל | I10: TASE | J10: RF | K10: פנימי | L10: ILS | M10: 4.269 | N10: 28/09/2028 | O10: 0.0225 | P10: 0.04072 | R10: 70000 | S10: 1 | T10: 93.79 | U10: 65.653 | W10: שווי הוגן | X10: 3e-06 | Y10: 0.0077061709 | Z10: 0.0059860263
A11: 158 | B11: 1441 | C11: שחר | D11: ממשל שקלית 0226 | E11: IL0011746976 | F11: לא צמוד למדד המחירים לצרכן ריבית קבועה | G11: ישראל | H11: ישראל | I11: TASE | J11: RF | K11: פנימי | L11: ILS | M11: 1.904 | N11: 27/02/2026 | O11: 0.005 | P11: 0.04029 | R11: 808000 | S11: 1 | T11: 93.69 | U11: 757.015 | W11: שווי הוגן | X11: 3.8e-05 | Y11: 0.088856389 | Z11: 0.069022175
A12: 158 | B12: 1441 | C12: שחר | D12: ממשל שקלית 0825 | E12: IL0011355570 | F12: לא צמוד למדד המחירים לצרכן ריבית קבועה | G12: ישראל | H12: ישראל | I12: TASE | J12: RF | K12: פנימי | L12: ILS | M12: 1.399 | N12: 31/08/2025 | O12: 0.0175 | P12: 0.04022 | R12: 344000 | S12: 1 | T12: 97.96 | U12: 336.982 | W12: שווי הוגן | X12: 1.4e-05 | Y12: 0.039554079 | Z12: 0.030724955
A13: 158 | B13: 1441 | C13: שחר | D13: ממשלתי שקלית 0142 | E13: IL0011254005 | F13: לא צמוד למדד המחירים לצרכן ריבית קבועה | G13: ישראל | H13: ישראל | I13: TASE | J13: RF | K13: פנימי | L13: ILS | M13: 11.998 | N13: 31/01/2042 | O13: 0.055 | P13: 0.04715 | R13: 148322 | S13: 1 | T13: 110.25 | U13: 163.525 | W13: שווי הוגן | X13: 8e-06 | Y13: 0.019194121 | Z13: 0.014909676
... A89: 158 | B89: 9937 | C89: בנק ישראל- מק"מ | D89: מקמ 614 | E89: IL0082406161 | F89: מק"מ קצר משנים עשר חודשים | G89: ישראל | H89: ישראל | I89: TASE | J89: RF | K89: פנימי | L89: ILS | M89: 0.178 | N89: 05/06/2024 | O89: 0 | P89: 0.04318 | R89: 62000 | S89: 1 | T89: 99.26 | U89: 61.541 | W89: שווי הוגן | X89: 3e-06 | Y89: 0.0060200688 | Z89: 0.001957461

Sheet ניירות ערך מסחריים
A1: מספר קופה/קרן/ח.פ. עבור חברת ביטוח | B1: מספר מסלול | C1: שם מנפיק | D1: מספר מנפיק | E1: סוג מספר מזהה מנפיק | F1: שם נייר ערך | G1: מספר נייר ערך | H1: סוג מספר נייר ערך | I1: מאפיין עיקרי | J1: ישראל/חו"ל | K1: מדינה לפי חשיפה כלכלית | L1: זירת מסחר | M1: ענף מסחר | N1: בעל עניין/צד קשור | O1: דירוג | P1: שם מדרג | Q1: דירוג נייר הערך/המנפיק | R1: מטבע פעילות | S1: מח"מ | T1: ריבית עוגן | U1: מועד פדיון | V1: שיעור ריבית | W1: תשואה לפדיון | X1: נחיתות חוזית | Y1: האם סווג כחוב בעייתי | Z1: ערך נקוב (יחידות) | AA1: שער חליפין | AB1: שער נייר הערך | AC1: סכום לקבל (במטבע הפעילות) | AD1: שווי הוגן (באלפי ש"ח) | AE1: עלות מופחתת (באלפי ש"ח) | AF1: עלות מופחתת (במטבע הפעילות) | AG1: השיטה שיושמה בדוח הכספי | AH1: שיעור מערך נקוב מונפק | AI1: שיעור מנכסי אפיק ההשקעה | AJ1: שיעור מסך נכסי ההשקעה
A2: 158 | B2: 9935 | C2: מגה אור החזקות בע"מ | D2: 513257873 | E2: ח.פ | F2: מגה אור נעמ 3 18062024 | G2: IL0011969552 | H2: ISIN | I2: לא צמוד למדד המחירים לצרכן ריבית קבועה | J2: ישראל | K2: ישראל | L2: TASE | M2: נדל"ן מניב בישראל | N2: לא | O2: A+ | P2: S&P מעלות | Q2: נייר ערך | R2: ILS | S2: 0.214 | T2: ריבית בנק ישראל | U2: 18/06/2024 | V2: 0.102 | W2: 0.06684 | X2: החוב לא נחות | Y2: לא | Z2: 86500 | AA2: 1 | AB2: 1044.33 | AD2: 903.345 | AG2: שווי הוגן | AH2: 0.005767 | AI2: 1 | AJ2: 0.00082407088
A3: 158 | B3: 9936 | C3: מגה אור החזקות בע"מ | D3: 513257873 | E3: ח.פ | F3: מגה אור נעמ 3 18062024 | G3: IL0011969552 | H3: ISIN | I3: לא צמוד למדד המחירים לצרכן ריבית קבועה | J3: ישראל | K3: ישראל | L3: TASE | M3: נדל"ן מניב בישראל | N3: לא | O3: A+ | P3: S&P מעלות | Q3: נייר ערך | R3: ILS | S3: 0.214 | T3: ריבית בנק ישראל | U3: 18/06/2024 | V3: 0.102 | W3: 0.06684 | X3: החוב לא נחות | Y3: לא | Z3: 2700 | AA3: 1 | AB3: 1044.33 | AD3: 28.197 | AG3: שווי הוגן | AH3: 0.00018 | AI3: 1 | AJ3: 0.0018522991

Sheet איגרות חוב
A1: מספר קופה/קרן/ח.פ. עבור חברת ביטוח | B1: מספר מסלול | C1: שם מנפיק | D1: מספר מנפיק | E1: סוג מספר מזהה מנפיק | F1: שם נייר ערך | G1: מספר נייר ערך | H1: סוג מספר נייר ערך | I1: מאפיין עיקרי | J1: ישראל/חו"ל | K1: מדינה לפי חשיפה כלכלית | L1: סטאטוס סחירות | M1: זירת מסחר | N1: ענף מסחר | O1: בעל עניין/צד קשור | P1: דירוג | Q1: שם מדרג | R1: דירוג נייר הערך/המנפיק | S1: מטבע פעילות | T1: מח"מ | U1: מועד פדיון | V1: שיעור ריבית | W1: תשואה לפדיון | X1: נחיתות חוזית | Y1: האם סווג כחוב בעייתי | Z1: ערך נקוב (יחידות) | AA1: שער חליפין | AB1: שער נייר הערך | AC1: סכום לקבל (במטבע הפעילות) | AD1: שווי הוגן (באלפי ש"ח) | AE1: עלות מופחתת (באלפי ש"ח) | AF1: עלות מופחתת (במטבע הפעילות) | AG1: השיטה שיושמה בדוח הכספי | AH1: שיעור מערך נקוב מונפק | AI1: שיעור מנכסי אפיק ההשקעה | AJ1: שיעור מסך נכסי ההשקעה
A2: 158 | B2: 1441 | C2: איירפורט סיטי בע"מ | D2: 511659401 | E2: ח.פ | F2: איירפורט אגח ה | G2: IL0011334872 | H2: ISIN | I2: צמוד למדד המחירים לצרכן | J2: ישראל | K2: ישראל | L2: סחיר | M2: TASE | N2: נדל"ן מניב בישראל | O2: לא | P2: AA | Q2: S&P מעלות | R2: נייר ערך | S2: ILS | T2: 2.698 | U2: 28/02/2029 | V2: 0.0234 | W2: 0.02157 | X2: החוב לא נחות | Y2: לא | Z2: 40362.48 | AA2: 1 | AB2: 111.84 | AD2: 45.141 | AG2: שווי הוגן | AH2: 1.6e-05 | AI2: 0.027522624 | AJ2: 0.0041158453
A3: 158 | B3: 1441 | C3: אלביט מערכות בע"מ | D3: 520043027 | E3: ח.פ | F3: אלביט מערכות ב' 1.08% | G3: IL0011782351 | H3: ISIN | I3: לא צמוד למדד המחירים לצרכן | J3: ישראל | K3: ישראל | L3: סחיר | M3: TASE | N3: ביטחוניות | O3: לא | P3: AA | Q3: S&P מעלות | R3: נייר ערך | S3: ILS | T3: 2.597 | U3: 01/07/2029 | V3: 0.0108 | W3: 0.04475 | X3: החוב לא נחות | Y3: לא | Z3: 25950.75 | AA3: 1 | AB3: 92.04 | AD3: 23.885 | AG3: שווי הוגן | AH3: 2e-05 | AI3: 0.014562682 | AJ3: 0.0021777628
A4: 158 | B4: 1441 | C4: אלוני-חץ נכסים והשקעות בע"מ | D4: 520038506 | E4: ח.פ | F4: אלוני חץ אגח ט | G4: IL0039003541 | H4: ISIN | I4: לא צמוד למדד המחירים לצרכן | J4: ישראל | K4: ישראל | L4: סחיר | M4: TASE | N4: נדל"ן מניב בישראל | O4: לא | P4: AA- | Q4: S&P מעלות | R4: נייר ערך | S4: ILS | T4: 1.858 | U4: 28/02/2027 | V4: 0.0385 | W4: 0.04768 | X4: החוב לא נחות | Y4: לא | Z4: 40500 | AA4: 1 | AB4: 98.71 | AD4: 39.978 | AG4: שווי הוגן | AH4: 4.2e-05 | AI4: 0.024374236 | AJ4: 0.0036450225
A5: 158 | B5: 1441 | C5: אלוני-חץ נכסים והשקעות בע"מ | D5: 520038506 | E5: ח.פ | F5: אלוני חץ אגח טו | G5: IL0011894149 | H5: ISIN | I5: צמוד למדד המחירים לצרכן | J5: ישראל | K5: ישראל | L5: סחיר | M5: TASE | N5: נדל"ן מניב בישראל | O5: לא | P5: Aa3 | Q5: מידרוג Moodys | R5: נייר ערך | S5: ILS | T5: 7.443 | U5: 28/02/2037 | V5: 0.0256 | W5: 0.03962 | X5: החוב לא נחות | Y5: לא | Z5: 10000 | AA5: 1 | AB5: 94.33 | AD5: 9.433 | AG5: שווי הוגן | AH5: 1.5e-05 | AI5: 0.0057512821 | AJ5: 0.00086007015
A6: 158 | B6: 1441 | C6: אלקטרה בע"מ | D6: 520028911 | E6: ח.פ | F6: אלקטרה אגח ה | G6: IL0073902228 | H6: ISIN | I6: לא צמוד למדד המחירים לצרכן | J6: ישראל | K6: ישראל | L6: סחיר | M6: TASE | N6: השקעה ואחזקות | O6: לא | P6: A+ | Q6: S&P מעלות | R6: נייר ערך | S6: ILS | T6: 3.41 | U6: 10/01/2031 | V6: 0.04 | W6: 0.0502 | X6: החוב לא נחות | Y6: לא | Z6: 31750 | AA6: 1 | AB6: 97.7 | AD6: 31.02 | AG6: שווי הוגן | AH6: 4.1e-05 | AI6: 0.018912682 | AJ6: 0.0028282796
A7: 158 | B7: 1441 | C7: אמות השקעות בע"מ | D7: 520026683 | E7: ח.פ | F7: אמות אגח ד | G7: IL0011331498 | H7: ISIN | I7: צמוד למדד המחירים לצרכן | J7: ישראל | K7: ישראל | L7: סחיר | M7: TASE | N7: נדל"ן מניב בישראל | O7: לא | P7: Aa2 | Q7: מידרוג Moodys | R7: נייר ערך | S7: ILS | T7: 2.036 | U7: 02/07/2028 | V7: 0.032 | W7: 0.021 | X7: החוב לא נחות | Y7: לא | Z7: 36000 | AA7: 1 | AB7: 116.39 | AD7: 41.9 | AG7: שווי הוגן | AH7: 2.6e-05 | AI7: 0.025546594 | AJ7: 0.0038203417
A8: 158 | B8: 1441 | C8: ביג מרכזי קניות (2004) בע"מ | D8: 513623314 | E8: ח.פ | F8: ביג אגח ז | G8: IL0011360844 | H8: ISIN | I8: צמוד למדד המחירים לצרכן | J8: ישראל | K8: ישראל | L8: סחיר | M8: TASE | N8: נדל"ן מניב בישראל | O8: לא | P8: Aa3 | Q8: מידרוג Moodys | R8: נייר ערך | S8: ILS | T8: 0.601 | U8: 11/05/2025 | V8: 0.025 | W8: 0.02022 | X8: החוב לא נחות | Y8: לא | Z8: 20001.27 | AA8: 1 | AB8: 113.37 | AD8: 22.675 | AG8: שווי הוגן | AH8: 4.2e-05 | AI8: 0.013825172 | AJ8: 0.0020674726
A9: 158 | B9: 1441 | C9: פז בית זיקוק לנפט-אשדוד בע"מ | D9: 513775163 | E9: ח.פ | F9: בית זיקוק אשדוד אגח 2 | G9: IL0011994881 | H9: ISIN | I9: לא צמוד למדד המחירים לצרכן | J9: ישראל | K9: ישראל | L9: סחיר | M9: TASE | N9: אנרגיה | O9: לא | P9: A3 | Q9: מידרוג Moodys | R9: נייר ערך | S9: ILS | T9: 3.07 | U9: 30/04/2029 | V9: 0.0725 | W9: 0.06232 | X9: החוב לא נחות | Y9: לא | Z9: 9954 | AA9: 1 | AB9: 108.29 | AD9: 10.779 | AG9: שווי הוגן | AH9: 1.7e-05 | AI9: 0.0065720495 | AJ9: 0.00098281105
A10: 158 | B10: 1441 | C10: דיסקונט מנפיקים בע"מ | D10: 520029935 | E10: ח.פ | F10: דיסק מנ אגח טו | G10: IL0074803045 | H10: ISIN | I10: צמוד למדד המחירים לצרכן | J10: ישראל | K10: ישראל | L10: סחיר | M10: TASE | N10: בנקים | O10: לא | P10: Aaa | Q10: מידרוג Moodys | R10: נייר ערך | S10: ILS | T10: 4.255 | U10: 15/08/2032 | V10: 0.002 | W10: 0.01936 | X10: החוב לא נחות | Y10: לא | Z10: 26842.1 | AA10: 1 | AB10: 101.27 | AD10: 27.183 | AG10: שווי הוגן | AH10: 6e-06 | AI10: 0.01657342 | AJ10: 0.0024784567
A11: 158 | B11: 1441 | C11: דיסקונט מנפיקים בע"מ | D11: 520029935 | E11: ח.פ | F11: דיסק מנ אגח טז | G11: IL0012031576 | H11: ISIN | I11: צמוד למדד המחירים לצרכן | J11: ישראל | K11: ישראל | L11: סחיר | M11: TASE | N11: בנקים | O11: לא | P11: Aaa | Q11: מידרוג Moodys | R11: נייר ערך | S11: ILS | T11: 5.62 | U11: 20/03/2035 | V11: 0.0247 | W11: 0.02011 | X11: החוב לא נחות | Y11: לא | Z11: 30000 | AA11: 1 | AB11: 101.35 | AD11: 30.405 | AG11: שווי הוגן | AH11: 1.9e-05 | AI11: 0.018537871 | AJ11: 0.0027722287
A12: 158 | B12: 1441 | C12: הראל ביטוח מימון והנפקות בע"מ | D12: 513834200 | E12: ח.פ | F12: הראל הנפ אגח טז | G12: IL0011576019 | H12: ISIN | I12: לא צמוד למדד המחירים לצרכן | J12: ישראל | K12: ישראל | L12: סחיר | M12: TASE | N12: ביטוח | O12: לא | P12: Aa3 | Q12: מידרוג Moodys | R12: נייר ערך | S12: ILS | T12: 2.174 | U12: 30/06/2026 | V12: 0.0291 | W12: 0.04602 | X12: החוב לא נחות | Y12: לא | Z12: 10000 | AA12: 1 | AB12: 97.28 | AD12: 9.728 | AG12: שווי הוגן | AH12: 1.7e-05 | AI12: 0.0059311431 | AJ12: 0.00088696729
A13: 158 | B13: 1441 | C13: הראל ביטוח מימון והנפקות בע"מ | D13: 513834200 | E13: ח.פ | F13: הראל הנפק אגח ז | G13: IL0011260770 | H13: ISIN | I13: צמוד למדד המחירים לצרכן | J13: ישראל | K13: ישראל | L13: סחיר | M13: TASE | N13: ביטוח | O13: לא | P13: AA- | Q13: מידרוג Moodys | R13: נייר ערך | S13: ILS | T13: 0.164 | U13: 31/05/2024 | V13: 0.0385 | W13: 0.0001 | X13: החוב לא נחות | Y13: לא | Z13: 27341 | AA13: 1 | AB13: 117.54 | AD13: 32.137 | AG13: שווי הוגן | AH13: 0.000109 | AI13: 0.019593631 | AJ13: 0.0029301113
... A15: 158 | B15: 1441 | C15: הראל השקעות בביטוח ושרותים פיננסים בע"מ | D15: 520033986 | E15: ח.פ | F15: הראל השקעות אגח א | G15: IL0058501102 | H15: ISIN | I15: לא צמוד למדד המחירים לצרכן | J15: ישראל | K15: ישראל | L15: סחיר | M15: TASE | N15: ביטוח | O15: לא | P15: Aa2 | Q15: מידרוג Moodys | R15: נייר ערך | S15: ILS | T15: 5.221 | U15: 31/12/2035 | V15: 0.0195 | W15: 0.05008 | X15: החוב לא נחות | Y15: לא | Z15: 37923.54 | AA15: 1 | AB15: 85.74 | AD15: 32.516 | AG15: שווי הוגן | AH15: 3.3e-05 | AI15: 0.019824726 | AJ15: 0.0029646702
A16: 158 | B16: 1441 | C16: חברת החשמל לישראל בע"מ | D16: 520000472 | E16: ח.פ | F16: חשמל אגח 27 | G16: IL0060002107 | H16: ISIN | I16: צמוד למדד המחירים לצרכן | J16: ישראל | K16: ישראל | L16: סחיר | M16: TASE | N16: אנרגיה | O16: לא | P16: Aa1 | Q16: מידרוג Moodys | R16: נייר ערך | S16: ILS | T16: 3.883 | U16: 12/04/2029 | V16: 0.0385 | W16: 0.0195 | X16: החוב לא נחות | Y16: לא | Z16: 95833.32 | AA16: 1 | AB16: 120.49 | AC16: 3.27 | AD16: 118.74 | AG16: שווי הוגן | AH16: 3.7e-05 | AI16: 0.072395251 | AJ16: 0.010826281
A17: 158 | B17: 1441 | C17: חברת החשמל לישראל בע"מ | D17: 520000472 | E17: ח.פ | F17: חשמל אגח 31 | G17: IL0060002859 | H17: ISIN | I17: צמוד למדד המחירים לצרכן | J17: ישראל | K17: ישראל | L17: סחיר | M17: TASE | N17: אנרגיה | O17: לא | P17: Aa1 | Q17: מידרוג Moodys | R17: נייר ערך | S17: ILS | T17: 6.24 | U17: 21/09/2031 | V17: 0.0239 | W17: 0.02476 | X17: החוב לא נחות | Y17: לא | Z17: 45000 | AA17: 1 | AB17: 110.76 | AD17: 49.842 | AG17: שווי הוגן | AH17: 1.2e-05 | AI17: 0.030388572 | AJ17: 0.0045444309
A18: 158 | B18: 1441 | C18: ישרס חברה להשקעות בע"מ | D18: 520017807 | E18: ח.פ | F18: ישרס אגח יד | G18: IL0061301995 | H18: ISIN | I18: לא צמוד למדד המחירים לצרכן | J18: ישראל | K18: ישראל | L18: סחיר | M18: TASE | N18: נדל"ן מניב בישראל | O18: לא | P18: Aa3 | Q18: מידרוג Moodys | R18: נייר ערך | S18: ILS | T18: 1.83 | U18: 01/03/2027 | V18: 0.0505 | W18: 0.0487 | X18: החוב לא נחות | Y18: לא | Z18: 35142.85 | AA18: 1 | AB18: 100.86 | AD18: 35.445 | AG18: שווי הוגן | AH18: 9.5e-05 | AI18: 0.021610797 | AJ18: 0.0032317666
A19: 158 | B19: 1441 | C19: כללביט מימון בע"מ | D19: 513754069 | E19: ח.פ | F19: כלל אגח יא | G19: IL0011606477 | H19: ISIN | I19: לא צמוד למדד המחירים לצרכן | J19: ישראל | K19: ישראל | L19: סחיר | M19: TASE | N19: ביטוח | O19: לא | P19: Aa3 | Q19: מידרוג Moodys | R19: נייר ערך | S19: ILS | T19: 5.554 | U19: 31/03/2030 | V19: 0.0264 | W19: 0.05041 | X19: החוב לא נחות | Y19: לא | Z19: 135500 | AA19: 1 | AB19: 88.01 | AD19: 119.254 | AG19: שווי הוגן | AH19: 8.3e-05 | AI19: 0.072708662 | AJ19: 0.010873149
A20: 158 | B20: 1441 | C20: בנק לאומי לישראל בע"מ | D20: 520018078 | E20: ח.פ | F20: לאומי אגח 179 | G20: IL0060403727 | H20: ISIN | I20: צמוד למדד המחירים לצרכן | J20: ישראל | K20: ישראל | L20: סחיר | M20: TASE | N20: בנקים | O20: לא | P20: Aaa | Q20: מידרוג Moodys | R20: נייר ערך | S20: ILS | T20: 1.23 | U20: 30/06/2026 | V20: 0.0083 | W20: 0.01398 | X20: החוב לא נחות | Y20: לא | Z20: 30000 | AA20: 1 | AB20: 111.66 | AD20: 33.498 | AG20: שווי הוגן | AH20: 1e-05 | AI20: 0.020423667 | AJ20: 0.0030542383
A21: 158 | B21: 1441 | C21: בנק לאומי לישראל בע"מ | D21: 520018078 | E21: ח.פ | F21: לאומי אגח 186 | G21: IL0012018391 | H21: ISIN | I21: צמוד למדד המחירים לצרכן | J21: ישראל | K21: ישראל | L21: סחיר | M21: TASE | N21: בנקים | O21: לא | P21: AAA | Q21: S&P מעלות | R21: נייר ערך | S21: ILS | T21: 5.54 | U21: 30/11/2033 | V21: 0.0202 | W21: 0.02037 | X21: החוב לא נחות | Y21: לא | Z21: 40000 | AA21: 1 | AB21: 100.75 | AD21: 40.3 | AG21: שווי הוגן | AH21: 1.9e-05 | AI21: 0.024570833 | AJ21: 0.0036744225
A22: 158 | B22: 1441 | C22: מבנה נדל"ן (כ.ד) בע"מ | D22: 520024126 | E22: ח.פ | F22: מבני תעשיה אגח טז | G22: IL0022604388 | H22: ISIN | I22: לא צמוד למדד המחירים לצרכן | J22: ישראל | K22: ישראל | L22: סחיר | M22: TASE | N22: נדל"ן מניב בישראל | O22: לא | P22: AA | Q22: S&P מעלות | R22: נייר ערך | S22: ILS | T22: 2.084 | U22: 30/06/2028 | V22: 0.0565 | W22: 0.04633 | X22: החוב לא נחות | Y22: לא | Z22: 32500 | AA22: 1 | AB22: 103.65 | AD22: 33.686 | AG22: שווי הוגן | AH22: 0.000139 | AI22: 0.020538442 | AJ22: 0.0030714023
A23: 158 | B23: 1441 | C23: מבנה נדל"ן (כ.ד) בע"מ | D23: 520024126 | E23: ח.פ | F23: מבני תעשיה אגח יז | G23: IL0022604461 | H23: ISIN | I23: צמוד למדד המחירים לצרכן | J23: ישראל | K23: ישראל | L23: סחיר | M23: TASE | N23: נדל"ן מניב בישראל | O23: לא | P23: Aa2 | Q23: מידרוג Moodys | R23: נייר ערך | S23: ILS | T23: 2.154 | U23: 30/06/2028 | V23: 0.037 | W23: 0.02189 | X23: החוב לא נחות | Y23: לא | Z23: 33125 | AA23: 1 | AB23: 116.15 | AD23: 38.475 | AG23: שווי הוגן | AH23: 8.8e-05 | AI23: 0.023457944 | AJ23: 0.0035079964
A24: 158 | B24: 1441 | C24: מגה אור החזקות בע"מ | D24: 513257873 | E24: ח.פ | F24: מגה אור אגח ז | G24: IL0011416968 | H24: ISIN | I24: צמוד למדד המחירים לצרכן | J24: ישראל | K24: ישראל | L24: סחיר | M24: TASE | N24: נדל"ן מניב בישראל | O24: לא | P24: A+ | Q24: S&P מעלות | R24: נייר ערך | S24: ILS | T24: 2.077 | U24: 30/08/2027 | V24: 0.0205 | W24: 0.02328 | X24: החוב לא נחות | Y24: לא | Z24: 21000 | AA24: 1 | AB24: 112.41 | AD24: 23.606 | AG24: שווי הוגן | AH24: 2.7e-05 | AI24: 0.014392594 | AJ24: 0.0021523272
A25: 158 | B25: 1441 | C25: מזרחי טפחות חברה להנפקות בע"מ | D25: 520032046 | E25: ח.פ | F25: מז הנפק 46 1.22% 9/2027 | G25: IL0023102259 | H25: ISIN | I25: צמוד למדד המחירים לצרכן | J25: ישראל | K25: ישראל | L25: סחיר | M25: TASE | N25: בנקים | O25: לא | P25: Aaa | Q25: מידרוג Moodys | R25: נייר ערך | S25: ILS | T25: 3.421 | U25: 28/09/2027 | V25: 0.0122 | W25: 0.018 | X25: החוב לא נחות | Y25: לא | Z25: 60000 | AA25: 1 | AB25: 111.35 | AD25: 66.81 | AG25: שווי הוגן | AH25: 2e-05 | AI25: 0.04073393 | AJ25: 0.0060915178
A26: 158 | B26: 1441 | C26: מזרחי טפחות חברה להנפקות בע"מ | D26: 520032046 | E26: ח.פ | F26: מז טפ הנ אגח 67 | G26: IL0011968075 | H26: ISIN | I26: צמוד למדד המחירים לצרכן | J26: ישראל | K26: ישראל | L26: סחיר | M26: TASE | N26: בנקים | O26: לא | P26: Aaa | Q26: מידרוג Moodys | R26: נייר ערך | S26: ILS | T26: 4.395 | U26: 12/06/2033 | V26: 0.0206 | W26: 0.01973 | X26: החוב לא נחות | Y26: לא | Z26: 30000 | AA26: 1 | AB26: 103.41 | AD26: 31.023 | AG26: שווי הוגן | AH26: 1.5e-05 | AI26: 0.018914664 | AJ26: 0.0028285759
A27: 158 | B27: 1441 | C27: מזרחי טפחות חברה להנפקות בע"מ | D27: 520032046 | E27: ח.פ | F27: מז טפ הנ אגח 68 | G27: IL0012021429 | H27: ISIN | I27: צמוד למדד המחירים לצרכן | J27: ישראל | K27: ישראל | L27: סחיר | M27: TASE | N27: בנקים | O27: לא | P27: AAA | Q27: S&P מעלות | R27: נייר ערך | S27: ILS | T27: 4.93 | U27: 25/12/2033 | V27: 0.0199 | W27: 0.01946 | X27: החוב לא נחות | Y27: לא | Z27: 30000 | AA27: 1 | AB27: 100.72 | AD27: 30.216 | AG27: שווי הוגן | AH27: 1.1e-05 | AI27: 0.018422638 | AJ27: 0.0027549963
A28: 158 | B28: 1441 | C28: מימון ישיר מקבוצת ישיר 2006 בע"מ | D28: 513893123 | E28: ח.פ | F28: מימון ישיר אגח ו | G28: IL0011916595 | H28: ISIN | I28: צמוד למדד המחירים לצרכן | J28: ישראל | K28: ישראל | L28: סחיר | M28: TASE | N28: אשראי חוץ בנקאי | O28: לא | P28: A1 | Q28: מידרוג Moodys | R28: נייר ערך | S28: ILS | T28: 2.129 | U28: 31/03/2027 | V28: 0.0354 | W28: 0.0321 | X28: החוב לא נחות | Y28: לא | Z28: 22000 | AA28: 1 | AB28: 104.17 | AD28: 22.917 | AG28: שווי הוגן | AH28: 3.2e-05 | AI28: 0.013972695 | AJ28: 0.0020895337
... A59: 158 | B59: 1522 | C59: קבוצת עזריאלי בע"מ (לשעבר קנית מימון) | D59: 510960719 | E59: ח.פ | F59: עזריאלי אגח ה | G59: IL0011566036 | H59: ISIN | I59: צמוד למדד המחירים לצרכן | J59: ישראל | K59: ישראל | L59: סחיר | M59: TASE | N59: נדל"ן מניב בישראל | O59: לא | P59: Aa1 | Q59: מידרוג Moodys | R59: נייר ערך | S59: ILS | T59: 2.864 | U59: 30/06/2028 | V59: 0.0177 | W59: 0.02054 | X59: החוב לא נחות | Y59: לא | Z59: 0.57 | AA59: 1 | AB59: 111.11 | AD59: 0.001 | AG59: שווי הוגן | AH59: 0 | AI59: 1.5582675e-06 | AJ59: 6.2782371e-08
A60: 158 | B60: 1522 | C60: קבוצת עזריאלי בע"מ (לשעבר קנית מימון) | D60: 510960719 | E60: ח.פ | F60: עזריאלי קבוצה אגח ב סחיר | G60: IL0011344368 | H60: ISIN | I60: צמוד למדד המחירים לצרכן | J60: ישראל | K60: ישראל | L60: סחיר | M60: TASE | N60: נדל"ן מניב בישראל | O60: לא | P60: AA+ | Q60: S&P מעלות | R60: נייר ערך | S60: ILS | T60: 0.998 | U60: 01/04/2025 | V60: 0.0065 | W60: 0.01649 | X60: החוב לא נחות | Y60: לא | Z60: 0 | AA60: 1 | AB60: 110.63 | AC60: 5.622 | AD60: 5.622 | AG60: שווי הוגן | AI60: 0.013833346 | AJ60: 0.00055734351
A61: 158 | B61: 1522 | C61: עמרם אברהם חברה לבנין בע"מ | D61: 513201582 | E61: ח.פ | F61: עמרם אברהם אגח א | G61: IL0011880445 | H61: ISIN | I61: לא צמוד למדד המחירים לצרכן | J61: ישראל | K61: ישראל | L61: סחיר | M61: TASE | N61: בנייה | O61: לא | P61: N/R | Q61: אחר | R61: מנפיק | S61: ILS | T61: 1.568 | U61: 31/05/2027 | V61: 0.06 | W61: 0.0618 | X61: החוב לא נחות | Y61: לא | Z61: 16100 | AA61: 1 | AB61: 101.88 | AD61: 16.403 | AG61: שווי הוגן | AH61: 6.4e-05 | AI61: 0.040357923 | AJ61: 0.0016260149
A62: 158 | B62: 1522 | C62: פסיפיק אוק אסאואר(בי וי איי) הולדינגס | D62: 1900288 | E62: ח.פ | F62: פסיפיק אגח ג | G62: IL0011976805 | H62: ISIN | I62: לא צמוד למדד המחירים לצרכן | J62: ישראל | K62: ארה"ב | L62: סחיר | M62: TASE | N62: נדל"ן מניב בחו"ל | O62: לא | P62: AA | Q62: S&P מעלות | R62: נייר ערך | S62: ILS | T62: 2.048 | U62: 30/06/2026 | V62: 0.09 | W62: 0.06228 | X62: החוב לא נחות | Y62: לא | Z62: 10000 | AA62: 1 | AB62: 108.21 | AD62: 10.821 | AG62: שווי הוגן | AH62: 3.1e-05 | AI62: 0.026624496 | AJ62: 0.0010726971
A63: 158 | B63: 1522 | C63: בנק לאומי לישראל בע"מ | D63: 520018078 | E63: ח.פ | F63: LUMIIT 3.275 01/29/31 | G63: IL0060404899 | H63: ISIN | I63: צמוד למט"ח | J63: ישראל | K63: ישראל | L63: סחיר | M63: אחר | N63: Banks | O63: לא | P63: BBB | Q63: S&P | R63: נייר ערך | S63: USD | T63: 1.69 | U63: 29/01/2031 | V63: 0.03275 | W63: 0.06581 | X63: החוב לא נחות | Y63: לא | Z63: 2000 | AA63: 3.681 | AB63: 92.834 | AD63: 6.875 | AG63: שווי הוגן | AH63: 3e-06 | AI63: 0.016916266 | AJ63: 0.00068155393
A64: 158 | B64: 1522 | C64: לוויתן בונד בע"מ | D64: 516223864 | E64: ח.פ | F64: LVIATH 6.5 30/06/27 | G64: IL0011677825 | H64: ISIN | I64: צמוד למט"ח | J64: ישראל | K64: ישראל | L64: סחיר | M64: אחר | N64: Energy Equipment & Services | O64: לא | P64: BB- | Q64: S&P | R64: נייר ערך | S64: USD | T64: 2.79 | U64: 30/06/2027 | V64: 0.065 | W64: 0.07799 | X64: החוב לא נחות | Y64: לא | Z64: 1000 | AA64: 3.681 | AB64: 96.843 | AD64: 3.625 | AG64: שווי הוגן | AH64: 2e-06 | AI64: 0.0089181533 | AJ64: 0.00035931111
A65: 158 | B65: 1522 | C65: בנק מזרחי טפחות בע"מ | D65: 520000522 | E65: ח.פ | F65: MZRHIT 3.077 04/07/31 | G65: IL0069508369 | H65: ISIN | I65: צמוד למט"ח | J65: ישראל | K65: ישראל | L65: סחיר | M65: אחר | N65: Banks | O65: לא | P65: BBB- | Q65: S&P | R65: נייר ערך | S65: USD | T65: 1.87 | U65: 07/04/2031 | V65: 0.03077 | W65: 0.07118 | X65: החוב לא נחות | Y65: לא | Z65: 2000 | AA65: 3.681 | AB65: 91.664 | AD65: 6.857 | AG65: שווי הוגן | AH65: 3e-06 | AI65: 0.016871686 | AJ65: 0.00067975781
A66: 158 | B66: 1522 | C66: Summit Properties Limited | D66: 213800KLWIACHRBYR158 | E66: LEI | F66: SMTPLN 2 01/31/25 | G66: XS1757821688 | H66: ISIN | I66: צמוד למט"ח | J66: חו"ל | K66: גרמניה | L66: סחיר | M66: אחר | N66: Real Estate Management & Development | O66: לא | P66: Ba1 | Q66: S&P | R66: נייר ערך | S66: EUR | T66: 0.77 | U66: 31/01/2025 | V66: 0.02 | W66: 0.0763 | X66: החוב לא נחות | Y66: לא | Z66: 1000 | AA66: 3.979 | AB66: 95.576 | AD66: 3.816 | AG66: שווי הוגן | AH66: 3e-06 | AI66: 0.0093898728 | AJ66: 0.00037831662
A67: 158 | B67: 9935 | C67: DELL INC | D67: 3E70L4WYANTIWWIPHC81 | E67: LEI | F67: DELL 5 1/4 02/01/28 | G67: US24703DBJ90 | H67: ISIN | I67: צמוד למט"ח | J67: חו"ל | K67: ארה"ב | L67: סחיר | M67: NYSE | N67: תוכנה ואינטרנט | O67: לא | P67: BBB | Q67: S&P | R67: נייר ערך | S67: USD | T67: 3.32 | U67: 01/02/2028 | V67: 0.0525 | W67: 0.05032 | X67: החוב לא נחות | Y67: לא | Z67: 260000 | AA67: 3.681 | AB67: 101.288 | AD67: 977.622 | AG67: שווי הוגן | AH67: 0.00026 | AI67: 0.0058497028 | AJ67: 0.00089182883
A68: 158 | B68: 9935 | C68: איירפורט סיטי בע"מ | D68: 511659401 | E68: ח.פ | F68: איירפורט אגח ה | G68: IL0011334872 | H68: ISIN | I68: צמוד למדד המחירים לצרכן | J68: ישראל | K68: ישראל | L68: סחיר | M68: TASE | N68: נדל"ן מניב בישראל | O68: לא | P68: AA | Q68: S&P מעלות | R68: נייר ערך | S68: ILS | T68: 2.698 | U68: 28/02/2029 | V68: 0.0234 | W68: 0.02157 | X68: החוב לא נחות | Y68: לא | Z68: 1031250 | AA68: 1 | AB68: 111.84 | AD68: 1153.35 | AG68: שווי הוגן | AH68: 0.000398 | AI68: 0.0069011921 | AJ68: 0.0010521359
A69: 158 | B69: 9935 | C69: אלביט מערכות בע"מ | D69: 520043027 | E69: ח.פ | F69: אלביט מערכות ב' 1.08% | G69: IL0011782351 | H69: ISIN | I69: לא צמוד למדד המחירים לצרכן | J69: ישראל | K69: ישראל | L69: סחיר | M69: TASE | N69: ביטחוניות | O69: לא | P69: AA | Q69: S&P מעלות | R69: נייר ערך | S69: ILS | T69: 2.597 | U69: 01/07/2029 | V69: 0.0108 | W69: 0.04475 | X69: החוב לא נחות | Y69: לא | Z69: 1482900 | AA69: 1 | AB69: 92.04 | AD69: 1364.861 | AG69: שווי הוגן | AH69: 0.00113 | AI69: 0.0081667916 | AJ69: 0.0012450855
A70: 158 | B70: 9935 | C70: אלוני-חץ נכסים והשקעות בע"מ | D70: 520038506 | E70: ח.פ | F70: אלוני חץ אגח ט | G70: IL0039003541 | H70: ISIN | I70: לא צמוד למדד המחירים לצרכן | J70: ישראל | K70: ישראל | L70: סחיר | M70: TASE | N70: נדל"ן מניב בישראל | O70: לא | P70: AA- | Q70: S&P מעלות | R70: נייר ערך | S70: ILS | T70: 1.858 | U70: 28/02/2027 | V70: 0.0385 | W70: 0.04768 | X70: החוב לא נחות | Y70: לא | Z70: 1506453.3 | AA70: 1 | AB70: 98.71 | AD70: 1487.02 | AG70: שווי הוגן | AH70: 0.001572 | AI70: 0.0088977423 | AJ70: 0.0013565242
A71: 158 | B71: 9935 | C71: אלוני-חץ נכסים והשקעות בע"מ | D71: 520038506 | E71: ח.פ | F71: אלוני חץ אגח טו | G71: IL0011894149 | H71: ISIN | I71: צמוד למדד המחירים לצרכן | J71: ישראל | K71: ישראל | L71: סחיר | M71: TASE | N71: נדל"ן מניב בישראל | O71: לא | P71: Aa3 | Q71: מידרוג Moodys | R71: נייר ערך | S71: ILS | T71: 7.443 | U71: 28/02/2037 | V71: 0.0256 | W71: 0.03962 | X71: החוב לא נחות | Y71: לא | Z71: 520000 | AA71: 1 | AB71: 94.33 | AD71: 490.516 | AG71: שווי הוגן | AH71: 0.000778 | AI71: 0.0029350545 | AJ71: 0.00044746996
...

Sheet מניות מבכ ויהש
A1: מספר קופה/קרן/ח.פ. עבור חברת ביטוח | B1: מספר מסלול | C1: שם מנפיק | D1: מספר מנפיק | E1: סוג מספר מזהה מנפיק | F1: שם נייר ערך | G1: מספר נייר ערך | H1: סוג מספר נייר ערך | I1: מאפיין עיקרי | J1: ישראל/חו"ל | K1: מדינה לפי חשיפה כלכלית | L1: סטאטוס סחירות | M1: זירת מסחר | N1: ענף מסחר | O1: בעל עניין/צד קשור | P1: מטבע פעילות | Q1: ערך נקוב (יחידות) | R1: שער חליפין | S1: שער נייר הערך | T1: סכום לקבל (במטבע הפעילות) | U1: שווי הוגן (באלפי ש"ח) | V1: שיעור מערך נקוב מונפק | W1: שיעור מנכסי אפיק ההשקעה | X1: שיעור מסך נכסי ההשקעה
A2: 158 | B2: 1522 | C2: נובה מכשירי מדידה בע"מ | D2: 511812463 | E2: ח.פ | F2: Nova measuring inst | G2: IL0010845571 | H2: ISIN | I2: מניות | J2: ישראל | K2: אסיה | L2: סחיר | M2: NASDAQ | N2: מוליכים למחצה | O2: לא | P2: USD | Q2: 60 | R2: 3.681 | S2: 177.38 | U2: 39.176 | V2: 2e-06 | W2: 0.017755242 | X2: 0.0038835726
A3: 158 | B3: 1522 | C3: איידנטי הלת'קייר בע"מ | D3: 515679405 | E3: ח.פ | F3: איידנטי הלת'קייר | G3: IL0011774507 | H3: ISIN | I3: מניות | J3: ישראל | K3: ישראל | L3: סחיר | M3: TASE | N3: תוכנה ואינטרנט | O3: לא | P3: ILS | Q3: 5100 | R3: 1 | S3: 312.3 | U3: 15.927 | V3: 0.000405 | W3: 0.0072185014 | X3: 0.00157889
A4: 158 | B4: 1522 | C4: אלביט מערכות בע"מ | D4: 520043027 | E4: ח.פ | F4: אלביט מערכות | G4: IL0010811243 | H4: ISIN | I4: מניות | J4: ישראל | K4: ישראל | L4: סחיר | M4: TASE | N4: ביטחוניות | O4: לא | P4: ILS | Q4: 22 | R4: 1 | S4: 77500 | U4: 17.05 | V4: 0 | W4: 0.0077273266 | X4: 0.0016901844
A5: 158 | B5: 1522 | C5: אלוני-חץ נכסים והשקעות בע"מ | D5: 520038506 | E5: ח.פ | F5: אלוני חץ | G5: IL0003900136 | H5: ISIN | I5: מניות | J5: ישראל | K5: ישראל | L5: סחיר | M5: TASE | N5: נדל"ן מניב בישראל | O5: לא | P5: ILS | Q5: 1400 | R5: 1 | S5: 2653 | T5: 0.252 | U5: 37.394 | V5: 8e-06 | W5: 0.016947546 | X5: 0.0037069065
A6: 158 | B6: 1522 | C6: אמות השקעות בע"מ | D6: 520026683 | E6: ח.פ | F6: אמות | G6: IL0010972789 | H6: ISIN | I6: מניות | J6: ישראל | K6: ישראל | L6: סחיר | M6: TASE | N6: נדל"ן מניב בישראל | O6: לא | P6: ILS | Q6: 3039 | R6: 1 | S6: 1749 | U6: 53.152 | V6: 6e-06 | W6: 0.024089367 | X6: 0.0052690245
A7: 158 | B7: 1522 | C7: אנלייט אנרגיה מתחדשת בע"מ | D7: 520041146 | E7: ח.פ | F7: אנלייט אנרגיה | G7: IL0007200111 | H7: ISIN | I7: מניות | J7: ישראל | K7: ישראל | L7: סחיר | M7: TASE | N7: אנרגיה מתחדשת | O7: לא | P7: ILS | Q7: 918.8 | R7: 1 | S7: 6299 | U7: 57.875 | V7: 8e-06 | W7: 0.026229951 | X7: 0.0057372306
A8: 158 | B8: 1522 | C8: אנרג'יקס אנרגיות מתחדשות בע"מ | D8: 513901371 | E8: ח.פ | F8: אנרג'יקס | G8: IL0011233553 | H8: ISIN | I8: מניות | J8: ישראל | K8: ישראל | L8: סחיר | M8: TASE | N8: אנרגיה מתחדשת | O8: לא | P8: ILS | Q8: 6766 | R8: 1 | S8: 1352 | U8: 91.476 | V8: 1.2e-05 | W8: 0.041458499 | X8: 0.0090681437
A9: 158 | B9: 1522 | C9: בזק החברה הישראלית לתקשורת בע"מ | D9: 520031931 | E9: ח.פ | F9: בזק | G9: IL0002300114 | H9: ISIN | I9: מניות | J9: ישראל | K9: ישראל | L9: סחיר | M9: TASE | N9: תקשורת ומדיה | O9: לא | P9: ILS | Q9: 16485 | R9: 1 | S9: 473 | U9: 77.974 | V9: 6e-06 | W9: 0.035339059 | X9: 0.0077296495
A10: 158 | B10: 1522 | C10: בליץ טכנולוגיות בעמ | D10: 520038779 | E10: ח.פ | F10: בליץ | G10: IL0004240102 | H10: ISIN | I10: מניות | J10: ישראל | K10: ישראל | L10: סחיר | M10: TASE | N10: אלקטרוניקה ואופטיקה | O10: לא | P10: ILS | Q10: 0.12 | R10: 1 | S10: 439.6 | U10: 0.001 | V10: 0 | W10: 2.3908031e-07 | X10: 5.2293612e-08
A11: 158 | B11: 1522 | C11: בנק דיסקונט לישראל בע"מ | D11: 520007030 | E11: ח.פ | F11: דיסקונט | G11: IL0006912120 | H11: ISIN | I11: מניות | J11: ישראל | K11: ישראל | L11: סחיר | M11: TASE | N11: בנקים | O11: לא | P11: ILS | Q11: 8539 | R11: 1 | S11: 1946 | T11: 1.269 | U11: 167.438 | V11: 7e-06 | W11: 0.075885384 | X11: 0.016598275
A12: 158 | B12: 1522 | C12: י.ח.דמרי בניה ופיתוח בע"מ | D12: 511399388 | E12: ח.פ | F12: דמרי | G12: IL0010903156 | H12: ISIN | I12: מניות | J12: ישראל | K12: ישראל | L12: סחיר | M12: TASE | N12: בנייה | O12: לא | P12: ILS | Q12: 230 | R12: 1 | S12: 28600 | U12: 65.78 | V12: 1.2e-05 | W12: 0.029812525 | X12: 0.0065208405
A13: 158 | B13: 1522 | C13: הפניקס אחזקות בע"מ | D13: 520017450 | E13: ח.פ | F13: הפניקס | G13: IL0007670123 | H13: ISIN | I13: מניות | J13: ישראל | K13: ישראל | L13: סחיר | M13: TASE | N13: ביטוח | O13: לא | P13: ILS | Q13: 1261 | R13: 1 | S13: 3810 | U13: 48.044 | V13: 5e-06 | W13: 0.021774337 | X13: 0.0047626621
A14: 158 | B14: 1522 | C14: ישראל קנדה (ט.ר) בעמ | D14: 520039298 | E14: ח.פ | F14: ישראל קנדה | G14: IL0004340191 | H14: ISIN | I14: מניות | J14: ישראל | K14: ישראל | L14: סחיר | M14: TASE | N14: בנייה | O14: לא | P14: ILS | Q14: 3300 | R14: 1 | S14: 1475 | U14: 48.675 | V14: 1.1e-05 | W14: 0.022060271 | X14: 0.0048252039
A15: 158 | B15: 1522 | C15: כלל החזקות עסקי ביטוח בע"מ | D15: 520036120 | E15: ח.פ | F15: כלל ביטוח | G15: IL0002240146 | H15: ISIN | I15: מניות | J15: ישראל | K15: ישראל | L15: סחיר | M15: TASE | N15: ביטוח | O15: לא | P15: ILS | Q15: 540 | R15: 1 | S15: 6569 | U15: 35.473 | V15: 7e-06 | W15: 0.016076737 | X15: 0.0035164361
A16: 158 | B16: 1522 | C16: בנק לאומי לישראל בע"מ | D16: 520018078 | E16: ח.פ | F16: לאומי | G16: IL0006046119 | H16: ISIN | I16: מניות | J16: ישראל | K16: ישראל | L16: סחיר | M16: TASE | N16: בנקים | O16: לא | P16: ILS | Q16: 6909 | R16: 1 | S16: 3100 | T16: 1.656 | U16: 215.835 | V16: 4e-06 | W16: 0.09781986 | X16: 0.021395964
A17: 158 | B17: 1522 | C17: בנק מזרחי טפחות בע"מ | D17: 520000522 | E17: ח.פ | F17: מזרחי טפחות | G17: IL0006954379 | H17: ISIN | I17: מניות | J17: ישראל | K17: ישראל | L17: סחיר | M17: TASE | N17: בנקים | O17: לא | P17: ILS | Q17: 737 | R17: 1 | S17: 14000 | U17: 103.18 | V17: 3e-06 | W17: 0.046762789 | X17: 0.010228342
A18: 158 | B18: 1522 | C18: מטריקס אי.טי בע"מ | D18: 520039413 | E18: ח.פ | F18: מטריקס | G18: IL0004450156 | H18: ISIN | I18: מניות | J18: ישראל | K18: ישראל | L18: סחיר | M18: TASE | N18: שירותי מידע | O18: לא | P18: ILS | Q18: 618 | R18: 1 | S18: 8160 | T18: 0.785 | U18: 51.214 | V18: 1e-05 | W18: 0.023210832 | X18: 0.0050768639
A19: 158 | B19: 1522 | C19: מיטרוניקס בע"מ | D19: 511527202 | E19: ח.פ | F19: מיטרוניקס | G19: IL0010910656 | H19: ISIN | I19: מניות | J19: ישראל | K19: ישראל | L19: סחיר | M19: TASE | N19: רובוטיקה ותלת מימד | O19: לא | P19: ILS | Q19: 890 | R19: 1 | S19: 3622 | U19: 32.236 | V19: 8e-06 | W19: 0.014609769 | X19: 0.0031955687
A20: 158 | B20: 1522 | C20: מליסרון בע"מ | D20: 520037789 | E20: ח.פ | F20: מליסרון | G20: IL0003230146 | H20: ISIN | I20: מניות | J20: ישראל | K20: ישראל | L20: סחיר | M20: TASE | N20: נדל"ן מניב בישראל | O20: לא | P20: ILS | Q20: 257 | R20: 1 | S20: 26900 | T20: 0.649 | U20: 69.782 | V20: 5e-06 | W20: 0.03162628 | X20: 0.00691756
A21: 158 | B21: 1522 | C21: נאוויטס פטרוליום, שותפות מוגבלת | D21: 550263107 | E21: ח.פ | F21: נאוויטס פט יהש | G21: IL0011419699 | H21: ISIN | I21: מניות | J21: חו"ל | K21: ארה"ב | L21: סחיר | M21: TASE | N21: חיפושי נפט וגז | O21: לא | P21: ILS | Q21: 481 | R21: 1 | S21: 4170 | U21: 20.058 | V21: 5e-06 | W21: 0.0090904633 | X21: 0.0019883409
A22: 158 | B22: 1522 | C22: נובה מכשירי מדידה בע"מ | D22: 511812463 | E22: ח.פ | F22: נובה | G22: IL0010845571 | H22: ISIN | I22: מניות | J22: ישראל | K22: ישראל | L22: סחיר | M22: TASE | N22: מוליכים למחצה | O22: לא | P22: ILS | Q22: 21 | R22: 1 | S22: 64720 | U22: 13.591 | V22: 1e-06 | W22: 0.0061597444 | X22: 0.0013473099
A23: 158 | B23: 1522 | C23: ניו-מד אנרג'י- שותפות מוגבלת | D23: 550013098 | E23: ח.פ | F23: ניו-מד אנרג'י יהש | G23: IL0004750209 | H23: ISIN | I23: מניות | J23: ישראל | K23: ישראל | L23: סחיר | M23: TASE | N23: חיפושי נפט וגז | O23: לא | P23: ILS | Q23: 2366 | R23: 1 | S23: 935.3 | T23: 0.453 | U23: 22.583 | V23: 2e-06 | W23: 0.01023475 | X23: 0.0022386287
A24: 158 | B24: 1522 | C24: נייס מערכות בע"מ | D24: 520036872 | E24: ח.פ | F24: נייס | G24: IL0002730112 | H24: ISIN | I24: מניות | J24: ישראל | K24: ישראל | L24: סחיר | M24: TASE | N24: תוכנה ואינטרנט | O24: לא | P24: ILS | Q24: 60 | R24: 1 | S24: 95150 | U24: 57.09 | V24: 1e-06 | W24: 0.025874081 | X24: 0.0056593917
A25: 158 | B25: 1522 | C25: קבוצת עזריאלי בע"מ (לשעבר קנית מימון) | D25: 510960719 | E25: ח.פ | F25: עזריאלי קבוצה | G25: IL0011194789 | H25: ISIN | I25: מניות | J25: ישראל | K25: ישראל | L25: סחיר | M25: TASE | N25: נדל"ן מניב בישראל | O25: לא | P25: ILS | Q25: 364 | R25: 1 | S25: 26610 | U25: 96.86 | V25: 3e-06 | W25: 0.043898648 | X25: 0.0096018732
A26: 158 | B26: 1522 | C26: בנק הפועלים בע"מ | D26: 520000118 | E26: ח.פ | F26: פועלים | G26: IL0006625771 | H26: ISIN | I26: מניות | J26: ישראל | K26: ישראל | L26: סחיר | M26: TASE | N26: בנקים | O26: לא | P26: ILS | Q26: 3948 | R26: 1 | S26: 3500 | T26: 1.039 | U26: 139.219 | V26: 3e-06 | W26: 0.063096314 | X26: 0.013800945
A27: 158 | B27: 1522 | C27: פוקס-ויזל בע"מ | D27: 512157603 | E27: ח.פ | F27: פוקס- ויזל | G27: IL0010870223 | H27: ISIN | I27: מניות | J27: ישראל | K27: ישראל | L27: סחיר | M27: TASE | N27: רשתות שיווק | O27: לא | P27: ILS | Q27: 160 | R27: 1 | S27: 34140 | U27: 54.624 | V27: 1.2e-05 | W27: 0.024756451 | X27: 0.0054149345
A28: 158 | B28: 1522 | C28: פורמולה מערכות (1985)בע"מ | D28: 520036690 | E28: ח.פ | F28: פורמולה מערכות | G28: IL0002560162 | H28: ISIN | I28: מניות | J28: ישראל | K28: ישראל | L28: סחיר | M28: TASE | N28: שירותי מידע | O28: לא | P28: ILS | Q28: 99 | R28: 1 | S28: 30030 | U28: 29.73 | V28: 6e-06 | W28: 0.013473965 | X28: 0.0029471364
A29: 158 | B29: 1522 | C29: קמטק בע"מ | D29: 511235434 | E29: ח.פ | F29: קמטק | G29: IL0010952641 | H29: ISIN | I29: מניות | J29: ישראל | K29: ישראל | L29: סחיר | M29: TASE | N29: מוליכים למחצה | O29: לא | P29: ILS | Q29: 270 | R29: 1 | S29: 30800 | U29: 83.16 | V29: 6e-06 | W29: 0.037689412 | X29: 0.0082437382
A30: 158 | B30: 1522 | C30: ריט 1 בע"מ | D30: 513821488 | E30: ח.פ | F30: ריט 1 | G30: IL0010989205 | H30: ISIN | I30: מניות | J30: ישראל | K30: ישראל | L30: סחיר | M30: TASE | N30: נדל"ן מניב בישראל | O30: לא | P30: ILS | Q30: 1543 | R30: 1 | S30: 1566 | U30: 24.163 | V30: 8e-06 | W30: 0.010951222 | X30: 0.0023953412
A31: 158 | B31: 1522 | C31: תדיראן גרופ בע"מ | D31: 520036732 | E31: ח.פ | F31: תדיראן גרופ | G31: IL0002580129 | H31: ISIN | I31: מניות | J31: ישראל | K31: ישראל | L31: סחיר | M31: TASE | N31: מסחר | O31: לא | P31: ILS | Q31: 52 | R31: 1 | S31: 30040 | T31: 0.137 | U31: 15.758 | V31: 6e-06 | W31: 0.0071418989 | X31: 0.0015621349
A32: 158 | B32: 1522 | C32: amazon.com | D32: 549300LQHH5G4WPME241 | E32: LEI | F32: AMAZON.COM INC | G32: US0231351067 | H32: ISIN | I32: מניות | J32: חו"ל | K32: ארה"ב | L32: סחיר | M32: NASDAQ | N32: Textiles, Apparel & Luxury Goods | O32: לא | P32: USD | Q32: 65 | R32: 3.681 | S32: 180.38 | U32: 43.159 | V32: 0 | W32: 0.019560162 | X32: 0.0042783594
A33: 158 | B33: 1522 | C33: ASML HOLDING NV-NY | D33: 724500Y6DUVHQD6OXN27 | E33: LEI | F33: Asml Holding NV | G33: USN070592100 | H33: ISIN | I33: מניות | J33: חו"ל | K33: ארה"ב | L33: סחיר | M33: NASDAQ | N33: Semiconductors & Semiconductor Equipment | O33: לא | P33: USD | Q33: 25 | R33: 3.681 | S33: 97047 | U33: 89.308 | V33: 0 | W33: 0.040475556 | X33: 0.0088531465
A34: 158 | B34: 1522 | C34: Broadcom Inc | D34: 549300GR48KUO03W2V88 | E34: LEI | F34: BROADCOM LTD | G34: US11135F1012 | H34: ISIN | I34: מניות | J34: חו"ל | K34: ארה"ב | L34: סחיר | M34: NASDAQ | N34: Semiconductors & Semiconductor Equipment | O34: לא | P34: USD | Q34: 6 | R34: 3.681 | S34: 132541 | U34: 29.273 | V34: 0 | W34: 0.013266984 | X34: 0.0029018638
A35: 158 | B35: 1522 | C35: COSTCO WHOLESAL | D35: 29DX7H14B9S6O3FD6V18 | E35: LEI | F35: COSTCO WHOLESAL | G35: US22160K1051 | H35: ISIN | I35: מניות | J35: חו"ל | K35: גלובלי | L35: סחיר | M35: NASDAQ | N35: Food & Staples Retailing Consumer Staples Distribution & Retail | O35: לא | P35: USD | Q35: 15 | R35: 3.681 | S35: 73263 | U35: 40.452 | V35: 0 | W35: 0.018333554 | X35: 0.0040100657
A36: 158 | B36: 1522 | C36: ALPHABET INC | D36: 7ZW8QJWVPR4P1J1KQY45 | E36: LEI | F36: Google Us Class c | G36: US02079K1079 | H36: ISIN | I36: מניות | J36: חו"ל | K36: ארה"ב | L36: סחיר | M36: NASDAQ | N36: Diversified Telecommunication Services | O36: לא | P36: USD | Q36: 162 | R36: 3.681 | S36: 15226 | U36: 90.796 | V36: 0 | W36: 0.041150161 | X36: 0.0090007017
A37: 158 | B37: 1522 | C37: MASTERCARD INC | D37: AR5L2ODV9HN37376R084 | E37: LEI | F37: MASTERCARD UNC | G37: US57636Q1040 | H37: ISIN | I37: מניות | J37: חו"ל | K37: ארה"ב | L37: סחיר | M37: NYSE | N37: Diversified Financial Services Financial Services | O37: לא | P37: USD | Q37: 50 | R37: 3.681 | S37: 481.57 | U37: 88.633 | V37: 0 | W37: 0.040169843 | X37: 0.0087862783
A38: 158 | B38: 1522 | C38: MICROSOFT CORP | D38: INR2EJN1ERAN0W5ZP974 | E38: LEI | F38: Microsoft crop | G38: US5949181045 | H38: ISIN | I38: מניות | J38: חו"ל | K38: ארה"ב | L38: סחיר | M38: NASDAQ | N38: Software | O38: לא | P38: USD | Q38: 8 | R38: 3.681 | S38: 420.72 | U38: 12.389 | V38: 0 | W38: 0.0056150528 | X38: 0.0012281705
A39: 158 | B39: 1522 | C39: NICE LTD | D39: 254900YTY4EF5Z4W0A51 | E39: LEI | F39: NICE SYS ADR | G39: US6536561086 | H39: ISIN | I39: מניות | J39: חו"ל | K39: ישראל | L39: סחיר | M39: NASDAQ | N39: Wireless Telecommunication Services | O39: לא | P39: USD | Q39: 22 | R39: 3.681 | S39: 26062 | U39: 21.106 | V39: 0 | W39: 0.0095653557 | X39: 0.0020922132
A40: 158 | B40: 1522 | C40: אורמת טכנולגיות אינק | D40: 5493000TSHHWY24VHM09 | E40: LEI | F40: Ormat Technologies | G40: US6866881021 | H40: ISIN | I40: מניות | J40: חו"ל | K40: ארה"ב | L40: סחיר | M40: NYSE | N40: Water Utilities | O40: לא | P40: USD | Q40: 28 | R40: 3.681 | S40: 66.19 | U40: 6.822 | V40: 1e-06 | W40: 0.0030918692 | X40: 0.00067627906
...

Sheet קרנות סל
A1: מספר קופה/קרן/ח.פ. עבור חברת ביטוח | B1: מספר מסלול | C1: שם מנפיק | D1: מספר מנפיק | E1: סוג מספר מזהה מנפיק | F1: שם נייר ערך | G1: מספר נייר ערך | H1: סוג מספר נייר ערך | I1: מאפיין עיקרי | J1: ישראל/חו"ל | K1: מדינה לפי חשיפה כלכלית | L1: זירת מסחר | M1: סיווג הקרן | N1: בעל עניין/צד קשור | O1: מטבע פעילות | P1: ערך נקוב (יחידות) | Q1: שער חליפין | R1: שער נייר הערך | S1: סכום לקבל (במטבע הפעילות) | T1: שווי הוגן (באלפי ש"ח) | U1: שיעור מערך נקוב מונפק | V1: שיעור מנכסי אפיק ההשקעה | W1: שיעור מסך נכסי ההשקעה
A2: 158 | B2: 1441 | C2: קסם קרנות נאמנות בע"מ | D2: 510938608 | E2: ח.פ | F2: קסם תל בונד שקלי | G2: IL0011464141 | H2: ISIN | I2: עוקב אחר מדדים אחרים בישראל | J2: ישראל | K2: ישראל | L2: TASE | M2: אג"ח בישראל - חברות והמרה | N2: לא | O2: ILS | P2: 10100 | Q2: 1 | R2: 3844.3 | T2: 388.274 | U2: 0.000289 | V2: 0.72978207 | W2: 0.035401583
A3: 158 | B3: 1441 | C3: קסם קרנות נאמנות בע"מ | D3: 510938608 | E3: ח.פ | F3: קסם.תלבונד ש 50 | G3: IL0011507626 | H3: ISIN | I3: עוקב אחר מדדים אחרים בישראל | J3: ישראל | K3: ישראל | L3: TASE | M3: אג"ח בישראל - חברות והמרה | N3: לא | O3: ILS | P3: 300 | Q3: 1 | R3: 3874.92 | T3: 11.625 | U3: 1.3e-05 | V3: 0.021849351 | W3: 0.0010599077
A4: 158 | B4: 1441 | C4: Real Estate Credit Investments Pcc ltd | D4: 549300D9O5F5P2DTYB19 | E4: LEI | F4: SPDR BLOOMBERG SASB US CORPORA | G4: IE00BLF7VX27 | H4: ISIN | I4: עוקב אחר מדדים אחרים בחו"ל | J4: חו"ל | K4: ארה"ב | L4: LSE | M4: Bond/Fixed Income Funds | N4: לא | O4: USD | P4: 700 | Q4: 3.681 | R4: 27.605 | T4: 71.13 | U4: 0 | V4: 0.13369222 | W4: 0.0064853833
A5: 158 | B5: 1441 | C5: Vanguard Group | D5: QS6WHLCJOJSYY4PYNF72 | E5: LEI | F5: VANGUARD USD CORPORATE BOND UC | G5: IE00BGYWFK87 | H5: ISIN | I5: עוקב אחר מדדים אחרים בחו"ל | J5: חו"ל | K5: ארה"ב | L5: LSE | M5: Bond/Fixed Income Funds | N5: לא | O5: USD | P5: 300 | Q5: 3.681 | R5: 5525 | T5: 61.013 | U5: 0 | V5: 0.11467636 | W5: 0.0055629275
A6: 158 | B6: 1522 | C6: ISHARES USD CROP BOND UCITS ET | D6: 549300QQR5SNTQVNFC45 | E6: LEI | F6: ITB US | G6: US4642887529 | H6: ISIN | I6: עוקב אחר מדדי מניות בחו"ל | J6: חו"ל | K6: ארה"ב | L6: NYSE | M6: מניות בחו"ל חשופות מט"ח | N6: לא | O6: USD | P6: 270 | Q6: 3.681 | R6: 115.77 | T6: 115.06 | U6: 7e-06 | V6: 0.029247139 | W6: 0.011406051
A7: 158 | B7: 1522 | C7: מגדל קרנות נאמנות בע"מ | D7: 511303661 | E7: ח.פ | F7: MTF סל תא 90 | G7: IL0011502593 | H7: ISIN | I7: עוקב אחר מדדי מניות בישראל | J7: ישראל | K7: ישראל | L7: TASE | M7: מניות בישראל | N7: לא | O7: ILS | P7: 8600 | Q7: 1 | R7: 3091 | T7: 265.826 | U7: 0.000239 | V7: 0.067570203 | W7: 0.026351611
A8: 158 | B8: 1522 | C8: קסם קרנות נאמנות בע"מ | D8: 510938608 | E8: ח.פ | F8: קסם קרן סל תא 125 | G8: IL0011463564 | H8: ISIN | I8: עוקב אחר מדדי מניות בישראל | J8: ישראל | K8: ישראל | L8: TASE | M8: מניות בישראל | N8: לא | O8: ILS | P8: 550 | Q8: 1 | R8: 20050 | T8: 110.275 | U8: 1.6e-05 | V8: 0.028030758 | W8: 0.010931677
A9: 158 | B9: 1522 | C9: קסם קרנות נאמנות בע"מ | D9: 510938608 | E9: ח.פ | F9: קסם תא נדלן | G9: IL0011465478 | H9: ISIN | I9: עוקב אחר מדדי מניות בישראל | J9: ישראל | K9: ישראל | L9: TASE | M9: מניות בישראל | N9: לא | O9: ILS | P9: 1900 | Q9: 1 | R9: 8947 | T9: 169.993 | U9: 0.001796 | V9: 0.043210452 | W9: 0.016851585
A10: 158 | B10: 1522 | C10: BlackRock Asset Managment | D10: 549300IJBBIPXKWNXJ28 | E10: LEI | F10: ISHARES EURO STOXX 50 DE | G10: DE0005933956 | H10: ISIN | I10: עוקב אחר מדדי מניות בחו"ל | J10: חו"ל | K10: אירופה | L10: FWB | M10: Equity Funds | N10: לא | O10: EUR | P10: 410 | Q10: 3.979 | R10: 5115 | T10: 83.448 | U10: 4e-06 | V10: 0.021211536 | W10: 0.0082722577
A11: 158 | B11: 1522 | C11: BlackRock Asset Managment | D11: 549300IJBBIPXKWNXJ28 | E11: LEI | F11: Ishares Phlx Se | G11: US4642875235 | H11: ISIN | I11: עוקב אחר מדדי מניות בחו"ל | J11: חו"ל | K11: ארה"ב | L11: NASDAQ | M11: Equity Funds | N11: לא | O11: USD | P11: 60 | Q11: 3.681 | R11: 22592 | T11: 49.897 | U11: 3e-06 | V11: 0.01268322 | W11: 0.0049463114
A12: 158 | B12: 1522 | C12: Invesco investment management limited | D12: 635400KFAN415FMIGG54 | E12: LEI | F12: Powershares QQQ NAS1 | G12: US46090E1038 | H12: ISIN | I12: עוקב אחר מדדי מניות בחו"ל | J12: חו"ל | K12: ארה"ב | L12: NASDAQ | M12: Equity Funds | N12: לא | O12: USD | P12: 410 | Q12: 3.681 | R12: 444.01 | S12: 0.18 | T12: 670.765 | U12: 1e-06 | V12: 0.17050154 | W12: 0.06649366
A13: 158 | B13: 1522 | C13: Invesco investment management limited | D13: 635400KFAN415FMIGG54 | E13: LEI | F13: SOURCE S&P 500 UCITS EFT | G13: IE00B3YCGJ38 | H13: ISIN | I13: עוקב אחר מדדי מניות בחו"ל | J13: חו"ל | K13: ארה"ב | L13: LSE | M13: Equity Funds | N13: לא | O13: USD | P13: 74 | Q13: 3.681 | R13: 102524 | T13: 279.269 | U13: 1.5e-05 | V13: 0.070987331 | W13: 0.027684252
A14: 158 | B14: 1522 | C14: State Street Corp | D14: 549300E2D1JKWI3P9D54 | E14: LEI | F14: SPDR S&P 500 ETF TRUST | G14: US78462F1030 | H14: ISIN | I14: עוקב אחר מדדי מניות בחו"ל | J14: חו"ל | K14: ארה"ב | L14: NYSE | M14: Equity Funds | N14: לא | O14: USD | P14: 350 | Q14: 3.681 | R14: 523.07 | S14: 0.426 | T14: 675.466 | U14: 0 | V14: 0.17169653 | W14: 0.066959695
A15: 158 | B15: 1522 | C15: S&P 500 | D15: Y6X4K52KMJMZE7I7MY94 | E15: LEI | F15: SPDR S&P 500 UCITS EFT | G15: IE000XZSV718 | H15: ISIN | I15: עוקב אחר מדדי מניות בחו"ל | J15: חו"ל | K15: ארה"ב | L15: LSE | M15: Equity Funds | N15: לא | O15: USD | P15: 8700 | Q15: 3.681 | R15: 1267.6 | T15: 405.945 | U15: 0 | V15: 0.10318702 | W15: 0.040241764
A16: 158 | B16: 1522 | C16: Van Eck ETF | D16: 549300WSDUDKDJCJOV22 | E16: LEI | F16: VANECK VECTORS SEMICONDUCTOR | G16: US92189F6768 | H16: ISIN | I16: עוקב אחר מדדי מניות בחו"ל | J16: חו"ל | K16: ארה"ב | L16: NASDAQ | M16: Equity Funds | N16: לא | O16: USD | P16: 55 | Q16: 3.681 | R16: 22499 | T16: 45.55 | U16: 2e-06 | V16: 0.011578425 | W16: 0.0045154541
A17: 158 | B17: 1522 | C17: Vanguard Group | D17: QS6WHLCJOJSYY4PYNF72 | E17: LEI | F17: VANGUARD FTSE BMERGING MARKETS | G17: IE00B3VVMM84 | H17: ISIN | I17: עוקב אחר מדדי מניות בחו"ל | J17: חו"ל | K17: שווקים מתעוררים | L17: LSE | M17: Equity Funds | N17: לא | O17: USD | P17: 500 | Q17: 3.681 | R17: 5682.5 | T17: 104.586 | U17: 0 | V17: 0.026584778 | W17: 0.010367761
