Workbook
Name Additional_Factor: 'אפשרויות בחירה'!$C$701:$C$850
Name Amoritization: 'אפשרויות בחירה'!$C$546:$C$550
Name Capsule: 'אפשרויות בחירה'!$C$926:$C$928
Name Company_Name: 'File Name Info'!$A$34:$A$120
Name Company_Name_ID: 'File Name Info'!$A$34:$B$120
Name Consortium: 'אפשרויות בחירה'!$C$514:$C$515
Name Country_list: 'אפשרויות בחירה'!$C$4:$C$85
Name Country_list_funds: 'אפשרויות בחירה'!$C$4:$C$103
Name CSA: 'אפשרויות בחירה'!$C$688:$C$689
Name Delivery: 'אפשרויות בחירה'!$C$666:$C$667
Name Dependence_Independence: 'אפשרויות בחירה'!$C$654:$C$655
Name Duration_Underlying_Interest_Rate: 'אפשרויות בחירה'!$C$680:$C$687
Name File_Type: 'File Name Info'!$A$10:$A$12
Name Full_File_Type: 'File Name Info'!$A$11:$B$13
Name Full_Type: 'File Name Info'!$A$2:$B$8
Name Full_Type_Nostro: 'File Name Info'!$A$3:$B$6
Name Full_Year: 'File Name Info'!$A$22:$B$31
Name Fund_Strategy: 'אפשרויות בחירה'!$C$597:$C$621
Name Fund_type: 'אפשרויות בחירה'!$C$328:$C$498
Name Holding_interest: 'אפשרויות בחירה'!$C$146:$C$147
Name In_the_books: 'אפשרויות בחירה'!$C$656:$C$657
Name Industry_Sector: 'אפשרויות בחירה'!$C$1129:$C$1245
Name Industry_sector_all: 'אפשרויות בחירה'!$C$202:$C$327
Name Industry_sectors: 'אפשרויות בחירה'!$C$202:$C$327
Name israel_abroad: 'אפשרויות בחירה'!$C$2:$C$3
Name Issuer_Number_Banks: 'אפשרויות בחירה'!$C$111:$C$113
Name Issuer_Number_Fund: 'אפשרויות בחירה'!$C$114:$C$117
Name issuer_number_loan: 'אפשרויות בחירה'!$C$118:$C$126
Name Issuer_Number_Type: 'אפשרויות בחירה'!$C$104:$C$110
Name Issuer_Number_Type_2: 'אפשרויות בחירה'!$C$1076:$C$1079
Name Issuer_Number_Type_3: 'אפשרויות בחירה'!$C$1081:$C$1085
Name Issuer_Number_Type_V2: 'אפשרויות בחירה'!$C$104:$C$110
Name Issuer_Type_TFunds: 'אפשרויות בחירה'!$C$1087:$C$1089
Name Leading_factor: 'אפשרויות בחירה'!$C$692:$C$700
Name Linked_Type: 'אפשרויות בחירה'!$C$516:$C$519
Name other_investments: 'אפשרויות בחירה'!$C$1000:$C$1033
Name Penalty: 'אפשרויות בחירה'!$C$851:$C$852
Name QTR: 'File Name Info'!$A$15:$A$19
Name Rating_Agency: 'אפשרויות בחירה'!$C$188:$C$201
Name real_estate_lifestage: 'אפשרויות בחירה'!$C$634:$C$642
Name real_estate_loans: 'אפשרויות בחירה'!$C$553:$C$591
Name Real_Estate_Main_Use: 'אפשרויות בחירה'!$C$622:$C$633
Name Recourse_Nonrecourse: 'אפשרויות בחירה'!$C$544:$C$545
Name Repayment_Rights: 'אפשרויות בחירה'!$C$551:$C$552
Name Reset_frequency: 'אפשרויות בחירה'!$C$658:$C$665
Name Security_ID_Number_Type: 'אפשרויות בחירה'!$C$1113:$C$1116
Name Security_Number_Loans: 'אפשרויות בחירה'!$C$131
Name Stock_Exchange: 'אפשרויות בחירה'!$C$1283:$C$1315
Name Stock_Exchange_Gov_Bonds: 'אפשרויות בחירה'!$C$148:$C$181
Name Subordination_Risk: 'אפשרויות בחירה'!$C$186:$C$187
Name Tradeable_Status: 'אפשרויות בחירה'!$C$1272:$C$1281
Name Tradeable_Status_All: 'אפשרויות בחירה'!$C$135:$C$145
Name tradeable_status_bonds: 'אפשרויות בחירה'!$C$1248:$C$1253
Name tradeable_status_funds: 'אפשרויות בחירה'!$C$1118:$C$1119
Name tradeable_status_stock: 'אפשרויות בחירה'!$C$1255:$C$1259
Name Tradeable_Status_v2: 'אפשרויות בחירה'!$C$1121:$C$1126
Name tradeable_status_warrants: 'אפשרויות בחירה'!$C$1261:$C$1265
Name tradeable_status_warrants_v2: 'אפשרויות בחירה'!$C$1267:$C$1269
Name Transaction: 'אפשרויות בחירה'!$C$643:$C$646
Name Type: 'File Name Info'!$A$2:$A$8

Sheet עמוד פתיחה
A1: קובץ דיווח עבור רשימת נכסים ברמת הנכס הבודד (חוזר גופים מוסדיים 2015-9-14)
A3: יש לבחור תחום: | D3: נכסי עמיתים - קופות גמל
A5: האם מדובר בקובץ לממומנה או לציבור: | D5: לציבור
A7: יש לבחור את רבעון הדיווח: | D7: 01
A9: יש לבחור את שנת הדיווח: | D9: 2024
A11: יש לבחור את הגוף המוסדי: | D11: תגמולים של עובדים בעירית ת"א יפו א.ש בע"מ
A13: ח.פ. הגוף המוסדי: | D13: 570002618
A15: שם קובץ לשמירה | D15: =IF(D5="לממונה",CONCATENATE(D13, "_",VLOOKUP(D3,Full_Type,2,0),"_",D7,VLOOKUP(D9,Full_Year,2,0),".xlxs"),IF(D5="לציבור",CONCATENATE(D13,"_",VLOOKUP(D3,Full_Type_Nostro,2,0),"_",VLOOKUP(D5,Full_File_Type,2,0),"_",D7,VLOOKUP(D9,Full_Year,2,0),".xlsx"),"שם קובץ לשמירה")) -> 570002618_gm_p_0124.xlsx
A17: פרטי האחראי על הדיווח בגוף המוסדי | B17: שם: | D17: צביקה שמיר , מנכ"ל
B19: מספר טלפון: | D19: 03-5210603
B21: כתובת מייל: | D21: zvi-sha@ovdim-tlv.org.il
A23: הוראות למילוי הדיווח: | D23: יש לדווח לפי ההנחיות בחלק ג' לנספח 5.4.3.2 שבפרק 3 שבחלק 4 לשער 5 בחוזר המאוחד - "רשימת נכסים ברמת הנכס הבודד".

Sheet סכום נכסים
C1: ידווח בקבצי נכסי הנוסטרו בלבד
B2: שווי הוגן | C2: עלות מופחתת | D2: השיטה שיושמה בדוח הכספי | E2: שיעור מסך נכסי השקעה
A3: מזומנים ושווי מזומנים | B3: =SUM('מזומנים ושווי מזומנים'!O:O) -> 140248.74 | D3: =B3+C3 -> 140248.74 | E3: =SUM('מזומנים ושווי מזומנים'!O:O)/B30 -> 0.12589573
A4: איגרות חוב ממשלתיות | B4: =SUM('איגרות חוב ממשלתיות'!U:U) -> 278744.77 | D4: =B4+C4 -> 278744.77 | E4: =SUM('איגרות חוב ממשלתיות'!U:U)/B30 -> 0.25021813
A5: ניירות ערך מסחריים | B5: =SUM('ניירות ערך מסחריים'!AD:AD) -> 2162.809 | D5: =B5+C5 -> 2162.809 | E5: =SUM('ניירות ערך מסחריים'!AD:AD)/B30 -> 0.0019414679
A6: איגרות חוב | B6: =SUM('איגרות חוב'!AD:AD) -> 260026.1 | D6: =B6+C6 -> 260026.1 | E6: =SUM('איגרות חוב'!AD:AD)/B30 -> 0.23341512
A7: מניות, מניות בכורה ויחידות השתתפות | B7: =SUM('מניות מבכ ויהש'!U:U) -> 171789.5 | D7: =B7+C7 -> 171789.5 | E7: =SUM('מניות מבכ ויהש'!U:U)/B30 -> 0.15420862
A8: קרנות סל | B8: =SUM('קרנות סל'!T:T) -> 6173.405 | D8: =B8+C8 -> 6173.405 | E8: =SUM('קרנות סל'!T:T)/B30 -> 0.0055416209
A9: קרנות נאמנות | B9: =SUM('קרנות נאמנות'!T:T) -> 2579.399 | D9: =B9+C9 -> 2579.399 | E9: =SUM('קרנות נאמנות'!T:T)/B30 -> 0.0023154242
A10: כתבי אופציה | B10: =SUM('כתבי אופציה'!W:W) -> 112.229 | D10: =B10+C10 -> 112.229 | E10: =SUM('כתבי אופציה'!W:W)/B30 -> 0.00010074352
A11: אופציות | B11: =SUM(אופציות!V:V) -> 0 | D11: =B11+C11 -> 0 | E11: =SUM(אופציות!V:V)/B30 -> 0
A12: חוזים עתידיים | B12: =SUM('חוזים עתידיים'!R:R) -> 6484.23 | D12: =B12+C12 -> 6484.23 | E12: =SUM('חוזים עתידיים'!R:R)/B30 -> 0.0058206362
A13: מוצרים מובנים | B13: =SUM('מוצרים מובנים'!Z:Z) -> 0 | D13: =B13+C13 -> 0 | E13: =SUM('מוצרים מובנים'!Z:Z)/B30 -> 0
A14: לא סחיר איגרות חוב ממשלתיות | B14: =SUM('לא סחיר איגרות חוב ממשלתיות'!U:U) -> 0 | D14: =B14+C14 -> 0 | E14: =SUM('לא סחיר איגרות חוב ממשלתיות'!U:U)/B30 -> 0
A15: לא סחיר איגרות חוב מיועדות | B15: =SUM('לא סחיר איגרות חוב מיועדות'!N:N) -> 0 | D15: =B15+C15 -> 0 | E15: =SUM('לא סחיר איגרות חוב מיועדות'!N:N)/B30 -> 0
A16: אפיק השקעה מובטח תשואה | B16: =SUM('אפיק השקעה מובטח תשואה'!F:F) -> 0 | D16: =B16+C16 -> 0 | E16: =SUM('אפיק השקעה מובטח תשואה'!F:F)/B30 -> 0
A17: לא סחיר ניירות ערך מסחריים | B17: =SUM('לא סחיר ניירות ערך מסחריים'!AI:AI) -> 5251.985 | D17: =B17+C17 -> 5251.985 | E17: =SUM('לא סחיר ניירות ערך מסחריים'!AI:AI)/B30 -> 0.0047144987
A18: לא סחיר איגרות חוב | B18: =SUM('לא סחיר איגרות חוב'!AG:AG) -> 16970.532 | D18: =B18+C18 -> 16970.532 | E18: =SUM('לא סחיר איגרות חוב'!AG:AG)/B30 -> 0.015233774
A19: לא סחיר מניות, מניות בכורה ויחידות השתתפות | B19: =SUM('לא סחיר מניות מבכ ויהש'!X:X) -> 16868.453 | D19: =B19+C19 -> 16868.453 | E19: =SUM('לא סחיר מניות מבכ ויהש'!X:X)/B30 -> 0.015142141
A20: קרנות השקעה | B20: =SUM('קרנות השקעה'!W:W) -> 156841.86 | D20: =B20+C20 -> 156841.86 | E20: =SUM('קרנות השקעה'!W:W)/B30 -> 0.14079072
A21: לא סחיר כתבי אופציה | B21: =SUM('לא סחיר כתבי אופציה'!Z:Z) -> 20.467 | D21: =B21+C21 -> 20.467 | E21: =SUM('לא סחיר כתבי אופציה'!Z:Z)/B30 -> 1.8372414e-05
A22: לא סחיר אופציות | B22: =SUM('לא סחיר אופציות'!Z:Z) -> 0 | D22: =B22+C22 -> 0 | E22: =SUM('לא סחיר אופציות'!Z:Z)/B30 -> 0
A23: לא סחיר נגזרים אחרים | B23: =SUM('לא סחיר נגזרים אחרים'!R:R) -> 8.08 | D23: =B23+C23 -> 8.08 | E23: =SUM('לא סחיר נגזרים אחרים'!R:R)/B30 -> 7.2530956e-06
A24: הלוואות | B24: =SUM(הלוואות!AT:AT) -> 47806.043 | D24: =B24+C24 -> 47806.043 | E24: =SUM(הלוואות!AT:AT)/B30 -> 0.042913589
A25: לא סחיר מוצרים מובנים | B25: =SUM('לא סחיר מוצרים מובנים'!AB:AB) -> 0 | D25: =B25+C25 -> 0 | E25: =SUM('לא סחיר מוצרים מובנים'!AB:AB)/B30 -> 0
A26: פיקדונות מעל 3 חודשים | B26: =SUM('פיקדונות מעל 3 חודשים'!T:T) -> 0 | D26: =B26+C26 -> 0 | E26: =SUM('פיקדונות מעל 3 חודשים'!T:T)/B30 -> 0
A27: זכויות מקרקעין | B27: =SUM('זכויות מקרקעין'!S:S) -> 5150 | D27: =B27+C27 -> 5150 | E27: =SUM('זכויות מקרקעין'!S:S)/B30 -> 0.0046229508
A28: השקעה בחברות מוחזקות | B28: =SUM('השקעה בחברות מוחזקות'!U:U) -> 0 | D28: =B28+C28 -> 0 | E28: =SUM('השקעה בחברות מוחזקות'!U:U)/B30 -> 0
A29: נכסים אחרים | B29: =SUM('נכסים אחרים'!N:N) -> -3231.508 | D29: =B29+C29 -> -3231.508 | E29: =SUM('נכסים אחרים'!N:N)/B30 -> -0.0029007966
A30: סך הכל נכסים | B30: =IF(SUM(B3:B29)=0,0.0001,SUM(B3:B29)) -> 1114007.1 | C30: =SUM(C3:C29) -> 0 | D30: =SUM(D3:D29) -> 1114007.1 | E30: =SUM(E3:E29) -> 1
A31: מסגרות אשראי
A32: יתרות התחייבויות להשקעה | B32: 55248.74 | E32: =B32/B30 -> 0.049594603

Sheet מזומנים ושווי מזומנים
A1: מספר קופה/קרן/ח.פ. עבור חברת ביטוח | B1: מספר מסלול | C1: שם הבנק | D1: מספר מזהה בנק | E1: סוג מספר מזהה בנק | F1: מאפיין עיקרי | G1: ישראל/חו"ל | H1: בעל עניין/צד קשור | I1: דירוג הבנק | J1: שם מדרג | K1: מטבע פעילות | L1: שווי מטבעי | M1: שער חליפין | N1: שיעור ריבית | O1: שווי הוגן (באלפי ש"ח) | P1: שיעור מנכסי אפיק ההשקעה | Q1: שיעור מסך נכסי ההשקעה
A2: 337 | B2: 1405 | C2: פועלים | D2: 12-600 | E2: סימול בנק | F2: פח"ק/פר"י | G2: ישראל | H2: לא | I2: AAA | J2: S&P מעלות | K2: ILS | L2: 497.749 | M2: 1 | O2: 497.749 | P2: 0.56409121 | Q2: 0.047076096
A3: 337 | B3: 1405 | C3: בנק לאומי לישראל בע"מ | D3: 10-800 | E3: סימול בנק | F3: מזומן ועו"ש בש"ח | G3: ישראל | H3: לא | I3: AAA | J3: S&P מעלות | K3: ILS | L3: 133.918 | M3: 1 | N3: 0.0405 | O3: 133.918 | P3: 0.15176758 | Q3: 0.012665727
A4: 337 | B4: 1405 | C4: פועלים | D4: 12-600 | E4: סימול בנק | F4: מזומן ועו"ש נקוב במט"ח | G4: חו"ל | H4: לא | I4: AAA | J4: S&P מעלות | K4: USD | L4: 65.885 | M4: 3.681 | O4: 242.522 | P4: 0.27484618 | Q4: 0.022937222
A5: 337 | B5: 1405 | C5: פועלים | D5: 12-600 | E5: סימול בנק | F5: מזומן ועו"ש נקוב במט"ח | G5: חו"ל | H5: לא | I5: AAA | J5: S&P מעלות | K5: EUR | L5: 2.06 | M5: 3.979 | O5: 8.197 | P5: 0.0092899716 | Q5: 0.00077529234
A6: 337 | B6: 1405 | C6: בנק לאומי לישראל בע"מ | D6: 10-800 | E6: סימול בנק | F6: מזומן ועו"ש בש"ח | G6: ישראל | H6: לא | I6: AAA | J6: S&P מעלות | K6: ILS | L6: 0.004 | M6: 1 | N6: 0.0405 | O6: 0.004 | P6: 5.0544509e-06 | Q6: 4.2181798e-07
A7: 337 | B7: 1477 | C7: פועלים | D7: 12-600 | E7: סימול בנק | F7: פח"ק/פר"י | G7: ישראל | H7: לא | I7: AAA | J7: S&P מעלות | K7: ILS | L7: 100.567 | M7: 1 | O7: 100.567 | P7: 0.061529878 | Q7: 0.010082965
A8: 337 | B8: 1477 | C8: פועלים | D8: 12-600 | E8: סימול בנק | F8: מזומן ועו"ש נקוב במט"ח | G8: ישראל | H8: לא | I8: AAA | J8: S&P מעלות | K8: CHF | L8: 0.648 | M8: 4.074 | O8: 2.639 | P8: 0.0016147016 | Q8: 0.00026460282
A9: 337 | B9: 1477 | C9: בנק לאומי לישראל בע"מ | D9: 10-800 | E9: סימול בנק | F9: מזומן ועו"ש בש"ח | G9: ישראל | H9: לא | I9: AAA | J9: S&P מעלות | K9: ILS | L9: 441.262 | M9: 1 | N9: 0.0405 | O9: 441.262 | P9: 0.26997726 | Q9: 0.044241454
A10: 337 | B10: 1477 | C10: פועלים | D10: 12-600 | E10: סימול בנק | F10: מזומן ועו"ש נקוב במט"ח | G10: חו"ל | H10: לא | I10: AAA | J10: S&P מעלות | K10: USD | L10: 250.048 | M10: 3.681 | O10: 920.426 | P10: 0.56314351 | Q10: 0.092282911
A11: 337 | B11: 1477 | C11: פועלים | D11: 12-600 | E11: סימול בנק | F11: מזומן ועו"ש נקוב במט"ח | G11: חו"ל | H11: לא | I11: AAA | J11: S&P מעלות | K11: HKD | L11: 2.916 | M11: 0.47 | O11: 1.371 | P11: 0.00083909408 | Q11: 0.00013750322
A12: 337 | B12: 1477 | C12: פועלים | D12: 12-600 | E12: סימול בנק | F12: מזומן ועו"ש נקוב במט"ח | G12: חו"ל | H12: לא | I12: AAA | J12: S&P מעלות | K12: EUR | L12: 40.699 | M12: 3.979 | O12: 161.946 | P12: 0.09908338 | Q12: 0.016236896
A13: 337 | B13: 1477 | C13: פועלים | D13: 12-600 | E13: סימול בנק | F13: מזומן ועו"ש נקוב במט"ח | G13: חו"ל | H13: לא | I13: AAA | J13: S&P מעלות | K13: JPY | L13: 88.168 | M13: 2.433 | O13: 2.145 | P13: 0.0013126726 | Q13: 0.00021510903
A14: 337 | B14: 1477 | C14: פועלים | D14: 12-600 | E14: סימול בנק | F14: מזומן ועו"ש נקוב במט"ח | G14: חו"ל | H14: לא | I14: AAA | J14: S&P מעלות | K14: GBP | L14: 0.341 | M14: 4.654 | O14: 1.587 | P14: 0.00097121907 | Q14: 0.00015915468
A15: 337 | B15: 1477 | C15: פועלים | D15: 12-600 | E15: סימול בנק | F15: מזומן ועו"ש בש"ח | G15: ישראל | H15: לא | I15: AAA | J15: S&P מעלות | K15: ILS | L15: 2.498 | M15: 1 | O15: 2.498 | P15: 0.0015282763 | Q15: 0.00025044022
A16: 337 | B16: 9962 | C16: פועלים | D16: 12-600 | E16: סימול בנק | F16: פח"ק/פר"י | G16: ישראל | H16: לא | I16: AAA | J16: S&P מעלות | K16: ILS | L16: 3729.594 | M16: 1 | O16: 3729.594 | P16: 0.69582212 | Q16: 0.1208265
A17: 337 | B17: 9962 | C17: פועלים | D17: 12-600 | E17: סימול בנק | F17: מזומן ועו"ש נקוב במט"ח | G17: ישראל | H17: לא | I17: AAA | J17: S&P מעלות | K17: CHF | L17: 1.057 | M17: 4.074 | O17: 4.306 | P17: 0.00080344727 | Q17: 0.00013951514
A18: 337 | B18: 9962 | C18: בנק לאומי לישראל בע"מ | D18: 10-800 | E18: סימול בנק | F18: מזומן ועו"ש בש"ח | G18: ישראל | H18: לא | I18: AAA | J18: S&P מעלות | K18: ILS | L18: 340.596 | M18: 1 | N18: 0.0405 | O18: 340.596 | P18: 0.06354428 | Q18: 0.011034189
A19: 337 | B19: 9962 | C19: פועלים | D19: 12-600 | E19: סימול בנק | F19: מזומן ועו"ש נקוב במט"ח | G19: חו"ל | H19: לא | I19: AAA | J19: S&P מעלות | K19: USD | L19: 164.928 | M19: 3.681 | O19: 607.1 | P19: 0.11326528 | Q19: 0.019668026
A20: 337 | B20: 9962 | C20: פועלים | D20: 12-600 | E20: סימול בנק | F20: מזומן ועו"ש נקוב במט"ח | G20: חו"ל | H20: לא | I20: AAA | J20: S&P מעלות | K20: HKD | L20: 0.908 | M20: 0.47 | O20: 0.427 | P20: 7.9663745e-05 | Q20: 1.3833264e-05
A21: 337 | B21: 9962 | C21: פועלים | D21: 12-600 | E21: סימול בנק | F21: מזומן ועו"ש נקוב במט"ח | G21: חו"ל | H21: לא | I21: AAA | J21: S&P מעלות | K21: EUR | L21: 168.797 | M21: 3.979 | O21: 671.659 | P21: 0.12530992 | Q21: 0.021759525
A22: 337 | B22: 9962 | C22: פועלים | D22: 12-600 | E22: סימול בנק | F22: מזומן ועו"ש נקוב במט"ח | G22: חו"ל | H22: לא | I22: AAA | J22: S&P מעלות | K22: JPY | L22: 99.373 | M22: 2.433 | O22: 2.418 | P22: 0.00045114956 | Q22: 7.8340165e-05
A23: 337 | B23: 9962 | C23: פועלים | D23: 12-600 | E23: סימול בנק | F23: מזומן ועו"ש נקוב במט"ח | G23: חו"ל | H23: לא | I23: AAA | J23: S&P מעלות | K23: GBP | L23: 0.297 | M23: 4.654 | O23: 1.383 | P23: 0.00025810519 | Q23: 4.4818847e-05
A24: 337 | B24: 9962 | C24: פועלים | D24: 12-600 | E24: סימול בנק | F24: מזומן ועו"ש בש"ח | G24: ישראל | H24: לא | I24: AAA | J24: S&P מעלות | K24: ILS | L24: 2.498 | M24: 1 | O24: 2.498 | P24: 0.000466024 | Q24: 8.0923048e-05
A25: 337 | B25: 9963 | C25: פועלים | D25: 12-600 | E25: סימול בנק | F25: פח"ק/פר"י | G25: ישראל | H25: לא | I25: AAA | J25: S&P מעלות | K25: ILS | L25: 119657.33 | M25: 1 | O25: 119657.33 | P25: 0.94008607 | Q25: 0.11645938
A26: 337 | B26: 9963 | C26: פועלים | D26: 12-600 | E26: סימול בנק | F26: מזומן ועו"ש נקוב במט"ח | G26: ישראל | H26: לא | I26: AAA | J26: S&P מעלות | K26: CHF | L26: 6.708 | M26: 4.074 | O26: 27.33 | P26: 0.00021471407 | Q26: 2.6599126e-05
A27: 337 | B27: 9963 | C27: בנק לאומי לישראל בע"מ | D27: 10-800 | E27: סימול בנק | F27: מזומן ועו"ש בש"ח | G27: ישראל | H27: לא | I27: AAA | J27: S&P מעלות | K27: ILS | L27: 2233.06 | M27: 1 | N27: 0.0405 | O27: 2233.06 | P27: 0.017544005 | Q27: 0.0021733796
A28: 337 | B28: 9963 | C28: פועלים | D28: 12-600 | E28: סימול בנק | F28: מזומן ועו"ש נקוב במט"ח | G28: חו"ל | H28: לא | I28: AAA | J28: S&P מעלות | K28: USD | L28: 219.166 | M28: 3.681 | O28: 806.751 | P28: 0.0063382262 | Q28: 0.0007851897
A29: 337 | B29: 9963 | C29: פועלים | D29: 12-600 | E29: סימול בנק | F29: מזומן ועו"ש נקוב במט"ח | G29: חו"ל | H29: לא | I29: AAA | J29: S&P מעלות | K29: HKD | L29: 87.459 | M29: 0.47 | O29: 41.141 | P29: 0.00032322281 | Q29: 4.0041364e-05
A30: 337 | B30: 9963 | C30: פועלים | D30: 12-600 | E30: סימול בנק | F30: מזומן ועו"ש נקוב במט"ח | G30: חו"ל | H30: לא | I30: AAA | J30: S&P מעלות | K30: CAD | L30: 1.121 | M30: 2.712 | O30: 3.04 | P30: 2.3880065e-05 | Q30: 2.9583011e-06
A31: 337 | B31: 9963 | C31: פועלים | D31: 12-600 | E31: סימול בנק | F31: מזומן ועו"ש נקוב במט"ח | G31: חו"ל | H31: לא | I31: AAA | J31: S&P מעלות | K31: EUR | L31: 77.805 | M31: 3.979 | O31: 309.593 | P31: 0.0024323153 | Q31: 0.00030131915
A32: 337 | B32: 9963 | C32: פועלים | D32: 12-600 | E32: סימול בנק | F32: מזומן ועו"ש נקוב במט"ח | G32: חו"ל | H32: לא | I32: AAA | J32: S&P מעלות | K32: JPY | L32: 57.023 | M32: 2.433 | O32: 1.388 | P32: 1.0901604e-05 | Q32: 1.3505084e-06
A33: 337 | B33: 9963 | C33: פועלים | D33: 12-600 | E33: סימול בנק | F33: מזומן ועו"ש נקוב במט"ח | G33: חו"ל | H33: לא | I33: AAA | J33: S&P מעלות | K33: GBP | L33: 20.777 | M33: 4.654 | O33: 96.686 | P33: 0.00075961398 | Q33: 9.4102207e-05
A34: 337 | B34: 9963 | C34: פועלים | D34: 12-600 | E34: סימול בנק | F34: מזומן ועו"ש בש"ח | G34: ישראל | H34: לא | I34: AAA | J34: S&P מעלות | K34: ILS | L34: 703.631 | M34: 1 | O34: 703.631 | P34: 0.0055280659 | Q34: 0.00068482574
A35: 337 | B35: 9963 | C35: בנק לאומי לישראל בע"מ | D35: 10-800 | E35: סימול בנק | F35: מזומן ועו"ש בש"ח | G35: ישראל | H35: לא | I35: AAA | J35: S&P מעלות | K35: ILS | L35: 3115.47 | M35: 1 | N35: 0.0405 | O35: 3115.47 | P35: 0.024476646 | Q35: 0.0030322065
A36: 337 | B36: 9963 | C36: בנק לאומי לישראל בע"מ | D36: 10-800 | E36: סימול בנק | F36: מזומן ועו"ש בש"ח | G36: ישראל | H36: לא | I36: AAA | J36: S&P מעלות | K36: ILS | L36: 279.842 | M36: 1 | N36: 0.0405 | O36: 279.842 | P36: 0.002198573 | Q36: 0.00027236277
A37: 337 | B37: 9963 | C37: בנק לאומי לישראל בע"מ | D37: 10-800 | E37: סימול בנק | F37: מזומן ועו"ש בש"ח | G37: ישראל | H37: לא | I37: AAA | J37: S&P מעלות | K37: ILS | L37: 8.117 | M37: 1 | N37: 0.0405 | O37: 8.117 | P37: 6.3770855e-05 | Q37: 7.9000365e-06
A38: 337 | B38: 9964 | C38: פועלים | D38: 12-600 | E38: סימול בנק | F38: פח"ק/פר"י | G38: ישראל | H38: לא | I38: AAA | J38: S&P מעלות | K38: ILS | L38: 3773.486 | M38: 1 | O38: 3773.486 | P38: 0.74156471 | Q38: 0.10877848
A39: 337 | B39: 9964 | C39: פועלים | D39: 12-600 | E39: סימול בנק | F39: מזומן ועו"ש נקוב במט"ח | G39: ישראל | H39: לא | I39: AAA | J39: S&P מעלות | K39: CHF | L39: 2.355 | M39: 4.074 | O39: 9.595 | P39: 0.0018855118 | Q39: 0.00027658153
A40: 337 | B40: 9964 | C40: בנק לאומי לישראל בע"מ | D40: 10-800 | E40: סימול בנק | F40: מזומן ועו"ש בש"ח | G40: ישראל | H40: לא | I40: AAA | J40: S&P מעלות | K40: ILS | L40: 380.639 | M40: 1 | N40: 0.0405 | O40: 380.639 | P40: 0.074803002 | Q40: 0.010972686
...

Sheet איגרות חוב ממשלתיות
A1: מספר קופה/קרן/ח.פ. עבור חברת ביטוח | B1: מספר מסלול | C1: שם מנפיק | D1: שם נייר ערך | E1: מספר נייר ערך | F1: מאפיין עיקרי | G1: ישראל/חו"ל | H1: מדינה לפי חשיפה כלכלית | I1: זירת מסחר | J1: דירוג | K1: שם מדרג | L1: מטבע פעילות | M1: מח"מ | N1: מועד פדיון | O1: שיעור ריבית | P1: תשואה לפדיון | Q1: סכום לקבל (במטבע הפעילות) | R1: ערך נקוב (יחידות) | S1: שער חליפין | T1: שער נייר הערך | U1: שווי הוגן (באלפי ש"ח) | V1: עלות מופחתת (באלפי ש"ח) | W1: השיטה שיושמה בדוח הכספי | X1: שיעור מערך נקוב מונפק | Y1: שיעור מנכסי אפיק ההשקעה | Z1: שיעור מסך נכסי ההשקעה
A2: 337 | B2: 1405 | C2: בנק ישראל- מק"מ | D2: מ.ק.מ. 315 | E2: IL0082503181 | F2: מק"מ קצר משנים עשר חודשים | G2: ישראל | H2: ישראל | I2: TASE | J2: RF | K2: פנימי | L2: ILS | M2: 0.94 | N2: 05/03/2025 | O2: 0 | P2: 0.04096 | R2: 238762 | S2: 1 | T2: 96.38 | U2: 230.119 | W2: שווי הוגן | X2: 0 | Y2: 0.044967376 | Z2: 0.021764182
A3: 337 | B3: 1405 | C3: בנק ישראל- מק"מ | D3: מלווה קצר מועד 1214 | E3: IL0082412185 | F3: מק"מ קצר משנים עשר חודשים | G3: ישראל | H3: ישראל | I3: TASE | J3: RF | K3: פנימי | L3: ILS | M3: 0.677 | N3: 04/12/2024 | O3: 0 | P3: 0.04238 | R3: 1064000 | S3: 1 | T3: 97.22 | U3: 1034.421 | W3: שווי הוגן | X3: 7.6e-05 | Y3: 0.20213553 | Z3: 0.097833473
A4: 337 | B4: 1405 | C4: גליל | D4: ממשלתי צמוד 841 | E4: IL0011205833 | F4: צמוד למדד המחירים לצרכן בריבית קבועה | G4: ישראל | H4: ישראל | I4: TASE | J4: RF | K4: פנימי | L4: ILS | M4: 14.135 | N4: 30/08/2041 | O4: 0.0275 | P4: 0.01782 | R4: 230000 | S4: 1 | T4: 138.12 | U4: 317.676 | W4: שווי הוגן | X4: 1.3e-05 | Y4: 0.062076872 | Z4: 0.030045168
A5: 337 | B5: 1405 | C5: שחר | D5: ממשלתי שקלית 0142 | E5: IL0011254005 | F5: לא צמוד למדד המחירים לצרכן ריבית קבועה | G5: ישראל | H5: ישראל | I5: TASE | J5: RF | K5: פנימי | L5: ILS | M5: 11.998 | N5: 31/01/2042 | O5: 0.055 | P5: 0.04715 | R5: 531206 | S5: 1 | T5: 110.25 | U5: 585.655 | W5: שווי הוגן | X5: 2.8e-05 | Y5: 0.11444241 | Z5: 0.055390055
A6: 337 | B6: 1405 | C6: גילון חדש | D6: ממשלתית משתנה 05/26 0.0866% | E6: IL0011417958 | F6: לא צמוד למדד המחירים לצרכן ריבית משתנה | G6: ישראל | H6: ישראל | I6: TASE | J6: RF | K6: פנימי | L6: ILS | M6: 2.072 | N6: 31/05/2026 | O6: 0.0394 | P6: 0.04743 | R6: 31000 | S6: 1 | T6: 99.22 | U6: 30.758 | W6: שווי הוגן | X6: 1e-06 | Y6: 0.0060104409 | Z6: 0.0029090497
A7: 337 | B7: 1405 | C7: גליל | D7: ממשלתית צמודה 0726 | E7: IL0011695645 | F7: צמוד למדד המחירים לצרכן בריבית קבועה | G7: ישראל | H7: ישראל | I7: TASE | J7: RF | K7: פנימי | L7: ILS | M7: 2.328 | N7: 31/07/2026 | O7: 0.001 | P7: 0.01041 | R7: 1593000 | S7: 1 | T7: 109.23 | U7: 1740.034 | W7: שווי הוגן | X7: 7.9e-05 | Y7: 0.34001895 | Z7: 0.16456896
A8: 337 | B8: 1405 | C8: שחר | D8: ממשלתית שקלית 1.00% 03/30 | E8: IL0011609851 | F8: לא צמוד למדד המחירים לצרכן ריבית קבועה | G8: ישראל | H8: ישראל | I8: TASE | J8: RF | K8: פנימי | L8: ILS | M8: 5.836 | N8: 31/03/2030 | O8: 0.01 | P8: 0.04173 | R8: 450000 | S8: 1 | T8: 83.47 | U8: 375.615 | W8: שווי הוגן | X8: 1.2e-05 | Y8: 0.073398696 | Z8: 0.035524924
A9: 337 | B9: 1405 | C9: בנק ישראל- מק"מ | D9: מקמ 524 | E9: IL0082405254 | F9: מק"מ קצר משנים עשר חודשים | G9: ישראל | H9: ישראל | I9: TASE | J9: RF | K9: פנימי | L9: ILS | M9: 0.101 | N9: 08/05/2024 | O9: 0 | P9: 0.04343 | R9: 400000 | S9: 1 | T9: 99.58 | U9: 398.32 | W9: שווי הוגן | X9: 2.2e-05 | Y9: 0.077835466 | Z9: 0.037672318
A10: 337 | B10: 1405 | C10: בנק ישראל- מק"מ | D10: מקמ 614 | E10: IL0082406161 | F10: מק"מ קצר משנים עשר חודשים | G10: ישראל | H10: ישראל | I10: TASE | J10: RF | K10: פנימי | L10: ILS | M10: 0.178 | N10: 05/06/2024 | O10: 0 | P10: 0.04318 | R10: 245800 | S10: 1 | T10: 99.26 | U10: 243.981 | W10: שווי הוגן | X10: 1.4e-05 | Y10: 0.047676193 | Z10: 0.023075248
A11: 337 | B11: 1405 | C11: US TREASURY N/B | D11: T-3 3/8 15/05/33 | E11: US91282CHC82 | F11: צמוד מט"ח בריבית קבועה | G11: חו"ל | H11: ארה"ב | I11: NYSE | J11: Aaa | K11: Moodys | L11: USD | M11: 7.57 | N11: 15/05/2033 | O11: 0.03375 | P11: 0.04409 | R11: 46000 | S11: 3.681 | T11: 95.014 | U11: 160.883 | W11: שווי הוגן | X11: 0 | Y11: 0.031438061 | Z11: 0.015216002
A12: 337 | B12: 1477 | C12: בנק ישראל- מק"מ | D12: מ.ק.מ. 315 | E12: IL0082503181 | F12: מק"מ קצר משנים עשר חודשים | G12: ישראל | H12: ישראל | I12: TASE | J12: RF | K12: פנימי | L12: ILS | M12: 0.94 | N12: 05/03/2025 | O12: 0 | P12: 0.04096 | R12: 376476 | S12: 1 | T12: 96.38 | U12: 362.848 | W12: שווי הוגן | X12: 0 | Y12: 0.098787297 | Z12: 0.036379499
A13: 337 | B13: 1477 | C13: בנק ישראל- מק"מ | D13: מלווה קצר מועד 1214 | E13: IL0082412185 | F13: מק"מ קצר משנים עשר חודשים | G13: ישראל | H13: ישראל | I13: TASE | J13: RF | K13: פנימי | L13: ILS | M13: 0.677 | N13: 04/12/2024 | O13: 0 | P13: 0.04238 | R13: 2606000 | S13: 1 | T13: 97.22 | U13: 2533.553 | W13: שווי הוגן | X13: 0.000186 | Y13: 0.68977415 | Z13: 0.25401685
... A59: 337 | B59: 9964 | C59: US TREASURY N/B | D59: T-3 3/8 15/05/33 | E59: US91282CHC82 | F59: צמוד מט"ח בריבית קבועה | G59: חו"ל | H59: ארה"ב | I59: NYSE | J59: Aaa | K59: Moodys | L59: USD | M59: 7.57 | N59: 15/05/2033 | O59: 0.03375 | P59: 0.04409 | R59: 235000 | S59: 3.681 | T59: 95.014 | U59: 821.903 | W59: שווי הוגן | X59: 2e-06 | Y59: 0.059035758 | Z59: 0.023693027

Sheet ניירות ערך מסחריים
A1: מספר קופה/קרן/ח.פ. עבור חברת ביטוח | B1: מספר מסלול | C1: שם מנפיק | D1: מספר מנפיק | E1: סוג מספר מזהה מנפיק | F1: שם נייר ערך | G1: מספר נייר ערך | H1: סוג מספר נייר ערך | I1: מאפיין עיקרי | J1: ישראל/חו"ל | K1: מדינה לפי חשיפה כלכלית | L1: זירת מסחר | M1: ענף מסחר | N1: בעל עניין/צד קשור | O1: דירוג | P1: שם מדרג | Q1: דירוג נייר הערך/המנפיק | R1: מטבע פעילות | S1: מח"מ | T1: ריבית עוגן | U1: מועד פדיון | V1: שיעור ריבית | W1: תשואה לפדיון | X1: נחיתות חוזית | Y1: האם סווג כחוב בעייתי | Z1: ערך נקוב (יחידות) | AA1: שער חליפין | AB1: שער נייר הערך | AC1: סכום לקבל (במטבע הפעילות) | AD1: שווי הוגן (באלפי ש"ח) | AE1: עלות מופחתת (באלפי ש"ח) | AF1: עלות מופחתת (במטבע הפעילות) | AG1: השיטה שיושמה בדוח הכספי | AH1: שיעור מערך נקוב מונפק | AI1: שיעור מנכסי אפיק ההשקעה | AJ1: שיעור מסך נכסי ההשקעה
A2: 337 | B2: 1405 | C2: מגה אור החזקות בע"מ | D2: 513257873 | E2: ח.פ | F2: מגה אור נעמ 3 18062024 | G2: IL0011969552 | H2: ISIN | I2: לא צמוד למדד המחירים לצרכן ריבית קבועה | J2: ישראל | K2: ישראל | L2: TASE | M2: נדל"ן מניב בישראל | N2: לא | O2: A+ | P2: S&P מעלות | Q2: נייר ערך | R2: ILS | S2: 0.214 | T2: ריבית בנק ישראל | U2: 18/06/2024 | V2: 0.102 | W2: 0.06684 | X2: החוב לא נחות | Y2: לא | Z2: 2300 | AA2: 1 | AB2: 1044.33 | AD2: 24.02 | AG2: שווי הוגן | AH2: 0.000153 | AI2: 1 | AJ2: 0.0022717253
A3: 337 | B3: 9962 | C3: מגה אור החזקות בע"מ | D3: 513257873 | E3: ח.פ | F3: מגה אור נעמ 3 18062024 | G3: IL0011969552 | H3: ISIN | I3: לא צמוד למדד המחירים לצרכן ריבית קבועה | J3: ישראל | K3: ישראל | L3: TASE | M3: נדל"ן מניב בישראל | N3: לא | O3: A+ | P3: S&P מעלות | Q3: נייר ערך | R3: ILS | S3: 0.214 | T3: ריבית בנק ישראל | U3: 18/06/2024 | V3: 0.102 | W3: 0.06684 | X3: החוב לא נחות | Y3: לא | Z3: 4700 | AA3: 1 | AB3: 1044.33 | AD3: 49.084 | AG3: שווי הוגן | AH3: 0.000313 | AI3: 1 | AJ3: 0.0015901433
A4: 337 | B4: 9963 | C4: מגה אור החזקות בע"מ | D4: 513257873 | E4: ח.פ | F4: מגה אור נעמ 3 18062024 | G4: IL0011969552 | H4: ISIN | I4: לא צמוד למדד המחירים לצרכן ריבית קבועה | J4: ישראל | K4: ישראל | L4: TASE | M4: נדל"ן מניב בישראל | N4: לא | O4: A+ | P4: S&P מעלות | Q4: נייר ערך | R4: ILS | S4: 0.214 | T4: ריבית בנק ישראל | U4: 18/06/2024 | V4: 0.102 | W4: 0.06684 | X4: החוב לא נחות | Y4: לא | Z4: 194100 | AA4: 1 | AB4: 1044.33 | AD4: 2027.045 | AG4: שווי הוגן | AH4: 0.01294 | AI4: 1 | AJ4: 0.0019728699
A5: 337 | B5: 9964 | C5: מגה אור החזקות בע"מ | D5: 513257873 | E5: ח.פ | F5: מגה אור נעמ 3 18062024 | G5: IL0011969552 | H5: ISIN | I5: לא צמוד למדד המחירים לצרכן ריבית קבועה | J5: ישראל | K5: ישראל | L5: TASE | M5: נדל"ן מניב בישראל | N5: לא | O5: A+ | P5: S&P מעלות | Q5: נייר ערך | R5: ILS | S5: 0.214 | T5: ריבית בנק ישראל | U5: 18/06/2024 | V5: 0.102 | W5: 0.06684 | X5: החוב לא נחות | Y5: לא | Z5: 6000 | AA5: 1 | AB5: 1044.33 | AD5: 62.66 | AG5: שווי הוגן | AH5: 0.0004 | AI5: 1 | AJ5: 0.0018062971

Sheet איגרות חוב
A1: מספר קופה/קרן/ח.פ. עבור חברת ביטוח | B1: מספר מסלול | C1: שם מנפיק | D1: מספר מנפיק | E1: סוג מספר מזהה מנפיק | F1: שם נייר ערך | G1: מספר נייר ערך | H1: סוג מספר נייר ערך | I1: מאפיין עיקרי | J1: ישראל/חו"ל | K1: מדינה לפי חשיפה כלכלית | L1: סטאטוס סחירות | M1: זירת מסחר | N1: ענף מסחר | O1: בעל עניין/צד קשור | P1: דירוג | Q1: שם מדרג | R1: דירוג נייר הערך/המנפיק | S1: מטבע פעילות | T1: מח"מ | U1: מועד פדיון | V1: שיעור ריבית | W1: תשואה לפדיון | X1: נחיתות חוזית | Y1: האם סווג כחוב בעייתי | Z1: ערך נקוב (יחידות) | AA1: שער חליפין | AB1: שער נייר הערך | AC1: סכום לקבל (במטבע הפעילות) | AD1: שווי הוגן (באלפי ש"ח) | AE1: עלות מופחתת (באלפי ש"ח) | AF1: עלות מופחתת (במטבע הפעילות) | AG1: השיטה שיושמה בדוח הכספי | AH1: שיעור מערך נקוב מונפק | AI1: שיעור מנכסי אפיק ההשקעה | AJ1: שיעור מסך נכסי ההשקעה
A2: 337 | B2: 1405 | C2: לוויתן בונד בע"מ | D2: 516223864 | E2: ח.פ | F2: LVIA 6.125% 6/25 | G2: IL0011677742 | H2: ISIN | I2: צמוד למט"ח | J2: ישראל | K2: ישראל | L2: סחיר | M2: אחר | N2: Energy Equipment & Services | O2: לא | P2: Ba3 | Q2: Moodys | R2: נייר ערך | S2: USD | T2: 1.14 | U2: 30/06/2025 | V2: 0.06125 | W2: 0.07568 | X2: החוב לא נחות | Y2: לא | Z2: 6000 | AA2: 3.681 | AB2: 98.581 | AD2: 22.111 | AG2: שווי הוגן | AH2: 1e-05 | AI2: 0.0053760933 | AJ2: 0.0020911949
A3: 337 | B3: 1405 | C3: אאורה השקעות בע"מ | D3: 520038274 | E3: ח.פ | F3: אאורה אגח טז | G3: IL0037305799 | H3: ISIN | I3: לא צמוד למדד המחירים לצרכן | J3: ישראל | K3: ישראל | L3: סחיר | M3: TASE | N3: בנייה | O3: לא | P3: A3 | Q3: מידרוג Moodys | R3: נייר ערך | S3: ILS | T3: 1.912 | U3: 30/09/2027 | V3: 0.035 | W3: 0.05656 | X3: החוב לא נחות | Y3: לא | Z3: 40456 | AA3: 1 | AB3: 96.19 | AD3: 38.915 | AG3: שווי הוגן | AH3: 0.000162 | AI3: 0.009461835 | AJ3: 0.0036804684
A4: 337 | B4: 1405 | C4: אאורה השקעות בע"מ | D4: 520038274 | E4: ח.פ | F4: אאורה אגח יז %3.85 31/01/2029 | G4: IL0011935801 | H4: ISIN | I4: צמוד למדד המחירים לצרכן | J4: ישראל | K4: ישראל | L4: סחיר | M4: TASE | N4: בנייה | O4: לא | P4: A- | Q4: S&P מעלות | R4: נייר ערך | S4: ILS | T4: 3.269 | U4: 31/01/2029 | V4: 0.0385 | W4: 0.03176 | X4: החוב לא נחות | Y4: לא | Z4: 9000 | AA4: 1 | AB4: 106.03 | AD4: 9.543 | AG4: שווי הוגן | AH4: 5.1e-05 | AI4: 0.0023202446 | AJ4: 0.00090252969
A5: 337 | B5: 1405 | C5: אאורה השקעות בע"מ | D5: 520038274 | E5: ח.פ | F5: אאורה אגח יז חסום עד 14.05.24 | G5: IL0011935801 | H5: ISIN | I5: צמוד למדד המחירים לצרכן | J5: ישראל | K5: ישראל | L5: חסום | M5: TASE | N5: בנייה | O5: לא | P5: A- | Q5: S&P מעלות | R5: נייר ערך | S5: ILS | T5: 3.45 | U5: 31/01/2029 | V5: 0.0385 | W5: 0.0297 | X5: החוב לא נחות | Y5: לא | Z5: 10000 | AA5: 1 | AB5: 105.578 | AD5: 10.558 | AG5: שווי הוגן | AH5: 5.6e-05 | AI5: 0.0025670571 | AJ5: 0.0009985349
A6: 337 | B6: 1405 | C6: אדגר השקעות ופיתוח בע"מ | D6: 520035171 | E6: ח.פ | F6: אדגר אגח י | G6: IL0018202080 | H6: ISIN | I6: צמוד למדד המחירים לצרכן | J6: ישראל | K6: ישראל | L6: סחיר | M6: TASE | N6: נדל"ן מניב בחו"ל | O6: לא | P6: A2 | Q6: מידרוג Moodys | R6: נייר ערך | S6: ILS | T6: 1.863 | U6: 01/09/2027 | V6: 0.0285 | W6: 0.02861 | X6: החוב לא נחות | Y6: לא | Z6: 24000 | AA6: 1 | AB6: 113.36 | AD6: 27.206 | AG6: שווי הוגן | AH6: 3.5e-05 | AI6: 0.0066150569 | AJ6: 0.0025731275
A7: 337 | B7: 1405 | C7: אדגר השקעות ופיתוח בע"מ | D7: 520035171 | E7: ח.פ | F7: אדגר אגח סד יא | G7: IL0018202817 | H7: ISIN | I7: צמוד למדד המחירים לצרכן | J7: ישראל | K7: ישראל | L7: סחיר | M7: TASE | N7: נדל"ן מניב בחו"ל | O7: לא | P7: A2 | Q7: מידרוג Moodys | R7: נייר ערך | S7: ILS | T7: 3.66 | U7: 31/03/2030 | V7: 0.0245 | W7: 0.03526 | X7: החוב לא נחות | Y7: לא | Z7: 4782.61 | AA7: 1 | AB7: 107.38 | AD7: 5.136 | AG7: שווי הוגן | AH7: 9e-06 | AI7: 0.0012486792 | AJ7: 0.00048571173
A8: 337 | B8: 1405 | C8: אדמה פתרונות לחקלאות בע"מ | D8: 520043605 | E8: ח.פ | F8: אדמה אגח ב | G8: IL0011109159 | H8: ISIN | I8: צמוד למדד המחירים לצרכן | J8: ישראל | K8: ישראל | L8: סחיר | M8: TASE | N8: כימיה, גומי ופלסטיק | O8: לא | P8: AA- | Q8: S&P מעלות | R8: נייר ערך | S8: ILS | T8: 5.674 | U8: 30/11/2036 | V8: 0.0515 | W8: 0.02931 | X8: החוב לא נחות | Y8: לא | Z8: 20312.5 | AA8: 1 | AB8: 154.27 | AD8: 31.336 | AG8: שווי הוגן | AH8: 6e-06 | AI8: 0.0076191647 | AJ8: 0.0029637058
A9: 337 | B9: 1405 | C9: או.פי.סי. אנרגיה בע"מ | D9: 514401702 | E9: ח.פ | F9: או פי סי אגח ב' | G9: IL0011660573 | H9: ISIN | I9: צמוד למדד המחירים לצרכן | J9: ישראל | K9: ישראל | L9: סחיר | M9: TASE | N9: אנרגיה | O9: לא | P9: A- | Q9: S&P מעלות | R9: מנפיק | S9: ILS | T9: 3.318 | U9: 01/10/2028 | V9: 0.0275 | W9: 0.02769 | X9: החוב לא נחות | Y9: לא | Z9: 36188.86 | AA9: 1 | AB9: 110.77 | AD9: 40.086 | AG9: שווי הוגן | AH9: 4e-05 | AI9: 0.0097467441 | AJ9: 0.0037912924
A10: 337 | B10: 1405 | C10: איירפורט סיטי בע"מ | D10: 511659401 | E10: ח.פ | F10: איירפורט אגח ה | G10: IL0011334872 | H10: ISIN | I10: צמוד למדד המחירים לצרכן | J10: ישראל | K10: ישראל | L10: סחיר | M10: TASE | N10: נדל"ן מניב בישראל | O10: לא | P10: AA | Q10: S&P מעלות | R10: נייר ערך | S10: ILS | T10: 2.698 | U10: 28/02/2029 | V10: 0.0234 | W10: 0.02157 | X10: החוב לא נחות | Y10: לא | Z10: 58021.99 | AA10: 1 | AB10: 111.84 | AD10: 64.892 | AG10: שווי הוגן | AH10: 2.2e-05 | AI10: 0.015778012 | AJ10: 0.0061373375
A11: 337 | B11: 1405 | C11: איסתא בע"מ | D11: 520042763 | E11: ח.פ | F11: איסתא אגח א להמרה | G11: IL0011971285 | H11: ISIN | I11: אג"ח להמרה לא צמוד למדד המחירים לצרכן | J11: ישראל | K11: ישראל | L11: סחיר | M11: TASE | N11: מלונאות ותיירות | O11: לא | P11: N/R | Q11: N/R | R11: N/R | S11: ILS | T11: 3.847 | U11: 30/06/2028 | V11: 0.0485 | W11: 0.04807 | X11: החוב לא נחות | Y11: לא | Z11: 13000 | AA11: 1 | AB11: 101.6 | AD11: 13.208 | AG11: שווי הוגן | AH11: 5.3e-05 | AI11: 0.0032114382 | AJ11: 0.0012491865
A12: 337 | B12: 1405 | C12: אלבר שירותי מימונית בע"מ | D12: 512025891 | E12: ח.פ | F12: אלבר אגח יט | G12: IL0011918245 | H12: ISIN | I12: צמוד למדד המחירים לצרכן | J12: ישראל | K12: ישראל | L12: סחיר | M12: TASE | N12: שירותים | O12: לא | P12: A+ | Q12: S&P מעלות | R12: נייר ערך | S12: ILS | T12: 2.036 | U12: 15/05/2028 | V12: 0.032 | W12: 0.02974 | X12: החוב לא נחות | Y12: לא | Z12: 8500 | AA12: 1 | AB12: 104.3 | AD12: 8.866 | AG12: שווי הוגן | AH12: 2.3e-05 | AI12: 0.0021555879 | AJ12: 0.00083848145
A13: 337 | B13: 1405 | C13: אלבר שירותי מימונית בע"מ | D13: 512025891 | E13: ח.פ | F13: אלבר אגח כ | G13: IL0011918328 | H13: ISIN | I13: לא צמוד למדד המחירים לצרכן | J13: ישראל | K13: ישראל | L13: סחיר | M13: TASE | N13: שירותים | O13: לא | P13: A+ | Q13: S&P מעלות | R13: נייר ערך | S13: ILS | T13: 2.059 | U13: 20/06/2028 | V13: 0.057 | W13: 0.05913 | X13: החוב לא נחות | Y13: לא | Z13: 10200 | AA13: 1 | AB13: 100.07 | AD13: 10.207 | AG13: שווי הוגן | AH13: 2.6e-05 | AI13: 0.0024817988 | AJ13: 0.00096537111
... A98: 337 | B98: 1405 | C98: קבוצת מנרב בע"מ | D98: 520034505 | E98: ח.פ | F98: מנרב אגח ד | G98: IL0015501690 | H98: ISIN | I98: צמוד למדד המחירים לצרכן | J98: ישראל | K98: ישראל | L98: סחיר | M98: TASE | N98: בנייה | O98: לא | P98: Baa1 | Q98: מידרוג Moodys | R98: נייר ערך | S98: ILS | T98: 3.667 | U98: 15/04/2032 | V98: 0.0207 | W98: 0.04213 | X98: החוב לא נחות | Y98: לא | Z98: 12000 | AA98: 1 | AB98: 101.49 | AD98: 12.179 | AG98: שווי הוגן | AH98: 2.6e-05 | AI98: 0.002961195 | AJ98: 0.0011518468
A99: 337 | B99: 1405 | C99: קבוצת מנרב בע"מ | D99: 520034505 | E99: ח.פ | F99: מנרב אגח ד חסום עד 07.09.24 | G99: IL0015501690 | H99: ISIN | I99: צמוד למדד המחירים לצרכן | J99: ישראל | K99: ישראל | L99: חסום | M99: TASE | N99: בנייה | O99: לא | P99: Baa1 | Q99: מידרוג Moodys | R99: נייר ערך | S99: ILS | T99: 3,67 | U99: 15/04/2032 | V99: 0.0182 | W99: 0.0421 | X99: החוב לא נחות | Y99: לא | Z99: 20000 | AA99: 1 | AB99: 100.203 | AD99: 20.041 | AG99: שווי הוגן | AH99: 0 | AI99: 0.0048727398 | AJ99: 0.0018954003
A100: 337 | B100: 1405 | C100: נאוויטס פטרוליום, שותפות מוגבלת | D100: 550263107 | E100: ח.פ | F100: נאוויטס פטרו אגח ה חסום עד 11.07.24 | G100: IL0011979122 | H100: ISIN | I100: לא צמוד למדד המחירים לצרכן | J100: ישראל | K100: ארה"ב | L100: חסום | M100: TASE | N100: חיפושי נפט וגז | O100: לא | P100: A- | Q100: S&P מעלות | R100: נייר ערך | S100: ILS | T100: 3.52 | U100: 31/12/2028 | V100: 0.065 | W100: 0.0615 | X100: החוב לא נחות | Y100: לא | Z100: 21000 | AA100: 1 | AB100: 101.78 | AD100: 21.374 | AG100: שווי הוגן | AH100: 0 | AI100: 0.0051969037 | AJ100: 0.0020214937
A101: 337 | B101: 1405 | C101: נאוויטס פטרוליום, שותפות מוגבלת | D101: 550263107 | E101: ח.פ | F101: נאוויטס פטרו אגח ו | G101: IL0012048257 | H101: ISIN | I101: לא צמוד למדד המחירים לצרכן | J101: ישראל | K101: ישראל | L101: סחיר | M101: TASE | N101: חיפושי נפט וגז | O101: לא | P101: A- | Q101: S&P מעלות | R101: נייר ערך | S101: ILS | T101: 4.14 | U101: 30/09/2029 | V101: 0.067 | W101: 0.06089 | X101: החוב לא נחות | Y101: לא | Z101: 17000 | AA101: 1 | AB101: 103.21 | AD101: 17.546 | AG101: שווי הוגן | AH101: 0 | AI101: 0.0042661213 | AJ101: 0.0016594376
A102: 337 | B102: 1405 | C102: ע.י נופר אנרגי' בע"מ | D102: 514599943 | E102: ח.פ | F102: נופר אנרג אגח א | G102: IL0011793408 | H102: ISIN | I102: צמוד למדד המחירים לצרכן | J102: ישראל | K102: ישראל | L102: סחיר | M102: TASE | N102: אנרגיה מתחדשת | O102: לא | P102: N/R | Q102: N/R | R102: N/R | S102: ILS | T102: 2.765 | U102: 31/12/2027 | V102: 0.0148 | W102: 0.03608 | X102: החוב לא נחות | Y102: לא | Z102: 27720 | AA102: 1 | AB102: 103.65 | AD102: 28.732 | AG102: שווי הוגן | AH102: 3.2e-05 | AI102: 0.006985943 | AJ102: 0.0027173949
A103: 337 | B103: 1405 | C103: חברה לנכסים ולבנין בע"מ | D103: 520025438 | E103: ח.פ | F103: נכסים ובניין אגח ט | G103: IL0069902125 | H103: ISIN | I103: לא צמוד למדד המחירים לצרכן | J103: ישראל | K103: ישראל | L103: סחיר | M103: TASE | N103: נדל"ן מניב בישראל | O103: לא | P103: A2 | Q103: מידרוג Moodys | R103: נייר ערך | S103: ILS | T103: 3.208 | U103: 01/07/2029 | V103: 0.0395 | W103: 0.07855 | X103: החוב לא נחות | Y103: לא | Z103: 26495.62 | AA103: 1 | AB103: 89.72 | AD103: 23.772 | AG103: שווי הוגן | AH103: 1.6e-05 | AI103: 0.0057799736 | AJ103: 0.0022482965
A104: 337 | B104: 1405 | C104: חברה לנכסים ולבנין בע"מ | D104: 520025438 | E104: ח.פ | F104: נכסים ובנין אגח י | G104: IL0011936304 | H104: ISIN | I104: צמוד למדד המחירים לצרכן | J104: ישראל | K104: ישראל | L104: סחיר | M104: TASE | N104: נדל"ן מניב בישראל | O104: לא | P104: A | Q104: S&P מעלות | R104: נייר ערך | S104: ILS | T104: 4.414 | U104: 01/07/2029 | V104: 0.0362 | W104: 0.03562 | X104: החוב לא נחות | Y104: לא | Z104: 11640 | AA104: 1 | AB104: 103.98 | AD104: 12.103 | AG104: שווי הוגן | AH104: 7e-06 | AI104: 0.0029428308 | AJ104: 0.0011447035
A105: 337 | B105: 1405 | C105: נמקו ריאליטי לטד | D105: 1905761 | E105: מספר תאגיד או שותפות בחו"ל | F105: נמקו אגח ג | G105: IL0011987612 | H105: ISIN | I105: לא צמוד למדד המחירים לצרכן | J105: ישראל | K105: ישראל | L105: סחיר | M105: TASE | N105: נדל"ן מניב בחו"ל | O105: לא | P105: AA | Q105: S&P מעלות | R105: נייר ערך | S105: ILS | T105: 2.865 | U105: 30/06/2027 | V105: 0.0635 | W105: 0.05893 | X105: החוב לא נחות | Y105: לא | Z105: 10000 | AA105: 1 | AB105: 103.15 | AD105: 10.315 | AG105: שווי הוגן | AH105: 2.4e-05 | AI105: 0.0025080243 | AJ105: 0.0009755723
A106: 337 | B106: 1405 | C106: סולאיר אנרגיות מתחדשות בע"מ | D106: 516046307 | E106: ח.פ | F106: סולאיר אגח א | G106: IL0011837304 | H106: ISIN | I106: צמוד למדד המחירים לצרכן | J106: ישראל | K106: ישראל | L106: סחיר | M106: TASE | N106: אנרגיה מתחדשת | O106: לא | P106: N/R | Q106: N/R | R106: N/R | S106: ILS | T106: 2.57 | U106: 31/12/2027 | V106: 0.023 | W106: 0.04785 | X106: החוב לא נחות | Y106: לא | Z106: 22386.6 | AA106: 1 | AB106: 102.88 | AD106: 23.031 | AG106: שווי הוגן | AH106: 9.3e-05 | AI106: 0.0055999171 | AJ106: 0.002178258
A107: 337 | B107: 1405 | C107: סולגרין בע"מ | D107: 512882747 | E107: ח.פ | F107: סולגרין אגח ב | G107: IL0011862468 | H107: ISIN | I107: צמוד למדד המחירים לצרכן | J107: ישראל | K107: ישראל | L107: סחיר | M107: TASE | N107: אנרגיה מתחדשת | O107: לא | P107: N/R | Q107: N/R | R107: N/R | S107: ILS | T107: 2.57 | U107: 31/12/2027 | V107: 0.0295 | W107: 0.03944 | X107: החוב לא נחות | Y107: לא | Z107: 11400 | AA107: 1 | AB107: 105.44 | AD107: 12.02 | AG107: שווי הוגן | AH107: 6.3e-05 | AI107: 0.0029226227 | AJ107: 0.001136843
A108: 337 | B108: 1405 | C108: סטרוברי פילדס ריט לימיטד | D108: 1863501 | E108: פנימי | F108: סטרוברי אגח ג | G108: IL0011790198 | H108: ISIN | I108: לא צמוד למדד המחירים לצרכן | J108: ישראל | K108: גלובלי | L108: סחיר | M108: TASE | N108: נדל"ן מניב בחו"ל | O108: לא | P108: A+ | Q108: S&P מעלות | R108: נייר ערך | S108: ILS | T108: 2.006 | U108: 31/07/2026 | V108: 0.057 | W108: 0.06157 | X108: החוב לא נחות | Y108: לא | Z108: 22316.43 | AA108: 1 | AB108: 100.25 | AD108: 22.372 | AG108: שווי הוגן | AH108: 9.5e-05 | AI108: 0.0054396581 | AJ108: 0.0021159204
A109: 337 | B109: 1405 | C109: סטרוברי פילדס ריט לימיטד | D109: 1863501 | E109: פנימי | F109: סטרוברי אגח ד | G109: IL0011970295 | H109: ISIN | I109: לא צמוד למדד המחירים לצרכן | J109: ישראל | K109: ארה"ב | L109: סחיר | M109: TASE | N109: נדל"ן מניב בחו"ל | O109: לא | P109: A | Q109: S&P מעלות | R109: נייר ערך | S109: ILS | T109: 2.15 | U109: 30/09/2026 | V109: 0.091 | W109: 0.06969 | X109: החוב לא נחות | Y109: לא | Z109: 18000 | AA109: 1 | AB109: 104.76 | AD109: 18.857 | AG109: שווי הוגן | AH109: 0.000118 | AI109: 0.0045849067 | AJ109: 0.0017834388
A110: 337 | B110: 1405 | C110: סיאון אינווסטמנט קורפוריישן | D110: 14242259 | E110: פנימי | F110: סיאון אגח א - חסום עד 05/04/24 | G110: IL0011940181 | H110: ISIN | I110: צמוד למט"ח | J110: ישראל | K110: ארה"ב | L110: חסום | M110: TASE | N110: אשראי חוץ בנקאי | O110: לא | P110: A1 | Q110: מידרוג Moodys | R110: נייר ערך | S110: ILS | T110: 2.4 | U110: 31/08/2026 | V110: 0.089127 | W110: 0.0655 | X110: החוב לא נחות | Y110: לא | Z110: 18000 | AA110: 1 | AB110: 104.923 | AD110: 18.886 | AG110: שווי הוגן | AH110: 0 | AI110: 0.0045920405 | AJ110: 0.0017862138
A111: 337 | B111: 1405 | C111: ספיר קורפ בע"מ | D111: 520038340 | E111: ח.פ | F111: ספיר קור אגח יט | G111: IL0011886483 | H111: ISIN | I111: לא צמוד למדד המחירים לצרכן | J111: ישראל | K111: ישראל | L111: סחיר | M111: TASE | N111: נדל"ן מניב בחו"ל | O111: לא | P111: N/R | Q111: N/R | R111: N/R | S111: ILS | T111: 2.087 | U111: 30/06/2026 | V111: 0.0675 | W111: 0.07486 | X111: החוב לא נחות | Y111: לא | Z111: 58000 | AA111: 1 | AB111: 100.49 | AD111: 58.284 | AG111: שווי הוגן | AH111: 0.000199 | AI111: 0.014171419 | AJ111: 0.0055124044
... A142: 337 | B142: 1405 | C142: G City Europe Ltd | D142: 213800OJ67K27RCO2J56 | E142: LEI | F142: ATRSAV 4 1/4 09/11/25 | G142: XS1829325239 | H142: ISIN | I142: צמוד למט"ח | J142: חו"ל | K142: אירופה | L142: סחיר | M142: אחר | N142: Real Estate Management & Development | O142: לא | P142: B2 | Q142: Moodys | R142: נייר ערך | S142: EUR | T142: 1.28 | U142: 11/09/2025 | V142: 0.0425 | W142: 0.07885 | X142: החוב לא נחות | Y142: לא | Z142: 3000 | AA142: 3.979 | AB142: 94.738 | AD142: 11.59 | AG142: שווי הוגן | AH142: 6e-06 | AI142: 0.0028179356 | AJ142: 0.0010961217
A143: 337 | B143: 1405 | C143: Energean plc | D143: 549300RVMKU0CYUZBB05 | E143: LEI | F143: ENOIGA 5 3/8 30/03/28 | G143: IL0011736738 | H143: ISIN | I143: צמוד למט"ח | J143: חו"ל | K143: גלובלי | L143: סחיר | M143: אחר | N143: חיפושי נפט וגז | O143: לא | P143: Ba3 | Q143: Moodys | R143: נייר ערך | S143: USD | T143: 3.63 | U143: 30/03/2028 | V143: 0.05375 | W143: 0.0892 | X143: החוב לא נחות | Y143: לא | Z143: 4000 | AA143: 3.681 | AB143: 91.602 | AC143: 0.107 | AD143: 13.883 | AG143: שווי הוגן | AH143: 6e-06 | AI143: 0.0033756052 | AJ143: 0.0013130443
A144: 337 | B144: 1405 | C144: Energean plc | D144: 549300RVMKU0CYUZBB05 | E144: LEI | F144: ENOIGA 5 7/8 30/03/31 | G144: IL0011736811 | H144: ISIN | I144: צמוד למט"ח | J144: חו"ל | K144: גלובלי | L144: סחיר | M144: אחר | N144: חיפושי נפט וגז | O144: לא | P144: Ba3 | Q144: Moodys | R144: נייר ערך | S144: USD | T144: 5.72 | U144: 30/03/2031 | V144: 0.05875 | W144: 0.0907 | X144: החוב לא נחות | Y144: לא | Z144: 4000 | AA144: 3.681 | AB144: 87.729 | AC144: 0.117 | AD144: 13.35 | AG144: שווי הוגן | AH144: 6e-06 | AI144: 0.0032459002 | AJ144: 0.0012625916
A145: 337 | B145: 1405 | C145: Hyundai Capital America | D145: 549300RIPPWJB5Z0FK07 | E145: LEI | F145: HYNMTR 5.6 03/30/28 | G145: US44891CCD39 | H145: ISIN | I145: צמוד למט"ח | J145: חו"ל | K145: ארה"ב | L145: סחיר | M145: אחר | N145: Textiles, Apparel & Luxury Goods | O145: לא | P145: BBB+ | Q145: Moodys | R145: נייר ערך | S145: USD | T145: 3.45 | U145: 30/03/2028 | V145: 0.056 | W145: 0.0543 | X145: החוב לא נחות | Y145: לא | Z145: 6000 | AA145: 3.681 | AB145: 101.197 | AD145: 22.35 | AG145: שווי הוגן | AH145: 8e-06 | AI145: 0.005434345 | AJ145: 0.0021138537
A146: 337 | B146: 1405 | C146: ITHACA ENERGY NORTH | D146: 21380057TNFLXPXBIP34 | E146: LEI | F146: IAECN 9% 07/26 | G146: USG49774AB18 | H146: ISIN | I146: צמוד למט"ח | J146: חו"ל | K146: בריטניה | L146: סחיר | M146: אחר | N146: Energy Equipment & Services | O146: לא | P146: B3 | Q146: Moodys | R146: נייר ערך | S146: USD | T146: 1.16 | U146: 15/07/2026 | V146: 0.09 | W146: 0.08178 | X146: החוב לא נחות | Y146: לא | Z146: 19000 | AA146: 3.681 | AB146: 100.85 | AD146: 71.845 | AG146: שווי הוגן | AH146: 3e-05 | AI146: 0.017468599 | AJ146: 0.0067949426
A147: 337 | B147: 1405 | C147: JPMORGAN CHASE | D147: 8I5DZWZKVSZI1NUHU748 | E147: LEI | F147: JPM 4.912 07/25/33 | G147: US46647PDH64 | H147: ISIN | I147: צמוד למט"ח | J147: חו"ל | K147: ארה"ב | L147: סחיר | M147: אחר | N147: Banks | O147: לא | P147: A- | Q147: Moodys | R147: נייר ערך | S147: USD | T147: 6.63 | U147: 25/07/2033 | V147: 0.04912 | W147: 0.05599 | X147: החוב לא נחות | Y147: לא | Z147: 3000 | AA147: 3.681 | AB147: 97.836 | AD147: 10.902 | AG147: שווי הוגן | AH147: 1e-06 | AI147: 0.0026507419 | AJ147: 0.0010310866
A148: 337 | B148: 1405 | C148: בנק לאומי לישראל בע"מ | D148: 520018078 | E148: ח.פ | F148: LUMIIT 3.275 01/29/31 | G148: IL0060404899 | H148: ISIN | I148: צמוד למט"ח | J148: ישראל | K148: ישראל | L148: סחיר | M148: אחר | N148: Banks | O148: לא | P148: BBB | Q148: S&P | R148: נייר ערך | S148: USD | T148: 1.69 | U148: 29/01/2031 | V148: 0.03275 | W148: 0.06581 | X148: החוב לא נחות | Y148: לא | Z148: 3000 | AA148: 3.681 | AB148: 92.834 | AD148: 10.313 | AG148: שווי הוגן | AH148: 4e-06 | AI148: 0.0025075193 | AJ148: 0.00097537586
A149: 337 | B149: 1405 | C149: לוויתן בונד בע"מ | D149: 516223864 | E149: ח.פ | F149: LVIATH 6.5 30/06/27 | G149: IL0011677825 | H149: ISIN | I149: צמוד למט"ח | J149: ישראל | K149: ישראל | L149: סחיר | M149: אחר | N149: Energy Equipment & Services | O149: לא | P149: BB- | Q149: אחר | R149: מנפיק | S149: USD | T149: 2.79 | U149: 30/06/2027 | V149: 0.065 | W149: 0.07799 | X149: החוב לא נחות | Y149: לא | Z149: 2000 | AA149: 3.681 | AB149: 96.843 | AD149: 7.249 | AG149: שווי הוגן | AH149: 3e-06 | AI149: 0.0017625987 | AJ149: 0.00068561634
A150: 337 | B150: 1405 | C150: AP MOLLER- MAERSK A/S | D150: 549300D2K6PKKKXVNN73 | E150: LEI | F150: MAERSK 5 7/8 14/09/33 | G150: USK0479SAG32 | H150: ISIN | I150: צמוד למט"ח | J150: חו"ל | K150: דנמרק | L150: סחיר | M150: אחר | N150: Transportation Infrastructure | O150: לא | P150: Baa1 | Q150: Moodys | R150: נייר ערך | S150: USD | T150: 7.02 | U150: 14/09/2033 | V150: 0.05875 | W150: 0.05588 | X150: החוב לא נחות | Y150: לא | Z150: 6000 | AA150: 3.681 | AB150: 102.749 | AD150: 22.751 | AG150: שווי הוגן | AH150: 8e-06 | AI150: 0.0055317103 | AJ150: 0.0021517269
A151: 337 | B151: 1405 | C151: Macquarie Group TLD | D151: ACMHD8HWFMFUIQQ8Y590 | E151: LEI | F151: MQGAU 5.887 06/15/34 | G151: US55608KBN46 | H151: ISIN | I151: צמוד למט"ח | J151: חו"ל | K151: ארה"ב | L151: סחיר | M151: אחר | N151: Diversified Financial Services Financial Services | O151: לא | P151: BBB+ | Q151: Moodys | R151: נייר ערך | S151: USD | T151: 6.92 | U151: 15/06/2034 | V151: 0.05887 | W151: 0.05811 | X151: החוב לא נחות | Y151: לא | Z151: 6000 | AA151: 3.681 | AB151: 102.133 | AD151: 22.936 | AG151: שווי הוגן | AH151: 8e-06 | AI151: 0.0055768151 | AJ151: 0.0021692718
A152: 337 | B152: 1405 | C152: בנק מזרחי טפחות בע"מ | D152: 520000522 | E152: ח.פ | F152: MZRHIT 3.077 04/07/31 | G152: IL0069508369 | H152: ISIN | I152: צמוד למט"ח | J152: ישראל | K152: ישראל | L152: סחיר | M152: אחר | N152: Banks | O152: לא | P152: BBB- | Q152: S&P מעלות | R152: מנפיק | S152: USD | T152: 1.87 | U152: 07/04/2031 | V152: 0.03077 | W152: 0.07118 | X152: החוב לא נחות | Y152: לא | Z152: 3000 | AA152: 3.681 | AB152: 91.664 | AD152: 10.286 | AG152: שווי הוגן | AH152: 5e-06 | AI152: 0.0025009111 | AJ152: 0.00097280542
A153: 337 | B153: 1405 | C153: OMEGA HEALTHCARE IN | D153: 549300OJ7ENK42CZ8E73 | E153: LEI | F153: OHI 3 3/8 01/02/31 | G153: US681936BM17 | H153: ISIN | I153: צמוד למט"ח | J153: חו"ל | K153: ארה"ב | L153: סחיר | M153: אחר | N153: Real Estate Management & Development | O153: לא | P153: BBB- | Q153: אחר | R153: מנפיק | S153: USD | T153: 5.85 | U153: 01/02/2031 | V153: 0.03375 | W153: 0.06157 | X153: החוב לא נחות | Y153: לא | Z153: 7000 | AA153: 3.681 | AB153: 85.454 | AD153: 22.161 | AG153: שווי הוגן | AH153: 1e-05 | AI153: 0.005388412 | AJ153: 0.0020959867
A154: 337 | B154: 1405 | C154: PROSPECT CAPITAL CORP | D154: 549300FSD8T39P5Q0O47 | E154: LEI | F154: PSEC 3.364% 11/26 | G154: US74348TAV44 | H154: ISIN | I154: צמוד למט"ח | J154: חו"ל | K154: ארה"ב | L154: סחיר | M154: אחר | N154: Diversified Financial Services Financial Services | O154: לא | P154: Baa3 | Q154: Moodys | R154: נייר ערך | S154: USD | T154: 2.39 | U154: 15/11/2026 | V154: 0.03364 | W154: 0.06959 | X154: החוב לא נחות | Y154: לא | Z154: 5000 | AA154: 3.681 | AB154: 91.462 | AD154: 17.066 | AG154: שווי הוגן | AH154: 1.7e-05 | AI154: 0.0041494271 | AJ154: 0.0016140458
...

Sheet מניות מבכ ויהש
A1: מספר קופה/קרן/ח.פ. עבור חברת ביטוח | B1: מספר מסלול | C1: שם מנפיק | D1: מספר מנפיק | E1: סוג מספר מזהה מנפיק | F1: שם נייר ערך | G1: מספר נייר ערך | H1: סוג מספר נייר ערך | I1: מאפיין עיקרי | J1: ישראל/חו"ל | K1: מדינה לפי חשיפה כלכלית | L1: סטאטוס סחירות | M1: זירת מסחר | N1: ענף מסחר | O1: בעל עניין/צד קשור | P1: מטבע פעילות | Q1: ערך נקוב (יחידות) | R1: שער חליפין | S1: שער נייר הערך | T1: סכום לקבל (במטבע הפעילות) | U1: שווי הוגן (באלפי ש"ח) | V1: שיעור מערך נקוב מונפק | W1: שיעור מנכסי אפיק ההשקעה | X1: שיעור מסך נכסי ההשקעה | Y1: שער נייר הערך
A2: 337 | B2: 1405 | C2: אלביט מערכות בע"מ | D2: 520043027 | E2: ח.פ | F2: אלביט מערכות | G2: IL0010811243 | H2: ISIN | I2: מניות | J2: ישראל | K2: ישראל | L2: סחיר | M2: TASE | N2: ביטחוניות | O2: לא | P2: ILS | Q2: 46 | R2: 1 | S2: 77500 | U2: 35.65 | V2: 1e-06 | W2: 0.28235929 | X2: 0.0033717065 | Y2: 77500 | Z2: =(U2-T2*R2)/R2/Q2*100000 -> 77500
A3: 337 | B3: 1405 | C3: הפניקס אחזקות בע"מ | D3: 520017450 | E3: ח.פ | F3: הפניקס | G3: IL0007670123 | H3: ISIN | I3: מניות | J3: ישראל | K3: ישראל | L3: סחיר | M3: TASE | N3: ביטוח | O3: לא | P3: ILS | Q3: 500 | R3: 1 | S3: 3810 | U3: 19.05 | V3: 2e-06 | W3: 0.15088203 | X3: 0.0018017113 | Y3: 3810 | Z3: =(U3-T3*R3)/R3/Q3*100000 -> 3810
A4: 337 | B4: 1405 | C4: בנק לאומי לישראל בע"מ | D4: 520018078 | E4: ח.פ | F4: לאומי | G4: IL0006046119 | H4: ISIN | I4: מניות | J4: ישראל | K4: ישראל | L4: סחיר | M4: TASE | N4: בנקים | O4: לא | P4: ILS | Q4: 600 | R4: 1 | S4: 3100 | T4: 0.144 | U4: 18.744 | V4: 0 | W4: 0.14845699 | X4: 0.0017727534 | Y4: 3100 | Z4: =(U4-T4*R4)/R4/Q4*100000 -> 3100
A5: 337 | B5: 1405 | C5: מבנה נדל"ן (כ.ד) בע"מ | D5: 520024126 | E5: ח.פ | F5: מבנה | G5: IL0002260193 | H5: ISIN | I5: מניות | J5: ישראל | K5: ישראל | L5: סחיר | M5: TASE | N5: נדל"ן מניב בישראל | O5: לא | P5: ILS | Q5: 1000 | R5: 1 | S5: 907.1 | U5: 9.071 | V5: 1e-06 | W5: 0.071845194 | X5: 0.00085791724 | Y5: 907.1 | Z5: =(U5-T5*R5)/R5/Q5*100000 -> 907.1
A6: 337 | B6: 1405 | C6: קבוצת עזריאלי בע"מ (לשעבר קנית מימון) | D6: 510960719 | E6: ח.פ | F6: עזריאלי קבוצה | G6: IL0011194789 | H6: ISIN | I6: מניות | J6: ישראל | K6: ישראל | L6: סחיר | M6: TASE | N6: נדל"ן מניב בישראל | O6: לא | P6: ILS | Q6: 50 | R6: 1 | S6: 26610 | U6: 13.305 | V6: 0 | W6: 0.10537981 | X6: 0.0012583606 | Y6: 26610 | Z6: =(U6-T6*R6)/R6/Q6*100000 -> 26610
A7: 337 | B7: 1405 | C7: פוקס-ויזל בע"מ | D7: 512157603 | E7: ח.פ | F7: פוקס- ויזל | G7: IL0010870223 | H7: ISIN | I7: מניות | J7: ישראל | K7: ישראל | L7: סחיר | M7: TASE | N7: רשתות שיווק | O7: לא | P7: ILS | Q7: 20 | R7: 1 | S7: 34140 | U7: 6.828 | V7: 1e-06 | W7: 0.054079923 | X7: 0.00064577873 | Y7: 34140 | Z7: =(U7-T7*R7)/R7/Q7*100000 -> 34140
A8: 337 | B8: 1405 | C8: רשת חנויות רמי לוי שיווק השיקמה 2006 בע"מ | D8: 513770669 | E8: ח.פ | F8: רמי לוי | G8: IL0011042491 | H8: ISIN | I8: מניות | J8: ישראל | K8: ישראל | L8: סחיר | M8: TASE | N8: רשתות שיווק | O8: לא | P8: ILS | Q8: 48 | R8: 1 | S8: 22050 | U8: 10.584 | V8: 3e-06 | W8: 0.083828633 | X8: 0.0010010138 | Y8: 22050 | Z8: =(U8-T8*R8)/R8/Q8*100000 -> 22050
A9: 337 | B9: 1405 | C9: רני צים מרכזי קניות בע"מ | D9: 514353671 | E9: ח.פ | F9: רני צים | G9: IL0011436198 | H9: ISIN | I9: מניות | J9: ישראל | K9: ישראל | L9: סחיר | M9: TASE | N9: נדל"ן מניב בישראל | O9: לא | P9: ILS | Q9: 1478 | R9: 1 | S9: 266.1705 | U9: 3.934 | V9: 1e-05 | W9: 0.03116198 | X9: 0.00037211117 | Y9: 266.2 | Z9: =(U9-T9*R9)/R9/Q9*100000 -> 266.1705
A10: 337 | B10: 1405 | C10: תדיראן גרופ בע"מ | D10: 520036732 | E10: ח.פ | F10: תדיראן גרופ | G10: IL0002580129 | H10: ISIN | I10: מניות | J10: ישראל | K10: ישראל | L10: סחיר | M10: TASE | N10: מסחר | O10: לא | P10: ILS | Q10: 30 | R10: 1 | S10: 30040 | T10: 0.079 | U10: 9.091 | V10: 3e-06 | W10: 0.072006135 | X10: 0.00085983906 | Y10: 30040 | Z10: =(U10-T10*R10)/R10/Q10*100000 -> 30040
A11: 337 | B11: 1477 | C11: או.פי.סי. אנרגיה בע"מ | D11: 514401702 | E11: ח.פ | F11: או פי סי אנרגיה | G11: IL0011415713 | H11: ISIN | I11: מניות | J11: ישראל | K11: ישראל | L11: סחיר | M11: TASE | N11: אנרגיה | O11: לא | P11: ILS | Q11: 382 | R11: 1 | S11: 2615.9686 | U11: 9.993 | V11: 2e-06 | W11: 0.0036216102 | X11: 0.0010019213 | Y11: 2616 | Z11: =(U11-T11*R11)/R11/Q11*100000 -> 2615.9686
A12: 337 | B12: 1477 | C12: אטראו שוקי הון בע"מ לשעבר לידר | D12: 513773564 | E12: ח.פ | F12: אטראו שוקי הון | G12: IL0010961063 | H12: ISIN | I12: מניות | J12: ישראל | K12: ישראל | L12: סחיר | M12: TASE | N12: שירותים פיננסיים | O12: לא | P12: ILS | Q12: 457 | R12: 1 | S12: 5664.9891 | U12: 25.889 | V12: 3.1e-05 | W12: 0.0093824599 | X12: 0.0025956648 | Y12: 5665 | Z12: =(U12-T12*R12)/R12/Q12*100000 -> 5664.9891
A13: 337 | B13: 1477 | C13: אי.טי.גי. איי גרופ בע"מ | D13: 513764399 | E13: ח.פ | F13: אי. טי. ג'י. איי | G13: IL0011761140 | H13: ISIN | I13: מניות | J13: ישראל | K13: ישראל | L13: סחיר | M13: TASE | N13: שירותים | O13: לא | P13: ILS | Q13: 185 | R13: 1 | S13: 1050.2703 | T13: 0.029 | U13: 1.972 | V13: 8e-06 | W13: 0.000714579 | X13: 0.00019768884 | Y13: 1050 | Z13: =(U13-T13*R13)/R13/Q13*100000 -> 1050.2703
A14: 337 | B14: 1477 | C14: איי.סי.אל גרופ בע"מ (דואלי) | D14: 520027830 | E14: ח.פ | F14: איי.סי.אל | G14: IL0002810146 | H14: ISIN | I14: מניות | J14: ישראל | K14: ישראל | L14: סחיר | M14: TASE | N14: כימיה, גומי ופלסטיק | O14: לא | P14: ILS | Q14: 2525 | R14: 1 | S14: 1951.0099 | U14: 49.263 | V14: 2e-06 | W14: 0.017853331 | X14: 0.0049391379 | Y14: 1951 | Z14: =(U14-T14*R14)/R14/Q14*100000 -> 1951.0099
A15: 337 | B15: 1477 | C15: אינרום תעשיות בנייה בע"מ | D15: 515001659 | E15: ח.פ | F15: אינרום חסום 06.08.24 | G15: IL0011323560 | H15: ISIN | I15: מניות | J15: ישראל | K15: ישראל | L15: חסום | M15: TASE | N15: מתכת ומוצרי בניה | O15: לא | P15: ILS | Q15: 1000 | R15: 1 | S15: 1172.3 | U15: 11.723 | V15: 7e-06 | W15: 0.0042484051 | X15: 0.0011753246 | Y15: 1172.264 | Z15: =(U15-T15*R15)/R15/Q15*100000 -> 1172.3
A16: 337 | B16: 1477 | C16: איסתא בע"מ | D16: 520042763 | E16: ח.פ | F16: איסתא | G16: IL0010810740 | H16: ISIN | I16: מניות | J16: ישראל | K16: ישראל | L16: סחיר | M16: TASE | N16: מלונאות ותיירות | O16: לא | P16: ILS | Q16: 113 | R16: 1 | S16: 8312.3894 | U16: 9.393 | V16: 7e-06 | W16: 0.003403961 | X16: 0.00094170847 | Y16: 8312 | Z16: =(U16-T16*R16)/R16/Q16*100000 -> 8312.3894
A17: 337 | B17: 1477 | C17: אלביט מערכות בע"מ | D17: 520043027 | E17: ח.פ | F17: אלביט מערכות | G17: IL0010811243 | H17: ISIN | I17: מניות | J17: ישראל | K17: ישראל | L17: סחיר | M17: TASE | N17: ביטחוניות | O17: לא | P17: ILS | Q17: 69 | R17: 1 | S17: 77500 | U17: 53.475 | V17: 2e-06 | W17: 0.019379894 | X17: 0.0053614628 | Y17: 77500 | Z17: =(U17-T17*R17)/R17/Q17*100000 -> 77500
A18: 337 | B18: 1477 | C18: אלקטרה נדל"ן בע"מ | D18: 510607328 | E18: ח.פ | F18: אלקטרה נדלן | G18: IL0010940448 | H18: ISIN | I18: מניות | J18: ישראל | K18: ישראל | L18: סחיר | M18: TASE | N18: נדל"ן מניב בחו"ל | O18: לא | P18: ILS | Q18: 417 | R18: 1 | S18: 3879.8561 | T18: 0.139 | U18: 16.318 | V18: 7e-06 | W18: 0.0059139608 | X18: 0.0016361019 | Y18: 3880 | Z18: =(U18-T18*R18)/R18/Q18*100000 -> 3879.8561
A19: 337 | B19: 1477 | C19: אמות השקעות בע"מ | D19: 520026683 | E19: ח.פ | F19: אמות | G19: IL0010972789 | H19: ISIN | I19: מניות | J19: ישראל | K19: ישראל | L19: סחיר | M19: TASE | N19: נדל"ן מניב בישראל | O19: לא | P19: ILS | Q19: 1860 | R19: 1 | S19: 1748.9785 | U19: 32.531 | V19: 4e-06 | W19: 0.011789716 | X19: 0.0032616342 | Y19: 1749 | Z19: =(U19-T19*R19)/R19/Q19*100000 -> 1748.9785
A20: 337 | B20: 1477 | C20: אנלייט אנרגיה מתחדשת בע"מ | D20: 520041146 | E20: ח.פ | F20: אנלייט אנרגיה | G20: IL0007200111 | H20: ISIN | I20: מניות | J20: ישראל | K20: ישראל | L20: סחיר | M20: TASE | N20: אנרגיה מתחדשת | O20: לא | P20: ILS | Q20: 949.3 | R20: 1 | S20: 6298.9571 | U20: 59.796 | V20: 8e-06 | W20: 0.021670837 | X20: 0.005995254 | Y20: 6299 | Z20: =(U20-T20*R20)/R20/Q20*100000 -> 6298.9571
A21: 337 | B21: 1477 | C21: אנרג'יקס אנרגיות מתחדשות בע"מ | D21: 513901371 | E21: ח.פ | F21: אנרג'יקס | G21: IL0011233553 | H21: ISIN | I21: מניות | J21: ישראל | K21: ישראל | L21: סחיר | M21: TASE | N21: אנרגיה מתחדשת | O21: לא | P21: ILS | Q21: 1032 | R21: 1 | S21: 1352.0349 | U21: 13.953 | V21: 2e-06 | W21: 0.0050565813 | X21: 0.0013989071 | Y21: 1352 | Z21: =(U21-T21*R21)/R21/Q21*100000 -> 1352.0349
A22: 337 | B22: 1477 | C22: ארגו פרופרטיז אן. וי | D22: 724500VWIAC6N6VHCK55 | E22: LEI | F22: ארגו פרופרטיז אן. וי | G22: NL0015000D84 | H22: ISIN | I22: מניות | J22: חו"ל | K22: גרמניה | L22: סחיר | M22: TASE | N22: נדל"ן מניב בחו"ל | O22: לא | P22: ILS | Q22: 112 | R22: 1 | S22: 7563.3929 | U22: 8.471 | V22: 6e-06 | W22: 0.0030698187 | X22: 0.00084926773 | Y22: 7563 | Z22: =(U22-T22*R22)/R22/Q22*100000 -> 7563.3929
A23: 337 | B23: 1477 | C23: ארד בע"מ | D23: 510007800 | E23: ח.פ | F23: ארד | G23: IL0010916513 | H23: ISIN | I23: מניות | J23: ישראל | K23: ישראל | L23: סחיר | M23: TASE | N23: אלקטרוניקה ואופטיקה | O23: לא | P23: ILS | Q23: 204 | R23: 1 | S23: 5100 | U23: 10.404 | V23: 8e-06 | W23: 0.0037705174 | X23: 0.0010431166 | Y23: 5100 | Z23: =(U23-T23*R23)/R23/Q23*100000 -> 5100
A24: 337 | B24: 1477 | C24: בזק החברה הישראלית לתקשורת בע"מ | D24: 520031931 | E24: ח.פ | F24: בזק | G24: IL0002300114 | H24: ISIN | I24: מניות | J24: ישראל | K24: ישראל | L24: סחיר | M24: TASE | N24: תקשורת ומדיה | O24: לא | P24: ILS | Q24: 11240 | R24: 1 | S24: 472.99822 | U24: 53.165 | V24: 4e-06 | W24: 0.019267619 | X24: 0.0053304019 | Y24: 473 | Z24: =(U24-T24*R24)/R24/Q24*100000 -> 472.99822
A25: 337 | B25: 1477 | C25: ביג מרכזי קניות (2004) בע"מ | D25: 513623314 | E25: ח.פ | F25: ביג | G25: IL0010972607 | H25: ISIN | I25: מניות | J25: ישראל | K25: ישראל | L25: סחיר | M25: TASE | N25: נדל"ן מניב בישראל | O25: לא | P25: ILS | Q25: 161 | R25: 1 | S25: 41029.814 | U25: 66.058 | V25: 7e-06 | W25: 0.023940212 | X25: 0.0066230784 | Y25: 41030 | Z25: =(U25-T25*R25)/R25/Q25*100000 -> 41029.814
A26: 337 | B26: 1477 | C26: הבנק הבינלאומי הראשון לישראל בע"מ | D26: 520029083 | E26: ח.פ | F26: בינלאומי 5 | G26: IL0005930388 | H26: ISIN | I26: מניות | J26: ישראל | K26: ישראל | L26: סחיר | M26: TASE | N26: בנקים | O26: לא | P26: ILS | Q26: 545 | R26: 1 | S26: 15440 | U26: 84.148 | V26: 5e-06 | W26: 0.030496107 | X26: 0.0084367717 | Y26: 15440 | Z26: =(U26-T26*R26)/R26/Q26*100000 -> 15440
A27: 337 | B27: 1477 | C27: בית בכפר בע"מ | D27: 511605719 | E27: ח.פ | F27: בית בכפר | G27: IL0011836561 | H27: ISIN | I27: מניות | J27: ישראל | K27: ישראל | L27: סחיר | M27: TASE | N27: נדל"ן מניב בישראל | O27: לא | P27: ILS | Q27: 542 | R27: 1 | S27: 1161.0701 | U27: 6.293 | V27: 8e-06 | W27: 0.0022805107 | X27: 0.00063090505 | Y27: 1161 | Z27: =(U27-T27*R27)/R27/Q27*100000 -> 1161.0701
A28: 337 | B28: 1477 | C28: מנועי בית שמש אחזקות (1997) בע"מ | D28: 520043480 | E28: ח.פ | F28: בית שמש | G28: IL0010815616 | H28: ISIN | I28: מניות | J28: ישראל | K28: ישראל | L28: סחיר | M28: TASE | N28: מתכת ומוצרי בניה | O28: לא | P28: ILS | Q28: 200 | R28: 1 | S28: 14790 | U28: 29.58 | V28: 2.3e-05 | W28: 0.010720098 | X28: 0.0029657236 | Y28: 14790 | Z28: =(U28-T28*R28)/R28/Q28*100000 -> 14790
A29: 337 | B29: 1477 | C29: חברת גב-ים לקרקעות בע"מ | D29: 520001736 | E29: ח.פ | F29: גב ים | G29: IL0007590198 | H29: ISIN | I29: מניות | J29: ישראל | K29: ישראל | L29: סחיר | M29: TASE | N29: נדל"ן מניב בישראל | O29: לא | P29: ILS | Q29: 348 | R29: 1 | S29: 2779.8851 | U29: 9.674 | V29: 0.000173 | W29: 0.0035061028 | X29: 0.00096996606 | Y29: 2780 | Z29: =(U29-T29*R29)/R29/Q29*100000 -> 2779.8851
A30: 337 | B30: 1477 | C30: בנק דיסקונט לישראל בע"מ | D30: 520007030 | E30: ח.פ | F30: דיסקונט | G30: IL0006912120 | H30: ISIN | I30: מניות | J30: ישראל | K30: ישראל | L30: סחיר | M30: TASE | N30: בנקים | O30: לא | P30: ILS | Q30: 4067 | R30: 1 | S30: 1946.0044 | T30: 0.604 | U30: 79.748 | V30: 3e-06 | W30: 0.028901541 | X30: 0.0079956339 | Y30: 1946 | Z30: =(U30-T30*R30)/R30/Q30*100000 -> 1946.0044
