Workbook
Name Tsua: [1]תשואה!$A$6
Name tsua1: [2]תשואה!$A$6

Sheet פרסום מרכיבי תשואה
B1: פירוט תרומת אפיקי ההשקעה לתשואה הכוללת עתודות קרן עתודות ותיקה 2023
B2: אפיקי השקעה: | C2: התרומה לתשואה ינואר 2023 | D2: שיעור מסך הנכסים ינואר 2023 | E2: התרומה לתשואה פברואר 2023 | F2: שיעור מסך הנכסים פברואר 2023 | G2: התרומה לתשואה מרץ 2023 | H2: שיעור מסך הנכסים מרץ 2023 | I2: התרומה לתשואה אפריל 2023 | J2: שיעור מסך הנכסים אפריל 2023 | K2: התרומה לתשואה מאי 2023 | L2: שיעור מסך הנכסים מאי 2023 | M2: התרומה לתשואה יוני 2023 | N2: שיעור מסך הנכסים יוני 2023 | O2: התרומה לתשואה יולי 2023 | P2: שיעור מסך הנכסים יולי 2023 | Q2: התרומה לתשואה אוגוסט 2023 | R2: שיעור מסך הנכסים אוגוסט 2023 | S2: התרומה לתשואה ספטמבר 2023 | T2: שיעור מסך הנכסים ספטמבר 2023 | U2: התרומה לתשואה אוקטובר 2023 | V2: שיעור מסך הנכסים אוקטובר 2023 | W2: התרומה לתשואה נובמבר 2023 | X2: שיעור מסך הנכסים נובמבר 2023 | Y2: התרומה לתשואה דצמבר 2023 | Z2: שיעור מסך הנכסים דצמבר 2023
B3: מזומנים ושווי מזומנים | C3: 2.021049e-06 | D3: 0.01344707 | E3: 0.00014318035 | F3: 0.015514533 | G3: 5.5042992e-06 | H3: 0.011431228 | I3: 0.00011009416 | J3: 0.0080532578 | K3: 3.7225505e-05 | L3: 0.00095722067 | M3: 3.7973506e-05 | N3: 0.0086326951 | O3: 8.3421007e-05 | P3: 0.0086326951 | Q3: 0.00038971673 | R3: 0.024128488 | S3: 0.00014423741 | T3: 0.025031134 | U3: 0.00079166023 | V3: 0.029064516 | W3: -0.0017037044 | X3: 0.020775244 | Y3: -0.00026515906 | Z3: 0.034824495
B4: אגרות חוב ממשלתיות | C4: 0.011347982 | D4: 0.50612223 | E4: -0.015437334 | F4: 0.50231449 | G4: 0.0071191265 | H4: 0.50401156 | I4: -0.0081633854 | J4: 0.49635134 | K4: 0.014833273 | L4: 0.49776425 | M4: 0.0032003889 | N4: 0.49069723 | O4: -0.0013843438 | P4: 0.49069723 | Q4: -0.003577124 | R4: 0.48297229 | S4: -0.0088355585 | T4: 0.47909408 | U4: -0.025491146 | V4: 0.47044622 | W4: 0.021319776 | X4: 0.47543311 | Y4: 0.0080265262 | Z4: 0.47322123
B5: תעודות חוב מסחריות סחירות | C5: 0 | D5: 0 | E5: 0 | F5: 0 | G5: 0 | H5: 0 | I5: 0 | J5: 0 | K5: 0 | L5: 0 | M5: 0 | N5: 0 | O5: 0 | P5: 0 | Q5: 0 | R5: 0 | S5: 0 | T5: 0 | U5: 0 | V5: 0 | W5: 0 | X5: 0 | Y5: 0 | Z5: 0
B6: תעודות חוב מסחריות לא סחירות | C6: 0 | D6: 0 | E6: 0 | F6: 0 | G6: 0 | H6: 0 | I6: 0 | J6: 0 | K6: 0 | L6: 0 | M6: 0 | N6: 0 | O6: 0 | P6: 0 | Q6: 0 | R6: 0 | S6: 0 | T6: 0 | U6: 0 | V6: 0 | W6: 0 | X6: 0 | Y6: 0 | Z6: 0
B7: אגרות חוב קונצרניות סחירות | C7: 0.0025855601 | D7: 0.12351699 | E7: -0.0032215709 | F7: 0.1252173 | G7: 0.0012951709 | H7: 0.12731046 | I7: 0.00092397359 | J7: 0.12909304 | K7: 0.0028176989 | L7: 0.12842833 | M7: 0.00078964228 | N7: 0.13593721 | O7: 0.00079446264 | P7: 0.13593721 | Q7: 0.00024979736 | R7: 0.13226758 | S7: -0.0011313148 | T7: 0.13278813 | U7: -0.0028979957 | V7: 0.13666369 | W7: 0.0043879605 | X7: 0.13741649 | Y7: 0.0023383111 | Z7: 0.13664474
B8: אגרות חוב קונצרניות לא סחירות | C8: -1.488677e-05 | D8: 0.036979818 | E8: -0.00067370101 | F8: 0.036583782 | G8: 0.00036573256 | H8: 0.036082545 | I8: 0.00017001375 | J8: 0.036380877 | K8: 0.00093733108 | L8: 0.03650795 | M8: 4.8085755e-05 | N8: 0.035780371 | O8: 0.00012812452 | P8: 0.035780371 | Q8: 9.8277244e-05 | R8: 0.024938112 | S8: -0.00018027934 | T8: 0.025033629 | U8: -0.0010212496 | V8: 0.02497417 | W8: 0.0012276561 | X8: 0.02541854 | Y8: 0.00028239085 | Z8: 0.023606886
B9: מניות | C9: 0.00194447 | D9: 0.091041025 | E9: -0.0031484878 | F9: 0.08857152 | G9: -1.7682255e-05 | H9: 0.082875921 | I9: 0.0015707083 | J9: 0.084788628 | K9: 0.00085803667 | L9: 0.084632917 | M9: 0.0020641218 | N9: 0.080455696 | O9: 0.0039197976 | P9: 0.080455696 | Q9: -0.00186736 | R9: 0.079137086 | S9: -0.00082770472 | T9: 0.074820978 | U9: -0.0043602277 | V9: 0.07582516 | W9: 0.00326733 | X9: 0.077078934 | Y9: 0.0031690098 | Z9: 0.07040018
B10: תעודות סל | C10: 0.0015981464 | D10: 0.049326934 | E10: -6.5835511e-05 | F10: 0.048307847 | G10: 7.0780448e-05 | H10: 0.050672972 | I10: 0.001158773 | J10: 0.052920417 | K10: -0.00037620539 | L10: 0.054530666 | M10: 0.0022037595 | N10: 0.052313055 | O10: 0.0017978371 | P10: 0.052313055 | Q10: 9.4752521e-06 | R10: 0.056125002 | S10: -0.0014570224 | T10: 0.066192013 | U10: -6.6422535e-05 | V10: 0.06949452 | W10: 0.00031951766 | X10: 0.068468905 | Y10: 0.0018652053 | Z10: 0.063552241
B11: קרנות נאמנות | C11: 0.00035095593 | D11: 0.011303978 | E11: 0.00040021671 | F11: 0.01201706 | G11: -7.5419693e-05 | H11: 0.012021444 | I11: 0.0002615895 | J11: 0.012337659 | K11: 0.0001972035 | L11: 0.012311228 | M11: 0.00016694572 | N11: 0.01267731 | O11: 0.00027765856 | P11: 0.01267731 | Q11: 0.00026527492 | R11: 0.01114987 | S11: -0.00014967828 | T11: 0.010979274 | U11: 0.00036939473 | V11: 0.011964698 | W11: -0.00031621081 | X11: 0.013397148 | Y11: 0.00016582301 | Z11: 0.012656301
B12: קרנות השקעה | C12: -0.00048868339 | D12: 0.072236246 | E12: 0.0031911527 | F12: 0.078265279 | G12: -0.00038010513 | H12: 0.07812808 | I12: 0.00087625114 | J12: 0.080039229 | K12: 0.0025599556 | L12: 0.082817693 | M12: 0.00078498843 | N12: 0.084349887 | O12: 0.00045973434 | P12: 0.084349887 | Q12: 0.0029247751 | R12: 0.08950892 | S12: 0.00010935479 | T12: 0.091542793 | U12: 0.003854838 | V12: 0.10089651 | W12: -0.005080753 | X12: 0.093685805 | Y12: -0.0016636736 | Z12: 0.091654334
B13: כתבי אופציה | C13: -4.0788033e-06 | D13: 4.2062644e-05 | E13: -5.9524693e-06 | F13: 3.7096621e-05 | G13: -4.6527124e-06 | H13: 3.2144618e-05 | I13: 4.9851571e-06 | J13: 3.7283066e-05 | K13: -1.1894624e-05 | L13: 2.9131611e-05 | M13: 3.1333267e-06 | N13: 3.1912809e-05 | O13: 1.2987894e-06 | P13: 3.1912809e-05 | Q13: 4.951505e-05 | R13: 6.0817501e-05 | S13: -8.854956e-07 | T13: 5.2970112e-05 | U13: -1.3297808e-05 | V13: 4.1653539e-05 | W13: 8.0131674e-06 | X13: 4.8353412e-05 | Y13: 0.00013079729 | Z13: 0.00017432644
B14: חוזים עתידיים | C14: 0.0022885556 | D14: -0.0056005809 | E14: -0.0047208965 | F14: -0.010166026 | G14: 0.0013488613 | H14: -0.006118398 | I14: -0.00041953263 | J14: -0.0066668121 | K14: -0.0091849985 | L14: -0.0021698848 | M14: 0.00098372166 | N14: -0.0053729115 | O14: 0.0011569451 | P14: -0.0053729115 | Q14: -0.0034861048 | R14: -0.0045436171 | S14: -0.001790039 | T14: -0.0068299791 | U14: -0.0059420717 | V14: -0.013186012 | W14: 0.0092445379 | X14: -0.0036719072 | Y14: 0.0031414859 | Z14: -0.0015722282
... B22: תשואה חודשית | C22: 0.020385312 | D22: 1 | E22: -0.023986931 | F22: 1 | G22: 0.0092223548 | H22: 1 | I22: -0.0023118484 | J22: 1 | K22: 0.014991886 | L22: 1 | M22: 0.010326379 | N22: 1 | O22: 0.0077805689 | P22: 1 | Q22: -0.0040367322 | R22: 1 | S22: -0.013485993 | T22: 1 | U22: -0.036733912 | V22: 1 | W22: 0.03303509 | X22: 1 | Y22: 0.018209941 | Z22: 1
B23: סה"כ רווח השקעתי לתקופה (אלפי ש"ח) | C23: 247287.51 | E23: -296278.99 | G23: 111053.99 | I23: -28075.862 | K23: 118944.72 | M23: 126562.33 | O23: 92972.446 | Q23: -43436.252 | S23: -166737.55 | U23: -448275.63 | W23: 387459.34 | Y23: 220161.95
B25: נכסים בארץ | C25: 0.013968076 | D25: 0.83610147 | E25: -0.029069703 | F25: 0.82979927 | G25: 0.0082535479 | H25: 0.82701696 | I25: -0.0049048775 | J25: 0.82166351 | K25: 0.010999629 | L25: 0.81679849 | M25: 0.005239055 | N25: 0.81692519 | O25: 0.0027332794 | P25: 0.81692519 | Q25: -0.0056536373 | R25: 0.8232734 | S25: -0.0088096775 | T25: 0.80670113 | U25: -0.042208338 | V25: 0.77872261 | W25: 0.038169904 | X25: 0.78939985 | Y25: 0.016022102 | Z25: 0.79418785
B26: נכסים בחול | C26: 0.0064172359 | D26: 0.16389853 | E26: 0.0050827718 | F26: 0.17020073 | G26: 0.00096880693 | H26: 0.17298304 | I26: 0.0025930291 | J26: 0.17833649 | K26: 0.0039922568 | L26: 0.18320151 | M26: 0.005087324 | N26: 0.18307481 | O26: 0.0050472896 | P26: 0.18307481 | Q26: 0.001616905 | R26: 0.1767266 | S26: -0.004676315 | T26: 0.19329887 | U26: 0.0054744266 | V26: 0.22127739 | W26: -0.005134814 | X26: 0.21060015 | Y26: 0.0021878383 | Z26: 0.20581215
B27: תשואה חודשית | C27: 0.020385312 | D27: 1 | E27: -0.023986931 | F27: 1 | G27: 0.0092223548 | H27: 1 | I27: -0.0023118484 | J27: 1 | K27: 0.014991886 | L27: 1 | M27: 0.010326379 | N27: 1 | O27: 0.0077805689 | P27: 1 | Q27: -0.0040367322 | R27: 1 | S27: -0.013485993 | T27: 1 | U27: -0.036733912 | V27: 1 | W27: 0.03303509 | X27: 1 | Y27: 0.018209941 | Z27: 1
B29: נכסים סחירים | C29: 0.013617903 | D29: 0.4206772 | E29: -0.012190023 | F29: 0.41829208 | G29: 0.0040037734 | H29: 0.41796662 | I29: 0.00051919312 | J29: 0.41734156 | K29: 0.0085138583 | L29: 0.41209352 | M29: 0.0074188975 | N29: 0.41841574 | O29: 0.0071837006 | P29: 0.41841574 | Q29: -0.0047634206 | R29: 0.42856654 | S29: -0.0086715528 | T29: 0.42369234 | U29: -0.021040618 | V29: 0.42392477 | W29: 0.017674008 | X29: 0.42621858 | Y29: 0.011641503 | Z29: 0.43044458
B30: נכסים לא סחירים | C30: 0.0067674088 | D30: 0.5793228 | E30: -0.011796908 | F30: 0.58170792 | G30: 0.0052185814 | H30: 0.58203338 | I30: -0.0028310415 | J30: 0.58265844 | K30: 0.0064780276 | L30: 0.58790648 | M30: 0.0029074815 | N30: 0.58158426 | O30: 0.00059686838 | P30: 0.58158426 | Q30: 0.00072668837 | R30: 0.57143346 | S30: -0.0048144397 | T30: 0.57630766 | U30: -0.015693293 | V30: 0.57607523 | W30: 0.015361082 | X30: 0.57378142 | Y30: 0.0065684378 | Z30: 0.56955542
B31: תשואה חודשית | C31: 0.020385312 | D31: 1 | E31: -0.023986931 | F31: 1 | G31: 0.0092223548 | H31: 1 | I31: -0.0023118484 | J31: 1 | K31: 0.014991886 | L31: 1 | M31: 0.010326379 | N31: 1 | O31: 0.0077805689 | P31: 1 | Q31: -0.0040367322 | R31: 1 | S31: -0.013485993 | T31: 1 | U31: -0.036733912 | V31: 1 | W31: 0.03303509 | X31: 1 | Y31: 0.018209941 | Z31: 1
B33: נתונים מצטברים | C33: התרומה לתשואה ינואר-מרץ 2023 | D33: שיעור מסך הנכסים ינואר-מרץ 2023 | E33: התרומה לתשואה ינואר-יוני 2023 | F33: שיעור מסך הנכסים ינואר-יוני 2023 | G33: התרומה לתשואה ינואר-ספטמבר 2023 | H33: שיעור מסך הנכסים ינואר-ספטמבר 2023 | I33: התרומה לתשואה ינואר-דצמבר 2023 | J33: שיעור מסך הנכסים ינואר-דצמבר 2023
B34: מזומנים ושווי מזומנים | C34: 0.00015431172 | D34: 0.011431228 | E34: 0.00033603758 | F34: 0.0086326951 | G34: 0.00062255753 | H34: 0.025031134 | I34: -0.00085987859 | J34: 0.034824495
B35: אגרות חוב ממשלתיות | C35: 0.002690283 | D35: 0.50401156 | E35: 0.01262197 | F35: 0.49069723 | G35: -0.0012998409 | H35: 0.47909408 | I35: 0.0019697504 | J35: 0.47322123
B36: תעודות חוב מסחריות סחירות | C36: 0 | D36: 0 | E36: 0 | F36: 0 | G36: 0 | H36: 0 | I36: 0 | J36: 0
B37: תעודות חוב מסחריות לא סחירות | C37: 0 | D37: 0 | E37: 0 | F37: 0 | G37: 0 | H37: 0 | I37: 0 | J37: 0
B38: אגרות חוב קונצרניות סחירות | C38: 0.00058964401 | D38: 0.12731046 | E38: 0.0051898198 | F38: 0.13593721 | G38: 0.0051013249 | H38: 0.13278813 | I38: 0.0089398208 | J38: 0.13664474
B39: אגרות חוב קונצרניות לא סחירות | C39: -0.00033704512 | D39: 0.036082545 | E39: 0.00083217279 | F39: 0.035780371 | G39: 0.00087830534 | H39: 0.025033629 | I39: 0.0013663352 | J39: 0.023606886
B40: מניות | C40: -0.0012760447 | D40: 0.082875921 | E40: 0.0032659056 | F40: 0.080455696 | G40: 0.0044855965 | H40: 0.074820978 | I40: 0.0065531867 | J40: 0.07040018
B41: תעודות סל | C41: 0.0015977558 | D41: 0.050672972 | E41: 0.0032659056 | F41: 0.052313055 | G41: 0.0049447702 | H41: 0.066192013 | I41: 0.0070739982 | J41: 0.063552241
B42: קרנות נאמנות | C42: 0.00068205267 | D42: 0.012021444 | E42: 0.0013021266 | F42: 0.01267731 | G42: 0.0016958863 | H42: 0.010979274 | I42: 0.0019151564 | J42: 0.012656301
B43: קרנות השקעה | C43: 0.0023765208 | D43: 0.07812808 | E43: 0.0065557192 | F43: 0.084349887 | G43: 0.010074214 | H43: 0.091542793 | I43: 0.0071378256 | J43: 0.091654334
B44: כתבי אופציה | C44: -1.4725017e-05 | D44: 3.2144618e-05 | E44: -1.846008e-05 | F44: 3.1912809e-05 | G44: 3.1467362e-05 | H44: 5.2970112e-05 | I44: 0.00015698317 | J44: 0.00017432644
B45: חוזים עתידיים | C45: -0.0011767061 | D45: -0.006118398 | E45: -0.0097145114 | F45: -0.0053729115 | G45: -0.013793552 | H45: -0.0068299791 | I45: -0.0074825977 | J45: -0.0015722282
... B53: תשואה מצטברת | C53: 0.0050940298 | D53: 1 | E53: 0.028314052 | F53: 1 | G53: 0.018212276 | H53: 1 | I53: 0.031660983 | J53: 1
B54: סה"כ רווח השקעתי לתקופה (אלפי ש"ח) | C54: 62062.5 | E54: 279493.69 | G54: 162292.33 | I54: 321637.99
B56: נכסים בארץ | C56: -0.0080851265 | D56: 0.82701696 | E56: 0.0038458799 | F56: 0.81692519 | G56: -0.0081761823 | H56: 0.80670113 | I56: 0.002706531 | J56: 0.79418785
B57: נכסים בחול | C57: 0.013179156 | D57: 0.17298304 | E57: 0.024375725 | F57: 0.18307481 | G57: 0.026388458 | H57: 0.19329887 | I57: 0.028954452 | J57: 0.20581215
B58: תשואה מצטברת | C58: 0.0050940298 | D58: 1 | E58: 0.028314052 | F58: 1 | G58: 0.018212276 | H58: 1 | I58: 0.031660983 | J58: 1
...

Sheet מצטבר
A1: נתונים מצטברים | B1: התרומה לתשואה ינואר-מרץ 2023 | C1: שיעור מסך הנכסים ינואר-מרץ 2023 | D1: התרומה לתשואה ינואר-יוני 2023 | E1: שיעור מסך הנכסים ינואר-יוני 2023 | F1: התרומה לתשואה ינואר-ספטמבר 2023 | G1: שיעור מסך הנכסים ינואר-ספטמבר 2023 | H1: התרומה לתשואה ינואר-דצמבר 2023 | I1: שיעור מסך הנכסים ינואר-דצמבר 2023
A2: מזומנים ושווי מזומנים | B2: =(1+'פרסום מרכיבי תשואה'!C3)*(1+'פרסום מרכיבי תשואה'!E3)*(1+'פרסום מרכיבי תשואה'!G3)-1 -> 0.00015070679 | C2: ='פרסום מרכיבי תשואה'!H3 -> 0.011431228 | D2: =(1+'פרסום מרכיבי תשואה'!I3)*(1+'פרסום מרכיבי תשואה'!K3)*(1+'פרסום מרכיבי תשואה'!M3)*(1+B2)-1 -> 0.00033603758 | E2: ='פרסום מרכיבי תשואה'!N3 -> 0.0086326951 | G2: ='פרסום מרכיבי תשואה'!T3 -> 0.025031134 | I2: ='פרסום מרכיבי תשואה'!Z3 -> 0.034824495
A3: אגרות חוב ממשלתיות | B3: =(1+'פרסום מרכיבי תשואה'!C4)*(1+'פרסום מרכיבי תשואה'!E4)*(1+'פרסום מרכיבי תשואה'!G4)-1 -> 0.0028242315 | C3: ='פרסום מרכיבי תשואה'!H4 -> 0.50401156 | D3: =(1+'פרסום מרכיבי תשואה'!I4)*(1+'פרסום מרכיבי תשואה'!K4)*(1+'פרסום מרכיבי תשואה'!M4)*(1+B3)-1 -> 0.01262197 | E3: ='פרסום מרכיבי תשואה'!N4 -> 0.49069723 | G3: ='פרסום מרכיבי תשואה'!T4 -> 0.47909408 | I3: ='פרסום מרכיבי תשואה'!Z4 -> 0.47322123
A4: תעודות חוב מסחריות סחירות | B4: =(1+'פרסום מרכיבי תשואה'!C5)*(1+'פרסום מרכיבי תשואה'!E5)*(1+'פרסום מרכיבי תשואה'!G5)-1 -> 0 | C4: ='פרסום מרכיבי תשואה'!H5 -> 0 | D4: =(1+'פרסום מרכיבי תשואה'!I5)*(1+'פרסום מרכיבי תשואה'!K5)*(1+'פרסום מרכיבי תשואה'!M5)*(1+B4)-1 -> 0 | E4: ='פרסום מרכיבי תשואה'!N5 -> 0 | G4: ='פרסום מרכיבי תשואה'!T5 -> 0 | I4: ='פרסום מרכיבי תשואה'!Z5 -> 0
A5: תעודות חוב מסחריות לא סחירות | B5: =(1+'פרסום מרכיבי תשואה'!C6)*(1+'פרסום מרכיבי תשואה'!E6)*(1+'פרסום מרכיבי תשואה'!G6)-1 -> 0 | C5: ='פרסום מרכיבי תשואה'!H6 -> 0 | D5: =(1+'פרסום מרכיבי תשואה'!I6)*(1+'פרסום מרכיבי תשואה'!K6)*(1+'פרסום מרכיבי תשואה'!M6)*(1+B5)-1 -> 0 | E5: ='פרסום מרכיבי תשואה'!N6 -> 0 | G5: ='פרסום מרכיבי תשואה'!T6 -> 0 | I5: ='פרסום מרכיבי תשואה'!Z6 -> 0
A6: אגרות חוב קונצרניות סחירות | B6: =(1+'פרסום מרכיבי תשואה'!C7)*(1+'פרסום מרכיבי תשואה'!E7)*(1+'פרסום מרכיבי תשואה'!G7)-1 -> 0.00064999593 | C6: ='פרסום מרכיבי תשואה'!H7 -> 0.12731046 | D6: =(1+'פרסום מרכיבי תשואה'!I7)*(1+'פרסום מרכיבי תשואה'!K7)*(1+'פרסום מרכיבי תשואה'!M7)*(1+B6)-1 -> 0.0051898198 | E6: ='פרסום מרכיבי תשואה'!N7 -> 0.13593721 | G6: ='פרסום מרכיבי תשואה'!T7 -> 0.13278813 | I6: ='פרסום מרכיבי תשואה'!Z7 -> 0.13664474
A7: אגרות חוב קונצרניות לא סחירות | B7: =(1+'פרסום מרכיבי תשואה'!C8)*(1+'פרסום מרכיבי תשואה'!E8)*(1+'פרסום מרכיבי תשואה'!G8)-1 -> -0.00032309703 | C7: ='פרסום מרכיבי תשואה'!H8 -> 0.036082545 | D7: =(1+'פרסום מרכיבי תשואה'!I8)*(1+'פרסום מרכיבי תשואה'!K8)*(1+'פרסום מרכיבי תשואה'!M8)*(1+B7)-1 -> 0.00083217279 | E7: ='פרסום מרכיבי תשואה'!N8 -> 0.035780371 | G7: ='פרסום מרכיבי תשואה'!T8 -> 0.025033629 | I7: ='פרסום מרכיבי תשואה'!Z8 -> 0.023606886
A8: מניות | B8: =(1+'פרסום מרכיבי תשואה'!C9)*(1+'פרסום מרכיבי תשואה'!E9)*(1+'פרסום מרכיבי תשואה'!G9)-1 -> -0.0012278007 | C8: ='פרסום מרכיבי תשואה'!H9 -> 0.082875921 | D8: =(1+'פרסום מרכיבי תשואה'!I9)*(1+'פרסום מרכיבי תשואה'!K9)*(1+'פרסום מרכיבי תשואה'!M9)*(1+B8)-1 -> 0.0032659056 | E8: ='פרסום מרכיבי תשואה'!N9 -> 0.080455696 | G8: ='פרסום מרכיבי תשואה'!T9 -> 0.074820978 | I8: ='פרסום מרכיבי תשואה'!Z9 -> 0.07040018
A9: תעודות סל | B9: =(1+'פרסום מרכיבי תשואה'!C10)*(1+'פרסום מרכיבי תשואה'!E10)*(1+'פרסום מרכיבי תשואה'!G10)-1 -> 0.0016030946 | C9: ='פרסום מרכיבי תשואה'!H10 -> 0.050672972 | D9: =(1+'פרסום מרכיבי תשואה'!I10)*(1+'פרסום מרכיבי תשואה'!K10)*(1+'פרסום מרכיבי תשואה'!M10)*(1+B9)-1 -> 0.0045954988 | E9: ='פרסום מרכיבי תשואה'!N10 -> 0.052313055 | G9: ='פרסום מרכיבי תשואה'!T10 -> 0.066192013 | I9: ='פרסום מרכיבי תשואה'!Z10 -> 0.063552241
A10: קרנות נאמנות | B10: =(1+'פרסום מרכיבי תשואה'!C11)*(1+'פרסום מרכיבי תשואה'!E11)*(1+'פרסום מרכיבי תשואה'!G11)-1 -> 0.00067583673 | C10: ='פרסום מרכיבי תשואה'!H11 -> 0.012021444 | D10: =(1+'פרסום מרכיבי תשואה'!I11)*(1+'פרסום מרכיבי תשואה'!K11)*(1+'פרסום מרכיבי תשואה'!M11)*(1+B10)-1 -> 0.0013021266 | E10: ='פרסום מרכיבי תשואה'!N11 -> 0.01267731 | G10: ='פרסום מרכיבי תשואה'!T11 -> 0.010979274 | I10: ='פרסום מרכיבי תשואה'!Z11 -> 0.012656301
A11: קרנות השקעה | B11: =(1+'פרסום מרכיבי תשואה'!C12)*(1+'פרסום מרכיבי תשואה'!E12)*(1+'פרסום מרכיבי תשואה'!G12)-1 -> 0.0023197781 | C11: ='פרסום מרכיבי תשואה'!H12 -> 0.07812808 | D11: =(1+'פרסום מרכיבי תשואה'!I12)*(1+'פרסום מרכיבי תשואה'!K12)*(1+'פרסום מרכיבי תשואה'!M12)*(1+B11)-1 -> 0.0065557192 | E11: ='פרסום מרכיבי תשואה'!N12 -> 0.084349887 | G11: ='פרסום מרכיבי תשואה'!T12 -> 0.091542793 | I11: ='פרסום מרכיבי תשואה'!Z12 -> 0.091654334
A12: כתבי אופציה | B12: =(1+'פרסום מרכיבי תשואה'!C13)*(1+'פרסום מרכיבי תשואה'!E13)*(1+'פרסום מרכיבי תשואה'!G13)-1 -> -1.4683914e-05 | C12: ='פרסום מרכיבי תשואה'!H13 -> 3.2144618e-05 | D12: =(1+'פרסום מרכיבי תשואה'!I13)*(1+'פרסום מרכיבי תשואה'!K13)*(1+'פרסום מרכיבי תשואה'!M13)*(1+B12)-1 -> -1.846008e-05 | E12: ='פרסום מרכיבי תשואה'!N13 -> 3.1912809e-05 | G12: ='פרסום מרכיבי תשואה'!T13 -> 5.2970112e-05 | I12: ='פרסום מרכיבי תשואה'!Z13 -> 0.00017432644
A13: חוזים עתידיים | B13: =(1+'פרסום מרכיבי תשואה'!C14)*(1+'פרסום מרכיבי תשואה'!E14)*(1+'פרסום מרכיבי תשואה'!G14)-1 -> -0.0010975791 | C13: ='פרסום מרכיבי תשואה'!H14 -> -0.006118398 | D13: =(1+'פרסום מרכיבי תשואה'!I14)*(1+'פרסום מרכיבי תשואה'!K14)*(1+'פרסום מרכיבי תשואה'!M14)*(1+B13)-1 -> -0.0097145114 | E13: ='פרסום מרכיבי תשואה'!N14 -> -0.0053729115 | G13: ='פרסום מרכיבי תשואה'!T14 -> -0.0068299791 | I13: ='פרסום מרכיבי תשואה'!Z14 -> -0.0015722282
... A20: השקעות אחרות | B20: =(1+'פרסום מרכיבי תשואה'!C21)*(1+'פרסום מרכיבי תשואה'!E21)*(1+'פרסום מרכיבי תשואה'!G21)-1 -> -8.3644203e-13 | C20: ='פרסום מרכיבי תשואה'!H21 -> 0.013002765 | D20: =(1+'פרסום מרכיבי תשואה'!I21)*(1+'פרסום מרכיבי תשואה'!K21)*(1+'פרסום מרכיבי תשואה'!M21)*(1+B20)-1 -> 1.6844304e-12 | E20: ='פרסום מרכיבי תשואה'!N21 -> 0.015442054 | G20: ='פרסום מרכיבי תשואה'!T21 -> 0.0081075395 | I20: ='פרסום מרכיבי תשואה'!Z21 -> 0.010444676
A21: תשואה מצטברת | B21: =(1+'פרסום מרכיבי תשואה'!C22)*(1+'פרסום מרכיבי תשואה'!E22)*(1+'פרסום מרכיבי תשואה'!G22)-1 -> 0.0050940298 | C21: 1 | D21: =(1+'פרסום מרכיבי תשואה'!I22)*(1+'פרסום מרכיבי תשואה'!K22)*(1+'פרסום מרכיבי תשואה'!M22)*(1+B21)-1 -> 0.028314052 | E21: 1 | G21: 1 | I21: 1
A22: סה"כ רווח השקעתי לתקופה (אלפי ש"ח) | B22: 61933.915
A24: נכסים בארץ | B24: =(1+'פרסום מרכיבי תשואה'!C25)*(1+'פרסום מרכיבי תשואה'!E25)*(1+'פרסום מרכיבי תשואה'!G25)-1 -> -0.0073821201 | C24: ='פרסום מרכיבי תשואה'!H25 -> 0.82701696 | D24: =(1+'פרסום מרכיבי תשואה'!I25)*(1+'פרסום מרכיבי תשואה'!K25)*(1+'פרסום מרכיבי תשואה'!M25)*(1+B24)-1 -> 0.0038458799 | E24: ='פרסום מרכיבי תשואה'!N25 -> 0.81692519 | G24: ='פרסום מרכיבי תשואה'!T25 -> 0.80670113 | I24: ='פרסום מרכיבי תשואה'!Z25 -> 0.79418785
A25: נכסים בחול | B25: =(1+'פרסום מרכיבי תשואה'!C26)*(1+'פרסום מרכיבי תשואה'!E26)*(1+'פרסום מרכיבי תשואה'!G26)-1 -> 0.012512605 | C25: ='פרסום מרכיבי תשואה'!H26 -> 0.17298304 | D25: =(1+'פרסום מרכיבי תשואה'!I26)*(1+'פרסום מרכיבי תשואה'!K26)*(1+'פרסום מרכיבי תשואה'!M26)*(1+B25)-1 -> 0.024375725 | E25: ='פרסום מרכיבי תשואה'!N26 -> 0.18307481 | G25: ='פרסום מרכיבי תשואה'!T26 -> 0.19329887 | I25: ='פרסום מרכיבי תשואה'!Z26 -> 0.20581215
A26: תשואה מצטברת | B26: 0.0050940298 | C26: 1 | D26: =(1+'פרסום מרכיבי תשואה'!I27)*(1+'פרסום מרכיבי תשואה'!K27)*(1+'פרסום מרכיבי תשואה'!M27)*(1+B26)-1 -> 0.028314052 | E26: 1 | G26: 1 | I26: 1
A28: נכסים סחירים | B28: =(1+'פרסום מרכיבי תשואה'!C29)*(1+'פרסום מרכיבי תשואה'!E29)*(1+'פרסום מרכיבי תשואה'!G29)-1 -> 0.0052707036 | C28: ='פרסום מרכיבי תשואה'!H29 -> 0.41796662 | D28: =(1+'פרסום מרכיבי תשואה'!I29)*(1+'פרסום מרכיבי תשואה'!K29)*(1+'פרסום מרכיבי תשואה'!M29)*(1+B28)-1 -> 0.021881211 | E28: ='פרסום מרכיבי תשואה'!N29 -> 0.41841574 | G28: ='פרסום מרכיבי תשואה'!T29 -> 0.42369234 | I28: ='פרסום מרכיבי תשואה'!Z29 -> 0.43044458
A29: נכסים לא סחירים | B29: =(1+'פרסום מרכיבי תשואה'!C30)*(1+'פרסום מרכיבי תשואה'!E30)*(1+'פרסום מרכיבי תשואה'!G30)-1 -> 8.2583973e-05 | C29: ='פרסום מרכיבי תשואה'!H30 -> 0.58203338 | D29: =(1+'פרסום מרכיבי תשואה'!I30)*(1+'פרסום מרכיבי תשואה'!K30)*(1+'פרסום מרכיבי תשואה'!M30)*(1+B29)-1 -> 0.0066298029 | E29: ='פרסום מרכיבי תשואה'!N30 -> 0.58158426 | G29: ='פרסום מרכיבי תשואה'!T30 -> 0.57630766 | I29: ='פרסום מרכיבי תשואה'!Z30 -> 0.56955542
A30: תשואה מצטברת | B30: 0.0050940298 | C30: 1 | D30: =(1+'פרסום מרכיבי תשואה'!I31)*(1+'פרסום מרכיבי תשואה'!K31)*(1+'פרסום מרכיבי תשואה'!M31)*(1+B30)-1 -> 0.028314052 | E30: 1 | G30: 1 | I30: 1
