Workbook

Sheet הכשרה - קרן י
A1: קרן י'
A3: אפיק השקעה | B3: שיעור חשיפה ליום 16/11/25 | C3: מדיניות השקעות 2025 | D3: שיעור חשיפה מומלץ לשנת 2026 | E3: טווח סטייה | F3: גבולות שיעור החשיפה המומלץ | I3: מדד ייחוס | J3: שינוי ממדיניות 2025
A4: מניות (תעודות סל, קרנות נאמנות, חוזים אופציות ונגזרים) | B4: 0.4913 | C4: 0.44 | D4: 0.44 | E4: +/- 6% | F4: =D4+6% -> 0.5 | G4: - | H4: =IF(D4-6%<0%,0%,D4-6%) -> 0.38 | I4: 35% - ת"א 125 | J4: =D4-C4 -> 0
I5: 65% - MSCI World | J5: =D5-C5 -> 0
J6: =D6-C6 -> 0
A7: אג"ח ממשלתי (סחיר ולא סחיר, קרנות נאמנות, תעודות סל, חוזים ונגזרים) | B7: 0.176 | C7: 0.19 | D7: 0.19 | E7: +/- 5% | F7: =D7+5% -> 0.24 | G7: - | H7: =IF(D7-5%<0%,0%,D7-5%) -> 0.14 | I7: 50% מדד ממשלתי שקלי 2-5 | J7: =D7-C7 -> 0
I8: 50% מדד ממשלתי צמוד 2-5 | J8: =D8-C8 -> 0
A9: אג"ח קונצרני (סחיר ולא סחיר, קרנות נאמנות, תעודות סל, חוזים ונגזרים) | B9: 0.1131 | C9: 0.1 | D9: 0.1 | E9: +/- 6% | F9: =D9+6% -> 0.16 | G9: - | H9: =IF(D9-6%<0%,0%,D9-6%) -> 0.04 | I9: 80% תלבונד 60 | J9: =D9-C9 -> 0
I10: 20% Barclays Global Aggregate Index | J10: =D10-C10 -> 0
A11: נדל"ן | B11: 0.1131 | C11: 0.1 | D11: 0.1 | E11: +/- 5% | F11: =D11+5% -> 0.15 | G11: - | H11: =IF(D11-5%<0%,0%,D11-5%) -> 0.05 | I11: ממשלתי צמוד 5-10 | J11: =D11-C11 -> 0
A12: קרנות השקעה + קרנות גידור | B12: 0.2249 | C12: 0.21 | D12: 0.21 | E12: +/- 5% | F12: =D12+5% -> 0.26 | G12: - | H12: =IF(D12-5%<0%,0%,D12-5%) -> 0.16 | I12: מדד HFRI WORLD | J12: =D12-C12 -> 0
A13: הלוואות לחברות + הלוואות עמיתים | B13: 0.0042 | C13: 0.03 | D13: 0.03 | E13: +/- 5% | F13: =D13+5% -> 0.08 | G13: - | H13: =IF(D13-5%<0%,0%,D13-5%) -> 0 | I13: ממשלתי לא צמוד 2-5 | J13: =D13-C13 -> 0
A14: אחר (מזומן, פקדונות, סחורות) | B14: 0.0826 | C14: 0.06 | D14: 0.08 | E14: +/- 5% | F14: =D14+5% -> 0.13 | G14: - | H14: =IF(D14-5%<0%,0%,D14-5%) -> 0.03 | I14: ריבית בנק ישראל | J14: =D14-C14 -> 0.02
A15: סה"כ | B15: =SUM(B4:B14) -> 1.2052 | C15: =SUM(C4:C14) -> 1.13 | D15: =SUM(D4:D14) -> 1.15 | J15: =SUM(J4:J14) -> 0.02
A16: חשיפה למט"ח | B16: 0.2032 | C16: 0.22 | D16: 0.19 | E16: +/- 6% | F16: =D16+6% -> 0.25 | G16: - | H16: =IF(D16-6%<0%,0%,D16-6%) -> 0.13 | I16: 80% דולר 20% אירו | J16: =D16-C16 -> -0.03
A17: מגבלת עמלת ניהול חיצוני לשנת 2026 | B17: 0.0035
A19: בתאריך 30.03.2026 אישר הדירקטוריון את השינוי הבא
A20: אפיק השקעה | B20: מדיניות קודמת | C20: שינוי החל מתאריך 30.03.26 | D20: שינוי ממדיניות קודמת | E20: טווח סטייה | F20: גבולות שיעור החשיפה המומלץ
A21: מניות (תעודות סל, קרנות נאמנות, חוזים אופציות ונגזרים) | B21: 0.44 | C21: 0.46 | D21: =C21-B21 -> 0.02 | E21: +/- 6% | F21: =C21+6% -> 0.52 | G21: - | H21: =IF(C21-6%<0%,0%,C21-6%) -> 0.4
A22: אג"ח ממשלתי (סחיר ולא סחיר, קרנות נאמנות, תעודות סל, חוזים ונגזרים) | B22: 0.19 | C22: 0.17 | D22: =C22-B22 -> -0.02 | E22: +/- 5% | F22: =C22+5% -> 0.22 | G22: - | H22: =IF(C22-5%<0%,0%,C22-5%) -> 0.12
A23: קרנות השקעה + קרנות גידור | B23: 0.21 | C23: 0.19 | D23: =C23-B23 -> -0.02 | E23: +/- 5% | F23: =C23+5% -> 0.24 | G23: - | H23: =IF(C23-5%<0%,0%,C23-5%) -> 0.14
A24: הלוואות לחברות + הלוואות עמיתים | B24: 0.03 | C24: 0.02 | D24: =C24-B24 -> -0.01 | E24: +/- 5% | F24: =C24+5% -> 0.07 | G24: - | H24: =IF(C24-5%<0%,0%,C24-5%) -> 0
A25: חשיפה למט"ח | B25: 0.19 | C25: 0.2 | D25: =C25-B25 -> 0.01 | E25: +/- 6% | F25: =C25+6% -> 0.26 | G25: - | H25: =IF(C25-6%<0%,0%,C25-6%) -> 0.14

Sheet הכשרה- קרן ט
A1: קרן ט'
A3: אפיק השקעה | B3: ='הכשרה - קרן י'!$B$3 -> שיעור חשיפה ליום 16/11/25 | C3: ='הכשרה - קרן י'!$C$3 -> מדיניות השקעות 2025 | D3: ='הכשרה - קרן י'!$D$3 -> שיעור חשיפה מומלץ לשנת 2026 | E3: טווח סטייה | F3: גבולות שיעור החשיפה המומלץ | I3: מדד ייחוס | J3: ='הכשרה - קרן י'!$J$3 -> שינוי ממדיניות 2025
A4: מניות (תעודות סל, קרנות נאמנות, חוזים אופציות ונגזרים) | B4: 0.4621 | C4: 0.41 | D4: 0.41 | E4: +/- 6% | F4: =D4+6% -> 0.47 | G4: - | H4: =IF(D4-6%<0%,0%,D4-6%) -> 0.35 | I4: 35% - ת"א 125 | J4: =D4-C4 -> 0
I5: 65% - MSCI World | J5: =D5-C5 -> 0
J6: =D6-C6 -> 0
A7: אג"ח ממשלתי | B7: 0.4163 | C7: 0.41 | D7: 0.41 | E7: +/- 5% | F7: =D7+5% -> 0.46 | G7: - | H7: =IF(D7-5%<0%,0%,D7-5%) -> 0.36 | I7: 50% מדד ממשלתי שקלי 2-5 | J7: =D7-C7 -> 0
A8: מתוך זה : | I8: 50% מדד ממשלתי צמוד 2-5 | J8: =D8-C8 -> 0
A9: ממשלתי סחיר | B9: =B7-B10 -> 0.1452 | C9: 0.1 | D9: 0.1 | E9: +/- 5% | F9: =D9+5% -> 0.15 | G9: - | H9: =IF(D9-5%<0%,0%,D9-5%) -> 0.05 | J9: =D9-C9 -> 0
A10: אג"ח מיועדות | B10: 0.2711 | C10: 0.31 | D10: 0.31 | E10: +/- 5% | F10: =D10+5% -> 0.36 | G10: - | H10: =IF(D10-5%<0%,0%,D10-5%) -> 0.26
A11: אג"ח קונצרני (סחיר ולא סחיר, קרנות נאמנות, תעודות סל, חוזים ונגזרים) | B11: 0.0617 | C11: 0.06 | D11: 0.06 | E11: +/- 6% | F11: =D11+6% -> 0.12 | G11: - | H11: =IF(D11-6%<0%,0%,D11-6%) -> 0 | I11: 80% תלבונד 60 | J11: =D11-C11 -> 0
I12: 20% Barclays Global Aggregate Index | J12: =D12-C12 -> 0
A13: נדל"ן | B13: 0.0008 | C13: 0.01 | D13: 0.01 | E13: +/- 5% | F13: =D13+5% -> 0.06 | G13: - | H13: =IF(D13-5%<0%,0%,D13-5%) -> 0 | I13: ממשלתי צמוד 5-10 | J13: =D13-C13 -> 0
A14: קרנות השקעה + קרנות גידור | B14: 0.0878 | C14: 0.1 | D14: 0.1 | E14: +/- 5% | F14: =D14+5% -> 0.15 | G14: - | H14: =IF(D14-5%<0%,0%,D14-5%) -> 0.05 | I14: מדד HFRI WORLD | J14: =D14-C14 -> 0
A15: הלוואות לחברות + הלוואות עמיתים | B15: 0 | C15: 0.02 | D15: 0.02 | E15: +/- 5% | F15: =D15+5% -> 0.07 | G15: - | H15: =IF(D15-5%<0%,0%,D15-5%) -> 0 | I15: ממשלתי לא צמוד 2-5 | J15: =D15-C15 -> 0
A16: אחר (מזומן, פקדונות, סחורות) | B16: 0.0622 | C16: 0.03 | D16: 0.06 | E16: +/- 5% | F16: =D16+5% -> 0.11 | G16: - | H16: =IF(D16-5%<0%,0%,D16-5%) -> 0.01 | I16: ריבית בנק ישראל | J16: =D16-C16 -> 0.03
A17: סה"כ | B17: =B16+B15+B14+B13+B11+B7+B4 -> 1.0909 | C17: =SUM(C4:C16)-C9-C10 -> 1.04 | D17: =SUM(D4:D16)-D9-D10 -> 1.07 | J17: =SUM(J4:J16) -> 0.03
A18: חשיפה למט"ח | B18: 0.1778 | C18: 0.22 | D18: 0.19 | E18: +/- 6% | F18: =D18+6% -> 0.25 | G18: - | H18: =IF(D18-6%<0%,0%,D18-6%) -> 0.13 | I18: 80% דולר 20% אירו | J18: =D18-C18 -> -0.03
A19: ='הכשרה - קרן י'!$A$17 -> מגבלת עמלת ניהול חיצוני לשנת 2026 | B19: 0.0025

Sheet הכשרה - כללי
A1: מסלול כללי
A3: אפיק השקעה | B3: ='הכשרה - קרן י'!$B$3 -> שיעור חשיפה ליום 16/11/25 | C3: ='הכשרה - קרן י'!$C$3 -> מדיניות השקעות 2025 | D3: ='הכשרה - קרן י'!$D$3 -> שיעור חשיפה מומלץ לשנת 2026 | E3: טווח סטייה | F3: גבולות שיעור החשיפה המומלץ | I3: מדד ייחוס | J3: ='הכשרה - קרן י'!$J$3 -> שינוי ממדיניות 2025
A4: מניות (תעודות סל, קרנות נאמנות, חוזים אופציות ונגזרים) | B4: 0.4954 | C4: 0.45 | D4: 0.45 | E4: +/- 6% | F4: =D4+6% -> 0.51 | G4: - | H4: =IF(D4-6%<0%,0%,D4-6%) -> 0.39 | I4: 35% - ת"א 125 | J4: =D4-C4 -> 0
I5: 65% - MSCI World | J5: =D5-C5 -> 0
J6: =D6-C6 -> 0
A7: אג"ח ממשלתי (סחיר ולא סחיר, קרנות נאמנות, תעודות סל, חוזים ונגזרים) | B7: 0.2319 | C7: 0.25 | D7: 0.24 | E7: +/- 5% | F7: =D7+5% -> 0.29 | G7: - | H7: =IF(D7-5%<0%,0%,D7-5%) -> 0.19 | I7: 50% מדד ממשלתי שקלי 2-5 | J7: =D7-C7 -> -0.01
I8: 50% מדד ממשלתי צמוד 2-5 | J8: =D8-C8 -> 0
A9: אג"ח קונצרני (סחיר ולא סחיר, קרנות נאמנות, תעודות סל, חוזים ונגזרים) | B9: 0.1218 | C9: 0.11 | D9: 0.11 | E9: +/- 6% | F9: =D9+6% -> 0.17 | G9: - | H9: =IF(D9-6%<0%,0%,D9-6%) -> 0.05 | I9: 80% תלבונד 60 | J9: =D9-C9 -> 0
I10: 20% Barclays Global Aggregate Index | J10: =D10-C10 -> 0
A11: נדל"ן | B11: 0.0484 | C11: 0.05 | D11: 0.05 | E11: +/- 5% | F11: =D11+5% -> 0.1 | G11: - | H11: =IF(D11-5%<0%,0%,D11-5%) -> 0 | I11: ממשלתי צמוד 5-10 | J11: =D11-C11 -> 0
A12: קרנות השקעה + קרנות גידור | B12: 0.1683 | C12: 0.16 | D12: 0.16 | E12: +/- 5% | F12: =D12+5% -> 0.21 | G12: - | H12: =IF(D12-5%<0%,0%,D12-5%) -> 0.11 | I12: מדד HFRI WORLD | J12: =D12-C12 -> 0
A13: הלוואות לחברות + הלוואות עמיתים | B13: 0.0147 | C13: 0.03 | D13: 0.03 | E13: +/- 5% | F13: =D13+5% -> 0.08 | G13: - | H13: =IF(D13-5%<0%,0%,D13-5%) -> 0 | I13: ממשלתי לא צמוד 2-5 | J13: =D13-C13 -> 0
A14: אחר (מזומן, פקדונות, סחורות) | B14: 0.0854 | C14: 0.07 | D14: 0.08 | E14: +/- 5% | F14: =D14+5% -> 0.13 | G14: - | H14: =IF(D14-5%<0%,0%,D14-5%) -> 0.03 | I14: ריבית בנק ישראל | J14: =D14-C14 -> 0.01
A15: סה"כ | B15: =SUM(B4:B14) -> 1.1659 | C15: =SUM(C4:C14) -> 1.12 | D15: =SUM(D4:D14) -> 1.12 | J15: =D15-C15 -> 0
A16: חשיפה למט"ח | B16: 0.1835 | C16: 0.22 | D16: 0.18 | E16: +/- 6% | F16: =D16+6% -> 0.24 | G16: - | H16: =IF(D16-6%<0%,0%,D16-6%) -> 0.12 | I16: 80% דולר 20% אירו | J16: =D16-C16 -> -0.04
A17: ='הכשרה - קרן י'!$A$17 -> מגבלת עמלת ניהול חיצוני לשנת 2026 | B17: 0.0028
A19: בתאריך 30.03.2026 אישר הדירקטוריון את השינוי הבא
A20: אפיק השקעה | B20: מדיניות קודמת | C20: שינוי החל מתאריך 30.03.26 | D20: שינוי ממדיניות קודמת | E20: טווח סטייה | F20: גבולות שיעור החשיפה המומלץ
A21: מניות (תעודות סל, קרנות נאמנות, חוזים אופציות ונגזרים) | B21: 0.45 | C21: 0.48 | D21: =C21-B21 -> 0.03 | E21: +/- 6% | F21: =C21+6% -> 0.54 | G21: - | H21: =IF(C21-6%<0%,0%,C21-6%) -> 0.42
A22: קרנות השקעה + קרנות גידור | B22: 0.16 | C22: 0.14 | D22: =C22-B22 -> -0.02 | E22: +/- 5% | F22: =C22+5% -> 0.19 | G22: - | H22: =IF(C22-5%<0%,0%,C22-5%) -> 0.09
A23: חשיפה למט"ח | B23: 0.18 | C23: 0.19 | D23: =C23-B23 -> 0.01 | E23: +/- 6% | F23: =C23+6% -> 0.25 | G23: - | H23: =IF(C23-6%<0%,0%,C23-6%) -> 0.13

Sheet הכשרה - מסלול לבני 50 ומטה
A1: הכשרה לבני 50 ומטה
A3: אפיק השקעה | B3: ='הכשרה - קרן י'!$B$3 -> שיעור חשיפה ליום 16/11/25 | C3: ='הכשרה - קרן י'!$C$3 -> מדיניות השקעות 2025 | D3: ='הכשרה - קרן י'!$D$3 -> שיעור חשיפה מומלץ לשנת 2026 | E3: טווח סטייה | F3: גבולות שיעור החשיפה המומלץ | I3: מדד ייחוס | J3: ='הכשרה - קרן י'!$J$3 -> שינוי ממדיניות 2025
A4: מניות (תעודות סל, קרנות נאמנות, חוזים אופציות ונגזרים) | B4: 0.5698 | C4: 0.52 | D4: 0.53 | E4: +/- 6% | F4: =D4+6% -> 0.59 | G4: - | H4: =IF(D4-6%<0%,0%,D4-6%) -> 0.47 | I4: 35% - ת"א 125 | J4: =D4-C4 -> 0.01
I5: 65% - MSCI World | J5: =D5-C5 -> 0
J6: =D6-C6 -> 0
A7: אג"ח ממשלתי (סחיר ולא סחיר, קרנות נאמנות, תעודות סל, חוזים ונגזרים) | B7: 0.1585 | C7: 0.18 | D7: 0.17 | E7: +/- 5% | F7: =D7+5% -> 0.22 | G7: - | H7: =IF(D7-5%<0%,0%,D7-5%) -> 0.12 | I7: 50% מדד ממשלתי שקלי 2-5 | J7: =D7-C7 -> -0.01
I8: 50% מדד ממשלתי צמוד 2-5 | J8: =D8-C8 -> 0
A9: אג"ח קונצרני (סחיר ולא סחיר, קרנות נאמנות, תעודות סל, חוזים ונגזרים) | B9: 0.0981 | C9: 0.1 | D9: 0.09 | E9: +/- 6% | F9: =D9+6% -> 0.15 | G9: - | H9: =IF(D9-6%<0%,0%,D9-6%) -> 0.03 | I9: 80% תלבונד 60 | J9: =D9-C9 -> -0.01
I10: 20% Barclays Global Aggregate Index | J10: =D10-C10 -> 0
A11: נדל"ן | B11: 0.0128 | C11: 0.04 | D11: 0.04 | E11: +/- 5% | F11: =D11+5% -> 0.09 | G11: - | H11: =IF(D11-5%<0%,0%,D11-5%) -> 0 | I11: ממשלתי צמוד 5-10 | J11: =D11-C11 -> 0
A12: קרנות השקעה + קרנות גידור | B12: 0.2377 | C12: 0.22 | D12: 0.22 | E12: +/- 5% | F12: =D12+5% -> 0.27 | G12: - | H12: =IF(D12-5%<0%,0%,D12-5%) -> 0.17 | I12: מדד HFRI WORLD | J12: =D12-C12 -> 0
A13: הלוואות לחברות + הלוואות עמיתים | B13: 0.0047 | C13: 0.03 | D13: 0.03 | E13: +/- 5% | F13: =D13+5% -> 0.08 | G13: - | H13: =IF(D13-5%<0%,0%,D13-5%) -> 0 | I13: ממשלתי לא צמוד 2-5 | J13: =D13-C13 -> 0
A14: אחר (מזומן, פקדונות, סחורות) | B14: 0.0788 | C14: 0.05 | D14: 0.06 | E14: +/- 5% | F14: =D14+5% -> 0.11 | G14: - | H14: =IF(D14-5%<0%,0%,D14-5%) -> 0.01 | I14: ריבית בנק ישראל | J14: =D14-C14 -> 0.01
A15: סה"כ | B15: =SUM(B4:B14) -> 1.1604 | C15: =SUM(C4:C14) -> 1.14 | D15: =SUM(D4:D14) -> 1.14 | J15: =SUM(J4:J14) -> 1.3877788e-17
A16: חשיפה למט"ח | B16: 0.2409 | C16: 0.23 | D16: 0.21 | E16: +/- 6% | F16: =D16+6% -> 0.27 | G16: - | H16: =IF(D16-6%<0%,0%,D16-6%) -> 0.15 | I16: 80% דולר 20% אירו | J16: =D16-C16 -> -0.02
A17: ='הכשרה - קרן י'!$A$17 -> מגבלת עמלת ניהול חיצוני לשנת 2026 | B17: 0.0033

Sheet הכשרה - מסלול לבני 50 עד 60
A1: הכשרה לבני 50-60
A3: אפיק השקעה | B3: ='הכשרה - קרן י'!$B$3 -> שיעור חשיפה ליום 16/11/25 | C3: ='הכשרה - קרן י'!$C$3 -> מדיניות השקעות 2025 | D3: ='הכשרה - קרן י'!$D$3 -> שיעור חשיפה מומלץ לשנת 2026 | E3: טווח סטייה | F3: גבולות שיעור החשיפה המומלץ | I3: מדד ייחוס | J3: ='הכשרה - קרן י'!$J$3 -> שינוי ממדיניות 2025
A4: מניות (תעודות סל, קרנות נאמנות, חוזים אופציות ונגזרים) | B4: 0.4695 | C4: 0.42 | D4: 0.42 | E4: +/- 6% | F4: =D4+6% -> 0.48 | G4: - | H4: =IF(D4-6%<0%,0%,D4-6%) -> 0.36 | I4: 35% - ת"א 125 | J4: =D4-C4 -> 0
I5: 65% - MSCI World | J5: =D5-C5 -> 0
J6: =D6-C6 -> 0
A7: אג"ח ממשלתי (סחיר ולא סחיר, קרנות נאמנות, תעודות סל, חוזים ונגזרים) | B7: 0.2546 | C7: 0.25 | D7: 0.25 | E7: +/- 5% | F7: =D7+5% -> 0.3 | G7: - | H7: =IF(D7-5%<0%,0%,D7-5%) -> 0.2 | I7: 50% מדד ממשלתי שקלי 2-5 | J7: =D7-C7 -> 0
I8: 50% מדד ממשלתי צמוד 2-5 | J8: =D8-C8 -> 0
A9: אג"ח קונצרני (סחיר ולא סחיר, קרנות נאמנות, תעודות סל, חוזים ונגזרים) | B9: 0.1679 | C9: 0.14 | D9: 0.14 | E9: +/- 6% | F9: =D9+6% -> 0.2 | G9: - | H9: =IF(D9-6%<0%,0%,D9-6%) -> 0.08 | I9: 80% תלבונד 60 | J9: =D9-C9 -> 0
I10: 20% Barclays Global Aggregate Index | J10: =D10-C10 -> 0
A11: נדל"ן | B11: 0.0059 | C11: 0.04 | D11: 0.04 | E11: +/- 5% | F11: =D11+5% -> 0.09 | G11: - | H11: =IF(D11-5%<0%,0%,D11-5%) -> 0 | I11: ממשלתי צמוד 5-10 | J11: =D11-C11 -> 0
A12: קרנות השקעה + קרנות גידור | B12: 0.116 | C12: 0.12 | D12: 0.12 | E12: +/- 5% | F12: =D12+5% -> 0.17 | G12: - | H12: =IF(D12-5%<0%,0%,D12-5%) -> 0.07 | I12: מדד HFRI WORLD | J12: =D12-C12 -> 0
A13: הלוואות לחברות + הלוואות עמיתים | B13: 0.0021 | C13: 0.03 | D13: 0.03 | E13: +/- 5% | F13: =D13+5% -> 0.08 | G13: - | H13: =IF(D13-5%<0%,0%,D13-5%) -> 0 | I13: ממשלתי לא צמוד 2-5 | J13: =D13-C13 -> 0
A14: אחר (מזומן, פקדונות, סחורות) | B14: 0.0774 | C14: 0.05 | D14: 0.07 | E14: +/- 5% | F14: =D14+5% -> 0.12 | G14: - | H14: =IF(D14-5%<0%,0%,D14-5%) -> 0.02 | I14: ריבית בנק ישראל | J14: =D14-C14 -> 0.02
A15: סה"כ | B15: =SUM(B4:B14) -> 1.0934 | C15: =SUM(C4:C14) -> 1.05 | D15: =SUM(D4:D14) -> 1.07 | J15: =SUM(J4:J14) -> 0.02
A16: חשיפה למט"ח | B16: 0.1971 | C16: 0.21 | D16: 0.19 | E16: +/- 6% | F16: =D16+6% -> 0.25 | G16: - | H16: =IF(D16-6%<0%,0%,D16-6%) -> 0.13 | I16: 80% דולר 20% אירו | J16: =D16-C16 -> -0.02
A17: ='הכשרה - קרן י'!$A$17 -> מגבלת עמלת ניהול חיצוני לשנת 2026 | B17: 0.0025

Sheet הכשרה - מסלול לבני 60 ומעלה
A1: הכשרה לבני 60 ומעלה
A3: אפיק השקעה | B3: ='הכשרה - קרן י'!$B$3 -> שיעור חשיפה ליום 16/11/25 | C3: ='הכשרה - קרן י'!$C$3 -> מדיניות השקעות 2025 | D3: ='הכשרה - קרן י'!$D$3 -> שיעור חשיפה מומלץ לשנת 2026 | E3: טווח סטייה | F3: גבולות שיעור החשיפה המומלץ | I3: מדד ייחוס | J3: ='הכשרה - קרן י'!$J$3 -> שינוי ממדיניות 2025
A4: מניות (תעודות סל, קרנות נאמנות, חוזים אופציות ונגזרים) | B4: 0.3112 | C4: 0.26 | D4: 0.26 | E4: +/- 6% | F4: =D4+6% -> 0.32 | G4: - | H4: =IF(D4-6%<0%,0%,D4-6%) -> 0.2 | I4: 35% - ת"א 125 | J4: =D4-C4 -> 0
I5: 65% - MSCI World
A7: אג"ח ממשלתי (סחיר ולא סחיר, קרנות נאמנות, תעודות סל, חוזים ונגזרים) | B7: 0.3585 | C7: 0.33 | D7: 0.33 | E7: +/- 5% | F7: =D7+5% -> 0.38 | G7: - | H7: =IF(D7-5%<0%,0%,D7-5%) -> 0.28 | I7: 50% מדד ממשלתי שקלי 2-5 | J7: =D7-C7 -> 0
I8: 50% מדד ממשלתי צמוד 2-5
A9: אג"ח קונצרני (סחיר ולא סחיר, קרנות נאמנות, תעודות סל, חוזים ונגזרים) | B9: 0.2102 | C9: 0.19 | D9: 0.19 | E9: +/- 6% | F9: =D9+6% -> 0.25 | G9: - | H9: =IF(D9-6%<0%,0%,D9-6%) -> 0.13 | I9: 80% תלבונד 60 | J9: =D9-C9 -> 0
I10: 20% Barclays Global Aggregate Index
A11: נדל"ן | B11: 0.0052 | C11: 0.04 | D11: 0.04 | E11: +/- 5% | F11: =D11+5% -> 0.09 | G11: - | H11: =IF(D11-5%<0%,0%,D11-5%) -> 0 | I11: ממשלתי צמוד 5-10 | J11: =D11-C11 -> 0
A12: קרנות השקעה + קרנות גידור | B12: 0.1058 | C12: 0.1 | D12: 0.1 | E12: +/- 5% | F12: =D12+5% -> 0.15 | G12: - | H12: =IF(D12-5%<0%,0%,D12-5%) -> 0.05 | I12: מדד HFRI WORLD | J12: =D12-C12 -> 0
A13: הלוואות לחברות + הלוואות עמיתים | B13: 0.0034 | C13: 0.02 | D13: 0.02 | E13: +/- 5% | F13: =D13+5% -> 0.07 | G13: - | H13: =IF(D13-5%<0%,0%,D13-5%) -> 0 | I13: ממשלתי לא צמוד 2-5 | J13: =D13-C13 -> 0
A14: אחר (מזומן, פקדונות, סחורות) | B14: 0.044 | C14: 0.06 | D14: 0.06 | E14: +/- 5% | F14: =D14+5% -> 0.11 | G14: - | H14: =IF(D14-5%<0%,0%,D14-5%) -> 0.01 | I14: ריבית בנק ישראל | J14: =D14-C14 -> 0
A15: סה"כ | B15: =SUM(B4:B14) -> 1.0383 | C15: =SUM(C4:C14) -> 1 | D15: =SUM(D4:D14) -> 1 | J15: =D15-C15 -> 0
A16: חשיפה למט"ח | B16: 0.1529 | C16: 0.19 | D16: 0.15 | E16: +/- 6% | F16: =D16+6% -> 0.21 | G16: - | H16: =IF(D16-6%<0%,0%,D16-6%) -> 0.09 | I16: 80% דולר 20% אירו | J16: =D16-C16 -> -0.04
A17: ='הכשרה - קרן י'!$A$17 -> מגבלת עמלת ניהול חיצוני לשנת 2026 | B17: 0.0025

Sheet הכשרה - מסלול בסיסי למקבלי קצבה
A1: הכשרה למקבלי קצבה
A3: אפיק השקעה | B3: ='הכשרה - קרן י'!$B$3 -> שיעור חשיפה ליום 16/11/25 | C3: ='הכשרה - קרן י'!$C$3 -> מדיניות השקעות 2025 | D3: ='הכשרה - קרן י'!$D$3 -> שיעור חשיפה מומלץ לשנת 2026 | E3: טווח סטייה | F3: גבולות שיעור החשיפה המומלץ | I3: מדד ייחוס | J3: ='הכשרה - קרן י'!$J$3 -> שינוי ממדיניות 2025
A4: מניות (תעודות סל, קרנות נאמנות, חוזים אופציות ונגזרים) | B4: 0.2816 | C4: 0.26 | D4: 0.26 | E4: +/- 6% | F4: =D4+6% -> 0.32 | G4: - | H4: =IF(D4-6%<0%,0%,D4-6%) -> 0.2 | I4: 35% - ת"א 125 | J4: =D4-C4 -> 0
I5: 65% - MSCI World
A7: אג"ח ממשלתי (סחיר ולא סחיר, קרנות נאמנות, תעודות סל, חוזים ונגזרים) | B7: 0.3882 | C7: 0.35 | D7: 0.36 | E7: +/- 5% | F7: =D7+5% -> 0.41 | G7: - | H7: =IF(D7-5%<0%,0%,D7-5%) -> 0.31 | I7: 50% מדד ממשלתי שקלי 2-5 | J7: =D7-C7 -> 0.01
I8: 50% מדד ממשלתי צמוד 2-5
A9: אג"ח קונצרני (סחיר ולא סחיר, קרנות נאמנות, תעודות סל, חוזים ונגזרים) | B9: 0.1839 | C9: 0.2 | D9: 0.2 | E9: +/- 6% | F9: =D9+6% -> 0.26 | G9: - | H9: =IF(D9-6%<0%,0%,D9-6%) -> 0.14 | I9: 80% תלבונד 60 | J9: =D9-C9 -> 0
I10: 20% Barclays Global Aggregate Index
A11: נדל"ן | B11: 0.0083 | C11: 0.05 | D11: 0.02 | E11: +/- 5% | F11: =D11+5% -> 0.07 | G11: - | H11: =IF(D11-5%<0%,0%,D11-5%) -> 0 | I11: ממשלתי צמוד 5-10 | J11: =D11-C11 -> -0.03
A12: קרנות השקעה + קרנות גידור | B12: 0.1031 | C12: 0.13 | D12: 0.12 | E12: +/- 5% | F12: =D12+5% -> 0.17 | G12: - | H12: =IF(D12-5%<0%,0%,D12-5%) -> 0.07 | I12: מדד HFRI WORLD | J12: =D12-C12 -> -0.01
A13: הלוואות לחברות + הלוואות עמיתים | B13: 0.0028 | C13: 0.02 | D13: 0.02 | E13: +/- 5% | F13: =D13+5% -> 0.07 | G13: - | H13: =IF(D13-5%<0%,0%,D13-5%) -> 0 | I13: ממשלתי לא צמוד 2-5 | J13: =D13-C13 -> 0
A14: אחר (מזומן, פקדונות, סחורות) | B14: 0.0942 | C14: 0.05 | D14: 0.08 | E14: +/- 5% | F14: =D14+5% -> 0.13 | G14: - | H14: =IF(D14-5%<0%,0%,D14-5%) -> 0.03 | I14: ריבית בנק ישראל | J14: =D14-C14 -> 0.03
A15: סה"כ | B15: =SUM(B4:B14) -> 1.0621 | C15: =SUM(C4:C14) -> 1.06 | D15: =SUM(D4:D14) -> 1.06 | J15: =SUM(J4:J14) -> 0
A16: חשיפה למט"ח | B16: 0.1322 | C16: 0.19 | D16: 0.14 | E16: +/- 6% | F16: =D16+6% -> 0.2 | G16: - | H16: =IF(D16-6%<0%,0%,D16-6%) -> 0.08 | I16: 80% דולר 20% אירו | J16: =D16-C16 -> -0.05
A17: ='הכשרה - קרן י'!$A$17 -> מגבלת עמלת ניהול חיצוני לשנת 2026 | B17: 0.0025

Sheet הכשרה - כספי (שקלי)
A1: הכשרה כספי (שקלי)
A3: אפיק השקעה | B3: ='הכשרה - קרן י'!$B$3 -> שיעור חשיפה ליום 16/11/25 | C3: ='הכשרה - קרן י'!$C$3 -> מדיניות השקעות 2025 | D3: ='הכשרה - קרן י'!$D$3 -> שיעור חשיפה מומלץ לשנת 2026 | E3: טווח סטייה | F3: גבולות שיעור החשיפה המומלץ | I3: מדד ייחוס | J3: ='הכשרה - קרן י'!$J$3 -> שינוי ממדיניות 2025
A4: ממשלתי שקלי (מק"מ, ממשלתי שקלי, פקדונות) | B4: 0.9718 | C4: 0.95 | D4: 0.95 | E4: +/- 5% | F4: =D4+5% -> 1 | G4: - | H4: =IF(D4-5%<0%,0%,D4-5%) -> 0.9 | I4: ממשלתי לא צמוד 2-5 | J4: =D4-C4 -> 0
A5: אחר (מזומן, הלוואות עמיתים, קונצרני, ממשלתי צמוד מדד) | B5: 0.0282 | C5: 0.05 | D5: 0.05 | E5: +/- 5% | F5: =D5+5% -> 0.1 | G5: - | H5: =IF(D5-5%<0%,0%,D5-5%) -> 0 | I5: ריבית בנק ישראל | J5: =D5-C5 -> 0
A6: סה"כ | B6: =SUM(B4:B5) -> 1 | C6: =SUM(C4:C5) -> 1 | D6: =SUM(D4:D5) -> 1 | J6: =SUM(J4:J5) -> 0
A7: חשיפה למט"ח | B7: 0 | C7: 0 | D7: 0 | E7: ללא חשיפת מט"ח
A8: ='הכשרה - קרן י'!$A$17 -> מגבלת עמלת ניהול חיצוני לשנת 2026 | B8: 0.0005
A10: נכסי המסלול יהיו חשופים לנכסים הבאים אשר אינם צמודים ואינם חשופים לסיכוני מטבע (פרט למטבע השקל החדש): פיקדונות שקליים, מלוות ממשלתיות נקובות בש"ח, הלוואות שקליות ואג"ח שקליות (סחירות ושאינן סחירות),
A11: בשיעור שלא יפחת מ-75% ולא יעלה על 120% מנכסי המסלול. חשיפה לנכסים כאמור תושג באמצעות השקעה במישרין, בנגזרים (לרבות חוזים עתידיים, אופציות וכתבי אופציות), בקרנות סל ובקרנות נאמנות.
A12: יתרת הנכסים תושקע בכפוף להוראות הדין ובתנאי ששיעור החשיפה הכולל במסלול לא יעלה על 120% מנכסי המסלול.
A14: בתאריך 26.08.26 אישר הדירקטוריון את השינוי הבא
A15: אפיק השקעה | B15: מדיניות קודמת | C15: שינוי החל מתאריך 26.08.26 | D15: שינוי ממדיניות קודמת | E15: טווח סטייה | F15: גבולות שיעור החשיפה המומלץ
A16: ממשלתי שקלי (מק"מ, ממשלתי שקלי, פקדונות) | B16: 0.95 | C16: 0.85 | D16: =C16-B16 -> -0.1 | E16: +/- 5% | F16: =C16+5% -> 0.9 | G16: - | H16: =IF(C16-5%<0%,0%,C16-5%) -> 0.8
A17: אחר (מזומן, הלוואות עמיתים, קונצרני, ממשלתי צמוד מדד) | B17: 0.05 | C17: 0.15 | D17: =C17-B17 -> 0.1 | E17: +/- 5% | F17: =C17+5% -> 0.2 | G17: - | H17: =IF(C17-5%<0%,0%,C17-5%) -> 0.1

Sheet הכשרה - עוקב מדדים גמיש
A1: מסלול עוקב מדדים גמיש
A3: אפיק השקעה | B3: ='הכשרה - קרן י'!$B$3 -> שיעור חשיפה ליום 16/11/25 | C3: ='הכשרה - קרן י'!$C$3 -> מדיניות השקעות 2025 | D3: ='הכשרה - קרן י'!$D$3 -> שיעור חשיפה מומלץ לשנת 2026 | E3: טווח סטייה | F3: גבולות שיעור החשיפה המומלץ | I3: מדד ייחוס | J3: ='הכשרה - קרן י'!$J$3 -> שינוי ממדיניות 2025
A4: מניות (סחיר) | B4: 0.338 | C4: 0.3 | D4: 0.3 | E4: +/- 6% | F4: =D4+6% -> 0.36 | G4: - | H4: =IF(D4-6%<0%,0%,D4-6%) -> 0.24 | I4: 35% - ת"א 125 | J4: =D4-C4 -> 0
I5: 65% - MSCI World
A7: אג"ח ממשלתי (סחיר בארץ ובחו"ל) | B7: 0.3455 | C7: 0.35 | D7: 0.35 | E7: +/- 5% | F7: =D7+5% -> 0.4 | G7: - | H7: =IF(D7-5%<0%,0%,D7-5%) -> 0.3 | I7: 50% מדד ממשלתי שקלי 2-5 | J7: =D7-C7 -> 0
I8: 50% מדד ממשלתי צמוד 2-5
A9: אג"ח קונצרני (סחיר בארץ ובחו"ל) | B9: 0.2511 | C9: 0.25 | D9: 0.25 | E9: +/- 6% | F9: =D9+6% -> 0.31 | G9: - | H9: =IF(D9-6%<0%,0%,D9-6%) -> 0.19 | I9: 80% תלבונד 60 | J9: =D9-C9 -> 0
I10: 20% Barclays Global Aggregate Index
A11: אחר (מזומן, פקדונות, סחורות) | B11: 0.065 | C11: 0.1 | D11: 0.1 | E11: +/- 5% | F11: =D11+5% -> 0.15 | G11: - | H11: =IF(D11-5%<0%,0%,D11-5%) -> 0.05 | I11: ריבית בנק ישראל | J11: =D11-C11 -> 0
A12: סה"כ | B12: =SUM(B4:B11) -> 0.9996 | C12: =SUM(C4:C11) -> 1 | D12: =SUM(D4:D11) -> 1 | J12: =SUM(J4:J11) -> 0
A13: חשיפה למט"ח | B13: 0.1446 | C13: 0.15 | D13: 0.14 | E13: +/- 6% | F13: =D13+6% -> 0.2 | G13: - | H13: =IF(D13-6%<0%,0%,D13-6%) -> 0.08 | I13: 80% דולר 20% אירו | J13: =D13-C13 -> -0.01
A14: ='הכשרה - קרן י'!$A$17 -> מגבלת עמלת ניהול חיצוני לשנת 2026 | B14: 0.0015
A16: נכסי המסלול יעקבו באמצעות מכשירים עוקבי מדד ובשיעור שלא יפחת מ-75% ולא יעלה על 100%, אחר מדדי מניות או מדדי אג"ח קונצרני או מדדי אג"ח ממשלות, או שילוב ביניהם, ולכל הפחות אחר שלושה מדדים כאמור שאינם דומים.
A17: שיעור המעקב אחר כל אחד משלושת המדדים, ששיעורם מסך נכסי המסלול הוא הגדול ביותר, לא יפחת מ-10% ולא יעלה על 50% מנכסי המסלול.
A18: יתרת נכסי המסלול יעקבו אחר מדדים שונים, למעט שיעור מהנכסים שיושקע באופן הבא:
A19: א. בנגזרים המשמשים לצרכי גידור;
A20: ב. לצורך הפקדות, משיכות והעברות כספים או טיפול בביטחונות בגין נגזרים, באחד או יותר מן הבאים:
A21: 1) מזומנים;
A22: 2) מק"מ;
A23: 3) פיקדונות שהופקדו לתקופה שאינה עולה על 12 חודשים ממועד הפקדתם;
A24: 4) באג"ח של מדינת ישראל שמועד פירעונן אינו עולה על 12 חודשים;
A25: 5) באג"ח של מדינת חוץ מאושרת שמועד פירעונן אינו עולה על 12 חודשים, ובלבד שהאג"ח והנגזר נרכשו באותה מדינת חוץ מאושרת;
A26: 6) קרן כספית שהגדרתה בתקנות השקעות משותפות בנאמנות (נכסים שמותר לקנות ולהחזיק בקרן ושיעוריהם המרביים), התשנ"ה-1994.
A27: המעקב אחר המדדים כאמור יהיה בכפוף להוראות הדין ועשוי להיות חשוף לסיכוני מטבע.

Sheet הכשרה - משולב סחיר
A1: מסלול משולב סחיר - 100% ישראל
A3: אפיק השקעה | B3: ='הכשרה - קרן י'!$B$3 -> שיעור חשיפה ליום 16/11/25 | C3: ='הכשרה - קרן י'!$C$3 -> מדיניות השקעות 2025 | D3: ='הכשרה - קרן י'!$D$3 -> שיעור חשיפה מומלץ לשנת 2026 | E3: טווח סטייה | F3: גבולות שיעור החשיפה המומלץ | I3: מדד ייחוס | J3: ='הכשרה - קרן י'!$J$3 -> שינוי ממדיניות 2025
A4: מניות (סחיר בארץ) | B4: 0.4508 | C4: 0.44 | D4: 0.44 | E4: +/- 6% | F4: =D4+6% -> 0.5 | G4: - | H4: =IF(D4-6%<0%,0%,D4-6%) -> 0.38 | J4: =D4-C4 -> 0
I5: ת"א 125
A7: אג"ח ממשלתי (סחיר בארץ) | B7: 0.1033 | C7: 0.11 | D7: 0.11 | E7: +/- 5% | F7: =D7+5% -> 0.16 | G7: - | H7: =IF(D7-5%<0%,0%,D7-5%) -> 0.06 | I7: 50% מדד ממשלתי שקלי 2-5 | J7: =D7-C7 -> 0
I8: 50% מדד ממשלתי צמוד 2-5
A9: אג"ח קונצרני (סחיר בארץ) | B9: 0.3588 | C9: 0.41 | D9: 0.38 | E9: +/- 6% | F9: =D9+6% -> 0.44 | G9: - | H9: =IF(D9-6%<0%,0%,D9-6%) -> 0.32 | I9: תל בונד 60 | J9: =D9-C9 -> -0.03
A11: אחר (מזומן, פקדונות, סחורות) | B11: 0.0871 | C11: 0.08 | D11: 0.1 | E11: +/- 5% | F11: =D11+5% -> 0.15 | G11: - | H11: =IF(D11-5%<0%,0%,D11-5%) -> 0.05 | I11: ריבית בנק ישראל | J11: =D11-C11 -> 0.02
A12: סה"כ | B12: =SUM(B4:B11) -> 1 | C12: =SUM(C4:C11) -> 1.04 | D12: =SUM(D4:D11) -> 1.03 | J12: =SUM(J4:J11) -> -0.01
A13: חשיפה למט"ח | B13: 0.0002 | C13: 0.02 | D13: 0.01 | E13: +/- 6% | F13: =D13+6% -> 0.07 | G13: - | H13: =IF(D13-6%<0%,0%,D13-6%) -> 0 | I13: 80% דולר 20% אירו | J13: =D13-C13 -> -0.01
A14: ='הכשרה - קרן י'!$A$17 -> מגבלת עמלת ניהול חיצוני לשנת 2026 | B14: 0.001
A16: נכסי המסלול יהיו חשופים לתמהיל של מניות, אג"ח קונצרני ואג"ח ממשלתי, בארץ ובחו"ל, בשיעור חשיפה שלא יפחת מ-75% ולא יעלה על 120% מנכסי המסלול. חשיפה לנכסים כאמור תושג באמצעות השקעה בנכסים סחירים בלבד.
A17: ההשקעה עשויה להתבצע הן במישרין (בנכסי בסיס) והן באמצעות השקעה בנגזרים (לרבות חוזים עתידיים, אופציות וכתבי אופציות ולרבות נגזרים לא סחירים אשר משמשים לצרכי גידור ונגזרים לא סחירים אשר שווים נגזר מנכס בסיס סחיר), בקרנות סל ובקרנות נאמנות.
A18: יתרת הנכסים תושקע במזומנים ופיקדונות שהופקדו לתקופה שאינה עולה על 3 חודשים ממועד הפקדתם. השקעה במסלול זה עשויה להיות חשופה לסיכוני מטבע.

Sheet הכשרה אשראי ואג"ח
A1: מסלול אשראי ואג"ח בניהול הכשרה חברה לביטוח
A3: אפיק השקעה | B3: ='הכשרה - קרן י'!$B$3 -> שיעור חשיפה ליום 16/11/25 | C3: ='הכשרה - קרן י'!$C$3 -> מדיניות השקעות 2025 | D3: ='הכשרה - קרן י'!$D$3 -> שיעור חשיפה מומלץ לשנת 2026 | E3: טווח סטייה | F3: גבולות שיעור החשיפה המומלץ | I3: מדד ייחוס | J3: ='הכשרה - קרן י'!$J$3 -> שינוי ממדיניות 2025
A4: מניות (תעודות סל, חוזים, אופציות ונגזרים) | B4: 0.0578 | C4: 0.01 | D4: 0.02 | E4: +/- 6% | F4: =D4+6% -> 0.08 | G4: - | H4: =IF(D4-6%<0%,0%,D4-6%) -> 0 | I4: 35% - ת"א 125 | J4: =D4-C4 -> 0.01
I5: 65% - MSCI World
A7: אג"ח ממשלתי (סחיר ולא סחיר, תעודות סל, חוזים ונגזרים) | B7: 0.202 | C7: 0.25 | D7: 0.23 | E7: +/- 5% | F7: =D7+5% -> 0.28 | G7: - | H7: =IF(D7-5%<0%,0%,D7-5%) -> 0.18 | I7: 50% מדד ממשלתי שקלי 2-5 | J7: =D7-C7 -> -0.02
I8: 50% מדד ממשלתי צמוד 2-5
A9: אג"ח קונצרני (סחיר ולא סחיר, תעודות סל, חוזים ונגזרים) | B9: 0.203 | C9: 0.25 | D9: 0.23 | E9: +/- 6% | F9: =D9+6% -> 0.29 | G9: - | H9: =IF(D9-6%<0%,0%,D9-6%) -> 0.17 | I9: 80% תלבונד 60 | J9: =D9-C9 -> -0.02
I10: 20% Barclays Global Aggregate Index
A11: קרנות השקעה + קרנות גידור+קרנות נאמנות מתמחות חוב | B11: 0.5452 | C11: 0.55 | D11: 0.52 | E11: +/- 5% | F11: =D11+5% -> 0.57 | G11: - | H11: =IF(D11-5%<0%,0%,D11-5%) -> 0.47 | I11: מדד HFRI WORLD | J11: =D11-C11 -> -0.03
A12: הלוואות לחברות | B12: 0.00226536 | C12: 0.01 | D12: 0.01 | E12: +/- 5% | F12: =D12+5% -> 0.06 | G12: - | H12: =IF(D12-5%<0%,0%,D12-5%) -> 0 | I12: ממשלתי לא צמוד 2-5 | J12: =D12-C12 -> 0
A13: אחר (מזומן, פקדונות, סחורות, נדל"ן) | B13: 0.0282 | C13: 0.05 | D13: 0.09 | E13: +/- 5% | F13: =D13+5% -> 0.14 | G13: - | H13: =IF(D13-5%<0%,0%,D13-5%) -> 0.04 | I13: ריבית בנק ישראל | J13: =D13-C13 -> 0.04
A14: סה"כ | B14: =SUM(B4:B13) -> 1.0384654 | C14: =SUM(C4:C13) -> 1.12 | D14: =SUM(D4:D13) -> 1.1 | J14: =SUM(J4:J13) -> -0.02
A15: חשיפה למט"ח | B15: 0.0518 | C15: 0.1 | D15: 0.07 | E15: +/- 6% | F15: =D15+6% -> 0.13 | G15: - | H15: =IF(D15-6%<0%,0%,D15-6%) -> 0.01 | I15: 80% דולר 20% אירו | J15: =D15-C15 -> -0.03
A16: ='הכשרה - קרן י'!$A$17 -> מגבלת עמלת ניהול חיצוני לשנת 2026 | B16: 0.005
A18: נכסי המסלול יהיו חשופים לנכסים הבאים בארץ ובחו"ל: פיקדונות, אג"ח סחירות ושאינן סחירות לרבות אג"ח הכוללות רכיב המרה, וני"ע מסחריים, שהנפיקו תאגידים או ממשלות, הלוואות שאינן סחירות שהועמדו לתאגידים ולפרטיים,
A19: קרנות השקעה וקרנות סל אשר מירב נכסיהן מושקעים באפיקי חוב, בשיעור חשיפה שלא יפחת מ-75% ולא יעלה על 120% מנכסי המסלול.
A20: חשיפה לנכסים כאמור תושג באמצעות השקעה במישרין והן באמצעות השקעה בנגזרים (לרבות חוזים עתידיים, אופציות וכתבי אופציות), בקרנות סל, בקרנות נאמנות ובקרנות השקעה המתמחות בחוב.
A21: החל מיום 1 ביולי 2024 השקעה בקרנות השקעה מתמחות בחוב תהיה בתנאי שבהתאם למדיניות ההשקעה שלהן, שיעור החשיפה לחוב לא יפחת מ 75%.
A22: יתרת הנכסים תושקע בכפוף להוראות הדין ובתנאי ששיעור החשיפה הכולל במסלול לא יעלה על 120% מנכסי המסלול.
A23: השקעה במסלול זה עשויה להיות חשופה לסיכוני מטבע.

Sheet הכשרה אשראי ואג"ח (25% מניות)
A1: מסלול אשראי ואג"ח (עד 25% מניות) בניהול הכשרה חברה לביטוח
A3: אפיק השקעה | B3: ='הכשרה - קרן י'!$B$3 -> שיעור חשיפה ליום 16/11/25 | C3: ='הכשרה - קרן י'!$C$3 -> מדיניות השקעות 2025 | D3: ='הכשרה - קרן י'!$D$3 -> שיעור חשיפה מומלץ לשנת 2026 | E3: טווח סטייה | F3: גבולות שיעור החשיפה המומלץ | I3: מדד ייחוס | J3: ='הכשרה - קרן י'!$J$3 -> שינוי ממדיניות 2025
A4: מניות (תעודות סל, חוזים, אופציות ונגזרים) | B4: 0.2252 | C4: 0.19 | D4: 0.19 | E4: +/- 6% | F4: =D4+6% -> 0.25 | G4: - | H4: =IF(D4-6%<0%,0%,D4-6%) -> 0.13 | I4: 35% - ת"א 125 | J4: =D4-C4 -> 0
I5: 65% - MSCI World
A7: אג"ח ממשלתי (סחיר ולא סחיר, תעודות סל, חוזים ונגזרים) | B7: 0.3775 | C7: 0.36 | D7: 0.36 | E7: +/- 5% | F7: =D7+5% -> 0.41 | G7: - | H7: =IF(D7-5%<0%,0%,D7-5%) -> 0.31 | I7: 50% מדד ממשלתי שקלי 2-5 | J7: =D7-C7 -> 0
I8: 50% מדד ממשלתי צמוד 2-5
A9: אג"ח קונצרני (סחיר ולא סחיר, תעודות סל, חוזים ונגזרים) | B9: 0.2917 | C9: 0.3 | D9: 0.29 | E9: +/- 6% | F9: =D9+6% -> 0.35 | G9: - | H9: =IF(D9-6%<0%,0%,D9-6%) -> 0.23 | I9: 80% תלבונד 60 | J9: =D9-C9 -> -0.01
I10: 20% Barclays Global Aggregate Index
A11: קרנות השקעה + קרנות גידור+קרנות נאמנות מתמחות חוב | B11: 0.1064 | C11: 0.14 | D11: 0.13 | E11: +/- 5% | F11: =D11+5% -> 0.18 | G11: - | H11: =IF(D11-5%<0%,0%,D11-5%) -> 0.08 | I11: מדד HFRI WORLD | J11: =D11-C11 -> -0.01
A12: אחר (מזומן, פקדונות, סחורות, נדל"ן) | B12: 0.0902 | C12: 0.05 | D12: 0.07 | E12: +/- 5% | F12: =D12+5% -> 0.12 | G12: - | H12: =IF(D12-5%<0%,0%,D12-5%) -> 0.02 | I12: ריבית בנק ישראל | J12: =D12-C12 -> 0.02
A13: סה"כ | B13: =SUM(B4:B12) -> 1.091 | C13: =SUM(C4:C12) -> 1.04 | D13: =SUM(D4:D12) -> 1.04 | J13: =SUM(J4:J12) -> 0
A14: חשיפה למט"ח | B14: 0.0726 | C14: 0.1 | D14: 0.09 | E14: +/- 6% | F14: =D14+6% -> 0.15 | G14: - | H14: =IF(D14-6%<0%,0%,D14-6%) -> 0.03 | I14: 80% דולר 20% אירו | J14: =D14-C14 -> -0.01
A15: ='הכשרה - קרן י'!$A$17 -> מגבלת עמלת ניהול חיצוני לשנת 2026 | B15: 0.0015
A17: נכסי המסלול יהיו חשופים לאשראי ואג"ח באמצעות הנכסים הבאים בארץ ובחו"ל: פיקדונות, אג"ח סחירות ושאינן סחירות לרבות אג"ח הכוללות רכיב המרה, ני"ע מסחריים,
A18: שהנפיקו תאגידים או ממשלות, הלוואות שאינן סחירות שהועמדו לתאגידים ולפרטיים, קרנות השקעה וקרנות סל אשר מירב נכסיהן מושקעים באפיקי חוב, בשיעור חשיפה שלא יפחת מ-75%.
A19: חשיפה למניות תהיה בשיעור שלא יעלה על 25% מנכסי המסלול. שיעור החשיפה הכולל במסלול לא יעלה על 120% מנכסי המסלול.
A20: חשיפה לנכסים כאמור תושג באמצעות השקעה במישרין והן באמצעות השקעה בנגזרים (לרבות חוזים עתידיים, אופציות וכתבי אופציות), בקרנות סל, בקרנות נאמנות, בקרנות השקעה ובקרנות השקעה המתמחות בחוב.
A21: החל מיום 1 ביולי 2024 השקעה בקרנות השקעה מתמחות בחוב תהיה בתנאי שבהתאם למדיניות ההשקעה שלהן, שיעור החשיפה לחוב לא יפחת מ 75%.
A22: יתרת הנכסים תושקע בכפוף להוראות הדין ובתנאי ששיעור החשיפה הכולל במסלול לא יעלה על 120% מנכסי המסלול. השקעה במסלול זה עשויה להיות חשופה לסיכוני מטבע.

Sheet עוקב מדדי מניות - DIV
A1: עוקב מדדי מניות - DIV
A3: אפיק השקעה | B3: ='הכשרה - קרן י'!$D$3 -> שיעור חשיפה מומלץ לשנת 2026 | C3: טווח סטייה | D3: גבולות שיעור החשיפה המומלץ | G3: מדד ייחוס
A4: מניות (סחיר) | B4: 0.94 | C4: +/- 6% | D4: =B4+6% -> 1 | E4: - | F4: =IF(B4-6%<0%,0%,B4-6%) -> 0.88 | G4: 45% - MSCI World High Dividend
G5: 30% - MSCI Top 50 Dividend Index
G6: 25% - MSCI Emerging Markets
A7: אחר (מזומן, פקדונות, סחורות) | B7: 0.06 | C7: +/- 5% | D7: =B7+5% -> 0.11 | E7: - | F7: =IF(B7-5%<0%,0%,B7-5%) -> 0.01 | G7: ריבית בנק ישראל
A8: סה"כ | B8: =SUM(B4:B7) -> 1
A9: חשיפה למט"ח | B9: 0.94 | C9: +/- 6% | D9: =B9+6% -> 1 | E9: - | F9: =IF(B9-6%<0%,0%,B9-6%) -> 0.88 | G9: 80% דולר 20% אירו
A10: ='הכשרה - קרן י'!$A$17 -> מגבלת עמלת ניהול חיצוני לשנת 2026 | B10: 0.002
A12: המסלול נפתח ב- 11/5/26
A14: מסלול עוקב מדדי מניות
A15: נכסי המסלול, יעקבו באמצעות מכשירים עוקבי מדד ובשיעור שלא יפחת מ-75% ולא יעלה על 100%, אחר מדדי מניות ולכל הפחות בשלושה מדדים כאמור שאינם דומים.
A16: שיעור המעקב אחר כל אחד משלושת המדדים, ששיעורם מסך נכסי המסלול הוא הגדול ביותר, לא יפחת מ-10% ולא יעלה על 50% מנכסי המסלול.
A17: יתרת נכסי המסלול יעקבו אחר מדדים שונים למעט שיעור מהנכסים שיושקע באופן הבא:
A18: א. בנגזרים המשמשים לצרכי גידור;
A19: ב. לצורך הפקדות, משיכות והעברות כספים או טיפול בביטחונות בגין נגזרים, באחד או יותר מן הבאים:
A20: 1) מזומנים;
A21: 2) מק"מ;
A22: 3) פיקדונות שהופקדו לתקופה שאינה עולה על 12 חודשים ממועד הפקדתם;
A23: 4) אג"ח של מדינת ישראל שמועד פירעונן אינו עולה על 12 חודשים;
A24: 5) באג"ח של מדינת חוץ מאושרת שמועד פירעונן אינו עולה על 12 חודשים, ובלבד שהאג"ח והנגזר נרכשו באותה מדינת חוץ מאושרת;
... A26: המעקב אחר המדדים כאמור יהיה בכפוף להוראות הדין ועשוי להיות חשוף לסיכוני מטבע.

Sheet מניות סחיר - 100% ישראל
A1: מניות סחיר - 100% ישראל
A3: אפיק השקעה | B3: ='הכשרה - קרן י'!$D$3 -> שיעור חשיפה מומלץ לשנת 2026 | C3: טווח סטייה | D3: גבולות שיעור החשיפה המומלץ | G3: מדד ייחוס
A4: מניות (סחיר בארץ) | B4: 0.94 | C4: +/- 6% | D4: =B4+6% -> 1 | E4: - | F4: =IF(B4-6%<0%,0%,B4-6%) -> 0.88
G5: 100% - ת"א 125
A7: אחר (מזומן, פקדונות, סחורות) | B7: 0.06 | C7: +/- 5% | D7: =B7+5% -> 0.11 | E7: - | F7: =IF(B7-5%<0%,0%,B7-5%) -> 0.01 | G7: ריבית בנק ישראל
A8: סה"כ | B8: =SUM(B4:B7) -> 1
A9: חשיפה למט"ח | B9: 0.01 | C9: +/- 6% | D9: =B9+6% -> 0.07 | E9: - | F9: =IF(B9-6%<0%,0%,B9-6%) -> 0 | G9: 80% דולר 20% אירו
A10: ='הכשרה - קרן י'!$A$17 -> מגבלת עמלת ניהול חיצוני לשנת 2026 | B10: 0.002
A12: המסלול נפתח ב- 11/5/26
A14: מסלול מניות סחיר
A15: נכסי המסלול יהיו חשופים למניות בארץ ובחו"ל, בשיעור חשיפה שלא יפחת מ-75% ולא יעלה על 120% חשיפה לנכסים כאמור תושג באמצעות השקעה בנכסים סחירים בלבד.
A16: ההשקעה עשויה להתבצע הן במישרין (בנכסי בסיס) והן באמצעות השקעה בנגזרים (לרבות חוזים עתידיים, אופציות וכתבי אופציות ולרבות נגזרים לא סחירים אשר משמשים לצרכי גידור ונגזרים לא סחירים אשר שווים נגזר מנכס בסיס סחיר), בקרנות סל ובקרנות נאמנות.
A17: יתרת הנכסים תושקע במזומנים ופיקדונות שהופקדו לתקופה שאינה עולה על 3 חודשים ממועד הפקדתם.
A18: השקעה במסלול זה עשויה להיות חשופה לסיכוני מטבע.

Sheet אג"ח ממשלות
A2: מסלול אג"ח ממשלות בניהול: אלטשולר שחם, מיטב, ילין לפידות, מור, אנליסט
A3: אפיק השקעה | B3: שיעור חשיפה ליום 16/11/25 (ממוצע כלל המנהלים) | C3: ='הכשרה - קרן י'!$C$3 -> מדיניות השקעות 2025 | D3: ='הכשרה - קרן י'!$D$3 -> שיעור חשיפה מומלץ לשנת 2026 | E3: טווח סטייה | F3: גבולות שיעור החשיפה המומלץ | I3: מדד ייחוס | J3: ='הכשרה - קרן י'!$J$3 -> שינוי ממדיניות 2025
A4: מניות (תעודות סל, קרנות נאמנות, חוזים אופציות ונגזרים) | B4: =(0%+3.09%+0.04%+0.32%+0.58%)/5 -> 0.00806 | C4: 0.01 | D4: 0.01 | E4: +/- 6% | F4: =D4+6% -> 0.07 | G4: - | H4: =IF(D4-6%<0%,0%,D4-6%) -> 0 | I4: 35% - ת"א 125 | J4: =D4-C4 -> 0
I5: 65% - MSCI World
A7: אג"ח ממשלתי (סחיר ולא סחיר, קרנות נאמנות, תעודות סל, חוזים ונגזרים) | B7: =(87.45%+82.29%+83.52%+80.1%+81.84%)/5 -> 0.8304 | C7: 0.85 | D7: 0.85 | E7: +/- 5% | F7: =D7+5% -> 0.9 | G7: - | H7: =IF(D7-5%<0%,0%,D7-5%) -> 0.8 | I7: 50% מדד ממשלתי שקלי 2-5 | J7: =D7-C7 -> 0
I8: 50% מדד ממשלתי צמוד 2-5
A9: אג"ח קונצרני (סחיר ולא סחיר, קרנות נאמנות, תעודות סל, חוזים ונגזרים) | B9: =(14.8%+11.8%+14.6%+20.7%+15.9%)/5 -> 0.1556 | C9: 0.15 | D9: 0.15 | E9: +/- 6% | F9: =D9+6% -> 0.21 | G9: - | H9: =IF(D9-6%<0%,0%,D9-6%) -> 0.09 | I9: 80% תלבונד 60 | J9: =D9-C9 -> 0
I10: 20% Barclays Global Aggregate Index
A11: קרנות השקעה + קרנות גידור | B11: =(0%+0%+0.43%+0.83%+0%)/5 -> 0.00252 | C11: 0.05 | D11: 0.05 | E11: +/- 5% | F11: =D11+5% -> 0.1 | G11: - | H11: =IF(D11-5%<0%,0%,D11-5%) -> 0 | I11: מדד HFRI WORLD | J11: =D11-C11 -> 0
A12: הלוואות לחברות + הלוואות עמיתים | B12: =(1.13%+0.89%+1.67%+0.71%+0%)/5 -> 0.0088 | C12: 0.01 | D12: 0.01 | E12: +/- 5% | F12: =D12+5% -> 0.06 | G12: - | H12: =IF(D12-5%<0%,0%,D12-5%) -> 0 | I12: ממשלתי לא צמוד 2-5 | J12: =D12-C12 -> 0
A13: אחר (מזומן, פקדונות, סחורות, נדל"ן) | B13: =(6.04%+1.94%+4.46%+2.26%+1.72%)/5 -> 0.03284 | C13: 0.05 | D13: 0.05 | E13: +/- 5% | F13: =D13+5% -> 0.1 | G13: - | H13: =IF(D13-5%<0%,0%,D13-5%) -> 0 | I13: ריבית בנק ישראל | J13: =D13-C13 -> 0
A14: סה"כ | B14: =SUM(B4:B13) -> 1.03822 | C14: =SUM(C4:C13) -> 1.12 | D14: =SUM(D4:D13) -> 1.12 | J14: =SUM(J4:J13) -> 0
A15: חשיפה למט"ח | B15: =(4.1%+3.33%+5.18%+7.36%+3.24%)/5 -> 0.04642 | C15: 0.06 | D15: 0.06 | E15: +/- 6% | F15: =D15+6% -> 0.12 | G15: - | H15: =IF(D15-6%<0%,0%,D15-6%) -> 0 | I15: 80% דולר 20% אירו | J15: =D15-C15 -> 0
A16: ='הכשרה - קרן י'!$A$17 -> מגבלת עמלת ניהול חיצוני לשנת 2026 | B16: 0.0015
A17: מסלול אג"ח ממשלות בניהול: הכשרה חברה לביטוח
A18: אפיק השקעה | B18: שיעור חשיפה ליום 16/11/25 | C18: ='הכשרה - קרן י'!$C$3 -> מדיניות השקעות 2025 | D18: ='הכשרה - קרן י'!$D$3 -> שיעור חשיפה מומלץ לשנת 2026 | E18: טווח סטייה | F18: גבולות שיעור החשיפה המומלץ | I18: מדד ייחוס | J18: ='הכשרה - קרן י'!$J$3 -> שינוי ממדיניות 2025
A19: מניות (תעודות סל, קרנות נאמנות, חוזים אופציות ונגזרים) | B19: 0.0658 | C19: 0.01 | D19: 0.01 | E19: +/- 6% | F19: =D19+6% -> 0.07 | G19: - | H19: =IF(D19-6%<0%,0%,D19-6%) -> 0 | I19: 35% - ת"א 125 | J19: =D19-C19 -> 0
I20: 65% - MSCI World
A22: אג"ח ממשלתי (סחיר ולא סחיר, קרנות נאמנות, תעודות סל, חוזים ונגזרים) | B22: 0.8351 | C22: 0.87 | D22: 0.85 | E22: +/- 5% | F22: =D22+5% -> 0.9 | G22: - | H22: =IF(D22-5%<0%,0%,D22-5%) -> 0.8 | I22: 50% מדד ממשלתי שקלי 2-5 | J22: =D22-C22 -> -0.02
I23: 50% מדד ממשלתי צמוד 2-5
A24: אג"ח קונצרני (סחיר ולא סחיר, קרנות נאמנות, תעודות סל, חוזים ונגזרים) | B24: 0.0744 | C24: 0.09 | D24: 0.08 | E24: +/- 6% | F24: =D24+6% -> 0.14 | G24: - | H24: =IF(D24-6%<0%,0%,D24-6%) -> 0.02 | I24: 80% תלבונד 60 | J24: =D24-C24 -> -0.01
I25: 20% Barclays Global Aggregate Index
A26: קרנות השקעה + קרנות גידור | B26: 0.0891 | C26: 0.05 | D26: 0.06 | E26: +/- 5% | F26: =D26+5% -> 0.11 | G26: - | H26: =IF(D26-5%<0%,0%,D26-5%) -> 0.01 | I26: מדד HFRI WORLD | J26: =D26-C26 -> 0.01
A27: הלוואות לחברות + הלוואות עמיתים | B27: 0.0129 | C27: 0.01 | D27: 0.01 | E27: +/- 5% | F27: =D27+5% -> 0.06 | G27: - | H27: =IF(D27-5%<0%,0%,D27-5%) -> 0 | I27: ממשלתי לא צמוד 2-5 | J27: =D27-C27 -> 0
A28: אחר (מזומן, פקדונות, סחורות, נדל"ן) | B28: 0.0567 | C28: 0.05 | D28: 0.08 | E28: +/- 5% | F28: =D28+5% -> 0.13 | G28: - | H28: =IF(D28-5%<0%,0%,D28-5%) -> 0.03 | I28: ריבית בנק ישראל | J28: =D28-C28 -> 0.03
A29: סה"כ | B29: =SUM(B19:B28) -> 1.134 | C29: =SUM(C19:C28) -> 1.08 | D29: =SUM(D19:D28) -> 1.09 | J29: =SUM(J19:J28) -> 0.01
A30: חשיפה למט"ח | B30: 0.0144 | C30: 0.06 | D30: 0.06 | E30: +/- 6% | F30: =D30+6% -> 0.12 | G30: - | H30: =IF(D30-6%<0%,0%,D30-6%) -> 0 | I30: 80% דולר 20% אירו | J30: =D30-C30 -> 0
A31: ='הכשרה - קרן י'!$A$17 -> מגבלת עמלת ניהול חיצוני לשנת 2026 | B31: 0.001
A33: בתאריך 29.07.26 אישר הדירקטוריון את השינוי הבא (במסלול המנוהל ע"י הכשרה)
A34: אפיק השקעה | B34: מדיניות קודמת | C34: שינוי החל מתאריך 29.07.26 | D34: שינוי ממדיניות קודמת | E34: טווח סטייה | F34: גבולות שיעור החשיפה המומלץ
A35: מניות (תעודות סל, קרנות נאמנות, חוזים אופציות ונגזרים) | B35: 0.01 | C35: 0.03 | D35: =C35-B35 -> 0.02 | E35: +/- 6% | F35: =C35+6% -> 0.09 | G35: - | H35: =IF(C35-6%<0%,0%,C35-6%) -> 0
A36: אג"ח ממשלתי (סחיר ולא סחיר, קרנות נאמנות, תעודות סל, חוזים ונגזרים) | B36: 0.85 | C36: 0.83 | D36: =C36-B36 -> -0.02 | E36: +/- 5% | F36: =C36+5% -> 0.88 | G36: - | H36: =IF(C36-5%<0%,0%,C36-5%) -> 0.78
A38: נכסי המסלול יהיו חשופים לאג"ח של ממשלות בדירוג של מדינת חוץ מאושרת כהגדרתה בתקנות כללי השקעה, בשיעור חשיפה שלא יפחת מ-75% ולא יעלה על 120% מנכסי המסלול.
A39: חשיפה לנכסים כאמור תושג באמצעות השקעה במישרין והן באמצעות השקעה בנגזרים (לרבות חוזים עתידיים, אופציות וכתבי אופציות), בקרנות סל ובקרנות נאמנות.
A40: יתרת הנכסים תושקע בכפוף להוראות הדין ובתנאי ששיעור החשיפה הכולל במסלול לא יעלה על 120% מנכסי המסלול.
A41: השקעה במסלול זה עשויה להיות חשופה לסיכוני מטבע.

Sheet מסלול מניות
A1: מסלול מניות בניהול :
A2: הכשרה חברה לביטוח, אלטשולר שחם, מיטב, ילין לפידות, מור, אנליסט
A4: אפיק השקעה | B4: שיעור חשיפה ליום 16/11/25 (ממוצע כלל המנהלים) | C4: ='הכשרה - קרן י'!$C$3 -> מדיניות השקעות 2025 | D4: ='הכשרה - קרן י'!$D$3 -> שיעור חשיפה מומלץ לשנת 2026 | E4: טווח סטייה | F4: גבולות שיעור החשיפה המומלץ | I4: מדד ייחוס | J4: ='הכשרה - קרן י'!$J$3 -> שינוי ממדיניות 2025
A5: מניות (תעודות סל, קרנות נאמנות, חוזים אופציות ונגזרים) | B5: =(91.25%+91.44%+96.31%+94.7%+96.1%+94.22%)/6 -> 0.94003333 | C5: 0.94 | D5: 0.94 | E5: +/- 6% | F5: =D5+6% -> 1 | G5: - | H5: =IF(D5-6%<0%,0%,D5-6%) -> 0.88 | I5: 35% - ת"א 125 | J5: =D5-C5 -> 0
I6: 65% - MSCI World
A8: אג"ח ממשלתי (סחיר ולא סחיר, קרנות נאמנות, תעודות סל, חוזים ונגזרים) | B8: =(5.28%+4.19%+10.12%+1.09%+9.77%+3.1%)/6 -> 0.055916667 | C8: 0.06 | D8: 0.06 | E8: +/- 5% | F8: =D8+5% -> 0.11 | G8: - | H8: =IF(D8-5%<0%,0%,D8-5%) -> 0.01 | I8: 50% מדד ממשלתי שקלי 2-5 | J8: =D8-C8 -> 0
I9: 50% מדד ממשלתי צמוד 2-5
A10: אג"ח קונצרני (סחיר ולא סחיר, קרנות נאמנות, תעודות סל, חוזים ונגזרים) | B10: =(0%+0.1%+4%+6.7%+1.6%+0%)/6 -> 0.020666667 | C10: 0.04 | D10: 0.04 | E10: +/- 6% | F10: =D10+6% -> 0.1 | G10: - | H10: =IF(D10-6%<0%,0%,D10-6%) -> 0 | I10: 80% תלבונד 60 | J10: =D10-C10 -> 0
I11: 20% Barclays Global Aggregate Index
A12: קרנות השקעה + קרנות גידור | B12: =(0%+0%+0%+0.45%+0%+4.5%)/6 -> 0.00825 | C12: 0.05 | D12: 0.05 | E12: +/- 5% | F12: =D12+5% -> 0.1 | G12: - | H12: =IF(D12-5%<0%,0%,D12-5%) -> 0 | I12: מדד HFRI WORLD | J12: =D12-C12 -> 0
A13: הלוואות לחברות | B13: =(0%+0%+0%+0%+0%+0.18%)/6 -> 0.0003 | C13: 0.01 | D13: 0.01 | E13: +/- 5% | F13: =D13+5% -> 0.06 | G13: - | H13: =IF(D13-5%<0%,0%,D13-5%) -> 0 | I13: ממשלתי לא צמוד 2-5 | J13: =D13-C13 -> 0
A14: אחר (מזומן, פקדונות, סחורות, נדל"ן) | B14: =(12.46%+9.62%+7.58%+4.95%+11.64%+12.88%)/6 -> 0.09855 | C14: 0.1 | D14: 0.07 | E14: +/- 5% | F14: =D14+5% -> 0.12 | G14: - | H14: =IF(D14-5%<0%,0%,D14-5%) -> 0.02 | I14: ריבית בנק ישראל | J14: =D14-C14 -> -0.03
A15: סה"כ | B15: =SUM(B5:B14) -> 1.1237167 | C15: =SUM(C5:C14) -> 1.2 | D15: =SUM(D5:D14) -> 1.17 | J15: =SUM(J5:J14) -> -0.03
A16: חשיפה למט"ח | B16: =(32.8%+31.95%+32.75%+32.19%+32.48%+31.99%)/6 -> 0.3236 | C16: 0.38 | D16: 0.38 | E16: +/- 6% | F16: =D16+6% -> 0.44 | G16: - | H16: =IF(D16-6%<0%,0%,D16-6%) -> 0.32 | I16: 80% דולר 20% אירו | J16: =D16-C16 -> 0
A17: ='הכשרה - קרן י'!$A$17 -> מגבלת עמלת ניהול חיצוני לשנת 2026 | B17: 0.0025
A19: נכסי המסלול יהיו חשופים למניות בארץ ובחו"ל, בשיעור חשיפה שלא יפחת מ-75% ולא יעלה על 120% מנכסי המסלול.
A20: חשיפה לנכסים כאמור תושג באמצעות השקעה במישרין ובאמצעות השקעה בנגזרים (לרבות חוזים עתידיים, אופציות וכתבי אופציות), בקרנות סל, בקרנות נאמנות ובקרנות השקעה.
A21: יתרת הנכסים תושקע בכפוף להוראות הדין ובתנאי ששיעור החשיפה הכולל במסלול לא יעלה על 120% מנכסי המסלול.
A22: השקעה במסלול זה עשויה להיות חשופה לסיכוני מטבע.
A24: בתאריך 26.08.26 אישר הדירקטוריון את השינוי הבא
A25: אפיק השקעה | B25: מדיניות קודמת | C25: שינוי החל מתאריך 26.08.26 | D25: שינוי ממדיניות קודמת | E25: טווח סטייה | F25: גבולות שיעור החשיפה המומלץ
A26: חשיפה למט"ח | B26: 0.38 | C26: 0.32 | D26: =C26-B26 -> -0.06 | E26: +/- 6% | F26: =C26+6% -> 0.38 | G26: - | H26: =IF(C26-6%<0%,0%,C26-6%) -> 0.26

Sheet הכשרה - עוקב מדד S&P500
A1: הכשרה - עוקב מדד S&P500
A3: אפיק | B3: ='הכשרה - קרן י'!$B$3 -> שיעור חשיפה ליום 16/11/25 | C3: ='הכשרה - קרן י'!$C$3 -> מדיניות השקעות 2025 | D3: ='הכשרה - קרן י'!$D$3 -> שיעור חשיפה מומלץ לשנת 2026 | E3: טווח סטייה | F3: גבולות שיעור החשיפה המומלץ | I3: מדד ייחוס | J3: ='הכשרה - קרן י'!$J$3 -> שינוי ממדיניות 2025
A4: מניות | B4: 0.9918 | C4: 1 | D4: 1 | E4: +/- 6% | F4: =D4 -> 1 | G4: - | H4: =IF(D4-6%<0%,0%,D4-6%) -> 0.94 | I4: S&P500 - 100% | J4: =D4-C4 -> 0
A5: סה"כ | B5: =SUM(B4) -> 0.9918 | C5: =SUM(C4) -> 1 | D5: =SUM(D4) -> 1 | J5: =SUM(J4) -> 0
A6: חשיפה למט"ח | B6: 1.0026 | C6: 1 | D6: 1 | E6: +/- 6% | F6: =D6+6% -> 1.06 | G6: - | H6: =IF(D6-6%<0%,0%,D6-6%) -> 0.94 | I6: 100% - דולר | J6: =D6-C6 -> 0
A7: ='הכשרה - קרן י'!$A$17 -> מגבלת עמלת ניהול חיצוני לשנת 2026 | B7: 0.001 | D7: 0.0025
A9: נכסי המסלול, יעקבו באמצעות מכשירים עוקבי מדד ונגזרים (לרבות חוזים עתידיים, אופציות וכתבי אופציות) ובשיעור חשיפה שלא יעלה על 100% מנכסי המסלול, אחר מדד 500 S&P.
A10: נכסי המסלול העוקבים אחר המדד יהיו כל נכסי המסלול למעט שיעור מהנכסים שיושקע באופן הבא:
A11: א. בנגזרים המשמשים לצרכי גידור;
A12: ב. לצורך הפקדות, משיכות והעברות כספים או טיפול בביטחונות בגין נגזרים, באחד או יותר מן הבאים:
A13: 1) מזומנים;
A14: 2) מק"מ;
A15: 3) פיקדונות שהופקדו לתקופה שאינה עולה על 12 חודשים ממועד הפקדתם,
A16: 4) אג"ח של מדינת ישראל שמועד פירעונן אינו עולה על 12 חודשים;
A17: 5) באג"ח של מדינת חוץ מאושרת שמועד פירעונן אינו עולה על 12 חודשים, ובלבד שהאג"ח והנגזר נרכשו באותה מדינת חוץ מאושרת;
A18: 6) קרן כספית שהגדרתה בתקנות השקעות משותפות בנאמנות (נכסים שמותר לקנות ולהחזיק בקרן ושיעוריהם המרביים), התשנ"ה-1994.
A19: המעקב אחר המדד יהיה בכפוף להוראות הדין ועשוי להיות חשוף לסיכוני מטבע.

Sheet בתי השקעות - כללי
B2: מסלול כללי אלטשולר שחם 2026
B4: אפיק השקעה | C4: שיעור חשיפה ליום 16/11/25 | D4: מדיניות השקעות 2025 | E4: שיעור חשיפה מומלץ לשנת 2026 | F4: טווח סטייה | G4: גבולות שיעור החשיפה המומלץ | J4: מדד ייחוס | K4: שינוי מ- 2025
B5: מניות (תעודות סל, קרנות נאמנות, חוזים אופציות ונגזרים) | C5: 0.449 | D5: 0.46 | E5: 0.44 | F5: +/- 6% | G5: =E5+6% -> 0.5 | H5: - | I5: =IF(E5-6%<0%,0%,E5-6%) -> 0.38 | J5: 35% - ת"א 125 | K5: =E5-D5 -> -0.02
J6: 65% - MSCI World
B8: אג"ח ממשלתי (סחיר ולא סחיר, קרנות נאמנות, תעודות סל, חוזים ונגזרים) | C8: 0.4438 | D8: 0.44 | E8: 0.46 | F8: +/- 5% | G8: =E8+5% -> 0.51 | H8: - | I8: =IF(E8-5%<0%,0%,E8-5%) -> 0.41 | J8: 50% מדד ממשלתי שקלי 2-5 | K8: =E8-D8 -> 0.02
J9: 50% מדד ממשלתי צמוד 2-5
B10: אג"ח קונצרני (סחיר ולא סחיר, קרנות נאמנות, תעודות סל, חוזים ונגזרים) | C10: 0.1181 | D10: 0.13 | E10: 0.12 | F10: +/- 6% | G10: =E10+6% -> 0.18 | H10: - | I10: =IF(E10-6%<0%,0%,E10-6%) -> 0.06 | J10: 80% תלבונד 60 | K10: =E10-D10 -> -0.01
J11: 20% Barclays Global Aggregate Index
B12: קרנות השקעה + קרנות גידור | C12: 0 | D12: 0 | E12: 0 | F12: +/- 5% | G12: =E12+5% -> 0.05 | H12: - | I12: =IF(E12-5%<0%,0%,E12-5%) -> 0 | J12: מדד HFRI WORLD | K12: =E12-D12 -> 0
B13: הלוואות לחברות + הלוואות עמיתים | C13: 0.0283 | D13: 0.01 | E13: 0.01 | F13: +/- 5% | G13: =E13+5% -> 0.06 | H13: - | I13: =IF(E13-5%<0%,0%,E13-5%) -> 0 | J13: ממשלתי לא צמוד 2-5 | K13: =E13-D13 -> 0
B14: אחר (מזומן, פקדונות, סחורות) | C14: 0.096 | D14: 0.09 | E14: 0.09 | F14: +/- 5% | G14: =E14+5% -> 0.14 | H14: - | I14: =IF(E14-5%<0%,0%,E14-5%) -> 0.04 | J14: ריבית בנק ישראל | K14: =E14-D14 -> 0
B15: סה"כ | C15: =SUM(C5:C14) -> 1.1352 | D15: =SUM(D5:D14) -> 1.13 | E15: =SUM(E5:E14) -> 1.12 | K15: =E15-D15 -> -0.01
B16: חשיפה למט"ח | C16: 0.1898 | D16: 0.24 | E16: 0.18 | F16: +/- 6% | G16: =E16+6% -> 0.24 | H16: - | I16: =IF(E16-6%<0%,0%,E16-6%) -> 0.12 | J16: 80% דולר 20% אירו | K16: =E16-D16 -> -0.06
B17: ='הכשרה - קרן י'!$A$17 -> מגבלת עמלת ניהול חיצוני לשנת 2026 | C17: 0.001
B19: בתאריך 29.06.26 אישר הדירקטוריון את השינוי הבא
B20: אפיק השקעה | C20: מדיניות קודמת | D20: שינוי החל מתאריך 29.06.26 | E20: שינוי ממדיניות קודמת | F20: טווח סטייה | G20: גבולות שיעור החשיפה המומלץ
B21: מניות (תעודות סל, קרנות נאמנות, חוזים אופציות ונגזרים) | C21: 0.44 | D21: 0.5 | E21: =D21-C21 -> 0.06 | F21: +/- 6% | G21: =D21+6% -> 0.56 | H21: - | I21: =IF(D21-6%<0%,0%,D21-6%) -> 0.44
B22: אג"ח ממשלתי (סחיר ולא סחיר, קרנות נאמנות, תעודות סל, חוזים ונגזרים) | C22: 0.46 | D22: 0.41 | E22: =D22-C22 -> -0.05 | F22: +/- 5% | G22: =D22+5% -> 0.46 | H22: - | I22: =IF(D22-5%<0%,0%,D22-5%) -> 0.36
B23: הלוואות לחברות + הלוואות עמיתים | C23: 0.01 | D23: 0.03 | E23: =D23-C23 -> 0.02 | F23: +/- 5% | G23: =D23+5% -> 0.08 | H23: - | I23: =IF(D23-5%<0%,0%,D23-5%) -> 0
B24: אחר (מזומן, פקדונות, סחורות) | C24: 0.09 | D24: 0.07 | E24: =D24-C24 -> -0.02 | F24: +/- 5% | G24: =D24+5% -> 0.12 | H24: - | I24: =IF(D24-5%<0%,0%,D24-5%) -> 0.02
B26: מסלול כללי מיטב 2026
B28: אפיק השקעה | C28: =$C$4 -> שיעור חשיפה ליום 16/11/25 | D28: =$D$4 -> מדיניות השקעות 2025 | E28: =$E$4 -> שיעור חשיפה מומלץ לשנת 2026 | F28: טווח סטייה | G28: גבולות שיעור החשיפה המומלץ | J28: מדד ייחוס | K28: =$K$4 -> שינוי מ- 2025
B29: מניות (תעודות סל, קרנות נאמנות, חוזים אופציות ונגזרים) | C29: 0.4352 | D29: 0.42 | E29: 0.43 | F29: +/- 6% | G29: =E29+6% -> 0.49 | H29: - | I29: =IF(E29-6%<0%,0%,E29-6%) -> 0.37 | J29: 35% - ת"א 125 | K29: =E29-D29 -> 0.01
J30: 65% - MSCI World
B32: אג"ח ממשלתי (סחיר ולא סחיר, קרנות נאמנות, תעודות סל, חוזים ונגזרים) | C32: 0.2727 | D32: 0.3 | E32: 0.3 | F32: +/- 5% | G32: =E32+5% -> 0.35 | H32: - | I32: =IF(E32-5%<0%,0%,E32-5%) -> 0.25 | J32: 50% מדד ממשלתי שקלי 2-5 | K32: =E32-D32 -> 0
J33: 50% מדד ממשלתי צמוד 2-5
B34: אג"ח קונצרני (סחיר ולא סחיר, קרנות נאמנות, תעודות סל, חוזים ונגזרים) | C34: 0.201 | D34: 0.22 | E34: 0.22 | F34: +/- 6% | G34: =E34+6% -> 0.28 | H34: - | I34: =IF(E34-6%<0%,0%,E34-6%) -> 0.16 | J34: 80% תלבונד 60 | K34: =E34-D34 -> 0
J35: 20% Barclays Global Aggregate Index
B36: קרנות השקעה + קרנות גידור | C36: 0 | D36: 0 | E36: 0 | F36: +/- 5% | G36: =E36+5% -> 0.05 | H36: - | I36: =IF(E36-5%<0%,0%,E36-5%) -> 0 | J36: מדד HFRI WORLD | K36: =E36-D36 -> 0
B37: הלוואות לחברות + הלוואות עמיתים | C37: 0.013 | D37: 0.02 | E37: 0.02 | F37: +/- 5% | G37: =E37+5% -> 0.07 | H37: - | I37: =IF(E37-5%<0%,0%,E37-5%) -> 0 | J37: ממשלתי לא צמוד 2-5 | K37: =E37-D37 -> 0
B38: אחר (מזומן, פקדונות, סחורות) | C38: 0.0781 | D38: 0.04 | E38: 0.04 | F38: +/- 5% | G38: =E38+5% -> 0.09 | H38: - | I38: =IF(E38-5%<0%,0%,E38-5%) -> 0 | J38: ריבית בנק ישראל | K38: =E38-D38 -> 0
B39: סה"כ | C39: =SUM(C29:C38) -> 1 | D39: =SUM(D29:D38) -> 1 | E39: =SUM(E29:E38) -> 1.01 | K39: =E39-D39 -> 0.01
B40: חשיפה למט"ח | C40: 0.1539 | D40: 0.18 | E40: 0.17 | F40: +/- 6% | G40: =E40+6% -> 0.23 | H40: - | I40: =IF(E40-6%<0%,0%,E40-6%) -> 0.11 | J40: 80% דולר 20% אירו | K40: =E40-D40 -> -0.01
B41: =$B$17 -> מגבלת עמלת ניהול חיצוני לשנת 2026 | C41: 0.001
B44: מסלול כללי ילין 2026
B46: אפיק השקעה | C46: =$C$4 -> שיעור חשיפה ליום 16/11/25 | D46: =$D$4 -> מדיניות השקעות 2025 | E46: =$E$4 -> שיעור חשיפה מומלץ לשנת 2026 | F46: טווח סטייה | G46: גבולות שיעור החשיפה המומלץ | J46: מדד ייחוס | K46: =$K$4 -> שינוי מ- 2025
B47: מניות (תעודות סל, קרנות נאמנות, חוזים אופציות ונגזרים) | C47: 0.469 | D47: 0.46 | E47: 0.47 | F47: +/- 6% | G47: =E47+6% -> 0.53 | H47: - | I47: =IF(E47-6%<0%,0%,E47-6%) -> 0.41 | J47: 35% - ת"א 125 | K47: =E47-D47 -> 0.01
J48: 65% - MSCI World
B50: אג"ח ממשלתי (סחיר ולא סחיר, קרנות נאמנות, תעודות סל, חוזים ונגזרים) | C50: 0.4278 | D50: 0.42 | E50: 0.43 | F50: +/- 5% | G50: =E50+5% -> 0.48 | H50: - | I50: =IF(E50-5%<0%,0%,E50-5%) -> 0.38 | J50: 50% מדד ממשלתי שקלי 2-5 | K50: =E50-D50 -> 0.01
J51: 50% מדד ממשלתי צמוד 2-5
...

Sheet פיזור ענפי - טיוטא
D2: Under/Over | E2: מתחרים כללי ממוצע | F2: הכשרה כללי | G2: שם נייר | H2: ענף פעילות
D3: =F3-E3 -> -0.0018 | E3: 0.0037 | F3: 0.0019 | G3: AAPL - Apple | H3: Technology Hardware & Equip
D4: =F4-E4 -> 0.0026 | E4: 0 | F4: 0.0026 | G4: ADOBE SYSTENS-ADBE | H4: Software & Services
D5: =F5-E5 -> 0.0021 | E5: 0 | F5: 0.0021 | G5: AMAZON-AMZN COM | H5: Other
D6: =F6-E6 -> 0.0052 | E6: 0 | F6: 0.0052 | G6: AVALORN JP - AJVFPF LX | H6: Other
D7: =F7-E7 -> -0.004 | E7: 0.004 | F7: 0 | G7: ALIBABA GROUP H | H7: Software & Services
D8: =F8-E8 -> -0.0001 | E8: 0.0001 | F8: 0 | G8: ALIGN TECHNOLOGY-ALGN | H8: Pharma & Biotechnology
D9: =F9-E9 -> -0.0002 | E9: 0.0002 | F9: 0 | G9: AROUNDTOWN PROP | H9: Real Estate
D10: =F10-E10 -> -0.0021 | E10: 0.0021 | F10: 0 | G10: AROUNDTOWN PROP-ALATP | H10: Real Estate
D11: =F11-E11 -> -0.0009 | E11: 0.0009 | F11: 0 | G11: ATRIUM EUROPEAN-ARTS AV | H11: Real Estate
D12: =F12-E12 -> -0.0002 | E12: 0.0002 | F12: 0 | G12: ATTUNITY LTD- ATTU | H12: Software & Services
D13: =F13-E13 -> -0.0022 | E13: 0.0022 | F13: 0 | G13: BA - BOEING CO | H13: Capital Goods
D14: =F14-E14 -> -0.0033 | E14: 0.0033 | F14: 0 | G14: BIDU - BAIDU | H14: Technology Hardware & Equip
... D20: =F20-E20 -> -0.0013 | E20: 0.0034 | F20: 0.0021 | G20: CHKP - CHECK POINT | H20: Software & Services
D21: =F21-E21 -> -0.0005 | E21: 0.0005 | F21: 0% | G21: COM.888 | H21: Utilities
D22: =F22-E22 -> -0.006 | E22: 0.006 | F22: 0 | G22: Comgest Growth Europe Opportun | H22: Other
D23: =F23-E23 -> 0.0013 | E23: 0.004 | F23: 0.0053 | G23: CSI-KWEB CHINA | H23: Other
D24: =F24-E24 -> -0.005 | E24: 0.005 | F24: 0 | G24: DAXEX GY - DAX | H24: Other
D25: =F25-E25 -> -0.0008 | E25: 0.0008 | F25: 0 | G25: DELEK US HLDNGS-DK | H25: Energy
D26: =F26-E26 -> -0.0012 | E26: 0.0012 | F26: 0 | G26: DELTA AIR LINES | H26: Transportation
D27: =F27-E27 -> -0.0001 | E27: 0.0001 | F27: 0 | G27: DIA - Dow Jones | H27: Other
D28: =F28-E28 -> -0.0002 | E28: 0.0002 | F28: 0 | G28: DXJ - WISDOM TREE JAPAN | H28: Other
D29: =F29-E29 -> -0.0003 | E29: 0.0003 | F29: 0 | G29: ELOXX PHARMACEUTICALS-ELOX | H29: Pharma & Biotechnology
D30: =F30-E30 -> -0.0001 | E30: 0.0001 | F30: 0 | G30: Emerging Markets - EEM | H30: Other
D31: =F31-E31 -> -0.0028 | E31: 0.0028 | F31: 0 | G31: EWY - SOUTH KOREA | H31: Other
D32: =F32-E32 -> 0.0019 | E32: 0 | F32: 0.0019 | G32: ELBIT SYSTEMS L | H32: Other
D33: =F33-E33 -> 0.0065 | E33: 0 | F33: 0.0065 | G33: FIRST TRUST CLOUD COMPUTING-SK | H33: Technology Hardware & Equip
... D50: =F50-E50 -> 0.0052 | E50: 0.0001 | F50: 0.0053 | G50: KORNIT DIGITAL-KRNT | H50: Other
D51: =F51-E51 -> -0.0001 | E51: 0.0001 | F51: 0.00% | G51: KAMADA LTD | H51: Pharma & Biotechnology
D52: =F52-E52 -> 0.001 | E52: 0.0002 | F52: 0.0012 | G52: MSFT - MICROSOFT | H52: Software & Services
D53: =F53-E53 -> -0.0026 | E53: 0.0026 | F53: 0 | G53: KOTAK FUNDS-IND-KOTIMAU | H53: Other
D54: =F54-E54 -> -0.0009 | E54: 0.0009 | F54: 0 | G54: LGI HOMES INC | H54: Real Estate
D55: =F55-E55 -> -0.0002 | E55: 0.0002 | F55: 0 | G55: MDWD-MEDIWOUND LTD | H55: Pharma & Biotechnology
D56: =F56-E56 -> -0.0002 | E56: 0.0002 | F56: 0 | G56: MICRON TECH-INC | H56: Semiconductors & Semicon Equip
D57: =F57-E57 -> -0.0002 | E57: 0.0002 | F57: 0 | G57: MLNX - MELLANOX | H57: Semiconductors & Semicon Equip
D58: =F58-E58 -> 0.0035 | E58: 0.0003 | F58: 0.0038 | G58: MYL-MYLAN LABORATOR | H58: Pharma & Biotechnology
D59: =F59-E59 -> 0.0019 | E59: 0 | F59: 0.0019 | G59: NETFLIX | H59: Media
D60: =F60-E60 -> 0.0019 | E60: 0.005 | F60: 0.0069 | G60: NICE SYSTEMS LT | H60: Software & Services
D61: =F61-E61 -> 0.0006 | E61: 0.0011 | F61: 0.0017 | G61: NVIDIA CORP - NVDA | H61: Semiconductors & Semicon Equip
D62: =F62-E62 -> 0.0026 | E62: 0 | F62: 0.0026 | G62: ORMAT TECHNOLOGIES-ORA | H62: Utilities
...
