Workbook

Sheet נספח 1 - מצרפי
A1: נספח 1- סך ההוצאות הישירות ששולמו בעד כל סוג של הוצאה ישירה לתקופה המסתיימת ביום 31.12.2024
A3: שם חברת הביטוח: הכשרה חברה לביטוח - משתתפות ברווחים | B3: אלפי ₪
A5: 31.12.2024 נספח 1- סך ההוצאות הישירות ששולמו בעד כל סוג של הוצאה ישירה לתקופה המסתיימת ביום
A7: הוצאות ישירות שאינן מסוג עמלת ניהול חיצוני
A8: 1. סך הכל עמלות קנייה ומכירה של ניירות ערך סחירים | B8: =SUM(B9:B10) -> 8725.8722
A9: א. סך עמלות קנייה ומכירה של ניירות ערך סחירים לצדדים קשורים
A10: ב. סך עמלות קנייה ומכירה של ניירות ערך סחירים לצדדים שאינם קשורים | B10: ='קרן ט'!B10+'קרן י'!B10+'הכשרה כללי'!B10+'הכשרה אגח ממשלות'!B10+'הכשרה מניות'!B10+'כספי שקלי'!B10+'הכשרה לבני 50 ומטה'!B10+'הכשרה לבני 50-60'!B10+'הכשרה לבני 60 ומעלה'!B10+'הכשרה מקבלי קצבה'!B10+'הכשרה אשראי ואג"ח'!B10+'הכשרה אשראי ואג"ח עד 25%'!B10+'הכשרה עוקב מדדים גמיש'!B10+'הכשרה משולב סחיר'!B10+'אלשטולר כללי'!B10+'אלשטושלר מניות'!B10+'אלטשולר אג"ח'!B10+'ילין כללי'!B10+'ילין מניות'!B10+'ילין אג"ח'!B10+'מיטב כללי'!B10+'מיטב מניות'!B10+'מיטב אג"ח'!B10+'פאסיבי כללי'!B10+'הכשרה עוקב מדד SP500'!B10+'מור כללי'!B10+'מור מניות'!B10+'מור אג"ח'!B10+'אנליסט כללי'!B10+'אנליסט מניות'!B10+'אנליסט אג"ח'!B10 -> 8725.8722
A12: 2. סך הכל דמי שמירה בשל ניירות ערך סחירים וכל עמלה שגובה מי שמבצע את משמרות ניירות הערך עמלות (קסטודיאן) | B12: =SUM(B13:B14) -> 87.951773
A13: א. סך עמלות קסטודיאן לצדדים קשורים
A14: ב. סך עמלות קסטודיאן לצדדים שאינם קשורים | B14: ='קרן ט'!B14+'קרן י'!B14+'הכשרה כללי'!B14+'הכשרה אגח ממשלות'!B14+'הכשרה מניות'!B14+'כספי שקלי'!B14+'הכשרה לבני 50 ומטה'!B14+'הכשרה לבני 50-60'!B14+'הכשרה לבני 60 ומעלה'!B14+'הכשרה מקבלי קצבה'!B14+'הכשרה אשראי ואג"ח'!B14+'הכשרה אשראי ואג"ח עד 25%'!B14+'הכשרה עוקב מדדים גמיש'!B14+'הכשרה משולב סחיר'!B14+'אלשטולר כללי'!B14+'אלשטושלר מניות'!B14+'אלטשולר אג"ח'!B14+'ילין כללי'!B14+'ילין מניות'!B14+'ילין אג"ח'!B14+'מיטב כללי'!B14+'מיטב מניות'!B14+'מיטב אג"ח'!B14+'פאסיבי כללי'!B14+'הכשרה עוקב מדד SP500'!B14+'מור כללי'!B14+'מור מניות'!B14+'מור אג"ח'!B14+'אנליסט כללי'!B14+'אנליסט מניות'!B14+'אנליסט אג"ח'!B14 -> 87.951773
A16: 3. סך הכל הוצאות הנובעות מהשקעות לא סחירות | B16: =SUM(B17:B19) -> 502.04772
A17: א. הוצאה הנובעת מהשקעה בניירות ערך לא סחירים או ממתן הלוואה למי שאינו עמית או מבוטח | B17: ='קרן ט'!B17+'קרן י'!B17+'הכשרה כללי'!B17+'הכשרה אגח ממשלות'!B17+'הכשרה מניות'!B17+'כספי שקלי'!B17+'הכשרה לבני 50 ומטה'!B17+'הכשרה לבני 50-60'!B17+'הכשרה לבני 60 ומעלה'!B17+'הכשרה מקבלי קצבה'!B17+'הכשרה אשראי ואג"ח'!B17+'הכשרה אשראי ואג"ח עד 25%'!B17+'הכשרה עוקב מדדים גמיש'!B17+'הכשרה משולב סחיר'!B17+'אלשטולר כללי'!B17+'אלשטושלר מניות'!B17+'אלטשולר אג"ח'!B17+'ילין כללי'!B17+'ילין מניות'!B17+'ילין אג"ח'!B17+'מיטב כללי'!B17+'מיטב מניות'!B17+'מיטב אג"ח'!B17+'פאסיבי כללי'!B17+'הכשרה עוקב מדד SP500'!B17+'מור כללי'!B17+'מור מניות'!B17+'מור אג"ח'!B17+'אנליסט כללי'!B17+'אנליסט מניות'!B17+'אנליסט אג"ח'!B17 -> 502.04772
A18: ב. הוצאה הנובעת מהשקעה בזכויות במקרקעין
A20: 4. מסים החלים על משקיע מוסדי, על נכסיו, על הכנסותיו ועל עסקאות שנעשו בנכסיו | B20: ='קרן ט'!B20+'קרן י'!B20+'הכשרה כללי'!B20+'הכשרה אגח ממשלות'!B20+'הכשרה מניות'!B20+'כספי שקלי'!B20+'הכשרה לבני 50 ומטה'!B20+'הכשרה לבני 50-60'!B20+'הכשרה לבני 60 ומעלה'!B20+'הכשרה מקבלי קצבה'!B20+'הכשרה אשראי ואג"ח'!B20+'הכשרה עוקב מדדים גמיש'!B20+'הכשרה משולב סחיר'!B20+'אלשטולר כללי'!B20+'אלשטושלר מניות'!B20+'אלטשולר אג"ח'!B20+'ילין כללי'!B20+'ילין מניות'!B20+'ילין אג"ח'!B20+'מיטב כללי'!B20+'מיטב מניות'!B20+'מיטב אג"ח'!B20+'הכשרה עוקב מדד SP500'!B20+'מור כללי'!B20+'מור מניות'!B20+'מור אג"ח'!B20+'אנליסט כללי'!B20+'אנליסט מניות'!B20+'אנליסט אג"ח'!B20 -> 0
A22: 5. סך הוצאות בעד ניהול תביעות | B22: ='קרן ט'!B22+'קרן י'!B22+'הכשרה כללי'!B22+'הכשרה אגח ממשלות'!B22+'הכשרה מניות'!B22+'כספי שקלי'!B22+'הכשרה לבני 50 ומטה'!B22+'הכשרה לבני 50-60'!B22+'הכשרה לבני 60 ומעלה'!B22+'הכשרה מקבלי קצבה'!B22+'הכשרה אשראי ואג"ח'!B22+'הכשרה עוקב מדדים גמיש'!B22+'הכשרה משולב סחיר'!B22+'אלשטולר כללי'!B22+'אלשטושלר מניות'!B22+'אלטשולר אג"ח'!B22+'ילין כללי'!B22+'ילין מניות'!B22+'ילין אג"ח'!B22+'מיטב כללי'!B22+'מיטב מניות'!B22+'מיטב אג"ח'!B22+'הכשרה עוקב מדד SP500'!B22+'מור כללי'!B22+'מור מניות'!B22+'מור אג"ח'!B22+'אנליסט כללי'!B22+'אנליסט מניות'!B22+'אנליסט אג"ח'!B22 -> 0
A24: 6. סך הוצאות בעד מתן משכנתאות | B24: ='קרן ט'!B24+'קרן י'!B24+'הכשרה כללי'!B24+'הכשרה אגח ממשלות'!B24+'הכשרה מניות'!B24+'כספי שקלי'!B24+'הכשרה לבני 50 ומטה'!B24+'הכשרה לבני 50-60'!B24+'הכשרה לבני 60 ומעלה'!B24+'הכשרה מקבלי קצבה'!B24+'הכשרה אשראי ואג"ח'!B24+'הכשרה עוקב מדדים גמיש'!B24+'הכשרה משולב סחיר'!B24+'אלשטולר כללי'!B24+'אלשטושלר מניות'!B24+'אלטשולר אג"ח'!B24+'ילין כללי'!B24+'ילין מניות'!B24+'ילין אג"ח'!B24+'מיטב כללי'!B24+'מיטב מניות'!B24+'מיטב אג"ח'!B24+'הכשרה עוקב מדד SP500'!B24+'מור כללי'!B24+'מור מניות'!B24+'מור אג"ח'!B24+'אנליסט כללי'!B24+'אנליסט מניות'!B24+'אנליסט אג"ח'!B24 -> 0
A26: 7. סך הכל הוצאות ישירות שאינן מסוג עמלת ניהול חיצוני (סכום סעיפים 1 עד 6) | B26: =B8+B12+B16+B20+B22+B24 -> 9315.8717
A28: 8. שווי ממוצע של נכסי הקופה או המסלול (ממוצע פשוט של סעיפים8א ו- 8ב) | B28: =(B29+B30)/2 -> 24040053
A29: א. השווי המשוערך של נכסי הקופה או המסלול נכון ליום 31 בדצמבר של שנת הכספים שהסתיימה 2024 | B29: ='קרן ט'!B29+'קרן י'!B29+'הכשרה כללי'!B29+'הכשרה אגח ממשלות'!B29+'הכשרה מניות'!B29+'כספי שקלי'!B29+'הכשרה לבני 50 ומטה'!B29+'הכשרה לבני 50-60'!B29+'הכשרה לבני 60 ומעלה'!B29+'הכשרה מקבלי קצבה'!B29+'הכשרה אשראי ואג"ח'!B29+'הכשרה אשראי ואג"ח עד 25%'!B29+'הכשרה עוקב מדדים גמיש'!B29+'הכשרה משולב סחיר'!B29+'אלשטולר כללי'!B29+'אלשטושלר מניות'!B29+'אלטשולר אג"ח'!B29+'ילין כללי'!B29+'ילין מניות'!B29+'ילין אג"ח'!B29+'מיטב כללי'!B29+'מיטב מניות'!B29+'מיטב אג"ח'!B29+'פאסיבי כללי'!B29+'הכשרה עוקב מדד SP500'!B29+'מור כללי'!B29+'מור מניות'!B29+'מור אג"ח'!B29+'אנליסט כללי'!B29+'אנליסט מניות'!B29+'אנליסט אג"ח'!B29 -> 26409167
A30: ב. השווי המשוערך של נכסי הקופה או המסלול נכון ליום 31 בדצמבר של שנת הכספים שהסתיימה לפני 2023 או לתקופה אחרת לפי העניין | B30: ='קרן ט'!B30+'קרן י'!B30+'הכשרה כללי'!B30+'הכשרה אגח ממשלות'!B30+'הכשרה מניות'!B30+'כספי שקלי'!B30+'הכשרה לבני 50 ומטה'!B30+'הכשרה לבני 50-60'!B30+'הכשרה לבני 60 ומעלה'!B30+'הכשרה מקבלי קצבה'!B30+'הכשרה אשראי ואג"ח'!B30+'הכשרה אשראי ואג"ח עד 25%'!B30+'הכשרה עוקב מדדים גמיש'!B30+'הכשרה משולב סחיר'!B30+'אלשטולר כללי'!B30+'אלשטושלר מניות'!B30+'אלטשולר אג"ח'!B30+'ילין כללי'!B30+'ילין מניות'!B30+'ילין אג"ח'!B30+'מיטב כללי'!B30+'מיטב מניות'!B30+'מיטב אג"ח'!B30+'פאסיבי כללי'!B30+'הכשרה עוקב מדד SP500'!B30+'מור כללי'!B30+'מור מניות'!B30+'מור אג"ח'!B30+'אנליסט כללי'!B30+'אנליסט מניות'!B30+'אנליסט אג"ח'!B30 -> 21670938
A32: 9. שיעור שנתי של הוצאות ישירות שאינן מסוג עמלת ניהול חיצוני (חלוקה של סעיף 7 בסעיף 8) | B32: =B26/B28 -> 0.00038751461
A34: הוצאות ישירות מסוג עמלת ניהול חיצוני
A35: 10 . סך דמי ניהול משתנים – החלק מתשלום עמלת ניהול חיצוני שנגזר מתשואת הנכסים | B35: ='קרן ט'!B35+'קרן י'!B35+'הכשרה כללי'!B35+'הכשרה אגח ממשלות'!B35+'הכשרה מניות'!B35+'כספי שקלי'!B35+'הכשרה לבני 50 ומטה'!B35+'הכשרה לבני 50-60'!B35+'הכשרה לבני 60 ומעלה'!B35+'הכשרה מקבלי קצבה'!B35+'הכשרה אשראי ואג"ח'!B35+'הכשרה עוקב מדדים גמיש'!B35+'הכשרה משולב סחיר'!B35+'אלשטולר כללי'!B35+'אלשטושלר מניות'!B35+'אלטשולר אג"ח'!B35+'ילין כללי'!B35+'ילין מניות'!B35+'ילין אג"ח'!B35+'מיטב כללי'!B35+'מיטב מניות'!B35+'מיטב אג"ח'!B35+'פאסיבי כללי'!B35+'הכשרה עוקב מדד SP500'!B35+'מור כללי'!B35+'מור מניות'!B35+'מור אג"ח'!B35+'אנליסט כללי'!B35+'אנליסט מניות'!B35+'אנליסט אג"ח'!B35 -> 11199.012
A37: 11. סה"כ הוצאות ישירות מסוג "עמלת ניהול חיצוני" (סכום סעיפים 11.א עד11.ט) | B37: =SUM(B38:B46) -> 24694.073
A38: א. סך תשלומים הנובעים מהשקעה בקרנות השקעה בישראל | B38: ='קרן ט'!B38+'קרן י'!B38+'הכשרה כללי'!B38+'הכשרה אגח ממשלות'!B38+'הכשרה מניות'!B38+'כספי שקלי'!B38+'הכשרה לבני 50 ומטה'!B38+'הכשרה לבני 50-60'!B38+'הכשרה לבני 60 ומעלה'!B38+'הכשרה מקבלי קצבה'!B38+'הכשרה אשראי ואג"ח'!B38+'הכשרה אשראי ואג"ח עד 25%'!B38+'הכשרה עוקב מדדים גמיש'!B38+'הכשרה משולב סחיר'!B38+'אלשטולר כללי'!B38+'אלשטושלר מניות'!B38+'אלטשולר אג"ח'!B38+'ילין כללי'!B38+'ילין מניות'!B38+'ילין אג"ח'!B38+'מיטב כללי'!B38+'מיטב מניות'!B38+'מיטב אג"ח'!B38+'פאסיבי כללי'!B38+'הכשרה עוקב מדד SP500'!B38+'מור כללי'!B38+'מור מניות'!B38+'מור אג"ח'!B38+'אנליסט כללי'!B38+'אנליסט מניות'!B38+'אנליסט אג"ח'!B38 -> 11568.279
A39: ב. סך תשלומים הנובעים מהשקעה בקרנות השקעה בחו"ל | B39: ='קרן ט'!B39+'קרן י'!B39+'הכשרה כללי'!B39+'הכשרה אגח ממשלות'!B39+'הכשרה מניות'!B39+'כספי שקלי'!B39+'הכשרה לבני 50 ומטה'!B39+'הכשרה לבני 50-60'!B39+'הכשרה לבני 60 ומעלה'!B39+'הכשרה מקבלי קצבה'!B39+'הכשרה אשראי ואג"ח'!B39+'הכשרה אשראי ואג"ח עד 25%'!B39+'הכשרה עוקב מדדים גמיש'!B39+'הכשרה משולב סחיר'!B39+'אלשטולר כללי'!B39+'אלשטושלר מניות'!B39+'אלטשולר אג"ח'!B39+'ילין כללי'!B39+'ילין מניות'!B39+'ילין אג"ח'!B39+'מיטב כללי'!B39+'מיטב מניות'!B39+'מיטב אג"ח'!B39+'פאסיבי כללי'!B39+'הכשרה עוקב מדד SP500'!B39+'מור כללי'!B39+'מור מניות'!B39+'מור אג"ח'!B39+'אנליסט כללי'!B39+'אנליסט מניות'!B39+'אנליסט אג"ח'!B39 -> 5539.3836
A40: ג. סך תשלומים למנהלי תיקים ישראלים בגין השקעה בחו"ל | B40: ='קרן ט'!B40+'קרן י'!B40+'הכשרה כללי'!B40+'הכשרה אגח ממשלות'!B40+'הכשרה מניות'!B40+'כספי שקלי'!B40+'הכשרה לבני 50 ומטה'!B40+'הכשרה לבני 50-60'!B40+'הכשרה לבני 60 ומעלה'!B40+'הכשרה מקבלי קצבה'!B40+'הכשרה אשראי ואג"ח'!B40+'הכשרה אשראי ואג"ח עד 25%'!B40+'הכשרה עוקב מדדים גמיש'!B40+'הכשרה משולב סחיר'!B40+'אלשטולר כללי'!B40+'אלשטושלר מניות'!B40+'אלטשולר אג"ח'!B40+'ילין כללי'!B40+'ילין מניות'!B40+'ילין אג"ח'!B40+'מיטב כללי'!B40+'מיטב מניות'!B40+'מיטב אג"ח'!B40+'פאסיבי כללי'!B40+'הכשרה עוקב מדד SP500'!B40+'מור כללי'!B40+'מור מניות'!B40+'מור אג"ח'!B40+'אנליסט כללי'!B40+'אנליסט מניות'!B40+'אנליסט אג"ח'!B40 -> 0
A41: ד. סך תשלומים למנהלי תיקים זרים | B41: ='קרן ט'!B41+'קרן י'!B41+'הכשרה כללי'!B41+'הכשרה אגח ממשלות'!B41+'הכשרה מניות'!B41+'כספי שקלי'!B41+'הכשרה לבני 50 ומטה'!B41+'הכשרה לבני 50-60'!B41+'הכשרה לבני 60 ומעלה'!B41+'הכשרה מקבלי קצבה'!B41+'הכשרה אשראי ואג"ח'!B41+'הכשרה אשראי ואג"ח עד 25%'!B41+'הכשרה עוקב מדדים גמיש'!B41+'הכשרה משולב סחיר'!B41+'אלשטולר כללי'!B41+'אלשטושלר מניות'!B41+'אלטשולר אג"ח'!B41+'ילין כללי'!B41+'ילין מניות'!B41+'ילין אג"ח'!B41+'מיטב כללי'!B41+'מיטב מניות'!B41+'מיטב אג"ח'!B41+'פאסיבי כללי'!B41+'הכשרה עוקב מדד SP500'!B41+'מור כללי'!B41+'מור מניות'!B41+'מור אג"ח'!B41+'אנליסט כללי'!B41+'אנליסט מניות'!B41+'אנליסט אג"ח'!B41 -> 0
A42: ה. סך תשלומים בגין השקעה בקרנות סל כאשר 75 אחוזים לפחות מנכסי הקרן הם נכסים שהונפקו במדינת ישראל לפי מדדים שעליהם הורה הממונה ובתנאים שהורה | B42: ='קרן ט'!B42+'קרן י'!B42+'הכשרה כללי'!B42+'הכשרה אגח ממשלות'!B42+'הכשרה מניות'!B42+'כספי שקלי'!B42+'הכשרה לבני 50 ומטה'!B42+'הכשרה לבני 50-60'!B42+'הכשרה לבני 60 ומעלה'!B42+'הכשרה מקבלי קצבה'!B42+'הכשרה אשראי ואג"ח'!B42+'הכשרה אשראי ואג"ח עד 25%'!B42+'הכשרה עוקב מדדים גמיש'!B42+'הכשרה משולב סחיר'!B42+'אלשטולר כללי'!B42+'אלשטושלר מניות'!B42+'אלטשולר אג"ח'!B42+'ילין כללי'!B42+'ילין מניות'!B42+'ילין אג"ח'!B42+'מיטב כללי'!B42+'מיטב מניות'!B42+'מיטב אג"ח'!B42+'פאסיבי כללי'!B42+'הכשרה עוקב מדד SP500'!B42+'מור כללי'!B42+'מור מניות'!B42+'מור אג"ח'!B42+'אנליסט כללי'!B42+'אנליסט מניות'!B42+'אנליסט אג"ח'!B42 -> 82.813403
A43: ו. סך תשלומים בגין השקעה בקרנות סל כאשר 75 אחוזים לפחות מנכסי הקרן הם נכסים שלא הונפקו במדינת ישראל ואינם נסחרים או מוחזקים בה | B43: ='קרן ט'!B43+'קרן י'!B43+'הכשרה כללי'!B43+'הכשרה אגח ממשלות'!B43+'הכשרה מניות'!B43+'כספי שקלי'!B43+'הכשרה לבני 50 ומטה'!B43+'הכשרה לבני 50-60'!B43+'הכשרה לבני 60 ומעלה'!B43+'הכשרה מקבלי קצבה'!B43+'הכשרה אשראי ואג"ח'!B43+'הכשרה אשראי ואג"ח עד 25%'!B43+'הכשרה עוקב מדדים גמיש'!B43+'הכשרה משולב סחיר'!B43+'אלשטולר כללי'!B43+'אלשטושלר מניות'!B43+'אלטשולר אג"ח'!B43+'ילין כללי'!B43+'ילין מניות'!B43+'ילין אג"ח'!B43+'מיטב כללי'!B43+'מיטב מניות'!B43+'מיטב אג"ח'!B43+'פאסיבי כללי'!B43+'הכשרה עוקב מדד SP500'!B43+'מור כללי'!B43+'מור מניות'!B43+'מור אג"ח'!B43+'אנליסט כללי'!B43+'אנליסט מניות'!B43+'אנליסט אג"ח'!B43 -> 4362.7231
A44: ז. סך תשלומים בגין השקעה בקרנות נאמנות ישראליות כאשר 75 אחוזים לפחות מנכסי הקרן מושקעים בנכסים שלא הונפקו במדינת ישראל ואינם נסחרים או מוחזקים בה | B44: ='קרן ט'!B44+'קרן י'!B44+'הכשרה כללי'!B44+'הכשרה אגח ממשלות'!B44+'הכשרה מניות'!B44+'כספי שקלי'!B44+'הכשרה לבני 50 ומטה'!B44+'הכשרה לבני 50-60'!B44+'הכשרה לבני 60 ומעלה'!B44+'הכשרה מקבלי קצבה'!B44+'הכשרה אשראי ואג"ח'!B44+'הכשרה אשראי ואג"ח עד 25%'!B44+'הכשרה עוקב מדדים גמיש'!B44+'הכשרה משולב סחיר'!B44+'אלשטולר כללי'!B44+'אלשטושלר מניות'!B44+'אלטשולר אג"ח'!B44+'ילין כללי'!B44+'ילין מניות'!B44+'ילין אג"ח'!B44+'מיטב כללי'!B44+'מיטב מניות'!B44+'מיטב אג"ח'!B44+'פאסיבי כללי'!B44+'הכשרה עוקב מדד SP500'!B44+'מור כללי'!B44+'מור מניות'!B44+'מור אג"ח'!B44+'אנליסט כללי'!B44+'אנליסט מניות'!B44+'אנליסט אג"ח'!B44 -> 169.82702
A45: ח. סך תשלומים בגין השקעה בקרנות נאמנות זרות כאשר 75 אחוזים לפחות מנכסי הקרן מושקעים בנכסים שלא הונפקו במדינת ישראל ואינם נסחרים או מוחזקים בה | B45: ='קרן ט'!B45+'קרן י'!B45+'הכשרה כללי'!B45+'הכשרה אגח ממשלות'!B45+'הכשרה מניות'!B45+'כספי שקלי'!B45+'הכשרה לבני 50 ומטה'!B45+'הכשרה לבני 50-60'!B45+'הכשרה לבני 60 ומעלה'!B45+'הכשרה מקבלי קצבה'!B45+'הכשרה אשראי ואג"ח'!B45+'הכשרה אשראי ואג"ח עד 25%'!B45+'הכשרה עוקב מדדים גמיש'!B45+'הכשרה משולב סחיר'!B45+'אלשטולר כללי'!B45+'אלשטושלר מניות'!B45+'אלטשולר אג"ח'!B45+'ילין כללי'!B45+'ילין מניות'!B45+'ילין אג"ח'!B45+'מיטב כללי'!B45+'מיטב מניות'!B45+'מיטב אג"ח'!B45+'פאסיבי כללי'!B45+'הכשרה עוקב מדד SP500'!B45+'מור כללי'!B45+'מור מניות'!B45+'מור אג"ח'!B45+'אנליסט כללי'!B45+'אנליסט מניות'!B45+'אנליסט אג"ח'!B45 -> 2960.7475
A46: ט. סך תשלומים בגין השקעה בקרן טכנולוגיה עילית | B46: ='קרן ט'!B46+'קרן י'!B46+'הכשרה כללי'!B46+'הכשרה אגח ממשלות'!B46+'הכשרה מניות'!B46+'כספי שקלי'!B46+'הכשרה לבני 50 ומטה'!B46+'הכשרה לבני 50-60'!B46+'הכשרה לבני 60 ומעלה'!B46+'הכשרה מקבלי קצבה'!B46+'הכשרה אשראי ואג"ח'!B46+'הכשרה אשראי ואג"ח עד 25%'!B46+'הכשרה עוקב מדדים גמיש'!B46+'הכשרה משולב סחיר'!B46+'אלשטולר כללי'!B46+'אלשטושלר מניות'!B46+'אלטשולר אג"ח'!B46+'ילין כללי'!B46+'ילין מניות'!B46+'ילין אג"ח'!B46+'מיטב כללי'!B46+'מיטב מניות'!B46+'מיטב אג"ח'!B46+'פאסיבי כללי'!B46+'הכשרה עוקב מדד SP500'!B46+'מור כללי'!B46+'מור מניות'!B46+'מור אג"ח'!B46+'אנליסט כללי'!B46+'אנליסט מניות'!B46+'אנליסט אג"ח'!B46 -> 10.300035
A48: 12. שיעור עמלת ניהול חיצוני בפועל לפני החזר, ככל שבוצע (חלוקה של סעיף 11 בסעיף 8.ב) | B48: =B37/B30 -> 0.0011395018
A50: 13. שיעור מגבלת עמלת ניהול חיצוני שהמשקיע המוסדי הצהיר עליה עבור שנת הכספים שהסתיימה
A52: 14. ההפרש בין שיעור מגבלת עמלת ניהול חיצוני מוצהרת לבין שיעור עמלת ניהול חיצוני בפועל (סעיף 13 פחות סעיף 12)
A54: 15.א סכום שהוחזר לחוסכים (אם הוחזר) | B54: ='קרן ט'!B54+'קרן י'!B54+'הכשרה כללי'!B54+'הכשרה אגח ממשלות'!B54+'הכשרה מניות'!B54+'כספי שקלי'!B54+'הכשרה לבני 50 ומטה'!B54+'הכשרה לבני 50-60'!B54+'הכשרה לבני 60 ומעלה'!B54+'הכשרה מקבלי קצבה'!B54+'הכשרה אשראי ואג"ח'!B54+'הכשרה עוקב מדדים גמיש'!B54+'הכשרה משולב סחיר'!B54+'אלשטולר כללי'!B54+'אלשטושלר מניות'!B54+'אלטשולר אג"ח'!B54+'ילין כללי'!B54+'ילין מניות'!B54+'ילין אג"ח'!B54+'מיטב כללי'!B54+'מיטב מניות'!B54+'מיטב אג"ח'!B54+'פאסיבי כללי'!B54+'הכשרה עוקב מדד SP500'!B54+'מור כללי'!B54+'מור מניות'!B54+'מור אג"ח'!B54+'אנליסט כללי'!B54+'אנליסט מניות'!B54+'אנליסט אג"ח'!B54 -> 0
A55: 15.ב שיעור עמלת ניהול חיצוני בפועל לאחר החזר, (חלוקה של התוצאה של סעיף 11 בניכוי סעיף 15א, בסעיף 8.ב)
A57: סך הכל הוצאות ישירות בפועל (למעט דמי ניהול משתנים כאמור בסעיף 10)
A59: 16. סך כל הוצאות ישירות (סכום של סעיף 7 וסעיף 1 1בניכוי סעיף 15א) | B59: =B26+B37-B54 -> 34009.945
...

Sheet קרן ט
A1: נספח 1- סך ההוצאות הישירות ששולמו בעד כל סוג של הוצאה ישירה לתקופה המסתיימת ביום 31.12.2024
A3: שם חברת הביטוח: הכשרה חברה לביטוח - קרן ט | B3: אלפי ₪
A5: 31.12.2024 נספח 1- סך ההוצאות הישירות ששולמו בעד כל סוג של הוצאה ישירה לתקופה המסתיימת ביום
A7: הוצאות ישירות שאינן מסוג עמלת ניהול חיצוני
A8: 1. סך הכל עמלות קנייה ומכירה של ניירות ערך סחירים | B8: 21.957283
A9: א. סך עמלות קנייה ומכירה של ניירות ערך סחירים לצדדים קשורים
A10: ב. סך עמלות קנייה ומכירה של ניירות ערך סחירים לצדדים שאינם קשורים | B10: 21.957283
A12: 2. סך הכל דמי שמירה בשל ניירות ערך סחירים וכל עמלה שגובה מי שמבצע את משמרות ניירות הערך עמלות (קסטודיאן) | B12: 1.7039316
A13: א. סך עמלות קסטודיאן לצדדים קשורים
A14: ב. סך עמלות קסטודיאן לצדדים שאינם קשורים | B14: 1.7039316
A16: 3. סך הכל הוצאות הנובעות מהשקעות לא סחירות | B16: 5.5860765
A17: א. הוצאה הנובעת מהשקעה בניירות ערך לא סחירים או ממתן הלוואה למי שאינו עמית או מבוטח | B17: 5.5860765
A18: ב. הוצאה הנובעת מהשקעה בזכויות במקרקעין
A20: 4. מסים החלים על משקיע מוסדי, על נכסיו, על הכנסותיו ועל עסקאות שנעשו בנכסיו
A22: 5. סך הוצאות בעד ניהול תביעות | B22: 0
A24: 6. סך הוצאות בעד מתן משכנתאות | B24: 0
A26: 7. סך הכל הוצאות ישירות שאינן מסוג עמלת ניהול חיצוני (סכום סעיפים 1 עד 6) | B26: 29.247291
A28: 8. שווי ממוצע של נכסי הקופה או המסלול (ממוצע פשוט של סעיפים8א ו- 8ב) | B28: 69121.165
A29: א. השווי המשוערך של נכסי הקופה או המסלול נכון ליום 31 בדצמבר של שנת הכספים שהסתיימה 2024 | B29: 67335.36
A30: ב. השווי המשוערך של נכסי הקופה או המסלול נכון ליום 31 בדצמבר של שנת הכספים שהסתיימה לפני 2023 או לתקופה אחרת לפי העניין | B30: 70906.97
A32: 9. שיעור שנתי של הוצאות ישירות שאינן מסוג עמלת ניהול חיצוני (חלוקה של סעיף 7 בסעיף 8) | B32: 0.00042313076
A34: הוצאות ישירות מסוג עמלת ניהול חיצוני
A35: 10 . סך דמי ניהול משתנים – החלק מתשלום עמלת ניהול חיצוני שנגזר מתשואת הנכסים | B35: 64.705215
A37: 11. סה"כ הוצאות ישירות מסוג "עמלת ניהול חיצוני" (סכום סעיפים 11.א עד11.ט) | B37: 98.004597
A38: א. סך תשלומים הנובעים מהשקעה בקרנות השקעה בישראל | B38: 43.417954
A39: ב. סך תשלומים הנובעים מהשקעה בקרנות השקעה בחו"ל | B39: 21.281216
A40: ג. סך תשלומים למנהלי תיקים ישראלים בגין השקעה בחו"ל
A41: ד. סך תשלומים למנהלי תיקים זרים
A42: ה. סך תשלומים בגין השקעה בקרנות סל כאשר 75 אחוזים לפחות מנכסי הקרן הם נכסים שהונפקו במדינת ישראל לפי מדדים שעליהם הורה הממונה ובתנאים שהורה | B42: 0.49231703
A43: ו. סך תשלומים בגין השקעה בקרנות סל כאשר 75 אחוזים לפחות מנכסי הקרן הם נכסים שלא הונפקו במדינת ישראל ואינם נסחרים או מוחזקים בה | B43: 17.481537
A44: ז. סך תשלומים בגין השקעה בקרנות נאמנות ישראליות כאשר 75 אחוזים לפחות מנכסי הקרן מושקעים בנכסים שלא הונפקו במדינת ישראל ואינם נסחרים או מוחזקים בה | B44: 0.99697831
A45: ח. סך תשלומים בגין השקעה בקרנות נאמנות זרות כאשר 75 אחוזים לפחות מנכסי הקרן מושקעים בנכסים שלא הונפקו במדינת ישראל ואינם נסחרים או מוחזקים בה | B45: 14.161295
A46: ט. סך תשלומים בגין השקעה בקרן טכנולוגיה עילית | B46: 0.17330019
A48: 12. שיעור עמלת ניהול חיצוני בפועל לפני החזר, ככל שבוצע (חלוקה של סעיף 11 בסעיף 8.ב) | B48: 0.0013821575
A50: 13. שיעור מגבלת עמלת ניהול חיצוני שהמשקיע המוסדי הצהיר עליה עבור שנת הכספים שהסתיימה | B50: 0.0025
A52: 14. ההפרש בין שיעור מגבלת עמלת ניהול חיצוני מוצהרת לבין שיעור עמלת ניהול חיצוני בפועל (סעיף 13 פחות סעיף 12) | B52: 0.0011178425
A54: 15.א סכום שהוחזר לחוסכים (אם הוחזר) | B54: 0
A55: 15.ב שיעור עמלת ניהול חיצוני בפועל לאחר החזר, (חלוקה של התוצאה של סעיף 11 בניכוי סעיף 15א, בסעיף 8.ב) | B55: 0.0013821575
A57: סך הכל הוצאות ישירות בפועל (למעט דמי ניהול משתנים כאמור בסעיף 10)
A59: 16. סך כל הוצאות ישירות (סכום של סעיף 7 וסעיף 11 בניכוי סעיף 15א) | B59: 127.25189
...

Sheet קרן י
A1: נספח 1- סך ההוצאות הישירות ששולמו בעד כל סוג של הוצאה ישירה לתקופה המסתיימת ביום 31.12.2024
A3: שם חברת הביטוח: הכשרה חברה לביטוח - קרן י | B3: אלפי ₪
A5: 31.12.2024 נספח 1- סך ההוצאות הישירות ששולמו בעד כל סוג של הוצאה ישירה לתקופה המסתיימת ביום
A7: הוצאות ישירות שאינן מסוג עמלת ניהול חיצוני
A8: 1. סך הכל עמלות קנייה ומכירה של ניירות ערך סחירים | B8: 524.13595
A9: א. סך עמלות קנייה ומכירה של ניירות ערך סחירים לצדדים קשורים
A10: ב. סך עמלות קנייה ומכירה של ניירות ערך סחירים לצדדים שאינם קשורים | B10: 524.13595
A12: 2. סך הכל דמי שמירה בשל ניירות ערך סחירים וכל עמלה שגובה מי שמבצע את משמרות ניירות הערך עמלות (קסטודיאן) | B12: 6.175063
A13: א. סך עמלות קסטודיאן לצדדים קשורים
A14: ב. סך עמלות קסטודיאן לצדדים שאינם קשורים | B14: 6.175063
A16: 3. סך הכל הוצאות הנובעות מהשקעות לא סחירות | B16: 162.92571
A17: א. הוצאה הנובעת מהשקעה בניירות ערך לא סחירים או ממתן הלוואה למי שאינו עמית או מבוטח | B17: 162.92571
A18: ב. הוצאה הנובעת מהשקעה בזכויות במקרקעין | B18: 0
A20: 4. מסים החלים על משקיע מוסדי, על נכסיו, על הכנסותיו ועל עסקאות שנעשו בנכסיו
A22: 5. סך הוצאות בעד ניהול תביעות | B22: 0
A24: 6. סך הוצאות בעד מתן משכנתאות | B24: 0
A26: 7. סך הכל הוצאות ישירות שאינן מסוג עמלת ניהול חיצוני (סכום סעיפים 1 עד 6) | B26: 693.23672
A28: 8. שווי ממוצע של נכסי הקופה או המסלול (ממוצע פשוט של סעיפים8א ו- 8ב) | B28: 1789110.5
A29: א. השווי המשוערך של נכסי הקופה או המסלול נכון ליום 31 בדצמבר של שנת הכספים שהסתיימה 2024 | B29: 1846452.8
A30: ב. השווי המשוערך של נכסי הקופה או המסלול נכון ליום 31 בדצמבר של שנת הכספים שהסתיימה לפני 2023 או לתקופה אחרת לפי העניין | B30: 1731768.3
A32: 9. שיעור שנתי של הוצאות ישירות שאינן מסוג עמלת ניהול חיצוני (חלוקה של סעיף 7 בסעיף 8) | B32: 0.00038747562
A34: הוצאות ישירות מסוג עמלת ניהול חיצוני
A35: 10 . סך דמי ניהול משתנים – החלק מתשלום עמלת ניהול חיצוני שנגזר מתשואת הנכסים | B35: 3110.3704
A37: 11. סה"כ הוצאות ישירות מסוג "עמלת ניהול חיצוני" (סכום סעיפים 11.א עד11.ט) | B37: 5431.0036
A38: א. סך תשלומים הנובעים מהשקעה בקרנות השקעה בישראל | B38: 3350.7025
A39: ב. סך תשלומים הנובעים מהשקעה בקרנות השקעה בחו"ל | B39: 1364.2336
A40: ג. סך תשלומים למנהלי תיקים ישראלים בגין השקעה בחו"ל
A41: ד. סך תשלומים למנהלי תיקים זרים
A42: ה. סך תשלומים בגין השקעה בקרנות סל כאשר 75 אחוזים לפחות מנכסי הקרן הם נכסים שהונפקו במדינת ישראל לפי מדדים שעליהם הורה הממונה ובתנאים שהורה | B42: 5.9690821
A43: ו. סך תשלומים בגין השקעה בקרנות סל כאשר 75 אחוזים לפחות מנכסי הקרן הם נכסים שלא הונפקו במדינת ישראל ואינם נסחרים או מוחזקים בה | B43: 249.89058
A44: ז. סך תשלומים בגין השקעה בקרנות נאמנות ישראליות כאשר 75 אחוזים לפחות מנכסי הקרן מושקעים בנכסים שלא הונפקו במדינת ישראל ואינם נסחרים או מוחזקים בה | B44: 25.043292
A45: ח. סך תשלומים בגין השקעה בקרנות נאמנות זרות כאשר 75 אחוזים לפחות מנכסי הקרן מושקעים בנכסים שלא הונפקו במדינת ישראל ואינם נסחרים או מוחזקים בה | B45: 431.04344
A46: ט. סך תשלומים בגין השקעה בקרן טכנולוגיה עילית | B46: 4.1211095
A48: 12. שיעור עמלת ניהול חיצוני בפועל לפני החזר, ככל שבוצע (חלוקה של סעיף 11 בסעיף 8.ב) | B48: 0.003136103
A50: 13. שיעור מגבלת עמלת ניהול חיצוני שהמשקיע המוסדי הצהיר עליה עבור שנת הכספים שהסתיימה | B50: 0.0035
A52: 14. ההפרש בין שיעור מגבלת עמלת ניהול חיצוני מוצהרת לבין שיעור עמלת ניהול חיצוני בפועל (סעיף 13 פחות סעיף 12) | B52: 0.00036389702
A54: 15.א סכום שהוחזר לחוסכים (אם הוחזר) | B54: 0
A55: 15.ב שיעור עמלת ניהול חיצוני בפועל לאחר החזר, (חלוקה של התוצאה של סעיף 11 בניכוי סעיף 15א, בסעיף 8.ב) | B55: 0.003136103
A57: סך הכל הוצאות ישירות בפועל (למעט דמי ניהול משתנים כאמור בסעיף 10)
A59: 16. סך כל הוצאות ישירות (סכום של סעיף 7 וסעיף 11 בניכוי סעיף 15א) | B59: 6124.2403
...

Sheet הכשרה כללי
A1: נספח 1- סך ההוצאות הישירות ששולמו בעד כל סוג של הוצאה ישירה לתקופה המסתיימת ביום 31.12.2024
A3: שם חברת הביטוח: הכשרה חברה לביטוח - מסלולית כללית | B3: אלפי ₪
A5: 31.12.2024 נספח 1- סך ההוצאות הישירות ששולמו בעד כל סוג של הוצאה ישירה לתקופה המסתיימת ביום
A7: הוצאות ישירות שאינן מסוג עמלת ניהול חיצוני
A8: 1. סך הכל עמלות קנייה ומכירה של ניירות ערך סחירים | B8: 1392.6259
A9: א. סך עמלות קנייה ומכירה של ניירות ערך סחירים לצדדים קשורים
A10: ב. סך עמלות קנייה ומכירה של ניירות ערך סחירים לצדדים שאינם קשורים | B10: 1392.6259
A12: 2. סך הכל דמי שמירה בשל ניירות ערך סחירים וכל עמלה שגובה מי שמבצע את משמרות ניירות הערך עמלות (קסטודיאן) | B12: 6.7788716
A13: א. סך עמלות קסטודיאן לצדדים קשורים
A14: ב. סך עמלות קסטודיאן לצדדים שאינם קשורים | B14: 6.7788716
A16: 3. סך הכל הוצאות הנובעות מהשקעות לא סחירות | B16: 249.18992
A17: א. הוצאה הנובעת מהשקעה בניירות ערך לא סחירים או ממתן הלוואה למי שאינו עמית או מבוטח | B17: 249.18992
A18: ב. הוצאה הנובעת מהשקעה בזכויות במקרקעין
A20: 4. מסים החלים על משקיע מוסדי, על נכסיו, על הכנסותיו ועל עסקאות שנעשו בנכסיו
A22: 5. סך הוצאות בעד ניהול תביעות | B22: 0
A24: 6. סך הוצאות בעד מתן משכנתאות | B24: 0
A26: 7. סך הכל הוצאות ישירות שאינן מסוג עמלת ניהול חיצוני (סכום סעיפים 1 עד 6) | B26: 1648.5947
A28: 8. שווי ממוצע של נכסי הקופה או המסלול (ממוצע פשוט של סעיפים8א ו- 8ב) | B28: 4481964.3
A29: א. השווי המשוערך של נכסי הקופה או המסלול נכון ליום 31 בדצמבר של שנת הכספים שהסתיימה 2024 | B29: 4580556.2
A30: ב. השווי המשוערך של נכסי הקופה או המסלול נכון ליום 31 בדצמבר של שנת הכספים שהסתיימה לפני 2023 או לתקופה אחרת לפי העניין | B30: 4383372.5
A32: 9. שיעור שנתי של הוצאות ישירות שאינן מסוג עמלת ניהול חיצוני (חלוקה של סעיף 7 בסעיף 8) | B32: 0.00036782861
A34: הוצאות ישירות מסוג עמלת ניהול חיצוני
A35: 10 . סך דמי ניהול משתנים – החלק מתשלום עמלת ניהול חיצוני שנגזר מתשואת הנכסים | B35: 5703.8754
A37: 11. סה"כ הוצאות ישירות מסוג "עמלת ניהול חיצוני" (סכום סעיפים 11.א עד11.ט) | B37: 10786.521
A38: א. סך תשלומים הנובעים מהשקעה בקרנות השקעה בישראל | B38: 6187.2683
A39: ב. סך תשלומים הנובעים מהשקעה בקרנות השקעה בחו"ל | B39: 2849.7779
A40: ג. סך תשלומים למנהלי תיקים ישראלים בגין השקעה בחו"ל | B40: 0
A41: ד. סך תשלומים למנהלי תיקים זרים | B41: 0
A42: ה. סך תשלומים בגין השקעה בקרנות סל כאשר 75 אחוזים לפחות מנכסי הקרן הם נכסים שהונפקו במדינת ישראל לפי מדדים שעליהם הורה הממונה ובתנאים שהורה | B42: 48.55245
A43: ו. סך תשלומים בגין השקעה בקרנות סל כאשר 75 אחוזים לפחות מנכסי הקרן הם נכסים שלא הונפקו במדינת ישראל ואינם נסחרים או מוחזקים בה | B43: 758.72196
A44: ז. סך תשלומים בגין השקעה בקרנות נאמנות ישראליות כאשר 75 אחוזים לפחות מנכסי הקרן מושקעים בנכסים שלא הונפקו במדינת ישראל ואינם נסחרים או מוחזקים בה | B44: 63.158422
A45: ח. סך תשלומים בגין השקעה בקרנות נאמנות זרות כאשר 75 אחוזים לפחות מנכסי הקרן מושקעים בנכסים שלא הונפקו במדינת ישראל ואינם נסחרים או מוחזקים בה | B45: 874.3183
A46: ט. סך תשלומים בגין השקעה בקרן טכנולוגיה עילית | B46: 4.7236137
A48: 12. שיעור עמלת ניהול חיצוני בפועל לפני החזר, ככל שבוצע (חלוקה של סעיף 11 בסעיף 8.ב) | B48: 0.0024607813
... A52: 14. ההפרש בין שיעור מגבלת עמלת ניהול חיצוני מוצהרת לבין שיעור עמלת ניהול חיצוני בפועל (סעיף 13 פחות סעיף 12) | B52: 3.9218747e-05
A54: 15.א סכום שהוחזר לחוסכים (אם הוחזר)
A55: 15.ב שיעור עמלת ניהול חיצוני בפועל לאחר החזר, (חלוקה של התוצאה של סעיף 11 בניכוי סעיף 15א, בסעיף 8.ב) | B55: 0.0024607813
A57: סך הכל הוצאות ישירות בפועל (למעט דמי ניהול משתנים כאמור בסעיף 10)
A59: 16. סך כל הוצאות ישירות (סכום של סעיף 7 וסעיף 11 בניכוי סעיף 15א) | B59: 12435.116
A61: 17. שיעור סך ההוצאות הישירות מתוך יתרת נכסים ממוצעת (חלוקה של סעיף 16 בסעיף 8) | B61: 0.0027744789
...

Sheet הכשרה אגח ממשלות
A1: נספח 1- סך ההוצאות הישירות ששולמו בעד כל סוג של הוצאה ישירה לתקופה המסתיימת ביום 31.12.2024
A3: שם חברת הביטוח: הכשרה חברה לביטוח - מסלולית אג"ח ממשלות | B3: אלפי ₪
A5: 31.12.2024 נספח 1- סך ההוצאות הישירות ששולמו בעד כל סוג של הוצאה ישירה לתקופה המסתיימת ביום
A7: הוצאות ישירות שאינן מסוג עמלת ניהול חיצוני
A8: 1. סך הכל עמלות קנייה ומכירה של ניירות ערך סחירים | B8: 175.99353
A9: א. סך עמלות קנייה ומכירה של ניירות ערך סחירים לצדדים קשורים
A10: ב. סך עמלות קנייה ומכירה של ניירות ערך סחירים לצדדים שאינם קשורים | B10: 175.99353
A12: 2. סך הכל דמי שמירה בשל ניירות ערך סחירים וכל עמלה שגובה מי שמבצע את משמרות ניירות הערך עמלות (קסטודיאן) | B12: 1.8345521
A13: א. סך עמלות קסטודיאן לצדדים קשורים
A14: ב. סך עמלות קסטודיאן לצדדים שאינם קשורים | B14: 1.8345521
A16: 3. סך הכל הוצאות הנובעות מהשקעות לא סחירות | B16: 24.168117
A17: א. הוצאה הנובעת מהשקעה בניירות ערך לא סחירים או ממתן הלוואה למי שאינו עמית או מבוטח | B17: 24.168117
A18: ב. הוצאה הנובעת מהשקעה בזכויות במקרקעין
A20: 4. מסים החלים על משקיע מוסדי, על נכסיו, על הכנסותיו ועל עסקאות שנעשו בנכסיו
A22: 5. סך הוצאות בעד ניהול תביעות | B22: 0
A24: 6. סך הוצאות בעד מתן משכנתאות | B24: 0
A26: 7. סך הכל הוצאות ישירות שאינן מסוג עמלת ניהול חיצוני (סכום סעיפים 1 עד 6) | B26: 201.9962
A28: 8. שווי ממוצע של נכסי הקופה או המסלול (ממוצע פשוט של סעיפים8א ו- 8ב) | B28: 395417.09
A29: א. השווי המשוערך של נכסי הקופה או המסלול נכון ליום 31 בדצמבר של שנת הכספים שהסתיימה 2024 | B29: 362986.56
A30: ב. השווי המשוערך של נכסי הקופה או המסלול נכון ליום 31 בדצמבר של שנת הכספים שהסתיימה לפני 2023 או לתקופה אחרת לפי העניין | B30: 427847.62
A32: 9. שיעור שנתי של הוצאות ישירות שאינן מסוג עמלת ניהול חיצוני (חלוקה של סעיף 7 בסעיף 8) | B32: 0.00051084337
A34: הוצאות ישירות מסוג עמלת ניהול חיצוני
A35: 10 . סך דמי ניהול משתנים – החלק מתשלום עמלת ניהול חיצוני שנגזר מתשואת הנכסים | B35: 219.67657
A37: 11. סה"כ הוצאות ישירות מסוג "עמלת ניהול חיצוני" (סכום סעיפים 11.א עד11.ט) | B37: 331.76259
A38: א. סך תשלומים הנובעים מהשקעה בקרנות השקעה בישראל | B38: 180.49285
A39: ב. סך תשלומים הנובעים מהשקעה בקרנות השקעה בחו"ל | B39: 105.76467
A40: ג. סך תשלומים למנהלי תיקים ישראלים בגין השקעה בחו"ל | B40: 0
A41: ד. סך תשלומים למנהלי תיקים זרים | B41: 0
A42: ה. סך תשלומים בגין השקעה בקרנות סל כאשר 75 אחוזים לפחות מנכסי הקרן הם נכסים שהונפקו במדינת ישראל לפי מדדים שעליהם הורה הממונה ובתנאים שהורה | B42: 0
A43: ו. סך תשלומים בגין השקעה בקרנות סל כאשר 75 אחוזים לפחות מנכסי הקרן הם נכסים שלא הונפקו במדינת ישראל ואינם נסחרים או מוחזקים בה | B43: 12.992987
A44: ז. סך תשלומים בגין השקעה בקרנות נאמנות ישראליות כאשר 75 אחוזים לפחות מנכסי הקרן מושקעים בנכסים שלא הונפקו במדינת ישראל ואינם נסחרים או מוחזקים בה | B44: 0
A45: ח. סך תשלומים בגין השקעה בקרנות נאמנות זרות כאשר 75 אחוזים לפחות מנכסי הקרן מושקעים בנכסים שלא הונפקו במדינת ישראל ואינם נסחרים או מוחזקים בה | B45: 32.335621
A46: ט. סך תשלומים בגין השקעה בקרן טכנולוגיה עילית | B46: 0.17645211
A48: 12. שיעור עמלת ניהול חיצוני בפועל לפני החזר, ככל שבוצע (חלוקה של סעיף 11 בסעיף 8.ב) | B48: 0.00077542229
... A55: 15.ב שיעור עמלת ניהול חיצוני בפועל לאחר החזר, (חלוקה של התוצאה של סעיף 11 בניכוי סעיף 15א, בסעיף 8.ב) | B55: 0.00077542229
A57: סך הכל הוצאות ישירות בפועל (למעט דמי ניהול משתנים כאמור בסעיף 10)
A59: 16. סך כל הוצאות ישירות (סכום של סעיף 7 וסעיף 11 בניכוי סעיף 15א) | B59: 533.75879
A61: 17. שיעור סך ההוצאות הישירות מתוך יתרת נכסים ממוצעת (חלוקה של סעיף 16 בסעיף 8) | B61: 0.0013498627
A63: סך הכל הוצאות ישירות (לצורך חישוב שיעור עלות שנתית צפויה)
A64: 18. שיעור מגבלת עמלת ניהול חיצוני שהמשקיע המוסדי הצהיר עליה בהתאם לתקנה 2א לתקנות הוצאות ישירות עבור שנת הכספים הבאה | B64: 0.0015
...

Sheet הכשרה מניות
A1: נספח 1- סך ההוצאות הישירות ששולמו בעד כל סוג של הוצאה ישירה לתקופה המסתיימת ביום 31.12.2024
A3: שם חברת הביטוח: הכשרה חברה לביטוח - מסלולית מניות | B3: אלפי ₪
A5: 31.12.2024 נספח 1- סך ההוצאות הישירות ששולמו בעד כל סוג של הוצאה ישירה לתקופה המסתיימת ביום
A7: הוצאות ישירות שאינן מסוג עמלת ניהול חיצוני
A8: 1. סך הכל עמלות קנייה ומכירה של ניירות ערך סחירים | B8: 307.87761
A9: א. סך עמלות קנייה ומכירה של ניירות ערך סחירים לצדדים קשורים
A10: ב. סך עמלות קנייה ומכירה של ניירות ערך סחירים לצדדים שאינם קשורים | B10: 307.87761
A12: 2. סך הכל דמי שמירה בשל ניירות ערך סחירים וכל עמלה שגובה מי שמבצע את משמרות ניירות הערך עמלות (קסטודיאן) | B12: 3.6120443
A13: א. סך עמלות קסטודיאן לצדדים קשורים
A14: ב. סך עמלות קסטודיאן לצדדים שאינם קשורים | B14: 3.6120443
A16: 3. סך הכל הוצאות הנובעות מהשקעות לא סחירות | B16: 11.441104
A17: א. הוצאה הנובעת מהשקעה בניירות ערך לא סחירים או ממתן הלוואה למי שאינו עמית או מבוטח | B17: 11.441104
A18: ב. הוצאה הנובעת מהשקעה בזכויות במקרקעין
A20: 4. מסים החלים על משקיע מוסדי, על נכסיו, על הכנסותיו ועל עסקאות שנעשו בנכסיו
A22: 5. סך הוצאות בעד ניהול תביעות | B22: 0
A24: 6. סך הוצאות בעד מתן משכנתאות | B24: 0
A26: 7. סך הכל הוצאות ישירות שאינן מסוג עמלת ניהול חיצוני (סכום סעיפים 1 עד 6) | B26: 322.93076
A28: 8. שווי ממוצע של נכסי הקופה או המסלול (ממוצע פשוט של סעיפים8א ו- 8ב) | B28: 376747.19
A29: א. השווי המשוערך של נכסי הקופה או המסלול נכון ליום 31 בדצמבר של שנת הכספים שהסתיימה 2024 | B29: 416699.53
A30: ב. השווי המשוערך של נכסי הקופה או המסלול נכון ליום 31 בדצמבר של שנת הכספים שהסתיימה לפני 2023 או לתקופה אחרת לפי העניין | B30: 336794.85
A32: 9. שיעור שנתי של הוצאות ישירות שאינן מסוג עמלת ניהול חיצוני (חלוקה של סעיף 7 בסעיף 8) | B32: 0.00085715507
A34: הוצאות ישירות מסוג עמלת ניהול חיצוני
A35: 10 . סך דמי ניהול משתנים – החלק מתשלום עמלת ניהול חיצוני שנגזר מתשואת הנכסים | B35: 168.99886
A37: 11. סה"כ הוצאות ישירות מסוג "עמלת ניהול חיצוני" (סכום סעיפים 11.א עד11.ט) | B37: 625.31316
A38: א. סך תשלומים הנובעים מהשקעה בקרנות השקעה בישראל | B38: 275.17245
A39: ב. סך תשלומים הנובעים מהשקעה בקרנות השקעה בחו"ל | B39: 98.392723
A40: ג. סך תשלומים למנהלי תיקים ישראלים בגין השקעה בחו"ל | B40: 0
A41: ד. סך תשלומים למנהלי תיקים זרים | B41: 0
A42: ה. סך תשלומים בגין השקעה בקרנות סל כאשר 75 אחוזים לפחות מנכסי הקרן הם נכסים שהונפקו במדינת ישראל לפי מדדים שעליהם הורה הממונה ובתנאים שהורה | B42: 7.7483208
A43: ו. סך תשלומים בגין השקעה בקרנות סל כאשר 75 אחוזים לפחות מנכסי הקרן הם נכסים שלא הונפקו במדינת ישראל ואינם נסחרים או מוחזקים בה | B43: 155.34243
A44: ז. סך תשלומים בגין השקעה בקרנות נאמנות ישראליות כאשר 75 אחוזים לפחות מנכסי הקרן מושקעים בנכסים שלא הונפקו במדינת ישראל ואינם נסחרים או מוחזקים בה | B44: 8.0545854
A45: ח. סך תשלומים בגין השקעה בקרנות נאמנות זרות כאשר 75 אחוזים לפחות מנכסי הקרן מושקעים בנכסים שלא הונפקו במדינת ישראל ואינם נסחרים או מוחזקים בה | B45: 80.362635
A46: ט. סך תשלומים בגין השקעה בקרן טכנולוגיה עילית | B46: 0.24001275
A48: 12. שיעור עמלת ניהול חיצוני בפועל לפני החזר, ככל שבוצע (חלוקה של סעיף 11 בסעיף 8.ב) | B48: 0.0018566589
... A55: 15.ב שיעור עמלת ניהול חיצוני בפועל לאחר החזר, (חלוקה של התוצאה של סעיף 11 בניכוי סעיף 15א, בסעיף 8.ב) | B55: 0.0018566589
A57: סך הכל הוצאות ישירות בפועל (למעט דמי ניהול משתנים כאמור בסעיף 10)
A59: 16. סך כל הוצאות ישירות (סכום של סעיף 7 וסעיף 11 בניכוי סעיף 15א) | B59: 948.24392
A61: 17. שיעור סך ההוצאות הישירות מתוך יתרת נכסים ממוצעת (חלוקה של סעיף 16 בסעיף 8) | B61: 0.0025169237
A63: סך הכל הוצאות ישירות (לצורך חישוב שיעור עלות שנתית צפויה)
A64: 18. שיעור מגבלת עמלת ניהול חיצוני שהמשקיע המוסדי הצהיר עליה בהתאם לתקנה 2א לתקנות הוצאות ישירות עבור שנת הכספים הבאה | B64: 0.0025
...

Sheet כספי שקלי
A1: נספח 1- סך ההוצאות הישירות ששולמו בעד כל סוג של הוצאה ישירה לתקופה המסתיימת ביום 31.12.2024
A3: שם חברת הביטוח: הכשרה חברה לביטוח - הכשרה כספי שקלי | B3: אלפי ₪
A5: 31.12.2024 נספח 1- סך ההוצאות הישירות ששולמו בעד כל סוג של הוצאה ישירה לתקופה המסתיימת ביום
A7: הוצאות ישירות שאינן מסוג עמלת ניהול חיצוני
A8: 1. סך הכל עמלות קנייה ומכירה של ניירות ערך סחירים | B8: 53.635763
A9: א. סך עמלות קנייה ומכירה של ניירות ערך סחירים לצדדים קשורים
A10: ב. סך עמלות קנייה ומכירה של ניירות ערך סחירים לצדדים שאינם קשורים | B10: 53.635763
A12: 2. סך הכל דמי שמירה בשל ניירות ערך סחירים וכל עמלה שגובה מי שמבצע את משמרות ניירות הערך עמלות (קסטודיאן) | B12: 0.07565
A13: א. סך עמלות קסטודיאן לצדדים קשורים
A14: ב. סך עמלות קסטודיאן לצדדים שאינם קשורים | B14: 0.07565
A16: 3. סך הכל הוצאות הנובעות מהשקעות לא סחירות | B16: 0
A17: א. הוצאה הנובעת מהשקעה בניירות ערך לא סחירים או ממתן הלוואה למי שאינו עמית או מבוטח | B17: 0
A18: ב. הוצאה הנובעת מהשקעה בזכויות במקרקעין
A20: 4. מסים החלים על משקיע מוסדי, על נכסיו, על הכנסותיו ועל עסקאות שנעשו בנכסיו
A22: 5. סך הוצאות בעד ניהול תביעות | B22: 0
A24: 6. סך הוצאות בעד מתן משכנתאות | B24: 0
A26: 7. סך הכל הוצאות ישירות שאינן מסוג עמלת ניהול חיצוני (סכום סעיפים 1 עד 6) | B26: 53.711413
A28: 8. שווי ממוצע של נכסי הקופה או המסלול (ממוצע פשוט של סעיפים8א ו- 8ב) | B28: 395417.09
A29: א. השווי המשוערך של נכסי הקופה או המסלול נכון ליום 31 בדצמבר של שנת הכספים שהסתיימה 2024 | B29: 362986.56
A30: ב. השווי המשוערך של נכסי הקופה או המסלול נכון ליום 31 בדצמבר של שנת הכספים שהסתיימה לפני 2023 או לתקופה אחרת לפי העניין | B30: 427847.62
A32: 9. שיעור שנתי של הוצאות ישירות שאינן מסוג עמלת ניהול חיצוני (חלוקה של סעיף 7 בסעיף 8) | B32: 0.00013583483
A34: הוצאות ישירות מסוג עמלת ניהול חיצוני
A35: 10 . סך דמי ניהול משתנים – החלק מתשלום עמלת ניהול חיצוני שנגזר מתשואת הנכסים | B35: 0
A37: 11. סה"כ הוצאות ישירות מסוג "עמלת ניהול חיצוני" (סכום סעיפים 11.א עד11.ט) | B37: 0
A38: א. סך תשלומים הנובעים מהשקעה בקרנות השקעה בישראל | B38: 0
A39: ב. סך תשלומים הנובעים מהשקעה בקרנות השקעה בחו"ל | B39: 0
A40: ג. סך תשלומים למנהלי תיקים ישראלים בגין השקעה בחו"ל | B40: 0
A41: ד. סך תשלומים למנהלי תיקים זרים | B41: 0
A42: ה. סך תשלומים בגין השקעה בקרנות סל כאשר 75 אחוזים לפחות מנכסי הקרן הם נכסים שהונפקו במדינת ישראל לפי מדדים שעליהם הורה הממונה ובתנאים שהורה | B42: 0
A43: ו. סך תשלומים בגין השקעה בקרנות סל כאשר 75 אחוזים לפחות מנכסי הקרן הם נכסים שלא הונפקו במדינת ישראל ואינם נסחרים או מוחזקים בה | B43: 0
A44: ז. סך תשלומים בגין השקעה בקרנות נאמנות ישראליות כאשר 75 אחוזים לפחות מנכסי הקרן מושקעים בנכסים שלא הונפקו במדינת ישראל ואינם נסחרים או מוחזקים בה | B44: 0
A45: ח. סך תשלומים בגין השקעה בקרנות נאמנות זרות כאשר 75 אחוזים לפחות מנכסי הקרן מושקעים בנכסים שלא הונפקו במדינת ישראל ואינם נסחרים או מוחזקים בה | B45: 0
A46: ט. סך תשלומים בגין השקעה בקרן טכנולוגיה עילית | B46: 0
A48: 12. שיעור עמלת ניהול חיצוני בפועל לפני החזר, ככל שבוצע (חלוקה של סעיף 11 בסעיף 8.ב) | B48: 0
... A55: 15.ב שיעור עמלת ניהול חיצוני בפועל לאחר החזר, (חלוקה של התוצאה של סעיף 11 בניכוי סעיף 15א, בסעיף 8.ב) | B55: 0
A57: סך הכל הוצאות ישירות בפועל (למעט דמי ניהול משתנים כאמור בסעיף 10)
A59: 16. סך כל הוצאות ישירות (סכום של סעיף 7 וסעיף 11 בניכוי סעיף 15א) | B59: 53.711413
A61: 17. שיעור סך ההוצאות הישירות מתוך יתרת נכסים ממוצעת (חלוקה של סעיף 16 בסעיף 8) | B61: 0.00013583483
A63: סך הכל הוצאות ישירות (לצורך חישוב שיעור עלות שנתית צפויה)
A64: 18. שיעור מגבלת עמלת ניהול חיצוני שהמשקיע המוסדי הצהיר עליה בהתאם לתקנה 2א לתקנות הוצאות ישירות עבור שנת הכספים הבאה | B64: 0.0015
...

Sheet הכשרה לבני 50 ומטה
A1: נספח 1- סך ההוצאות הישירות ששולמו בעד כל סוג של הוצאה ישירה לתקופה המסתיימת ביום 31.12.2024
A3: שם חברת הביטוח: הכשרה חברה לביטוח - הכשרה לבני 50 ומטה | B3: אלפי ₪
A5: 31.12.2024 נספח 1- סך ההוצאות הישירות ששולמו בעד כל סוג של הוצאה ישירה לתקופה המסתיימת ביום
A7: הוצאות ישירות שאינן מסוג עמלת ניהול חיצוני
A8: 1. סך הכל עמלות קנייה ומכירה של ניירות ערך סחירים | B8: 100.7087
A9: א. סך עמלות קנייה ומכירה של ניירות ערך סחירים לצדדים קשורים
A10: ב. סך עמלות קנייה ומכירה של ניירות ערך סחירים לצדדים שאינם קשורים | B10: 100.7087
A12: 2. סך הכל דמי שמירה בשל ניירות ערך סחירים וכל עמלה שגובה מי שמבצע את משמרות ניירות הערך עמלות (קסטודיאן) | B12: 5.4207944
A13: א. סך עמלות קסטודיאן לצדדים קשורים
A14: ב. סך עמלות קסטודיאן לצדדים שאינם קשורים | B14: 5.4207944
A16: 3. סך הכל הוצאות הנובעות מהשקעות לא סחירות | B16: 24.600583
A17: א. הוצאה הנובעת מהשקעה בניירות ערך לא סחירים או ממתן הלוואה למי שאינו עמית או מבוטח | B17: 24.600583
A18: ב. הוצאה הנובעת מהשקעה בזכויות במקרקעין
A20: 4. מסים החלים על משקיע מוסדי, על נכסיו, על הכנסותיו ועל עסקאות שנעשו בנכסיו
A22: 5. סך הוצאות בעד ניהול תביעות | B22: 0
A24: 6. סך הוצאות בעד מתן משכנתאות | B24: 0
A26: 7. סך הכל הוצאות ישירות שאינן מסוג עמלת ניהול חיצוני (סכום סעיפים 1 עד 6) | B26: 130.73008
A28: 8. שווי ממוצע של נכסי הקופה או המסלול (ממוצע פשוט של סעיפים8א ו- 8ב) | B28: 287760.29
A29: א. השווי המשוערך של נכסי הקופה או המסלול נכון ליום 31 בדצמבר של שנת הכספים שהסתיימה 2024 | B29: 304042.4
A30: ב. השווי המשוערך של נכסי הקופה או המסלול נכון ליום 31 בדצמבר של שנת הכספים שהסתיימה לפני 2023 או לתקופה אחרת לפי העניין | B30: 271478.18
A32: 9. שיעור שנתי של הוצאות ישירות שאינן מסוג עמלת ניהול חיצוני (חלוקה של סעיף 7 בסעיף 8) | B32: 0.00045430201
A34: הוצאות ישירות מסוג עמלת ניהול חיצוני
A35: 10 . סך דמי ניהול משתנים – החלק מתשלום עמלת ניהול חיצוני שנגזר מתשואת הנכסים | B35: 371.02323
A37: 11. סה"כ הוצאות ישירות מסוג "עמלת ניהול חיצוני" (סכום סעיפים 11.א עד11.ט) | B37: 804.85527
A38: א. סך תשלומים הנובעים מהשקעה בקרנות השקעה בישראל | B38: 450.21106
A39: ב. סך תשלומים הנובעים מהשקעה בקרנות השקעה בחו"ל | B39: 208.69295
A40: ג. סך תשלומים למנהלי תיקים ישראלים בגין השקעה בחו"ל | B40: 0
A41: ד. סך תשלומים למנהלי תיקים זרים | B41: 0
A42: ה. סך תשלומים בגין השקעה בקרנות סל כאשר 75 אחוזים לפחות מנכסי הקרן הם נכסים שהונפקו במדינת ישראל לפי מדדים שעליהם הורה הממונה ובתנאים שהורה | B42: 2.7474488
A43: ו. סך תשלומים בגין השקעה בקרנות סל כאשר 75 אחוזים לפחות מנכסי הקרן הם נכסים שלא הונפקו במדינת ישראל ואינם נסחרים או מוחזקים בה | B43: 73.343319
A44: ז. סך תשלומים בגין השקעה בקרנות נאמנות ישראליות כאשר 75 אחוזים לפחות מנכסי הקרן מושקעים בנכסים שלא הונפקו במדינת ישראל ואינם נסחרים או מוחזקים בה | B44: 4.1396236
A45: ח. סך תשלומים בגין השקעה בקרנות נאמנות זרות כאשר 75 אחוזים לפחות מנכסי הקרן מושקעים בנכסים שלא הונפקו במדינת ישראל ואינם נסחרים או מוחזקים בה | B45: 65.112579
A46: ט. סך תשלומים בגין השקעה בקרן טכנולוגיה עילית | B46: 0.60828168
A48: 12. שיעור עמלת ניהול חיצוני בפועל לפני החזר, ככל שבוצע (חלוקה של סעיף 11 בסעיף 8.ב) | B48: 0.0029647144
... A52: 14. ההפרש בין שיעור מגבלת עמלת ניהול חיצוני מוצהרת לבין שיעור עמלת ניהול חיצוני בפועל (סעיף 13 פחות סעיף 12) | B52: 3.5285572e-05
A54: 15.א סכום שהוחזר לחוסכים (אם הוחזר)
A55: 15.ב שיעור עמלת ניהול חיצוני בפועל לאחר החזר, (חלוקה של התוצאה של סעיף 11 בניכוי סעיף 15א, בסעיף 8.ב) | B55: 0.0029647144
A57: סך הכל הוצאות ישירות בפועל (למעט דמי ניהול משתנים כאמור בסעיף 10)
A59: 16. סך כל הוצאות ישירות (סכום של סעיף 7 וסעיף 11 בניכוי סעיף 15א) | B59: 935.58535
A61: 17. שיעור סך ההוצאות הישירות מתוך יתרת נכסים ממוצעת (חלוקה של סעיף 16 בסעיף 8) | B61: 0.0032512663
...

Sheet הכשרה לבני 50-60
A1: נספח 1- סך ההוצאות הישירות ששולמו בעד כל סוג של הוצאה ישירה לתקופה המסתיימת ביום 31.12.2024
A3: שם חברת הביטוח: הכשרה חברה לביטוח - הכשרה לבני 50-60 | B3: אלפי ₪
A5: 31.12.2024 נספח 1- סך ההוצאות הישירות ששולמו בעד כל סוג של הוצאה ישירה לתקופה המסתיימת ביום
A7: הוצאות ישירות שאינן מסוג עמלת ניהול חיצוני
A8: 1. סך הכל עמלות קנייה ומכירה של ניירות ערך סחירים | B8: 64.118023
A9: א. סך עמלות קנייה ומכירה של ניירות ערך סחירים לצדדים קשורים
A10: ב. סך עמלות קנייה ומכירה של ניירות ערך סחירים לצדדים שאינם קשורים | B10: 64.118023
A12: 2. סך הכל דמי שמירה בשל ניירות ערך סחירים וכל עמלה שגובה מי שמבצע את משמרות ניירות הערך עמלות (קסטודיאן) | B12: 4.8718485
A13: א. סך עמלות קסטודיאן לצדדים קשורים
A14: ב. סך עמלות קסטודיאן לצדדים שאינם קשורים | B14: 4.8718485
A16: 3. סך הכל הוצאות הנובעות מהשקעות לא סחירות | B16: 8.5501
A17: א. הוצאה הנובעת מהשקעה בניירות ערך לא סחירים או ממתן הלוואה למי שאינו עמית או מבוטח | B17: 8.5501
A18: ב. הוצאה הנובעת מהשקעה בזכויות במקרקעין
A20: 4. מסים החלים על משקיע מוסדי, על נכסיו, על הכנסותיו ועל עסקאות שנעשו בנכסיו
A22: 5. סך הוצאות בעד ניהול תביעות | B22: 0
A24: 6. סך הוצאות בעד מתן משכנתאות | B24: 0
A26: 7. סך הכל הוצאות ישירות שאינן מסוג עמלת ניהול חיצוני (סכום סעיפים 1 עד 6) | B26: 77.539972
A28: 8. שווי ממוצע של נכסי הקופה או המסלול (ממוצע פשוט של סעיפים8א ו- 8ב) | B28: 199935.48
A29: א. השווי המשוערך של נכסי הקופה או המסלול נכון ליום 31 בדצמבר של שנת הכספים שהסתיימה 2024 | B29: 232636.38
A30: ב. השווי המשוערך של נכסי הקופה או המסלול נכון ליום 31 בדצמבר של שנת הכספים שהסתיימה לפני 2023 או לתקופה אחרת לפי העניין | B30: 167234.58
A32: 9. שיעור שנתי של הוצאות ישירות שאינן מסוג עמלת ניהול חיצוני (חלוקה של סעיף 7 בסעיף 8) | B32: 0.00038782498
A34: הוצאות ישירות מסוג עמלת ניהול חיצוני
A35: 10 . סך דמי ניהול משתנים – החלק מתשלום עמלת ניהול חיצוני שנגזר מתשואת הנכסים | B35: 150.83698
A37: 11. סה"כ הוצאות ישירות מסוג "עמלת ניהול חיצוני" (סכום סעיפים 11.א עד11.ט) | B37: 339.5317
A38: א. סך תשלומים הנובעים מהשקעה בקרנות השקעה בישראל | B38: 165.49321
A39: ב. סך תשלומים הנובעים מהשקעה בקרנות השקעה בחו"ל | B39: 87.825816
A40: ג. סך תשלומים למנהלי תיקים ישראלים בגין השקעה בחו"ל | B40: 0
A41: ד. סך תשלומים למנהלי תיקים זרים | B41: 0
A42: ה. סך תשלומים בגין השקעה בקרנות סל כאשר 75 אחוזים לפחות מנכסי הקרן הם נכסים שהונפקו במדינת ישראל לפי מדדים שעליהם הורה הממונה ובתנאים שהורה | B42: 1.6644672
A43: ו. סך תשלומים בגין השקעה בקרנות סל כאשר 75 אחוזים לפחות מנכסי הקרן הם נכסים שלא הונפקו במדינת ישראל ואינם נסחרים או מוחזקים בה | B43: 47.473852
A44: ז. סך תשלומים בגין השקעה בקרנות נאמנות ישראליות כאשר 75 אחוזים לפחות מנכסי הקרן מושקעים בנכסים שלא הונפקו במדינת ישראל ואינם נסחרים או מוחזקים בה | B44: 2.3573487
A45: ח. סך תשלומים בגין השקעה בקרנות נאמנות זרות כאשר 75 אחוזים לפחות מנכסי הקרן מושקעים בנכסים שלא הונפקו במדינת ישראל ואינם נסחרים או מוחזקים בה | B45: 34.545077
A46: ט. סך תשלומים בגין השקעה בקרן טכנולוגיה עילית | B46: 0.1719253
A48: 12. שיעור עמלת ניהול חיצוני בפועל לפני החזר, ככל שבוצע (חלוקה של סעיף 11 בסעיף 8.ב) | B48: 0.0020302721
... A52: 14. ההפרש בין שיעור מגבלת עמלת ניהול חיצוני מוצהרת לבין שיעור עמלת ניהול חיצוני בפועל (סעיף 13 פחות סעיף 12) | B52: 0.00046972786
A54: 15.א סכום שהוחזר לחוסכים (אם הוחזר)
A55: 15.ב שיעור עמלת ניהול חיצוני בפועל לאחר החזר, (חלוקה של התוצאה של סעיף 11 בניכוי סעיף 15א, בסעיף 8.ב) | B55: 0.0020302721
A57: סך הכל הוצאות ישירות בפועל (למעט דמי ניהול משתנים כאמור בסעיף 10)
A59: 16. סך כל הוצאות ישירות (סכום של סעיף 7 וסעיף 11 בניכוי סעיף 15א) | B59: 417.07167
A61: 17. שיעור סך ההוצאות הישירות מתוך יתרת נכסים ממוצעת (חלוקה של סעיף 16 בסעיף 8) | B61: 0.0020860314
...

Sheet הכשרה לבני 60 ומעלה
A1: נספח 1- סך ההוצאות הישירות ששולמו בעד כל סוג של הוצאה ישירה לתקופה המסתיימת ביום 31.12.2024
A3: שם חברת הביטוח: הכשרה חברה לביטוח - הכשרה לבני 60 ומעלה | B3: אלפי ₪
A5: 31.12.2024 נספח 1- סך ההוצאות הישירות ששולמו בעד כל סוג של הוצאה ישירה לתקופה המסתיימת ביום
A7: הוצאות ישירות שאינן מסוג עמלת ניהול חיצוני
A8: 1. סך הכל עמלות קנייה ומכירה של ניירות ערך סחירים | B8: 48.032812
A9: א. סך עמלות קנייה ומכירה של ניירות ערך סחירים לצדדים קשורים
A10: ב. סך עמלות קנייה ומכירה של ניירות ערך סחירים לצדדים שאינם קשורים | B10: 48.032812
A12: 2. סך הכל דמי שמירה בשל ניירות ערך סחירים וכל עמלה שגובה מי שמבצע את משמרות ניירות הערך עמלות (קסטודיאן) | B12: 4.8296602
A13: א. סך עמלות קסטודיאן לצדדים קשורים
A14: ב. סך עמלות קסטודיאן לצדדים שאינם קשורים | B14: 4.8296602
A16: 3. סך הכל הוצאות הנובעות מהשקעות לא סחירות | B16: 6.7789166
A17: א. הוצאה הנובעת מהשקעה בניירות ערך לא סחירים או ממתן הלוואה למי שאינו עמית או מבוטח | B17: 6.7789166
A18: ב. הוצאה הנובעת מהשקעה בזכויות במקרקעין
A20: 4. מסים החלים על משקיע מוסדי, על נכסיו, על הכנסותיו ועל עסקאות שנעשו בנכסיו
A22: 5. סך הוצאות בעד ניהול תביעות | B22: 0
A24: 6. סך הוצאות בעד מתן משכנתאות | B24: 0
A26: 7. סך הכל הוצאות ישירות שאינן מסוג עמלת ניהול חיצוני (סכום סעיפים 1 עד 6) | B26: 59.641389
A28: 8. שווי ממוצע של נכסי הקופה או המסלול (ממוצע פשוט של סעיפים8א ו- 8ב) | B28: 157545.98
A29: א. השווי המשוערך של נכסי הקופה או המסלול נכון ליום 31 בדצמבר של שנת הכספים שהסתיימה 2024 | B29: 189618.82
A30: ב. השווי המשוערך של נכסי הקופה או המסלול נכון ליום 31 בדצמבר של שנת הכספים שהסתיימה לפני 2023 או לתקופה אחרת לפי העניין | B30: 125473.13
A32: 9. שיעור שנתי של הוצאות ישירות שאינן מסוג עמלת ניהול חיצוני (חלוקה של סעיף 7 בסעיף 8) | B32: 0.00037856497
A34: הוצאות ישירות מסוג עמלת ניהול חיצוני
A35: 10 . סך דמי ניהול משתנים – החלק מתשלום עמלת ניהול חיצוני שנגזר מתשואת הנכסים | B35: 113.46385
A37: 11. סה"כ הוצאות ישירות מסוג "עמלת ניהול חיצוני" (סכום סעיפים 11.א עד11.ט) | B37: 237.55748
A38: א. סך תשלומים הנובעים מהשקעה בקרנות השקעה בישראל | B38: 124.49653
A39: ב. סך תשלומים הנובעים מהשקעה בקרנות השקעה בחו"ל | B39: 65.215449
A40: ג. סך תשלומים למנהלי תיקים ישראלים בגין השקעה בחו"ל | B40: 0
A41: ד. סך תשלומים למנהלי תיקים זרים | B41: 0
A42: ה. סך תשלומים בגין השקעה בקרנות סל כאשר 75 אחוזים לפחות מנכסי הקרן הם נכסים שהונפקו במדינת ישראל לפי מדדים שעליהם הורה הממונה ובתנאים שהורה | B42: 0.3392382
A43: ו. סך תשלומים בגין השקעה בקרנות סל כאשר 75 אחוזים לפחות מנכסי הקרן הם נכסים שלא הונפקו במדינת ישראל ואינם נסחרים או מוחזקים בה | B43: 25.928516
A44: ז. סך תשלומים בגין השקעה בקרנות נאמנות ישראליות כאשר 75 אחוזים לפחות מנכסי הקרן מושקעים בנכסים שלא הונפקו במדינת ישראל ואינם נסחרים או מוחזקים בה | B44: 1.3547556
A45: ח. סך תשלומים בגין השקעה בקרנות נאמנות זרות כאשר 75 אחוזים לפחות מנכסי הקרן מושקעים בנכסים שלא הונפקו במדינת ישראל ואינם נסחרים או מוחזקים בה | B45: 20.149011
A46: ט. סך תשלומים בגין השקעה בקרן טכנולוגיה עילית | B46: 0.073985787
A48: 12. שיעור עמלת ניהול חיצוני בפועל לפני החזר, ככל שבוצע (חלוקה של סעיף 11 בסעיף 8.ב) | B48: 0.0018932936
... A55: 15.ב שיעור עמלת ניהול חיצוני בפועל לאחר החזר, (חלוקה של התוצאה של סעיף 11 בניכוי סעיף 15א, בסעיף 8.ב) | B55: 0.0018932936
A57: סך הכל הוצאות ישירות בפועל (למעט דמי ניהול משתנים כאמור בסעיף 10)
A59: 16. סך כל הוצאות ישירות (סכום של סעיף 7 וסעיף 11 בניכוי סעיף 15א) | B59: 297.19887
A61: 17. שיעור סך ההוצאות הישירות מתוך יתרת נכסים ממוצעת (חלוקה של סעיף 16 בסעיף 8) | B61: 0.0018864263
A63: סך הכל הוצאות ישירות (לצורך חישוב שיעור עלות שנתית צפויה)
A64: 18. שיעור מגבלת עמלת ניהול חיצוני שהמשקיע המוסדי הצהיר עליה בהתאם לתקנה 2א לתקנות הוצאות ישירות עבור שנת הכספים הבאה | B64: 0.0025
...

Sheet הכשרה מקבלי קצבה
A1: נספח 1- סך ההוצאות הישירות ששולמו בעד כל סוג של הוצאה ישירה לתקופה המסתיימת ביום 31.12.2024
A3: שם חברת הביטוח: הכשרה חברה לביטוח - הכשרה מקבלי קצבה | B3: אלפי ₪
A5: 31.12.2024 נספח 1- סך ההוצאות הישירות ששולמו בעד כל סוג של הוצאה ישירה לתקופה המסתיימת ביום
A7: הוצאות ישירות שאינן מסוג עמלת ניהול חיצוני
A8: 1. סך הכל עמלות קנייה ומכירה של ניירות ערך סחירים | B8: 71.996571
A9: א. סך עמלות קנייה ומכירה של ניירות ערך סחירים לצדדים קשורים
A10: ב. סך עמלות קנייה ומכירה של ניירות ערך סחירים לצדדים שאינם קשורים | B10: 71.996571
A12: 2. סך הכל דמי שמירה בשל ניירות ערך סחירים וכל עמלה שגובה מי שמבצע את משמרות ניירות הערך עמלות (קסטודיאן) | B12: 5.0576032
A13: א. סך עמלות קסטודיאן לצדדים קשורים
A14: ב. סך עמלות קסטודיאן לצדדים שאינם קשורים | B14: 5.0576032
A16: 3. סך הכל הוצאות הנובעות מהשקעות לא סחירות | B16: 7.3482018
A17: א. הוצאה הנובעת מהשקעה בניירות ערך לא סחירים או ממתן הלוואה למי שאינו עמית או מבוטח | B17: 7.3482018
A18: ב. הוצאה הנובעת מהשקעה בזכויות במקרקעין
A20: 4. מסים החלים על משקיע מוסדי, על נכסיו, על הכנסותיו ועל עסקאות שנעשו בנכסיו
A22: 5. סך הוצאות בעד ניהול תביעות | B22: 0
A24: 6. סך הוצאות בעד מתן משכנתאות | B24: 0
A26: 7. סך הכל הוצאות ישירות שאינן מסוג עמלת ניהול חיצוני (סכום סעיפים 1 עד 6) | B26: 84.402376
A28: 8. שווי ממוצע של נכסי הקופה או המסלול (ממוצע פשוט של סעיפים8א ו- 8ב) | B28: 261265.48
A29: א. השווי המשוערך של נכסי הקופה או המסלול נכון ליום 31 בדצמבר של שנת הכספים שהסתיימה 2024 | B29: 285860.85
A30: ב. השווי המשוערך של נכסי הקופה או המסלול נכון ליום 31 בדצמבר של שנת הכספים שהסתיימה לפני 2023 או לתקופה אחרת לפי העניין | B30: 236670.1
A32: 9. שיעור שנתי של הוצאות ישירות שאינן מסוג עמלת ניהול חיצוני (חלוקה של סעיף 7 בסעיף 8) | B32: 0.00032305216
A34: הוצאות ישירות מסוג עמלת ניהול חיצוני
A35: 10 . סך דמי ניהול משתנים – החלק מתשלום עמלת ניהול חיצוני שנגזר מתשואת הנכסים | B35: 203.03009
A37: 11. סה"כ הוצאות ישירות מסוג "עמלת ניהול חיצוני" (סכום סעיפים 11.א עד11.ט) | B37: 442.76767
A38: א. סך תשלומים הנובעים מהשקעה בקרנות השקעה בישראל | B38: 247.02888
A39: ב. סך תשלומים הנובעים מהשקעה בקרנות השקעה בחו"ל | B39: 117.8773
A40: ג. סך תשלומים למנהלי תיקים ישראלים בגין השקעה בחו"ל | B40: 0
A41: ד. סך תשלומים למנהלי תיקים זרים | B41: 0
A42: ה. סך תשלומים בגין השקעה בקרנות סל כאשר 75 אחוזים לפחות מנכסי הקרן הם נכסים שהונפקו במדינת ישראל לפי מדדים שעליהם הורה הממונה ובתנאים שהורה | B42: 2.2759709
A43: ו. סך תשלומים בגין השקעה בקרנות סל כאשר 75 אחוזים לפחות מנכסי הקרן הם נכסים שלא הונפקו במדינת ישראל ואינם נסחרים או מוחזקים בה | B43: 38.197893
A44: ז. סך תשלומים בגין השקעה בקרנות נאמנות ישראליות כאשר 75 אחוזים לפחות מנכסי הקרן מושקעים בנכסים שלא הונפקו במדינת ישראל ואינם נסחרים או מוחזקים בה | B44: 2.7053978
A45: ח. סך תשלומים בגין השקעה בקרנות נאמנות זרות כאשר 75 אחוזים לפחות מנכסי הקרן מושקעים בנכסים שלא הונפקו במדינת ישראל ואינם נסחרים או מוחזקים בה | B45: 34.670877
A46: ט. סך תשלומים בגין השקעה בקרן טכנולוגיה עילית | B46: 0.011353694
A48: 12. שיעור עמלת ניהול חיצוני בפועל לפני החזר, ככל שבוצע (חלוקה של סעיף 11 בסעיף 8.ב) | B48: 0.0018708222
... A55: 15.ב שיעור עמלת ניהול חיצוני בפועל לאחר החזר, (חלוקה של התוצאה של סעיף 11 בניכוי סעיף 15א, בסעיף 8.ב) | B55: 0.0018708222
A57: סך הכל הוצאות ישירות בפועל (למעט דמי ניהול משתנים כאמור בסעיף 10)
A59: 16. סך כל הוצאות ישירות (סכום של סעיף 7 וסעיף 11 בניכוי סעיף 15א) | B59: 527.17005
A61: 17. שיעור סך ההוצאות הישירות מתוך יתרת נכסים ממוצעת (חלוקה של סעיף 16 בסעיף 8) | B61: 0.0020177563
A63: סך הכל הוצאות ישירות (לצורך חישוב שיעור עלות שנתית צפויה)
A64: 18. שיעור מגבלת עמלת ניהול חיצוני שהמשקיע המוסדי הצהיר עליה בהתאם לתקנה 2א לתקנות הוצאות ישירות עבור שנת הכספים הבאה | B64: 0.0025
...

Sheet הכשרה אשראי ואג"ח
A1: נספח 1- סך ההוצאות הישירות ששולמו בעד כל סוג של הוצאה ישירה לתקופה המסתיימת ביום 31.12.2024
A3: שם חברת הביטוח: הכשרה חברה לביטוח - הכשרה אג"ח | B3: אלפי ₪
A5: 31.12.2024 נספח 1- סך ההוצאות הישירות ששולמו בעד כל סוג של הוצאה ישירה לתקופה המסתיימת ביום
A7: הוצאות ישירות שאינן מסוג עמלת ניהול חיצוני
A8: 1. סך הכל עמלות קנייה ומכירה של ניירות ערך סחירים | B8: 129.91325
A9: א. סך עמלות קנייה ומכירה של ניירות ערך סחירים לצדדים קשורים
A10: ב. סך עמלות קנייה ומכירה של ניירות ערך סחירים לצדדים שאינם קשורים | B10: 129.91325
A12: 2. סך הכל דמי שמירה בשל ניירות ערך סחירים וכל עמלה שגובה מי שמבצע את משמרות ניירות הערך עמלות (קסטודיאן) | B12: 0.69921646
A13: א. סך עמלות קסטודיאן לצדדים קשורים
A14: ב. סך עמלות קסטודיאן לצדדים שאינם קשורים | B14: 0.69921646
A16: 3. סך הכל הוצאות הנובעות מהשקעות לא סחירות | B16: 1.459
A17: א. הוצאה הנובעת מהשקעה בניירות ערך לא סחירים או ממתן הלוואה למי שאינו עמית או מבוטח | B17: 1.459
A18: ב. הוצאה הנובעת מהשקעה בזכויות במקרקעין
A20: 4. מסים החלים על משקיע מוסדי, על נכסיו, על הכנסותיו ועל עסקאות שנעשו בנכסיו
A22: 5. סך הוצאות בעד ניהול תביעות | B22: 0
A24: 6. סך הוצאות בעד מתן משכנתאות | B24: 0
A26: 7. סך הכל הוצאות ישירות שאינן מסוג עמלת ניהול חיצוני (סכום סעיפים 1 עד 6) | B26: 132.07146
A28: 8. שווי ממוצע של נכסי הקופה או המסלול (ממוצע פשוט של סעיפים8א ו- 8ב) | B28: 342950.69
A29: א. השווי המשוערך של נכסי הקופה או המסלול נכון ליום 31 בדצמבר של שנת הכספים שהסתיימה 2024 | B29: 407963.52
A30: ב. השווי המשוערך של נכסי הקופה או המסלול נכון ליום 31 בדצמבר של שנת הכספים שהסתיימה לפני 2023 או לתקופה אחרת לפי העניין | B30: 277937.85
A32: 9. שיעור שנתי של הוצאות ישירות שאינן מסוג עמלת ניהול חיצוני (חלוקה של סעיף 7 בסעיף 8) | B32: 0.00038510336
A34: הוצאות ישירות מסוג עמלת ניהול חיצוני
A35: 10 . סך דמי ניהול משתנים – החלק מתשלום עמלת ניהול חיצוני שנגזר מתשואת הנכסים | B35: 1090.5621
A37: 11. סה"כ הוצאות ישירות מסוג "עמלת ניהול חיצוני" (סכום סעיפים 11.א עד11.ט) | B37: 1175.4149
A38: א. סך תשלומים הנובעים מהשקעה בקרנות השקעה בישראל | B38: 165.665
A39: ב. סך תשלומים הנובעים מהשקעה בקרנות השקעה בחו"ל | B39: 433.91519
A40: ג. סך תשלומים למנהלי תיקים ישראלים בגין השקעה בחו"ל | B40: 0
A41: ד. סך תשלומים למנהלי תיקים זרים | B41: 0
A42: ה. סך תשלומים בגין השקעה בקרנות סל כאשר 75 אחוזים לפחות מנכסי הקרן הם נכסים שהונפקו במדינת ישראל לפי מדדים שעליהם הורה הממונה ובתנאים שהורה | B42: 0
A43: ו. סך תשלומים בגין השקעה בקרנות סל כאשר 75 אחוזים לפחות מנכסי הקרן הם נכסים שלא הונפקו במדינת ישראל ואינם נסחרים או מוחזקים בה | B43: 19.994036
A44: ז. סך תשלומים בגין השקעה בקרנות נאמנות ישראליות כאשר 75 אחוזים לפחות מנכסי הקרן מושקעים בנכסים שלא הונפקו במדינת ישראל ואינם נסחרים או מוחזקים בה | B44: 0
A45: ח. סך תשלומים בגין השקעה בקרנות נאמנות זרות כאשר 75 אחוזים לפחות מנכסי הקרן מושקעים בנכסים שלא הונפקו במדינת ישראל ואינם נסחרים או מוחזקים בה | B45: 555.8407
A46: ט. סך תשלומים בגין השקעה בקרן טכנולוגיה עילית | B46: 0
A48: 12. שיעור עמלת ניהול חיצוני בפועל לפני החזר, ככל שבוצע (חלוקה של סעיף 11 בסעיף 8.ב) | B48: 0.0042290567
... A55: 15.ב שיעור עמלת ניהול חיצוני בפועל לאחר החזר, (חלוקה של התוצאה של סעיף 11 בניכוי סעיף 15א, בסעיף 8.ב) | B55: 0.0042290567
A57: סך הכל הוצאות ישירות בפועל (למעט דמי ניהול משתנים כאמור בסעיף 10)
A59: 16. סך כל הוצאות ישירות (סכום של סעיף 7 וסעיף 11 בניכוי סעיף 15א) | B59: 1307.4864
A61: 17. שיעור סך ההוצאות הישירות מתוך יתרת נכסים ממוצעת (חלוקה של סעיף 16 בסעיף 8) | B61: 0.0038124618
A63: סך הכל הוצאות ישירות (לצורך חישוב שיעור עלות שנתית צפויה)
A64: 18. שיעור מגבלת עמלת ניהול חיצוני שהמשקיע המוסדי הצהיר עליה בהתאם לתקנה 2א לתקנות הוצאות ישירות עבור שנת הכספים הבאה | B64: 0.005
...

Sheet הכשרה אשראי ואג"ח עד 25%
A1: נספח 1- סך ההוצאות הישירות ששולמו בעד כל סוג של הוצאה ישירה לתקופה המסתיימת ביום 31.12.2024
A3: שם חברת הביטוח: הכשרה חברה לביטוח - הכשרה אשראי ואג"ח עד 25% | B3: אלפי ₪
A5: 31.12.2024 נספח 1- סך ההוצאות הישירות ששולמו בעד כל סוג של הוצאה ישירה לתקופה המסתיימת ביום
A7: הוצאות ישירות שאינן מסוג עמלת ניהול חיצוני
A8: 1. סך הכל עמלות קנייה ומכירה של ניירות ערך סחירים | B8: 9.9190345
A9: א. סך עמלות קנייה ומכירה של ניירות ערך סחירים לצדדים קשורים
A10: ב. סך עמלות קנייה ומכירה של ניירות ערך סחירים לצדדים שאינם קשורים | B10: 9.9190345
A12: 2. סך הכל דמי שמירה בשל ניירות ערך סחירים וכל עמלה שגובה מי שמבצע את משמרות ניירות הערך עמלות (קסטודיאן) | B12: 0.02795222
A13: א. סך עמלות קסטודיאן לצדדים קשורים
A14: ב. סך עמלות קסטודיאן לצדדים שאינם קשורים | B14: 0.02795222
A16: 3. סך הכל הוצאות הנובעות מהשקעות לא סחירות | B16: 0
A17: א. הוצאה הנובעת מהשקעה בניירות ערך לא סחירים או ממתן הלוואה למי שאינו עמית או מבוטח | B17: 0
A18: ב. הוצאה הנובעת מהשקעה בזכויות במקרקעין
A20: 4. מסים החלים על משקיע מוסדי, על נכסיו, על הכנסותיו ועל עסקאות שנעשו בנכסיו
A22: 5. סך הוצאות בעד ניהול תביעות | B22: 0
A24: 6. סך הוצאות בעד מתן משכנתאות | B24: 0
A26: 7. סך הכל הוצאות ישירות שאינן מסוג עמלת ניהול חיצוני (סכום סעיפים 1 עד 6) | B26: 9.9469867
A28: 8. שווי ממוצע של נכסי הקופה או המסלול (ממוצע פשוט של סעיפים8א ו- 8ב) | B28: 33148.507
A29: א. השווי המשוערך של נכסי הקופה או המסלול נכון ליום 31 בדצמבר של שנת הכספים שהסתיימה 2024 | B29: 33148.507
A30: ב. השווי המשוערך של נכסי הקופה או המסלול נכון ליום 31 בדצמבר של שנת הכספים שהסתיימה לפני 2023 או לתקופה אחרת לפי העניין | B30: 33148.507
A32: 9. שיעור שנתי של הוצאות ישירות שאינן מסוג עמלת ניהול חיצוני (חלוקה של סעיף 7 בסעיף 8) | B32: 0.00030007344
A34: הוצאות ישירות מסוג עמלת ניהול חיצוני
A35: 10 . סך דמי ניהול משתנים – החלק מתשלום עמלת ניהול חיצוני שנגזר מתשואת הנכסים | B35: 0
A37: 11. סה"כ הוצאות ישירות מסוג "עמלת ניהול חיצוני" (סכום סעיפים 11.א עד11.ט) | B37: 0.2586348
A38: א. סך תשלומים הנובעים מהשקעה בקרנות השקעה בישראל | B38: 0
A39: ב. סך תשלומים הנובעים מהשקעה בקרנות השקעה בחו"ל | B39: 0
A40: ג. סך תשלומים למנהלי תיקים ישראלים בגין השקעה בחו"ל | B40: 0
A41: ד. סך תשלומים למנהלי תיקים זרים | B41: 0
A42: ה. סך תשלומים בגין השקעה בקרנות סל כאשר 75 אחוזים לפחות מנכסי הקרן הם נכסים שהונפקו במדינת ישראל לפי מדדים שעליהם הורה הממונה ובתנאים שהורה | B42: 0
A43: ו. סך תשלומים בגין השקעה בקרנות סל כאשר 75 אחוזים לפחות מנכסי הקרן הם נכסים שלא הונפקו במדינת ישראל ואינם נסחרים או מוחזקים בה | B43: 0.2586348
A44: ז. סך תשלומים בגין השקעה בקרנות נאמנות ישראליות כאשר 75 אחוזים לפחות מנכסי הקרן מושקעים בנכסים שלא הונפקו במדינת ישראל ואינם נסחרים או מוחזקים בה | B44: 0
A45: ח. סך תשלומים בגין השקעה בקרנות נאמנות זרות כאשר 75 אחוזים לפחות מנכסי הקרן מושקעים בנכסים שלא הונפקו במדינת ישראל ואינם נסחרים או מוחזקים בה | B45: 0
A46: ט. סך תשלומים בגין השקעה בקרן טכנולוגיה עילית | B46: 0
A48: 12. שיעור עמלת ניהול חיצוני בפועל לפני החזר, ככל שבוצע (חלוקה של סעיף 11 בסעיף 8.ב) | B48: 7.8023061e-06
... A55: 15.ב שיעור עמלת ניהול חיצוני בפועל לאחר החזר, (חלוקה של התוצאה של סעיף 11 בניכוי סעיף 15א, בסעיף 8.ב) | B55: 7.8023061e-06
A57: סך הכל הוצאות ישירות בפועל (למעט דמי ניהול משתנים כאמור בסעיף 10)
A59: 16. סך כל הוצאות ישירות (סכום של סעיף 7 וסעיף 11 בניכוי סעיף 15א) | B59: 10.205621
A61: 17. שיעור סך ההוצאות הישירות מתוך יתרת נכסים ממוצעת (חלוקה של סעיף 16 בסעיף 8) | B61: 0.00030787575
A63: סך הכל הוצאות ישירות (לצורך חישוב שיעור עלות שנתית צפויה)
A64: 18. שיעור מגבלת עמלת ניהול חיצוני שהמשקיע המוסדי הצהיר עליה בהתאם לתקנה 2א לתקנות הוצאות ישירות עבור שנת הכספים הבאה | B64: 0.0015
...

Sheet הכשרה עוקב מדדים גמיש
A1: נספח 1- סך ההוצאות הישירות ששולמו בעד כל סוג של הוצאה ישירה לתקופה המסתיימת ביום 31.12.2024
A3: שם חברת הביטוח: הכשרה חברה לביטוח - הכשרה עוקב מדדים גמיש | B3: אלפי ₪
A5: 31.12.2024 נספח 1- סך ההוצאות הישירות ששולמו בעד כל סוג של הוצאה ישירה לתקופה המסתיימת ביום
A7: הוצאות ישירות שאינן מסוג עמלת ניהול חיצוני
A8: 1. סך הכל עמלות קנייה ומכירה של ניירות ערך סחירים | B8: 8.4462963
A9: א. סך עמלות קנייה ומכירה של ניירות ערך סחירים לצדדים קשורים
A10: ב. סך עמלות קנייה ומכירה של ניירות ערך סחירים לצדדים שאינם קשורים | B10: 8.4462963
A12: 2. סך הכל דמי שמירה בשל ניירות ערך סחירים וכל עמלה שגובה מי שמבצע את משמרות ניירות הערך עמלות (קסטודיאן) | B12: 0
A13: א. סך עמלות קסטודיאן לצדדים קשורים
A14: ב. סך עמלות קסטודיאן לצדדים שאינם קשורים | B14: 0
A16: 3. סך הכל הוצאות הנובעות מהשקעות לא סחירות | B16: 0
A17: א. הוצאה הנובעת מהשקעה בניירות ערך לא סחירים או ממתן הלוואה למי שאינו עמית או מבוטח | B17: 0
A18: ב. הוצאה הנובעת מהשקעה בזכויות במקרקעין
A20: 4. מסים החלים על משקיע מוסדי, על נכסיו, על הכנסותיו ועל עסקאות שנעשו בנכסיו
A22: 5. סך הוצאות בעד ניהול תביעות | B22: 0
A24: 6. סך הוצאות בעד מתן משכנתאות | B24: 0
A26: 7. סך הכל הוצאות ישירות שאינן מסוג עמלת ניהול חיצוני (סכום סעיפים 1 עד 6) | B26: 8.4462963
A28: 8. שווי ממוצע של נכסי הקופה או המסלול (ממוצע פשוט של סעיפים8א ו- 8ב) | B28: 19842.705
A29: א. השווי המשוערך של נכסי הקופה או המסלול נכון ליום 31 בדצמבר של שנת הכספים שהסתיימה 2024 | B29: 25842.298
A30: ב. השווי המשוערך של נכסי הקופה או המסלול נכון ליום 31 בדצמבר של שנת הכספים שהסתיימה לפני 2023 או לתקופה אחרת לפי העניין | B30: 13843.112
A32: 9. שיעור שנתי של הוצאות ישירות שאינן מסוג עמלת ניהול חיצוני (חלוקה של סעיף 7 בסעיף 8) | B32: 0.00042566254
A34: הוצאות ישירות מסוג עמלת ניהול חיצוני
