Workbook

Sheet קרן י
B1: מדיניות השקעה לשנת 2024
B2: תחילת מידע טבלה
A3: תחילת מידע טבלה צד ימין | B3: קרן י' | H3: סוף מידע טבלה צד שמאל
B4: אפיק השקעה | C4: שיעור חשיפה צפוי לשנת 2024 | D4: טווח סטייה %-/+ | E4: גבולות שיעור החשיפה הצפויה | G4: מדד הייחוס (**)
B5: מניות | C5: 0.42 | D5: 0.06 | E5: =IF(C5-D5>0,C5-D5,0) -> 0.36 | F5: =C5+D5 -> 0.48 | G5: 40%- מדד ת"א 125, 60%- MSCI WORLD AC
B6: אג"ח ממשלתי (צמוד,שקלי ומט"ח), ממשלות זרות בנטרול חשיפות בנגזרים (*) | C6: 0.06 | D6: 0.05 | E6: =IF(C6-D6>0,C6-D6,0) -> 0.01 | F6: =C6+D6 -> 0.11 | G6: מדד אג"ח ממשלתי כללי
B7: אג"ח קונצרני (קרנות נאמנות, תעודות סל) | C7: 0.27 | D7: 0.06 | E7: =IF(C7-D7>0,C7-D7,0) -> 0.21 | F7: =C7+D7 -> 0.33 | G7: 35% - תל בונד כללי , 20% - תל בונד 60 , 15% - תל בונד 50 , 15% - IBOXX HY - 15%, IBOXX IG
B8: נדל"ן | C8: 0.08 | D8: 0.05 | E8: =IF(C8-D8>0,C8-D8,0) -> 0.03 | F8: =C8+D8 -> 0.13
B9: קרנות השקעה | C9: 0.06 | D9: 0.05 | E9: =IF(C9-D9>0,C9-D9,0) -> 0.01 | F9: =C9+D9 -> 0.11
B10: אחר (Co Invest,תשתיות, גידור) | C10: 0.07 | D10: 0.05 | E10: =IF(C10-D10>0,C10-D10,0) -> 0.02 | F10: =C10+D10 -> 0.12
B11: מזומנים (*) | C11: 0.04
B12: סה"כ | C12: 1
B13: חשיפה למט"ח | C13: 0.24 | D13: 0.06 | E13: =IF(C13-D13>0,C13-D13,0) -> 0.18 | F13: =C13+D13 -> 0.3
B14: מגבלת עמלת ניהול חיצוני לשנת 2024 | C14: 0.0025
B15: סוף מידע טבלה
B16: קופה 100
B17: * מוצג בנטרול תוספת החשיפה הנובעת מהשקעה בנגזרים
B18: ** מובהר כי תיק הנכסים אינו תואם בהכרח במלואו להרכב מדד הייחוס. אין בציון מדד הייחוס בכדי להוות מצג, הצהרה או התחייבות כלשהי לגבי התשואה שתושג בפועל בתיק
A19: סוף מידע גיליון

Sheet קרן ט
B1: ='קרן י'!B1:G1 -> מדיניות השקעה לשנת 2024
B2: תחילת מידע טבלה
A3: תחילת מידע טבלה צד ימין | B3: קרן ט' | H3: סוף מידע טבלה צד שמאל
B4: אפיק השקעה | C4: ='קרן י'!C4 -> שיעור חשיפה צפוי לשנת 2024 | D4: טווח סטייה %-/+ | E4: גבולות שיעור החשיפה הצפויה | G4: מדד הייחוס (**)
B5: מניות | C5: 0.36 | D5: 0.06 | E5: =IF(C5-D5>0,C5-D5,0) -> 0.3 | F5: =C5+D5 -> 0.42 | G5: 40%- מדד ת"א 125, 60%- MSCI WORLD AC
B6: אג"ח ממשלתי (צמוד,שקלי ומט"ח), ממשלות זרות בנטרול חשיפות בנגזרים (*) | C6: 0.05 | D6: 0.05 | E6: =IF(C6-D6>0,C6-D6,0) -> 0 | F6: =C6+D6 -> 0.1 | G6: מדד אג"ח ממשלתי כללי
B7: אג"ח מיועדות (חץ) | C7: 0.35 | D7: 0.05 | E7: =IF(C7-D7>0,C7-D7,0) -> 0.3 | F7: =C7+D7 -> 0.4
B8: אג"ח קונצרני (קרנות נאמנות, תעודות סל) | C8: 0.17 | D8: 0.06 | E8: =IF(C8-D8>0,C8-D8,0) -> 0.11 | F8: =C8+D8 -> 0.23 | G8: 35% - תל בונד כללי , 20% - תל בונד 60 , 15% - תל בונד 50 , 15% - IBOXX HY - 15%, IBOXX IG
B9: אחר (קרנות השקיעה,Co Invest,תשתיות, גידור) | C9: 0.05 | D9: 0.05 | E9: =IF(C9-D9>0,C9-D9,0) -> 0 | F9: =C9+D9 -> 0.1
B10: מזומנים (*) | C10: 0.02
B11: סה"כ | C11: =SUM(C5:C10) -> 1
B12: חשיפה למט"ח | C12: 0.21 | D12: 0.06 | E12: =IF(C12-D12>0,C12-D12,0) -> 0.15 | F12: =C12+D12 -> 0.27
B13: מגבלת עמלת ניהול חיצוני לשנת 2024 | C13: 0.0015
B14: סוף מידע טבלה
B15: קופה 200
B16: * מוצג בנטרול תוספת החשיפה הנובעת מהשקעה בנגזרים
B17: ** מובהר כי תיק הנכסים אינו תואם בהכרח במלואו להרכב מדד הייחוס. אין בציון מדד הייחוס בכדי להוות מצג, הצהרה או התחייבות כלשהי לגבי התשואה שתושג בפועל בתיק
A18: סוף מידע גיליון

Sheet פרט - אשכול 1 - אקטיבי
B1: ='קרן י'!B1 -> מדיניות השקעה לשנת 2024
B2: תחילת מידע טבלה
A3: תחילת מידע טבלה צד ימין | B3: הפניקס ביטוח מסלול כללי - לשעבר מסלול כללי 1 | I3: סוף מידע טבלה צד שמאל
B4: מספר מסלול באוצר 50
B5: אפיק השקעה | C5: שיעור חשיפה צפוי לשנת 2024 (החל מיום 1.7.24) | D5: שיעור חשיפה ליום 30.6.24 | E5: טווח סטייה %-/+ | F5: גבולות שיעור החשיפה הצפויה | H5: מדד הייחוס (**)
B6: מניות | C6: 0.42 | D6: 0.42 | E6: 0.06 | F6: =IF(C6-E6>0,C6-E6,0) -> 0.36 | G6: =C6+E6 -> 0.48 | H6: 40%- מדד ת"א 125, 60%- MSCI WORLD AC
B7: אג"ח ממשלתי (צמוד,שקלי ומט"ח), ממשלות זרות בנטרול חשיפות בנגזרים (*) | C7: 0.08 | D7: 0.08 | E7: 0.05 | F7: =IF(C7-E7>0,C7-E7,0) -> 0.03 | G7: =C7+E7 -> 0.13 | H7: מדד אג"ח ממשלתי כללי
B8: אג"ח קונצרני (קרנות נאמנות, תעודות סל) | C8: 0.3 | D8: 0.33 | E8: 0.06 | F8: =IF(C8-E8>0,C8-E8,0) -> 0.24 | G8: =C8+E8 -> 0.36 | H8: 35% - תל בונד כללי , 20% - תל בונד 60 , 15% - תל בונד 50 , 15% - IBOXX HY - 15%, IBOXX IG
B9: נדל"ן | C9: 0.04 | D9: 0.05 | E9: 0.05 | F9: =IF(C9-E9>0,C9-E9,0) -> 0 | G9: =C9+E9 -> 0.09
B10: קרנות השקעה | C10: 0.04 | D10: 0.05 | E10: 0.05 | F10: =IF(C10-E10>0,C10-E10,0) -> 0 | G10: =C10+E10 -> 0.09
B11: תשתיות | C11: 0.04 | E11: 0.05 | F11: =IF(C11-E11>0,C11-E11,0) -> 0 | G11: =C11+E11 -> 0.09
B12: אחר (Co Invest,תשתיות, גידור) | C12: 0.04 | D12: 0.05 | E12: 0.05 | F12: =IF(C12-E12>0,C12-E12,0) -> 0 | G12: =C12+E12 -> 0.09
B13: מזומנים (*) | C13: 0.04 | D13: 0.02
B14: סה"כ | C14: =SUM(C6:C13) -> 1 | D14: 1
B15: חשיפה למט"ח | C15: 0.24 | D15: 0.22 | E15: 0.06 | F15: =IF(C15-E15>0,C15-E15,0) -> 0.18 | G15: =C15+E15 -> 0.3
B16: מגבלת עמלת ניהול חיצוני לשנת 2024 | C16: 0.0025
B17: סוף מידע טבלה
B18: תחילת מידע טבלה
A19: תחילת מידע טבלה צד ימין | B19: הפניקס ביטוח מסלול כספי (שקלי) - לשעבר הפניקס ביטוח מסלול שקלי טווח קצר | I19: סוף מידע טבלה צד שמאל
B21: מספר מסלול באוצר 9592
B22: אפיק השקעה | C22: שיעור חשיפה צפוי לשנת 2024 (החל מיום 1.7.24) | D22: שיעור חשיפה ליום 30.6.24 | E22: טווח סטיה | F22: גבולות שיעור החשיפה הצפויה | H22: מדד ייחוס
B23: אג"ח ממשלתי (צמוד, שקלי ומט"ח), ממשלות זרות בנטרול חשיפות בנגזרים | C23: 0.75 | D23: 0.75 | E23: 0.05 | F23: =+C23-E23 -> 0.7 | G23: =+C23+E23 -> 0.8 | H23: מדד אג"ח ממשלתי כללי
B24: אג"ח קונצרני (כולל קרנות נאמנות, תעודות סל) | C24: 0.23 | D24: 0.2 | E24: 0.06 | F24: =+C24-E24 -> 0.17 | G24: =+C24+E24 -> 0.29 | H24: 35% - תל בונד כללי , 20% - תל בונד 60 , 15% - תל בונד 50 , 15% - IBOXX HY - 15%, IBOXX IG
B25: מזומנים (*) | C25: 0.02 | D25: 0.05
B26: סה"כ | C26: =SUM(C23:C25) -> 1 | D26: =SUM(D23:D25) -> 1
B27: חשיפה למט"ח | C27: 0 | D27: 0 | E27: 0.06 | F27: 0 | G27: =+C27+E27 -> 0.06
B28: מגבלת עמלת ניהול חיצוני לשנת 2024 | C28: 0.0005
B29: סוף מידע טבלה
B30: תחילת מידע טבלה
A31: תחילת מידע טבלה צד ימין | B31: הפניקס פרט מסלול אשראי ואג"ח עם מניות (עד 25%) - לשעבר הפניקס ביטוח מסלול אג"ח עד 25% | I31: סוף מידע טבלה צד שמאל
B32: מספר מסלול באוצר 9585
B33: אפיק השקעה | C33: שיעור חשיפה צפוי לשנת 2024 (החל מיום 1.7.24) | D33: שיעור חשיפה ליום 30.6.24 | E33: טווח סטיה | F33: גבולות שיעור החשיפה הצפויה | H33: מדד ייחוס
B34: מניות (כולל תעודות סל, אופציות, קרנות נאמנות) | C34: 0.19 | D34: 0.17 | E34: 0.06 | F34: =+C34-E34 -> 0.13 | G34: =+C34+E34 -> 0.25 | H34: 40%- מדד ת"א 125 , 60%- MSCI WORLD AC
B35: אג"ח ממשלתי (צמוד, שקלי ומט"ח), ממשלות זרות בנטרול חשיפות בנגזרים | C35: 0.15 | D35: 0.17 | E35: 0.05 | F35: =+C35-E35 -> 0.1 | G35: =+C35+E35 -> 0.2 | H35: מדד אג"ח ממשלתי כללי
B36: אג"ח קונצרני (כולל קרנות נאמנות, תעודות סל) | C36: 0.53 | D36: 0.56 | E36: 0.06 | F36: =+C36-E36 -> 0.47 | G36: =+C36+E36 -> 0.59 | H36: 35% - תל בונד כללי , 20% - תל בונד 60 , 15% - תל בונד 50 , 15% - IBOXX HY - 15%, IBOXX IG
B37: אחר ( Co Invest, נדל"ן, קרנות השקעהתשתיות, גידור) | C37: 0.08 | D37: 0.06 | E37: 0.05 | F37: =+C37-E37 -> 0.03 | G37: =+C37+E37 -> 0.13
B38: מזומנים (*) | C38: 0.05 | D38: 0.04 | F38: =+C38-E38 -> 0.05 | G38: =+C38+E38 -> 0.05
B39: סה"כ | C39: =SUM(C34:C38) -> 1 | D39: =SUM(D34:D38) -> 1
B40: חשיפה למט"ח | C40: 0.16 | D40: 0.16 | E40: 0.06 | F40: =IF(C40-E40>0,C40-E40,0) -> 0.1 | G40: =C40+E40 -> 0.22
B41: מגבלת עמלת ניהול חיצוני לשנת 2024 | C41: 0.0025
...

Sheet פרט - אשכול 1 אקטיבי - בלאקרוק
B1: ='קרן י'!B1:I1 -> מדיניות השקעה לשנת 2024
B2: תחילת מידע טבלה
A3: תחילת מידע טבלה צד ימין | B3: הפניקס Blackrock כללי | I3: סוף מידע טבלה צד שמאל
B4: מספר מסלול באוצר 13644
B5: אפיק השקעה | C5: שיעור חשיפה צפוי לשנת 2024 (החל מיום 1.7.24) | D5: שיעור חשיפה ליום 30.6.24 | E5: טווח סטייה %-/+ | F5: גבולות שיעור החשיפה הצפויה | H5: מדד הייחוס (**)
B6: מניות (כולל תעודות סל, אופציות, קרנות נאמנות) | C6: 0.6 | D6: 0.6 | E6: 0.06 | F6: =+C6-E6 -> 0.54 | G6: =+C6+E6 -> 0.66 | H6: MSCI WORLD AC
B7: אג"ח ממשלתי (צמוד,שקלי ומט"ח), ממשלות זרות בנטרול חשיפות בנגזרים (*) | C7: 0.26 | D7: 0.26 | E7: 0.05 | F7: =+C7-E7 -> 0.21 | G7: =+C7+E7 -> 0.31 | H7: 100%-(CFIIWDCS index) World gov bond index
B8: אג"ח קונצרני (כולל קרנות נאמנות, תעודות סל) | C8: 0.13 | D8: 0.13 | E8: 0.06 | F8: =+C8-E8 -> 0.07 | G8: =+C8+E8 -> 0.19 | H8: 100%-(GOBC Index)ICE BOFA global corp index
B9: מזומנים (*) | C9: 0.01 | D9: 0.01
B10: סה"כ | C10: =SUM(C6:C9) -> 1 | D10: =SUM(D6:D9) -> 1
B11: חשיפה למט"ח | C11: 0.95 | D11: 1 | E11: 0.06 | F11: =+C11-E11 -> 0.89 | G11: =+C11+E11 -> 1.01
B12: מגבלת עמלת ניהול חיצוני לשנת 2024 | C12: 0
B13: סוף מידע טבלה
B16: תחילת מידע טבלה
A17: תחילת מידע טבלה צד ימין | B17: הפניקס Blackrock אשראי ואג"ח | I17: סוף מידע טבלה צד שמאל
B18: מספר מסלול באוצר 14663
B19: אפיק השקעה | C19: שיעור חשיפה צפוי לשנת 2024 (החל מיום 1.7.24) | D19: שיעור חשיפה ליום 30.6.24 | E19: טווח סטיה | F19: גבולות שיעור החשיפה הצםויה | H19: מדד ייחוס
B20: אג"ח ממשלתי (צמוד, שקלי ומט"ח), ממשלות זרות בנטרול חשיפות בנגזרים | C20: 0.65 | D20: 0.7 | E20: 0.05 | F20: =+C20-E20 -> 0.6 | G20: =+C20+E20 -> 0.7 | H20: מדד אג"ח ממשלתי כללי
B21: אג"ח קונצרני (כולל קרנות נאמנות, תעודות סל) | C21: 0.3 | D21: 0.25 | E21: 0.06 | F21: =+C21-E21 -> 0.24 | G21: =+C21+E21 -> 0.36 | H21: 35% - תל בונד כללי , 20% - תל בונד 60 , 15% - תל בונד 50 , 15% - IBOXX HY - 15%, IBOXX IG
B22: מזומנים (*) | C22: 0.05 | D22: 0.05
B23: סה"כ | C23: =SUM(C20:C22) -> 1 | D23: =SUM(D20:D22) -> 1
B24: חשיפה למט"ח | C24: 0.95 | D24: 0.99 | E24: 0.06 | F24: =IF(C24-E24>0,C24-E24,0) -> 0.89 | G24: =C24+E24 -> 1.01
B25: מגבלת עמלת ניהול חיצוני לשנת 2024 | C25: 0
B26: סוף מידע טבלה
B28: תחילת מידע טבלה
A29: תחילת מידע טבלה צד ימין | B29: הפניקס Blackrock מניות | I29: סוף מידע טבלה צד שמאל
B30: מספר מסלול באוצר 13645
B31: אפיק השקעה | C31: שיעור חשיפה צפוי לשנת 2024 (החל מיום 1.7.24) | D31: שיעור חשיפה ליום 30.6.24 | E31: טווח סטיה | F31: גבולות שיעור החשיפה הצםויה | H31: מדד ייחוס
B32: מניות (כולל תעודות סל, אופציות, קרנות נאמנות) | C32: 0.94 | D32: 0.94 | E32: 0.06 | F32: =+C32-E32 -> 0.88 | G32: =+C32+E32 -> 1 | H32: MSCI WORLD AC
B33: מזומנים (*) | C33: 0.06 | D33: 0.06 | F33: =+C33-E33 -> 0.06 | G33: =+C33+E33 -> 0.06
B34: סה"כ | C34: =SUM(C32:C33) -> 1 | D34: =SUM(D32:D33) -> 1
B35: חשיפה למט"ח | C35: 0.95 | D35: 0.96 | E35: 0.06 | F35: =IF(C35-E35>0,C35-E35,0) -> 0.89 | G35: =C35+E35 -> 1.01
B36: מגבלת עמלת ניהול חיצוני לשנת 2024 | C36: 0
B37: סוף מידע טבלה
B38: * מוצג בנטרול תוספת החשיפה הנובעת מהשקעה בנגזרים
B39: ** מובהר כי תיק הנכסים אינו תואם בהכרח במלואו להרכב מדד הייחוס. אין בציון מדד הייחוס בכדי להוות מצג, הצהרה או התחייבות כלשהי לגבי התשואה שתושג בפועל בתיק
A40: סוף מידע גיליון

Sheet פרט - אשכול 1 אקטיבי - אפולו
B1: ='קרן י'!B1 -> מדיניות השקעה לשנת 2024
B3: תחילת מידע טבלה
A4: תחילת מידע טבלה צד ימין | B4: הפניקס ביטוח-אפולו אשראי ואג"ח - מסלול חדש החל מ - 01.11.2024 | H4: סוף מידע טבלה צד שמאל
B6: אפיק השקעה | C6: שיעור חשיפה צפוי לשנת 2024 (החל מיום 1.11.24) | D6: טווח סטיה | E6: גבולות שיעור החשיפה הצפויה | G6: מדד ייחוס
B7: אג"ח קונצרני (כולל קרנות נאמנות, תעודות סל) | C7: 0.92 | D7: 0.06 | E7: =+C7-D7 -> 0.86 | F7: =+C7+D7 -> 0.98 | G7: IBOXX IG
B8: אחר ( Co Invest, נדל"ן, קרנות השקעה,תשתיות, גידור) | C8: 0.03 | D8: 0.05 | E8: 0 | F8: =+C8+D8 -> 0.08
B9: מזומנים (*) | C9: 0.05 | D9: 0.05 | E9: =+C9-D9 -> 0 | F9: =+C9+D9 -> 0.1
B10: סה"כ | C10: =SUM(C7:C9) -> 1
B11: חשיפה למט"ח | C11: 0.94 | D11: 0.06 | E11: =+C11-D11 -> 0.88 | F11: =+C11+D11 -> 1
B12: מגבלת עמלת ניהול חיצוני לשנת 2024 | C12: 0
B13: סוף מידע טבלה
B14: * מוצג בנטרול תוספת החשיפה הנובעת מהשקעה בנגזרים
B15: ** מובהר כי תיק הנכסים אינו תואם בהכרח במלואו להרכב מדד הייחוס. אין בציון מדד הייחוס בכדי להוות מצג, הצהרה או התחייבות כלשהי לגבי התשואה שתושג בפועל בתיק
A16: סוף מידע גיליון

Sheet פרט - אשכול 3 סחיר
B1: ='קרן י'!B1:I1 -> מדיניות השקעה לשנת 2024
B3: תחילת מידע טבלה
A4: תחילת מידע טבלה צד ימין | B4: הפניקס פרט מסלול אג"ח סחיר - לשעבר הפניקס מסלול מתמחה אג"ח חו"ל שמסלול פאסיבי מדדי אג"ח חו"ל מוזג אליו | I4: סוף מידע טבלה צד שמאל
B5: מספר מסלול באוצר 12881
B6: אפיק השקעה | C6: שיעור חשיפה צפוי לשנת 2024 (החל מיום 1.7.24) | D6: שיעור חשיפה ליום 30.6.24 | E6: טווח סטיה | F6: גבולות שיעור החשיפה הצפויה | H6: מדד ייחוס
B7: אג"ח ממשלתי (צמוד, שקלי ומט"ח), ממשלות זרות בנטרול חשיפות בנגזרים | C7: 0.02 | D7: 0.02 | E7: 0.05 | F7: 0 | G7: =+C7+E7 -> 0.07 | H7: מדד אג"ח ממשלתי כללי
B8: אג"ח קונצרני (כולל קרנות נאמנות, תעודות סל) | C8: 0.93 | D8: 0.93 | E8: 0.06 | F8: =+C8-E8 -> 0.87 | G8: =+C8+E8 -> 0.99 | H8: 50% - IBOXX HY - 50%, IBOXX IG
B9: אחר ( Co Invest, נדל"ן, קרנות השקעהתשתיות, גידור) | C9: 0 | D9: 0.02 | E9: 0.05 | F9: 0 | G9: =+C9+E9 -> 0.05
B10: מזומנים (*) | C10: 0.05 | D10: 0.03
B11: סה"כ | C11: =SUM(C7:C10) -> 1 | D11: =SUM(D7:D10) -> 1
B12: חשיפה למט"ח | C12: 0.98 | D12: 0.97 | E12: 0.06 | F12: =IF(C12-E12>0,C12-E12,0) -> 0.92 | G12: =C12+E12 -> 1.04
B13: מגבלת עמלת ניהול חיצוני לשנת 2024 | C13: 0.002
B14: סוף מידע טבלה
B15: תחילת מידע טבלה
A16: תחילת מידע טבלה צד ימין | B16: הפניקס פרט מסלול מניות סחיר - לשעבר הפניקס מסלול מתמחה מניות חו"ל | I16: סוף מידע טבלה צד שמאל
B17: מספר מסלול באוצר 12882
B18: אפיק השקעה | C18: שיעור חשיפה צפוי לשנת 2024 (החל מיום 1.7.24) | D18: שיעור חשיפה ליום 30.6.24 | E18: טווח סטיה | F18: גבולות שיעור החשיפה הצפויה | H18: מדד ייחוס
B19: מניות (כולל תעודות סל, אופציות, קרנות נאמנות) | C19: 0.93 | D19: 0.93 | E19: 0.06 | F19: =+C19-E19 -> 0.87 | G19: =+C19+E19 -> 0.99 | H19: MSCI WORLD AC
B20: אג"ח ממשלתי (צמוד, שקלי ומט"ח), ממשלות זרות בנטרול חשיפות בנגזרים | C20: 0.03 | D20: 0.03 | E20: 0.05 | F20: =+C20-E20 -> -0.02 | G20: =+C20+E20 -> 0.08 | H20: מדד אג"ח ממשלתי כללי
B21: מזומנים (*) | C21: 0.04 | D21: 0.04
B22: סה"כ | C22: =SUM(C19:C21) -> 1 | D22: =SUM(D19:D21) -> 1
B23: חשיפה למט"ח | C23: 0.95 | D23: 0.96 | E23: 0.06 | F23: =IF(C23-E23>0,C23-E23,0) -> 0.89 | G23: =C23+E23 -> 1.01
B24: מגבלת עמלת ניהול חיצוני לשנת 2024 | C24: 0.0025
B25: סוף מידע טבלה
B26: * מוצג בנטרול תוספת החשיפה הנובעת מהשקעה בנגזרים
B27: ** מובהר כי תיק הנכסים אינו תואם בהכרח במלואו להרכב מדד הייחוס. אין בציון מדד הייחוס בכדי להוות מצג, הצהרה או התחייבות כלשהי לגבי התשואה שתושג בפועל בתיק
A28: סוף מידע גיליון
B30: הפניקס ביטוח מסלול אג"ח עד 25%
B32: אפיק השקעה | C32: טווח סטיה | D32: גבולות שיעור החשיפה הצםויה | F32: מדד ייחוס
B33: מניות (כולל תעודות סל, אופציות, קרנות נאמנות) | C33: 0.06 | D33: =+#REF!-C33 -> #REF! | E33: =+#REF!+C33 -> #REF! | F33: 40%- מדד ת"א 125 , 60%- MSCI WORLD AC
B34: אג"ח ממשלתי (צמוד, שקלי ומט"ח), ממשלות זרות בנטרול חשיפות בנגזרים | C34: 0.05 | D34: =+#REF!-C34 -> #REF! | E34: =+#REF!+C34 -> #REF! | F34: מדד אג"ח ממשלתי כללי
B35: אג"ח קונצרני (כולל קרנות נאמנות, תעודות סל) | C35: 0.06 | D35: =+#REF!-C35 -> #REF! | E35: =+#REF!+C35 -> #REF! | F35: 35% - תל בונד כללי , 20% - תל בונד 60 , 15% - תל בונד 50 , 15% - IBOXX HY - 15%, IBOXX IG
B36: אחר ( Co Invest, נדל"ן, קרנות השקעהתשתיות, גידור) | C36: 0.05 | D36: 0 | E36: =+#REF!+C36 -> #REF!
B37: מזומנים (*) | D37: =+#REF!-C37 -> #REF! | E37: =+#REF!+C37 -> #REF!
B38: סה"כ
B39: חשיפה למט"ח | C39: 0.05 | D39: =IF(#REF!-C39>0,#REF!-C39,0) -> #REF! | E39: =#REF!+C39 -> #REF!
B40: מגבלת עמלת ניהול חיצוני לשנת 2024
B42: כספי (שקלי) - לשעבר הפניקס ביטוח מסלול שקלי טווח קצר
B44: אפיק השקעה | C44: שיעור חשיפה מבוקש לאחר רפורמה | D44: שיעור חשיפה צפוי לשנת 2024 | E44: טווח סטיה | F44: גבולות שיעור החשיפה הצםויה | H44: מדד ייחוס
B45: אג"ח ממשלתי (צמוד, שקלי ומט"ח), ממשלות זרות בנטרול חשיפות בנגזרים | C45: 0.75 | D45: 0.75 | E45: 0.05 | F45: =+D45-E45 -> 0.7 | G45: =+D45+E45 -> 0.8 | H45: מדד אג"ח ממשלתי כללי
...

Sheet פרט - אשכול 4 - עוקב מדדים
B1: ='קרן י'!B1 -> מדיניות השקעה לשנת 2024
B3: תחילת מידע טבלה
A4: תחילת מידע טבלה צד ימין | B4: הפניקס פרט מסלול עוקב מדדים גמיש - פאסיבי כללי | J4: סוף מידע טבלה צד שמאל
B5: מספר מסלול באוצר 12092
B6: אפיק השקעה | C6: שיעור חשיפה צפוי לשנת 2024 (החל מיום 1.7.24) | D6: שיעור חשיפה ליום 30.6.24 | E6: טווח סטייה %-/+ | F6: גבולות שיעור החשיפה הצפויה | H6: מדד הייחוס (**)
H7: 0.27 | I7: S&P500
H8: 0.096 | I8: STOXX600
B9: מניות (תעודות סל, אופציות, קרנות נאמנות) | C9: 0.54 | D9: 0.54 | E9: 0.06 | F9: =C9-E9 -> 0.48 | G9: =C9+E9 -> 0.6 | H9: 0.096 | I9: MSCI EM
H10: 0.048 | I10: TPX
H11: 0.09 | I11: NASDAQ100
H12: 0.36 | I12: תל אביב 125
H13: 0.02 | I13: ת"א SME60
H14: 0.02 | I14: BlueStar TA-BIG Tech Israel Tech
H15: 0.12 | I15: משקל גליל 0-2
B16: אג"ח ממשלתי (צמוד, שקלי ומט"ח), ממשלות | C16: 0.08 | D16: 0.08 | E16: 0.05 | F16: =C16-E16 -> 0.03 | G16: =C16+E16 -> 0.13 | H16: 0.17 | I16: משקל גליל 2-5
B17: זרות בנטרול חשיפות בנגזרים | H17: 0.07 | I17: משקל גליל 5-10
H18: 0.09 | I18: משקל גליל 10+
H19: 0.13 | I19: משקל שחר 0-2
H20: 0.17 | I20: משקל שחר 2-5
H21: 0.09 | I21: משקל שחר 5-10
H22: 0.16 | I22: משקל שחר 10+
H23: 0.126 | I23: IBOXX HY
H24: 0.072 | I24: IBXXC1D1
H25: 0.045 | I25: JGENUUG
B26: אג"ח קונצרני (קרנות נאמנות, תעודות סל) | C26: 0.36 | D26: 0.36 | E26: 0.06 | F26: =C26-E26 -> 0.3 | G26: =C26+E26 -> 0.42 | H26: 0.018 | I26: JCMBCOMP
H27: 0.039 | I27: IBOXIG
H28: 0.315 | I28: תל בונד 60
H29: 0.231 | I29: תל בונד שקלי
H30: 0.07 | I30: תל בונד תשואות
H31: 0.035 | I31: תל בונד תשואות שקלי
H32: 0.049 | I32: תל בונד דולר
B33: מזומנים (*) | C33: 0.02 | D33: 0.02 | H33: 1 | I33: ריבית פח"ק
B34: סה"כ | C34: =SUM(C7:C33) -> 1 | D34: 1
B35: חשיפה למט"ח | C35: 0.22 | D35: 0.22 | E35: 0.06 | F35: =IF((C35-E35)<0,0,C35-E35) -> 0.16 | G35: =C35+E35 -> 0.28
B36: מגבלת עמלת ניהול חיצוני לשנת 2024 | D36: 0.001
B37: סוף מידע טבלה
B38: תחילת מידע טבלה
A39: תחילת מידע טבלה צד ימין | B39: הפניקס ביטוח מסלול עוקב מדד s&p 500 - לשעבר ביטוח מחקה מדד s&p | I39: סוף מידע טבלה צד שמאל
B40: מספר מסלול באוצר 9554
B41: אפיק השקעה | C41: שיעור חשיפה צפוי לשנת 2024 (החל מיום 1.7.24) | D41: שיעור חשיפה ליום 30.6.24 | E41: טווח סטיה | F41: גבולות שיעור החשיפה הצפויה | H41: מדד ייחוס
...

Sheet תלוי גיל פאסיבי
B1: ='קרן י'!B1 -> מדיניות השקעה לשנת 2024
B2: ביטוח תלוי גיל פאסיבי לבני 50 ומטה | J2: מסלולי הציליאני הפאסיבי מתמזגים למסלולי הציליאני האקטיבי
B3: אפיק השקעה | C3: שיעור חשיפה צפוי לשנת 2024 | D3: טווח סטייה %-/+ | E3: גבולות שיעור החשיפה הצפויה | G3: מדד הייחוס (**)
G4: 0.27 | H4: S&P500
G5: 0.096 | H5: STOXX600
B6: מניות (תעודות סל, אופציות, קרנות נאמנות) | C6: 0.66 | D6: 0.06 | E6: =C6-D6 -> 0.6 | F6: =C6+D6 -> 0.72 | G6: 0.096 | H6: MSCI EM
G7: 0.048 | H7: TPX
G8: 0.09 | H8: NASDAQ100
G9: 0.36 | H9: תל אביב 125
G10: 0.02 | H10: ת"א SME60
G11: 0.02 | H11: BlueStar TA-BIG Tech Israel Tech
G12: 0.12 | H12: משקל גליל 0-2
B13: אג"ח ממשלתי (צמוד, שקלי ומט"ח), ממשלות | C13: 0.02 | D13: 0.05 | E13: =C13-D13 -> -0.03 | F13: =C13+D13 -> 0.07 | G13: 0.17 | H13: משקל גליל 2-5
B14: זרות בנטרול חשיפות בנגזרים | G14: 0.07 | H14: משקל גליל 5-10
G15: 0.09 | H15: משקל גליל 10+
G16: 0.13 | H16: משקל שחר 0-2
G17: 0.17 | H17: משקל שחר 2-5
G18: 0.09 | H18: משקל שחר 5-10
G19: 0.16 | H19: משקל שחר 10+
G20: 0.126 | H20: IBOXX HY
G21: 0.072 | H21: IBXXC1D1
G22: 0.045 | H22: JGENUUG
B23: אג"ח קונצרני (קרנות נאמנות, תעודות סל) | C23: 0.3 | D23: 0.06 | E23: =C23-D23 -> 0.24 | F23: =C23+D23 -> 0.36 | G23: 0.018 | H23: JCMBCOMP
G24: 0.039 | H24: IBOXIG
G25: 0.315 | H25: תל בונד 60
G26: 0.231 | H26: תל בונד שקלי
G27: 0.07 | H27: תל בונד תשואות
G28: 0.035 | H28: תל בונד תשואות שקלי
G29: 0.049 | H29: תל בונד דולר
B30: אחר | C30: 0 | D30: 0.05 | E30: =IF((C30-D30)<0,0,C30-D30) -> 0 | F30: =C30+D30 -> 0.05
B31: מזומנים (*) | C31: 0.02 | G31: 1 | H31: ריבית פח"ק
B32: סה"כ | C32: =SUM(C4:C31) -> 1
B33: חשיפה למט"ח | C33: 0.2 | D33: 0.06 | E33: =C33-D33 -> 0.14 | F33: =C33+D33 -> 0.26
B34: מגבלת עמלת ניהול חיצוני לשנת 2024 | C34: 0.001
B35: קופה 4211
B37: ביטוח תלוי גיל פאסיבי לבני 50 עד 60 | J37: מסלולי הציליאני הפאסיבי מתמזגים למסלולי הציליאני האקטיבי
B38: אפיק השקעה | C38: שיעור חשיפה צפוי לשנת 2024 | D38: טווח סטייה %-/+ | E38: גבולות שיעור החשיפה הצפויה | G38: מדד הייחוס (**)
G39: 0.27 | H39: S&P500
G40: 0.096 | H40: STOXX600
G41: 0.096 | H41: MSCI EM
...

Sheet פרט - אשכול 5
B1: ='קרן י'!B1 -> מדיניות השקעה לשנת 2024
B3: תחילת מידע טבלה
A4: תחילת מידע טבלה צד ימין | B4: הפניקס ביטוח שריעה - מסלול חדש החל מ - 01.07.2024 | H4: סוף מידע טבלה צד שמאל
B5: מספר מסלול באוצר 15206
B6: אפיק השקעה | C6: שיעור חשיפה צפוי לשנת 2024 (החל מיום 1.7.24) | D6: טווח סטיה | E6: גבולות שיעור החשיפה הצפויה | G6: מדד ייחוס
B7: מניות (כולל תעודות סל, אופציות, קרנות נאמנות) | C7: 0.92 | D7: 0.06 | E7: =+C7-D7 -> 0.86 | F7: =+C7+D7 -> 0.98 | G7: s&p שריעה
B8: מזומנים (*) | C8: 0.08 | E8: =+C8-D8 -> 0.08 | F8: =+C8+D8 -> 0.08
B9: סה"כ | C9: =SUM(C7:C8) -> 1
B10: חשיפה למט"ח | C10: 0.95 | D10: 0.06 | E10: =IF(C10-D10>0,C10-D10,0) -> 0.89 | F10: =C10+D10 -> 1.01
B11: מגבלת עמלת ניהול חיצוני לשנת 2024 | C11: 0.0006
B12: סוף מידע טבלה
B13: תחילת מידע טבלה
A14: תחילת מידע טבלה צד ימין | B14: הפניקס ביטוח מסלול הלכה | I14: סוף מידע טבלה צד שמאל
B15: אפיק השקעה | C15: שיעור חשיפה צפוי לשנת 2024 (החל מיום 1.7.24) | D15: שיעור חשיפה ליום 30.6.24 | E15: טווח סטייה %-/+ | F15: גבולות שיעור החשיפה הצפויה | H15: מדד הייחוס (**)
B16: מניות | C16: 0.46 | D16: 0.46 | E16: 0.06 | F16: =IF(C16-E16>0,C16-E16,0) -> 0.4 | G16: =C16+E16 -> 0.52 | H16: 40%- מדד ת"א 125, 60%- MSCI WORLD AC
B17: אג"ח ממשלתי (צמוד,שקלי ומט"ח), ממשלות זרות בנטרול חשיפות בנגזרים (*) | C17: 0.19 | D17: 0.19 | E17: 0.05 | F17: =IF(C17-E17>0,C17-E17,0) -> 0.14 | G17: =C17+E17 -> 0.24 | H17: מדד אג"ח ממשלתי כללי
B18: אג"ח קונצרני (קרנות נאמנות, תעודות סל) | C18: 0.31 | D18: 0.31 | E18: 0.06 | F18: =IF(C18-E18>0,C18-E18,0) -> 0.25 | G18: =C18+E18 -> 0.37 | H18: 70% - מדד תל בונד 60 , 30% - מדד BarCap Global Corporate Total Return Bond Index UnHedged
B19: מזומנים (*) | C19: 0.04 | D19: 0.04
B20: סה"כ | C20: =SUM(C16:C19) -> 1 | D20: 1
B21: חשיפה למט"ח | C21: 0.21 | D21: 0.21 | E21: 0.06 | F21: =IF(C21-E21>0,C21-E21,0) -> 0.15 | G21: =C21+E21 -> 0.27
B22: מגבלת עמלת ניהול חיצוני לשנת 2024 | D22: 0.001
B23: סוף מידע טבלה
B25: * מוצג בנטרול תוספת החשיפה הנובעת מהשקעה בנגזרים
B26: ** מובהר כי תיק הנכסים אינו תואם בהכרח במלואו להרכב מדד הייחוס. אין בציון מדד הייחוס בכדי להוות מצג, הצהרה או התחייבות כלשהי לגבי התשואה שתושג בפועל בתיק

Sheet גילאי
B1: ='קרן י'!B1 -> מדיניות השקעה לשנת 2024
B3: תחילת מידע טבלה
A4: תחילת מידע טבלה צד ימין | B4: הפניקס ביטוח מסלול תלוי גיל לגילאי 0-50 | I4: סוף מידע טבלה צד שמאל
B5: מספר מסלול באוצר 471 | C5: מספר מסלול באוצר 471
B6: אפיק השקעה | C6: שיעור חשיפה צפוי לשנת 2024 (החל מיום 1.7.24) | D6: שיעור חשיפה ליום 30.6.24 | E6: טווח סטייה %-/+ | F6: גבולות שיעור החשיפה הצפויה | H6: מדד הייחוס (**)
B7: מניות | C7: 0.53 | D7: 0.5 | E7: 0.06 | F7: =IF(C7-E7>0,C7-E7,0) -> 0.47 | G7: =C7+E7 -> 0.59 | H7: 40%- מדד ת"א 125, 60%- MSCI WORLD AC
B8: אג"ח ממשלתי (צמוד,שקלי ומט"ח), ממשלות זרות בנטרול חשיפות בנגזרים (*) | C8: 0.05 | D8: 0.05 | E8: 0.05 | F8: =IF(C8-E8>0,C8-E8,0) -> 0 | G8: =C8+E8 -> 0.1 | H8: מדד אג"ח ממשלתי כללי
B9: אג"ח קונצרני (קרנות נאמנות, תעודות סל) | C9: 0.25 | D9: 0.27 | E9: 0.06 | F9: =IF(C9-E9>0,C9-E9,0) -> 0.19 | G9: =C9+E9 -> 0.31 | H9: 35% - תל בונד כללי , 20% - תל בונד 60 , 15% - תל בונד 50 , 15% - IBOXX HY - 15%, IBOXX IG
B10: קרנות השקעה | C10: 0.05 | D10: 0.06 | E10: 0.05 | F10: =IF(C10-E10>0,C10-E10,0) -> 0 | G10: =C10+E10 -> 0.1
B11: Co Invest | C11: 0.05 | D11: 0.05 | E11: 0.05 | F11: =IF(C11-E11>0,C11-E11,0) -> 0 | G11: =C11+E11 -> 0.1
B12: אחר (תשתיות, גידור) | C12: 0.05 | D12: 0.05 | E12: 0.05 | F12: =IF(C12-E12>0,C12-E12,0) -> 0 | G12: =C12+E12 -> 0.1
B13: מזומנים (*) | C13: 0.02 | D13: 0.02
B14: סה"כ | C14: =SUM(C7:C13) -> 1 | D14: 1
B15: חשיפה למט"ח | C15: 0.22 | D15: 0.22 | E15: 0.06 | F15: =IF(C15-E15>0,C15-E15,0) -> 0.16 | G15: =C15+E15 -> 0.28
B16: מגבלת עמלת ניהול חיצוני לשנת 2024 | D16: 0.0033
B17: סוף מידע טבלה
B18: תחילת מידע טבלה
A19: תחילת מידע טבלה צד ימין | B19: הפניקס ביטוח מסלול תלוי גיל לגילאי 50-60 | I19: סוף מידע טבלה צד שמאל
B20: מספר מסלול באוצר 9593 | D20: מספר מסלול באוצר 9593
B21: אפיק השקעה | C21: שיעור חשיפה צפוי לשנת 2024 (החל מיום 1.7.24) | D21: שיעור חשיפה ליום 30.6.24 | E21: טווח סטייה %-/+ | F21: גבולות שיעור החשיפה הצפויה | H21: מדד הייחוס (**)
B22: מניות | C22: 0.42 | D22: 0.42 | E22: 0.06 | F22: =IF(C22-E22>0,C22-E22,0) -> 0.36 | G22: =C22+E22 -> 0.48 | H22: 40%- מדד ת"א 125, 60%- MSCI WORLD AC
B23: אג"ח ממשלתי (צמוד,שקלי ומט"ח), ממשלות זרות בנטרול חשיפות בנגזרים (*) | C23: 0.15 | D23: 0.15 | E23: 0.05 | F23: =IF(C23-E23>0,C23-E23,0) -> 0.1 | G23: =C23+E23 -> 0.2 | H23: מדד אג"ח ממשלתי כללי
B24: אג"ח קונצרני (קרנות נאמנות, תעודות סל) | C24: 0.31 | D24: 0.32 | E24: 0.06 | F24: =IF(C24-E24>0,C24-E24,0) -> 0.25 | G24: =C24+E24 -> 0.37 | H24: 35% - תל בונד כללי , 20% - תל בונד 60 , 15% - תל בונד 50 , 15% - IBOXX HY - 15%, IBOXX IG
B25: קרנות השקעה | C25: 0.03 | D25: 0.03 | E25: 0.05 | F25: =IF(C25-E25>0,C25-E25,0) -> 0 | G25: =C25+E25 -> 0.08
B26: אחר (Co Invest,תשתיות, גידור) | C26: 0.07 | D26: 0.05 | E26: 0.05 | F26: =IF(C26-E26>0,C26-E26,0) -> 0.02 | G26: =C26+E26 -> 0.12
B27: מזומנים (*) | C27: 0.02 | D27: 0.03
B28: סה"כ | C28: =SUM(C22:C27) -> 1 | D28: 1
B29: חשיפה למט"ח | C29: 0.21 | D29: 0.24 | E29: 0.06 | F29: =IF(C29-E29>0,C29-E29,0) -> 0.15 | G29: =C29+E29 -> 0.27
B30: מגבלת עמלת ניהול חיצוני לשנת 2024 | D30: 0.0028
B31: סוף מידע טבלה
B32: תחילת מידע טבלה
A33: תחילת מידע טבלה צד ימין | B33: הפניקס ביטוח מסלול תלוי גיל לגילאי 60+ | I33: סוף מידע טבלה צד שמאל
B34: מספר מסלול באוצר 9594 | D34: מספר מסלול באוצר 9593
B35: אפיק השקעה | C35: שיעור חשיפה צפוי לשנת 2024 (החל מיום 1.7.24) | D35: שיעור חשיפה ליום 30.6.24 | E35: טווח סטייה %-/+ | F35: גבולות שיעור החשיפה הצפויה | H35: מדד הייחוס (**)
B36: מניות | C36: 0.24 | D36: 0.24 | E36: 0.06 | F36: =IF(C36-E36>0,C36-E36,0) -> 0.18 | G36: =C36+E36 -> 0.3 | H36: 40%- מדד ת"א 125, 60%- MSCI WORLD AC
B37: אג"ח ממשלתי (צמוד,שקלי ומט"ח), ממשלות זרות בנטרול חשיפות בנגזרים (*) | C37: 0.28 | D37: 0.29 | E37: 0.05 | F37: =IF(C37-E37>0,C37-E37,0) -> 0.23 | G37: =C37+E37 -> 0.33 | H37: מדד אג"ח ממשלתי כללי
B38: אג"ח קונצרני (קרנות נאמנות, תעודות סל) | C38: 0.35 | D38: 0.35 | E38: 0.06 | F38: =IF(C38-E38>0,C38-E38,0) -> 0.29 | G38: =C38+E38 -> 0.41 | H38: 35% - תל בונד כללי , 20% - תל בונד 60 , 15% - תל בונד 50 , 15% - IBOXX HY - 15%, IBOXX IG
B39: קרנות השקעה | C39: 0.04 | D39: 0.04 | E39: 0.05 | F39: =IF(C39-E39>0,C39-E39,0) -> 0 | G39: =C39+E39 -> 0.09
B40: אחר (Co Invest,תשתיות, גידור) | C40: 0.06 | D40: 0.05 | E40: 0.05 | F40: =IF(C40-E40>0,C40-E40,0) -> 0.01 | G40: =C40+E40 -> 0.11
B41: מזומנים (*) | C41: 0.03 | D41: 0.03
...

Sheet ביטוח - אשכול 1 אקטיבי
B1: ='קרן י'!B1 -> מדיניות השקעה לשנת 2024
B3: תחילת מידע טבלה
A4: תחילת מידע טבלה צד ימין | B4: הפניקס ביטוח מסלול כספי (שקלי) - לשעבר הפניקס ביטוח מסלול שקלי טווח קצר | I4: סוף מידע טבלה צד שמאל
B6: מספר מסלול באוצר 9592
B7: אפיק השקעה | C7: שיעור חשיפה צפוי לשנת 2024 (החל מיום 1.7.24) | D7: שיעור חשיפה ליום 30.6.24 | E7: טווח סטיה | F7: גבולות שיעור החשיפה הצפויה | H7: מדד ייחוס
B8: אג"ח ממשלתי (צמוד, שקלי ומט"ח), ממשלות זרות בנטרול חשיפות בנגזרים | C8: 0.75 | D8: 0.75 | E8: 0.05 | F8: =+C8-E8 -> 0.7 | G8: =+C8+E8 -> 0.8 | H8: מדד אג"ח ממשלתי כללי
B9: אג"ח קונצרני (כולל קרנות נאמנות, תעודות סל) | C9: 0.23 | D9: 0.2 | E9: 0.06 | F9: =+C9-E9 -> 0.17 | G9: =+C9+E9 -> 0.29 | H9: 35% - תל בונד כללי , 20% - תל בונד 60 , 15% - תל בונד 50 , 15% - IBOXX HY - 15%, IBOXX IG
B10: מזומנים (*) | C10: 0.02 | D10: 0.05
B11: סה"כ | C11: =SUM(C8:C10) -> 1 | D11: =SUM(D8:D10) -> 1
B12: חשיפה למט"ח | C12: 0 | D12: 0 | E12: 0.06 | F12: 0 | G12: =+C12+E12 -> 0.06
B13: מגבלת עמלת ניהול חיצוני לשנת 2024 | C13: 0.0005
B14: סוף מידע טבלה
B16: תחילת מידע טבלה
A17: תחילת מידע טבלה צד ימין | B17: הפניקס ביטוח מסלול אשראי ואג"ח - לשעבר הפניקס מסלול אג"ח 1 (עד 60%) | I17: סוף מידע טבלה צד שמאל
B18: מספר מסלול באוצר 47
B19: אפיק השקעה | C19: שיעור חשיפה צפוי לשנת 2024 (החל מיום 1.7.24) | D19: שיעור חשיפה ליום 30.6.24 | E19: טווח סטיה | F19: גבולות שיעור החשיפה הצפויה | H19: מדד ייחוס
B20: מניות (כולל תעודות סל, אופציות, קרנות נאמנות) | C20: 0.01 | D20: 0.01 | E20: 0.06 | F20: 0 | G20: =+C20+E20 -> 0.07 | H20: 40%- מדד ת"א 125 , 60%- MSCI WORLD AC
B21: אג"ח ממשלתי (צמוד, שקלי ומט"ח), ממשלות זרות בנטרול חשיפות בנגזרים | C21: 0.35 | D21: 0.35 | E21: 0.05 | F21: =+C21-E21 -> 0.3 | G21: =+C21+E21 -> 0.4 | H21: מדד אג"ח ממשלתי כללי
B22: אג"ח קונצרני (כולל קרנות נאמנות, תעודות סל) | C22: 0.55 | D22: 0.55 | E22: 0.06 | F22: =+C22-E22 -> 0.49 | G22: =+C22+E22 -> 0.61 | H22: 35% - תל בונד כללי , 20% - תל בונד 60 , 15% - תל בונד 50 , 15% - IBOXX HY - 15%, IBOXX IG
B23: אחר ( Co Invest, נדל"ן, קרנות השקעהתשתיות, גידור) | C23: 0.04 | D23: 0.03 | E23: 0.05 | F23: 0 | G23: =+C23+E23 -> 0.09
B24: מזומנים (*) | C24: 0.05 | D24: 0.06 | F24: =+C24-E24 -> 0.05 | G24: =+C24+E24 -> 0.05
B25: סה"כ | C25: =SUM(C20:C24) -> 1 | D25: =SUM(D20:D24) -> 1
B26: חשיפה למט"ח | C26: 0.13 | D26: 0.13 | E26: 0.06 | F26: =IF(C26-E26>0,C26-E26,0) -> 0.07 | G26: =C26+E26 -> 0.19
B27: מגבלת עמלת ניהול חיצוני לשנת 2024 | C27: 0.0005
B28: סוף מידע טבלה
B29: הפניקס ביטוח מסלול אג"ח עד 25%
B31: אפיק השקעה | C31: שיעור חשיפה צפוי לשנת 2024 | D31: טווח סטיה | E31: גבולות שיעור החשיפה הצםויה | G31: מדד ייחוס
B32: מניות (כולל תעודות סל, אופציות, קרנות נאמנות) | C32: 0.17 | D32: 0.06 | E32: =+C32-D32 -> 0.11 | F32: =+C32+D32 -> 0.23 | G32: 40%- מדד ת"א 125 , 60%- MSCI WORLD AC
B33: אג"ח ממשלתי (צמוד, שקלי ומט"ח), ממשלות זרות בנטרול חשיפות בנגזרים | C33: 0.17 | D33: 0.05 | E33: =+C33-D33 -> 0.12 | F33: =+C33+D33 -> 0.22 | G33: מדד אג"ח ממשלתי כללי
B34: אג"ח קונצרני (כולל קרנות נאמנות, תעודות סל) | C34: 0.56 | D34: 0.06 | E34: =+C34-D34 -> 0.5 | F34: =+C34+D34 -> 0.62 | G34: 35% - תל בונד כללי , 20% - תל בונד 60 , 15% - תל בונד 50 , 15% - IBOXX HY - 15%, IBOXX IG
B35: אחר ( Co Invest, נדל"ן, קרנות השקעהתשתיות, גידור) | C35: 0.06 | D35: 0.05 | E35: 0 | F35: =+C35+D35 -> 0.11
B36: מזומנים (*) | C36: 0.04 | E36: =+C36-D36 -> 0.04 | F36: =+C36+D36 -> 0.04
B37: סה"כ | C37: =SUM(C32:C36) -> 1
B38: חשיפה למט"ח | C38: 0.16 | D38: 0.05 | E38: =IF(C38-D38>0,C38-D38,0) -> 0.11 | F38: =C38+D38 -> 0.21
B39: מגבלת עמלת ניהול חיצוני לשנת 2024 | C39: 0.0025
B42: תחילת מידע טבלה
A43: תחילת מידע טבלה צד ימין | B43: הפניקס ביטוח מסלול מניות - לשעבר הפניקס ביטוח מסלול מניות | I43: סוף מידע טבלה צד שמאל
B44: מספר מסלול באוצר 9579
B45: אפיק השקעה | C45: שיעור חשיפה צפוי לשנת 2024 (החל מיום 1.7.24) | D45: שיעור חשיפה ליום 30.6.24 | E45: טווח סטיה | F45: גבולות שיעור החשיפה הצפויה | H45: מדד ייחוס
B46: מניות (כולל תעודות סל, אופציות, קרנות נאמנות) | C46: 0.94 | D46: 0.94 | E46: 0.06 | F46: =+C46-E46 -> 0.88 | G46: =+C46+E46 -> 1 | H46: 40%- מדד ת"א 125 , 60%- MSCI WORLD AC
...

Sheet אשכול 3 - סחיר (ביטוח)
B1: ='קרן י'!B1 -> מדיניות השקעה לשנת 2024
B3: תחילת מידע טבלה
A4: תחילת מידע טבלה צד ימין | B4: הפניקס ביטוח מסלול משולב סחיר | I4: סוף מידע טבלה צד שמאל
B5: מספר מסלול באוצר 14290
B6: אפיק השקעה | C6: שיעור חשיפה צפוי לשנת 2024 (החל מיום 1.7.24) | D6: שיעור חשיפה ליום 30.6.24 | E6: טווח סטייה %-/+ | F6: גבולות שיעור החשיפה הצפויה | H6: מדד הייחוס (**)
B7: מניות (כולל תעודות סל, אופציות, קרנות נאמנות) | C7: 0.52 | D7: 0.52 | E7: 0.06 | F7: =+C7-E7 -> 0.46 | G7: =+C7+E7 -> 0.58 | H7: 40%- מדד ת"א 125, 60%- MSCI WORLD AC
B8: אג"ח ממשלתי (צמוד, שקלי ומט"ח), ממשלות זרות בנטרול חשיפות בנגזרים(*) | C8: 0.08 | D8: 0.08 | E8: 0.05 | F8: =+C8-E8 -> 0.03 | G8: =+C8+E8 -> 0.13 | H8: מדד אג"ח ממשלתי כללי
B9: אג"ח קונצרני (קרנות נאמנות, תעודות סל) | C9: 0.38 | D9: 0.38 | E9: 0.06 | F9: =+C9-E9 -> 0.32 | G9: =+C9+E9 -> 0.44 | H9: 35% - תל בונד כללי , 20% - תל בונד 60 , 15% - תל בונד 50 , 15% - IBOXX HY - 15%, IBOXX IG
B10: מזומנים (*) | C10: 0.02 | D10: 0.02
B11: סה"כ | C11: =SUM(C7:C10) -> 1 | D11: =SUM(D7:D10) -> 1
B12: חשיפה למט"ח | C12: 0.2 | D12: 0.19 | E12: 0.06 | F12: =+C12-E12 -> 0.14 | G12: =+C12+E12 -> 0.26
B13: מגבלת עמלת ניהול חיצוני לשנת 2024 | C13: 0.0005
B14: סוף מידע טבלה
B15: * מוצג בנטרול תוספת החשיפה הנובעת מהשקעה בנגזרים
B16: ** מובהר כי תיק הנכסים אינו תואם בהכרח במלואו להרכב מדד הייחוס. אין בציון מדד הייחוס בכדי להוות מצג, הצהרה או התחייבות כלשהי לגבי התשואה שתושג בפועל בתיק
B17: אג"ח סחיר - מסלול חדש | I17: מסלול חדש - נבחן כמסלול BGA
B18: אפיק השקעה | C18: שיעור חשיפה מבוקש לאחר רפורמה | D18: שיעור חשיפה צפוי לשנת 2024 | E18: טווח סטייה %-/+ | F18: גבולות שיעור החשיפה הצפויה | H18: מדד הייחוס (**)
B19: מניות (כולל תעודות סל, אופציות, קרנות נאמנות) | E19: 0.06 | F19: =+D19-E19 -> -0.06 | G19: =+D19+E19 -> 0.06 | H19: 40%- מדד ת"א 125, 60%- MSCI WORLD AC
B20: אג"ח ממשלתי (צמוד, שקלי ומט"ח), ממשלות זרות בנטרול חשיפות בנגזרים(*) | E20: 0.05 | F20: =+D20-E20 -> -0.05 | G20: =+D20+E20 -> 0.05 | H20: מדד אג"ח ממשלתי כללי
B21: אג"ח קונצרני (קרנות נאמנות, תעודות סל) | E21: 0.06 | F21: =+D21-E21 -> -0.06 | G21: =+D21+E21 -> 0.06 | H21: 35% - תל בונד כללי , 20% - תל בונד 60 , 15% - תל בונד 50 , 15% - IBOXX HY - 15%, IBOXX IG
B22: מזומנים (*)
B23: סה"כ | C23: =SUM(C19:C22) -> 0 | D23: =SUM(D19:D22) -> 0
B24: חשיפה למט"ח | E24: 0.06 | F24: =+D24-E24 -> -0.06 | G24: =+D24+E24 -> 0.06
B25: מגבלת עמלת ניהול חיצוני לשנת 2024 | D25: 0.0005
B30: מניות סחיר - מסלול חדש | I30: מסלול חדש - נבחן כמסלול BGA
B31: אפיק השקעה | C31: שיעור חשיפה מבוקש לאחר רפורמה | D31: שיעור חשיפה צפוי לשנת 2024 | E31: טווח סטייה %-/+ | F31: גבולות שיעור החשיפה הצפויה | H31: מדד הייחוס (**)
B32: מניות (כולל תעודות סל, אופציות, קרנות נאמנות) | E32: 0.06 | F32: =+D32-E32 -> -0.06 | G32: =+D32+E32 -> 0.06 | H32: 40%- מדד ת"א 125, 60%- MSCI WORLD AC
B33: אג"ח ממשלתי (צמוד, שקלי ומט"ח), ממשלות זרות בנטרול חשיפות בנגזרים(*) | E33: 0.05 | F33: =+D33-E33 -> -0.05 | G33: =+D33+E33 -> 0.05 | H33: מדד אג"ח ממשלתי כללי
B34: אג"ח קונצרני (קרנות נאמנות, תעודות סל) | E34: 0.06 | F34: =+D34-E34 -> -0.06 | G34: =+D34+E34 -> 0.06 | H34: 35% - תל בונד כללי , 20% - תל בונד 60 , 15% - תל בונד 50 , 15% - IBOXX HY - 15%, IBOXX IG
B35: מזומנים (*)
B36: סה"כ | C36: =SUM(C32:C35) -> 0 | D36: =SUM(D32:D35) -> 0
B37: חשיפה למט"ח | E37: 0.06 | F37: =+D37-E37 -> -0.06 | G37: =+D37+E37 -> 0.06
B38: מגבלת עמלת ניהול חיצוני לשנת 2024 | D38: 0.0005
A39: סוף מידע גיליון

Sheet אשכול 4 - עוקב מדדים
B1: ='קרן י'!B1 -> מדיניות השקעה לשנת 2024
B3: תחילת מידע טבלה
A4: תחילת מידע טבלה צד ימין | B4: הפניקס ביטוח מסלול עוקב מדדים גמיש | I4: סוף מידע טבלה צד שמאל
B5: מספר מסלול באוצר 14291
B6: אפיק השקעה | C6: שיעור חשיפה צפוי לשנת 2024 (החל מיום 1.7.24) | D6: שיעור חשיפה ליום 30.6.24 | E6: טווח סטיה | F6: גבולות שיעור החשיפה הצפויה | H6: מדד ייחוס
B7: מניות (כולל תעודות סל, אופציות, קרנות נאמנות) | C7: 0.5 | D7: 0.5 | E7: 0.06 | F7: =+C7-E7 -> 0.44 | G7: =+C7+E7 -> 0.56 | H7: MSCI WORLD AC
B8: אג"ח ממשלתי (צמוד, שקלי ומט"ח), ממשלות זרות בנטרול חשיפות בנגזרים | C8: 0.09 | D8: 0.08 | E8: 0.05 | F8: =+C8-E8 -> 0.04 | G8: =+C8+E8 -> 0.14 | H8: ISHARES 7-10 YEARS TREASURY
B9: אג"ח קונצרני (כולל קרנות נאמנות, תעודות סל) | C9: 0.37 | D9: 0.39 | E9: 0.06 | F9: =+C9-E9 -> 0.31 | G9: =+C9+E9 -> 0.43 | H9: IBOXY HY 46, IBXXC1D1 12% , JGENUUG 8%, JCMBCOMP 8%, IBOXIG 26%
B10: מזומנים (*) | C10: 0.04 | D10: 0.03
B11: סה"כ | C11: =SUM(C7:C10) -> 1 | D11: =SUM(D7:D10) -> 1
B12: חשיפה למט"ח | C12: 0.95 | D12: 0.24 | E12: 0.06 | F12: =IF(C12-E12>0,C12-E12,0) -> 0.89 | G12: =C12+E12 -> 1.01
B13: מגבלת עמלת ניהול חיצוני לשנת 2024 | C13: 0.001
B14: סוף מידע טבלה
B15: תחילת מידע טבלה
A16: תחילת מידע טבלה צד ימין | B16: הפניקס ביטוח מסלול עוקב מדד s&p 500 - לשעבר ביטוח מחקה מדד s&p | I16: סוף מידע טבלה צד שמאל
B17: מספר מסלול באוצר 9554
B18: אפיק השקעה | C18: שיעור חשיפה צפוי לשנת 2024 (החל מיום 1.7.24) | D18: שיעור חשיפה ליום 30.6.24 | E18: טווח סטיה | F18: גבולות שיעור החשיפה הצפויה | H18: מדד ייחוס
B19: מניות (כולל תעודות סל, אופציות, קרנות נאמנות) | C19: 0.94 | D19: 0.94 | E19: 0.06 | F19: =+C19-E19 -> 0.88 | G19: =+C19+E19 -> 1 | H19: s&p 500
B20: מזומנים (*) | C20: 0.06 | D20: 0.06 | F20: =+C20-E20 -> 0.06 | G20: =+C20+E20 -> 0.06
B21: סה"כ | C21: =SUM(C19:C20) -> 1 | D21: =SUM(D19:D20) -> 1
B22: חשיפה למט"ח | C22: 0.94 | D22: 0.96 | E22: 0.06 | F22: =IF(C22-E22>0,C22-E22,0) -> 0.88 | G22: =C22+E22 -> 1
B23: מגבלת עמלת ניהול חיצוני לשנת 2024 | C23: 0.0005
B24: סוף מידע טבלה
B25: עוקב מדדי אג"ח לשעבר -- מסלול פאסיבי - מדדי אג"ח חו"ל | J25: מספר מסלול באוצר 9556
B26: מספר מסלול באוצר 9556 | J26: שינוי שם
B27: אפיק השקעה | C27: חשיפה 20.02.2024 | D27: שיעור חשיפה מבוקש לאחר רפורמה | E27: שיעור חשיפה צפוי לשנת 2024 | F27: טווח סטיה | G27: גבולות שיעור החשיפה הצפויה | I27: מדד ייחוס | J27: לא נדרשת מדיניות חדשה
B28: מניות (כולל תעודות סל, אופציות, קרנות נאמנות) | C28: 0 | D28: 0 | E28: 0 | F28: 0.05 | G28: 0 | H28: =+E28+F28 -> 0.05
B29: אג"ח ממשלתי (צמוד, שקלי ומט"ח), ממשלות זרות בנטרול חשיפות בנגזרים | C29: 0.0723 | D29: 0.08 | E29: 0.08 | F29: 0.05 | G29: 0 | H29: =+E29+F29 -> 0.13
B30: אג"ח קונצרני (כולל קרנות נאמנות, תעודות סל) | C30: 0.8932 | D30: 0.89 | E30: 0.89 | F30: 0.05 | G30: 0 | H30: =+E30+F30 -> 0.94
B31: מזומנים (*) | C31: 0.0346 | D31: 0.03 | E31: 0.03 | F31: 0.05 | G31: 0 | H31: =+E31+F31 -> 0.08
B32: סה"כ | C32: =SUM(C28:C31) -> 1.0001 | D32: =SUM(D28:D31) -> 1 | E32: =SUM(E28:E31) -> 1 | F32: 0.05 | G32: 0 | H32: =+E32+F32 -> 1.05
B33: חשיפה למט"ח | C33: 0.9594 | D33: 0.94 | E33: 0.96 | F33: 0.05 | G33: =IF(E33-F33>0,E33-F33,0) -> 0.91 | H33: =E33+F33 -> 1.01
B34: מגבלת עמלת ניהול חיצוני לשנת 2024 | E34: 0.002
B37: תחילת מידע טבלה
A38: תחילת מידע טבלה צד ימין | B38: הפניקס ביטוח עוקב מדדי מניות - מסלול חדש החל מ - 01.07.2024 | H38: סוף מידע טבלה צד שמאל
B39: מספר מסלול באוצר 15207
B40: אפיק השקעה | C40: שיעור חשיפה צפוי לשנת 2024 (החל מיום 1.7.24) | D40: טווח סטיה | E40: גבולות שיעור החשיפה הצפויה | G40: מדד ייחוס
B41: מניות (כולל תעודות סל, אופציות, קרנות נאמנות) | C41: 0.94 | D41: 0.06 | E41: =+C41-D41 -> 0.88 | F41: =+C41+D41 -> 1 | G41: 50% Xndx 40% SP5T5T 10% - SPTRMDCP
B42: מזומנים (*) | C42: 0.06 | E42: =+C42-D42 -> 0.06 | F42: =+C42+D42 -> 0.06
B43: סה"כ | C43: =SUM(C41:C42) -> 1
...

Sheet אשכול 5 - אמונה (הלכה)
B1: ='קרן י'!B1 -> מדיניות השקעה לשנת 2024
B2: תחילת מידע טבלה
A3: תחילת מידע טבלה צד ימין | B3: הפניקס ביטוח מסלול הלכה | I3: סוף מידע אבלה צד שמאל
B4: מספר מסלול באוצר 9586
B5: אפיק השקעה | C5: שיעור חשיפה צפוי לשנת 2024 (החל מיום 1.7.24) | D5: שיעור חשיפה ליום 30.6.24 | E5: טווח סטייה %-/+ | F5: גבולות שיעור החשיפה הצפויה | H5: מדד הייחוס (**)
B6: מניות | C6: 0.46 | D6: 0.46 | E6: 0.06 | F6: =IF(C6-E6>0,C6-E6,0) -> 0.4 | G6: =C6+E6 -> 0.52 | H6: 40%- מדד ת"א 125, 60%- MSCI WORLD AC
B7: אג"ח ממשלתי (צמוד,שקלי ומט"ח), ממשלות זרות בנטרול חשיפות בנגזרים (*) | C7: 0.19 | D7: 0.19 | E7: 0.05 | F7: =IF(C7-E7>0,C7-E7,0) -> 0.14 | G7: =C7+E7 -> 0.24 | H7: מדד אג"ח ממשלתי כללי
B8: אג"ח קונצרני (קרנות נאמנות, תעודות סל) | C8: 0.31 | D8: 0.31 | E8: 0.06 | F8: =IF(C8-E8>0,C8-E8,0) -> 0.25 | G8: =C8+E8 -> 0.37 | H8: 70% - מדד תל בונד 60 , 30% - מדד BarCap Global Corporate Total Return Bond Index UnHedged
B9: מזומנים (*) | C9: 0.04 | D9: 0.04
B10: סה"כ | C10: =SUM(C6:C9) -> 1 | D10: 1
B11: חשיפה למט"ח | C11: 0.21 | D11: 0.21 | E11: 0.06 | F11: =IF(C11-E11>0,C11-E11,0) -> 0.15 | G11: =C11+E11 -> 0.27
B12: מגבלת עמלת ניהול חיצוני לשנת 2024 | D12: 0.001
B13: סוף מידע טבלה
B14: * מוצג בנטרול תוספת החשיפה הנובעת מהשקעה בנגזרים
B15: ** מובהר כי תיק הנכסים אינו תואם בהכרח במלואו להרכב מדד הייחוס. אין בציון מדד הייחוס בכדי להוות מצג, הצהרה או התחייבות כלשהי לגבי התשואה שתושג בפועל בתיק
A16: סוף מידע גיליון

Sheet מסלולי השקעה למקבלי קצבה
B1: ='קרן י'!B1 -> מדיניות השקעה לשנת 2024
B2: תחילת מידע טבלה
A3: תחילת מידע טבלה צד ימין | B3: הפניקס מסלול השקעה בסיסי למקבלי קצבה - מסלול בסיסי למקבלי קצבאות (גמלה) | I3: סוף מידע טבלה צד שמאל
B4: מספר מסלול באוצר 9587
B5: אפיק השקעה | C5: שיעור חשיפה צפוי לשנת 2024 (החל מיום 1.7.24) | D5: שיעור חשיפה ליום 30.6.24 | E5: טווח סטייה %-/+ | F5: גבולות שיעור החשיפה הצפויה | H5: מדד הייחוס (**)
B6: מניות | C6: 0.17 | D6: 0.17 | E6: 0.06 | F6: =IF(C6-E6>0,D6-E6,0) -> 0.11 | G6: =C6+E6 -> 0.23 | H6: 40%- מדד ת"א 125, 60%- MSCI WORLD AC
B7: אג"ח ממשלתי (צמוד,שקלי ומט"ח), ממשלות זרות בנטרול חשיפות בנגזרים (*) | C7: 0.4 | D7: 0.4 | E7: 0.05 | F7: =IF(C7-E7>0,D7-E7,0) -> 0.35 | G7: =C7+E7 -> 0.45 | H7: מדד אג"ח ממשלתי כללי
B8: אג"ח קונצרני (קרנות נאמנות, תעודות סל) | C8: 0.3 | D8: 0.3 | E8: 0.06 | F8: =IF(C8-E8>0,D8-E8,0) -> 0.24 | G8: =C8+E8 -> 0.36 | H8: 35% - תל בונד כללי , 20% - תל בונד 60 , 15% - תל בונד 50 , 15% - IBOXX HY - 15%, IBOXX IG
B9: קרנות השקעה | C9: 0.04 | D9: 0.04 | E9: 0.05 | F9: =IF(C9-E9>0,D9-E9,0) -> 0 | G9: =C9+E9 -> 0.09
B10: תשתיות | C10: 0.03 | F10: =IF(C10-E10>0,D10-E10,0) -> 0 | G10: =C10+E10 -> 0.03
B11: אחר (Co Invest, גידור) | C11: 0.04 | D11: 0.05 | E11: 0.05 | F11: =IF(C11-E11>0,D11-E11,0) -> 0 | G11: =C11+E11 -> 0.09
B12: מזומנים (*) | C12: 0.02 | D12: 0.04
B13: סה"כ | C13: =SUM(C6:C12) -> 1 | D13: 1
B14: חשיפה למט"ח | C14: 0.14 | D14: 0.14 | E14: 0.06 | F14: =IF(C14-E14>0,C14-E14,0) -> 0.08 | G14: =C14+E14 -> 0.2
B15: מגבלת עמלת ניהול חיצוני לשנת 2024 | D15: 0.0028
B16: סוף מידע טבלה
B17: תחילת מידע טבלה
A18: תחילת מידע טבלה צד ימין | B18: הפניקס מסלול הלכה למקבלי קצבה ביטוח | I18: סוף מידע טבלה צד שמאל
B19: מסםר מסלול באוצר 9591
B20: אפיק השקעה | C20: שיעור חשיפה צפוי לשנת 2024 (החל מיום 1.7.24) | D20: שיעור חשיפה ליום 30.6.24 | E20: טווח סטייה %-/+ | F20: גבולות שיעור החשיפה הצפויה | H20: מדד הייחוס (**)
B21: מניות | C21: 0.24 | D21: 0.24 | E21: 0.06 | F21: =IF(C21-E21>0,C21-E21,0) -> 0.18 | G21: =C21+E21 -> 0.3 | H21: 40%- מדד ת"א 125, 60%- MSCI WORLD AC
B22: אג"ח ממשלתי (צמוד,שקלי ומט"ח), ממשלות זרות בנטרול חשיפות בנגזרים (*) | C22: 0.4 | D22: 0.41 | E22: 0.05 | F22: =IF(C22-E22>0,C22-E22,0) -> 0.35 | G22: =C22+E22 -> 0.45 | H22: מדד אג"ח ממשלתי כללי
B23: אג"ח קונצרני (קרנות נאמנות, תעודות סל) | C23: 0.32 | D23: 0.31 | E23: 0.06 | F23: =IF(C23-E23>0,C23-E23,0) -> 0.26 | G23: =C23+E23 -> 0.38 | H23: 70% - מדד תל בונד 60 , 30% - מדד BarCap Global Corporate Total Return Bond Index UnHedged
B24: מזומנים (*) | C24: 0.04 | D24: 0.04
B25: סה"כ | C25: =SUM(C21:C24) -> 1 | D25: 1
B26: חשיפה למט"ח | C26: 0.12 | D26: 0.12 | E26: 0.06 | F26: =IF(C26-E26>0,C26-E26,0) -> 0.06 | G26: =C26+E26 -> 0.18
B27: מגבלת עמלת ניהול חיצוני לשנת 2024 | D27: 0.001
B28: סוף מידע טבלה
B30: * מוצג בנטרול תוספת החשיפה הנובעת מהשקעה בנגזרים
B31: ** מובהר כי תיק הנכסים אינו תואם בהכרח במלואו להרכב מדד הייחוס. אין בציון מדד הייחוס בכדי להוות מצג, הצהרה או התחייבות כלשהי לגבי התשואה שתושג בפועל בתיק
A32: סוף מידע גיליון

Sheet מסלולים מתמחים למקבלי קצבה
C3: הפניקס ביטוח מסלול מקבלי קצבה מתמחה אג"ח | I3: מספר מסלול באוצר 9588
C5: אפיק השקעה | D5: שיעור חשיפה צפוי לשנת 2024 | E5: טווח סטיה | F5: גבולות שיעור החשיפה הצםויה | H5: מדד ייחוס | I5: בהתאם לדרישות החוזר, לא ניתן לנהל מסלולים מתמחים למקבלי קצבה ועל כן מסלולים אלו (3 מסלולים) ימוזגו למסלול הבסיסי:
C6: מניות (כולל תעודות סל, אופציות, קרנות נאמנות) | D6: 0.01 | E6: 0.06 | F6: 0 | G6: =+D6+E6 -> 0.07 | H6: 40%- מדד ת"א 125 , 60%- MSCI WORLD AC | I6: מתמחה מניות למקבלי קצבה
C7: אג"ח ממשלתי (צמוד, שקלי ומט"ח), ממשלות זרות בנטרול חשיפות בנגזרים | D7: 0.37 | E7: 0.05 | F7: =+D7-E7 -> 0.32 | G7: =+D7+E7 -> 0.42 | H7: מדד אג"ח ממשלתי כללי | I7: מתמחה משולב למקבלי קצבה עד 25% מניות
C8: אג"ח קונצרני (כולל קרנות נאמנות, תעודות סל) | D8: 0.57 | E8: 0.06 | F8: =+D8-E8 -> 0.51 | G8: =+D8+E8 -> 0.63 | H8: 35% - תל בונד כללי , 20% - תל בונד 60 , 15% - תל בונד 50 , 15% - IBOXX HY - 15%, IBOXX IG | I8: מתמחה אג"ח למקבלי קצבה
C9: אחר ( Co Invest, נדל"ן, קרנות השקעהתשתיות, גידור) | D9: 0.01 | E9: 0.05 | F9: 0 | G9: =+D9+E9 -> 0.06
C10: מזומנים (*) | D10: 0.04 | F10: =+D10-E10 -> 0.04 | G10: =+D10+E10 -> 0.04 | I10: לא נדרשת מדיניות חדשה
C11: סה"כ | D11: =SUM(D6:D10) -> 1
C12: חשיפה למט"ח | D12: 0.14 | E12: 0.05 | F12: =IF(D12-E12>0,D12-E12,0) -> 0.09 | G12: =D12+E12 -> 0.19
C13: מגבלת עמלת ניהול חיצוני לשנת 2024 | D13: 0.0005
C15: הפניקס ביטוח מסלול מקבלי קצבה עד 25% מניות | I15: מספר מסלול באוצר 9589
C17: אפיק השקעה | D17: שיעור חשיפה צפוי לשנת 2024 | E17: טווח סטיה | F17: גבולות שיעור החשיפה הצםויה | H17: מדד ייחוס
C18: מניות (כולל תעודות סל, אופציות, קרנות נאמנות) | D18: 0.18 | E18: 0.06 | F18: =+D18-E18 -> 0.12 | G18: =+D18+E18 -> 0.24 | H18: 40%- מדד ת"א 125 , 60%- MSCI WORLD AC
C19: אג"ח ממשלתי (צמוד, שקלי ומט"ח), ממשלות זרות בנטרול חשיפות בנגזרים | D19: 0.16 | E19: 0.05 | F19: =+D19-E19 -> 0.11 | G19: =+D19+E19 -> 0.21 | H19: מדד אג"ח ממשלתי כללי
C20: אג"ח קונצרני (כולל קרנות נאמנות, תעודות סל) | D20: 0.57 | E20: 0.06 | F20: =+D20-E20 -> 0.51 | G20: =+D20+E20 -> 0.63 | H20: 35% - תל בונד כללי , 20% - תל בונד 60 , 15% - תל בונד 50 , 15% - IBOXX HY - 15%, IBOXX IG
C21: אחר ( Co Invest, נדל"ן, קרנות השקעהתשתיות, גידור) | D21: 0.05 | E21: 0.05 | F21: 0 | G21: =+D21+E21 -> 0.1
C22: מזומנים (*) | D22: 0.04 | F22: =+D22-E22 -> 0.04 | G22: =+D22+E22 -> 0.04
C23: סה"כ | D23: =SUM(D18:D22) -> 1
C24: חשיפה למט"ח | D24: 0.18 | E24: 0.05 | F24: =IF(D24-E24>0,D24-E24,0) -> 0.13 | G24: =D24+E24 -> 0.23
C25: מגבלת עמלת ניהול חיצוני לשנת 2024 | D25: 0.001
C27: הפניקס ביטוח מסלול מקבלי קצבה מניות | I27: מספר מסלול באוצר 9590
C29: אפיק השקעה | D29: שיעור חשיפה צפוי לשנת 2024 | E29: טווח סטיה | F29: גבולות שיעור החשיפה הצםויה | H29: מדד ייחוס
C30: מניות (כולל תעודות סל, אופציות, קרנות נאמנות) | D30: 0.94 | E30: 0.06 | F30: =+D30-E30 -> 0.88 | G30: =+D30+E30 -> 1 | H30: 40%- מדד ת"א 125 , 60%- MSCI WORLD AC
C31: אג"ח ממשלתי (צמוד, שקלי ומט"ח), ממשלות זרות בנטרול חשיפות בנגזרים | D31: 0.03 | E31: 0.05 | F31: =+D31-E31 -> -0.02 | G31: =+D31+E31 -> 0.08 | H31: מדד אג"ח ממשלתי כללי
C32: אג"ח קונצרני (כולל קרנות נאמנות, תעודות סל) | D32: 0 | E32: 0.06 | F32: =+D32-E32 -> -0.06 | G32: =+D32+E32 -> 0.06 | H32: 35% - תל בונד כללי , 20% - תל בונד 60 , 15% - תל בונד 50 , 15% - IBOXX HY - 15%, IBOXX IG
C33: אחר ( Co Invest, נדל"ן, קרנות השקעהתשתיות, גידור) | D33: 0 | E33: 0.05 | F33: 0 | G33: =+D33+E33 -> 0.05
C34: מזומנים (*) | D34: 0.03 | F34: =+D34-E34 -> 0.03 | G34: =+D34+E34 -> 0.03
C35: סה"כ | D35: =SUM(D30:D34) -> 1
C36: חשיפה למט"ח | D36: 0.28 | E36: 0.05 | F36: =IF(D36-E36>0,D36-E36,0) -> 0.23 | G36: =D36+E36 -> 0.33
C37: מגבלת עמלת ניהול חיצוני לשנת 2024 | D37: 0.001

Sheet הלכה למקבלי קצבה
B1: ='קרן י'!B1 -> מדיניות השקעה לשנת 2024
B2: הלכה - לשעבר מסלול הלכה למקבלי קצבה ביטוח | J2: מספר מסלול באוצר 9591
B3: אפיק השקעה | C3: חשיפה 20.02.2024 | D3: שיעור חשיפה מבוקש לאחר רפורמה | E3: ='קרן י'!C4 -> שיעור חשיפה צפוי לשנת 2024 | F3: טווח סטייה %-/+ | G3: גבולות שיעור החשיפה הצפויה | I3: מדד הייחוס (**) | J3: ללא שינוי
B4: מניות | C4: 0.2297 | D4: 0.24 | E4: 0.24 | F4: 0.06 | G4: =IF(E4-F4>0,E4-F4,0) -> 0.18 | H4: =E4+F4 -> 0.3 | I4: 40%- מדד ת"א 125, 60%- MSCI WORLD AC | J4: צורף לגיליון גמלה
B5: אג"ח ממשלתי (צמוד,שקלי ומט"ח), ממשלות זרות בנטרול חשיפות בנגזרים (*) | C5: 0.3825 | D5: 0.38 | E5: 0.41 | F5: 0.05 | G5: =IF(E5-F5>0,E5-F5,0) -> 0.36 | H5: =E5+F5 -> 0.46 | I5: מדד אג"ח ממשלתי כללי
B6: אג"ח קונצרני (קרנות נאמנות, תעודות סל) | C6: 0.3443 | D6: 0.34 | E6: 0.31 | F6: 0.06 | G6: =IF(E6-F6>0,E6-F6,0) -> 0.25 | H6: =E6+F6 -> 0.37 | I6: 70% - מדד תל בונד 60 , 30% - מדד BarCap Global Corporate Total Return Bond Index UnHedged
B7: נדל"ן | C7: 0 | D7: 0 | E7: 0 | F7: 0.05 | G7: =IF(E7-F7>0,E7-F7,0) -> 0 | H7: =E7+F7 -> 0.05
B8: אחר (קרנות השקיעה,Co Invest,תשתיות, גידור) | C8: 0 | D8: 0 | E8: 0 | F8: 0.05 | G8: =IF(E8-F8>0,E8-F8,0) -> 0 | H8: =E8+F8 -> 0.05
B9: מזומנים (*) | C9: 0.0435 | D9: 0.04 | E9: 0.04
B10: סה"כ | C10: =SUM(C4:C9) -> 1 | D10: =SUM(D4:D9) -> 1 | E10: 1
B11: חשיפה למט"ח | C11: 0.1286 | E11: 0.12 | F11: 0.06 | G11: =IF(E11-F11>0,E11-F11,0) -> 0.06 | H11: =E11+F11 -> 0.18
B12: מגבלת עמלת ניהול חיצוני לשנת 2024 | E12: 0.001
B13: קופה 2415
B14: * מוצג בנטרול תוספת החשיפה הנובעת מהשקעה בנגזרים
B15: ** מובהר כי תיק הנכסים אינו תואם בהכרח במלואו להרכב מדד הייחוס. אין בציון מדד הייחוס בכדי להוות מצג, הצהרה או התחייבות כלשהי לגבי התשואה שתושג בפועל בתיק

Sheet אקסלנס אינווסט כללי
B1: מדיניות השקעה צפויה לשנת 2024
B2: תחילת מידע טבלה
A3: תחילת מידע טבלה צד ימין | B3: אקסלנס אינווסט - מסלול כללי | H3: סוף מידע טבלה צד שמאל
B4: אפיק השקעה | C4: שיעור חשיפה צפוי לשנת 2024 (החל מיום 1.7.24) | D4: טווח סטייה %-/+ | E4: גבולות שיעור החשיפה הצפויה | G4: מדד הייחוס (**)
B5: מניות (תעודות סל, אופציות, קרנות נאמנות) | C5: 0.4 | D5: 0.06 | E5: =IF(C5-D5>0,C5-D5,0) -> 0.34 | F5: =C5+D5 -> 0.46 | G5: 50%- מדד ת"א 125 , 50%- MSCI WORLD AC
B6: אג"ח ממשלתי (צמוד, שקלי ומט"ח), ממשלות זרות בנטרול חשיפות בנגזרים | C6: 0.2 | D6: 0.05 | E6: =IF(C6-D6>0,C6-D6,0) -> 0.15 | F6: =C6+D6 -> 0.25 | G6: 10% מקמ, 40% ממשלתי שקלי 2-5 , 10% ממשלתי שקלי 5+ , 35% ממשלתי צמוד 2-5 ,5% ממשלתי צמוד 5-10
B7: אג"ח קונצרני (קרנות נאמנות, תעודות סל) | C7: 0.35 | D7: 0.06 | E7: =IF(C7-D7>0,C7-D7,0) -> 0.29 | F7: =C7+D7 -> 0.41 | G7: 55% - מדד תל בונד 60, 35% - בונד שקלי 10% - מדד BarCap Global Corporate Total Return Bond Index UnHedged
B8: נדל"ן | C8: 0 | D8: 0.05 | E8: =IF(C8-D8>0,C8-D8,0) -> 0 | F8: =C8+D8 -> 0.05
B9: אחר (קרנות השקעה, PE, VC, קרדיט, גידור) | C9: 0 | D9: 0.05 | E9: =IF(C9-D9>0,C9-D9,0) -> 0 | F9: =C9+D9 -> 0.05
B10: מזומנים (*) | C10: 0.05 | G10: מדד המקמ
B11: סה"כ | C11: =SUM(C5:C10) -> 1
B12: חשיפה למט"ח | C12: 0.2 | D12: 0.06 | E12: =IF(C12-D12>0,C12-D12,0) -> 0.14 | F12: =C12+D12 -> 0.26 | G12: סל המטבעות
B13: מגבלת עמלת ניהול חיצוני לשנת 2024 | C13: 0.0015
B14: סוף מידע טבלה
B15: * מוצג בנטרול תוספת החשיפה הנובעת מהשקעה בנגזרים
B16: ** מובהר כי תיק הנכסים אינו תואם בהכרח במלואו להרכב מדד הייחוס. אין בציון מדד הייחוס בכדי להוות מצג, הצהרה או התחייבות כלשהי לגבי התשואה שתושג בפועל בתיק
A17: סוף מידע גיליון

Sheet אקסלנס אינווסט הלכתי
B1: מדיניות השקעה צפויה לשנת 2024
B2: תחילת מידע טבלה
A3: תחילת מידע טבלה צד ימין | B3: אקסלנס אינווסט - מסלול הלכה - ביטוח | H3: סוף מידע טבלה צד שמאל
B4: אפיק השקעה | C4: שיעור חשיפה צפוי לשנת 2024 (החל מיום 1.7.24) | D4: טווח סטייה %-/+ | E4: גבולות שיעור החשיפה הצפויה | G4: מדד הייחוס (**)
B5: מניות (תעודות סל, אופציות, קרנות נאמנות) | C5: 0.4 | D5: 0.06 | E5: =IF(C5-D5>0,C5-D5,0) -> 0.34 | F5: =C5+D5 -> 0.46 | G5: 50%- מדד ת"א 125 , 50%- MSCI WORLD AC
B6: אג"ח ממשלתי (צמוד, שקלי ומט"ח), ממשלות זרות בנטרול חשיפות בנגזרים | C6: 0.2 | D6: 0.05 | E6: =IF(C6-D6>0,C6-D6,0) -> 0.15 | F6: =C6+D6 -> 0.25 | G6: 10% מקמ, 40% ממשלתי שקלי 2-5 , 10% ממשלתי שקלי 5+ , 35% ממשלתי צמוד 2-5 ,5% ממשלתי צמוד 5-10
B7: אג"ח קונצרני (קרנות נאמנות, תעודות סל) | C7: 0.35 | D7: 0.06 | E7: =IF(C7-D7>0,C7-D7,0) -> 0.29 | F7: =C7+D7 -> 0.41 | G7: 55% - מדד תל בונד 60, 35% - בונד שקלי 10% - מדד BarCap Global Corporate Total Return Bond Index UnHedged
B8: נדל"ן | C8: 0 | D8: 0.05 | E8: =IF(C8-D8>0,C8-D8,0) -> 0 | F8: =C8+D8 -> 0.05
B9: אחר (קרנות השקעה, PE, VC, קרדיט, גידור) | C9: 0 | D9: 0.05 | E9: =IF(C9-D9>0,C9-D9,0) -> 0 | F9: =C9+D9 -> 0.05
B10: מזומנים (*) | C10: 0.05 | G10: מדד המקמ
B11: סה"כ | C11: =SUM(C5:C10) -> 1
B12: חשיפה למט"ח | C12: 0.2 | D12: 0.06 | E12: =IF(C12-D12>0,C12-D12,0) -> 0.14 | F12: =C12+D12 -> 0.26 | G12: סל המטבעות
B13: מגבלת עמלת ניהול חיצוני לשנת 2024 | C13: 0.001
B14: סוף מידע טבלה
B15: * מוצג בנטרול תוספת החשיפה הנובעת מהשקעה בנגזרים
B16: ** מובהר כי תיק הנכסים אינו תואם בהכרח במלואו להרכב מדד הייחוס. אין בציון מדד הייחוס בכדי להוות מצג, הצהרה או התחייבות כלשהי לגבי התשואה שתושג בפועל בתיק
A17: סוף מידע גיליון

Sheet אקסלנס אינווסט-מסלולים מתמחים
B1: מדיניות השקעה צפויה לשנת 2024
B3: תחילת מידע טבלה
A4: תחילת מידע טבלה צד ימין | B4: אקסלנס אינווסט עד 15% מניות | H4: סוף מידע טבלה צד שמאל
B6: אפיק השקעה | C6: שיעור חשיפה צפוי לשנת 2024 | D6: טווח סטיה | E6: גבולות שיעור החשיפה הצםויה | G6: מדד ייחוס
B7: מניות (כולל תעודות סל, אופציות, קרנות נאמנות) | C7: 0.09 | D7: 0.06 | E7: =+C7-D7 -> 0.03 | F7: =+C7+D7 -> 0.15 | G7: 40%- מדד ת"א 125 , 60%- MSCI WORLD AC
B8: אג"ח ממשלתי (צמוד, שקלי ומט"ח), ממשלות זרות בנטרול חשיפות בנגזרים | C8: 0.33 | D8: 0.05 | E8: =+C8-D8 -> 0.28 | F8: =+C8+D8 -> 0.38 | G8: מדד אג"ח ממשלתי כללי
B9: אג"ח קונצרני (כולל קרנות נאמנות, תעודות סל) | C9: 0.51 | D9: 0.06 | E9: =+C9-D9 -> 0.45 | F9: =+C9+D9 -> 0.57 | G9: 35% - תל בונד כללי , 20% - תל בונד 60 , 15% - תל בונד 50 , 15% - IBOXX HY - 15%, IBOXX IG
B10: מזומנים (*) | C10: 0.07 | E10: 0.02 | F10: 0.02
B11: סה"כ | C11: =SUM(C7:C10) -> 1
B12: חשיפה למט"ח | C12: 0.14 | D12: 0.05 | E12: =IF(C12-D12>0,C12-D12,0) -> 0.09 | F12: =C12+D12 -> 0.19
B13: מגבלת עמלת ניהול חיצוני לשנת 2024 | C13: 0.0005
B14: סוף מידע טבלה
B15: תחילת מידע טבלה
A16: תחילת מידע טבלה צד ימין | B16: אקסלנס אינווסט עד 25% מניות | H16: סוף מידע טבלה צד שמאל
B18: אפיק השקעה | C18: שיעור חשיפה צפוי לשנת 2024 | D18: טווח סטיה | E18: גבולות שיעור החשיפה הצםויה | G18: מדד ייחוס
B19: מניות (כולל תעודות סל, אופציות, קרנות נאמנות) | C19: 0.19 | D19: 0.06 | E19: =+C19-D19 -> 0.13 | F19: =+C19+D19 -> 0.25 | G19: 40%- מדד ת"א 125 , 60%- MSCI WORLD AC
B20: אג"ח ממשלתי (צמוד, שקלי ומט"ח), ממשלות זרות בנטרול חשיפות בנגזרים | C20: 0.3 | D20: 0.05 | E20: =+C20-D20 -> 0.25 | F20: =+C20+D20 -> 0.35 | G20: מדד אג"ח ממשלתי כללי
B21: אג"ח קונצרני (כולל קרנות נאמנות, תעודות סל) | C21: 0.46 | D21: 0.06 | E21: =+C21-D21 -> 0.4 | F21: =+C21+D21 -> 0.52 | G21: 35% - תל בונד כללי , 20% - תל בונד 60 , 15% - תל בונד 50 , 15% - IBOXX HY - 15%, IBOXX IG
B22: מזומנים (*) | C22: 0.05 | E22: 0.02 | F22: 0.02
B23: סה"כ | C23: =SUM(C19:C22) -> 1
B24: חשיפה למט"ח | C24: 0.18 | D24: 0.05 | E24: =IF(C24-D24>0,C24-D24,0) -> 0.13 | F24: =C24+D24 -> 0.23
B25: מגבלת עמלת ניהול חיצוני לשנת 2024 | C25: 0.0005
B26: סוף מידע טבלה
B27: תחילת מידע טבלה
A28: תחילת מידע טבלה צד ימין | B28: אקסלנס אינווסט מסלול מניות | H28: סוף מידע טבלה צד שמאל
B30: אפיק השקעה | C30: שיעור חשיפה צפוי לשנת 2024 | D30: טווח סטיה | E30: גבולות שיעור החשיפה הצםויה | G30: מדד ייחוס
B31: מניות (כולל תעודות סל, אופציות, קרנות נאמנות) | C31: 0.94 | D31: 0.06 | E31: =+C31-D31 -> 0.88 | F31: =+C31+D31 -> 1 | G31: 40%- מדד ת"א 125 , 60%- MSCI WORLD AC
B32: מזומנים (*) | C32: 0.06 | E32: 0.02 | F32: 0.02
B33: סה"כ | C33: =SUM(C31:C32) -> 1
B34: חשיפה למט"ח | C34: 0.48 | D34: 0.05 | E34: =IF(C34-D34>0,C34-D34,0) -> 0.43 | F34: =C34+D34 -> 0.53
B35: מגבלת עמלת ניהול חיצוני לשנת 2024 | C35: 0.0015
B36: סוף מידע טבלה
B37: תחילת מידע טבלה
A38: תחילת מידע טבלה צד ימין | B38: אקסלנס אינווסט מסלול שקלי | H38: סוף מידע טבלה צד שמאל
B40: אפיק השקעה | C40: שיעור חשיפה צפוי לשנת 2024 | D40: טווח סטיה | E40: גבולות שיעור החשיפה הצםויה | G40: מדד ייחוס
B41: אג"ח ממשלתי (צמוד, שקלי ומט"ח), ממשלות זרות בנטרול חשיפות בנגזרים | C41: 0.94 | D41: 0.05 | E41: =+C41-D41 -> 0.89 | F41: =+C41+D41 -> 0.99 | G41: מדד אג"ח ממשלתי כללי
B42: מזומנים (*) | C42: 0.06 | E42: 0.02 | F42: 0.02
B43: סה"כ | C43: =SUM(C41:C42) -> 1
B44: חשיפה למט"ח | C44: 0 | D44: 0.05 | E44: =IF(C44-D44>0,C44-D44,0) -> 0 | F44: =C44+D44 -> 0.05
B45: מגבלת עמלת ניהול חיצוני לשנת 2024 | C45: 0.0005
...

Sheet מכבי סיעודית
B1: ='קרן י'!B1 -> מדיניות השקעה לשנת 2024
B2: תחילת מידע טבלה
A3: תחילת מידע טבלה צד ימין | B3: מכבי סיעודית | H3: סוף מידע טבלה צד שמאל
B4: אפיק השקעה | C4: ='קרן י'!C4 -> שיעור חשיפה צפוי לשנת 2024 | D4: טווח סטייה %-/+ | E4: גבולות שיעור החשיפה הצפויה | G4: מדד הייחוס (**)
B5: מניות | C5: 0.59 | D5: 0.06 | E5: =IF(C5-D5>0,C5-D5,0) -> 0.53 | F5: =C5+D5 -> 0.65 | G5: 40%- מדד ת"א 125, 60%- MSCI WORLD AC
B6: אג"ח ממשלתי (צמוד,שקלי ומט"ח), ממשלות זרות בנטרול חשיפות בנגזרים (*) | C6: 0.06 | D6: 0.05 | E6: =IF(C6-D6>0,C6-D6,0) -> 0.01 | F6: =C6+D6 -> 0.11 | G6: מדד אג"ח ממשלתי כללי
B7: אג"ח קונצרני (קרנות נאמנות, תעודות סל) | C7: 0.32 | D7: 0.06 | E7: =IF(C7-D7>0,C7-D7,0) -> 0.26 | F7: =C7+D7 -> 0.38 | G7: 35% - תל בונד כללי , 20% - תל בונד 60 , 15% - תל בונד 50 , 15% - IBOXX HY - 15%, IBOXX IG
B8: אחר (קרנות השקעה, PE, VC, קרדיט, גידור) | C8: 0.01 | D8: 0.05 | E8: =IF(C8-D8>0,C8-D8,0) -> 0 | F8: =C8+D8 -> 0.06
B9: מזומנים (*) | C9: 0.02
B10: סה"כ | C10: 1
B11: חשיפה למט"ח | C11: 0.2 | D11: 0.06 | E11: =IF(C11-D11>0,C11-D11,0) -> 0.14 | F11: =C11+D11 -> 0.26
B13: סוף מידע טבלה
B15: * מוצג בנטרול תוספת החשיפה הנובעת מהשקעה בנגזרים
B16: ** מובהר כי תיק הנכסים אינו תואם בהכרח במלואו להרכב מדד הייחוס. אין בציון מדד הייחוס בכדי להוות מצג, הצהרה או התחייבות כלשהי לגבי התשואה שתושג בפועל בתיק
A17: סוף מידע גיליון

Sheet  אקסלנס ישן
A1: ='קרן י'!B1:G1 -> #VALUE!
A2: מסלולי אקסלנס אינווסט
A3: ***כל מסלולי אקסלנס אינווסט, מלבד מסלול מנוהל כללי 1, הינם מסלולים מתמחים וישקעו ע"פ מדיניות ההשקעה שהוגדרה בפוליסה
A4: מדיניות ההשקעה | B4: מדד הייחוס
A5: אג"ח 1 - שיעור הנכסים המושקעים באג"ח חברות או באג"ח ממשלתיות בישראל לא יפחת מ- 80% | B5: 85% מדד אג"ח כללי,
B6: 15% מדד מק"מ
A7: אג"ח 2 - שיעור הנכסים המושקעים באג"ח בארץ ובחו"ל לא יפחת מ- 85%, שיעור הנכסים המושקעים במניות סחירות ו/או תעודות סל בארץ ובחו"ל לא יעלה על 15% | B7: 80% מדד אג"ח כללי,
B8: 15% מדד ת"א 100,
B9: 5% מדד מק"מ
A10: אג"ח 3 - שיעור הנכסים המושקעים באג"ח בארץ ובחו"ל לא יפחת מ- 70%, שיעור הנכסים המושקעים במניות סחירות ו/או תעודות סל בארץ ובחו"ל לא יעלה על 30% | B10: 60% מדד אג"ח כללי,
B11: 30% מדד ת"א 100,
B12: 10% מדד מק"מ
A13: אג"ח 4 - שיעור הנכסים המושקעים באג"ח בארץ ובחו"ל לא יפחת מ- 50%, שיעור הנכסים המושקעים במניות סחירות ו/או תעודות סל בארץ ובחו"ל לא יעלה על 50% | B13: 40% מדד אג"ח כללי,
B14: 50% מדד ת"א 100,
B15: 10% מדד מק"מ
A16: אג"ח קצר מועד - הנכסים שיצטברו במסלול יושקעו בנכסים נושאי תשואה כולל פיקדונות ו/או אג"ח ממשלתיות בישראל ובחו"ל ו/או ניירות ערך מסחריים של חברות בישראל בדירוגAA ומעלה בעלי מח"מ של עד שנה. | B16: 100% מדד מק"מ
A17: למרות האמור, ה- מח"מ של עד 20% מהנכסים אפשר ויעלה על שנה ובלבד שה- מח"מ הממוצע של כלל הנכסים אינו עולה על שנה.
A18: אג"ח מדינה ללא מניות - לפחות 90% מהנכסים שיצטברו במסלול יושקעו באג"ח ממשלתיות בישראל ו/או בחו"ל ו/או במק"מ. עד 10% מהנכסים יושקעו לפי שיקול דעתו של בית ההשקעות . לא יושקעו כל נכסים במניות בבורסה בת"א ו/או בבורסות זרות בחו"ל . | B18: 90% מדד אג"ח כללי ממשלתי,
B19: 10% מדד מק"מ
A20: אקסלנס אינווסט חו"ל - לפחות 75% מהנכסים שיצטברו במסלול יושקעו במניות ו/או תעודות סל עוקבות מניות הנסחרות בחו"ל. שיעור הנכסים המושקעים במזומנים ושווי מזומנים במטבע חוץ, לרבות פיקדונות בבנקים, לא יעלה על 25% משווי הנכסים במסלול. | B20: MSCI WORLD AC
A23: מסלול מנוהל כללי 1
A25: אפיק השקעה | B25: שיעור חשיפה קודם | C25: שיעור חשיפה צפוי לשנת 2016 | D25: טווח סטייה | E25: גבולות החשיפה שאושרו | F25: מדד הייחוס
A26: מניות | B26: 0.91 | C26: 0.91 | D26: +/- 6% | E26: 85%-97% | F26: מדד ת"א 100
A27: מזומנים | B27: 0.09 | C27: 0.09 | D27: +/- 5% | E27: 4%-14% | F27: מדד מק"מ

Sheet אינווסט - מתמחים
A1: מדיניות השקעה לשנת 2016
A3: מסלולים מתמחים
A4: שם המסלול | B4: מדיניות ההשקעה | C4: מדד הייחוס
A5: מסלול מתמחה אג"ח | B5: נכסי המסלול יהיו חשופים לנכסים הבאים בארץ ובחו"ל: אג"ח סחירות ושאינן סחירות, ני"ע מסחריים, הלוואות שאינן סחירות, אג"ח להמרה ופקדונות, בשיעור חשיפה שלא יפחת מ-75% ולא יעלה על 120% מנכסי המסלול. חשיפה לנכסים כאמור תושג באמצעות השקעה במישרין, בנגזרים, בתעודות סל, בקרנות נאמנות או בקרנות השקעה.
A6: מסלול מתמחה אג"ח עד 25% מניות | B6: נכסי המסלול יהיו חשופים לנכסים הבאים: אג"ח סחירות ושאינן סחירות של חברות, ני"ע מסחריים, הלוואות שאינן סחירות לחברות, אג"ח להמרה, פקדונות, אג"ח של ממשלת ישראל או אג"ח של ממשלות אחרות. חשיפה לנכסי אג"ח תהיה בשיעור שלא יפחת מ-75% ולא יעלה על 120% מנכסי המסלול. חשיפה למניות תהיה בשיעור שלא יעלה על25% [ובכל אופן החשיפה לא תעלה על 25% מנכסי המסלול]. חשיפה לנכסים כאמור לעיל תושג הן באמצעות השקעה במישרין והן באמצעות השקעה בנגזרים, בתעודות סל, בקרנות נאמנות או בקרנות השקעה. חשיפה לנכסים שאינם נכסי אג"ח ואינם מניות תהיה על פי שיקול דעתה של ועדת ההשקעות ובכפוף לכל דין.
A7: מסלול מתמחה מניות | B7: נכסי המסלול יהיו חשופים למניות בארץ ובחו"ל, בשיעור חשיפה שלא יפחת מ-75% ולא יעלה על 120% מנכסי המסלול. חשיפה לנכסים כאמור תושג באמצעות השקעה במישרין, בנגזרים, בתעודות סל, בקרנות נאמנות או בקרנות השקעה. יתרת הנכסים תושקע בכפוף להוראות הדין, ובכפוף לשיקול דעתה של ועדת ההשקעות.
A8: מסלול מתמחה הלכה | B8: נכסי המסלול יהיו חשופים לנכסים מסוגים שונים בכפוף להוראות הדין ובכפוף לכללי ההלכה היהודית בלבד. ההשקעות במסלול תהיינה בסמכותה ובאחריותה הבלעדית של ועדת ההשקעות והחברה המנהלת תהיה חייבת לפעול בנאמנות על פי העמיתים במסלול זה. השאת התשואה במסלול מוגבלת בכך שההשקעות בו כפופות לכללי ההלכה היהודית.
A12: מדיניות ההשקעה | B12: מדד הייחוס
A13: אג"ח 1 | B13: יסגר
A14: אג"ח 2 | B14: יהפוך למסלול מתמחה אג"ח
A15: אג"ח 3 | B15: יהפוך למסלול מתמחה אג"ח עד 25% מניות
A16: אג"ח 4 | B16: יסגר
A17: אג"ח קצר מועד | B17: יסגר
A18: אג"ח מדינה ללא מניות | B18: יסגר
A19: אקסלנס אינווסט חו"ל | B19: יסגר
