Workbook
Name Additional_Factor: 'אפשרויות בחירה'!$C$701:$C$850
Name Amoritization: 'אפשרויות בחירה'!$C$546:$C$550
Name Capsule: 'אפשרויות בחירה'!$C$926:$C$928
Name Company_Name: 'File Name Info'!$A$34:$A$120
Name Company_Name_ID: 'File Name Info'!$A$34:$B$120
Name Consortium: 'אפשרויות בחירה'!$C$514:$C$515
Name Country_list: 'אפשרויות בחירה'!$C$4:$C$85
Name Country_list_funds: 'אפשרויות בחירה'!$C$4:$C$103
Name CSA: 'אפשרויות בחירה'!$C$688:$C$689
Name Delivery: 'אפשרויות בחירה'!$C$666:$C$667
Name Dependence_Independence: 'אפשרויות בחירה'!$C$654:$C$655
Name Duration_Underlying_Interest_Rate: 'אפשרויות בחירה'!$C$680:$C$687
Name File_Type: 'File Name Info'!$A$10:$A$12
Name Full_File_Type: 'File Name Info'!$A$11:$B$13
Name Full_Type: 'File Name Info'!$A$2:$B$8
Name Full_Type_Nostro: 'File Name Info'!$A$3:$B$6
Name Full_Year: 'File Name Info'!$A$22:$B$31
Name Fund_Strategy: 'אפשרויות בחירה'!$C$597:$C$621
Name Fund_type: 'אפשרויות בחירה'!$C$328:$C$498
Name Holding_interest: 'אפשרויות בחירה'!$C$146:$C$147
Name In_the_books: 'אפשרויות בחירה'!$C$656:$C$657
Name Industry_Sector: 'אפשרויות בחירה'!$C$1129:$C$1245
Name Industry_sector_all: 'אפשרויות בחירה'!$C$202:$C$327
Name Industry_sectors: 'אפשרויות בחירה'!$C$202:$C$327
Name israel_abroad: 'אפשרויות בחירה'!$C$2:$C$3
Name Issuer_Number_Banks: 'אפשרויות בחירה'!$C$111:$C$113
Name Issuer_Number_Fund: 'אפשרויות בחירה'!$C$114:$C$117
Name issuer_number_loan: 'אפשרויות בחירה'!$C$118:$C$126
Name Issuer_Number_Type: 'אפשרויות בחירה'!$C$104:$C$110
Name Issuer_Number_Type_2: 'אפשרויות בחירה'!$C$1076:$C$1079
Name Issuer_Number_Type_3: 'אפשרויות בחירה'!$C$1081:$C$1085
Name Issuer_Number_Type_V2: 'אפשרויות בחירה'!$C$104:$C$110
Name Issuer_Type_TFunds: 'אפשרויות בחירה'!$C$1087:$C$1089
Name Leading_factor: 'אפשרויות בחירה'!$C$692:$C$700
Name Linked_Type: 'אפשרויות בחירה'!$C$516:$C$519
Name other_investments: 'אפשרויות בחירה'!$C$1000:$C$1033
Name Penalty: 'אפשרויות בחירה'!$C$851:$C$852
Name QTR: 'File Name Info'!$A$15:$A$19
Name Rating_Agency: 'אפשרויות בחירה'!$C$188:$C$201
Name real_estate_lifestage: 'אפשרויות בחירה'!$C$634:$C$642
Name real_estate_loans: 'אפשרויות בחירה'!$C$553:$C$591
Name Real_Estate_Main_Use: 'אפשרויות בחירה'!$C$622:$C$633
Name Recourse_Nonrecourse: 'אפשרויות בחירה'!$C$544:$C$545
Name Repayment_Rights: 'אפשרויות בחירה'!$C$551:$C$552
Name Reset_frequency: 'אפשרויות בחירה'!$C$658:$C$665
Name Security_ID_Number_Type: 'אפשרויות בחירה'!$C$1113:$C$1116
Name Security_Number_Loans: 'אפשרויות בחירה'!$C$131
Name Stock_Exchange: 'אפשרויות בחירה'!$C$1283:$C$1315
Name Stock_Exchange_Gov_Bonds: 'אפשרויות בחירה'!$C$148:$C$181
Name Subordination_Risk: 'אפשרויות בחירה'!$C$186:$C$187
Name Tradeable_Status: 'אפשרויות בחירה'!$C$1272:$C$1281
Name Tradeable_Status_All: 'אפשרויות בחירה'!$C$135:$C$145
Name tradeable_status_bonds: 'אפשרויות בחירה'!$C$1248:$C$1253
Name tradeable_status_funds: 'אפשרויות בחירה'!$C$1118:$C$1119
Name tradeable_status_stock: 'אפשרויות בחירה'!$C$1255:$C$1259
Name Tradeable_Status_v2: 'אפשרויות בחירה'!$C$1121:$C$1126
Name tradeable_status_warrants: 'אפשרויות בחירה'!$C$1261:$C$1265
Name tradeable_status_warrants_v2: 'אפשרויות בחירה'!$C$1267:$C$1269
Name Transaction: 'אפשרויות בחירה'!$C$643:$C$646
Name Type: 'File Name Info'!$A$2:$A$8

Sheet עמוד פתיחה
A1: קובץ דיווח עבור רשימת נכסים ברמת הנכס הבודד (חוזר גופים מוסדיים 2015-9-14)
A3: יש לבחור תחום: | D3: נכסי עמיתים - קופות גמל
A5: האם מדובר בקובץ לממומנה או לציבור: | D5: לציבור
A7: יש לבחור את רבעון הדיווח: | D7: 03
A9: יש לבחור את שנת הדיווח: | D9: 2024
A11: יש לבחור את הגוף המוסדי: | D11: חברת ב'ת למ'ד דל'ת בע"מ
A13: ח.פ. הגוף המוסדי: | D13: =IFERROR(VLOOKUP(D11,'File Name Info'!A35:B121,2,0),"תא מחושב") -> 510142789
A15: שם קובץ לשמירה | D15: =IF(D5="לממונה",CONCATENATE(D13, "_",VLOOKUP(D3,Full_Type,2,0),"_",D7,VLOOKUP(D9,Full_Year,2,0),".xlxs"),IF(D5="לציבור",CONCATENATE(D13,"_",VLOOKUP(D3,Full_Type_Nostro,2,0),"_",VLOOKUP(D5,Full_File_Type,2,0),"_",D7,VLOOKUP(D9,Full_Year,2,0),".xlsx"),"שם קובץ לשמירה")) -> 510142789_gm_p_0324.xlsx
A17: פרטי האחראי על הדיווח בגוף המוסדי | B17: שם: | D17: עינת מאיר , מנכ"ל
B19: מספר טלפון:
B21: כתובת מייל: | D21: einat.meir@dbank.co.il

Sheet סכום נכסים
C1: ידווח בקבצי נכסי הנוסטרו בלבד
B2: שווי הוגן | C2: עלות מופחתת | D2: השיטה שיושמה בדוח הכספי | E2: שיעור מסך נכסי השקעה
A3: מזומנים ושווי מזומנים | B3: =SUM('מזומנים ושווי מזומנים'!O:O) -> 45530.568 | D3: =B3+C3 -> 45530.568 | E3: =SUM('מזומנים ושווי מזומנים'!O:O)/B30 -> 0.048343441
A4: איגרות חוב ממשלתיות | B4: =SUM('איגרות חוב ממשלתיות'!U:U) -> 253570.51 | D4: =B4+C4 -> 253570.51 | E4: =SUM('איגרות חוב ממשלתיות'!U:U)/B30 -> 0.26923607
A5: ניירות ערך מסחריים | B5: =SUM('ניירות ערך מסחריים'!AD:AD) -> 0 | D5: =B5+C5 -> 0 | E5: =SUM('ניירות ערך מסחריים'!AD:AD)/B30 -> 0
A6: איגרות חוב | B6: =SUM('איגרות חוב'!AD:AD) -> 171226.16 | D6: =B6+C6 -> 171226.16 | E6: =SUM('איגרות חוב'!AD:AD)/B30 -> 0.18180449
A7: מניות, מניות בכורה ויחידות השתתפות | B7: =SUM('מניות מבכ ויהש'!U:U) -> 131532.29 | D7: =B7+C7 -> 131532.29 | E7: =SUM('מניות מבכ ויהש'!U:U)/B30 -> 0.13965833
A8: קרנות סל | B8: =SUM('קרנות סל'!T:T) -> 230708 | D8: =B8+C8 -> 230708 | E8: =SUM('קרנות סל'!T:T)/B30 -> 0.24496111
A9: קרנות נאמנות | B9: =SUM('קרנות נאמנות'!T:T) -> 0 | D9: =B9+C9 -> 0 | E9: =SUM('קרנות נאמנות'!T:T)/B30 -> 0
A10: כתבי אופציה | B10: =SUM('כתבי אופציה'!W:W) -> 0 | D10: =B10+C10 -> 0 | E10: =SUM('כתבי אופציה'!W:W)/B30 -> 0
A11: אופציות | B11: =SUM(אופציות!V:V) -> 0 | D11: =B11+C11 -> 0 | E11: =SUM(אופציות!V:V)/B30 -> 0
A12: חוזים עתידיים | B12: =SUM('חוזים עתידיים'!R:R) -> 0 | D12: =B12+C12 -> 0 | E12: =SUM('חוזים עתידיים'!R:R)/B30 -> 0
A13: מוצרים מובנים | B13: =SUM('מוצרים מובנים'!Z:Z) -> 0 | D13: =B13+C13 -> 0 | E13: =SUM('מוצרים מובנים'!Z:Z)/B30 -> 0
A14: לא סחיר איגרות חוב ממשלתיות | B14: =SUM('לא סחיר איגרות חוב ממשלתיות'!U:U) -> 0 | D14: =B14+C14 -> 0 | E14: =SUM('לא סחיר איגרות חוב ממשלתיות'!U:U)/B30 -> 0
A15: לא סחיר איגרות חוב מיועדות | B15: =SUM('לא סחיר איגרות חוב מיועדות'!N:N) -> 0 | D15: =B15+C15 -> 0 | E15: =SUM('לא סחיר איגרות חוב מיועדות'!N:N)/B30 -> 0
A16: אפיק השקעה מובטח תשואה | B16: =SUM('אפיק השקעה מובטח תשואה'!F:F) -> 0 | D16: =B16+C16 -> 0 | E16: =SUM('אפיק השקעה מובטח תשואה'!F:F)/B30 -> 0
A17: לא סחיר ניירות ערך מסחריים | B17: =SUM('לא סחיר ניירות ערך מסחריים'!AI:AI) -> 0 | D17: =B17+C17 -> 0 | E17: =SUM('לא סחיר ניירות ערך מסחריים'!AI:AI)/B30 -> 0
A18: לא סחיר איגרות חוב | B18: =SUM('לא סחיר איגרות חוב'!AG:AG) -> 10866.955 | D18: =B18+C18 -> 10866.955 | E18: =SUM('לא סחיר איגרות חוב'!AG:AG)/B30 -> 0.011538314
A19: לא סחיר מניות, מניות בכורה ויחידות השתתפות | B19: =SUM('לא סחיר מניות מבכ ויהש'!X:X) -> 0 | D19: =B19+C19 -> 0 | E19: =SUM('לא סחיר מניות מבכ ויהש'!X:X)/B30 -> 0
A20: קרנות השקעה | B20: =SUM('קרנות השקעה'!W:W) -> 95775.561 | D20: =B20+C20 -> 95775.561 | E20: =SUM('קרנות השקעה'!W:W)/B30 -> 0.10169256
A21: לא סחיר כתבי אופציה | B21: =SUM('לא סחיר כתבי אופציה'!Z:Z) -> 0 | D21: =B21+C21 -> 0 | E21: =SUM('לא סחיר כתבי אופציה'!Z:Z)/B30 -> 0
A22: לא סחיר אופציות | B22: =SUM('לא סחיר אופציות'!Z:Z) -> 0 | D22: =B22+C22 -> 0 | E22: =SUM('לא סחיר אופציות'!Z:Z)/B30 -> 0
A23: לא סחיר נגזרים אחרים | B23: =SUM('לא סחיר נגזרים אחרים'!R:R) -> 2623.8501 | D23: =B23+C23 -> 2623.8501 | E23: =SUM('לא סחיר נגזרים אחרים'!R:R)/B30 -> 0.0027859512
A24: הלוואות | B24: =SUM(הלוואות!AT:AT) -> 0 | D24: =B24+C24 -> 0 | E24: =SUM(הלוואות!AT:AT)/B30 -> 0
A25: לא סחיר מוצרים מובנים | B25: =SUM('לא סחיר מוצרים מובנים'!AB:AB) -> 0 | D25: =B25+C25 -> 0 | E25: =SUM('לא סחיר מוצרים מובנים'!AB:AB)/B30 -> 0
A26: פיקדונות מעל 3 חודשים | B26: =SUM('פיקדונות מעל 3 חודשים'!T:T) -> 0 | D26: =B26+C26 -> 0 | E26: =SUM('פיקדונות מעל 3 חודשים'!T:T)/B30 -> 0
A27: זכויות מקרקעין | B27: =SUM('זכויות מקרקעין'!S:S) -> 0 | D27: =B27+C27 -> 0 | E27: =SUM('זכויות מקרקעין'!S:S)/B30 -> 0
A28: השקעה בחברות מוחזקות | B28: =SUM('השקעה בחברות מוחזקות'!U:U) -> 0 | D28: =B28+C28 -> 0 | E28: =SUM('השקעה בחברות מוחזקות'!U:U)/B30 -> 0
A29: נכסים אחרים | B29: =SUM('נכסים אחרים'!N:N) -> -19.089 | D29: =B29+C29 -> -19.089 | E29: =SUM('נכסים אחרים'!N:N)/B30 -> -2.0268316e-05
A30: סך הכל נכסים | B30: =IF(SUM(B3:B29)=0,0.0001,SUM(B3:B29)) -> 941814.8 | C30: =SUM(C3:C29) -> 0 | D30: =SUM(D3:D29) -> 941814.8 | E30: =SUM(E3:E29) -> 1
A31: מסגרות אשראי
A32: יתרות התחייבויות להשקעה | B32: =SUM('יתרות התחייבות להשקעה'!O:O) -> 28082.007

Sheet מזומנים ושווי מזומנים
A1: מספר קופה/קרן/ח.פ. עבור חברת ביטוח | B1: מספר מסלול | C1: שם הבנק | D1: מספר מזהה בנק | E1: סוג מספר מזהה בנק | F1: מאפיין עיקרי | G1: ישראל/חו"ל | H1: בעל עניין/צד קשור | I1: דירוג הבנק | J1: שם מדרג | K1: מטבע פעילות | L1: שווי מטבעי | M1: שער חליפין | N1: שיעור ריבית | O1: שווי הוגן (באלפי ש"ח) | P1: שיעור מנכסי אפיק ההשקעה | Q1: שיעור מסך נכסי ההשקעה
A2: 233 | B2: 233 | C2: בנק דיסקונט לישראל בע"מ | D2: 11-10 | E2: סימול בנק | F2: מזומן ועו"ש נקוב במט"ח | G2: ישראל | H2: כן | I2: AAA | J2: S&P מעלות | K2: USD | L2: 4898.117 | M2: 3.71 | N2: 0.0386 | O2: 18172.016 | P2: 0.39911683 | Q2: 0.019348584
A3: 233 | B3: 233 | C3: בנק דיסקונט לישראל בע"מ | D3: 11-10 | E3: סימול בנק | F3: מזומן ועו"ש נקוב במט"ח | G3: ישראל | H3: כן | I3: AAA | J3: S&P מעלות | K3: HKD | L3: 54.886 | M3: 0.4766 | N3: 0 | O3: 26.159 | P3: 0.00057452749 | Q3: 2.785223e-05
A4: 233 | B4: 233 | C4: בנק דיסקונט לישראל בע"מ | D4: 11-10 | E4: סימול בנק | F4: מזומן ועו"ש נקוב במט"ח | G4: ישראל | H4: כן | I4: AAA | J4: S&P מעלות | K4: EUR | L4: 184.713 | M4: 4.1524 | N4: 0 | O4: 767.004 | P4: 0.016845903 | Q4: 0.00081666406
A5: 233 | B5: 233 | C5: בנק דיסקונט לישראל בע"מ | D5: 11-10 | E5: סימול בנק | F5: מזומן ועו"ש נקוב במט"ח | G5: ישראל | H5: כן | I5: AAA | J5: S&P מעלות | K5: JPY | L5: 0.353 | M5: 0.026029 | N5: 0 | O5: 0.009 | P5: 2.0158075e-07 | Q5: 9.7723318e-09
A6: 233 | B6: 233 | C6: בנק דיסקונט לישראל בע"מ | D6: 11-10 | E6: סימול בנק | F6: מזומן ועו"ש נקוב במט"ח | G6: ישראל | H6: כן | I6: AAA | J6: S&P מעלות | K6: GBP | L6: 0 | M6: 4.9748 | N6: 0 | O6: 0.001 | P6: 3.2778858e-08 | Q6: 1.5890698e-09
A7: 233 | B7: 233 | C7: בנק דיסקונט לישראל בע"מ | D7: 11-10 | E7: סימול בנק | F7: מזומן ועו"ש בש"ח | G7: ישראל | H7: כן | I7: AAA | J7: S&P מעלות | K7: ILS | L7: 26564.692 | M7: 1 | N7: 0.0414 | O7: 26564.692 | P7: 0.58344742 | Q7: 0.028284655
A8: 233 | B8: 233 | C8: בנק לאומי לישראל בע"מ | D8: 10-800 | E8: סימול בנק | F8: מזומן ועו"ש בש"ח | G8: ישראל | H8: לא | I8: AAA | J8: S&P מעלות | K8: ILS | L8: 0.687 | M8: 1 | N8: 0 | O8: 0.687 | P8: 1.509162e-05 | Q8: 7.3161905e-07

Sheet איגרות חוב ממשלתיות
A1: מספר קופה/קרן/ח.פ. עבור חברת ביטוח | B1: מספר מסלול | C1: שם מנפיק | D1: שם נייר ערך | E1: מספר נייר ערך | F1: מאפיין עיקרי | G1: ישראל/חו"ל | H1: מדינה לפי חשיפה כלכלית | I1: זירת מסחר | J1: דירוג | K1: שם מדרג | L1: מטבע פעילות | M1: מח"מ | N1: מועד פדיון | O1: שיעור ריבית | P1: תשואה לפדיון | Q1: סכום לקבל (במטבע הפעילות) | R1: ערך נקוב (יחידות) | S1: שער חליפין | T1: שער נייר הערך | U1: שווי הוגן (באלפי ש"ח) | V1: עלות מופחתת (באלפי ש"ח) | W1: השיטה שיושמה בדוח הכספי | X1: שיעור מערך נקוב מונפק | Y1: שיעור מנכסי אפיק ההשקעה | Z1: שיעור מסך נכסי ההשקעה
A2: 233 | B2: 233 | C2: גליל | D2: ממשל צמודה 0527 | E2: IL0011408478 | F2: צמוד למדד המחירים לצרכן בריבית קבועה | G2: ישראל | H2: ישראל | I2: TASE | J2: RF | K2: פנימי | L2: ILS | M2: 2.64 | N2: 31/05/2027 | O2: 0.0075 | P2: 0.0163 | R2: 34481553 | S2: 1 | T2: 114.25 | U2: 39395.174 | W2: שווי הוגן | X2: 0.001547 | Y2: 0.15536181 | Z2: 0.041945862
A3: 233 | B3: 233 | C3: גליל | D3: ממשל צמודה 1131 | E3: IL0011722209 | F3: צמוד למדד המחירים לצרכן בריבית קבועה | G3: ישראל | H3: ישראל | I3: TASE | J3: RF | K3: פנימי | L3: ILS | M3: 7.134 | N3: 30/11/2031 | O3: 0.001 | P3: 0.01991 | R3: 2325000 | S3: 1 | T3: 101.1 | U3: 2350.575 | W3: שווי הוגן | X3: 7.6e-05 | Y3: 0.0092699066 | Z3: 0.0025027658
A4: 233 | B4: 233 | C4: שחר | D4: ממשל שיקלית 0928 | E4: IL0011508798 | F4: לא צמוד למדד המחירים לצרכן ריבית קבועה | G4: ישראל | H4: ישראל | I4: TASE | J4: RF | K4: פנימי | L4: ILS | M4: 3.86 | N4: 28/09/2028 | O4: 0.0225 | P4: 0.04516 | R4: 73000000 | S4: 1 | T4: 91.9 | U4: 67087 | W4: שווי הוגן | X4: 0.002178 | Y4: 0.2645694 | Z4: 0.071430628
A5: 233 | B5: 233 | C5: שחר | D5: ממשל שקלית 0927 | E5: IL0012035791 | F5: לא צמוד למדד המחירים לצרכן ריבית קבועה | G5: ישראל | H5: ישראל | I5: TASE | J5: RF | K5: פנימי | L5: ILS | M5: 2.89 | N5: 30/09/2027 | O5: 0.0375 | P5: 0.04453 | R5: 5000000 | S5: 1 | T5: 98.09 | U5: 4904.5 | W5: שווי הוגן | X5: 0.000297 | Y5: 0.01934176 | Z5: 0.0052220477
A6: 233 | B6: 233 | C6: שחר | D6: ממשל שקלית 0825 | E6: IL0011355570 | F6: לא צמוד למדד המחירים לצרכן ריבית קבועה | G6: ישראל | H6: ישראל | I6: TASE | J6: RF | K6: פנימי | L6: ILS | M6: 0.92 | N6: 31/08/2025 | O6: 0.0175 | P6: 0.04184 | R6: 25160000 | S6: 1 | T6: 98.02 | U6: 24661.832 | W6: שווי הוגן | X6: 0.001058 | Y6: 0.09725828 | Z6: 0.026258592
A7: 233 | B7: 233 | C7: שחר | D7: ממשלתי שקלית 0142 | E7: IL0011254005 | F7: לא צמוד למדד המחירים לצרכן ריבית קבועה | G7: ישראל | H7: ישראל | I7: TASE | J7: RF | K7: פנימי | L7: ILS | M7: 11.238 | N7: 31/01/2042 | O7: 0.055 | P7: 0.05173 | R7: 5400000 | S7: 1 | T7: 107.34 | U7: 5796.36 | W7: שווי הוגן | X7: 0.000251 | Y7: 0.022858967 | Z7: 0.0061716522
A8: 233 | B8: 233 | C8: גליל | D8: ממשלתית צמודה 0.5% 0529 | E8: IL0011570236 | F8: צמוד למדד המחירים לצרכן בריבית קבועה | G8: ישראל | H8: ישראל | I8: TASE | J8: RF | K8: פנימי | L8: ILS | M8: 4.61 | N8: 31/05/2029 | O8: 0.005 | P8: 0.01828 | R8: 34300103 | S8: 1 | T8: 108.85 | U8: 37335.662 | W8: שווי הוגן | X8: 0.001272 | Y8: 0.14723976 | Z8: 0.039753004
A9: 233 | B9: 233 | C9: גליל | D9: ממשלתית צמודה 1.10% 1028 | E9: IL0011973265 | F9: צמוד למדד המחירים לצרכן בריבית קבועה | G9: ישראל | H9: ישראל | I9: TASE | J9: RF | K9: פנימי | L9: ILS | M9: 3.972 | N9: 31/10/2028 | O9: 0.011 | P9: 0.01806 | R9: 44080000 | S9: 1 | T9: 102.6 | U9: 45226.08 | W9: שווי הוגן | X9: 0.002161 | Y9: 0.17835701 | Z9: 0.048154297
A10: 233 | B10: 233 | C10: שחר | D10: ממשלתית שקלית 1.3% 04/32 | E10: IL0011806606 | F10: לא צמוד למדד המחירים לצרכן ריבית קבועה | G10: ישראל | H10: ישראל | I10: TASE | J10: RF | K10: פנימי | L10: ILS | M10: 7.124 | N10: 30/04/2032 | O10: 0.013 | P10: 0.04754 | R10: 20750000 | S10: 1 | T10: 78.98 | U10: 16388.35 | W10: שווי הוגן | X10: 0.000692 | Y10: 0.064630346 | Z10: 0.017449433
A11: 233 | B11: 233 | C11: State of Israel,3416 | D11: STATE OF ISAREL 5.5% 12/03/2034 | E11: US46514BRL35 | F11: צמוד מט"ח בריבית קבועה | G11: חו"ל | H11: ישראל | I11: אחר | J11: Baa1 | K11: Moodys | L11: USD | M11: 7.49 | N11: 12/03/2034 | O11: 0.055 | P11: 0.05872 | R11: 2800000 | S11: 3.71 | T11: 100.356 | U11: 10424.981 | W11: שווי הוגן | X11: 0.000933 | Y11: 0.04111275 | Z11: 0.011099959

Sheet ניירות ערך מסחריים
A1: מספר קופה/קרן/ח.פ. עבור חברת ביטוח | B1: מספר מסלול | C1: שם מנפיק | D1: מספר מנפיק | E1: סוג מספר מזהה מנפיק | F1: שם נייר ערך | G1: מספר נייר ערך | H1: סוג מספר נייר ערך | I1: מאפיין עיקרי | J1: ישראל/חו"ל | K1: מדינה לפי חשיפה כלכלית | L1: זירת מסחר | M1: ענף מסחר | N1: בעל עניין/צד קשור | O1: דירוג | P1: שם מדרג | Q1: דירוג נייר הערך/המנפיק | R1: מטבע פעילות | S1: מח"מ | T1: ריבית עוגן | U1: מועד פדיון | V1: שיעור ריבית | W1: תשואה לפדיון | X1: נחיתות חוזית | Y1: האם סווג כחוב בעייתי | Z1: ערך נקוב (יחידות) | AA1: שער חליפין | AB1: שער נייר הערך | AC1: סכום לקבל (במטבע הפעילות) | AD1: שווי הוגן (באלפי ש"ח) | AE1: עלות מופחתת (באלפי ש"ח) | AF1: עלות מופחתת (במטבע הפעילות) | AG1: השיטה שיושמה בדוח הכספי | AH1: שיעור מערך נקוב מונפק | AI1: שיעור מנכסי אפיק ההשקעה | AJ1: שיעור מסך נכסי ההשקעה

Sheet איגרות חוב
A1: מספר קופה/קרן/ח.פ. עבור חברת ביטוח | B1: מספר מסלול | C1: שם מנפיק | D1: מספר מנפיק | E1: סוג מספר מזהה מנפיק | F1: שם נייר ערך | G1: מספר נייר ערך | H1: סוג מספר נייר ערך | I1: מאפיין עיקרי | J1: ישראל/חו"ל | K1: מדינה לפי חשיפה כלכלית | L1: סטאטוס סחירות | M1: זירת מסחר | N1: ענף מסחר | O1: בעל עניין/צד קשור | P1: דירוג | Q1: שם מדרג | R1: דירוג נייר הערך/המנפיק | S1: מטבע פעילות | T1: מח"מ | U1: מועד פדיון | V1: שיעור ריבית | W1: תשואה לפדיון | X1: נחיתות חוזית | Y1: האם סווג כחוב בעייתי | Z1: ערך נקוב (יחידות) | AA1: שער חליפין | AB1: שער נייר הערך | AC1: סכום לקבל (במטבע הפעילות) | AD1: שווי הוגן (באלפי ש"ח) | AE1: עלות מופחתת (באלפי ש"ח) | AF1: עלות מופחתת (במטבע הפעילות) | AG1: השיטה שיושמה בדוח הכספי | AH1: שיעור מערך נקוב מונפק | AI1: שיעור מנכסי אפיק ההשקעה | AJ1: שיעור מסך נכסי ההשקעה
A2: 233 | B2: 233 | C2: אלבר שירותי מימונית בע"מ | D2: 512025891 | E2: ח.פ | F2: אלבר אגח יט | G2: IL0011918245 | H2: ISIN | I2: צמוד למדד המחירים לצרכן | J2: ישראל | K2: ישראל | L2: סחיר | M2: TASE | N2: שירותים | O2: לא | P2: A+ | Q2: S&P מעלות | R2: נייר ערך | S2: ILS | T2: 1.802 | U2: 15/05/2028 | V2: 0.032 | W2: 0.03135 | X2: החוב לא נחות | Y2: לא | Z2: 3125000 | AA2: 1 | AB2: 107.71 | AD2: 3365.938 | AG2: שווי הוגן | AH2: 0.003798 | AI2: 0.019657847 | AJ2: 0.0035838691
A3: 233 | B3: 233 | C3: אלוני-חץ נכסים והשקעות בע"מ | D3: 520038506 | E3: ח.פ | F3: אלוני חץ אגח טו | G3: IL0011894149 | H3: ISIN | I3: צמוד למדד המחירים לצרכן | J3: ישראל | K3: ישראל | L3: סחיר | M3: TASE | N3: נדל"ן מניב בישראל | O3: לא | P3: AA- | Q3: S&P מעלות | R3: נייר ערך | S3: ILS | T3: 6.911 | U3: 01/03/2037 | V3: 0.0256 | W3: 0.04235 | X3: החוב לא נחות | Y3: לא | Z3: 950000 | AA3: 1 | AB3: 97.49 | AD3: 926.155 | AG3: שווי הוגן | AH3: 0.000904 | AI3: 0.0054089575 | AJ3: 0.00098612001
A4: 233 | B4: 233 | C4: אמות השקעות בע"מ | D4: 520026683 | E4: ח.פ | F4: אמות אגח ד | G4: IL0011331498 | H4: ISIN | I4: צמוד למדד המחירים לצרכן | J4: ישראל | K4: ישראל | L4: סחיר | M4: TASE | N4: נדל"ן מניב בישראל | O4: לא | P4: AA | Q4: S&P מעלות | R4: נייר ערך | S4: ILS | T4: 2.182 | U4: 02/07/2028 | V4: 0.032 | W4: 0.02647 | X4: החוב לא נחות | Y4: לא | Z4: 918000 | AA4: 1 | AB4: 117.37 | AD4: 1077.457 | AG4: שווי הוגן | AH4: 0.000873 | AI4: 0.0062925935 | AJ4: 0.0011472178
A5: 233 | B5: 233 | C5: אנלייט אנרגיה מתחדשת בע"מ | D5: 520041146 | E5: ח.פ | F5: אנלייט אנר אגח ו | G5: IL0072001733 | H5: ISIN | I5: לא צמוד למדד המחירים לצרכן | J5: ישראל | K5: ארה"ב | L5: סחיר | M5: TASE | N5: אנרגיה מתחדשת | O5: לא | P5: A | Q5: מידרוג Moodys | R5: נייר ערך | S5: ILS | T5: 1.736 | U5: 01/09/2026 | V5: 0.0345 | W5: 0.05725 | X5: החוב לא נחות | Y5: לא | Z5: 6000051.8 | AA5: 1 | AB5: 96.61 | AD5: 5796.65 | AG5: שווי הוגן | AH5: 0.009335 | AI5: 0.033853765 | AJ5: 0.006171961
A6: 233 | B6: 233 | C6: אנרג'יקס אנרגיות מתחדשות בע"מ | D6: 513901371 | E6: ח.פ | F6: אנרג'יקס אגח א | G6: IL0011617516 | H6: ISIN | I6: לא צמוד למדד המחירים לצרכן | J6: ישראל | K6: ישראל | L6: סחיר | M6: TASE | N6: אנרגיה מתחדשת | O6: לא | P6: A | Q6: S&P מעלות | R6: נייר ערך | S6: ILS | T6: 2.859 | U6: 01/08/2030 | V6: 0.0205 | W6: 0.05923 | X6: החוב לא נחות | Y6: לא | Z6: 6606199.3 | AA6: 1 | AB6: 90.04 | AD6: 5948.222 | AG6: שווי הוגן | AH6: 0.01478 | AI6: 0.034738979 | AJ6: 0.0063333466
A7: 233 | B7: 233 | C7: קבוצת אשטרום | D7: 510381601 | E7: ח.פ | F7: אשטרום קב אגח א | G7: IL0011323230 | H7: ISIN | I7: צמוד למדד המחירים לצרכן | J7: ישראל | K7: ישראל | L7: סחיר | M7: TASE | N7: בנייה | O7: לא | P7: A | Q7: S&P מעלות | R7: נייר ערך | S7: ILS | T7: 0.6 | U7: 10/11/2025 | V7: 0.024 | W7: 0.03405 | X7: החוב לא נחות | Y7: לא | Z7: 1338855.9 | AA7: 1 | AB7: 115.96 | AD7: 1552.537 | AG7: שווי הוגן | AH7: 0.013314 | AI7: 0.009067174 | AJ7: 0.0016530582
A8: 233 | B8: 233 | C8: קבוצת אשטרום | D8: 510381601 | E8: ח.פ | F8: אשטרום קב אגח ג | G8: IL0011401028 | H8: ISIN | I8: לא צמוד למדד המחירים לצרכן | J8: ישראל | K8: ישראל | L8: סחיר | M8: TASE | N8: בנייה | O8: לא | P8: A | Q8: S&P מעלות | R8: נייר ערך | S8: ILS | T8: 1.61 | U8: 15/01/2029 | V8: 0.043 | W8: 0.06117 | X8: החוב לא נחות | Y8: לא | Z8: 2606173 | AA8: 1 | AB8: 97.33 | AD8: 2536.588 | AG8: שווי הוגן | AH8: 0.002869 | AI8: 0.014814256 | AJ8: 0.0027008226
A9: 233 | B9: 233 | C9: בתי זקוק לנפט בע"מ | D9: 520036658 | E9: ח.פ | F9: בזן אגח י | G9: IL0025905113 | H9: ISIN | I9: לא צמוד למדד המחירים לצרכן | J9: ישראל | K9: ישראל | L9: סחיר | M9: TASE | N9: אנרגיה | O9: לא | P9: A+ | Q9: S&P מעלות | R9: נייר ערך | S9: ILS | T9: 2.311 | U9: 25/09/2031 | V9: 0.027 | W9: 0.05902 | X9: החוב לא נחות | Y9: לא | Z9: 5541462.8 | AA9: 1 | AB9: 93.07 | AD9: 5157.439 | AG9: שווי הוגן | AH9: 0.008128 | AI9: 0.030120628 | AJ9: 0.005491364
A10: 233 | B10: 233 | C10: פז בית זיקוק לנפט-אשדוד בע"מ | D10: 513775163 | E10: ח.פ | F10: בית זיקוק אשדוד אגח 2 | G10: IL0011994881 | H10: ISIN | I10: לא צמוד למדד המחירים לצרכן | J10: ישראל | K10: ישראל | L10: סחיר | M10: TASE | N10: אנרגיה | O10: לא | P10: A- | Q10: מידרוג Moodys | R10: נייר ערך | S10: ILS | T10: 3.001 | U10: 30/04/2029 | V10: 0.0725 | W10: 0.06395 | X10: החוב לא נחות | Y10: לא | Z10: 2661400 | AA10: 1 | AB10: 105.92 | AD10: 2818.955 | AG10: שווי הוגן | AH10: 0.003696 | AI10: 0.016463343 | AJ10: 0.0030014715
A11: 233 | B11: 233 | C11: חברת גב-ים לקרקעות בע"מ | D11: 520001736 | E11: ח.פ | F11: גב ים אגח ט | G11: IL0075902192 | H11: ISIN | I11: צמוד למדד המחירים לצרכן | J11: ישראל | K11: ישראל | L11: סחיר | M11: TASE | N11: נדל"ן מניב בישראל | O11: לא | P11: AA | Q11: S&P מעלות | R11: נייר ערך | S11: ILS | T11: 3.969 | U11: 30/06/2033 | V11: 0.005 | W11: 0.03189 | X11: החוב לא נחות | Y11: לא | Z11: 4162179.1 | AA11: 1 | AB11: 103.53 | AD11: 4309.104 | AG11: שווי הוגן | AH11: 0.002586 | AI11: 0.025166155 | AJ11: 0.0045881021
A12: 233 | B12: 233 | C12: י.ח.דמרי בניה ופיתוח בע"מ | D12: 511399388 | E12: ח.פ | F12: דמרי אגח ט | G12: IL0011683682 | H12: ISIN | I12: לא צמוד למדד המחירים לצרכן | J12: ישראל | K12: ישראל | L12: סחיר | M12: TASE | N12: בנייה | O12: לא | P12: A+ | Q12: מידרוג Moodys | R12: נייר ערך | S12: ILS | T12: 2.079 | U12: 31/12/2027 | V12: 0.0258 | W12: 0.05516 | X12: החוב לא נחות | Y12: לא | Z12: 3900000 | AA12: 1 | AB12: 94.9 | AD12: 3701.1 | AG12: שווי הוגן | AH12: 0.014552 | AI12: 0.021615272 | AJ12: 0.0039407321
A13: 233 | B13: 233 | C13: הראל ביטוח מימון והנפקות בע"מ | D13: 513834200 | E13: ח.פ | F13: הראל הנפקות אגח יט | G13: IL0011927725 | H13: ISIN | I13: לא צמוד למדד המחירים לצרכן | J13: ישראל | K13: ישראל | L13: סחיר | M13: TASE | N13: ביטוח | O13: לא | P13: AA- | Q13: S&P מעלות | R13: נייר ערך | S13: ILS | T13: 4.681 | U13: 31/12/2029 | V13: 0.0438 | W13: 0.05527 | X13: החוב לא נחות | Y13: לא | Z13: 4240000 | AA13: 1 | AB13: 96.24 | AD13: 4080.576 | AG13: שווי הוגן | AH13: 0.00848 | AI13: 0.023831499 | AJ13: 0.0043447778
... A44: 233 | B44: 233 | C44: רבוע כחול נדל"ן בע"מ | D44: 513765859 | E44: ח.פ | F44: רבוע נדלן אגח ו | G44: IL0011406076 | H44: ISIN | I44: צמוד למדד המחירים לצרכן | J44: ישראל | K44: ישראל | L44: סחיר | M44: TASE | N44: נדל"ן מניב בישראל | O44: לא | P44: AA- | Q44: S&P מעלות | R44: נייר ערך | S44: ILS | T44: 1.209 | U44: 30/11/2026 | V44: 0.0215 | W44: 0.02655 | X44: החוב לא נחות | Y44: לא | Z44: 2426974 | AA44: 1 | AB44: 117.11 | AD44: 2842.229 | AG44: שווי הוגן | AH44: 0.001237 | AI44: 0.01659927 | AJ44: 0.0030262528
A45: 233 | B45: 233 | C45: שיכון ובינוי בע"מ | D45: 520036104 | E45: ח.פ | F45: שיכון ובינוי אגח 6 | G45: IL0011297335 | H45: ISIN | I45: צמוד למדד המחירים לצרכן | J45: ישראל | K45: ישראל | L45: סחיר | M45: TASE | N45: בנייה | O45: לא | P45: A | Q45: S&P מעלות | R45: נייר ערך | S45: ILS | T45: 0.499 | U45: 01/04/2025 | V45: 0.0434 | W45: 0.03468 | X45: החוב לא נחות | Y45: לא | Z45: 656653 | AA45: 1 | AB45: 115.84 | AC45: 16.433 | AD45: 777.1 | AG45: שווי הוגן | AH45: 0.00151 | AI45: 0.0045384404 | AJ45: 0.00082741395
A46: 233 | B46: 233 | C46: שיכון ובינוי אנרגיה בע"מ | D46: 510459928 | E46: ח.פ | F46: שיכון ובינוי אנרגיה אגח א' | G46: IL0011985715 | H46: ISIN | I46: לא צמוד למדד המחירים לצרכן | J46: ישראל | K46: ישראל | L46: סחיר | M46: TASE | N46: אנרגיה | O46: לא | P46: A- | Q46: מידרוג Moodys | R46: נייר ערך | S46: ILS | T46: 4.254 | U46: 30/06/2034 | V46: 0.0677 | W46: 0.06639 | X46: החוב לא נחות | Y46: לא | Z46: 3710000 | AA46: 1 | AB46: 102.69 | AD46: 3809.799 | AG46: שווי הוגן | AH46: 0.004947 | AI46: 0.0222501 | AJ46: 0.004056469
A47: 233 | B47: 233 | C47: ש.שלמה החזקות בע"מ | D47: 520034372 | E47: ח.פ | F47: שלמה החז אגח יח | G47: IL0014103076 | H47: ISIN | I47: צמוד למדד המחירים לצרכן | J47: ישראל | K47: ישראל | L47: סחיר | M47: TASE | N47: שירותים | O47: לא | P47: AA | Q47: S&P מעלות | R47: נייר ערך | S47: ILS | T47: 0.959 | U47: 21/06/2026 | V47: 0.018 | W47: 0.02275 | X47: החוב לא נחות | Y47: לא | Z47: 1890383.3 | AA47: 1 | AB47: 115.47 | AD47: 2182.826 | AG47: שווי הוגן | AH47: 0.003325 | AI47: 0.012748202 | AJ47: 0.0023241553
A48: 233 | B48: 233 | C48: בנק הפועלים בע"מ | D48: 520000118 | E48: ח.פ | F48: BANK HAPOALIM 3.255 21.01.32 | G48: IL0066204707 | H48: ISIN | I48: צמוד למט"ח | J48: חו"ל | K48: ישראל | L48: סחיר | M48: אחר | N48: בנקים | O48: לא | P48: AAA | Q48: S&P מעלות | R48: נייר ערך | S48: USD | T48: 6.21 | U48: 21/01/2032 | V48: 0.03255 | W48: 0.06395 | X48: החוב לא נחות | Y48: לא | Z48: 2800000 | AA48: 3.71 | AB48: 92.937 | AD48: 9654.296 | AG48: שווי הוגן | AH48: 0.0028 | AI48: 0.056383299 | AJ48: 0.010279374
A49: 233 | B49: 233 | C49: בנק לאומי לישראל בע"מ | D49: 520018078 | E49: ח.פ | F49: LUMIIT 3.275 01/29/2031 | G49: IL0060404899 | H49: ISIN | I49: צמוד למט"ח | J49: חו"ל | K49: ישראל | L49: סחיר | M49: אחר | N49: בנקים | O49: לא | P49: AAA | Q49: S&P מעלות | R49: נייר ערך | S49: USD | T49: 5.494 | U49: 29/01/2031 | V49: 0.03275 | W49: 0.0602 | X49: החוב לא נחות | Y49: לא | Z49: 2700000 | AA49: 3.71 | AB49: 95.256 | AD49: 9541.794 | AG49: שווי הוגן | AH49: 0.0036 | AI49: 0.055726262 | AJ49: 0.010159588
A50: 233 | B50: 233 | C50: בנק מזרחי טפחות בע"מ | D50: 520000522 | E50: ח.פ | F50: MIZRAHIT 3.077 04/07/31 | G50: IL0069508369 | H50: ISIN | I50: צמוד למט"ח | J50: חו"ל | K50: ישראל | L50: סחיר | M50: אחר | N50: בנקים | O50: לא | P50: AAA | Q50: S&P מעלות | R50: נייר ערך | S50: USD | T50: 5.621 | U50: 07/04/2031 | V50: 0.03077 | W50: 0.06573 | X50: החוב לא נחות | Y50: לא | Z50: 600000 | AA50: 3.71 | AB50: 95.017 | AD50: 2115.078 | AG50: שווי הוגן | AH50: 0.001 | AI50: 0.012352543 | AJ50: 0.0022520217

Sheet מניות מבכ ויהש
A1: מספר קופה/קרן/ח.פ. עבור חברת ביטוח | B1: מספר מסלול | C1: שם מנפיק | D1: מספר מנפיק | E1: סוג מספר מזהה מנפיק | F1: שם נייר ערך | G1: מספר נייר ערך | H1: סוג מספר נייר ערך | I1: מאפיין עיקרי | J1: ישראל/חו"ל | K1: מדינה לפי חשיפה כלכלית | L1: סטאטוס סחירות | M1: זירת מסחר | N1: ענף מסחר | O1: בעל עניין/צד קשור | P1: מטבע פעילות | Q1: ערך נקוב (יחידות) | R1: שער חליפין | S1: שער נייר הערך | T1: סכום לקבל (במטבע הפעילות) | U1: שווי הוגן (באלפי ש"ח) | V1: שיעור מערך נקוב מונפק | W1: שיעור מנכסי אפיק ההשקעה | X1: שיעור מסך נכסי ההשקעה
A2: 233 | B2: 233 | C2: אלביט מערכות בע"מ | D2: 520043027 | E2: ח.פ | F2: אלביט מערכות | G2: IL0010811243 | H2: ISIN | I2: מניות | J2: ישראל | K2: ישראל | L2: סחיר | M2: TASE | N2: ביטחוניות | O2: לא | P2: ILS | Q2: 3867 | R2: 1 | S2: 74080 | U2: 2864.674 | V2: 8.7e-05 | W2: 0.021779243 | X2: 0.0030501503 | Y2: =(U2/R2-T2)/Q2*100000 -> 74080.01
A3: 233 | B3: 233 | C3: אלוני-חץ נכסים והשקעות בע"מ | D3: 520038506 | E3: ח.פ | F3: אלוני חץ | G3: IL0003900136 | H3: ISIN | I3: מניות | J3: ישראל | K3: ישראל | L3: סחיר | M3: TASE | N3: נדל"ן מניב בישראל | O3: לא | P3: ILS | Q3: 116736 | R3: 1 | S3: 2855 | U3: 3332.813 | V3: 0.000605 | W3: 0.025338363 | X3: 0.0035485997 | Y3: =(U3/R3-T3)/Q3*100000 -> 2855.0002
A4: 233 | B4: 233 | C4: אמות השקעות בע"מ | D4: 520026683 | E4: ח.פ | F4: אמות | G4: IL0010972789 | H4: ISIN | I4: מניות | J4: ישראל | K4: ישראל | L4: סחיר | M4: TASE | N4: נדל"ן מניב בישראל | O4: לא | P4: ILS | Q4: 62200 | R4: 1 | S4: 1609 | U4: 1000.798 | V4: 0.000132 | W4: 0.007608763 | X4: 0.0010655959 | Y4: =(U4/R4-T4)/Q4*100000 -> 1609
A5: 233 | B5: 233 | C5: אנלייט אנרגיה מתחדשת בע"מ | D5: 520041146 | E5: ח.פ | F5: אנלייט אנרגיה | G5: IL0007200111 | H5: ISIN | I5: מניות | J5: ישראל | K5: ארה"ב | L5: סחיר | M5: TASE | N5: אנרגיה מתחדשת | O5: לא | P5: ILS | Q5: 29706.1 | R5: 1 | S5: 6254 | U5: 1857.819 | V5: 0.000251 | W5: 0.014124437 | X5: 0.0019781062 | Y5: =(U5/R5-T5)/Q5*100000 -> 6253.9983
A6: 233 | B6: 233 | C6: אנרג'יקס אנרגיות מתחדשות בע"מ | D6: 513901371 | E6: ח.פ | F6: אנרג'יקס | G6: IL0011233553 | H6: ISIN | I6: מניות | J6: ישראל | K6: ישראל | L6: סחיר | M6: TASE | N6: אנרגיה מתחדשת | O6: לא | P6: ILS | Q6: 462305 | R6: 1 | S6: 1348 | U6: 6231.871 | V6: 0.000841 | W6: 0.047379024 | X6: 0.0066353614 | Y6: =(U6/R6-T6)/Q6*100000 -> 1347.9999
A7: 233 | B7: 233 | C7: אפריקה ישראל מגורים בע"מ | D7: 520034760 | E7: ח.פ | F7: אפריקה מגורים | G7: IL0010979487 | H7: ISIN | I7: מניות | J7: ישראל | K7: ישראל | L7: סחיר | M7: TASE | N7: בנייה | O7: לא | P7: ILS | Q7: 6080 | R7: 1 | S7: 24250 | U7: 1474.4 | V7: 0.000481 | W7: 0.011209415 | X7: 0.0015698618 | Y7: =(U7/R7-T7)/Q7*100000 -> 24250
A8: 233 | B8: 233 | C8: בזק החברה הישראלית לתקשורת בע"מ | D8: 520031931 | E8: ח.פ | F8: בזק | G8: IL0002300114 | H8: ISIN | I8: מניות | J8: ישראל | K8: ישראל | L8: סחיר | M8: TASE | N8: תקשורת ומדיה | O8: לא | P8: ILS | Q8: 437025 | R8: 1 | S8: 428.6 | T8: 64.26 | U8: 1937.349 | V8: 0.000158 | W8: 0.014729073 | X8: 0.0020627846 | Y8: =(U8/R8-T8)/Q8*100000 -> 428.59997
A9: 233 | B9: 233 | C9: י.ח.דמרי בניה ופיתוח בע"מ | D9: 511399388 | E9: ח.פ | F9: דמרי | G9: IL0010903156 | H9: ISIN | I9: מניות | J9: ישראל | K9: ישראל | L9: סחיר | M9: TASE | N9: בנייה | O9: לא | P9: ILS | Q9: 8346 | R9: 1 | S9: 33200 | U9: 2770.872 | V9: 0.000425 | W9: 0.021066098 | X9: 0.0029502754 | Y9: =(U9/R9-T9)/Q9*100000 -> 33200
A10: 233 | B10: 233 | C10: הפניקס אחזקות בע"מ | D10: 520017450 | E10: ח.פ | F10: הפניקס | G10: IL0007670123 | H10: ISIN | I10: מניות | J10: ישראל | K10: ישראל | L10: סחיר | M10: TASE | N10: ביטוח | O10: לא | P10: ILS | Q10: 40425 | R10: 1 | S10: 4200 | U10: 1697.85 | V10: 0.000161 | W10: 0.012908238 | X10: 0.0018077793 | Y10: =(U10/R10-T10)/Q10*100000 -> 4200
A11: 233 | B11: 233 | C11: טבע תעשיות פרמצבטיות בע"מ | D11: 520013954 | E11: ח.פ | F11: טבע | G11: IL0006290147 | H11: ISIN | I11: מניות | J11: ישראל | K11: ארה"ב | L11: סחיר | M11: TASE | N11: פארמה | O11: לא | P11: ILS | Q11: 23000 | R11: 1 | S11: 6629 | U11: 1524.67 | V11: 2e-05 | W11: 0.011591603 | X11: 0.0016233866 | Y11: =(U11/R11-T11)/Q11*100000 -> 6629
A12: 233 | B12: 233 | C12: טרמינל איקס אונליין בע"מ | D12: 515722536 | E12: ח.פ | F12: טרמינל איקס אונליין בעמ | G12: IL0011787145 | H12: ISIN | I12: מניות | J12: ישראל | K12: ישראל | L12: סחיר | M12: TASE | N12: רשתות שיווק | O12: לא | P12: ILS | Q12: 102000 | R12: 1 | S12: 332.4 | U12: 339.048 | V12: 0.000811 | W12: 0.0025776789 | X12: 0.00036100007 | Y12: =(U12/R12-T12)/Q12*100000 -> 332.4
A13: 233 | B13: 233 | C13: ישראל קנדה (ט.ר) בעמ | D13: 520039298 | E13: ח.פ | F13: ישראל קנדה | G13: IL0004340191 | H13: ISIN | I13: מניות | J13: ישראל | K13: ישראל | L13: סחיר | M13: TASE | N13: בנייה | O13: לא | P13: ILS | Q13: 170000 | R13: 1 | S13: 1373 | U13: 2334.1 | V13: 0.000527 | W13: 0.017745453 | X13: 0.0024852241 | Y13: =(U13/R13-T13)/Q13*100000 -> 1373
A14: 233 | B14: 233 | C14: כלל החזקות עסקי ביטוח בע"מ | D14: 520036120 | E14: ח.פ | F14: כלל ביטוח | G14: IL0002240146 | H14: ISIN | I14: מניות | J14: ישראל | K14: ישראל | L14: סחיר | M14: TASE | N14: ביטוח | O14: לא | P14: ILS | Q14: 15372 | R14: 1 | S14: 6329 | U14: 972.894 | V14: 0.000194 | W14: 0.0073966165 | X14: 0.0010358851 | Y14: =(U14/R14-T14)/Q14*100000 -> 6329.0008
A15: 233 | B15: 233 | C15: בנק לאומי לישראל בע"מ | D15: 520018078 | E15: ח.פ | F15: לאומי | G15: IL0006046119 | H15: ISIN | I15: מניות | J15: ישראל | K15: ישראל | L15: סחיר | M15: TASE | N15: בנקים | O15: לא | P15: ILS | Q15: 165110 | R15: 1 | S15: 3644 | U15: 6016.608 | V15: 0.000109 | W15: 0.045742445 | X15: 0.0064061609 | Y15: =(U15/R15-T15)/Q15*100000 -> 3643.9998
A16: 233 | B16: 233 | C16: בנק מזרחי טפחות בע"מ | D16: 520000522 | E16: ח.פ | F16: מזרחי טפחות | G16: IL0006954379 | H16: ISIN | I16: מניות | J16: ישראל | K16: ישראל | L16: סחיר | M16: TASE | N16: בנקים | O16: לא | P16: ILS | Q16: 29059 | R16: 1 | S16: 14550 | U16: 4228.084 | V16: 0.000112 | W16: 0.032144841 | X16: 0.0045018369 | Y16: =(U16/R16-T16)/Q16*100000 -> 14549.998
A17: 233 | B17: 233 | C17: מטריקס אי.טי בע"מ | D17: 520039413 | E17: ח.פ | F17: מטריקס | G17: IL0004450156 | H17: ISIN | I17: מניות | J17: ישראל | K17: ישראל | L17: סחיר | M17: TASE | N17: שירותי מידע | O17: לא | P17: ILS | Q17: 21808 | R17: 1 | S17: 7125 | T17: 17.883 | U17: 1571.703 | V17: 0.000343 | W17: 0.011949177 | X17: 0.0016734643 | Y17: =(U17/R17-T17)/Q17*100000 -> 7125
A18: 233 | B18: 233 | C18: מליסרון בע"מ | D18: 520037789 | E18: ח.פ | F18: מליסרון | G18: IL0003230146 | H18: ISIN | I18: מניות | J18: ישראל | K18: ישראל | L18: סחיר | M18: TASE | N18: נדל"ן מניב בישראל | O18: לא | P18: ILS | Q18: 9081 | R18: 1 | S18: 28210 | U18: 2561.75 | V18: 0.000191 | W18: 0.019476207 | X18: 0.0027276137 | Y18: =(U18/R18-T18)/Q18*100000 -> 28209.999
A19: 233 | B19: 233 | C19: מניבים קרן הריט החדשה בע"מ | D19: 515327120 | E19: ח.פ | F19: מניבים ריט | G19: IL0011405730 | H19: ISIN | I19: מניות | J19: ישראל | K19: ישראל | L19: סחיר | M19: TASE | N19: נדל"ן מניב בישראל | O19: לא | P19: ILS | Q19: 507422 | R19: 1 | S19: 177.8 | U19: 902.196 | V19: 0.00068 | W19: 0.0068591244 | X19: 0.00096061009 | Y19: =(U19/R19-T19)/Q19*100000 -> 177.79994
A20: 233 | B20: 233 | C20: ניו-מד אנרג'י- שותפות מוגבלת | D20: 550013098 | E20: מספר שותפות | F20: ניו-מד אנרג'י יהש | G20: IL0004750209 | H20: ISIN | I20: מניות | J20: ישראל | K20: ישראל | L20: סחיר | M20: TASE | N20: חיפושי נפט וגז | O20: לא | P20: ILS | Q20: 165000 | R20: 1 | S20: 1025 | U20: 1691.25 | V20: 0.000141 | W20: 0.01285806 | X20: 0.001800752 | Y20: =(U20/R20-T20)/Q20*100000 -> 1025
A21: 233 | B21: 233 | C21: נייס מערכות בע"מ | D21: 520036872 | E21: ח.פ | F21: נייס | G21: IL0002730112 | H21: ISIN | I21: מניות | J21: ישראל | K21: ארה"ב | L21: סחיר | M21: TASE | N21: תוכנה ואינטרנט | O21: לא | P21: ILS | Q21: 3756 | R21: 1 | S21: 64880 | U21: 2436.893 | V21: 6e-05 | W21: 0.018526955 | X21: 0.0025946723 | Y21: =(U21/R21-T21)/Q21*100000 -> 64880.005
A22: 233 | B22: 233 | C22: נקסט ויז'ן | D22: 514259019 | E22: ח.פ | F22: נקסט ויז'ן | G22: IL0011765935 | H22: ISIN | I22: מניות | J22: ישראל | K22: ישראל | L22: סחיר | M22: TASE | N22: אלקטרוניקה ואופטיקה | O22: לא | P22: ILS | Q22: 37000 | R22: 1 | S22: 3950 | U22: 1461.5 | V22: 0.000462 | W22: 0.01111134 | X22: 0.0015561266 | Y22: =(U22/R22-T22)/Q22*100000 -> 3950
A23: 233 | B23: 233 | C23: קבוצת עזריאלי בע"מ (לשעבר קנית מימון) | D23: 510960719 | E23: ח.פ | F23: עזריאלי קבוצה | G23: IL0011194789 | H23: ISIN | I23: מניות | J23: ישראל | K23: ישראל | L23: סחיר | M23: TASE | N23: נדל"ן מניב בישראל | O23: לא | P23: ILS | Q23: 14625 | R23: 1 | S23: 25940 | U23: 3793.725 | V23: 0.000121 | W23: 0.028842538 | X23: 0.0040393543 | Y23: =(U23/R23-T23)/Q23*100000 -> 25940
A24: 233 | B24: 233 | C24: בנק הפועלים בע"מ | D24: 520000118 | E24: ח.פ | F24: פועלים | G24: IL0006625771 | H24: ISIN | I24: מניות | J24: ישראל | K24: ישראל | L24: סחיר | M24: TASE | N24: בנקים | O24: לא | P24: ILS | Q24: 189815 | R24: 1 | S24: 3729 | U24: 7078.201 | V24: 0.000142 | W24: 0.053813414 | X24: 0.0075364879 | Y24: =(U24/R24-T24)/Q24*100000 -> 3728.9998
A25: 233 | B25: 233 | C25: פוקס-ויזל בע"מ | D25: 512157603 | E25: ח.פ | F25: פוקס- ויזל | G25: IL0010870223 | H25: ISIN | I25: מניות | J25: ישראל | K25: ישראל | L25: סחיר | M25: TASE | N25: רשתות שיווק | O25: לא | P25: ILS | Q25: 3574 | R25: 1 | S25: 28150 | U25: 1006.081 | V25: 0.000259 | W25: 0.0076489281 | X25: 0.0010712209 | Y25: =(U25/R25-T25)/Q25*100000 -> 28150
A26: 233 | B26: 233 | C26: amazon.com | D26: ZXTILKJKG63JELOEG630 | E26: LEI | F26: AMAZON COM INC | G26: US0231351067 | H26: ISIN | I26: מניות | J26: חו"ל | K26: ארה"ב | L26: סחיר | M26: NASDAQ | N26: Textiles, Apparel & Luxury Goods | O26: לא | P26: USD | Q26: 9600 | R26: 3.71 | S26: 18633 | U26: 6636.329 | V26: 1e-06 | W26: 0.050453995 | X26: 0.0070660063 | Y26: =(U26/R26-T26)/Q26*100000 -> 18632.999
A27: 233 | B27: 233 | C27: Advanced Micro Devices inc | D27: R2I72C950HOYXII45366 | E27: LEI | F27: AMD | G27: US007931078 | H27: ISIN | I27: מניות | J27: חו"ל | K27: ארה"ב | L27: סחיר | M27: NASDAQ | N27: Semiconductors & Semiconductor Equipment | O27: לא | P27: USD | Q27: 4572 | R27: 3.71 | S27: 16408 | U27: 2783.145 | V27: 4e-06 | W27: 0.021159403 | X27: 0.0029633427 | Y27: =(U27/R27-T27)/Q27*100000 -> 16408.002
A28: 233 | B28: 233 | C28: ASML HOLDING NV-NY | D28: 724500Y6DUVHQD6OXN27 | E28: LEI | F28: ASML Holding NV | G28: NL0010273215 | H28: ISIN | I28: מניות | J28: חו"ל | K28: הולנד | L28: סחיר | M28: אחר | N28: Semiconductors & Semiconductor Equipment | O28: לא | P28: EUR | Q28: 1530 | R28: 4.1524 | S28: 74560 | U28: 4736.925 | V28: 4e-06 | W28: 0.036013401 | X28: 0.0050436229 | Y28: =(U28/R28-T28)/Q28*100000 -> 74559.999
A29: 233 | B29: 233 | C29: ASML HOLDING NV-NY | D29: 724500Y6DUVHQD6OXN27 | E29: LEI | F29: ASML_ASML HOLDING NV-NY REG | G29: USN070592100 | H29: ISIN | I29: מניות | J29: חו"ל | K29: הולנד | L29: סחיר | M29: אחר | N29: Semiconductors & Semiconductor Equipment | O29: לא | P29: USD | Q29: 598 | R29: 3.71 | S29: 83325 | U29: 1848.632 | V29: 1e-06 | W29: 0.014054586 | X29: 0.0019683237 | Y29: =(U29/R29-T29)/Q29*100000 -> 83325.01
... A44: 233 | B44: 233 | C44: Wal-Mart Stores | D44: Y87794H0US1R65VBXU25 | E44: LEI | F44: WAL MART STORES INC | G44: US9311421039 | H44: ISIN | I44: מניות | J44: חו"ל | K44: ארה"ב | L44: סחיר | M44: NYSE | N44: Food & Staples Retailing Consumer Staples Distribution & Retail | O44: לא | P44: USD | Q44: 14569 | R44: 3.71 | S44: 8075 | U44: 4364.617 | V44: 2e-06 | W44: 0.03318286 | X44: 0.0046472098 | Y44: =(U44/R44-T44)/Q44*100000 -> 8074.9992

Sheet קרנות סל
A1: מספר קופה/קרן/ח.פ. עבור חברת ביטוח | B1: מספר מסלול | C1: שם מנפיק | D1: מספר מנפיק | E1: סוג מספר מזהה מנפיק | F1: שם נייר ערך | G1: מספר נייר ערך | H1: סוג מספר נייר ערך | I1: מאפיין עיקרי | J1: ישראל/חו"ל | K1: מדינה לפי חשיפה כלכלית | L1: זירת מסחר | M1: סיווג הקרן | N1: בעל עניין/צד קשור | O1: מטבע פעילות | P1: ערך נקוב (יחידות) | Q1: שער חליפין | R1: שער נייר הערך | S1: סכום לקבל (במטבע הפעילות) | T1: שווי הוגן (באלפי ש"ח) | U1: שיעור מערך נקוב מונפק | V1: שיעור מנכסי אפיק ההשקעה | W1: שיעור מסך נכסי ההשקעה
A2: 233 | B2: 233 | C2: מגדל קרנות נאמנות בע"מ | D2: 511303661 | E2: ח.פ | F2: MTF סל תא 90 | G2: IL0011502593 | H2: ISIN | I2: עוקב אחר מדדי מניות בישראל | J2: ישראל | K2: ישראל | L2: TASE | M2: מניות בישראל | N2: לא | O2: ILS | P2: 302998 | Q2: 1 | R2: 3034 | T2: 9192.959 | U2: 0.008412 | V2: 0.039846728 | W2: 0.0097881684
A3: 233 | B3: 233 | C3: הראל קרנות נאמנות בע"מ | D3: 511776783 | E3: ח.פ | F3: הראל סל תא בנקים | G3: IL0011489494 | H3: ISIN | I3: עוקב אחר מדדי מניות בישראל | J3: ישראל | K3: ישראל | L3: TASE | M3: מניות בישראל | N3: לא | O3: ILS | P3: 144122 | Q3: 1 | R3: 3960 | T3: 5707.231 | U3: 0.003195 | V3: 0.024737898 | W3: 0.0060767527
A4: 233 | B4: 233 | C4: הראל קרנות נאמנות בע"מ | D4: 511776783 | E4: ח.פ | F4: הראל סל תל בונד שקלי | G4: IL0011505232 | H4: ISIN | I4: עוקב אחר מדדים אחרים בישראל | J4: ישראל | K4: ישראל | L4: TASE | M4: אג"ח בישראל - חברות והמרה | N4: לא | O4: ILS | P4: 9890000 | Q4: 1 | R4: 389.18 | T4: 38489.902 | U4: 0.043388 | V4: 0.16683384 | W4: 0.040981977
A5: 233 | B5: 233 | C5: State Street Corp | D5: 07F5H7W3ET8ZLWNMFP29 | E5: LEI | F5: Amex tech sel indx | G5: US81369Y8030 | H5: ISIN | I5: עוקב אחר מדדי מניות בחו"ל | J5: חו"ל | K5: ארה"ב | L5: NYSE | M5: Equity Funds | N5: לא | O5: USD | P5: 7600 | Q5: 3.71 | R5: 22576 | T5: 6365.529 | U5: 2.5e-05 | V5: 0.027591279 | W5: 0.0067776727
A6: 233 | B6: 233 | C6: DEUTSCHE BANK AG | D6: 549300L70BS183Y6ML67 | E6: LEI | F6: DBX MSCI EMU 1D ETF | G6: LU0846194776 | H6: ISIN | I6: עוקב אחר מדדי מניות בחו"ל | J6: חו"ל | K6: אירופה | L6: FWB | M6: Equity Funds | N6: לא | O6: EUR | P6: 22337 | Q6: 4.1524 | R6: 5236 | T6: 4856.503 | U6: 0.000526 | V6: 0.021050431 | W6: 0.0051709431
A7: 233 | B7: 233 | C7: Global X Management Co LLc | D7: 5493003RA4QUTSYF1N15 | E7: LEI | F7: GLOBAL X CLOUD COMPUTING ETF | G7: US37954Y4420 | H7: ISIN | I7: עוקב אחר מדדי מניות בחו"ל | J7: חו"ל | K7: גלובלי | L7: NASDAQ | M7: Equity Funds | N7: לא | O7: USD | P7: 16274 | Q7: 3.71 | R7: 2055 | T7: 1240.738 | U7: 0.000426 | V7: 0.0053779576 | W7: 0.001321071
A8: 233 | B8: 233 | C8: State Street Corp | D8: 07F5H7W3ET8ZLWNMFP29 | E8: LEI | F8: INDUSTRIAL SELECT SECT FUND | G8: US81369Y7040 | H8: ISIN | I8: עוקב אחר מדדי מניות בחו"ל | J8: חו"ל | K8: ארה"ב | L8: NYSE | M8: Equity Funds | N8: לא | O8: USD | P8: 4153 | Q8: 3.71 | R8: 13544 | T8: 2086.809 | U8: 3e-05 | V8: 0.0090452404 | W8: 0.0022219224
A9: 233 | B9: 233 | C9: BlackRock Asset Managment | D9: 5493004330BCAPB3GT42 | E9: LEI | F9: ISHARES CORE S&P 500 ETF | G9: US4642872000 | H9: ISIN | I9: עוקב אחר מדדי מניות בחו"ל | J9: חו"ל | K9: ארה"ב | L9: NYSE | M9: Equity Funds | N9: לא | O9: USD | P9: 1520 | Q9: 3.71 | R9: 57682 | T9: 3252.803 | U9: 2e-06 | V9: 0.014099222 | W9: 0.00346341
A10: 233 | B10: 233 | C10: BlackRock Asset Managment | D10: 5493004330BCAPB3GT42 | E10: LEI | F10: Ishares ftse china25 | G10: US4642871846 | H10: ISIN | I10: עוקב אחר מדדי מניות בחו"ל | J10: חו"ל | K10: סין | L10: NYSE | M10: Equity Funds | N10: לא | O10: USD | P10: 23693 | Q10: 3.71 | R10: 3178 | T10: 2793.495 | U10: 0.000295 | V10: 0.012108356 | W10: 0.0029743629
A11: 233 | B11: 233 | C11: BlackRock Asset Managment | D11: 5493004330BCAPB3GT42 | E11: LEI | F11: ISHARES NASDAQ 100 ETF | G11: IE00B53SZB19 | H11: ISIN | I11: עוקב אחר מדדי מניות בחו"ל | J11: חו"ל | K11: ארה"ב | L11: LSE | M11: Equity Funds | N11: לא | O11: USD | P11: 880 | Q11: 3.71 | R11: 114192.5 | T11: 3728.157 | U11: 6.6e-05 | V11: 0.016159633 | W11: 0.0039695407
A12: 233 | B12: 233 | C12: BlackRock Asset Managment | D12: 5493004330BCAPB3GT42 | E12: LEI | F12: ITB US Equity | G12: US4642887529 | H12: ISIN | I12: עוקב אחר מדדי מניות בחו"ל | J12: חו"ל | K12: ארה"ב | L12: NYSE | M12: Equity Funds | N12: לא | O12: USD | P12: 10650 | Q12: 3.71 | R12: 12710 | T12: 5021.912 | U12: 0.00024 | V12: 0.021767392 | W12: 0.0053470613
A13: 233 | B13: 233 | C13: KRANESHARES | D13: 549300VLDRC0RUX0E553 | E13: LEI | F13: KRANESHARES CSI CHINA INTERNET | G13: US5007673065 | H13: ISIN | I13: עוקב אחר מדדי מניות בחו"ל | J13: חו"ל | K13: סין | L13: NYSE | M13: Equity Funds | N13: לא | O13: USD | P13: 44390 | Q13: 3.71 | R13: 3402 | T13: 5602.648 | U13: 0.000301 | V13: 0.024284585 | W13: 0.0059653985
... A25: 233 | B25: 233 | C25: Ubs Fund Management | D25: 549300TBYE6SH20B4I40 | E25: LEI | F25: UBS ETF B. US LIQ CORP 1-5 | G25: LU1048315086 | H25: ISIN | I25: עוקב אחר מדדים אחרים בחו"ל | J25: חו"ל | K25: ארה"ב | L25: SIX | M25: Bond/Fixed Income Funds | N25: לא | O25: USD | P25: 180000 | Q25: 3.71 | R25: 1790.9 | T25: 11959.63 | U25: 0.010651 | V25: 0.051838817 | W25: 0.012733971

Sheet קרנות נאמנות
A1: מספר קופה/קרן/ח.פ. עבור חברת ביטוח | B1: מספר מסלול | C1: שם מנפיק | D1: מספר מנפיק | E1: סוג מספר מזהה מנפיק | F1: שם נייר ערך | G1: מספר נייר ערך | H1: סוג מספר נייר ערך | I1: מאפיין עיקרי | J1: ישראל/חו"ל | K1: מדינה לפי חשיפה כלכלית | L1: סטאטוס סחירות | M1: זירת מסחר | N1: סיווג הקרן | O1: בעל עניין/צד קשור | P1: מטבע פעילות | Q1: ערך נקוב (יחידות) | R1: שער חליפין | S1: שער נייר הערך | T1: שווי הוגן (באלפי ש"ח) | U1: שיעור מערך נקוב מונפק | V1: שיעור מנכסי אפיק ההשקעה | W1: שיעור מסך נכסי ההשקעה

Sheet כתבי אופציה
A1: מספר קופה/קרן/ח.פ. עבור חברת ביטוח | B1: מספר מסלול | C1: שם מנפיק | D1: מספר מנפיק | E1: סוג מספר מזהה מנפיק | F1: שם נייר ערך | G1: מספר נייר ערך | H1: סוג מספר נייר ערך | I1: ישראל/חו"ל | J1: מדינה לפי חשיפה כלכלית | K1: סטאטוס סחירות | L1: זירת מסחר | M1: נכס בסיס (כתב אופציה) | N1: ענף מסחר | O1: תאריך פקיעה | P1: בעל עניין/צד קשור | Q1: מטבע פעילות | R1: שער מימוש | S1: יחס המרה | T1: ערך נקוב (יחידות) | U1: שער חליפין | V1: שער נייר הערך | W1: שווי הוגן (באלפי ש"ח) | X1: שיעור מנכסי אפיק ההשקעה | Y1: שיעור מסך נכסי ההשקעה

Sheet אופציות
A1: מספר קופה/קרן/ח.פ. עבור חברת ביטוח | B1: מספר מסלול | C1: שם מנפיק | D1: מספר מנפיק | E1: סוג מספר מזהה מנפיק | F1: שם נייר ערך | G1: מספר נייר ערך | H1: סוג מספר נייר ערך | I1: מאפיין עיקרי | J1: ישראל/חו"ל | K1: מדינה לפי חשיפה כלכלית | L1: זירת מסחר | M1: ענף מסחר | N1: נכס בסיס | O1: תאריך פקיעה | P1: בעל עניין/צד קשור | Q1: מטבע פעילות | R1: שער מימוש | S1: ערך נקוב (יחידות) | T1: שער חליפין | U1: שער נייר הערך | V1: שווי הוגן (באלפי ש"ח) | W1: שיעור מנכסי אפיק ההשקעה | X1: שיעור מסך נכסי ההשקעה

Sheet חוזים עתידיים
A1: מספר קופה/קרן/ח.פ. עבור חברת ביטוח | B1: מספר מסלול | C1: שם מנפיק | D1: מספר מנפיק | E1: סוג מספר מזהה מנפיק | F1: שם נייר ערך | G1: מספר נייר ערך | H1: סוג מספר נייר ערך | I1: ישראל/חו"ל | J1: מדינה לפי חשיפה כלכלית | K1: זירת מסחר | L1: נכס בסיס | M1: בעל עניין/צד קשור | N1: מטבע פעילות | O1: ערך נקוב (יחידות) | P1: שער חליפין | Q1: שער נייר הערך | R1: שווי הוגן (באלפי ש"ח) | S1: שיעור מנכסי אפיק ההשקעה | T1: שיעור מסך נכסי ההשקעה

Sheet מוצרים מובנים
A1: מספר קופה/קרן/ח.פ. עבור חברת ביטוח | B1: מספר מסלול | C1: שם מנפיק | D1: מספר מנפיק | E1: סוג מספר מזהה מנפיק | F1: שם נייר ערך | G1: מספר נייר ערך | H1: סוג מספר נייר ערך | I1: מאפיין עיקרי | J1: ישראל/חו"ל | K1: מדינה לפי חשיפה כלכלית | L1: סטאטוס סחירות | M1: זירת מסחר | N1: נכס בסיס | O1: בעל עניין/צד קשור | P1: מח"מ | Q1: שיעור ריבית | R1: תשואה לפדיון | S1: דירוג | T1: שם מדרג | U1: דירוג נייר הערך/המנפיק | V1: מטבע פעילות | W1: ערך נקוב (יחידות) | X1: שער חליפין | Y1: שער נייר הערך | Z1: שווי הוגן (באלפי ש"ח) | AA1: שיעור מנכסי אפיק ההשקעה | AB1: שיעור מסך נכסי ההשקעה

Sheet לא סחיר איגרות חוב ממשלתיות
A1: מספר קופה/קרן/ח.פ. עבור חברת ביטוח | B1: מספר מסלול | C1: שם מנפיק | D1: שם נייר ערך | E1: מספר נייר ערך | F1: סוג מספר נייר ערך | G1: מאפיין עיקרי | H1: ישראל/חו"ל | I1: מדינה לפי חשיפה כלכלית | J1: תאריך רכישה | K1: דירוג | L1: שם מדרג | M1: מטבע פעילות | N1: מח"מ | O1: מועד פדיון | P1: שיעור ריבית | Q1: תשואה לפדיון | R1: ערך נקוב (יחידות) | S1: שער חליפין | T1: שער נייר הערך | U1: שווי הוגן (באלפי ש"ח) | V1: עלות מופחתת (באלפי ש"ח) | W1: השיטה שיושמה בדוח הכספי | X1: שיעור מנכסי אפיק ההשקעה | Y1: שיעור מסך נכסי ההשקעה

Sheet לא סחיר איגרות חוב מיועדות
A1: מספר קופה/קרן/ח.פ. עבור חברת ביטוח | B1: מספר מסלול | C1: מאפיין עיקרי | D1: שם נייר ערך | E1: מספר נייר ערך | F1: תאריך רכישה | G1: מח"מ | H1: סוג הצמדה | I1: מועד פדיון | J1: שיעור ריבית | K1: תשואה לפדיון | L1: ערך נקוב (יחידות) | M1: שער נייר הערך | N1: שווי הוגן (באלפי ש"ח) | O1: עלות מופחתת (באלפי ש"ח) | P1: השיטה שיושמה בדוח הכספי | Q1: שיעור מנכסי אפיק ההשקעה | R1: שיעור מסך נכסי ההשקעה

Sheet אפיק השקעה מובטח תשואה
A1: מספר קרן | B1: מספר מסלול | C1: מאפיין עיקרי | D1: חודש הנפקת שכבה | E1: חודש הבדיקה | F1: שווי הנכסים באפיק (באלפי ש"ח) | G1: שיעור מסך נכסי ההשקעה

Sheet לא סחיר ניירות ערך מסחריים
A1: מספר קופה/קרן/ח.פ. עבור חברת ביטוח | B1: מספר מסלול | C1: שם מנפיק | D1: מספר מנפיק | E1: סוג מספר מזהה מנפיק | F1: שם נייר ערך | G1: מספר נייר ערך | H1: סוג מספר נייר ערך | I1: מאפיין עיקרי | J1: ישראל/חו"ל | K1: מדינה לפי חשיפה כלכלית | L1: ענף מסחר | M1: בעל עניין/צד קשור | N1: תאריך רכישה | O1: דירוג | P1: שם מדרג | Q1: דירוג נייר הערך/המנפיק | R1: מטבע פעילות | S1: מח"מ | T1: סוג הצמדה | U1: ריבית עוגן | V1: מועד פדיון | W1: שיעור ריבית | X1: תשואה לפדיון | Y1: נחיתות חוזית | Z1: האם סווג כחוב בעייתי | AA1: סוג גורם משערך | AB1: תלות/אי-תלות המשערך | AC1: שם גורם משערך | AD1: תאריך שערוך אחרון | AE1: תאריך אחרון בו נבחנה בפועל ירידת ערך | AF1: ערך נקוב (יחידות) | AG1: שער חליפין | AH1: שער נייר הערך | AI1: שווי הוגן (באלפי ש"ח) | AJ1: עלות מופחתת (באלפי ש"ח) | AK1: עלות מופחתת (במטבע הפעילות) | AL1: השיטה שיושמה בדוח הכספי | AM1: שיעור מנכסי אפיק ההשקעה | AN1: שיעור מסך נכסי ההשקעה

Sheet לא סחיר איגרות חוב
A1: מספר קופה/קרן/ח.פ. עבור חברת ביטוח | B1: מספר מסלול | C1: שם מנפיק | D1: מספר מנפיק | E1: סוג מספר מזהה מנפיק | F1: שם נייר ערך | G1: מספר נייר ערך | H1: סוג מספר נייר ערך | I1: מאפיין עיקרי | J1: ישראל/חו"ל | K1: מדינה לפי חשיפה כלכלית | L1: סטאטוס סחירות | M1: ענף מסחר | N1: בעל עניין/צד קשור | O1: תאריך רכישה | P1: דירוג | Q1: שם מדרג | R1: דירוג נייר הערך/המנפיק | S1: מטבע פעילות | T1: מח"מ | U1: מועד פדיון | V1: תשואה לפדיון | W1: שיעור ריבית | X1: נחיתות חוזית | Y1: האם סווג כחוב בעייתי | Z1: סוג גורם משערך | AA1: תלות/אי-תלות המשערך | AB1: תאריך שערוך אחרון | AC1: תאריך אחרון בו נבחנה בפועל ירידת ערך | AD1: ערך נקוב (יחידות) | AE1: שער חליפין | AF1: שער נייר הערך | AG1: שווי הוגן (באלפי ש"ח) | AH1: עלות מופחתת (באלפי ש"ח) | AI1: עלות מופחתת (במטבע הפעילות) | AJ1: השיטה שיושמה בדוח הכספי | AK1: שיעור מנכסי אפיק ההשקעה | AL1: שיעור מסך נכסי ההשקעה
A2: 233 | B2: 233 | C2: אלון חברת הדלק לישראל בע"מ | D2: 520041690 | E2: ח.פ | F2: אלון חברת הדלק אגח סד' א דיסקונט | G2: IL0011015679 | H2: ISIN | I2: צמוד למדד המחירים לצרכן | J2: ישראל | K2: ישראל | L2: אחר | M2: השקעה ואחזקות | N2: לא | O2: 01/01/2018 | P2: N/R | Q2: NR | R2: NR | S2: ILS | T2: 2.47 | U2: 30/06/2025 | V2: 0.0001 | W2: 0.0535 | X2: החוב נחות | Y2: כן | Z2: גורם תלוי/פנימי | AA2: קיימת תלות | AB2: 30/09/2024 | AD2: 626824.15 | AE2: 1 | AF2: 15.31 | AG2: 95.967 | AJ2: שווי הוגן | AK2: 0.0088310646 | AL2: 0.00010218026
A3: 233 | B3: 233 | C3: אמפל-אמריקן ישראל קורפוריישן | D3: 130435685 | E3: מספר תאגיד או שותפות בחו"ל | F3: אמפל אמריקן אגח ב (מחוקה ) | G3: IL0011103780 | H3: ISIN | I3: אחר | J3: ישראל | K3: ישראל | L3: אחר | M3: השקעה ואחזקות | N3: לא | O3: 01/01/2018 | P3: N/R | Q3: NR | R3: NR | S3: ILS | T3: 0.01 | U3: 31/12/2022 | V3: 0 | W3: 0.066 | X3: החוב נחות | Y3: כן | Z3: גורם תלוי/פנימי | AA3: קיימת תלות | AB3: 04/05/2018 | AD3: 135000 | AE3: 1 | AF3: 0 | AG3: 0 | AJ3: שווי הוגן | AK3: 1.2422984e-10 | AL3: 1.4374074e-12
A4: 233 | B4: 233 | C4: אמפל-אמריקן ישראל קורפוריישן | D4: 130435685 | E4: מספר תאגיד או שותפות בחו"ל | F4: אמפל אמריקן אגח ב חש 1/12 | G4: IL0011103780 | H4: ISIN | I4: אחר | J4: ישראל | K4: ישראל | L4: אחר | M4: השקעה ואחזקות | N4: לא | O4: 01/01/2018 | P4: N/R | Q4: NR | R4: NR | S4: ILS | T4: 0.01 | U4: 31/12/2022 | V4: 0 | W4: 0.066 | X4: החוב נחות | Y4: כן | Z4: גורם תלוי/פנימי | AA4: קיימת תלות | AB4: 04/05/2018 | AD4: 135000 | AE4: 1 | AF4: 0 | AG4: 0 | AJ4: שווי הוגן | AK4: 1.2422984e-10 | AL4: 1.4374074e-12
A5: 233 | B5: 233 | C5: אמפל-אמריקן ישראל קורפוריישן | D5: 130435685 | E5: מספר תאגיד או שותפות בחו"ל | F5: אמפל אמריקן חש 01/13 | G5: IL0011103780 | H5: ISIN | I5: אחר | J5: ישראל | K5: ישראל | L5: אחר | M5: השקעה ואחזקות | N5: לא | O5: 01/01/2018 | P5: N/R | Q5: NR | R5: NR | S5: ILS | T5: 0.01 | U5: 31/12/2022 | V5: 0 | W5: 0.066 | X5: החוב נחות | Y5: כן | Z5: גורם תלוי/פנימי | AA5: קיימת תלות | AB5: 28/03/2018 | AD5: 135000 | AE5: 1 | AF5: 0 | AG5: 0 | AJ5: שווי הוגן | AK5: 1.2422984e-10 | AL5: 1.4374074e-12
A6: 233 | B6: 233 | C6: אמפל-אמריקן ישראל קורפוריישן | D6: 130435685 | E6: מספר תאגיד או שותפות בחו"ל | F6: אמפל אמריקן חש 01/14 | G6: IL0011103780 | H6: ISIN | I6: אחר | J6: ישראל | K6: ישראל | L6: אחר | M6: השקעה ואחזקות | N6: לא | O6: 01/01/2018 | P6: N/R | Q6: NR | R6: NR | S6: ILS | T6: 0.01 | U6: 31/12/2022 | V6: 0 | W6: 0.066 | X6: החוב נחות | Y6: כן | Z6: גורם תלוי/פנימי | AA6: קיימת תלות | AB6: 04/05/2018 | AD6: 135000 | AE6: 1 | AF6: 0 | AG6: 0 | AJ6: שווי הוגן | AK6: 1.2422984e-10 | AL6: 1.4374074e-12
A7: 233 | B7: 233 | C7: אמפל-אמריקן ישראל קורפוריישן | D7: 130435685 | E7: מספר תאגיד או שותפות בחו"ל | F7: אמפל אמריקן חש 1/15 | G7: IL0011103780 | H7: ISIN | I7: אחר | J7: ישראל | K7: ישראל | L7: אחר | M7: השקעה ואחזקות | N7: לא | O7: 01/01/2018 | P7: N/R | Q7: NR | R7: NR | S7: ILS | T7: 0.01 | U7: 31/12/2022 | V7: 0 | W7: 0.066 | X7: החוב נחות | Y7: כן | Z7: גורם תלוי/פנימי | AA7: קיימת תלות | AB7: 28/03/2018 | AD7: 135000 | AE7: 1 | AF7: 0 | AG7: 0 | AJ7: שווי הוגן | AK7: 1.2422984e-10 | AL7: 1.4374074e-12
A8: 233 | B8: 233 | C8: בולוס גד תיירות ומלונאות בע"מ | D8: 512559824 | E8: ח.פ | F8: בולוס גד תיירות אג"ח מחוקה | G8: IL0010851173 | H8: ISIN | I8: אחר | J8: ישראל | K8: ישראל | L8: אחר | M8: מלונאות ותיירות | N8: לא | O8: 01/01/2018 | P8: N/R | Q8: NR | R8: NR | S8: ILS | T8: 0 | U8: 05/05/2008 | V8: 0 | W8: 0 | X8: החוב לא נחות | Y8: כן | Z8: אחר | AA8: אי תלות | AB8: 15/03/2018 | AD8: 44213.79 | AE8: 1 | AF8: 0 | AG8: 0 | AJ8: שווי הוגן | AK8: 4.0686459e-09 | AL8: 4.7076465e-11
A9: 233 | B9: 233 | C9: בולוס גד תיירות ומלונאות בע"מ | D9: 512559824 | E9: ח.פ | F9: בולוס גד תיירות ומלונאות אג"ח(מחוקה) | G9: il1087816 | H9: ISIN | I9: אחר | J9: ישראל | K9: ישראל | L9: אחר | M9: מלונאות ותיירות | N9: לא | O9: 01/01/2018 | P9: N/R | Q9: NR | R9: NR | S9: ILS | T9: 0.01 | U9: 30/12/2021 | V9: 0.0001 | W9: 0 | X9: החוב לא נחות | Y9: כן | Z9: אחר | AA9: אי תלות | AB9: 31/08/2020 | AD9: 8842.75 | AE9: 1 | AF9: 0 | AG9: 0 | AJ9: שווי הוגן | AK9: 8.1372844e-12 | AL9: 9.4152844e-14
A10: 233 | B10: 233 | C10: בסר לאס וגאס | D10: 513751610 | E10: ח.פ | F10: בסר לאס וגס סידרה 1 | G10: 800068835 | H10: פנימי | I10: אחר | J10: ישראל | K10: ישראל | L10: אחר | M10: אחר | N10: לא | O10: 10/02/2019 | P10: N/R | Q10: NR | R10: NR | S10: ILS | T10: 0.01 | U10: 30/09/2008 | V10: 0.0001 | W10: 0 | X10: החוב נחות | Y10: כן | Z10: אחר | AA10: אי תלות | AB10: 31/10/2017 | AD10: 4000000 | AE10: 1 | AF10: 0 | AG10: 0 | AJ10: שווי הוגן | AK10: 3.6808841e-09 | AL10: 4.2589848e-11
A11: 233 | B11: 233 | C11: קאר אנד גו (סדרה א) בע"מ | D11: 513406835 | E11: ח.פ | F11: מחוקה _קאר אנד גו %7.4 (חודשי+קרן) 07 | G11: IL0010882020 | H11: ISIN | I11: אחר | J11: ישראל | K11: ישראל | L11: אחר | M11: שירותים | N11: לא | O11: 01/01/2018 | P11: N/R | Q11: NR | R11: NR | S11: ILS | T11: 0.01 | U11: 10/08/2007 | V11: 0.0001 | W11: 0.074 | X11: החוב נחות | Y11: כן | Z11: אחר | AA11: אי תלות | AB11: 28/12/2014 | AD11: 44577.13 | AE11: 1 | AF11: 0 | AG11: 0 | AJ11: שווי הוגן | AK11: 4.1020812e-09 | AL11: 4.746333e-11
A12: 233 | B12: 233 | C12: בנק לאומי לישראל בע"מ | D12: 520018078 | E12: ח.פ | F12: בנק לאומי ש.ה 6.6% | G12: 80006929 | H12: פנימי | I12: צמוד למדד המחירים לצרכן | J12: ישראל | K12: ישראל | L12: אחר | M12: בנקים | N12: לא | O12: 23/01/2019 | P12: AA | Q12: S&P מעלות | R12: נייר ערך | S12: ILS | T12: 1.26 | U12: 24/01/2027 | V12: 0.02256 | W12: 0.066 | X12: החוב לא נחות | Y12: לא | Z12: חברת ציטוט | AA12: אי תלות | AB12: 30/09/2024 | AD12: 300000 | AE12: 1 | AF12: 155.29 | AG12: 465.87 | AJ12: שווי הוגן | AK12: 0.042870337 | AL12: 0.00049603331
A13: 233 | B13: 233 | C13: דרך ארץ הייווייז (1997) בע"מ | D13: 512475203 | E13: ח.פ | F13: דרך ארץ א מאוחדת A2 | G13: 800068801 | H13: פנימי | I13: צמוד למדד המחירים לצרכן | J13: ישראל | K13: ישראל | L13: אחר | M13: שירותים | N13: לא | O13: 03/12/2017 | P13: AA | Q13: S&P מעלות | R13: נייר ערך | S13: ILS | T13: 1.45 | U13: 30/06/2027 | V13: 0.0211 | W13: 0.051695 | X13: החוב לא נחות | Y13: לא | Z13: חברת ציטוט | AA13: אי תלות | AB13: 30/09/2024 | AD13: 6593587.3 | AE13: 1 | AF13: 156.29 | AG13: 10305.118 | AJ13: שווי הוגן | AK13: 0.94829859 | AL13: 0.010972335

Sheet לא סחיר מניות מבכ ויהש
A1: מספר קופה/קרן/ח.פ. עבור חברת ביטוח | B1: מספר מסלול | C1: שם מנפיק | D1: מספר מנפיק | E1: סוג מספר מזהה מנפיק | F1: שם נייר ערך | G1: מספר נייר ערך | H1: סוג מספר נייר ערך | I1: מאפיין עיקרי | J1: ישראל/חו"ל | K1: מדינה לפי חשיפה כלכלית | L1: סטאטוס סחירות | M1: ענף מסחר | N1: בעל עניין/צד קשור | O1: תאריך רכישה | P1: מטבע פעילות | Q1: סוג גורם משערך | R1: תלות/אי-תלות המשערך | S1: תאריך שערוך אחרון | T1: תאריך אחרון בו נבחנה בפועל ירידת ערך | U1: ערך נקוב (יחידות) | V1: שער חליפין | W1: שער נייר הערך | X1: שווי הוגן (באלפי ש"ח) | Y1: שיעור מנכסי אפיק ההשקעה | Z1: שיעור מסך נכסי ההשקעה
A2: 233 | B2: 233 | C2: בוימלגרין קפיטל בע"מ | D2: 520038555 | E2: ח.פ | F2: בוימלגרין | G2: IL0004020165 | H2: ISIN | I2: מניות לא סחירות | J2: ישראל | K2: ישראל | L2: אחר | M2: השקעה ואחזקות | N2: לא | O2: 40917 | P2: ILS | Q2: אחר | R2: אי-תלות | S2: 19/10/2021 | U2: 81826 | V2: 1 | W2: 0 | X2: 0 | Y2: 1 | Z2: 8.7123922e-13

Sheet קרנות השקעה
A1: מספר קופה/קרן/ח.פ. עבור חברת ביטוח | B1: מספר מסלול | C1: שם שותף כללי קרן השקעות | D1: מספר מזהה שותף כללי קרן השקעות | E1: סוג מספר מזהה שותף כללי קרן השקעות | F1: שם קרן השקעה | G1: מספר מזהה קרן השקעה | H1: סוג מספר מזהה קרן השקעות | I1: מאפיין עיקרי | J1: אסטרטגיית קרן ההשקעה | K1: ישראל/חו"ל | L1: מדינת התאגדות קרן השקעה | M1: מיקום משרד השותף הכללי | N1: מדינה לפי חשיפה כלכלית | O1: בעל עניין/צד קשור | P1: תאריך רכישה | Q1: מטבע פעילות | R1: סוג גורם משערך | S1: תלות/אי-תלות המשערך | T1: תאריך שערוך אחרון | U1: שער חליפין | V1: NAV (במטבע הדיווח של קרן ההשקעה) | W1: שווי הוגן (באלפי ש"ח) | X1: שיעור החזקה בקרן השקעה | Y1: שיעור מנכסי אפיק ההשקעה | Z1: שיעור מסך נכסי ההשקעה
A2: 233 | B2: 233 | C2: Fimi Israel Opportunity | D2: 530278548 | E2: מספר שותפות | F2: Fimi Apportunity 7 l.p | G2: 29994282 | H2: פנימי | I2: פרייבט אקוויטי | J2: Co-Investment/Direct | K2: ישראל | L2: ישראל | M2: כתובת: יגאל אלון 94 , תל אביב | N2: ישראל | O2: לא | P2: 31/05/2021 | Q2: USD | R2: אחר | S2: אי-תלות | T2: 08/09/2024 | U2: 3.71 | V2: 2580.214 | W2: 9572.594 | X2: 0.007228 | Y2: 0.09994819 | Z2: 0.010192383
A3: 233 | B3: 233 | C3: IGP | D3: 540281839 | E3: מספר שותפות | F3: IGP Investments II | G3: 8917762 | H3: פנימי | I3: פרייבט אקוויטי | J3: Value Added Infrastructure | K3: ישראל | L3: ישראל | M3: כתובת: אריק איינשטיין 3 , הרצליה | N3: ישראל | O3: לא | P3: 19/07/2018 | Q3: USD | R3: אחר | S3: אי-תלות | T3: 08/09/2024 | U3: 3.71 | V3: 2465.494 | W3: 9146.983 | X3: 0.013374 | Y3: 0.095504351 | Z3: 0.009739215
A4: 233 | B4: 233 | C4: קומרה קפיטל | D4: 540310885 | E4: מספר שותפות | F4: Qumra Capital | G4: 8917764 | H4: פנימי | I4: פרייבט אקוויטי | J4: Value Added Infrastructure | K4: ישראל | L4: ישראל | M4: כתובת: הנביאים 4 , תל אביב | N4: ישראל | O4: לא | P4: 07/03/2021 | Q4: USD | R4: אחר | S4: אי-תלות | T4: 29/07/2024 | U4: 3.71 | V4: 800.612 | W4: 2970.27 | X4: 0.007477 | Y4: 0.031012823 | Z4: 0.0031625842
A5: 233 | B5: 233 | C5: Vertex 2 Fund | D5: 27370 | E5: פנימי | F5: Vertex II Fund | G5: 892162703 | H5: פנימי | I5: פרייבט אקוויטי | J5: Other | K5: ישראל | N5: ישראל | O5: לא | P5: 10/02/2019 | Q5: USD | R5: אחר | S5: אי-תלות | T5: 15/04/2019 | U5: 3.71 | V5: 0 | W5: 0 | X5: 0 | Y5: 3.8736396e-10 | Z5: 3.9502084e-11
A6: 233 | B6: 233 | C6: Vertex | D6: 540283272 | E6: מספר שותפות | F6: Vertex VI Fund | G6: 800070395 | H6: פנימי | I6: פרייבט אקוויטי | J6: Co-Investment/Direct | K6: חו"ל | L6: ישראל | M6: כתובת: השיקמה 1 , סביון | N6: ישראל | O6: לא | P6: 04/01/2021 | Q6: USD | R6: אחר | S6: אי-תלות | T6: 30/09/2024 | U6: 3.71 | V6: 1383.002 | W6: 5130.937 | X6: 0.009065 | Y6: 0.053572513 | Z6: 0.0054631461
A7: 233 | B7: 233 | C7: ויטהלייף | D7: 550226906 | E7: מספר שותפות | F7: VITALIFE | G7: 800070385 | H7: פנימי | I7: פרייבט אקוויטי | J7: Value Added Infrastructure | K7: חו"ל | L7: ישראל | M7: כתובת: הברזל 32 , רמת החייל , תל אביב | N7: ישראל | O7: כן | P7: 10/02/2019 | Q7: USD | R7: אחר | S7: אי-תלות | T7: 15/12/2020 | U7: 3.71 | V7: 6.029 | W7: 22.368 | X7: 0 | Y7: 0.00023354173 | Z7: 2.3815806e-05
A8: 233 | B8: 233 | C8: גולדן גייט קרן הון סיכון ב | D8: 512875410 | E8: ח.פ | F8: גולדן גייט | G8: 800069247 | H8: פנימי | I8: פרייבט אקוויטי | J8: Other | K8: ישראל | N8: ישראל | O8: כן | P8: 10/02/2019 | Q8: USD | R8: אחר | S8: אי-תלות | T8: 31/10/2017 | U8: 3.71 | V8: 0 | W8: 0 | X8: 0 | Y8: 1.8648767e-10 | Z8: 1.901739e-11
A9: 233 | B9: 233 | C9: aMoon | D9: 540278827 | E9: מספר שותפות | F9: Amoon 2 Fund L.p | G9: 8917763 | H9: פנימי | I9: פרייבט אקוויטי | J9: Other | K9: חו"ל | L9: ישראל | M9: כתובת: שד' ירושלים 34, רעננה | N9: ישראל | O9: לא | P9: 20/03/2019 | Q9: USD | R9: אחר | S9: אי-תלות | T9: 15/08/2024 | U9: 3.71 | V9: 1389.723 | W9: 5155.872 | X9: 0.005869 | Y9: 0.05383286 | Z9: 0.0054896954
A10: 233 | B10: 233 | C10: Electra | D10: 89410 | E10: פנימי | F10: Electra Capital PM II Feeder 3 | G10: 865637 | H10: פנימי | I10: קרן חוב | J10: Mezzanine Debt | K10: חו"ל | L10: איי קיימן | M10: Address: 4890 West Kennedy blvd. Tampa, FL 33609 USA | N10: ארה"ב | O10: לא | P10: 29/12/2022 | Q10: USD | R10: אחר | S10: אי-תלות | T10: 11/09/2024 | U10: 3.71 | V10: 2521.756 | W10: 9355.715 | X10: 0.039311 | Y10: 0.097683737 | Z10: 0.0099614616
