Workbook
Name Additional_Factor: 'אפשרויות בחירה'!$C$701:$C$850
Name Amoritization: 'אפשרויות בחירה'!$C$546:$C$550
Name Capsule: 'אפשרויות בחירה'!$C$926:$C$928
Name Company_Name: 'File Name Info'!$A$34:$A$120
Name Company_Name_ID: 'File Name Info'!$A$34:$B$120
Name Consortium: 'אפשרויות בחירה'!$C$514:$C$515
Name Country_list: 'אפשרויות בחירה'!$C$4:$C$85
Name Country_list_funds: 'אפשרויות בחירה'!$C$4:$C$103
Name CSA: 'אפשרויות בחירה'!$C$688:$C$689
Name Delivery: 'אפשרויות בחירה'!$C$666:$C$667
Name Dependence_Independence: 'אפשרויות בחירה'!$C$654:$C$655
Name Duration_Underlying_Interest_Rate: 'אפשרויות בחירה'!$C$680:$C$687
Name File_Type: 'File Name Info'!$A$10:$A$12
Name Full_File_Type: 'File Name Info'!$A$11:$B$13
Name Full_Type: 'File Name Info'!$A$2:$B$8
Name Full_Type_Nostro: 'File Name Info'!$A$3:$B$6
Name Full_Year: 'File Name Info'!$A$22:$B$31
Name Fund_Strategy: 'אפשרויות בחירה'!$C$597:$C$621
Name Fund_type: 'אפשרויות בחירה'!$C$328:$C$498
Name Holding_interest: 'אפשרויות בחירה'!$C$146:$C$147
Name In_the_books: 'אפשרויות בחירה'!$C$656:$C$657
Name Industry_Sector: 'אפשרויות בחירה'!$C$1129:$C$1245
Name Industry_sector_all: 'אפשרויות בחירה'!$C$202:$C$327
Name Industry_sectors: 'אפשרויות בחירה'!$C$202:$C$327
Name israel_abroad: 'אפשרויות בחירה'!$C$2:$C$3
Name Issuer_Number_Banks: 'אפשרויות בחירה'!$C$111:$C$113
Name Issuer_Number_Fund: 'אפשרויות בחירה'!$C$114:$C$117
Name issuer_number_loan: 'אפשרויות בחירה'!$C$118:$C$126
Name Issuer_Number_Type: 'אפשרויות בחירה'!$C$104:$C$110
Name Issuer_Number_Type_2: 'אפשרויות בחירה'!$C$1076:$C$1079
Name Issuer_Number_Type_3: 'אפשרויות בחירה'!$C$1081:$C$1085
Name Issuer_Number_Type_V2: 'אפשרויות בחירה'!$C$104:$C$110
Name Issuer_Type_TFunds: 'אפשרויות בחירה'!$C$1087:$C$1089
Name Leading_factor: 'אפשרויות בחירה'!$C$692:$C$700
Name Linked_Type: 'אפשרויות בחירה'!$C$516:$C$519
Name other_investments: 'אפשרויות בחירה'!$C$1000:$C$1033
Name Penalty: 'אפשרויות בחירה'!$C$851:$C$852
Name QTR: 'File Name Info'!$A$15:$A$19
Name Rating_Agency: 'אפשרויות בחירה'!$C$188:$C$201
Name real_estate_lifestage: 'אפשרויות בחירה'!$C$634:$C$642
Name real_estate_loans: 'אפשרויות בחירה'!$C$553:$C$591
Name Real_Estate_Main_Use: 'אפשרויות בחירה'!$C$622:$C$633
Name Recourse_Nonrecourse: 'אפשרויות בחירה'!$C$544:$C$545
Name Repayment_Rights: 'אפשרויות בחירה'!$C$551:$C$552
Name Reset_frequency: 'אפשרויות בחירה'!$C$658:$C$665
Name Security_ID_Number_Type: 'אפשרויות בחירה'!$C$1113:$C$1116
Name Security_Number_Loans: 'אפשרויות בחירה'!$C$131
Name Stock_Exchange: 'אפשרויות בחירה'!$C$1283:$C$1315
Name Stock_Exchange_Gov_Bonds: 'אפשרויות בחירה'!$C$148:$C$181
Name Subordination_Risk: 'אפשרויות בחירה'!$C$186:$C$187
Name Tradeable_Status: 'אפשרויות בחירה'!$C$1272:$C$1281
Name Tradeable_Status_All: 'אפשרויות בחירה'!$C$135:$C$145
Name tradeable_status_bonds: 'אפשרויות בחירה'!$C$1248:$C$1253
Name tradeable_status_funds: 'אפשרויות בחירה'!$C$1118:$C$1119
Name tradeable_status_stock: 'אפשרויות בחירה'!$C$1255:$C$1259
Name Tradeable_Status_v2: 'אפשרויות בחירה'!$C$1121:$C$1126
Name tradeable_status_warrants: 'אפשרויות בחירה'!$C$1261:$C$1265
Name tradeable_status_warrants_v2: 'אפשרויות בחירה'!$C$1267:$C$1269
Name Transaction: 'אפשרויות בחירה'!$C$643:$C$646
Name Type: 'File Name Info'!$A$2:$A$8

Sheet עמוד פתיחה
A1: קובץ דיווח עבור רשימת נכסים ברמת הנכס הבודד (חוזר גופים מוסדיים 2015-9-14)
A3: יש לבחור תחום: | D3: נכסי עמיתים - קופות גמל
A5: האם מדובר בקובץ לממומנה או לציבור: | D5: לממונה
A7: יש לבחור את רבעון הדיווח: | D7: 03
A9: יש לבחור את שנת הדיווח: | D9: 2024
A11: יש לבחור את הגוף המוסדי: | D11: סלייס גמל בע"מ
A13: ח.פ. הגוף המוסדי: | D13: =IFERROR(VLOOKUP(D11,'File Name Info'!A35:B121,2,0),"תא מחושב") -> 514767490
A15: שם קובץ לשמירה | D15: =IF(D5="לממונה",CONCATENATE(D13, "_",VLOOKUP(D3,Full_Type,2,0),"_",D7,VLOOKUP(D9,Full_Year,2,0),".xlxs"),IF(D5="לציבור",CONCATENATE(D13,"_",VLOOKUP(D3,Full_Type_Nostro,2,0),"_",VLOOKUP(D5,Full_File_Type,2,0),"_",D7,VLOOKUP(D9,Full_Year,2,0),".xlsx"),"שם קובץ לשמירה")) -> 514767490_gm_0324.xlxs
A17: פרטי האחראי על הדיווח בגוף המוסדי | B17: שם: | D17: אפרת ריינהרדט
B19: מספר טלפון:
B21: כתובת מייל: | D21: efrat@slice.co.il
A23: הוראות למילוי הדיווח: | D23: יש לדווח לפי ההנחיות בחלק ג' לנספח 5.4.3.2 שבפרק 3 שבחלק 4 לשער 5 בחוזר המאוחד - "רשימת נכסים ברמת הנכס הבודד".

Sheet סכום נכסים
C1: ידווח בקבצי נכסי הנוסטרו בלבד
B2: שווי הוגן | C2: עלות מופחתת | D2: השיטה שיושמה בדוח הכספי | E2: שיעור מסך נכסי השקעה
A3: מזומנים ושווי מזומנים | B3: =SUM('מזומנים ושווי מזומנים'!$O:$O) -> 127965.22 | D3: שווי הוגן | E3: =+B3/$B$30 -> 0.10969785
A4: איגרות חוב ממשלתיות | B4: =SUM('איגרות חוב ממשלתיות'!U:U) -> 254163.79 | D4: שווי הוגן | E4: =+B4/$B$30 -> 0.21788124
A5: ניירות ערך מסחריים | E5: =+B5/$B$30 -> 0
A6: איגרות חוב | E6: =+B6/$B$30 -> 0
A7: מניות, מניות בכורה ויחידות השתתפות | B7: =SUM('מניות מבכ ויהש'!U:U) -> 23153.063 | D7: שווי הוגן | E7: =+B7/$B$30 -> 0.019847902
A8: קרנות סל | B8: =SUM('קרנות סל'!T:T) -> 493851.76 | D8: שווי הוגן | E8: =+B8/$B$30 -> 0.42335312
A9: קרנות נאמנות | B9: =SUM('קרנות נאמנות'!T:T) -> 82248.895 | D9: שווי הוגן | E9: =+B9/$B$30 -> 0.070507648
A10: כתבי אופציה | E10: =+B10/$B$30 -> 0
A11: אופציות | E11: =+B11/$B$30 -> 0
A12: חוזים עתידיים | E12: =+B12/$B$30 -> 0
A13: מוצרים מובנים | E13: =+B13/$B$30 -> 0
A14: לא סחיר איגרות חוב ממשלתיות | E14: =+B14/$B$30 -> 0
A15: לא סחיר איגרות חוב מיועדות | E15: =+B15/$B$30 -> 0
A16: אפיק השקעה מובטח תשואה | E16: =+B16/$B$30 -> 0
A17: לא סחיר ניירות ערך מסחריים | E17: =+B17/$B$30 -> 0
A18: לא סחיר איגרות חוב | E18: =+B18/$B$30 -> 0
A19: לא סחיר מניות, מניות בכורה ויחידות השתתפות | E19: =+B19/$B$30 -> 0
A20: קרנות השקעה | B20: =SUM('קרנות השקעה'!W:W) -> 141585.03 | D20: שווי הוגן | E20: =+B20/$B$30 -> 0.12137339
A21: לא סחיר כתבי אופציה | E21: =+B21/$B$30 -> 0
A22: לא סחיר אופציות | E22: =+B22/$B$30 -> 0
A23: לא סחיר נגזרים אחרים | B23: =SUM('לא סחיר נגזרים אחרים'!R:R) -> 1058.4248 | D23: שווי הוגן | E23: =+B23/$B$30 -> 0.00090733188
A24: הלוואות | B24: =SUM(הלוואות!AT:AT) -> 42498.266 | D24: שווי הוגן | E24: =+B24/$B$30 -> 0.036431527
A25: לא סחיר מוצרים מובנים | E25: =+B25/$B$30 -> 0
A26: פיקדונות מעל 3 חודשים | E26: =+B26/$B$30 -> 0
A27: זכויות מקרקעין | E27: =+B27/$B$30 -> 0
A28: השקעה בחברות מוחזקות | E28: =+B28/$B$30 -> 0
A29: נכסים אחרים | E29: =+B29/$B$30 -> 0
A30: סך הכל נכסים | B30: =SUM(B3:B29) -> 1166524.5 | C30: =SUM(C3:C29) -> 0 | D30: =SUM(D3:D29) -> 0 | E30: =SUM(E3:E29) -> 1
A31: מסגרות אשראי
A32: יתרות התחייבויות להשקעה

Sheet מזומנים ושווי מזומנים
A1: מספר קופה/קרן/ח.פ. עבור חברת ביטוח | B1: מספר מסלול | C1: שם הבנק | D1: מספר מזהה בנק | E1: סוג מספר מזהה בנק | F1: מאפיין עיקרי | G1: ישראל/חו"ל | H1: בעל עניין/צד קשור | I1: דירוג הבנק | J1: שם מדרג | K1: מטבע פעילות | L1: שווי מטבעי | M1: שער חליפין | N1: שיעור ריבית | O1: שווי הוגן (באלפי ש"ח) | P1: שיעור מנכסי אפיק ההשקעה | Q1: שיעור מסך נכסי ההשקעה
A2: 7891 | B2: 7892 | C2: בנק לאומי לישראל בע"מ | D2: 10 | E2: סימול בנק | F2: מזומן ועו"ש בש"ח | G2: ישראל | H2: לא | I2: ilAAA | J2: S&P מעלות | K2: ILS | L2: 175.47464 | M2: 1 | O2: 175.47464 | P2: 1 | Q2: 0.080559322
A3: 7891 | B3: 7893 | C3: בנק לאומי לישראל בע"מ | D3: 10 | E3: סימול בנק | F3: מזומן ועו"ש בש"ח | G3: ישראל | H3: לא | I3: ilAAA | J3: S&P מעלות | K3: ILS | L3: 35.75117 | M3: 1 | O3: 35.75117 | P3: 1 | Q3: 0.032894699
A4: 7891 | B4: 7895 | C4: בנק הפועלים בע"מ | D4: 12 | E4: סימול בנק | F4: מזומן ועו"ש בש"ח | G4: ישראל | H4: לא | I4: ilAAA | J4: S&P מעלות | K4: ILS | L4: 23.27839 | M4: 1 | O4: 23.27839 | P4: 1 | Q4: 0.075035899
A5: 7891 | B5: 7896 | C5: בנק הפועלים בע"מ | D5: 12 | E5: סימול בנק | F5: מזומן ועו"ש בש"ח | G5: ישראל | H5: לא | I5: ilAAA | J5: S&P מעלות | K5: ILS | L5: 458.87737 | M5: 1 | O5: 458.87737 | P5: 0.88015165 | Q5: 0.028040601
A6: 7891 | B6: 7896 | C6: בנק הפועלים בע"מ | D6: 12 | E6: סימול בנק | F6: מזומן ועו"ש נקוב במט"ח | G6: ישראל | H6: לא | I6: ilAAA | J6: S&P מעלות | K6: USD | L6: 14.14112 | M6: 3.71 | O6: 52.46356 | P6: 0.10062795 | Q6: 0.0032058886
A7: 7891 | B7: 7896 | C7: בנק הפועלים בע"מ | D7: 12 | E7: סימול בנק | F7: מזומן ועו"ש נקוב במט"ח | G7: ישראל | H7: לא | I7: ilAAA | J7: S&P מעלות | K7: EUR | L7: 2.41325 | M7: 4.1524 | O7: 10.02078 | P7: 0.019220399 | Q7: 0.0006123394
A8: 7891 | B8: 7897 | C8: בנק הפועלים בע"מ | D8: 12 | E8: סימול בנק | F8: מזומן ועו"ש בש"ח | G8: ישראל | H8: לא | I8: ilAAA | J8: S&P מעלות | K8: ILS | L8: 93.16327 | M8: 1 | O8: 93.16327 | P8: 0.0055424686 | Q8: 0.0010199523
A9: 7891 | B9: 7897 | C9: בנק הפועלים בע"מ | D9: 12 | E9: סימול בנק | F9: מזומן ועו"ש נקוב במט"ח | G9: ישראל | H9: לא | I9: ilAAA | J9: S&P מעלות | K9: USD | L9: -0.00018 | M9: 3.71 | O9: -0.00067 | P9: -3.9859635e-08 | Q9: -7.335166e-09
A10: 7891 | B10: 7897 | C10: בנק הפועלים בע"מ | D10: 12 | E10: סימול בנק | F10: מזומן ועו"ש בש"ח | G10: ישראל | H10: לא | I10: ilAAA | J10: S&P מעלות | K10: ILS | L10: 13461.115 | M10: 1 | O10: 13461.115 | P10: 0.80082856 | Q10: 0.14737241
A11: 7891 | B11: 7897 | C11: בנק הפועלים בע"מ | D11: 12 | E11: סימול בנק | F11: מזומן ועו"ש נקוב במט"ח | G11: ישראל | H11: לא | I11: ilAAA | J11: S&P מעלות | K11: USD | L11: 855.80193 | M11: 3.71 | O11: 3175.0252 | P11: 0.18888858 | Q11: 0.034760204
A12: 7891 | B12: 7897 | C12: בנק הפועלים בע"מ | D12: 12 | E12: סימול בנק | F12: מזומן ועו"ש נקוב במט"ח | G12: ישראל | H12: לא | I12: ilAAA | J12: S&P מעלות | K12: EUR | L12: 19.18936 | M12: 4.1524 | O12: 79.6819 | P12: 0.0047404351 | Q12: 0.00087235815
A13: 7891 | B13: 7900 | C13: בנק הפועלים בע"מ | D13: 12 | E13: סימול בנק | F13: מזומן ועו"ש בש"ח | G13: ישראל | H13: לא | I13: ilAAA | J13: S&P מעלות | K13: ILS | L13: 286.74183 | M13: 1 | O13: 286.74183 | P13: 0.9529249 | Q13: 0.027287193
... A53: 11342 | B53: 11345 | C53: בנק לאומי לישראל בע"מ | D53: 10 | E53: סימול בנק | F53: מזומן ועו"ש נקוב במט"ח | G53: ישראל | H53: לא | I53: ilAAA | J53: S&P מעלות | K53: GBP | L53: 2e-05 | M53: 4.9748 | O53: 0.0001 | P53: 2.3806971e-07 | Q53: 5.0524326e-09
A54: 7891 | B54: 7894
A55: 7891 | B55: 7898
A56: 7891 | B56: 7899
A57: 7891 | B57: 7901
A58: 7891 | B58: 7902
A59: 11925 | B59: 11927
A60: 11925 | B60: 11929
A61: 11925 | B61: 11930
A62: 11925 | B62: 11932
A63: 11925 | B63: 11933
A64: 11925 | B64: 11935
A65: 11925 | B65: 11936
... A71: 11939 | B71: 11950

Sheet איגרות חוב ממשלתיות
A1: מספר קופה/קרן/ח.פ. עבור חברת ביטוח | B1: מספר מסלול | C1: שם מנפיק | D1: שם נייר ערך | E1: מספר נייר ערך | F1: מאפיין עיקרי | G1: ישראל/חו"ל | H1: מדינה לפי חשיפה כלכלית | I1: זירת מסחר | J1: דירוג | K1: שם מדרג | L1: מטבע פעילות | M1: מח"מ | N1: מועד פדיון | O1: שיעור ריבית | P1: תשואה לפדיון | Q1: סכום לקבל (במטבע הפעילות) | R1: ערך נקוב (יחידות) | S1: שער חליפין | T1: שער נייר הערך | U1: שווי הוגן (באלפי ש"ח) | V1: עלות מופחתת (באלפי ש"ח) | W1: השיטה שיושמה בדוח הכספי | X1: שיעור מערך נקוב מונפק | Y1: שיעור מנכסי אפיק ההשקעה | Z1: שיעור מסך נכסי ההשקעה
A2: 7891 | B2: 7897 | C2: מדינת ישראל | D2: ממשל שקלית 0229 | E2: IL0011948028 | F2: לא צמוד למדד המחירים לצרכן ריבית קבועה | G2: ישראל | H2: ישראל | I2: TASE | J2: RF | K2: אחר | L2: ILS | M2: 4.057 | N2: 47177 | O2: 0.0375 | P2: 0.0456 | Q2: 0 | R2: 3139910 | S2: 1 | T2: 99.02 | U2: 3109.1389 | W2: שווי הוגן | X2: 9.5246196e-05 | Y2: 0.59530917 | Z2: 0.03403888
A3: 7891 | B3: 7897 | C3: מדינת ישראל | D3: ממשל צמודה 1028 | E3: IL0011973265 | F3: צמוד למדד המחירים לצרכן בריבית קבועה | G3: ישראל | H3: ישראל | I3: TASE | J3: RF | K3: אחר | L3: ILS | M3: 3.975 | N3: 47057 | O3: 0.011 | P3: 0.018 | Q3: 0 | R3: 2060030 | S3: 1 | T3: 102.6 | U3: 2113.5908 | W3: שווי הוגן | X3: 0.00010098128 | Y3: 0.40469083 | Z3: 0.023139611
A4: 7891 | B4: 7900 | C4: מדינת ישראל | D4: ממשל שקלית 0229 | E4: IL0011948028 | F4: לא צמוד למדד המחירים לצרכן ריבית קבועה | G4: ישראל | H4: ישראל | I4: TASE | J4: RF | K4: אחר | L4: ILS | M4: 4.057 | N4: 47177 | O4: 0.0375 | P4: 0.0456 | Q4: 0 | R4: 1325500 | S4: 1 | T4: 99.02 | U4: 1312.5101 | W4: שווי הוגן | X4: 4.0207787e-05 | Y4: 0.59726397 | Z4: 0.12490231
A5: 7891 | B5: 7900 | C5: מדינת ישראל | D5: ממשל צמודה 1028 | E5: IL0011973265 | F5: צמוד למדד המחירים לצרכן בריבית קבועה | G5: ישראל | H5: ישראל | I5: TASE | J5: RF | K5: אחר | L5: ILS | M5: 3.975 | N5: 47057 | O5: 0.011 | P5: 0.018 | Q5: 0 | R5: 862600 | S5: 1 | T5: 102.6 | U5: 885.0276 | W5: שווי הוגן | X5: 4.2284069e-05 | Y5: 0.40273603 | Z5: 0.08422182
A6: 11925 | B6: 11926 | C6: מדינת ישראל | D6: ממשל שקלית 0229 | E6: IL0011948028 | F6: לא צמוד למדד המחירים לצרכן ריבית קבועה | G6: ישראל | H6: ישראל | I6: TASE | J6: RF | K6: אחר | L6: ILS | M6: 4.057 | N6: 47177 | O6: 0.0375 | P6: 0.0456 | Q6: 0 | R6: 2821600 | S6: 1 | T6: 99.02 | U6: 2793.9483 | W6: שווי הוגן | X6: 8.5590564e-05 | Y6: 0.59731925 | Z6: 0.11562341
A7: 11925 | B7: 11926 | C7: מדינת ישראל | D7: ממשל צמודה 1028 | E7: IL0011973265 | F7: צמוד למדד המחירים לצרכן בריבית קבועה | G7: ישראל | H7: ישראל | I7: TASE | J7: RF | K7: אחר | L7: ILS | M7: 3.975 | N7: 47057 | O7: 0.011 | P7: 0.018 | Q7: 0 | R7: 1835800 | S7: 1 | T7: 102.6 | U7: 1883.5308 | W7: שווי הוגן | X7: 8.9989676e-05 | Y7: 0.40268075 | Z7: 0.077947129
A8: 11925 | B8: 11928 | C8: מדינת ישראל | D8: ממשל שקלית 0229 | E8: IL0011948028 | F8: לא צמוד למדד המחירים לצרכן ריבית קבועה | G8: ישראל | H8: ישראל | I8: TASE | J8: RF | K8: אחר | L8: ILS | M8: 4.057 | N8: 47177 | O8: 0.0375 | P8: 0.0456 | Q8: 0 | R8: 3738230 | S8: 1 | T8: 99.02 | U8: 3701.5954 | W8: שווי הוגן | X8: 0.00011339567 | Y8: 0.59587329 | Z8: 0.028602018
A9: 11925 | B9: 11928 | C9: מדינת ישראל | D9: ממשל צמודה 1028 | E9: IL0011973265 | F9: צמוד למדד המחירים לצרכן בריבית קבועה | G9: ישראל | H9: ישראל | I9: TASE | J9: RF | K9: אחר | L9: ILS | M9: 3.975 | N9: 47057 | O9: 0.011 | P9: 0.018 | Q9: 0 | R9: 2446838 | S9: 1 | T9: 102.6 | U9: 2510.4558 | W9: שווי הוגן | X9: 0.00011994235 | Y9: 0.40412671 | Z9: 0.01939815
A10: 11939 | B10: 11942 | C10: מדינת ישראל | D10: ממשל שקלית 0229 | E10: IL0011948028 | F10: לא צמוד למדד המחירים לצרכן ריבית קבועה | G10: ישראל | H10: ישראל | I10: TASE | J10: RF | K10: אחר | L10: ILS | M10: 4.057 | N10: 47177 | O10: 0.0375 | P10: 0.0456 | Q10: 0 | R10: 5041152 | S10: 1 | T10: 99.02 | U10: 4991.7487 | W10: שווי הוגן | X10: 0.00015291857 | Y10: 0.60024365 | Z10: 0.017976467
A11: 11939 | B11: 11942 | C11: מדינת ישראל | D11: ממשל צמודה 1028 | E11: IL0011973265 | F11: צמוד למדד המחירים לצרכן בריבית קבועה | G11: ישראל | H11: ישראל | I11: TASE | J11: RF | K11: אחר | L11: ILS | M11: 3.975 | N11: 47057 | O11: 0.011 | P11: 0.018 | Q11: 0 | R11: 3240210 | S11: 1 | T11: 102.6 | U11: 3324.4555 | W11: שווי הוגן | X11: 0.0001588329 | Y11: 0.39975635 | Z11: 0.01197215
A12: 11939 | B12: 11979 | C12: מדינת ישראל | D12: ממשל שקלית 0229 | E12: IL0011948028 | F12: לא צמוד למדד המחירים לצרכן ריבית קבועה | G12: ישראל | H12: ישראל | I12: TASE | J12: RF | K12: אחר | L12: ILS | M12: 4.057 | N12: 47177 | O12: 0.0375 | P12: 0.0456 | Q12: 0 | R12: 2347870 | S12: 1 | T12: 99.02 | U12: 2324.8609 | W12: שווי הוגן | X12: 7.1220413e-05 | Y12: 0.59752086 | Z12: 0.071909663
A13: 11939 | B13: 11979 | C13: מדינת ישראל | D13: ממשל צמודה 1028 | E13: IL0011973265 | F13: צמוד למדד המחירים לצרכן בריבית קבועה | G13: ישראל | H13: ישראל | I13: TASE | J13: RF | K13: אחר | L13: ILS | M13: 3.975 | N13: 47057 | O13: 0.011 | P13: 0.018 | Q13: 0 | R13: 1526300 | S13: 1 | T13: 102.6 | U13: 1565.9838 | W13: שווי הוגן | X13: 7.4818195e-05 | Y13: 0.40247914 | Z13: 0.048437035
... A23: 11342 | B23: 11345 | C23: מדינת ישראל | D23: ממשל צמודה 1028 | E23: IL0011973265 | F23: צמוד למדד המחירים לצרכן בריבית קבועה | G23: ישראל | H23: ישראל | I23: TASE | J23: RF | K23: אחר | L23: ILS | M23: 3.975 | N23: 47057 | O23: 0.011 | P23: 0.018 | Q23: 0 | R23: 832764 | S23: 1 | T23: 102.6 | U23: 854.41586 | W23: שווי הוגן | X23: 4.0821529e-05 | Y23: 0.40236381 | Z23: 0.043168786
A24: 7891 | B24: 7892
A25: 7891 | B25: 7893
A26: 7891 | B26: 7894
A27: 7891 | B27: 7895
A28: 7891 | B28: 7896
A29: 7891 | B29: 7898
A30: 7891 | B30: 7899
A31: 7891 | B31: 7901
A32: 7891 | B32: 7902
A33: 11925 | B33: 11927
A34: 11925 | B34: 11929
A35: 11925 | B35: 11930
... A50: 11939 | B50: 11950

Sheet ניירות ערך מסחריים
A1: מספר קופה/קרן/ח.פ. עבור חברת ביטוח | B1: מספר מסלול | C1: שם מנפיק | D1: מספר מנפיק | E1: סוג מספר מזהה מנפיק | F1: שם נייר ערך | G1: מספר נייר ערך | H1: סוג מספר נייר ערך | I1: מאפיין עיקרי | J1: ישראל/חו"ל | K1: מדינה לפי חשיפה כלכלית | L1: זירת מסחר | M1: ענף מסחר | N1: בעל עניין/צד קשור | O1: דירוג | P1: שם מדרג | Q1: דירוג נייר הערך/המנפיק | R1: מטבע פעילות | S1: מח"מ | T1: ריבית עוגן | U1: מועד פדיון | V1: שיעור ריבית | W1: תשואה לפדיון | X1: נחיתות חוזית | Y1: האם סווג כחוב בעייתי | Z1: ערך נקוב (יחידות) | AA1: שער חליפין | AB1: שער נייר הערך | AC1: סכום לקבל (במטבע הפעילות) | AD1: שווי הוגן (באלפי ש"ח) | AE1: עלות מופחתת (באלפי ש"ח) | AF1: עלות מופחתת (במטבע הפעילות) | AG1: השיטה שיושמה בדוח הכספי | AH1: שיעור מערך נקוב מונפק | AI1: שיעור מנכסי אפיק ההשקעה | AJ1: שיעור מסך נכסי ההשקעה
A2: 7891 | B2: 7892
A3: 7891 | B3: 7893
A4: 7891 | B4: 7894
A5: 7891 | B5: 7895
A6: 7891 | B6: 7896
A7: 7891 | B7: 7897
A8: 7891 | B8: 7898
A9: 7891 | B9: 7899
A10: 7891 | B10: 7900
A11: 7891 | B11: 7901
A12: 7891 | B12: 7902
A13: 11925 | B13: 11926
... A39: 11342 | B39: 11345

Sheet איגרות חוב
A1: מספר קופה/קרן/ח.פ. עבור חברת ביטוח | B1: מספר מסלול | C1: שם מנפיק | D1: מספר מנפיק | E1: סוג מספר מזהה מנפיק | F1: שם נייר ערך | G1: מספר נייר ערך | H1: סוג מספר נייר ערך | I1: מאפיין עיקרי | J1: ישראל/חו"ל | K1: מדינה לפי חשיפה כלכלית | L1: סטאטוס סחירות | M1: זירת מסחר | N1: ענף מסחר | O1: בעל עניין/צד קשור | P1: דירוג | Q1: שם מדרג | R1: דירוג נייר הערך/המנפיק | S1: מטבע פעילות | T1: מח"מ | U1: מועד פדיון | V1: שיעור ריבית | W1: תשואה לפדיון | X1: נחיתות חוזית | Y1: האם סווג כחוב בעייתי | Z1: ערך נקוב (יחידות) | AA1: שער חליפין | AB1: שער נייר הערך | AC1: סכום לקבל (במטבע הפעילות) | AD1: שווי הוגן (באלפי ש"ח) | AE1: עלות מופחתת (באלפי ש"ח) | AF1: עלות מופחתת (במטבע הפעילות) | AG1: השיטה שיושמה בדוח הכספי | AH1: שיעור מערך נקוב מונפק | AI1: שיעור מנכסי אפיק ההשקעה | AJ1: שיעור מסך נכסי ההשקעה
A2: 7891 | B2: 7892
A3: 7891 | B3: 7893
A4: 7891 | B4: 7894
A5: 7891 | B5: 7895
A6: 7891 | B6: 7896
A7: 7891 | B7: 7897
A8: 7891 | B8: 7898
A9: 7891 | B9: 7899
A10: 7891 | B10: 7900
A11: 7891 | B11: 7901
A12: 7891 | B12: 7902
A13: 11925 | B13: 11926
... A39: 11342 | B39: 11345

Sheet מניות מבכ ויהש
A1: מספר קופה/קרן/ח.פ. עבור חברת ביטוח | B1: מספר מסלול | C1: שם מנפיק | D1: מספר מנפיק | E1: סוג מספר מזהה מנפיק | F1: שם נייר ערך | G1: מספר נייר ערך | H1: סוג מספר נייר ערך | I1: מאפיין עיקרי | J1: ישראל/חו"ל | K1: מדינה לפי חשיפה כלכלית | L1: סטאטוס סחירות | M1: זירת מסחר | N1: ענף מסחר | O1: בעל עניין/צד קשור | P1: מטבע פעילות | Q1: ערך נקוב (יחידות) | R1: שער חליפין | S1: שער נייר הערך | T1: סכום לקבל (במטבע הפעילות) | U1: שווי הוגן (באלפי ש"ח) | V1: שיעור מערך נקוב מונפק | W1: שיעור מנכסי אפיק ההשקעה | X1: שיעור מסך נכסי ההשקעה
A2: 11925 | B2: 11931 | C2: בזק החברה הישראלית לתקשורת בע" | D2: 520031931 | E2: ח.פ | F2: בזק | G2: IL0002300114 | H2: ISIN | I2: מניות | J2: ישראל | K2: ישראל | L2: סחיר | M2: TASE | N2: תקשורת ומדיה | O2: לא | P2: ILS | Q2: 105208 | R2: 1 | S2: 428.6 | T2: 15.46964 | U2: 466.39113 | V2: 3.8008937e-05 | W2: 0.02014382 | X2: 0.019910339
A3: 11925 | B3: 11931 | C3: ישראמקו נגב 2 שותפות מוגבלת | D3: 550010003 | E3: מספר שותפות | F3: ישראמקו יהש | G3: IL0002320179 | H3: ISIN | I3: יחידות השתתפות | J3: ישראל | K3: ישראל | L3: סחיר | M3: TASE | N3: חיפושי נפט וגז | O3: לא | P3: ILS | Q3: 423045 | R3: 1 | S3: 161.9 | T3: 0 | U3: 684.90985 | V3: 0.00016297558 | W3: 0.029581824 | X3: 0.029238951
A4: 11925 | B4: 11931 | C4: פורמולה מערכות (1985)בע"מ | D4: 520036690 | E4: ח.פ | F4: פורמולה מערכות | G4: IL0002560162 | H4: ISIN | I4: מניות | J4: ישראל | K4: ישראל | L4: סחיר | M4: TASE | N4: שירותי מידע | O4: לא | P4: ILS | Q4: 1962 | R4: 1 | S4: 29830 | T4: 0 | U4: 585.2646 | V4: 0.00012796208 | W4: 0.025278063 | X4: 0.024985073
A5: 11925 | B5: 11931 | C5: נייס בע"מ | D5: 520036872 | E5: ח.פ | F5: נייס | G5: IL0002730112 | H5: ISIN | I5: מניות | J5: ישראל | K5: ישראל | L5: סחיר | M5: TASE | N5: תוכנה ואינטרנט | O5: לא | P5: ILS | Q5: 330 | R5: 1 | S5: 64880 | T5: 0 | U5: 214.104 | V5: 5.2490017e-06 | W5: 0.0092473293 | X5: 0.0091401464
A6: 11925 | B6: 11931 | C6: מליסרון בע"מ | D6: 520037789 | E6: ח.פ | F6: מליסרון | G6: IL0003230146 | H6: ISIN | I6: מניות | J6: ישראל | K6: ישראל | L6: סחיר | M6: TASE | N6: נדל"ן מניב בישראל | O6: לא | P6: ILS | Q6: 1893 | R6: 1 | S6: 28210 | T6: 0 | U6: 534.0153 | V6: 3.9832574e-05 | W6: 0.023064564 | X6: 0.022797229
A7: 11925 | B7: 11931 | C7: רציו אנרגיות-שותפות מוגבלת | D7: 550012777 | E7: מספר שותפות | F7: רציו יהש | G7: IL0003940157 | H7: ISIN | I7: יחידות השתתפות | J7: ישראל | K7: ישראל | L7: סחיר | M7: TASE | N7: חיפושי נפט וגז | O7: לא | P7: ILS | Q7: 116729 | R7: 1 | S7: 303 | T7: 0 | U7: 353.68887 | V7: 0.00010386333 | W7: 0.015276116 | X7: 0.015099055
A8: 11925 | B8: 11931 | C8: מטריקס אי.טי בע"מ | D8: 520039413 | E8: ח.פ | F8: מטריקס | G8: IL0004450156 | H8: ISIN | I8: מניות | J8: ישראל | K8: ישראל | L8: סחיר | M8: TASE | N8: שירותי מידע | O8: לא | P8: ILS | Q8: 7053 | R8: 1 | S8: 7125 | T8: 5.78346 | U8: 508.30971 | V8: 0.00011103227 | W8: 0.021954318 | X8: 0.021699852
A9: 11925 | B9: 11931 | C9: ניו-מד אנרג'י- שותפות מוגבלת | D9: 550013098 | E9: מספר שותפות | F9: ניו-מד אנרג יהש | G9: IL0004750209 | H9: ISIN | I9: יחידות השתתפות | J9: ישראל | K9: ישראל | L9: סחיר | M9: TASE | N9: חיפושי נפט וגז | O9: לא | P9: ILS | Q9: 40344 | R9: 1 | S9: 1025 | T9: 0 | U9: 413.526 | V9: 3.4369991e-05 | W9: 0.017860531 | X9: 0.017653515
A10: 11925 | B10: 11931 | C10: מנורה מבטחים החזקות בע"מ | D10: 520007469 | E10: ח.פ | F10: מנורה מב החז | G10: IL0005660183 | H10: ISIN | I10: מניות | J10: ישראל | K10: ישראל | L10: סחיר | M10: TASE | N10: ביטוח | O10: לא | P10: ILS | Q10: 4741 | R10: 1 | S10: 10880 | T10: 0 | U10: 515.8208 | V10: 7.6454095e-05 | W10: 0.022278728 | X10: 0.022020502
A11: 11925 | B11: 11931 | C11: הבנק הבינלאומי הראשון לישראל ב | D11: 520029083 | E11: ח.פ | F11: בינלאומי | G11: IL0005930388 | H11: ISIN | I11: מניות | J11: ישראל | K11: ישראל | L11: סחיר | M11: TASE | N11: בנקים | O11: לא | P11: ILS | Q11: 3405 | R11: 1 | S11: 15410 | T11: 0 | U11: 524.7105 | V11: 3.3937991e-05 | W11: 0.022662682 | X11: 0.022400005
A12: 11925 | B12: 11931 | C12: בנק לאומי לישראל בע"מ | D12: 520018078 | E12: ח.פ | F12: לאומי | G12: IL0006046119 | H12: ISIN | I12: מניות | J12: ישראל | K12: ישראל | L12: סחיר | M12: TASE | N12: בנקים | O12: לא | P12: ILS | Q12: 14452 | R12: 1 | S12: 3644 | T12: 0 | U12: 526.63088 | V12: 9.5772947e-06 | W12: 0.022745624 | X12: 0.022481987
A13: 11925 | B13: 11931 | C13: ישרס חברה להשקעות בע"מ | D13: 520017807 | E13: ח.פ | F13: ישרס | G13: IL0006130343 | H13: ISIN | I13: מניות | J13: ישראל | K13: ישראל | L13: סחיר | M13: TASE | N13: נדל"ן מניב בישראל | O13: לא | P13: ILS | Q13: 908 | R13: 1 | S13: 73900 | T13: 0 | U13: 671.012 | V13: 0.00018174274 | W13: 0.028981565 | X13: 0.028645648
... A48: 11925 | B48: 11931 | C48: בתי זקוק לנפט בע"מ | D48: 520036658 | E48: ח.פ | F48: בזן | G48: IL0025902482 | H48: ISIN | I48: מניות | J48: ישראל | K48: ישראל | L48: סחיר | M48: TASE | N48: אנרגיה | O48: לא | P48: ILS | Q48: 738856 | R48: 1 | S48: 96.1 | T48: 0 | U48: 710.04062 | V48: 0.00023752322 | W48: 0.030667243 | X48: 0.030311789
A49: 7891 | B49: 7892
A50: 7891 | B50: 7893
A51: 7891 | B51: 7894
A52: 7891 | B52: 7895
A53: 7891 | B53: 7896
A54: 7891 | B54: 7897
A55: 7891 | B55: 7898
A56: 7891 | B56: 7899
A57: 7891 | B57: 7900
A58: 7891 | B58: 7901
A59: 7891 | B59: 7902
A60: 11925 | B60: 11926
... A85: 11342 | B85: 11345

Sheet קרנות סל
A1: מספר קופה/קרן/ח.פ. עבור חברת ביטוח | B1: מספר מסלול | C1: שם מנפיק | D1: מספר מנפיק | E1: סוג מספר מזהה מנפיק | F1: שם נייר ערך | G1: מספר נייר ערך | H1: סוג מספר נייר ערך | I1: מאפיין עיקרי | J1: ישראל/חו"ל | K1: מדינה לפי חשיפה כלכלית | L1: זירת מסחר | M1: סיווג הקרן | N1: בעל עניין/צד קשור | O1: מטבע פעילות | P1: ערך נקוב (יחידות) | Q1: שער חליפין | R1: שער נייר הערך | S1: סכום לקבל (במטבע הפעילות) | T1: שווי הוגן (באלפי ש"ח) | U1: שיעור מערך נקוב מונפק | V1: שיעור מנכסי אפיק ההשקעה | W1: שיעור מסך נכסי ההשקעה
A2: 7891 | B2: 7892 | C2: מיטב קרנות נאמנות בע"מ | D2: 513534974 | E2: ח.פ. | F2: תכ.תא35 | G2: IL0011437006 | H2: ISIN | I2: עוקב אחר מדדי מניות בישראל | J2: ישראל | K2: ישראל | L2: TASE | M2: Large & Mid Cap מניות בארץ - מניות לפי שווי שוק-מניות | N2: לא | O2: ILS | P2: 23974 | Q2: 1 | R2: 2092 | S2: 0 | T2: 501.53608 | U2: 0 | V2: 0.25042628 | W2: 0.23025211
A3: 7891 | B3: 7892 | C3: קסם קרנות נאמנות בע"מ | D3: 510938608 | E3: ח.פ. | F3: קסם.תא 35 | G3: IL0011465700 | H3: ISIN | I3: עוקב אחר מדדי מניות בישראל | J3: ישראל | K3: ישראל | L3: TASE | M3: Large & Mid Cap מניות בארץ - מניות לפי שווי שוק-מניות | N3: לא | O3: ILS | P3: 2412 | Q3: 1 | R3: 20810 | S3: 0 | T3: 501.9372 | U3: 0 | V3: 0.25062657 | W3: 0.23043626
A4: 7891 | B4: 7892 | C4: הראל קרנות נאמנות בע"מ | D4: 511776783 | E4: ח.פ. | F4: הרל.תא 35 | G4: IL0011489072 | H4: ISIN | I4: עוקב אחר מדדי מניות בישראל | J4: ישראל | K4: ישראל | L4: TASE | M4: Large & Mid Cap מניות בארץ - מניות לפי שווי שוק-מניות | N4: לא | O4: ILS | P4: 23830 | Q4: 1 | R4: 2094 | S4: 0 | T4: 499.0002 | U4: 0 | V4: 0.24916007 | W4: 0.22908791
A5: 7891 | B5: 7892 | C5: מגדל קרנות נאמנות בע"מ | D5: 511303661 | E5: ח.פ. | F5: MTF.תא35 | G5: IL0011501843 | H5: ISIN | I5: עוקב אחר מדדי מניות בישראל | J5: ישראל | K5: ישראל | L5: TASE | M5: Large & Mid Cap מניות בארץ - מניות לפי שווי שוק-מניות | N5: לא | O5: ILS | P5: 17559 | Q5: 1 | R5: 2849 | S5: 0 | T5: 500.25591 | U5: 0 | V5: 0.24978707 | W5: 0.22966439
A6: 7891 | B6: 7893 | C6: מיטב קרנות נאמנות בע"מ | D6: 513534974 | E6: ח.פ. | F6: תכ.תלבונד60 | G6: IL0011451015 | H6: ISIN | I6: עוקב אחר מדדים אחרים בישראל | J6: ישראל | K6: ישראל | L6: TASE | M6: אג"ח בארץ - חברות והמרה-תל בונד צמוד מדד-תל בונד צמודות | N6: לא | O6: ILS | P6: 72091 | Q6: 1 | R6: 365.33 | S6: 0 | T6: 263.37005 | U6: 0 | V6: 0.25056954 | W6: 0.24232713
A7: 7891 | B7: 7893 | C7: קסם קרנות נאמנות בע"מ | D7: 510938608 | E7: ח.פ. | F7: קסם.תלבונד 60 | G7: IL0011462327 | H7: ISIN | I7: עוקב אחר מדדים אחרים בישראל | J7: ישראל | K7: ישראל | L7: TASE | M7: אג"ח בארץ - חברות והמרה-תל בונד צמוד מדד-תל בונד צמודות | N7: לא | O7: ILS | P7: 7259 | Q7: 1 | R7: 3637.39 | S7: 0 | T7: 264.03814 | U7: 0 | V7: 0.25120516 | W7: 0.24294184
A8: 7891 | B8: 7893 | C8: אי.בי.אי קרנות נאמנות בעמ | D8: 513765339 | E8: ח.פ. | F8: IBI.תלבונד 60 | G8: IL0011480063 | H8: ISIN | I8: עוקב אחר מדדים אחרים בישראל | J8: ישראל | K8: ישראל | L8: TASE | M8: אג"ח בארץ - חברות והמרה-תל בונד צמוד מדד-תל בונד צמודות | N8: לא | O8: ILS | P8: 71580 | Q8: 1 | R8: 365.93 | S8: 0 | T8: 261.93269 | U8: 0 | V8: 0.24920204 | W8: 0.24100462
A9: 7891 | B9: 7893 | C9: הראל קרנות נאמנות בע"מ | D9: 511776783 | E9: ח.פ. | F9: הרל.תלבונד 60 | G9: IL0011504730 | H9: ISIN | I9: עוקב אחר מדדים אחרים בישראל | J9: ישראל | K9: ישראל | L9: TASE | M9: אג"ח בארץ - חברות והמרה-תל בונד צמוד מדד-תל בונד צמודות | N9: לא | O9: ILS | P9: 71827 | Q9: 1 | R9: 364.41 | S9: 0 | T9: 261.74477 | U9: 0 | V9: 0.24902326 | W9: 0.24083171
A10: 7891 | B10: 7895 | C10: מיטב קרנות נאמנות בע"מ | D10: 513534974 | E10: ח.פ. | F10: תכ.שחר | G10: IL0011451437 | H10: ISIN | I10: עוקב אחר מדדים אחרים בישראל | J10: ישראל | K10: ישראל | L10: TASE | M10: אג"ח בארץ - מדינה-אג"ח מדינה שקליות -שקליות ריבית קבועה ממשלתיות | N10: לא | O10: ILS | P10: 16140 | Q10: 1 | R10: 438.57 | S10: 0 | T10: 70.7852 | U10: 0 | V10: 1 | W10: =+T10/'סכום נכסים'!$B$30 -> 6.0680425e-05
A11: 7891 | B11: 7896 | C11: Amundi S&P 500 UCITS ETF | D11: 2138007NOUJ46G9POA93 | E11: LEI | F11: AMUNDI S&P 500 UCITS ETF | G11: LU1681048804 | H11: ISIN | I11: עוקב אחר מדדי מניות בחו"ל | J11: חו"ל | K11: ארה"ב | L11: NASDAQ | M11: Equity Funds | N11: לא | O11: EUR | P11: 7678 | Q11: 4.1524 | R11: 10076.66 | S11: 0 | T11: 3212.6536 | U11: 0 | V11: 0.20277569 | W11: 0.19631549
A12: 7891 | B12: 7896 | C12: Invesco | D12: ECPGFXU8A2SH | E12: LEI | F12: INVESCO S&P 500 ACC | G12: IE00B3YCGJ38 | H12: ISIN | I12: עוקב אחר מדדי מניות בחו"ל | J12: חו"ל | K12: ארה"ב | L12: LSE | M12: Equity Funds | N12: לא | O12: USD | P12: 761 | Q12: 3.71 | R12: 112716 | S12: 0 | T12: 3182.3221 | U12: 0 | V12: 0.20086123 | W12: 0.19446203
A13: 7891 | B13: 7896 | C13: iShares Core S&P 500 UCITS ETF | D13: 5493006ESS9BM09FB892 | E13: LEI | F13: ISHARES CORE S&P 500 | G13: IE00B5BMR087 | H13: ISIN | I13: עוקב אחר מדדי מניות בחו"ל | J13: חו"ל | K13: ארה"ב | L13: LSE | M13: Equity Funds | N13: לא | O13: USD | P13: 1415 | Q13: 3.71 | R13: 60718 | S13: 0 | T13: 3187.4825 | U13: 0 | V13: 0.20118694 | W13: 0.19477736
A14: 7891 | B14: 7896 | C14: Xtrackers S&P 500 Swap UCITS E | D14: 54930044TWZ26JPZ4913 | E14: LEI | F14: X S&P 500 SWAP | G14: LU0490618542 | H14: ISIN | I14: עוקב אחר מדדי מניות בחו"ל | J14: חו"ל | K14: ארה"ב | L14: LSE | M14: Equity Funds | N14: לא | O14: USD | P14: 7584 | Q14: 3.71 | R14: 11363 | S14: 0 | T14: 3197.1664 | U14: 0 | V14: 0.20179817 | W14: 0.19536912
A15: 7891 | B15: 7896 | C15: SPDR S&P 500 UCITC ETF | D15: 549300F1TODGOV4WQV40 | E15: LEI | F15: SPDR S&P 500 UCITS ETF ACC | G15: IE000XZSV718 | H15: ISIN | I15: עוקב אחר מדדי מניות בחו"ל | J15: חו"ל | K15: ארה"ב | L15: LSE | M15: Equity Funds | N15: לא | O15: USD | P15: 59300 | Q15: 3.71 | R15: 1392.6 | S15: 0 | T15: 3063.7618 | U15: 0 | V15: 0.19337796 | W15: 0.18721717
A16: 7891 | B16: 7897 | C16: קסם קרנות נאמנות בע"מ | D16: 510938608 | E16: ח.פ. | F16: קסם.תל ג-צמ 0-2 | G16: IL0011461337 | H16: ISIN | I16: עוקב אחר מדדים אחרים בישראל | J16: ישראל | K16: ישראל | L16: TASE | M16: אג"ח בארץ - מדינה-אג"ח מדינה צמוד מדד-צמודות מדד - ממשלתיות 0-2 שנים | N16: לא | O16: ILS | P16: 168180 | Q16: 1 | R16: 2555.88 | S16: 0 | T16: 4298.479 | U16: 0.015 | V16: 0.12409173 | W16: 0.047059786
A17: 7891 | B17: 7897 | C17: אי.בי.אי קרנות נאמנות בעמ | D17: 513765339 | E17: ח.פ. | F17: IBI.תלבונד 60 | G17: IL0011480063 | H17: ISIN | I17: עוקב אחר מדדים אחרים בישראל | J17: ישראל | K17: ישראל | L17: TASE | M17: אג"ח בארץ - חברות והמרה-תל בונד צמוד מדד-תל בונד צמודות | N17: לא | O17: ILS | P17: 1866800 | Q17: 1 | R17: 365.93 | S17: 0 | T17: 6831.1812 | U17: 0.001 | V17: 0.19720769 | W17: 0.074787833
A18: 7891 | B18: 7897 | C18: מגדל קרנות נאמנות בע"מ | D18: 511303661 | E18: ח.פ. | F18: MTF.תלבונד60 | G18: IL0011499964 | H18: ISIN | I18: עוקב אחר מדדים אחרים בישראל | J18: ישראל | K18: ישראל | L18: TASE | M18: אג"ח בארץ - חברות והמרה-תל בונד צמוד מדד-תל בונד צמודות | N18: לא | O18: ILS | P18: 1948507 | Q18: 1 | R18: 465.93 | S18: 0 | T18: 9078.6787 | U18: 0.013 | V18: 0.26209014 | W18: 0.099393455
A19: 7891 | B19: 7897 | C19: הראל קרנות נאמנות בע"מ | D19: 511776783 | E19: ח.פ. | F19: הרל.תלבונד 60 | G19: IL0011504730 | H19: ISIN | I19: עוקב אחר מדדים אחרים בישראל | J19: ישראל | K19: ישראל | L19: TASE | M19: אג"ח בארץ - חברות והמרה-תל בונד צמוד מדד-תל בונד צמודות | N19: לא | O19: ILS | P19: 2085400 | Q19: 1 | R19: 364.41 | S19: 0 | T19: 7599.4061 | U19: 0.007 | V19: 0.21938539 | W19: 0.083198366
A20: 7891 | B20: 7897 | C20: מור ניהול קרנות נאמנות | D20: 514884485 | E20: ח.פ. | F20: מו.סל תלבונד 60 | G20: IL0011953044 | H20: ISIN | I20: עוקב אחר מדדים אחרים בישראל | J20: ישראל | K20: ישראל | L20: TASE | M20: אג"ח בארץ - חברות והמרה-תל בונד צמוד מדד-תל בונד צמודות | N20: לא | O20: ILS | P20: 128090 | Q20: 1 | R20: 5333.58 | S20: 0 | T20: 6831.7826 | U20: 0.021 | V20: 0.19722505 | W20: 0.074794417
A21: 7891 | B21: 7900 | C21: מיטב קרנות נאמנות בע"מ | D21: 513534974 | E21: ח.פ. | F21: תכ.תא125 | G21: IL0011437188 | H21: ISIN | I21: עוקב אחר מדדי מניות בישראל | J21: ישראל | K21: ישראל | L21: TASE | M21: Large & Mid Cap מניות בארץ - מניות לפי שווי שוק-מניות | N21: לא | O21: ILS | P21: 15920 | Q21: 1 | R21: 2081 | S21: 0 | T21: 331.2952 | U21: 0 | V21: 0.041360981 | W21: 0.031527022
A22: 7891 | B22: 7900 | C22: מיטב קרנות נאמנות בע"מ | D22: 513534974 | E22: ח.פ. | F22: תכ.תלבונד60 | G22: IL0011451015 | H22: ISIN | I22: עוקב אחר מדדים אחרים בישראל | J22: ישראל | K22: ישראל | L22: TASE | M22: אג"ח בארץ - חברות והמרה-תל בונד צמוד מדד-תל בונד צמודות | N22: לא | O22: ILS | P22: 35244 | Q22: 1 | R22: 365.33 | S22: 0 | T22: 128.75691 | U22: 0 | V22: 0.016074824 | W22: 0.012252885
A23: 7891 | B23: 7900 | C23: מיטב קרנות נאמנות בע"מ | D23: 513534974 | E23: ח.פ. | F23: תכ.תלבונדשקלי | G23: IL0011451841 | H23: ISIN | I23: עוקב אחר מדדים אחרים בישראל | J23: ישראל | K23: ישראל | L23: TASE | M23: אג"ח בארץ - חברות והמרה-תל בונד שקלי-תל בונד- שקלי | N23: לא | O23: ILS | P23: 83680 | Q23: 1 | R23: 390.51 | S23: 0 | T23: 326.77877 | U23: 0 | V23: 0.040797121 | W23: 0.031097225
A24: 7891 | B24: 7900 | C24: קסם קרנות נאמנות בע"מ | D24: 510938608 | E24: ח.פ. | F24: קסם.תלבונד שקלי | G24: IL0011464141 | H24: ISIN | I24: עוקב אחר מדדים אחרים בישראל | J24: ישראל | K24: ישראל | L24: TASE | M24: אג"ח בארץ - חברות והמרה-תל בונד שקלי-תל בונד- שקלי | N24: לא | O24: ILS | P24: 11970 | Q24: 1 | R24: 3880.51 | S24: 0 | T24: 464.49705 | U24: 0 | V24: 0.057990739 | W24: 0.0442029
A25: 7891 | B25: 7900 | C25: קסם קרנות נאמנות בע"מ | D25: 510938608 | E25: ח.פ. | F25: SP500.קסם | G25: IL0011464711 | H25: ISIN | I25: עוקב אחר מדדי מניות בחו"ל | J25: ישראל | K25: ארה"ב | L25: TASE | M25: מניות בחו"ל - מניות גיאוגרפי - חשופת מט"ח-ארה"ב - מדד אחר | N25: לא | O25: ILS | P25: 2240 | Q25: 1 | R25: 23280 | S25: 0 | T25: 521.472 | U25: 0 | V25: 0.065103851 | W25: 0.049624803
A26: 7891 | B26: 7900 | C26: קסם קרנות נאמנות בע"מ | D26: 510938608 | E26: ח.פ. | F26: קסם.SP500ממ | G26: IL0011466047 | H26: ISIN | I26: עוקב אחר מדדי מניות בחו"ל | J26: ישראל | K26: ארה"ב | L26: TASE | M26: מניות בחו"ל - מניות גיאוגרפי - מנוטרלת מט"ח-ארה"ב - מדד אחר | N26: לא | O26: ILS | P26: 2965 | Q26: 1 | R26: 5505 | S26: 0 | T26: 163.22325 | U26: 0 | V26: 0.020377819 | W26: 0.015532803
A27: 7891 | B27: 7900 | C27: אי.בי.אי קרנות נאמנות בעמ | D27: 513765339 | E27: ח.פ. | F27: IBI.תלבונד 60 | G27: IL0011480063 | H27: ISIN | I27: עוקב אחר מדדים אחרים בישראל | J27: ישראל | K27: ישראל | L27: TASE | M27: אג"ח בארץ - חברות והמרה-תל בונד צמוד מדד-תל בונד צמודות | N27: לא | O27: ILS | P27: 176100 | Q27: 1 | R27: 365.93 | S27: 0 | T27: 644.40273 | U27: 0 | V27: 0.080451298 | W27: 0.061323252
A28: 7891 | B28: 7900 | C28: הראל קרנות נאמנות בע"מ | D28: 511776783 | E28: ח.פ. | F28: הרל.SP500 ממ | G28: IL0011491375 | H28: ISIN | I28: עוקב אחר מדדי מניות בחו"ל | J28: ישראל | K28: ארה"ב | L28: TASE | M28: מניות בחו"ל - מניות גיאוגרפי - מנוטרלת מט"ח-ארה"ב - מדד אחר | N28: לא | O28: ILS | P28: 7840 | Q28: 1 | R28: 5590 | S28: 0 | T28: 438.256 | U28: 0 | V28: 0.054714641 | W28: 0.041705725
A29: 7891 | B29: 7900 | C29: מגדל קרנות נאמנות בע"מ | D29: 511303661 | E29: ח.פ. | F29: MTF.תא125 | G29: IL0011502833 | H29: ISIN | I29: עוקב אחר מדדי מניות בישראל | J29: ישראל | K29: ישראל | L29: TASE | M29: Large & Mid Cap מניות בארץ - מניות לפי שווי שוק-מניות | N29: לא | O29: ILS | P29: 15810 | Q29: 1 | R29: 3265 | S29: 0 | T29: 516.1965 | U29: 0 | V29: 0.064445224 | W29: 0.049122771
A30: 7891 | B30: 7900 | C30: מגדל קרנות נאמנות בע"מ | D30: 511303661 | E30: ח.פ. | F30: SP500.MTFממ | G30: IL0011505729 | H30: ISIN | I30: עוקב אחר מדדי מניות בחו"ל | J30: ישראל | K30: ארה"ב | L30: TASE | M30: מניות בחו"ל - מניות גיאוגרפי - מנוטרלת מט"ח-ארה"ב - מדד אחר | N30: לא | O30: ILS | P30: 3130 | Q30: 1 | R30: 7341 | S30: 0 | T30: 229.7733 | U30: 0 | V30: 0.028686347 | W30: 0.0218659
A31: 7891 | B31: 7900 | C31: מגדל קרנות נאמנות בע"מ | D31: 511303661 | E31: ח.פ. | F31: STX600.MTFממ | G31: IL0011506149 | H31: ISIN | I31: עוקב אחר מדדי מניות בחו"ל | J31: ישראל | K31: ארה"ב | L31: TASE | M31: מניות בחו"ל - מניות גיאוגרפי - מנוטרלת מט"ח-אירופה - מדד אחר | N31: לא | O31: ILS | P31: 6020 | Q31: 1 | R31: 7671 | S31: 0 | T31: 461.7942 | U31: 0.001 | V31: 0.057653298 | W31: 0.043945689
A32: 7891 | B32: 7900 | C32: מור ניהול קרנות נאמנות | D32: 514884485 | E32: ח.פ. | F32: מו.SP500ממ | G32: IL0011658288 | H32: ISIN | I32: עוקב אחר מדדי מניות בחו"ל | J32: ישראל | K32: ארה"ב | L32: TASE | M32: מניות בחו"ל - מניות גיאוגרפי - מנוטרלת מט"ח-ארה"ב - מדד אחר | N32: לא | O32: ILS | P32: 3980 | Q32: 1 | R32: 9006 | S32: 0 | T32: 358.4388 | U32: 0 | V32: 0.044749759 | W32: 0.034110086
A33: 7891 | B33: 7900 | C33: מור ניהול קרנות נאמנות | D33: 514884485 | E33: ח.פ. | F33: מו.סל תא 125 | G33: IL0011961534 | H33: ISIN | I33: עוקב אחר מדדי מניות בישראל | J33: ישראל | K33: ישראל | L33: TASE | M33: Large & Mid Cap מניות בארץ - מניות לפי שווי שוק-מניות | N33: לא | O33: ILS | P33: 13280 | Q33: 1 | R33: 5753 | S33: 0 | T33: 763.9984 | U33: 0.002 | V33: 0.095382375 | W33: 0.072704326
A34: 7891 | B34: 7900 | C34: Invesco QQQ Trust Series 1 | D34: 549300VY6FEJBCIMET58 | E34: LEI | F34: INVESCO QQQ TRUST SERIES 1 | G34: US46090E1038 | H34: ISIN | I34: עוקב אחר מדדי מניות בחו"ל | J34: חו"ל | K34: ארה"ב | L34: NASDAQ | M34: Equity Funds | N34: לא | O34: USD | P34: 238 | Q34: 3.71 | R34: 48807 | S34: 0.12081941 | T34: 431.40429 | U34: 0 | V34: 0.053859231 | W34: 0.041053696
A35: 7891 | B35: 7900 | C35: iShares 0-5 Year High Yield Co | D35: 549300R96U5WQ7R5ID10 | E35: LEI | F35: ISHARES 0-5 YR HY CORP BOND | G35: US46434V4077 | H35: ISIN | I35: עוקב אחר מדדים אחרים בחו"ל | J35: חו"ל | K35: ארה"ב | L35: NYSE | M35: Bond/Fixed Income Funds | N35: לא | O35: USD | P35: 3380 | Q35: 3.71 | R35: 4342 | S35: 0 | T35: 544.47812 | U35: 0 | V35: 0.06797608 | W35: 0.051814133
A36: 7891 | B36: 7900 | C36: iShares U.S. Financial Service | D36: 549300O3BGVZIZJEZC19 | E36: LEI | F36: ISHARES U.S. FINANCIAL SERVI | G36: US4642877702 | H36: ISIN | I36: עוקב אחר מדדי מניות בחו"ל | J36: חו"ל | K36: ארה"ב | L36: NYSE | M36: Equity Funds | N36: לא | O36: USD | P36: 564 | Q36: 3.71 | R36: 7102 | S36: 0.13522911 | T36: 149.10679 | U36: 0 | V36: 0.018615431 | W36: 0.014189439
A37: 7891 | B37: 7900 | C37: Invesco | D37: ECPGFXU8A2SH | E37: LEI | F37: INVESCO S&P 500 ACC | G37: IE00B3YCGJ38 | H37: ISIN | I37: עוקב אחר מדדי מניות בחו"ל | J37: חו"ל | K37: ארה"ב | L37: LSE | M37: Equity Funds | N37: לא | O37: USD | P37: 189 | Q37: 3.71 | R37: 112716 | S37: 0 | T37: 790.35332 | U37: 0 | V37: 0.09867269 | W37: 0.075212338
A38: 7891 | B38: 7900 | C38: iShares Core S&P 500 UCITS ETF | D38: 5493006ESS9BM09FB892 | E38: LEI | F38: ISHARES CORE S&P 500 | G38: IE00B5BMR087 | H38: ISIN | I38: עוקב אחר מדדי מניות בחו"ל | J38: חו"ל | K38: ארה"ב | L38: LSE | M38: Equity Funds | N38: לא | O38: USD | P38: 331 | Q38: 3.71 | R38: 60718 | S38: 0 | T38: 745.62311 | U38: 0 | V38: 0.093088288 | W38: 0.07095568
A39: 11925 | B39: 11926 | C39: מיטב קרנות נאמנות בע"מ | D39: 513534974 | E39: ח.פ. | F39: תכ.תלבונד60 | G39: IL0011451015 | H39: ISIN | I39: עוקב אחר מדדים אחרים בישראל | J39: ישראל | K39: ישראל | L39: TASE | M39: אג"ח בארץ - חברות והמרה-תל בונד צמוד מדד-תל בונד צמודות | N39: לא | O39: ILS | P39: 82255 | Q39: 1 | R39: 365.33 | S39: 0 | T39: 300.50219 | U39: 0 | V39: 0.016970892 | W39: 0.012435838
A40: 11925 | B40: 11926 | C40: מיטב קרנות נאמנות בע"מ | D40: 513534974 | E40: ח.פ. | F40: תכ.תלבונדשקלי | G40: IL0011451841 | H40: ISIN | I40: עוקב אחר מדדים אחרים בישראל | J40: ישראל | K40: ישראל | L40: TASE | M40: אג"ח בארץ - חברות והמרה-תל בונד שקלי-תל בונד- שקלי | N40: לא | O40: ILS | P40: 321670 | Q40: 1 | R40: 390.51 | S40: 0 | T40: 1256.1535 | U40: 0 | V40: 0.0709414 | W40: 0.051984051
...

Sheet קרנות נאמנות
A1: מספר קופה/קרן/ח.פ. עבור חברת ביטוח | B1: מספר מסלול | C1: שם מנפיק | D1: מספר מנפיק | E1: סוג מספר מזהה מנפיק | F1: שם נייר ערך | G1: מספר נייר ערך | H1: סוג מספר נייר ערך | I1: מאפיין עיקרי | J1: ישראל/חו"ל | K1: מדינה לפי חשיפה כלכלית | L1: סטאטוס סחירות | M1: זירת מסחר | N1: סיווג הקרן | O1: בעל עניין/צד קשור | P1: מטבע פעילות | Q1: ערך נקוב (יחידות) | R1: שער חליפין | S1: שער נייר הערך | T1: שווי הוגן (באלפי ש"ח) | U1: שיעור מערך נקוב מונפק | V1: שיעור מנכסי אפיק ההשקעה | W1: שיעור מסך נכסי ההשקעה
A2: 7891 | B2: 7895 | C2: קסם קרנות נאמנות בע"מ | D2: 510938608 | E2: ח.פ. | F2: קסם תל גוב-שקלי | G2: IL0051180474 | H2: ISIN | I2: אג"ח ממשלתי | J2: ישראל | K2: ישראל | L2: סחיר | M2: TASE | N2: אג"ח בארץ - מדינה-אג"ח מדינה שקליות- ללא מניות | O2: לא | P2: ILS | Q2: 60260 | R2: 1 | S2: 119.67 | T2: 72.11314 | U2: 0.00066095174 | V2: =+T2/SUM(T2:T4) -> 0.33360006 | W2: =+T2/'סכום נכסים'!$B$30 -> 6.1818799e-05
A3: 7891 | B3: 7895 | C3: מגדל קרנות נאמנות בע"מ | D3: 511303661 | E3: ח.פ. | F3: מח גוב שקלי MTF | G3: IL0051233935 | H3: ISIN | I3: אג"ח ממשלתי | J3: ישראל | K3: ישראל | L3: סחיר | M3: TASE | N3: אג"ח בארץ - מדינה-אג"ח מדינה שקליות- ללא מניות | O3: לא | P3: ILS | Q3: 70740 | R3: 1 | S3: 100.91 | T3: 71.38373 | U3: 0.001465785 | V3: =+T3/SUM(T2:T4) -> 0.33022576 | W3: =+T3/'סכום נכסים'!$B$30 -> 6.1193514e-05
A4: 7891 | B4: 7895 | C4: מגדל קרנות נאמנות בע"מ | D4: 511303661 | E4: ח.פ. | F4: הראל תל גוב-שקל | G4: IL0051281116 | H4: ISIN | I4: אג"ח ממשלתי | J4: ישראל | K4: ישראל | L4: סחיר | M4: TASE | N4: אג"ח בארץ - מדינה-אג"ח מדינה שקליות- ללא מניות | O4: לא | P4: ILS | Q4: 16050 | R4: 1 | S4: 452.77 | T4: 72.66958 | U4: 0.0044582564 | V4: =+T4/SUM(T2:T4) -> 0.33617418 | W4: =+T4/'סכום נכסים'!$B$30 -> 6.2295805e-05
A5: 7891 | B5: 7897 | C5: אלטשולר שחם ניהול קרנות | D5: 511944670 | E5: ח.פ. | F5: אלטש כספ לא קנצ | G5: IL0051058209 | H5: ISIN | I5: אג"ח קונצרני | J5: ישראל | K5: ישראל | L5: סחיר | M5: TASE | N5: קרן כספית-כספית שקלית-כספית שקלית עם קונצרני | O5: לא | P5: ILS | Q5: 2843030 | R5: 1 | S5: 134.08 | T5: 3811.9346 | U5: 0.0014542178 | V5: 0.30154947 | W5: 0.041733094
A6: 7891 | B6: 7897 | C6: מור ניהול קרנות נאמנות | D6: 514884485 | E6: ח.פ. | F6: מור כספית | G6: IL0051198138 | H6: ISIN | I6: אג"ח קונצרני | J6: ישראל | K6: ישראל | L6: סחיר | M6: TASE | N6: קרן כספית-כספית שקלית-כספית שקלית עם קונצרני | O6: לא | P6: ILS | Q6: 4028370 | R6: 1 | S6: 110.23 | T6: 4440.4722 | U6: 0.00087828585 | V6: 0.35127099 | W6: 0.04861433
A7: 7891 | B7: 7897 | C7: קסם קרנות נאמנות בע"מ | D7: 510938608 | E7: ח.פ. | F7: קסם אקטכספיתפט | G7: IL0051278815 | H7: ISIN | I7: אג"ח קונצרני | J7: ישראל | K7: ישראל | L7: סחיר | M7: TASE | N7: קרן כספית-כספית שקלית-כספית שקלית עם קונצרני | O7: לא | P7: ILS | Q7: 4014224.4 | R7: 1 | S7: 109.33 | T7: 4388.7515 | U7: 0.00044526165 | V7: 0.34717954 | W7: 0.04804809
A8: 11925 | B8: 11928 | C8: אלטשולר שחם ניהול קרנות | D8: 511944670 | E8: ח.פ. | F8: אלטש כספ לא קנצ | G8: IL0051058209 | H8: ISIN | I8: אג"ח קונצרני | J8: ישראל | K8: ישראל | L8: סחיר | M8: TASE | N8: קרן כספית-כספית שקלית-כספית שקלית ללא קונצרני | O8: לא | P8: ILS | Q8: 4042470 | R8: 1 | S8: 134.08 | T8: 5420.1438 | U8: 0.0020677347 | V8: 0.27918357 | W8: 0.041881144
A9: 11925 | B9: 11928 | C9: מור ניהול קרנות נאמנות | D9: 514884485 | E9: ח.פ. | F9: מור כספית | G9: IL0051198138 | H9: ISIN | I9: אג"ח קונצרני | J9: ישראל | K9: ישראל | L9: סחיר | M9: TASE | N9: קרן כספית-כספית שקלית-כספית שקלית עם קונצרני | O9: לא | P9: ILS | Q9: 5300320 | R9: 1 | S9: 110.23 | T9: 5842.5427 | U9: 0.0011556029 | V9: 0.30094071 | W9: 0.045144997
A10: 11925 | B10: 11928 | C10: קסם קרנות נאמנות בע"מ | D10: 510938608 | E10: ח.פ. | F10: קסם אקטכספיתפט | G10: IL0051278815 | H10: ISIN | I10: אג"ח קונצרני | J10: ישראל | K10: ישראל | L10: סחיר | M10: TASE | N10: קרן כספית-כספית שקלית-כספית שקלית עם קונצרני | O10: לא | P10: ILS | Q10: 7455939.2 | R10: 1 | S10: 109.33 | T10: 8151.5784 | U10: 0.00082702 | V10: 0.41987572 | W10: 0.062986784
A11: 11939 | B11: 11942 | C11: אלטשולר שחם ניהול קרנות | D11: 511944670 | E11: ח.פ. | F11: אלטש כספ לא קנצ | G11: IL0051058209 | H11: ISIN | I11: אג"ח קונצרני | J11: ישראל | K11: ישראל | L11: סחיר | M11: TASE | N11: קרן כספית-כספית שקלית-כספית שקלית ללא קונצרני | O11: לא | P11: ILS | Q11: 6960638 | R11: 1 | S11: 134.08 | T11: 9332.8234 | U11: 0.0035603857 | V11: 0.27623647 | W11: 0.033609704
A12: 11939 | B12: 11942 | C12: מור ניהול קרנות נאמנות | D12: 514884485 | E12: ח.פ. | F12: מור כספית | G12: IL0051198138 | H12: ISIN | I12: אג"ח קונצרני | J12: ישראל | K12: ישראל | L12: סחיר | M12: TASE | N12: קרן כספית-כספית שקלית-כספית שקלית עם קונצרני | O12: לא | P12: ILS | Q12: 7587682 | R12: 1 | S12: 110.23 | T12: 8363.9019 | U12: 0.0016543053 | V12: 0.24755796 | W12: 0.030120388
A13: 11939 | B13: 11942 | C13: הראל קרנות נאמנות בע"מ | D13: 511776783 | E13: ח.פ. | F13: הראל כס מגמ ריב | G13: IL0051277908 | H13: ISIN | I13: אג"ח קונצרני | J13: ישראל | K13: ישראל | L13: סחיר | M13: TASE | N13: קרן כספית-כספית שקלית-כספית שקלית עם קונצרני | O13: לא | P13: ILS | Q13: 835445 | R13: 1 | S13: 1095.57 | T13: 9152.8848 | U13: 5.3721063e-05 | V13: 0.27091057 | W13: 0.032961702
A14: 11939 | B14: 11942 | C14: קסם קרנות נאמנות בע"מ | D14: 510938608 | E14: ח.פ. | F14: קסם אקטכספיתפט | G14: IL0051278815 | H14: ISIN | I14: אג"ח קונצרני | J14: ישראל | K14: ישראל | L14: סחיר | M14: TASE | N14: קרן כספית-כספית שקלית-כספית שקלית עם קונצרני | O14: לא | P14: ILS | Q14: 6344115.4 | R14: 1 | S14: 109.33 | T14: 6936.0213 | U14: 0.00070369542 | V14: 0.205295 | W14: 0.024978253
A15: 11939 | B15: 11943 | C15: קסם קרנות נאמנות בע"מ | D15: 510938608 | E15: ח.פ. | F15: STX EURO600 קסם | G15: IL0051256126 | H15: ISIN | I15: מניות | J15: ישראל | K15: אירופה | L15: סחיר | M15: TASE | N15: מניות בחו"ל - מניות גיאוגרפי - חשופת מט"ח-אירופה - מדד אחר | O15: לא | P15: ILS | Q15: 52760 | R15: 1 | S15: 164.9 | T15: 87.00124 | U15: 0.00060396677 | V15: 1 | W15: 0.015070884
A16: 11939 | B16: 11944 | C16: BlackRock Advantage Eurore | D16: 549300MQT7YRWQ7R2C91 | E16: LEI | F16: BLKR ADV EUR X UK-D USD HDG | G16: IE00BFZP7J29 | H16: ISIN | I16: מניות | J16: חו"ל | K16: בריטניה | L16: סחיר | M16: NYSE | N16: Equity Funds | O16: לא | P16: USD | Q16: 776.17 | R16: 3.71 | S16: 20302.1 | T16: 584.61738 | U16: 0 | V16: 0.21526149 | W16: 0.025192956
A17: 11939 | B17: 11944 | C17: BlackRock Global Funds - Fixed | D17: 549300CNEUCVQC88OL03 | E17: LEI | F17: BGF-FIX INC GL OP-D2 USD | G17: LU0278469043 | H17: ISIN | I17: אג"ח קונצרני | J17: חו"ל | K17: ארה"ב | L17: סחיר | M17: NYSE | N17: Bond/Fixed Income Funds | O17: לא | P17: USD | Q17: 9665.44 | R17: 3.71 | S17: 1743 | T17: 625.01858 | U17: 0 | V17: 0.23013758 | W17: 0.026933967
A18: 11939 | B18: 11944 | C18: BlackRock Sustainable Advantag | D18: 5493002MQ0TZR3NYON05 | E18: LEI | F18: BLKRK ADV US EQ-D USD ACC | G18: IE00BFZP7V49 | H18: ISIN | I18: מניות | J18: חו"ל | K18: ארה"ב | L18: סחיר | M18: NYSE | N18: Equity Funds | O18: לא | P18: USD | Q18: 1357.09 | R18: 3.71 | S18: 22248.6 | T18: 1120.1734 | U18: 0 | V18: 0.41245813 | W18: 0.048271706
A19: 11939 | B19: 11944 | C19: BlackRock Funds I ICAV | D19: 549300CTIHAGMB3T0563 | E19: LEI | F19: BLCKRCK I ICAV TAC-D USD ACC | G19: IE00BK4PZV64 | H19: ISIN | I19: מניות | J19: חו"ל | K19: ארה"ב | L19: סחיר | M19: NYSE | N19: Equity Funds | O19: לא | P19: USD | Q19: 824.95 | R19: 3.71 | S19: 12613.3 | T19: 386.03818 | U19: 0 | V19: 0.1421428 | W19: 0.016635569
A20: 11939 | B20: 11980 | C20: אי.בי.אי קרנות נאמנות בעמ | D20: 513765339 | E20: ח.פ. | F20: IBI.יSHILLERUSמ | G20: IL0051346893 | H20: ISIN | I20: מניות | J20: ישראל | K20: ארה"ב | L20: סחיר | M20: TASE | N20: מניות בחו"ל - מניות גיאוגרפי - מנוטרלת מט"ח-ארה"ב - מדד אחר | O20: לא | P20: ILS | Q20: 184320 | R20: 1 | S20: 122.16 | T20: 225.16531 | U20: 0.00019456984 | V20: 1 | W20: 0.044755662
A21: 11939 | B21: 11981 | C21: אי.בי.אי קרנות נאמנות בעמ | D21: 513765339 | E21: ח.פ. | F21: IBI.יSHILLERUSמ | G21: IL0051346893 | H21: ISIN | I21: מניות | J21: ישראל | K21: ארה"ב | L21: סחיר | M21: TASE | N21: מניות בחו"ל - מניות גיאוגרפי - מנוטרלת מט"ח-ארה"ב - מדד אחר | O21: לא | P21: ILS | Q21: 71630 | R21: 1 | S21: 122.16 | T21: 87.50321 | U21: 7.5613269e-05 | V21: 1 | W21: 0.030379424
A22: 11342 | B22: 11343 | C22: אי.בי.אי קרנות נאמנות בעמ | D22: 513765339 | E22: ח.פ. | F22: SHILLERCUSי.IBI | G22: IL0051307374 | H22: ISIN | I22: מניות | J22: ישראל | K22: ארה"ב | L22: סחיר | M22: TASE | N22: מניות בחו"ל - מניות גיאוגרפי - חשופת מט"ח-ארה"ב - מדד אחר | O22: לא | P22: ILS | Q22: 4952705 | R22: 1 | S22: 228.09 | T22: 11296.625 | U22: 0.004476648 | V22: 1 | W22: 0.024489696
A23: 11342 | B23: 11344 | C23: אי.בי.אי קרנות נאמנות בעמ | D23: 513765339 | E23: ח.פ. | F23: IBI.SHILLER נ $ | G23: IL0051371792 | H23: ISIN | I23: מניות | J23: ישראל | K23: ארה"ב | L23: סחיר | M23: TASE | N23: מניות בחו"ל - מניות גיאוגרפי - חשופת מט"ח-ארה"ב - מדד אחר | O23: לא | P23: USD | Q23: 15273 | R23: 3.71 | S23: 127.9 | T23: 72.47176 | U23: 8.7881559e-05 | V23: 1 | W23: 0.022984448
A24: 11342 | B24: 11345 | C24: קסם קרנות נאמנות בע"מ | D24: 510938608 | E24: ח.פ. | F24: קסם SPHLTCAREממ | G24: IL0051360563 | H24: ISIN | I24: מניות | J24: ישראל | K24: ארה"ב | L24: סחיר | M24: TASE | N24: מניות בחו"ל - מניות לפי ענפים בחו"ל - מנוטרלת מט"ח-ענפים אחרים | O24: לא | P24: ILS | Q24: 3686 | R24: 1 | S24: 14266.15 | T24: 525.85029 | U24: 6.5697823e-05 | V24: 0.30804445 | W24: 0.026568232
A25: 11342 | B25: 11345 | C25: אי.בי.אי קרנות נאמנות בעמ | D25: 513765339 | E25: ח.פ. | F25: IBI.SHILLER נ $ | G25: IL0051371792 | H25: ISIN | I25: מניות | J25: ישראל | K25: ארה"ב | L25: סחיר | M25: TASE | N25: מניות בחו"ל - מניות גיאוגרפי - חשופת מט"ח-ארה"ב - מדד אחר | O25: לא | P25: USD | Q25: 248933 | R25: 3.71 | S25: 127.9 | T25: 1181.2095 | U25: 0.0014323722 | V25: 0.69195555 | W25: 0.059679814
A26: 7891 | B26: 7892
A27: 7891 | B27: 7893
A28: 7891 | B28: 7894
A29: 7891 | B29: 7896
A30: 7891 | B30: 7898
A31: 7891 | B31: 7899
A32: 7891 | B32: 7900
A33: 7891 | B33: 7901
A34: 7891 | B34: 7902
A35: 11925 | B35: 11926
A36: 11925 | B36: 11927
A37: 11925 | B37: 11929
... A52: 11939 | B52: 11979

Sheet כתבי אופציה
A1: מספר קופה/קרן/ח.פ. עבור חברת ביטוח | B1: מספר מסלול | C1: שם מנפיק | D1: מספר מנפיק | E1: סוג מספר מזהה מנפיק | F1: שם נייר ערך | G1: מספר נייר ערך | H1: סוג מספר נייר ערך | I1: ישראל/חו"ל | J1: מדינה לפי חשיפה כלכלית | K1: סטאטוס סחירות | L1: זירת מסחר | M1: נכס בסיס (כתב אופציה) | N1: ענף מסחר | O1: תאריך פקיעה | P1: בעל עניין/צד קשור | Q1: מטבע פעילות | R1: שער מימוש | S1: יחס המרה | T1: ערך נקוב (יחידות) | U1: שער חליפין | V1: שער נייר הערך | W1: שווי הוגן (באלפי ש"ח) | X1: שיעור מנכסי אפיק ההשקעה | Y1: שיעור מסך נכסי ההשקעה
A2: 7891 | B2: 7892
A3: 7891 | B3: 7893
A4: 7891 | B4: 7894
A5: 7891 | B5: 7895
A6: 7891 | B6: 7896
A7: 7891 | B7: 7897
A8: 7891 | B8: 7898
A9: 7891 | B9: 7899
A10: 7891 | B10: 7900
A11: 7891 | B11: 7901
A12: 7891 | B12: 7902
A13: 11925 | B13: 11926
... A39: 11342 | B39: 11345

Sheet אופציות
A1: מספר קופה/קרן/ח.פ. עבור חברת ביטוח | B1: מספר מסלול | C1: שם מנפיק | D1: מספר מנפיק | E1: סוג מספר מזהה מנפיק | F1: שם נייר ערך | G1: מספר נייר ערך | H1: סוג מספר נייר ערך | I1: מאפיין עיקרי | J1: ישראל/חו"ל | K1: מדינה לפי חשיפה כלכלית | L1: זירת מסחר | M1: ענף מסחר | N1: נכס בסיס | O1: תאריך פקיעה | P1: בעל עניין/צד קשור | Q1: מטבע פעילות | R1: שער מימוש | S1: ערך נקוב (יחידות) | T1: שער חליפין | U1: שער נייר הערך | V1: שווי הוגן (באלפי ש"ח) | W1: שיעור מנכסי אפיק ההשקעה | X1: שיעור מסך נכסי ההשקעה
A2: 7891 | B2: 7892
A3: 7891 | B3: 7893
A4: 7891 | B4: 7894
A5: 7891 | B5: 7895
A6: 7891 | B6: 7896
A7: 7891 | B7: 7897
A8: 7891 | B8: 7898
A9: 7891 | B9: 7899
A10: 7891 | B10: 7900
A11: 7891 | B11: 7901
A12: 7891 | B12: 7902
A13: 11925 | B13: 11926
... A39: 11342 | B39: 11345

Sheet חוזים עתידיים
A1: מספר קופה/קרן/ח.פ. עבור חברת ביטוח | B1: מספר מסלול | C1: שם מנפיק | D1: מספר מנפיק | E1: סוג מספר מזהה מנפיק | F1: שם נייר ערך | G1: מספר נייר ערך | H1: סוג מספר נייר ערך | I1: ישראל/חו"ל | J1: מדינה לפי חשיפה כלכלית | K1: זירת מסחר | L1: נכס בסיס | M1: בעל עניין/צד קשור | N1: מטבע פעילות | O1: ערך נקוב (יחידות) | P1: שער חליפין | Q1: שער נייר הערך | R1: שווי הוגן (באלפי ש"ח) | S1: שיעור מנכסי אפיק ההשקעה | T1: שיעור מסך נכסי ההשקעה
A2: 7891 | B2: 7892
A3: 7891 | B3: 7893
A4: 7891 | B4: 7894
A5: 7891 | B5: 7895
A6: 7891 | B6: 7896
A7: 7891 | B7: 7897
A8: 7891 | B8: 7898
A9: 7891 | B9: 7899
A10: 7891 | B10: 7900
A11: 7891 | B11: 7901
A12: 7891 | B12: 7902
A13: 11925 | B13: 11926
... A39: 11342 | B39: 11345

Sheet מוצרים מובנים
A1: מספר קופה/קרן/ח.פ. עבור חברת ביטוח | B1: מספר מסלול | C1: שם מנפיק | D1: מספר מנפיק | E1: סוג מספר מזהה מנפיק | F1: שם נייר ערך | G1: מספר נייר ערך | H1: סוג מספר נייר ערך | I1: מאפיין עיקרי | J1: ישראל/חו"ל | K1: מדינה לפי חשיפה כלכלית | L1: סטאטוס סחירות | M1: זירת מסחר | N1: נכס בסיס | O1: בעל עניין/צד קשור | P1: מח"מ | Q1: שיעור ריבית | R1: תשואה לפדיון | S1: דירוג | T1: שם מדרג | U1: דירוג נייר הערך/המנפיק | V1: מטבע פעילות | W1: ערך נקוב (יחידות) | X1: שער חליפין | Y1: שער נייר הערך | Z1: שווי הוגן (באלפי ש"ח) | AA1: שיעור מנכסי אפיק ההשקעה | AB1: שיעור מסך נכסי ההשקעה
A2: 7891 | B2: 7892
A3: 7891 | B3: 7893
A4: 7891 | B4: 7894
A5: 7891 | B5: 7895
A6: 7891 | B6: 7896
A7: 7891 | B7: 7897
A8: 7891 | B8: 7898
A9: 7891 | B9: 7899
A10: 7891 | B10: 7900
A11: 7891 | B11: 7901
A12: 7891 | B12: 7902
A13: 11925 | B13: 11926
... A39: 11342 | B39: 11345

Sheet לא סחיר איגרות חוב ממשלתיות
A1: מספר קופה/קרן/ח.פ. עבור חברת ביטוח | B1: מספר מסלול | C1: שם מנפיק | D1: שם נייר ערך | E1: מספר נייר ערך | F1: סוג מספר נייר ערך | G1: מאפיין עיקרי | H1: ישראל/חו"ל | I1: מדינה לפי חשיפה כלכלית | J1: תאריך רכישה | K1: דירוג | L1: שם מדרג | M1: מטבע פעילות | N1: מח"מ | O1: מועד פדיון | P1: שיעור ריבית | Q1: תשואה לפדיון | R1: ערך נקוב (יחידות) | S1: שער חליפין | T1: שער נייר הערך | U1: שווי הוגן (באלפי ש"ח) | V1: עלות מופחתת (באלפי ש"ח) | W1: השיטה שיושמה בדוח הכספי | X1: שיעור מנכסי אפיק ההשקעה | Y1: שיעור מסך נכסי ההשקעה
A2: 7891 | B2: 7892
A3: 7891 | B3: 7893
A4: 7891 | B4: 7894
A5: 7891 | B5: 7895
A6: 7891 | B6: 7896
A7: 7891 | B7: 7897
A8: 7891 | B8: 7898
A9: 7891 | B9: 7899
A10: 7891 | B10: 7900
A11: 7891 | B11: 7901
A12: 7891 | B12: 7902
A13: 11925 | B13: 11926
... A39: 11342 | B39: 11345

Sheet לא סחיר איגרות חוב מיועדות
A1: מספר קופה/קרן/ח.פ. עבור חברת ביטוח | B1: מספר מסלול | C1: מאפיין עיקרי | D1: שם נייר ערך | E1: מספר נייר ערך | F1: תאריך רכישה | G1: מח"מ | H1: סוג הצמדה | I1: מועד פדיון | J1: שיעור ריבית | K1: תשואה לפדיון | L1: ערך נקוב (יחידות) | M1: שער נייר הערך | N1: שווי הוגן (באלפי ש"ח) | O1: עלות מופחתת (באלפי ש"ח) | P1: השיטה שיושמה בדוח הכספי | Q1: שיעור מנכסי אפיק ההשקעה | R1: שיעור מסך נכסי ההשקעה
A2: 7891 | B2: 7892
A3: 7891 | B3: 7893
A4: 7891 | B4: 7894
A5: 7891 | B5: 7895
A6: 7891 | B6: 7896
A7: 7891 | B7: 7897
A8: 7891 | B8: 7898
A9: 7891 | B9: 7899
A10: 7891 | B10: 7900
A11: 7891 | B11: 7901
A12: 7891 | B12: 7902
A13: 11925 | B13: 11926
... A39: 11342 | B39: 11345

Sheet אפיק השקעה מובטח תשואה
A1: מספר קרן | B1: מספר מסלול | C1: מאפיין עיקרי | D1: חודש הנפקת שכבה | E1: חודש הבדיקה | F1: שווי הנכסים באפיק (באלפי ש"ח) | G1: שיעור מסך נכסי ההשקעה
A2: 7891 | B2: 7892
A3: 7891 | B3: 7893
A4: 7891 | B4: 7894
A5: 7891 | B5: 7895
A6: 7891 | B6: 7896
A7: 7891 | B7: 7897
A8: 7891 | B8: 7898
A9: 7891 | B9: 7899
A10: 7891 | B10: 7900
A11: 7891 | B11: 7901
A12: 7891 | B12: 7902
A13: 11925 | B13: 11926
... A39: 11342 | B39: 11345

Sheet לא סחיר ניירות ערך מסחריים
A1: מספר קופה/קרן/ח.פ. עבור חברת ביטוח | B1: מספר מסלול | C1: שם מנפיק | D1: מספר מנפיק | E1: סוג מספר מזהה מנפיק | F1: שם נייר ערך | G1: מספר נייר ערך | H1: סוג מספר נייר ערך | I1: מאפיין עיקרי | J1: ישראל/חו"ל | K1: מדינה לפי חשיפה כלכלית | L1: ענף מסחר | M1: בעל עניין/צד קשור | N1: תאריך רכישה | O1: דירוג | P1: שם מדרג | Q1: דירוג נייר הערך/המנפיק | R1: מטבע פעילות | S1: מח"מ | T1: סוג הצמדה | U1: ריבית עוגן | V1: מועד פדיון | W1: שיעור ריבית | X1: תשואה לפדיון | Y1: נחיתות חוזית | Z1: האם סווג כחוב בעייתי | AA1: סוג גורם משערך | AB1: תלות/אי-תלות המשערך | AC1: שם גורם משערך | AD1: תאריך שערוך אחרון | AE1: תאריך אחרון בו נבחנה בפועל ירידת ערך | AF1: ערך נקוב (יחידות) | AG1: שער חליפין | AH1: שער נייר הערך | AI1: שווי הוגן (באלפי ש"ח) | AJ1: עלות מופחתת (באלפי ש"ח) | AK1: עלות מופחתת (במטבע הפעילות) | AL1: השיטה שיושמה בדוח הכספי | AM1: שיעור מנכסי אפיק ההשקעה | AN1: שיעור מסך נכסי ההשקעה
A2: 7891 | B2: 7892
A3: 7891 | B3: 7893
A4: 7891 | B4: 7894
A5: 7891 | B5: 7895
A6: 7891 | B6: 7896
A7: 7891 | B7: 7897
A8: 7891 | B8: 7898
A9: 7891 | B9: 7899
A10: 7891 | B10: 7900
A11: 7891 | B11: 7901
A12: 7891 | B12: 7902
A13: 11925 | B13: 11926
... A39: 11342 | B39: 11345

Sheet לא סחיר איגרות חוב
A1: מספר קופה/קרן/ח.פ. עבור חברת ביטוח | B1: מספר מסלול | C1: שם מנפיק | D1: מספר מנפיק | E1: סוג מספר מזהה מנפיק | F1: שם נייר ערך | G1: מספר נייר ערך | H1: סוג מספר נייר ערך | I1: מאפיין עיקרי | J1: ישראל/חו"ל | K1: מדינה לפי חשיפה כלכלית | L1: סטאטוס סחירות | M1: ענף מסחר | N1: בעל עניין/צד קשור | O1: תאריך רכישה | P1: דירוג | Q1: שם מדרג | R1: דירוג נייר הערך/המנפיק | S1: מטבע פעילות | T1: מח"מ | U1: מועד פדיון | V1: תשואה לפדיון | W1: שיעור ריבית | X1: נחיתות חוזית | Y1: האם סווג כחוב בעייתי | Z1: סוג גורם משערך | AA1: תלות/אי-תלות המשערך | AB1: תאריך שערוך אחרון | AC1: תאריך אחרון בו נבחנה בפועל ירידת ערך | AD1: ערך נקוב (יחידות) | AE1: שער חליפין | AF1: שער נייר הערך | AG1: שווי הוגן (באלפי ש"ח) | AH1: עלות מופחתת (באלפי ש"ח) | AI1: עלות מופחתת (במטבע הפעילות) | AJ1: השיטה שיושמה בדוח הכספי | AK1: שיעור מנכסי אפיק ההשקעה | AL1: שיעור מסך נכסי ההשקעה
A2: 7891 | B2: 7892
A3: 7891 | B3: 7893
A4: 7891 | B4: 7894
A5: 7891 | B5: 7895
A6: 7891 | B6: 7896
A7: 7891 | B7: 7897
A8: 7891 | B8: 7898
A9: 7891 | B9: 7899
A10: 7891 | B10: 7900
A11: 7891 | B11: 7901
A12: 7891 | B12: 7902
A13: 11925 | B13: 11926
... A39: 11342 | B39: 11345

Sheet לא סחיר מניות מבכ ויהש
A1: מספר קופה/קרן/ח.פ. עבור חברת ביטוח | B1: מספר מסלול | C1: שם מנפיק | D1: מספר מנפיק | E1: סוג מספר מזהה מנפיק | F1: שם נייר ערך | G1: מספר נייר ערך | H1: סוג מספר נייר ערך | I1: מאפיין עיקרי | J1: ישראל/חו"ל | K1: מדינה לפי חשיפה כלכלית | L1: סטאטוס סחירות | M1: ענף מסחר | N1: בעל עניין/צד קשור | O1: תאריך רכישה | P1: מטבע פעילות | Q1: סוג גורם משערך | R1: תלות/אי-תלות המשערך | S1: תאריך שערוך אחרון | T1: תאריך אחרון בו נבחנה בפועל ירידת ערך | U1: ערך נקוב (יחידות) | V1: שער חליפין | W1: שער נייר הערך | X1: שווי הוגן (באלפי ש"ח) | Y1: שיעור מנכסי אפיק ההשקעה | Z1: שיעור מסך נכסי ההשקעה
A2: 7891 | B2: 7892
A3: 7891 | B3: 7893
A4: 7891 | B4: 7894
A5: 7891 | B5: 7895
A6: 7891 | B6: 7896
A7: 7891 | B7: 7897
A8: 7891 | B8: 7898
A9: 7891 | B9: 7899
A10: 7891 | B10: 7900
A11: 7891 | B11: 7901
A12: 7891 | B12: 7902
A13: 11925 | B13: 11926
... A39: 11342 | B39: 11345

Sheet קרנות השקעה
A1: מספר קופה/קרן/ח.פ. עבור חברת ביטוח | B1: מספר מסלול | C1: שם שותף כללי קרן השקעות | D1: מספר מזהה שותף כללי קרן השקעות | E1: סוג מספר מזהה שותף כללי קרן השקעות | F1: שם קרן השקעה | G1: מספר מזהה קרן השקעה | H1: סוג מספר מזהה קרן השקעות | I1: מאפיין עיקרי | J1: אסטרטגיית קרן ההשקעה | K1: ישראל/חו"ל | L1: מדינת התאגדות קרן השקעה | M1: מיקום משרד השותף הכללי | N1: מדינה לפי חשיפה כלכלית | O1: בעל עניין/צד קשור | P1: תאריך רכישה | Q1: מטבע פעילות | R1: סוג גורם משערך | S1: תלות/אי-תלות המשערך | T1: תאריך שערוך אחרון | U1: שער חליפין | V1: NAV (במטבע הדיווח של קרן ההשקעה) | W1: שווי הוגן (באלפי ש"ח) | X1: שיעור החזקה בקרן השקעה | Y1: שיעור מנכסי אפיק ההשקעה | Z1: שיעור מסך נכסי ההשקעה
A2: 7891 | B2: 7897 | C2: Stepstone | F2: Stepstone_SCL E | G2: 11017960 | H2: פנימי | I2: קרן חוב | K2: חו"ל | N2: אירופה | O2: לא | P2: 43661 | Q2: EUR | R2: דיווח מנהל הקרן | S2: אי-תלות | T2: 45565 | U2: 4.1524 | V2: 1369.0646 | W2: 5684.9039 | X2: 0.0056397314 | Y2: 0.37379764 | Z2: 0.062238378
A3: 7891 | B3: 7897 | C3: Stepstone | F3: SCL Enhanched $ | G3: 11017989 | H3: פנימי | I3: קרן חוב | K3: חו"ל | N3: אירופה | O3: לא | P3: 43718 | Q3: USD | R3: דיווח מנהל הקרן | S3: אי-תלות | T3: 45565 | U3: 3.71 | V3: 462.94651 | W3: 1717.5315 | X3: 0.0029774805 | Y3: 0.11293229 | Z3: 0.018803551
A4: 7891 | B4: 7897 | C4: פניקס קפיטל/פולן | F4: POLLEN FUND | G4: 11019167 | H4: פנימי | I4: קרן חוב | K4: חו"ל | N4: ארה"ב | O4: לא | P4: 44404 | Q4: USD | R4: דיווח מנהל הקרן | S4: אי-תלות | T4: 45565 | U4: 3.71 | V4: 1419.7316 | W4: 5267.2044 | X4: 0.0654 | Y4: 0.34633278 | Z4: 0.057665401
A5: 7891 | B5: 7897 | C5: Ares Real Estate Enhanced Income Advisors LLC | F5: Ares Real Estat | G5: 11019503 | H5: פנימי | I5: קרן חוב | K5: חו"ל | N5: ארה"ב | O5: לא | P5: 44655 | Q5: USD | R5: דיווח מנהל הקרן | S5: אי-תלות | T5: 45565 | U5: 3.71 | V5: 674.05511 | W5: 2500.7445 | X5: 0.025 | Y5: 0.16443064 | Z5: 0.027378173
