Workbook
Name Additional_Factor: 'אפשרויות בחירה'!$C$701:$C$850
Name Amoritization: 'אפשרויות בחירה'!$C$546:$C$550
Name Capsule: 'אפשרויות בחירה'!$C$926:$C$928
Name Company_Name: 'File Name Info'!$A$34:$A$120
Name Company_Name_ID: 'File Name Info'!$A$34:$B$120
Name Consortium: 'אפשרויות בחירה'!$C$514:$C$515
Name Country_list: 'אפשרויות בחירה'!$C$4:$C$85
Name Country_list_funds: 'אפשרויות בחירה'!$C$4:$C$103
Name CSA: 'אפשרויות בחירה'!$C$688:$C$689
Name Delivery: 'אפשרויות בחירה'!$C$666:$C$667
Name Dependence_Independence: 'אפשרויות בחירה'!$C$654:$C$655
Name Duration_Underlying_Interest_Rate: 'אפשרויות בחירה'!$C$680:$C$687
Name File_Type: 'File Name Info'!$A$10:$A$12
Name Full_File_Type: 'File Name Info'!$A$11:$B$13
Name Full_Type: 'File Name Info'!$A$2:$B$8
Name Full_Type_Nostro: 'File Name Info'!$A$3:$B$6
Name Full_Year: 'File Name Info'!$A$22:$B$31
Name Fund_Strategy: 'אפשרויות בחירה'!$C$597:$C$621
Name Fund_type: 'אפשרויות בחירה'!$C$328:$C$498
Name Holding_interest: 'אפשרויות בחירה'!$C$146:$C$147
Name In_the_books: 'אפשרויות בחירה'!$C$656:$C$657
Name Industry_Sector: 'אפשרויות בחירה'!$C$1129:$C$1245
Name Industry_sector_all: 'אפשרויות בחירה'!$C$202:$C$327
Name Industry_sectors: 'אפשרויות בחירה'!$C$202:$C$327
Name israel_abroad: 'אפשרויות בחירה'!$C$2:$C$3
Name Issuer_Number_Banks: 'אפשרויות בחירה'!$C$111:$C$113
Name Issuer_Number_Fund: 'אפשרויות בחירה'!$C$114:$C$117
Name issuer_number_loan: 'אפשרויות בחירה'!$C$118:$C$126
Name Issuer_Number_Type: 'אפשרויות בחירה'!$C$104:$C$110
Name Issuer_Number_Type_2: 'אפשרויות בחירה'!$C$1076:$C$1079
Name Issuer_Number_Type_3: 'אפשרויות בחירה'!$C$1081:$C$1085
Name Issuer_Number_Type_V2: 'אפשרויות בחירה'!$C$104:$C$110
Name Issuer_Type_TFunds: 'אפשרויות בחירה'!$C$1087:$C$1089
Name Leading_factor: 'אפשרויות בחירה'!$C$692:$C$700
Name Linked_Type: 'אפשרויות בחירה'!$C$516:$C$519
Name other_investments: 'אפשרויות בחירה'!$C$1000:$C$1033
Name Penalty: 'אפשרויות בחירה'!$C$851:$C$852
Name QTR: 'File Name Info'!$A$15:$A$19
Name Rating_Agency: 'אפשרויות בחירה'!$C$188:$C$201
Name real_estate_lifestage: 'אפשרויות בחירה'!$C$634:$C$642
Name real_estate_loans: 'אפשרויות בחירה'!$C$553:$C$591
Name Real_Estate_Main_Use: 'אפשרויות בחירה'!$C$622:$C$633
Name Recourse_Nonrecourse: 'אפשרויות בחירה'!$C$544:$C$545
Name Repayment_Rights: 'אפשרויות בחירה'!$C$551:$C$552
Name Reset_frequency: 'אפשרויות בחירה'!$C$658:$C$665
Name Security_ID_Number_Type: 'אפשרויות בחירה'!$C$1113:$C$1116
Name Security_Number_Loans: 'אפשרויות בחירה'!$C$131
Name Stock_Exchange: 'אפשרויות בחירה'!$C$1283:$C$1315
Name Stock_Exchange_Gov_Bonds: 'אפשרויות בחירה'!$C$148:$C$181
Name Subordination_Risk: 'אפשרויות בחירה'!$C$186:$C$187
Name Tradeable_Status: 'אפשרויות בחירה'!$C$1272:$C$1281
Name Tradeable_Status_All: 'אפשרויות בחירה'!$C$135:$C$145
Name tradeable_status_bonds: 'אפשרויות בחירה'!$C$1248:$C$1253
Name tradeable_status_funds: 'אפשרויות בחירה'!$C$1118:$C$1119
Name tradeable_status_stock: 'אפשרויות בחירה'!$C$1255:$C$1259
Name Tradeable_Status_v2: 'אפשרויות בחירה'!$C$1121:$C$1126
Name tradeable_status_warrants: 'אפשרויות בחירה'!$C$1261:$C$1265
Name tradeable_status_warrants_v2: 'אפשרויות בחירה'!$C$1267:$C$1269
Name Transaction: 'אפשרויות בחירה'!$C$643:$C$646
Name Type: 'File Name Info'!$A$2:$A$8

Sheet עמוד פתיחה
A1: קובץ דיווח עבור רשימת נכסים ברמת הנכס הבודד (חוזר גופים מוסדיים 2015-9-14)
A3: יש לבחור תחום: | D3: נכסי מבוטחים - חברת ביטוח
A5: האם מדובר בקובץ לממומנה או לציבור: | D5: לציבור
A7: יש לבחור את רבעון הדיווח: | D7: 03
A9: יש לבחור את שנת הדיווח: | D9: 2024
A11: יש לבחור את הגוף המוסדי: | D11: הכשרה חברה לביטוח בע"מ
A13: ח.פ. הגוף המוסדי: | D13: =IFERROR(VLOOKUP(D11,'File Name Info'!A35:B121,2,0),"תא מחושב") -> 520042177
A15: שם קובץ לשמירה | D15: =IF(D5="לממונה",CONCATENATE(D13, "_",VLOOKUP(D3,Full_Type,2,0),"_",D7,VLOOKUP(D9,Full_Year,2,0),".xlxs"),IF(D5="לציבור",CONCATENATE(D13,"_",VLOOKUP(D3,Full_Type_Nostro,2,0),"_",VLOOKUP(D5,Full_File_Type,2,0),"_",D7,VLOOKUP(D9,Full_Year,2,0),".xlsx"),"שם קובץ לשמירה")) -> 520042177_in_p_0324.xlsx
A17: פרטי האחראי על הדיווח בגוף המוסדי | B17: שם: | D17: ליזה שלו
B19: מספר טלפון: | D19: 03-7962110
B21: כתובת מייל: | D21: lizas@hcsra.co.il
A23: הוראות למילוי הדיווח: | D23: יש לדווח לפי ההנחיות בחלק ג' לנספח 5.4.3.2 שבפרק 3 שבחלק 4 לשער 5 בחוזר המאוחד - "רשימת נכסים ברמת הנכס הבודד".

Sheet סכום נכסים
C1: ידווח בקבצי נכסי הנוסטרו בלבד
B2: שווי הוגן | C2: עלות מופחתת | D2: השיטה שיושמה בדוח הכספי | E2: שיעור מסך נכסי השקעה
A3: מזומנים ושווי מזומנים | B3: =SUM('מזומנים ושווי מזומנים'!O:O) -> 2084238.4 | E3: 0.08464
A4: איגרות חוב ממשלתיות | B4: 7520912.2 | E4: 0.3101
A5: ניירות ערך מסחריים | B5: 4061.68 | E5: 0.00017
A6: איגרות חוב | B6: 2722894.4 | E6: 0.11227
A7: מניות, מניות בכורה ויחידות השתתפות | B7: =SUM('מניות מבכ ויהש'!U:U) -> 3123900.7 | E7: 0.1288
A8: קרנות סל | B8: =SUM('קרנות סל'!T:T) -> 5013340.2 | E8: 0.20671
A9: קרנות נאמנות | B9: 812167.06 | E9: 0.03349
A10: כתבי אופציה | B10: 1374.08 | E10: 6e-05
A11: אופציות | B11: 211.802 | E11: 1e-05
A12: חוזים עתידיים | B12: 71535.546 | E12: 0.00295
A13: מוצרים מובנים
A14: לא סחיר איגרות חוב ממשלתיות
A15: לא סחיר איגרות חוב מיועדות | B15: 22310.024 | E15: 0.00092
A16: אפיק השקעה מובטח תשואה
A17: לא סחיר ניירות ערך מסחריים | B17: 24711.457 | E17: 0.00102
A18: לא סחיר איגרות חוב | B18: 157337.56 | E18: 0.00649
A19: לא סחיר מניות, מניות בכורה ויחידות השתתפות | B19: 445131.6 | E19: 0.01835
A20: קרנות השקעה | B20: 1622866.9 | E20: 0.06691
A21: לא סחיר כתבי אופציה | B21: 5684 | E21: 0.00023
A22: לא סחיר אופציות
A23: לא סחיר נגזרים אחרים | B23: =SUM('לא סחיר נגזרים אחרים'!R:R) -> -26609.275 | E23: -0.00119
A24: הלוואות | B24: 282669.06 | E24: 0.01166
A25: לא סחיר מוצרים מובנים
A26: פיקדונות מעל 3 חודשים | B26: 31274.332 | E26: 0.00129
A27: זכויות מקרקעין | B27: 366760 | E27: 0.01512
A28: השקעה בחברות מוחזקות
A29: נכסים אחרים
A30: סך הכל נכסים | B30: =SUM(B3:B29) -> 24286772 | C30: =SUM(C3:C29) -> 0 | D30: =SUM(D3:D29) -> 0 | E30: =SUM(E3:E29) -> 1
A31: מסגרות אשראי
A32: יתרות התחייבויות להשקעה | B32: =SUM('יתרות התחייבות להשקעה'!O:O) -> 356511.06 | E32: =B32/B30 -> 0.014679228

Sheet מזומנים ושווי מזומנים
A1: מספר קופה/קרן/ח.פ. עבור חברת ביטוח | B1: מספר מסלול | C1: שם הבנק | D1: מספר מזהה בנק | E1: סוג מספר מזהה בנק | F1: מאפיין עיקרי | G1: ישראל/חו"ל | H1: בעל עניין/צד קשור | I1: דירוג הבנק | J1: שם מדרג | K1: מטבע פעילות | L1: שווי מטבעי | M1: שער חליפין | N1: שיעור ריבית | O1: שווי הוגן (באלפי ש"ח) | P1: שיעור מנכסי אפיק ההשקעה | Q1: שיעור מסך נכסי ההשקעה
A2: 520042177 | B2: 12936 | C2: בנק מזרחי | D2: 20-61 | E2: סימול בנק | F2: מזומן ועו"ש בש"ח | G2: ישראל | H2: לא | I2: Aaa.il | J2: מידרוג Moodys | K2: ILS | L2: =1765.579+178.583890000009 -> 1944.1629 | M2: 1 | N2: 0.04 | O2: =L2 -> 1944.1629 | P2: =O2/SUMIF(B:B,B2,O:O) -> 0.8460081 | Q2: 0.018272656
A3: 520042177 | B3: 12936 | C3: בנק מזרחי | D3: 20-61 | E3: סימול בנק | F3: מזומן ועו"ש נקוב במט"ח | G3: ישראל | H3: לא | I3: ilAAA | J3: S&P מעלות | K3: USD | L3: 4.555 | M3: 3.71 | N3: 0.0474 | O3: 16.899 | P3: =O3/SUMIF(B:B,B3,O:O) -> 0.0073536487 | Q3: 0.00015882908
A4: 520042177 | B4: 12936 | C4: בנק מזרחי | D4: 20-61 | E4: סימול בנק | F4: בטחונות שוטפים | G4: חו"ל | H4: לא | I4: Aaa.il | J4: מידרוג Moodys | K4: USD | L4: 90.831 | M4: 3.71 | N4: 0.045 | O4: 336.981 | P4: =O4/SUMIF(B:B,B4,O:O) -> 0.14663826 | Q4: 0.0031671924
A5: 520042177 | B5: 12937 | C5: בנק מזרחי | D5: 20-61 | E5: סימול בנק | F5: מזומן ועו"ש נקוב במט"ח | G5: ישראל | H5: לא | I5: ilAAA | J5: S&P מעלות | K5: USD | L5: 14572.909 | M5: 3.71 | N5: 0.0474 | O5: 54065.492 | P5: =O5/SUMIF(B:B,B5,O:O) -> 0.43911083 | Q5: 0.050027142
A6: 520042177 | B6: 12937 | C6: בנק מזרחי | D6: 20-61 | E6: סימול בנק | F6: מזומן ועו"ש בש"ח | G6: ישראל | H6: לא | I6: Aaa.il | J6: מידרוג Moodys | K6: ILS | L6: =43251.25+924.830700000049 -> 44176.081 | M6: 1 | N6: 0.04 | O6: =L6 -> 44176.081 | P6: =O6/SUMIF(B:B,B6,O:O) -> 0.3587907 | Q6: 0.040876407
A7: 520042177 | B7: 12937 | C7: בנק מזרחי | D7: 20-61 | E7: סימול בנק | F7: מזומן ועו"ש נקוב במט"ח | G7: ישראל | H7: לא | I7: ilAAA | J7: S&P מעלות | K7: EUR | L7: 959.087 | M7: 4.152 | N7: 0.0306 | O7: 3982.514 | P7: =O7/SUMIF(B:B,B7,O:O) -> 0.032345309 | Q7: 0.0036850454
A8: 520042177 | B8: 12937 | C8: בנק מזרחי | D8: 20-61 | E8: סימול בנק | F8: מזומן ועו"ש נקוב במט"ח | G8: ישראל | H8: לא | I8: Aaa.il | J8: מידרוג Moodys | K8: CHF | L8: 0.083 | M8: 4.397 | N8: 0 | O8: 0.363 | P8: =O8/SUMIF(B:B,B8,O:O) -> 2.9482249e-06 | Q8: 3.358862e-07
A9: 520042177 | B9: 12937 | C9: בנק מזרחי | D9: 20-61 | E9: סימול בנק | F9: בטחונות שוטפים | G9: חו"ל | H9: לא | I9: Aaa.il | J9: מידרוג Moodys | K9: USD | L9: 5233.337 | M9: 3.71 | N9: 0.045 | O9: 19415.681 | P9: =O9/SUMIF(B:B,B9,O:O) -> 0.1576909 | Q9: 0.017965453
A10: 520042177 | B10: 12937 | C10: בנק מזרחי | D10: 20-61 | E10: סימול בנק | F10: בטחונות שוטפים | G10: חו"ל | H10: לא | I10: Aaa.il | J10: מידרוג Moodys | K10: EUR | L10: 357.577 | M10: 4.152 | N10: 0.0273 | O10: 1484.803 | P10: =O10/SUMIF(B:B,B10,O:O) -> 0.01205932 | Q10: 0.0013738976
A11: 520042177 | B11: 12938 | C11: בנק מזרחי | D11: 20-61 | E11: סימול בנק | F11: מזומן ועו"ש בש"ח | G11: ישראל | H11: לא | I11: Aaa.il | J11: מידרוג Moodys | K11: ILS | L11: =7417.587+61.5857900000119 -> 7479.1728 | M11: 1 | N11: 0.04 | O11: =L11 -> 7479.1728 | P11: =O11/SUMIF(B:B,B11,O:O) -> 0.42396375 | Q11: 0.03293345
A12: 520042177 | B12: 12938 | C12: בנק מזרחי | D12: 20-61 | E12: סימול בנק | F12: מזומן ועו"ש נקוב במט"ח | G12: ישראל | H12: לא | I12: ilAAA | J12: S&P מעלות | K12: USD | L12: 630.285 | M12: 3.71 | N12: 0.0474 | O12: 2338.358 | P12: =O12/SUMIF(B:B,B12,O:O) -> 0.13255196 | Q12: 0.01029662
A13: 520042177 | B13: 12938 | C13: בנק מזרחי | D13: 20-61 | E13: סימול בנק | F13: מזומן ועו"ש נקוב במט"ח | G13: ישראל | H13: לא | I13: ilAAA | J13: S&P מעלות | K13: EUR | L13: 191.838 | M13: 4.152 | N13: 0.0306 | O13: 796.586 | P13: =O13/SUMIF(B:B,B13,O:O) -> 0.045155206 | Q13: 0.0035076507
A14: 520042177 | B14: 12938 | C14: בנק מזרחי | D14: 20-61 | E14: סימול בנק | F14: בטחונות שוטפים | G14: חו"ל | H14: לא | I14: Aaa.il | J14: מידרוג Moodys | K14: USD | L14: 1576.39 | M14: 3.71 | N14: 0.045 | O14: 5848.406 | P14: =O14/SUMIF(B:B,B14,O:O) -> 0.33152224 | Q14: 0.025752606
A15: 520042177 | B15: 12938 | C15: בנק מזרחי | D15: 20-61 | E15: סימול בנק | F15: בטחונות שוטפים | G15: חו"ל | H15: לא | I15: Aaa.il | J15: מידרוג Moodys | K15: EUR | L15: 283.822 | M15: 4.152 | N15: 0.0273 | O15: 1178.544 | P15: =O15/SUMIF(B:B,B15,O:O) -> 0.066806844 | Q15: 0.0051895472
A16: 520042177 | B16: 13498 | C16: בנק מזרחי | D16: 20-61 | E16: סימול בנק | F16: מזומן ועו"ש בש"ח | G16: ישראל | H16: לא | I16: Aaa.il | J16: מידרוג Moodys | K16: ILS | L16: =53762.465+118.273149999906 -> 53880.738 | M16: 1 | N16: 0.04 | O16: =L16 -> 53880.738 | P16: =O16/SUMIF(B:B,B16,O:O) -> 0.90155552 | Q16: 0.0676231
A17: 520042177 | B17: 13498 | C17: בנק מזרחי | D17: 20-61 | E17: סימול בנק | F17: מזומן ועו"ש נקוב במט"ח | G17: ישראל | H17: לא | I17: ilAAA | J17: S&P מעלות | K17: USD | L17: 319.663 | M17: 3.71 | N17: 0.0474 | O17: 1185.95 | P17: =O17/SUMIF(B:B,B17,O:O) -> 0.019843822 | Q17: 0.0014884283
A18: 520042177 | B18: 13498 | C18: בנק מזרחי | D18: 20-61 | E18: סימול בנק | F18: מזומן ועו"ש נקוב במט"ח | G18: ישראל | H18: לא | I18: ilAAA | J18: S&P מעלות | K18: EUR | L18: 0.5 | M18: 4.152 | N18: 0.0306 | O18: 2.075 | P18: =O18/SUMIF(B:B,B18,O:O) -> 3.4719786e-05 | Q18: 2.6042318e-06
A19: 520042177 | B19: 13498 | C19: בנק מזרחי | D19: 20-61 | E19: סימול בנק | F19: בטחונות שוטפים | G19: חו"ל | H19: לא | I19: Aaa.il | J19: מידרוג Moodys | K19: USD | L19: 1265.615 | M19: 3.71 | N19: 0.045 | O19: 4695.43 | P19: =O19/SUMIF(B:B,B19,O:O) -> 0.07856594 | Q19: 0.0058930064
A20: 520042177 | B20: 13499 | C20: בנק מזרחי | D20: 20-61 | E20: סימול בנק | F20: מזומן ועו"ש בש"ח | G20: ישראל | H20: לא | I20: Aaa.il | J20: מידרוג Moodys | K20: ILS | L20: =394.269-35.8783700000022 -> 358.39063 | M20: 1 | N20: 0.04 | O20: =L20 -> 358.39063 | P20: =O20/SUMIF(B:B,B20,O:O) -> 0.95865428 | Q20: 0.011368991
A21: 520042177 | B21: 13499 | C21: בנק מזרחי | D21: 20-61 | E21: סימול בנק | F21: מזומן ועו"ש נקוב במט"ח | G21: ישראל | H21: לא | I21: ilAAA | J21: S&P מעלות | K21: USD | L21: 4.166 | M21: 3.71 | N21: 0.0474 | O21: 15.457 | P21: =O21/SUMIF(B:B,B21,O:O) -> 0.041345722 | Q21: 0.00049033226
A22: 520042177 | B22: 13500 | C22: בנק מזרחי | D22: 20-61 | E22: סימול בנק | F22: מזומן ועו"ש בש"ח | G22: ישראל | H22: לא | I22: Aaa.il | J22: מידרוג Moodys | K22: ILS | L22: =19289.376+1205.91317000001 -> 20495.289 | M22: 1 | N22: 0.04 | O22: =L22 -> 20495.289 | P22: =O22/SUMIF(B:B,B22,O:O) -> 0.80594198 | Q22: 0.068932415
A23: 520042177 | B23: 13500 | C23: בנק מזרחי | D23: 20-61 | E23: סימול בנק | F23: מזומן ועו"ש נקוב במט"ח | G23: ישראל | H23: לא | I23: ilAAA | J23: S&P מעלות | K23: USD | L23: 57.382 | M23: 3.71 | N23: 0.0474 | O23: 212.887 | P23: =O23/SUMIF(B:B,B23,O:O) -> 0.0083714149 | Q23: 0.00071600917
A24: 520042177 | B24: 13500 | C24: בנק מזרחי | D24: 20-61 | E24: סימול בנק | F24: מזומן ועו"ש נקוב במט"ח | G24: ישראל | H24: לא | I24: ilAAA | J24: S&P מעלות | K24: EUR | L24: 2.334 | M24: 4.152 | N24: 0.0306 | O24: 9.693 | P24: =O24/SUMIF(B:B,B24,O:O) -> 0.00038116054 | Q24: 3.2600755e-05
A25: 520042177 | B25: 13500 | C25: בנק מזרחי | D25: 20-61 | E25: סימול בנק | F25: בטחונות שוטפים | G25: חו"ל | H25: לא | I25: Aaa.il | J25: מידרוג Moodys | K25: USD | L25: 1270.178 | M25: 3.71 | N25: 0.045 | O25: 4712.36 | P25: =O25/SUMIF(B:B,B25,O:O) -> 0.18530545 | Q25: 0.01584922
A26: 520042177 | B26: 141 | C26: בנק מזרחי | D26: 20-61 | E26: סימול בנק | F26: מזומן ועו"ש בש"ח | G26: ישראל | H26: לא | I26: Aaa.il | J26: מידרוג Moodys | K26: ILS | L26: =7071.388+1026.88323000003 -> 8098.2712 | M26: 1 | N26: 0.04 | O26: =L26 -> 8098.2712 | P26: =O26/SUMIF(B:B,B26,O:O) -> 0.65584776 | Q26: 0.021732935
A27: 520042177 | B27: 141 | C27: בנק מזרחי | D27: 20-61 | E27: סימול בנק | F27: מזומן ועו"ש נקוב במט"ח | G27: ישראל | H27: לא | I27: ilAAA | J27: S&P מעלות | K27: USD | L27: 5.387 | M27: 3.71 | N27: 0.0474 | O27: 19.986 | P27: =O27/SUMIF(B:B,B27,O:O) -> 0.0016185891 | Q27: 5.3635452e-05
A28: 520042177 | B28: 141 | C28: בנק מזרחי | D28: 20-61 | E28: סימול בנק | F28: מזומן ועו"ש נקוב במט"ח | G28: ישראל | H28: לא | I28: ilAAA | J28: S&P מעלות | K28: EUR | L28: 0.095 | M28: 4.152 | N28: 0.0306 | O28: 0.394 | P28: =O28/SUMIF(B:B,B28,O:O) -> 3.1908541e-05 | Q28: 1.0573586e-06
A29: 520042177 | B29: 141 | C29: בנק מזרחי | D29: 20-61 | E29: סימול בנק | F29: בטחונות שוטפים | G29: חו"ל | H29: לא | I29: Aaa.il | J29: מידרוג Moodys | K29: USD | L29: 1139.93 | M29: 3.71 | N29: 0.045 | O29: 4229.14 | P29: =O29/SUMIF(B:B,B29,O:O) -> 0.34250174 | Q29: 0.011349537
A30: 520042177 | B30: 142 | C30: בנק מזרחי | D30: 20-61 | E30: סימול בנק | F30: מזומן ועו"ש בש"ח | G30: ישראל | H30: לא | I30: Aaa.il | J30: מידרוג Moodys | K30: ILS | L30: =75647.115+1562.70276999997 -> 77209.818 | M30: 1 | N30: 0.04 | O30: =L30 -> 77209.818 | P30: =O30/SUMIF(B:B,B30,O:O) -> 0.75627439 | Q30: 0.11826302
A31: 520042177 | B31: 142 | C31: בנק מזרחי | D31: 20-61 | E31: סימול בנק | F31: מזומן ועו"ש נקוב במט"ח | G31: ישראל | H31: לא | I31: ilAAA | J31: S&P מעלות | K31: EUR | L31: 1651.805 | M31: 4.152 | N31: 0.0306 | O31: 6858.953 | P31: =O31/SUMIF(B:B,B31,O:O) -> 0.06718382 | Q31: 0.010505924
A32: 520042177 | B32: 142 | C32: בנק מזרחי | D32: 20-61 | E32: סימול בנק | F32: מזומן ועו"ש נקוב במט"ח | G32: ישראל | H32: לא | I32: ilAAA | J32: S&P מעלות | K32: USD | L32: 528.857 | M32: 3.71 | N32: 0.0474 | O32: 1962.061 | P32: =O32/SUMIF(B:B,B32,O:O) -> 0.019218495 | Q32: 0.0030053077
A33: 520042177 | B33: 142 | C33: בנק מזרחי | D33: 20-61 | E33: סימול בנק | F33: מזומן ועו"ש נקוב במט"ח | G33: ישראל | H33: לא | I33: ilAAA | J33: S&P מעלות | K33: NOK | L33: 2416.106 | M33: 0.352 | N33: 0 | O33: 851.436 | P33: =O33/SUMIF(B:B,B33,O:O) -> 0.0083398622 | Q33: 0.0013041527
A34: 520042177 | B34: 142 | C34: בנק מזרחי | D34: 20-61 | E34: סימול בנק | F34: מזומן ועו"ש נקוב במט"ח | G34: ישראל | H34: לא | I34: ilAAA | J34: S&P מעלות | K34: GBP | L34: 16.53 | M34: 4.975 | N34: 0 | O34: 82.233 | P34: =O34/SUMIF(B:B,B34,O:O) -> 0.00080547673 | Q34: 0.00012595708
A35: 520042177 | B35: 142 | C35: בנק מזרחי | D35: 20-61 | E35: סימול בנק | F35: מזומן ועו"ש נקוב במט"ח | G35: ישראל | H35: לא | I35: Aaa.il | J35: מידרוג Moodys | K35: CHF | L35: 14.526 | M35: 4.397 | N35: 0 | O35: 63.863 | P35: =O35/SUMIF(B:B,B35,O:O) -> 0.00062554158 | Q35: 9.781957e-05
A36: 520042177 | B36: 142 | C36: בנק מזרחי | D36: 20-61 | E36: סימול בנק | F36: בטחונות שוטפים | G36: חו"ל | H36: לא | I36: Aaa.il | J36: מידרוג Moodys | K36: USD | L36: 3745.933 | M36: 3.71 | N36: 0.045 | O36: 13897.412 | P36: =O36/SUMIF(B:B,B36,O:O) -> 0.13612591 | Q36: 0.021286799
A37: 520042177 | B37: 142 | C37: בנק מזרחי | D37: 20-61 | E37: סימול בנק | F37: בטחונות שוטפים | G37: חו"ל | H37: לא | I37: Aaa.il | J37: מידרוג Moodys | K37: JPY | L37: 35329.627 | M37: 0.026 | N37: -0.0057 | O37: 919.595 | P37: =O37/SUMIF(B:B,B37,O:O) -> 0.0090074833 | Q37: 0.0014085525
A38: 520042177 | B38: 142 | C38: בנק מזרחי | D38: 20-61 | E38: סימול בנק | F38: בטחונות שוטפים | G38: חו"ל | H38: לא | I38: Aaa.il | J38: מידרוג Moodys | K38: EUR | L38: 59.475 | M38: 4.152 | N38: 0.0273 | O38: 246.964 | P38: =O38/SUMIF(B:B,B38,O:O) -> 0.0024190259 | Q38: 0.00037827713
A39: 520042177 | B39: 143 | C39: בנק מזרחי | D39: 20-61 | E39: סימול בנק | F39: מזומן ועו"ש בש"ח | G39: ישראל | H39: לא | I39: Aaa.il | J39: מידרוג Moodys | K39: ILS | L39: =109085.423-291.965530000161 -> 108793.46 | M39: 1 | N39: 0.04 | O39: =L39 -> 108793.46 | P39: =O39/SUMIF(B:B,B39,O:O) -> 0.53967737 | Q39: 0.038804236
A40: 520042177 | B40: 143 | C40: בנק מזרחי | D40: 20-61 | E40: סימול בנק | F40: מזומן ועו"ש נקוב במט"ח | G40: ישראל | H40: לא | I40: ilAAA | J40: S&P מעלות | K40: EUR | L40: 4061.565 | M40: 4.152 | N40: 0.0306 | O40: 16865.241 | P40: =O40/SUMIF(B:B,B40,O:O) -> 0.08366118 | Q40: 0.0060154609
...

Sheet איגרות חוב ממשלתיות
A1: מספר קופה/קרן/ח.פ. עבור חברת ביטוח | B1: מספר מסלול | C1: שם מנפיק | D1: שם נייר ערך | E1: מספר נייר ערך | F1: מאפיין עיקרי | G1: ישראל/חו"ל | H1: מדינה לפי חשיפה כלכלית | I1: זירת מסחר | J1: דירוג | K1: שם מדרג | L1: מטבע פעילות | M1: מח"מ | N1: מועד פדיון | O1: שיעור ריבית | P1: תשואה לפדיון | Q1: סכום לקבל (במטבע הפעילות) | R1: ערך נקוב (יחידות) | S1: שער חליפין | T1: שער נייר הערך | U1: שווי הוגן (באלפי ש"ח) | V1: עלות מופחתת (באלפי ש"ח) | W1: השיטה שיושמה בדוח הכספי | X1: שיעור מערך נקוב מונפק | Y1: שיעור מנכסי אפיק ההשקעה | Z1: שיעור מסך נכסי ההשקעה
A2: 520042177 | B2: 12936 | C2: האוצר - ממשלתית צמודה | D2: ממשל צמודה 1025 | E2: IL0011359127 | F2: צמוד למדד המחירים לצרכן בריבית קבועה | G2: ישראל | H2: ישראל | I2: TASE | J2: ilRF | K2: S&P מעלות | L2: ILS | M2: 1.07 | N2: 31/10/2025 | O2: 0.00504 | P2: 0.013 | R2: 19500000 | S2: 1 | T2: 116.02 | U2: 22623.9 | W2: שווי הוגן | X2: 0.0009 | Y2: 0.27615 | Z2: 0.21264
A3: 520042177 | B3: 12936 | C3: האוצר - ממשלתית צמודה | D3: ממשל צמודה 1028 | E3: IL0011973265 | F3: צמוד למדד המחירים לצרכן בריבית קבועה | G3: ישראל | H3: ישראל | I3: TASE | J3: RF.il | K3: מידרוג Moodys | L3: ILS | M3: 3.97 | N3: 30/10/2028 | O3: 0.01026 | P3: 0.018 | R3: 12500000 | S3: 1 | T3: 102.6 | U3: 12825 | W3: שווי הוגן | X3: 0.00061 | Y3: 0.15654 | Z3: 0.12054
A4: 520042177 | B4: 12936 | C4: האוצר - ממשלתית שקלית | D4: ממשלתי שקלי 0425 | E4: IL0011626681 | F4: לא צמוד למדד המחירים לצרכן ריבית קבועה | G4: ישראל | H4: ישראל | I4: TASE | J4: RF.il | K4: מידרוג Moodys | L4: ILS | M4: 0.58 | N4: 30/04/2025 | O4: -0.00169 | P4: 0.0396 | R4: 11689889 | S4: 1 | T4: 98.27 | U4: 11487.654 | W4: שווי הוגן | X4: 0.00074 | Y4: 0.14022 | Z4: 0.10797
A5: 520042177 | B5: 12936 | C5: האוצר - ממשלתית שקלית | D5: ממשק0142 | E5: IL0011254005 | F5: לא צמוד למדד המחירים לצרכן ריבית קבועה | G5: ישראל | H5: ישראל | I5: TASE | J5: ilRF | K5: S&P מעלות | L5: ILS | M5: 11.32 | N5: 31/01/2042 | O5: 0.03673 | P5: 0.0517 | R5: 7227442 | S5: 1 | T5: 107.34 | U5: 7757.936 | W5: שווי הוגן | X5: 0.00033 | Y5: 0.09469 | Z5: 0.07291
A6: 520042177 | B6: 12936 | C6: האוצר - ממשלתית שקלית | D6: ממשל שקלית 0226 | E6: IL0011746976 | F6: לא צמוד למדד המחירים לצרכן ריבית קבועה | G6: ישראל | H6: ישראל | I6: TASE | J6: RF.il | K6: מידרוג Moodys | L6: ILS | M6: 1.4 | N6: 27/02/2026 | O6: 0.03966 | P6: 0.0438 | R6: 4685000 | S6: 1 | T6: 95.1 | U6: 4455.435 | W6: שווי הוגן | X6: 0.00017 | Y6: 0.05438 | Z6: 0.04188
A7: 520042177 | B7: 12936 | C7: האוצר - ממשלתית משתנה | D7: ממשלת משתנה 1130 | E7: IL0011665523 | F7: לא צמוד למדד המחירים לצרכן ריבית משתנה | G7: ישראל | H7: ישראל | I7: TASE | J7: ilRF | K7: S&P מעלות | L7: ILS | M7: 5.42 | N7: 29/11/2030 | O7: 0.00495 | P7: 0.0484 | R7: 4397500 | S7: 1 | T7: 97.9 | U7: 4305.153 | W7: שווי הוגן | X7: 0.00014 | Y7: 0.05255 | Z7: 0.04046
A8: 520042177 | B8: 12936 | C8: האוצר - ממשלתית שקלית | D8: ממשל שקלית 0330 | E8: IL0011609851 | F8: לא צמוד למדד המחירים לצרכן ריבית קבועה | G8: ישראל | H8: ישראל | I8: TASE | J8: ilRF | K8: S&P מעלות | L8: ILS | M8: 5.33 | N8: 31/03/2030 | O8: 0.03461 | P8: 0.0463 | R8: 3650000 | S8: 1 | T8: 83.24 | U8: 3038.26 | W8: שווי הוגן | X8: 0.0001 | Y8: 0.03709 | Z8: 0.02856
A9: 520042177 | B9: 12936 | C9: האוצר - ממשלתית משתנה | D9: ממשל משתנה 0526 | E9: IL0011417958 | F9: לא צמוד למדד המחירים לצרכן ריבית משתנה | G9: ישראל | H9: ישראל | I9: TASE | J9: ilRF | K9: S&P מעלות | L9: ILS | M9: 1.61 | N9: 31/05/2026 | O9: 0.00246 | P9: 0.047 | R9: 2380000 | S9: 1 | T9: 99.82 | U9: 2375.716 | W9: שווי הוגן | X9: 0.00011 | Y9: 0.029 | Z9: 0.02233
A10: 520042177 | B10: 12936 | C10: האוצר - ממשלתית שקלית | D10: ממשלתי 0825 | E10: IL0011355570 | F10: לא צמוד למדד המחירים לצרכן ריבית קבועה | G10: ישראל | H10: ישראל | I10: TASE | J10: ilRF | K10: S&P מעלות | L10: ILS | M10: 0.92 | N10: 31/08/2025 | O10: -0.00365 | P10: 0.0417 | R10: 1958268 | S10: 1 | T10: 98.02 | U10: 1919.494 | W10: שווי הוגן | X10: 8e-05 | Y10: 0.02343 | Z10: 0.01804
A11: 520042177 | B11: 12936 | C11: בנק ישראל- מק"מ | D11: מ.ק.מ. 315 | E11: IL0082503181 | F11: מק"מ קצר משנים עשר חודשים | G11: ישראל | H11: ישראל | I11: TASE | J11: ilRF | K11: S&P מעלות | L11: ILS | M11: 0.42 | N11: 05/03/2025 | O11: 0.04072 | P11: 0.0432 | R11: 1590000 | S11: 1 | T11: 98.22 | U11: 1561.698 | W11: שווי הוגן | X11: 0.00013 | Y11: 0.01906 | Z11: 0.01468
A12: 520042177 | B12: 12936 | C12: בנק ישראל- מק"מ | D12: מ.ק.מ. 815 | E12: IL0082508131 | F12: מק"מ קצר משנים עשר חודשים | G12: ישראל | H12: ישראל | I12: TASE | J12: RF.il | K12: מידרוג Moodys | L12: ILS | M12: 0.85 | N12: 06/08/2025 | O12: 0.04121 | P12: 0.0432 | R12: 1343000 | S12: 1 | T12: 96.48 | U12: 1295.726 | W12: שווי הוגן | X12: 0.00011 | Y12: 0.01582 | Z12: 0.01218
A13: 520042177 | B13: 12936 | C13: האוצר - ממשלתית צמודה | D13: ממשל צמודה 1131 | E13: IL0011722209 | F13: צמוד למדד המחירים לצרכן בריבית קבועה | G13: ישראל | H13: ישראל | I13: TASE | J13: RF.il | K13: מידרוג Moodys | L13: ILS | M13: 7.14 | N13: 30/11/2031 | O13: -0.00914 | P13: 0.0199 | R13: 1120000 | S13: 1 | T13: 101.1 | U13: 1132.32 | W13: שווי הוגן | X13: 4e-05 | Y13: 0.01382 | Z13: 0.01064
A14: 520042177 | B14: 12936 | C14: האוצר - ממשלתית צמודה | D14: ממשל צמודה 0529 | E14: IL0011570236 | F14: צמוד למדד המחירים לצרכן בריבית קבועה | G14: ישראל | H14: ישראל | I14: TASE | J14: RF.il | K14: מידרוג Moodys | L14: ILS | M14: 4.61 | N14: 31/05/2029 | O14: -0.01735 | P14: 0.0183 | R14: 969270 | S14: 1 | T14: 108.85 | U14: 1055.05 | W14: שווי הוגן | X14: 4e-05 | Y14: 0.01288 | Z14: 0.00992
A15: 520042177 | B15: 12936 | C15: בנק ישראל- מק"מ | D15: מ.ק.מ. 915 | E15: IL0082509121 | F15: מק"מ קצר משנים עשר חודשים | G15: ישראל | H15: ישראל | I15: TASE | J15: RF.il | K15: מידרוג Moodys | L15: ILS | M15: 0.92 | N15: 03/09/2025 | O15: 0.04253 | P15: 0.0429 | R15: 780000 | S15: 1 | T15: 96.2 | U15: 750.36 | W15: שווי הוגן | X15: 6e-05 | Y15: 0.00916 | Z15: 0.00705
A16: 520042177 | B16: 12936 | C16: האוצר - ממשלתית שקלית | D16: ממשל שקלית 0229 | E16: IL0011948028 | F16: לא צמוד למדד המחירים לצרכן ריבית קבועה | G16: ישראל | H16: ישראל | I16: TASE | J16: RF.il | K16: מידרוג Moodys | L16: ILS | M16: 4.06 | N16: 28/02/2029 | O16: 0.03504 | P16: 0.0456 | R16: 600000 | S16: 1 | T16: 99.02 | U16: 594.12 | W16: שווי הוגן | X16: 2e-05 | Y16: 0.00725 | Z16: 0.00558
A17: 520042177 | B17: 12936 | C17: האוצר - ממשלתית צמודה | D17: ממשל צמודה 0726 | E17: IL0011695645 | F17: צמוד למדד המחירים לצרכן בריבית קבועה | G17: ישראל | H17: ישראל | I17: TASE | J17: RF.il | K17: מידרוג Moodys | L17: ILS | M17: 1.83 | N17: 31/07/2026 | O17: 0.01508 | P17: 0.0157 | R17: 500000 | S17: 1 | T17: 112.44 | U17: 562.2 | W17: שווי הוגן | X17: 2e-05 | Y17: 0.00686 | Z17: 0.00528
A18: 520042177 | B18: 12936 | C18: האוצר - ממשלתית שקלית | D18: ממשק 1026 | E18: IL0010994569 | F18: לא צמוד למדד המחירים לצרכן ריבית קבועה | G18: ישראל | H18: ישראל | I18: TASE | J18: ilRF | K18: S&P מעלות | L18: ILS | M18: 1.91 | N18: 30/10/2026 | O18: 0.03708 | P18: 0.0432 | R18: 500000 | S18: 1 | T18: 109.5 | U18: 547.5 | W18: שווי הוגן | X18: 3e-05 | Y18: 0.00668 | Z18: 0.00515
A19: 520042177 | B19: 12936 | C19: בנק ישראל- מק"מ | D19: מ.ק.מ. 415 | E19: IL0082504171 | F19: מק"מ קצר משנים עשר חודשים | G19: ישראל | H19: ישראל | I19: TASE | J19: ilRF | K19: S&P מעלות | L19: ILS | M19: 0.5 | N19: 02/04/2025 | O19: 0.04241 | P19: 0.0432 | R19: 500000 | S19: 1 | T19: 97.9 | U19: 489.5 | W19: שווי הוגן | X19: 4e-05 | Y19: 0.00597 | Z19: 0.0046
A20: 520042177 | B20: 12936 | C20: בנק ישראל- מק"מ | D20: מ.ק.מ. 125 | E20: IL0082501284 | F20: מק"מ קצר משנים עשר חודשים | G20: ישראל | H20: ישראל | I20: TASE | J20: ilRF | K20: S&P מעלות | L20: ILS | M20: 0.27 | N20: 08/01/2025 | O20: 0.0398 | P20: 0.0432 | R20: 300000 | S20: 1 | T20: 98.86 | U20: 296.58 | W20: שווי הוגן | X20: 2e-05 | Y20: 0.00362 | Z20: 0.00279
A21: 520042177 | B21: 12936 | C21: ממשלת ארה"ב | D21: US TREASURY 4.0 15/02/34 | E21: US91282CJZ59 | F21: נקוב במט"ח | G21: חו"ל | H21: ארה"ב | I21: אחר | J21: AA+ | K21: Fitch | L21: USD | M21: 7.736 | N21: 15/02/2034 | O21: 0.03842 | P21: 0.03766 | R21: 750000 | S21: 3.71 | T21: =U21*1000/R21/S21*100 -> 102.51562 | U21: 2852.497 | W21: שווי הוגן | X21: 1e-05 | Y21: 0.03482 | Z21: 0.02681
A22: 520042177 | B22: 12937 | C22: האוצר - ממשלתית צמודה | D22: ממשל צמודה 1025 | E22: IL0011359127 | F22: צמוד למדד המחירים לצרכן בריבית קבועה | G22: ישראל | H22: ישראל | I22: TASE | J22: ilRF | K22: S&P מעלות | L22: ILS | M22: 1.07 | N22: 31/10/2025 | O22: 0.00131 | P22: 0.013 | R22: 102560594 | S22: 1 | T22: 116.02 | U22: 118990.8 | W22: שווי הוגן | X22: 0.00473 | Y22: 0.39823 | Z22: 0.11007
A23: 520042177 | B23: 12937 | C23: בנק ישראל- מק"מ | D23: מ.ק.מ. 915 | E23: IL0082509121 | F23: מק"מ קצר משנים עשר חודשים | G23: ישראל | H23: ישראל | I23: TASE | J23: RF.il | K23: מידרוג Moodys | L23: ILS | M23: 0.92 | N23: 03/09/2025 | O23: 0.04241 | P23: 0.0429 | R23: 49386000 | S23: 1 | T23: 96.2 | U23: 47509.332 | W23: שווי הוגן | X23: 0.00412 | Y23: 0.159 | Z23: 0.04395
A24: 520042177 | B24: 12937 | C24: האוצר - ממשלתית משתנה | D24: ממשל משתנה 0526 | E24: IL0011417958 | F24: לא צמוד למדד המחירים לצרכן ריבית משתנה | G24: ישראל | H24: ישראל | I24: TASE | J24: ilRF | K24: S&P מעלות | L24: ILS | M24: 1.61 | N24: 31/05/2026 | O24: 0.0005 | P24: 0.047 | R24: 44252501 | S24: 1 | T24: 99.82 | U24: 44172.846 | W24: שווי הוגן | X24: 0.00209 | Y24: 0.14783 | Z24: 0.04086
A25: 520042177 | B25: 12937 | C25: האוצר - ממשלתית שקלית | D25: ממשק0142 | E25: IL0011254005 | F25: לא צמוד למדד המחירים לצרכן ריבית קבועה | G25: ישראל | H25: ישראל | I25: TASE | J25: ilRF | K25: S&P מעלות | L25: ILS | M25: 11.32 | N25: 31/01/2042 | O25: 0.03769 | P25: 0.0517 | R25: 22673998 | S25: 1 | T25: 107.34 | U25: 24338.269 | W25: שווי הוגן | X25: 0.00103 | Y25: 0.08145 | Z25: 0.02251
A26: 520042177 | B26: 12937 | C26: בנק ישראל- מק"מ | D26: מ.ק.מ. 515 | E26: IL0082505160 | F26: מק"מ קצר משנים עשר חודשים | G26: ישראל | H26: ישראל | I26: TASE | J26: ilRF | K26: S&P מעלות | L26: ILS | M26: 0.6 | N26: 07/05/2025 | O26: 0.04218 | P26: 0.0429 | R26: 13163000 | S26: 1 | T26: 97.52 | U26: 12836.558 | W26: שווי הוגן | X26: 0.00094 | Y26: 0.04296 | Z26: 0.01187
A27: 520042177 | B27: 12937 | C27: האוצר - ממשלתית שקלית | D27: ממשלתי 0825 | E27: IL0011355570 | F27: לא צמוד למדד המחירים לצרכן ריבית קבועה | G27: ישראל | H27: ישראל | I27: TASE | J27: ilRF | K27: S&P מעלות | L27: ILS | M27: 0.92 | N27: 31/08/2025 | O27: 0.03173 | P27: 0.0417 | R27: 12745000 | S27: 1 | T27: 98.02 | U27: 12492.649 | W27: שווי הוגן | X27: 0.00054 | Y27: 0.04181 | Z27: 0.01156
A28: 520042177 | B28: 12937 | C28: בנק ישראל- מק"מ | D28: מ.ק.מ. 315 | E28: IL0082503181 | F28: מק"מ קצר משנים עשר חודשים | G28: ישראל | H28: ישראל | I28: TASE | J28: ilRF | K28: S&P מעלות | L28: ILS | M28: 0.42 | N28: 05/03/2025 | O28: 0.04071 | P28: 0.0432 | R28: 12250000 | S28: 1 | T28: 98.22 | U28: 12031.95 | W28: שווי הוגן | X28: 0.00102 | Y28: 0.04027 | Z28: 0.01113
A29: 520042177 | B29: 12937 | C29: האוצר - ממשלתית צמודה | D29: ממשלתי צמוד 0527 | E29: IL0011408478 | F29: צמוד למדד המחירים לצרכן בריבית קבועה | G29: ישראל | H29: ישראל | I29: TASE | J29: RF.il | K29: מידרוג Moodys | L29: ILS | M29: 2.64 | N29: 31/05/2027 | O29: -0.03607 | P29: 0.0163 | R29: 10000000 | S29: 1 | T29: 114.25 | U29: 11425 | W29: שווי הוגן | X29: 0.00045 | Y29: 0.03824 | Z29: 0.01057
A30: 520042177 | B30: 12937 | C30: האוצר - ממשלתית שקלית | D30: ממשל שקלית 0229 | E30: IL0011948028 | F30: לא צמוד למדד המחירים לצרכן ריבית קבועה | G30: ישראל | H30: ישראל | I30: TASE | J30: RF.il | K30: מידרוג Moodys | L30: ILS | M30: 4.06 | N30: 28/02/2029 | O30: 0.0387 | P30: 0.0456 | R30: 4500000 | S30: 1 | T30: 99.02 | U30: 4455.9 | W30: שווי הוגן | X30: 0.00014 | Y30: 0.01491 | Z30: 0.00412
A31: 520042177 | B31: 12937 | C31: האוצר - ממשלתית צמודה | D31: ממשל צמודה 1033 | E31: IL0012043795 | F31: צמוד למדד המחירים לצרכן בריבית קבועה | G31: ישראל | H31: ישראל | I31: TASE | J31: ilRF | K31: S&P מעלות | L31: ILS | M31: 8.43 | N31: 31/10/2033 | O31: 0.018 | P31: 0.0213 | R31: 2800000 | S31: 1 | T31: 100.1 | U31: 2802.8 | W31: שווי הוגן | X31: 0.00027 | Y31: 0.00938 | Z31: 0.00259
A32: 520042177 | B32: 12937 | C32: האוצר - ממשלתית משתנה | D32: ממשלת משתנה 1130 | E32: IL0011665523 | F32: לא צמוד למדד המחירים לצרכן ריבית משתנה | G32: ישראל | H32: ישראל | I32: TASE | J32: ilRF | K32: S&P מעלות | L32: ILS | M32: 5.42 | N32: 29/11/2030 | O32: 0.00515 | P32: 0.0484 | R32: 2861000 | S32: 1 | T32: 97.9 | U32: 2800.919 | W32: שווי הוגן | X32: 9e-05 | Y32: 0.00937 | Z32: 0.00259
A33: 520042177 | B33: 12937 | C33: האוצר - ממשלתית צמודה | D33: ממשל צמודה 1028 | E33: IL0011973265 | F33: צמוד למדד המחירים לצרכן בריבית קבועה | G33: ישראל | H33: ישראל | I33: TASE | J33: RF.il | K33: מידרוג Moodys | L33: ILS | M33: 3.97 | N33: 30/10/2028 | O33: 0.00918 | P33: 0.018 | R33: 2235000 | S33: 1 | T33: 102.6 | U33: 2293.11 | W33: שווי הוגן | X33: 0.00011 | Y33: 0.00767 | Z33: 0.00212
... A132: 520042177 | B132: 142 | C132: בנק ישראל- מק"מ | D132: מ.ק.מ. 615 | E132: IL0082506150 | F132: מק"מ קצר משנים עשר חודשים | G132: ישראל | H132: ישראל | I132: TASE | J132: ilRF | K132: S&P מעלות | L132: ILS | M132: 0.67 | N132: 04/06/2025 | O132: 0.0432 | P132: 0.0427 | R132: 8000000 | S132: 1 | T132: 97.22 | U132: 7777.6 | W132: שווי הוגן | X132: 0.00067 | Y132: 0.09496 | Z132: 0.01191
A133: 520042177 | B133: 142 | C133: ממשלת ארה"ב | D133: US TREASURY 0.5 28/02/26 | E133: US91282CBQ33 | F133: נקוב במט"ח | G133: חו"ל | H133: ארה"ב | I133: אחר | J133: AA+ | K133: Fitch | L133: USD | M133: 1.382 | N133: 28/02/2026 | O133: 0.05108 | P133: 0.03757 | R133: 6500000 | S133: 3.71 | T133: =U133*1000/R133/S133*100 -> 95.635468 | U133: 23062.493 | W133: שווי הוגן | X133: 9e-05 | Y133: 0.28158 | Z133: 0.03532
A134: 520042177 | B134: 143 | C134: האוצר - ממשלתית צמודה | D134: ממשלתי צמוד 0527 | E134: IL0011408478 | F134: צמוד למדד המחירים לצרכן בריבית קבועה | G134: ישראל | H134: ישראל | I134: TASE | J134: RF.il | K134: מידרוג Moodys | L134: ILS | M134: 2.64 | N134: 31/05/2027 | O134: -0.00894 | P134: 0.0163 | R134: 122350000 | S134: 1 | T134: 114.25 | U134: 139784.88 | W134: שווי הוגן | X134: 0.00549 | Y134: 0.11429 | Z134: 0.04986
A135: 520042177 | B135: 143 | C135: האוצר - ממשלתית שקלית | D135: ממשל שקלית 0335 | E135: IL0012023326 | F135: לא צמוד למדד המחירים לצרכן ריבית קבועה | G135: ישראל | H135: ישראל | I135: TASE | J135: ilRF | K135: S&P מעלות | L135: ILS | M135: 8.52 | N135: 30/03/2035 | O135: 0.04525 | P135: 0.0488 | R135: 111500000 | S135: 1 | T135: 94.93 | U135: 105846.95 | W135: שווי הוגן | X135: 0.00644 | Y135: 0.08654 | Z135: 0.03775
A136: 520042177 | B136: 143 | C136: בנק ישראל- מק"מ | D136: מ.ק.מ. 1214 | E136: IL0082412185 | F136: מק"מ קצר משנים עשר חודשים | G136: ישראל | H136: ישראל | I136: TASE | J136: ilRF | K136: S&P מעלות | L136: ILS | M136: 0.18 | N136: 04/12/2024 | O136: 0.04088 | P136: 0.0427 | R136: 95000000 | S136: 1 | T136: 99.27 | U136: 94306.5 | W136: שווי הוגן | X136: 0.00238 | Y136: 0.07711 | Z136: 0.03364
A137: 520042177 | B137: 143 | C137: בנק ישראל- מק"מ | D137: מ.ק.מ. 415 | E137: IL0082504171 | F137: מק"מ קצר משנים עשר חודשים | G137: ישראל | H137: ישראל | I137: TASE | J137: ilRF | K137: S&P מעלות | L137: ILS | M137: 0.5 | N137: 02/04/2025 | O137: 0.0409 | P137: 0.0432 | R137: 85000000 | S137: 1 | T137: 97.9 | U137: 83215 | W137: שווי הוגן | X137: 0.00708 | Y137: 0.06804 | Z137: 0.02968
A138: 520042177 | B138: 143 | C138: בנק ישראל- מק"מ | D138: מ.ק.מ. 915 | E138: IL0082509121 | F138: מק"מ קצר משנים עשר חודשים | G138: ישראל | H138: ישראל | I138: TASE | J138: RF.il | K138: מידרוג Moodys | L138: ILS | M138: 0.92 | N138: 03/09/2025 | O138: 0.04158 | P138: 0.0429 | R138: 85000000 | S138: 1 | T138: 96.2 | U138: 81770 | W138: שווי הוגן | X138: 0.00708 | Y138: 0.06686 | Z138: 0.02916
...

Sheet ניירות ערך מסחריים
A1: מספר קופה/קרן/ח.פ. עבור חברת ביטוח | B1: מספר מסלול | C1: שם מנפיק | D1: מספר מנפיק | E1: סוג מספר מזהה מנפיק | F1: שם נייר ערך | G1: מספר נייר ערך | H1: סוג מספר נייר ערך | I1: מאפיין עיקרי | J1: ישראל/חו"ל | K1: מדינה לפי חשיפה כלכלית | L1: זירת מסחר | M1: ענף מסחר | N1: בעל עניין/צד קשור | O1: דירוג | P1: שם מדרג | Q1: דירוג נייר הערך/המנפיק | R1: מטבע פעילות | S1: מח"מ | T1: ריבית עוגן | U1: מועד פדיון | V1: שיעור ריבית | W1: תשואה לפדיון | X1: נחיתות חוזית | Y1: האם סווג כחוב בעייתי | Z1: ערך נקוב (יחידות) | AA1: שער חליפין | AB1: שער נייר הערך | AC1: סכום לקבל (במטבע הפעילות) | AD1: שווי הוגן (באלפי ש"ח) | AE1: עלות מופחתת (באלפי ש"ח) | AF1: עלות מופחתת (במטבע הפעילות) | AG1: השיטה שיושמה בדוח הכספי | AH1: שיעור מערך נקוב מונפק | AI1: שיעור מנכסי אפיק ההשקעה | AJ1: שיעור מסך נכסי ההשקעה
A2: 520042177 | B2: 9300 | C2: מזרחי טפחות הנפ | D2: 520032046 | E2: ח.פ. | F2: מז טפ הנפ מסחרי3 | G2: IL0012075474 | H2: ISIN | I2: אחר | J2: ישראל | K2: ישראל | L2: TASE | M2: בנקים | N2: לא | O2: ilAAA | P2: S&P מעלות | Q2: נייר ערך | R2: ILS | S2: 0.68 | T2: ריבית בנק ישראל | U2: 05/06/2025 | V2: -0.90053 | W2: 0.0441 | X2: החוב לא נחות | Y2: לא | Z2: 20000 | AA2: 1 | AB2: 1015.42 | AD2: 203.084 | AG2: שווי הוגן | AH2: 1e-05 | AI2: 1 | AJ2: 0.00066
A3: 520042177 | B3: 9301 | C3: מזרחי טפחות הנפ | D3: 520032046 | E3: ח.פ. | F3: מז טפ הנפ מסחרי3 | G3: IL0012075474 | H3: ISIN | I3: אחר | J3: ישראל | K3: ישראל | L3: TASE | M3: בנקים | N3: לא | O3: ilAAA | P3: S&P מעלות | Q3: נייר ערך | R3: ILS | S3: 0.68 | T3: ריבית בנק ישראל | U3: 05/06/2025 | V3: -0.90053 | W3: 0.0441 | X3: החוב לא נחות | Y3: לא | Z3: 50000 | AA3: 1 | AB3: 1015.42 | AD3: 507.71 | AG3: שווי הוגן | AH3: 2e-05 | AI3: 1 | AJ3: 0.0007
A4: 520042177 | B4: 9302 | C4: מזרחי טפחות הנפ | D4: 520032046 | E4: ח.פ. | F4: מז טפ הנפ מסחרי3 | G4: IL0012075474 | H4: ISIN | I4: אחר | J4: ישראל | K4: ישראל | L4: TASE | M4: בנקים | N4: לא | O4: ilAAA | P4: S&P מעלות | Q4: נייר ערך | R4: ILS | S4: 0.68 | T4: ריבית בנק ישראל | U4: 05/06/2025 | V4: -0.90053 | W4: 0.0441 | X4: החוב לא נחות | Y4: לא | Z4: 330000 | AA4: 1 | AB4: 1015.42 | AD4: 3350.886 | AG4: שווי הוגן | AH4: 0.00015 | AI4: 1 | AJ4: 0.001
A5: 520042177 | B5: 12936
A6: 520042177 | B6: 12937
A7: 520042177 | B7: 12938
A8: 520042177 | B8: 13498
A9: 520042177 | B9: 13499
A10: 520042177 | B10: 13500
A11: 520042177 | B11: 141
A12: 520042177 | B12: 142
A13: 520042177 | B13: 143
A14: 520042177 | B14: 14318
A15: 520042177 | B15: 14406
A16: 520042177 | B16: 14425
... A23: 520042177 | B23: 8530
A24: 520042177 | B24: 15108
A25: 520042177 | B25: 9629
A26: 520042177 | B26: 9630
A27: 520042177 | B27: 9631
A28: 520042177 | B28: 9719
A29: 520042177 | B29: 9720
A30: 520042177 | B30: 9721
A31: 520042177 | B31: 9888

Sheet איגרות חוב
A1: מספר קופה/קרן/ח.פ. עבור חברת ביטוח | B1: מספר מסלול | C1: שם מנפיק | D1: מספר מנפיק | E1: סוג מספר מזהה מנפיק | F1: שם נייר ערך | G1: מספר נייר ערך | H1: סוג מספר נייר ערך | I1: מאפיין עיקרי | J1: ישראל/חו"ל | K1: מדינה לפי חשיפה כלכלית | L1: סטאטוס סחירות | M1: זירת מסחר | N1: ענף מסחר | O1: בעל עניין/צד קשור | P1: דירוג | Q1: שם מדרג | R1: דירוג נייר הערך/המנפיק | S1: מטבע פעילות | T1: מח"מ | U1: מועד פדיון | V1: שיעור ריבית | W1: תשואה לפדיון | X1: נחיתות חוזית | Y1: האם סווג כחוב בעייתי | Z1: ערך נקוב (יחידות) | AA1: שער חליפין | AB1: שער נייר הערך | AC1: סכום לקבל (במטבע הפעילות) | AD1: שווי הוגן (באלפי ש"ח) | AE1: עלות מופחתת (באלפי ש"ח) | AF1: עלות מופחתת (במטבע הפעילות) | AG1: השיטה שיושמה בדוח הכספי | AH1: שיעור מערך נקוב מונפק | AI1: שיעור מנכסי אפיק ההשקעה | AJ1: שיעור מסך נכסי ההשקעה
A2: 520042177 | B2: 12936 | C2: סטרוברי אינק | D2: 842336054 | E2: מספר תאגיד או שותפות בחו"ל | F2: סטרברי אנ אגח א | G2: IL0012098997 | H2: ISIN | I2: לא צמוד למדד המחירים לצרכן | J2: ישראל | K2: ארה"ב | L2: סחיר | M2: TASE | N2: נדל"ן מניב בחו"ל | O2: לא | P2: ilA+ | Q2: S&P מעלות | R2: נייר ערך | S2: ILS | T2: 1.84 | U2: 30/09/2026 | V2: 0.07373 | W2: 0.0737 | X2: החוב לא נחות | Y2: לא | Z2: 686384.83 | AA2: 1 | AB2: 99.55 | AD2: 683.296 | AG2: שווי הוגן | AH2: 0.00372 | AI2: =AD2/SUMIF(B:B,B2,AD:AD) -> 0.039020784 | AJ2: 0.0064221124
A3: 520042177 | B3: 12936 | C3: אקסטל לימיטד | D3: 1811308 | E3: מספר תאגיד או שותפות בחו"ל | F3: אקסטל אגח ד | G3: IL0011831695 | H3: ISIN | I3: לא צמוד למדד המחירים לצרכן | J3: ישראל | K3: ארה"ב | L3: סחיר | M3: TASE | N3: בנייה | O3: לא | P3: A3.il | Q3: מידרוג Moodys | R3: נייר ערך | S3: ILS | T3: 2.51 | U3: 31/12/2027 | V3: 0.065 | W3: 0.0838 | X3: החוב לא נחות | Y3: לא | Z3: 542000 | AA3: 1 | AB3: 97.5 | AD3: 528.45 | AG3: שווי הוגן | AH3: 0.0009 | AI3: =AD3/SUMIF(B:B,B3,AD:AD) -> 0.030178039 | AJ3: 0.0049667572
A4: 520042177 | B4: 12936 | C4: דליה אנרגיה | D4: 516269248 | E4: ח.פ. | F4: דליה אגח ב | G4: IL0011935983 | H4: ISIN | I4: צמוד למדד המחירים לצרכן | J4: ישראל | K4: ישראל | L4: סחיר | M4: TASE | N4: אנרגיה | O4: לא | P4: A3.il | Q4: מידרוג Moodys | R4: נייר ערך | S4: ILS | T4: 5.98 | U4: 01/10/2034 | V4: 0.03523 | W4: 0.0426 | X4: החוב לא נחות | Y4: לא | Z4: 518000 | AA4: 1 | AB4: 101.08 | AD4: 523.594 | AG4: שווי הוגן | AH4: 0.00042 | AI4: =AD4/SUMIF(B:B,B4,AD:AD) -> 0.029900728 | AJ4: 0.004921117
A5: 520042177 | B5: 12936 | C5: אמות | D5: 520026683 | E5: ח.פ. | F5: אמות אג ו' | G5: IL0011586091 | H5: ISIN | I5: צמוד למדד המחירים לצרכן | J5: ישראל | K5: ישראל | L5: סחיר | M5: TASE | N5: נדל"ן מניב בישראל | O5: לא | P5: ilAA | Q5: S&P מעלות | R5: נייר ערך | S5: ILS | T5: 3.33 | U5: 31/10/2029 | V5: 0.02161 | W5: 0.0292 | X5: החוב לא נחות | Y5: לא | Z5: 449000 | AA5: 1 | AB5: 107.2 | AC5: 5.816 | AD5: 487.144 | AG5: שווי הוגן | AH5: 0.00019 | AI5: =AD5/SUMIF(B:B,B5,AD:AD) -> 0.027819189 | AJ5: 0.0045785334
A6: 520042177 | B6: 12936 | C6: סיאון | D6: 2409 | E6: מספר מנפיק | F6: סיאון אגח א | G6: IL0011940181 | H6: ISIN | I6: צמוד למט"ח | J6: ישראל | K6: ארה"ב | L6: סחיר | M6: TASE | N6: אשראי חוץ בנקאי | O6: לא | P6: A1.il | Q6: מידרוג Moodys | R6: נייר ערך | S6: ILS | T6: 1.77 | U6: 31/08/2026 | V6: 0.00272 | W6: 0.0815 | X6: החוב לא נחות | Y6: לא | Z6: 450000 | AA6: 1 | AB6: 104.6 | AD6: 470.7 | AG6: שווי הוגן | AH6: 0.00107 | AI6: =AD6/SUMIF(B:B,B6,AD:AD) -> 0.026880126 | AJ6: 0.0044239807
A7: 520042177 | B7: 12936 | C7: מימון ישיר קב | D7: 513893123 | E7: ח.פ. | F7: מימון ישיר אגח ו | G7: IL0011916595 | H7: ISIN | I7: צמוד למדד המחירים לצרכן | J7: ישראל | K7: ישראל | L7: סחיר | M7: TASE | N7: אשראי חוץ בנקאי | O7: לא | P7: A1.il | Q7: מידרוג Moodys | R7: נייר ערך | S7: ILS | T7: 1.66 | U7: 31/03/2027 | V7: 0.0354 | W7: 0.0322 | X7: החוב לא נחות | Y7: לא | Z7: 400000 | AA7: 1 | AB7: 107.7 | AD7: 430.8 | AG7: שווי הוגן | AH7: 0.00036 | AI7: =AD7/SUMIF(B:B,B7,AD:AD) -> 0.024601569 | AJ7: 0.0040489715
A8: 520042177 | B8: 12936 | C8: דה לסר | D8: 1427976 | E8: מספר תאגיד או שותפות בחו"ל | F8: דה לסר אגח ט | G8: IL0012056813 | H8: ISIN | I8: לא צמוד למדד המחירים לצרכן | J8: ישראל | K8: ארה"ב | L8: סחיר | M8: TASE | N8: נדל"ן מניב בחו"ל | O8: לא | P8: ilA- | Q8: S&P מעלות | R8: נייר ערך | S8: ILS | T8: 4.14 | U8: 30/06/2031 | V8: 0.07182 | W8: 0.0821 | X8: החוב לא נחות | Y8: לא | Z8: 376000 | AA8: 1 | AB8: 107.75 | AD8: 405.14 | AG8: שווי הוגן | AH8: 0.0007 | AI8: =AD8/SUMIF(B:B,B8,AD:AD) -> 0.023136211 | AJ8: 0.0038078002
A9: 520042177 | B9: 12936 | C9: ספנסר אקוויטי | D9: 1838863 | E9: מספר תאגיד או שותפות בחו"ל | F9: ספנסר אגח ד | G9: IL0011887887 | H9: ISIN | I9: לא צמוד למדד המחירים לצרכן | J9: ישראל | K9: ארה"ב | L9: סחיר | M9: TASE | N9: נדל"ן מניב בחו"ל | O9: לא | P9: ilA | Q9: S&P מעלות | R9: נייר ערך | S9: ILS | T9: 2.5 | U9: 31/08/2029 | V9: 0.03171 | W9: 0.073 | X9: החוב לא נחות | Y9: לא | Z9: 400000.87 | AA9: 1 | AB9: 100.76 | AD9: 403.041 | AG9: שווי הוגן | AH9: 0.00076 | AI9: =AD9/SUMIF(B:B,B9,AD:AD) -> 0.023016344 | AJ9: 0.0037880722
A10: 520042177 | B10: 12936 | C10: ווסטדייל אמריקה | D10: 1991033 | E10: מספר תאגיד או שותפות בחו"ל | F10: ווסטדייל אגח ג | G10: IL0012085119 | H10: ISIN | I10: לא צמוד למדד המחירים לצרכן | J10: ישראל | K10: ארה"ב | L10: סחיר | M10: TASE | N10: נדל"ן מניב בחו"ל | O10: לא | P10: ilAA- | Q10: S&P מעלות | R10: נייר ערך | S10: ILS | T10: 4.29 | U10: 30/10/2029 | V10: 0.07385 | W10: 0.0667 | X10: החוב לא נחות | Y10: לא | Z10: 379000 | AA10: 1 | AB10: 104.03 | AD10: 394.274 | AG10: שווי הוגן | AH10: 0.00091 | AI10: =AD10/SUMIF(B:B,B10,AD:AD) -> 0.022515689 | AJ10: 0.0037056736
A11: 520042177 | B11: 12936 | C11: אס.אר אקורד | D11: 520038670 | E11: ח.פ. | F11: אסאר אקורד אגח ב | G11: IL0042203724 | H11: ISIN | I11: צמוד למדד המחירים לצרכן | J11: ישראל | K11: ישראל | L11: סחיר | M11: TASE | N11: אשראי חוץ בנקאי | O11: לא | P11: A3.il | Q11: מידרוג Moodys | R11: נייר ערך | S11: ILS | T11: 1.46 | U11: 30/06/2027 | V11: 0.05908 | W11: 0.0434 | X11: החוב לא נחות | Y11: לא | Z11: 367476.19 | AA11: 1 | AB11: 104.83 | AD11: 385.225 | AG11: שווי הוגן | AH11: 0.00199 | AI11: =AD11/SUMIF(B:B,B11,AD:AD) -> 0.021998931 | AJ11: 0.0036206245
A12: 520042177 | B12: 12936 | C12: לאומי | D12: 520018078 | E12: ח.פ. | F12: לאומי התח נד403 | G12: IL0060404303 | H12: ISIN | I12: צמוד למדד המחירים לצרכן | J12: ישראל | K12: ישראל | L12: סחיר | M12: TASE | N12: בנקים | O12: לא | P12: ilAA- | Q12: S&P מעלות | R12: נייר ערך | S12: ILS | T12: 0.41 | U12: 28/02/2025 | V12: 0.0242 | W12: 0.0359 | X12: החוב נחות | Y12: לא | Z12: 300000 | AA12: 1 | AB12: 116.43 | AD12: 349.29 | AG12: שווי הוגן | AH12: 0.00021 | AI12: =AD12/SUMIF(B:B,B12,AD:AD) -> 0.019946801 | AJ12: 0.0032828813
A13: 520042177 | B13: 12936 | C13: אדמה | D13: 520043605 | E13: ח.פ. | F13: אדמה אגח 2 | G13: IL0011109159 | H13: ISIN | I13: צמוד למדד המחירים לצרכן | J13: ישראל | K13: ישראל | L13: סחיר | M13: TASE | N13: כימיה, גומי ופלסטיק | O13: לא | P13: ilAA- | Q13: S&P מעלות | R13: נייר ערך | S13: ILS | T13: 5.02 | U13: 30/11/2036 | V13: 0.00838 | W13: 0.0515 | X13: החוב לא נחות | Y13: לא | Z13: 234000.02 | AA13: 1 | AB13: 141.9 | AD13: 332.046 | AG13: שווי הוגן | AH13: 8e-05 | AI13: =AD13/SUMIF(B:B,B13,AD:AD) -> 0.018962053 | AJ13: 0.0031208096
A14: 520042177 | B14: 12936 | C14: אורון קבוצה | D14: 513432765 | E14: ח.פ. | F14: אורון קב אגח ג | G14: IL0011977639 | H14: ISIN | I14: לא צמוד למדד המחירים לצרכן | J14: ישראל | K14: ישראל | L14: חסום | M14: TASE | N14: בנייה | O14: לא | P14: Baa1.il | Q14: מידרוג Moodys | R14: נייר ערך | S14: ILS | T14: 2.83 | U14: 01/07/2029 | V14: 0.07069 | W14: 0.0631 | X14: החוב לא נחות | Y14: לא | Z14: 300000 | AA14: 1 | AB14: =AD14*1000/Z14*100 -> 106.06733 | AD14: =321.24-3.038 -> 318.202 | AG14: שווי הוגן | AH14: 0.00145 | AI14: =AD14/SUMIF(B:B,B14,AD:AD) -> 0.018171468 | AJ14: 0.0029906937
A15: 520042177 | B15: 12936 | C15: מזרחי טפחות הנפ | D15: 520032046 | E15: ח.פ. | F15: מז טפ הנפ הת 69 | G15: IL0012021593 | H15: ISIN | I15: צמוד למדד המחירים לצרכן | J15: ישראל | K15: ישראל | L15: סחיר | M15: TASE | N15: בנקים | O15: לא | P15: ilAA- | Q15: S&P מעלות | R15: נייר ערך | S15: ILS | T15: 4.42 | U15: 25/06/2029 | V15: 0.03422 | W15: 0.0309 | X15: החוב נחות | Y15: לא | Z15: 300000 | AA15: 1 | AB15: 105.66 | AD15: 316.98 | AG15: שווי הוגן | AH15: 0.00026 | AI15: =AD15/SUMIF(B:B,B15,AD:AD) -> 0.018101684 | AJ15: 0.0029792084
A16: 520042177 | B16: 12936 | C16: גב ים | D16: 520001736 | E16: ח.פ. | F16: גב ים אגח יא | G16: IL0012083395 | H16: ISIN | I16: צמוד למדד המחירים לצרכן | J16: ישראל | K16: ישראל | L16: סחיר | M16: TASE | N16: נדל"ן מניב בישראל | O16: לא | P16: ilAA | Q16: S&P מעלות | R16: נייר ערך | S16: ILS | T16: 3.74 | U16: 31/03/2030 | V16: 0.02854 | W16: 0.0307 | X16: החוב לא נחות | Y16: לא | Z16: 300000 | AA16: 1 | AB16: 103.53 | AD16: 310.59 | AG16: שווי הוגן | AH16: 0.0004 | AI16: =AD16/SUMIF(B:B,B16,AD:AD) -> 0.017736772 | AJ16: 0.0029191506
A17: 520042177 | B17: 12936 | C17: קרסו נדלן | D17: 510488190 | E17: ח.פ. | F17: קרסו נדלן אגח א | G17: IL0011900086 | H17: ISIN | I17: לא צמוד למדד המחירים לצרכן | J17: ישראל | K17: ישראל | L17: סחיר | M17: TASE | N17: בנייה | O17: לא | P17: ilA | Q17: S&P מעלות | R17: נייר ערך | S17: ILS | T17: 2.84 | U17: 30/11/2029 | V17: 0.05133 | W17: 0.0624 | X17: החוב לא נחות | Y17: לא | Z17: 300000 | AA17: 1 | AB17: 99.54 | AD17: 298.62 | AG17: שווי הוגן | AH17: 0.00043 | AI17: =AD17/SUMIF(B:B,B17,AD:AD) -> 0.017053204 | AJ17: 0.0028066478
A18: 520042177 | B18: 12936 | C18: פועלים | D18: 520000118 | E18: ח.פ. | F18: פועלים הת נדח ט | G18: IL0011998841 | H18: ISIN | I18: צמוד למדד המחירים לצרכן | J18: ישראל | K18: ישראל | L18: סחיר | M18: TASE | N18: בנקים | O18: לא | P18: ilAA- | Q18: S&P מעלות | R18: נייר ערך | S18: ILS | T18: 0.5 | U18: 03/04/2025 | V18: 0.0202 | W18: 0.0357 | X18: החוב נחות | Y18: לא | Z18: 250000 | AA18: 1 | AB18: 115.6 | AD18: 289 | AG18: שווי הוגן | AH18: 0.00024 | AI18: =AD18/SUMIF(B:B,B18,AD:AD) -> 0.016503838 | AJ18: 0.002716232
A19: 520042177 | B19: 12936 | C19: נמקו ריאלטי | D19: 1905761 | E19: מספר תאגיד או שותפות בחו"ל | F19: נמקו אגח ב | G19: IL0011602583 | H19: ISIN | I19: לא צמוד למדד המחירים לצרכן | J19: ישראל | K19: ארה"ב | L19: סחיר | M19: TASE | N19: נדל"ן מניב בחו"ל | O19: לא | P19: ilAA- | Q19: S&P מעלות | R19: נייר ערך | S19: ILS | T19: 3.44 | U19: 15/10/2032 | V19: 0.06455 | W19: 0.0659 | X19: החוב לא נחות | Y19: לא | Z19: 300000.67 | AA19: 1 | AB19: 95.42 | AD19: 286.261 | AG19: שווי הוגן | AH19: 0.00033 | AI19: =AD19/SUMIF(B:B,B19,AD:AD) -> 0.016347423 | AJ19: 0.0026904889
A20: 520042177 | B20: 12936 | C20: רימון | D20: 512467994 | E20: ח.פ. | F20: רימון אגח א | G20: IL0012110362 | H20: ISIN | I20: לא צמוד למדד המחירים לצרכן | J20: ישראל | K20: ישראל | L20: סחיר | M20: TASE | N20: בנייה | O20: לא | P20: A2.il | Q20: מידרוג Moodys | R20: נייר ערך | S20: ILS | T20: 4.26 | U20: 30/04/2032 | V20: 0.05354 | W20: 0.0582 | X20: החוב לא נחות | Y20: לא | Z20: 282000 | AA20: 1 | AB20: 100.66 | AD20: 283.861 | AG20: שווי הוגן | AH20: 0.00161 | AI20: =AD20/SUMIF(B:B,B20,AD:AD) -> 0.016210367 | AJ20: 0.002667932
A21: 520042177 | B21: 12936 | C21: יובלים קבוצה | D21: 514625094 | E21: ח.פ. | F21: יובלים אגח א | G21: IL0011766438 | H21: ISIN | I21: לא צמוד למדד המחירים לצרכן | J21: ישראל | K21: ישראל | L21: חסום | M21: TASE | N21: בנייה | O21: לא | Q21: NR | R21: NR | S21: ILS | T21: 0.48 | U21: 06/07/2025 | V21: 0.06285 | W21: 0.0715 | X21: החוב לא נחות | Y21: לא | Z21: 275000 | AA21: 1 | AB21: =AD21*1000/Z21*100 -> 97.876 | AD21: =272.938-3.779 -> 269.159 | AG21: שווי הוגן | AH21: 0.00275 | AI21: =AD21/SUMIF(B:B,B21,AD:AD) -> 0.015370784 | AJ21: 0.0025297519
A22: 520042177 | B22: 12936 | C22: עמרם | D22: 513201582 | E22: ח.פ. | F22: עמרם אברהם אגח א | G22: IL0011880445 | H22: ISIN | I22: לא צמוד למדד המחירים לצרכן | J22: ישראל | K22: ישראל | L22: חסום | M22: TASE | N22: בנייה | O22: לא | Q22: NR | R22: NR | S22: ILS | T22: 1.59 | U22: 31/05/2027 | V22: 0.06489 | W22: 0.0631 | X22: החוב לא נחות | Y22: לא | Z22: 85000 | AA22: 1 | AB22: =AD22*1000/Z22*100 -> 100.6635 | AD22: =85563.9726775956/1000 -> 85.563973 | AG22: שווי הוגן | AH22: 0.00107 | AI22: =AD22/SUMIF(B:B,B22,AD:AD) -> 0.0048862766 | AJ22: 0.0008041924
A23: 520042177 | B23: 12936 | C23: אאורה | D23: 520038274 | E23: ח.פ. | F23: אאורה אגח יז | G23: IL0011935801 | H23: ISIN | I23: צמוד למדד המחירים לצרכן | J23: ישראל | K23: ישראל | L23: חסום | M23: TASE | N23: בנייה | O23: לא | P23: A2.il | Q23: מידרוג Moodys | R23: נייר ערך | S23: ILS | T23: 2.82 | U23: 31/01/2029 | V23: 0.03268 | W23: 0.0322 | X23: החוב לא נחות | Y23: לא | Z23: 159000 | AA23: 1 | AB23: =AD23*1000/Z23*100 -> 108.96918 | AD23: =173261.001639344/1000 -> 173.261 | AG23: שווי הוגן | AH23: 0.00083 | AI23: =AD23/SUMIF(B:B,B23,AD:AD) -> 0.009894365 | AJ23: 0.0016284328
A24: 520042177 | B24: 12936 | C24: מנרב | D24: 520034505 | E24: ח.פ. | F24: מנרב אגח ד | G24: IL0015501690 | H24: ISIN | I24: צמוד למדד המחירים לצרכן | J24: ישראל | K24: ישראל | L24: סחיר | M24: TASE | N24: בנייה | O24: לא | P24: Baa1.il | Q24: מידרוג Moodys | R24: נייר ערך | S24: ILS | T24: 3.66 | U24: 15/04/2032 | V24: 0.04574 | W24: 0.0497 | X24: החוב לא נחות | Y24: לא | Z24: 262225.5 | AA24: 1 | AB24: 101.96 | AD24: 267.365 | AG24: שווי הוגן | AH24: 0.00055 | AI24: =AD24/SUMIF(B:B,B24,AD:AD) -> 0.015268334 | AJ24: 0.0025128906
A25: 520042177 | B25: 12936 | C25: נאוויטס פטרו | D25: 550263107 | E25: ח.פ. | F25: נאוויטס פט אגחה | G25: IL0011979122 | H25: ISIN | I25: לא צמוד למדד המחירים לצרכן | J25: ישראל | K25: ישראל | L25: סחיר | M25: TASE | N25: חיפושי נפט וגז | O25: לא | P25: ilA- | Q25: S&P מעלות | R25: נייר ערך | S25: ILS | T25: 3.12 | U25: 31/12/2028 | V25: 0.07274 | W25: 0.0674 | X25: החוב לא נחות | Y25: לא | Z25: 263512 | AA25: 1 | AB25: 101.22 | AD25: 266.727 | AG25: שווי הוגן | AH25: 0.00053 | AI25: =AD25/SUMIF(B:B,B25,AD:AD) -> 0.0152319 | AJ25: 0.0025068942
A26: 520042177 | B26: 12936 | C26: מימון ישיר קב | D26: 513893123 | E26: ח.פ. | F26: מימון ישיר אגח ה | G26: IL0011828311 | H26: ISIN | I26: צמוד למדד המחירים לצרכן | J26: ישראל | K26: ישראל | L26: חסום | M26: TASE | N26: אשראי חוץ בנקאי | O26: לא | P26: A1.il | Q26: מידרוג Moodys | R26: נייר ערך | S26: ILS | T26: 3.25 | U26: 31/07/2031 | V26: 0.02949 | W26: 0.0333 | X26: החוב לא נחות | Y26: לא | Z26: 195000 | AA26: 1 | AB26: =AD26*1000/Z26*100 -> 104.02142 | AD26: =202841.770491803/1000 -> 202.84177 | AG26: שווי הוגן | AH26: 0.00016 | AI26: =AD26/SUMIF(B:B,B26,AD:AD) -> 0.011583625 | AJ26: 0.0019064544
A27: 520042177 | B27: 12936 | C27: שובל הנדסה | D27: 512951518 | E27: ח.פ. | F27: שובל אגח א | G27: IL0012079278 | H27: ISIN | I27: לא צמוד למדד המחירים לצרכן | J27: ישראל | K27: ישראל | L27: סחיר | M27: TASE | N27: בנייה | O27: לא | Q27: NR | R27: NR | S27: ILS | T27: 2.5 | U27: 30/09/2027 | V27: 0.08135 | W27: 0.0676 | X27: החוב לא נחות | Y27: לא | Z27: 248000 | AA27: 1 | AB27: 102.79 | AD27: 254.919 | AG27: שווי הוגן | AH27: 0.00183 | AI27: =AD27/SUMIF(B:B,B27,AD:AD) -> 0.014557584 | AJ27: 0.002395914
A28: 520042177 | B28: 12936 | C28: סטרוברי | D28: 1863501 | E28: מספר תאגיד או שותפות בחו"ל | F28: סטרוברי אגח ג | G28: IL0011790198 | H28: ISIN | I28: לא צמוד למדד המחירים לצרכן | J28: ישראל | K28: ארה"ב | L28: סחיר | M28: TASE | N28: נדל"ן מניב בחו"ל | O28: לא | P28: ilAA- | Q28: S&P מעלות | R28: נייר ערך | S28: ILS | T28: 1.68 | U28: 31/07/2026 | V28: 0.07003 | W28: 0.0671 | X28: החוב לא נחות | Y28: לא | Z28: 256106.06 | AA28: 1 | AB28: 99.49 | AD28: 254.8 | AG28: שווי הוגן | AH28: 0.00125 | AI28: =AD28/SUMIF(B:B,B28,AD:AD) -> 0.014550789 | AJ28: 0.0023947956
A29: 520042177 | B29: 12936 | C29: מודיעין יהש | D29: 550012405 | E29: ח.פ. | F29: מודיעין אג ב | G29: IL0012104423 | H29: ISIN | I29: צמוד למט"ח | J29: ישראל | K29: ישראל | L29: סחיר | M29: TASE | N29: חיפושי נפט וגז | O29: לא | Q29: NR | R29: NR | S29: ILS | T29: 3.51 | U29: 01/10/2028 | V29: 0.07327 | W29: 0.0978 | X29: החוב לא נחות | Y29: לא | Z29: 265000 | AA29: 1 | AB29: 92.3 | AD29: 244.595 | AG29: שווי הוגן | AH29: 0.00507 | AI29: =AD29/SUMIF(B:B,B29,AD:AD) -> 0.013968015 | AJ29: 0.0022988816
A30: 520042177 | B30: 12936 | C30: נמקו ריאלטי | D30: 1905761 | E30: מספר תאגיד או שותפות בחו"ל | F30: נמקו אגח ג | G30: IL0011987612 | H30: ISIN | I30: לא צמוד למדד המחירים לצרכן | J30: ישראל | K30: ארה"ב | L30: סחיר | M30: TASE | N30: נדל"ן מניב בחו"ל | O30: לא | P30: ilAA | Q30: S&P מעלות | R30: נייר ערך | S30: ILS | T30: 2.45 | U30: 30/06/2027 | V30: 0.06684 | W30: 0.062 | X30: החוב לא נחות | Y30: לא | Z30: 232000 | AA30: 1 | AB30: 102.2 | AD30: 237.104 | AG30: שווי הוגן | AH30: 0.00057 | AI30: =AD30/SUMIF(B:B,B30,AD:AD) -> 0.013540228 | AJ30: 0.0022284757
A31: 520042177 | B31: 12936 | C31: דה לסר | D31: 1427976 | E31: מספר תאגיד או שותפות בחו"ל | F31: דה לסר אגח ח | G31: IL0011931925 | H31: ISIN | I31: לא צמוד למדד המחירים לצרכן | J31: ישראל | K31: ארה"ב | L31: סחיר | M31: TASE | N31: נדל"ן מניב בחו"ל | O31: לא | P31: ilA | Q31: S&P מעלות | R31: נייר ערך | S31: ILS | T31: 2.02 | U31: 31/12/2026 | V31: 0.07793 | W31: 0.0652 | X31: החוב לא נחות | Y31: לא | Z31: 214370 | AA31: 1 | AB31: 102.45 | AD31: 219.622 | AG31: שווי הוגן | AH31: 0.00061 | AI31: =AD31/SUMIF(B:B,B31,AD:AD) -> 0.012541889 | AJ31: 0.0020641672
A32: 520042177 | B32: 12936 | C32: להב | D32: 520034257 | E32: ח.פ. | F32: להב אגח ג | G32: IL0011933418 | H32: ISIN | I32: צמוד למדד המחירים לצרכן | J32: ישראל | K32: ישראל | L32: סחיר | M32: TASE | N32: השקעה ואחזקות | O32: לא | P32: A2.il | Q32: מידרוג Moodys | R32: נייר ערך | S32: ILS | T32: 3.02 | U32: 10/07/2028 | V32: 0.02897 | W32: 0.0341 | X32: החוב לא נחות | Y32: לא | Z32: 200000 | AA32: 1 | AB32: 108.68 | AD32: 217.36 | AG32: שווי הוגן | AH32: 0.00057 | AI32: =AD32/SUMIF(B:B,B32,AD:AD) -> 0.012412714 | AJ32: 0.0020429073
A33: 520042177 | B33: 12936 | C33: אפקון החזקות | D33: 520033473 | E33: ח.פ. | F33: אפקון החז אגח ד | G33: IL0057801685 | H33: ISIN | I33: צמוד למדד המחירים לצרכן | J33: ישראל | K33: ישראל | L33: סחיר | M33: TASE | N33: השקעה ואחזקות | O33: לא | P33: ilA- | Q33: S&P מעלות | R33: נייר ערך | S33: ILS | T33: 2.61 | U33: 01/04/2029 | V33: 0.03562 | W33: 0.033 | X33: החוב לא נחות | Y33: לא | Z33: 189333.33 | AA33: 1 | AB33: 114.19 | AD33: 216.2 | AG33: שווי הוגן | AH33: 0.00084 | AI33: =AD33/SUMIF(B:B,B33,AD:AD) -> 0.01234647 | AJ33: 0.0020320047
A34: 520042177 | B34: 12936 | C34: פתאל אירופה | D34: 515328250 | E34: ח.פ. | F34: פתאל אירו אגח ה | G34: IL0011988867 | H34: ISIN | I34: לא צמוד למדד המחירים לצרכן | J34: ישראל | K34: ישראל | L34: סחיר | M34: TASE | N34: נדל"ן מניב בחו"ל | O34: לא | P34: A2.il | Q34: מידרוג Moodys | R34: נייר ערך | S34: ILS | T34: 3.33 | U34: 01/07/2029 | V34: 0.06335 | W34: 0.063 | X34: החוב לא נחות | Y34: לא | Z34: 208000 | AA34: 1 | AB34: 102.14 | AD34: 212.451 | AG34: שווי הוגן | AH34: 0.0005 | AI34: =AD34/SUMIF(B:B,B34,AD:AD) -> 0.012132377 | AJ34: 0.0019967689
A35: 520042177 | B35: 12936 | C35: ביג | D35: 513623314 | E35: ח.פ. | F35: ביג אגח ח | G35: IL0011389249 | H35: ISIN | I35: צמוד למדד המחירים לצרכן | J35: ישראל | K35: ישראל | L35: סחיר | M35: TASE | N35: נדל"ן מניב בישראל | O35: לא | P35: ilAA | Q35: S&P מעלות | R35: נייר ערך | S35: ILS | T35: 1.43 | U35: 12/04/2026 | V35: 0.01593 | W35: 0.0258 | X35: החוב לא נחות | Y35: לא | Z35: 183000 | AA35: 1 | AB35: 115.21 | AD35: 210.834 | AG35: שווי הוגן | AH35: 0.00037 | AI35: =AD35/SUMIF(B:B,B35,AD:AD) -> 0.012040035 | AJ35: 0.0019815712
A36: 520042177 | B36: 12936 | C36: אפי קפיטל נדלן | D36: 513948216 | E36: ח.פ. | F36: אפי קפיטל אגח ג | G36: IL0011997447 | H36: ISIN | I36: לא צמוד למדד המחירים לצרכן | J36: ישראל | K36: ישראל | L36: חסום | M36: TASE | N36: בנייה | O36: לא | Q36: NR | R36: NR | S36: ILS | T36: 2.05 | U36: 30/06/2027 | V36: 0.0661 | W36: 0.0711 | X36: החוב לא נחות | Y36: לא | Z36: 100000 | AA36: 1 | AB36: =AD36*1000/Z36*100 -> 104.73071 | AD36: =104730.710382514/1000 -> 104.73071 | AG36: שווי הוגן | AH36: 0.00154 | AI36: =AD36/SUMIF(B:B,B36,AD:AD) -> 0.0059808259 | AJ36: 0.00098433533
A37: 520042177 | B37: 12936 | C37: נופר אנרג'י | D37: 514599943 | E37: ח.פ. | F37: נופר אנרג אגח א | G37: IL0011793408 | H37: ISIN | I37: צמוד למדד המחירים לצרכן | J37: ישראל | K37: ישראל | L37: סחיר | M37: TASE | N37: אנרגיה מתחדשת | O37: לא | Q37: NR | R37: NR | S37: ILS | T37: 2.49 | U37: 31/12/2027 | V37: 0.0406 | W37: 0.0314 | X37: החוב לא נחות | Y37: לא | Z37: 185714.29 | AA37: 1 | AB37: 109.1 | AD37: 202.614 | AG37: שווי הוגן | AH37: 0.00025 | AI37: =AD37/SUMIF(B:B,B37,AD:AD) -> 0.011570618 | AJ37: 0.0019043136
A38: 520042177 | B38: 12936 | C38: אפי נכסים | D38: 510560188 | E38: ח.פ. | F38: אפי נכסים אגח יג | G38: IL0011782922 | H38: ISIN | I38: צמוד למדד המחירים לצרכן | J38: ישראל | K38: ישראל | L38: סחיר | M38: TASE | N38: נדל"ן מניב בחו"ל | O38: לא | P38: A2.il | Q38: מידרוג Moodys | R38: נייר ערך | S38: ILS | T38: 4.14 | U38: 01/07/2029 | V38: 0.0335 | W38: 0.0339 | X38: החוב לא נחות | Y38: לא | Z38: 194000 | AA38: 1 | AB38: 103.89 | AD38: 201.547 | AG38: שווי הוגן | AH38: 0.00027 | AI38: =AD38/SUMIF(B:B,B38,AD:AD) -> 0.011509685 | AJ38: 0.0018942852
A39: 520042177 | B39: 12936 | C39: 1 ריט | D39: 513821488 | E39: ח.פ. | F39: ריט 1 אגח ז | G39: IL0011712713 | H39: ISIN | I39: צמוד למדד המחירים לצרכן | J39: ישראל | K39: ישראל | L39: סחיר | M39: TASE | N39: נדל"ן מניב בישראל | O39: לא | P39: ilAA | Q39: S&P מעלות | R39: נייר ערך | S39: ILS | T39: 6.65 | U39: 20/09/2034 | V39: 0.02784 | W39: 0.0339 | X39: החוב לא נחות | Y39: לא | Z39: 184300 | AA39: 1 | AB39: 109.06 | AD39: 200.998 | AG39: שווי הוגן | AH39: 0.00022 | AI39: =AD39/SUMIF(B:B,B39,AD:AD) -> 0.011478334 | AJ39: 0.0018891253
A40: 520042177 | B40: 12936 | C40: אמפא יובלים | D40: 516286432 | E40: ח.פ. | F40: אמפא יובל אגח א | G40: IL0011935157 | H40: ISIN | I40: לא צמוד למדד המחירים לצרכן | J40: ישראל | K40: ישראל | L40: סחיר | M40: TASE | N40: נדל"ן מניב בישראל | O40: לא | Q40: NR | R40: NR | S40: ILS | T40: 0.92 | U40: 15/12/2025 | V40: 0.08753 | W40: 0.0869 | X40: החוב לא נחות | Y40: לא | Z40: 200000 | AA40: 1 | AB40: 100.1 | AD40: 200.2 | AG40: שווי הוגן | AH40: 0.00182 | AI40: =AD40/SUMIF(B:B,B40,AD:AD) -> 0.011432762 | AJ40: 0.0018816251
...

Sheet מניות מבכ ויהש
A1: מספר קופה/קרן/ח.פ. עבור חברת ביטוח | B1: מספר מסלול | C1: שם מנפיק | D1: מספר מנפיק | E1: סוג מספר מזהה מנפיק | F1: שם נייר ערך | G1: מספר נייר ערך | H1: סוג מספר נייר ערך | I1: מאפיין עיקרי | J1: ישראל/חו"ל | K1: מדינה לפי חשיפה כלכלית | L1: סטאטוס סחירות | M1: זירת מסחר | N1: ענף מסחר | O1: בעל עניין/צד קשור | P1: מטבע פעילות | Q1: ערך נקוב (יחידות) | R1: שער חליפין | S1: שער נייר הערך | T1: סכום לקבל (במטבע הפעילות) | U1: שווי הוגן (באלפי ש"ח) | V1: שיעור מערך נקוב מונפק | W1: שיעור מנכסי אפיק ההשקעה | X1: שיעור מסך נכסי ההשקעה
A2: 520042177 | B2: 12937 | C2: לאומי | D2: 520018078 | E2: ח.פ. | F2: לאומי | G2: IL0006046119 | H2: ISIN | I2: מניות | J2: ישראל | K2: ישראל | L2: סחיר | M2: TASE | N2: בנקים | O2: לא | P2: ILS | Q2: 185574 | R2: 1 | S2: 3644 | U2: 6762.317 | V2: 0.00011 | W2: =U2/SUMIF(B:B,B2,U:U) -> 0.043195288 | X2: 0.0062572147
A3: 520042177 | B3: 12937 | C3: טבע | D3: 520013954 | E3: ח.פ. | F3: טבע | G3: IL0006290147 | H3: ISIN | I3: מניות | J3: ישראל | K3: ישראל | L3: סחיר | M3: TASE | N3: פארמה | O3: לא | P3: ILS | Q3: 100940 | R3: 1 | S3: 6629 | U3: 6691.313 | V3: 8e-05 | W3: =U3/SUMIF(B:B,B3,U:U) -> 0.042741739 | X3: 0.0061915143
